File: scratch/college-stuff/ME Lab/ME lab Fall 2013/group3/group3.is_tens_RawData/Specimen_RawData_2.csv
Time,Extension,Load,Strain 2,Tensile strain,Tensile stress
(sec),(mm),(N),(mm/mm),(mm/mm),(MPa)
0.00000,0.00006,0.06002,0.00000,0.00000,0.00074
0.40000,0.01949,39.05451,0.00000,0.00001,0.47956
0.80000,0.04006,60.82923,0.00000,0.00001,0.74694
1.20000,0.06009,89.13641,0.00000,0.00002,1.09453
1.60000,0.08012,120.07040,0.00000,0.00002,1.47438
2.00000,0.10009,162.50358,0.00000,0.00002,1.99543
2.40000,0.11994,214.72326,0.00000,0.00003,2.63666
2.80000,0.13991,279.88462,0.00000,0.00003,3.43679
3.20000,0.15988,368.42709,0.00000,0.00004,4.52404
3.60000,0.17991,472.09845,0.00000,0.00006,5.79705
4.00000,0.20000,604.10132,0.00000,0.00007,7.41796
4.40000,0.22003,790.24956,0.00000,0.00009,9.70373
4.80000,0.24005,1014.64568,0.00000,0.00012,12.45916
5.20000,0.26008,1266.32098,0.00000,0.00015,15.54957
5.60000,0.28005,1546.28176,0.00000,0.00020,18.98730
6.00000,0.30008,1824.19494,0.00000,0.00024,22.39988
6.40000,0.32005,2112.53595,0.00000,0.00029,25.94052
6.80000,0.33996,2408.83101,0.00000,0.00034,29.57882
7.20000,0.35987,2709.43828,0.00000,0.00039,33.27007
7.60000,0.37984,3011.84990,0.00000,0.00044,36.98348
8.00000,0.39987,3311.94624,0.00000,0.00049,40.66846
8.40000,0.41990,3606.17265,0.00000,0.00052,44.28137
8.80000,0.43999,3899.75943,0.00000,0.00057,47.88641
9.20000,0.46002,4187.35445,0.00000,0.00062,51.41789
9.60000,0.47999,4468.58332,0.00000,0.00067,54.87119
10.00000,0.50002,4745.39995,0.00000,0.00072,58.27031
10.40000,0.52005,5016.18981,0.00000,0.00077,61.59543
10.80000,0.54002,5277.75250,0.00000,0.00081,64.80724
11.20000,0.55999,5525.31332,0.00000,0.00086,67.84712
11.60000,0.57996,5754.83851,0.00000,0.00090,70.66553
12.00000,0.59981,5958.58395,0.00000,0.00094,73.16739
12.40000,0.61984,6166.45403,0.00000,0.00097,75.71989
12.80000,0.63993,6370.26206,0.00000,0.00101,78.22252
13.20000,0.65990,6560.48134,0.00000,0.00104,80.55828
13.60000,0.67999,6740.53878,0.00000,0.00108,82.76927
14.00000,0.70002,6919.29609,0.00000,0.00111,84.96429
14.40000,0.72004,7101.97464,0.00000,0.00114,87.20746
14.80000,0.74007,7284.34324,0.00000,0.00118,89.44682
15.20000,0.76004,7468.73245,0.00000,0.00121,91.71099
15.60000,0.78001,7651.21430,0.00000,0.00124,93.95175
16.00000,0.79998,7834.98958,0.00000,0.00128,96.20838
16.40000,0.82001,8020.02922,0.00000,0.00131,98.48055
16.80000,0.83992,8204.90941,0.00000,0.00134,100.75075
17.20000,0.85989,8392.82498,0.00000,0.00137,103.05823
17.60000,0.87986,8579.81369,0.00000,0.00141,105.35432
18.00000,0.89989,8769.17467,0.00000,0.00144,107.67955
18.40000,0.91998,8958.13182,0.00000,0.00148,109.99981
18.80000,0.94001,9148.00465,0.00000,0.00151,112.33132
19.20000,0.96004,9339.57398,0.00000,0.00155,114.68367
19.60000,0.98007,9531.87644,0.00000,0.00158,117.04501
20.00000,0.99998,9722.04357,0.00000,0.00162,119.38013
20.40000,1.01995,9914.54422,0.00000,0.00165,121.74391
20.80000,1.03992,10107.38462,0.00000,0.00169,124.11186
21.20000,1.06001,10302.21730,0.00000,0.00172,126.50428
21.60000,1.07992,10495.32890,0.00000,0.00176,128.87556
22.00000,1.09989,10691.49598,0.00000,0.00180,131.28436
22.40000,1.11992,10888.03783,0.00000,0.00184,133.69776
22.80000,1.13989,11084.22577,0.00000,0.00187,136.10681
23.20000,1.15992,11279.67834,0.00000,0.00191,138.50684
23.60000,1.18007,11477.17386,0.00000,0.00194,140.93195
24.00000,1.20003,11676.02316,0.00000,0.00199,143.37369
24.40000,1.22006,11875.62495,0.00000,0.00202,145.82466
24.80000,1.24003,12076.17894,0.00000,0.00206,148.28733
25.20000,1.25994,12274.58939,0.00000,0.00210,150.72367
25.60000,1.27997,12472.75844,0.00000,0.00214,153.15706
26.00000,1.30000,12672.98311,0.00000,0.00218,155.61568
26.40000,1.31997,12875.70596,0.00000,0.00222,158.10498
26.80000,1.34000,13079.22602,0.00000,0.00226,160.60407
27.20000,1.35991,13281.16059,0.00000,0.00230,163.08369
27.60000,1.37988,13482.21451,0.00000,0.00234,165.55250
28.00000,1.39997,13684.06713,0.00000,0.00238,168.03111
28.40000,1.42000,13889.69719,0.00000,0.00242,170.55611
28.80000,1.44009,14093.48696,0.00000,0.00246,173.05851
29.20000,1.46006,14296.22173,0.00000,0.00250,175.54796
29.60000,1.48003,14499.83716,0.00000,0.00254,178.04822
30.00000,1.49994,14704.12761,0.00000,0.00258,180.55676
30.40000,1.51997,14908.71161,0.00000,0.00262,183.06892
30.80000,1.54000,15113.63238,0.00000,0.00266,185.58521
31.20000,1.55991,15316.89912,0.00000,0.00271,188.08119
31.60000,1.57994,15524.56170,0.00000,0.00275,190.63114
32.00000,1.59985,15730.15749,0.00000,0.00279,193.15572
32.40000,1.61994,15937.26873,0.00000,0.00284,195.69891
32.80000,1.63997,16142.17460,0.00000,0.00288,198.21501
33.20000,1.66000,16350.39449,0.00000,0.00292,200.77181
33.60000,1.68008,16560.09406,0.00000,0.00297,203.34678
34.00000,1.70005,16763.76462,0.00000,0.00301,205.84772
34.40000,1.72002,16970.17252,0.00000,0.00306,208.38227
34.80000,1.73993,17177.77550,0.00000,0.00310,210.93149
35.20000,1.75996,17383.50987,0.00000,0.00315,213.45777
35.60000,1.78005,17587.85695,0.00000,0.00320,215.96701
36.00000,1.80002,17792.28002,0.00000,0.00325,218.47719
36.40000,1.81993,17998.05164,0.00000,0.00329,221.00393
36.80000,1.83990,18205.42961,0.00000,0.00334,223.55039
37.20000,1.85993,18411.90606,0.00000,0.00339,226.08578
37.60000,1.87996,18616.22036,0.00000,0.00344,228.59462
38.00000,1.89993,18818.35610,0.00000,0.00349,231.07671
38.40000,1.92008,19023.70751,0.00000,0.00354,233.59829
38.80000,1.94011,19225.61377,0.00000,0.00360,236.07756
39.20000,1.96002,19423.78432,0.00000,0.00365,238.51096
39.60000,1.97999,19622.59263,0.00000,0.00370,240.95220
40.00000,2.00002,19815.74595,0.00000,0.00376,243.32399
40.40000,2.01999,20007.48366,0.00000,0.00382,245.67840
40.80000,2.03996,20201.69944,0.00000,0.00387,248.06324
41.20000,2.05999,20388.27688,0.00000,0.00394,250.35428
41.60000,2.07990,20572.45076,0.00000,0.00400,252.61581
42.00000,2.09987,20755.87660,0.00000,0.00406,254.86816
42.40000,2.11990,20932.37936,0.00000,0.00413,257.03549
42.80000,2.13993,21103.49387,0.00000,0.00420,259.13666
43.20000,2.16013,21268.54062,0.00000,0.00428,261.16333
43.60000,2.18010,21425.20547,0.00000,0.00436,263.08706
44.00000,2.20001,21572.62713,0.00000,0.00444,264.89730
44.40000,2.22004,21711.05742,0.00000,0.00453,266.59713
44.80000,2.24001,21838.37295,0.00000,0.00462,268.16048
45.20000,2.25992,21955.40667,0.00000,0.00472,269.59758
45.60000,2.27995,22065.45323,0.00000,0.00483,270.94888
46.00000,2.29992,22163.71894,0.00000,0.00495,272.15551
46.40000,2.31995,22254.36270,0.00000,0.00507,273.26856
46.80000,2.33992,22332.59827,0.00000,0.00521,274.22924
47.20000,2.35995,22401.88420,0.00000,0.00535,275.08002
47.60000,2.37998,22464.75220,0.00000,0.00550,275.85200
48.00000,2.40013,22520.82825,0.00000,0.00565,276.54057
48.40000,2.42010,22568.19159,0.00000,0.00582,277.12216
48.80000,2.44007,22613.09326,0.00000,0.00598,277.67353
49.20000,2.46004,22654.51699,0.00000,0.00616,278.18218
49.60000,2.48001,22690.00709,0.00000,0.00635,278.61798
50.00000,2.49992,22721.19820,0.00000,0.00653,279.00098
50.40000,2.51989,22750.84704,0.00000,0.00672,279.36505
50.80000,2.53998,22780.22468,0.00000,0.00692,279.72579
51.20000,2.55995,22806.95587,0.00000,0.00712,280.05403
51.60000,2.57998,22833.22364,0.00000,0.00732,280.37658
52.00000,2.60001,22853.95563,0.00000,0.00752,280.63115
52.40000,2.62004,22876.69182,0.00000,0.00774,280.91034
52.80000,2.64012,22894.94723,0.00000,0.00795,281.13450
53.20000,2.66015,22915.06082,0.00000,0.00816,281.38148
53.60000,2.68006,22932.61737,0.00000,0.00837,281.59707
54.00000,2.70003,22949.32753,0.00000,0.00858,281.80226
54.40000,2.72000,22964.68467,0.00000,0.00880,281.99083
54.80000,2.73985,22977.42516,0.00000,0.00902,282.14728
55.20000,2.75994,22992.17582,0.00000,0.00925,282.32840
55.60000,2.77997,23007.76839,0.00000,0.00947,282.51987
56.00000,2.79994,23022.08990,0.00000,0.00969,282.69573
56.40000,2.81997,23036.54552,0.00000,0.00992,282.87323
56.80000,2.84000,23050.07577,0.00000,0.01014,283.03938
57.20000,2.85997,23061.66589,0.00000,0.01037,283.18169
57.60000,2.88012,23073.02505,0.00000,0.01059,283.32118
58.00000,2.90009,23086.13360,0.00000,0.01082,283.48214
58.40000,2.92006,23099.87247,0.00000,0.01104,283.65085
58.80000,2.94009,23110.38673,0.00000,0.01127,283.77995
59.20000,2.95994,23119.10838,0.00000,0.01150,283.88705
59.60000,2.97991,23129.81635,0.00000,0.01173,284.01854
60.00000,2.99988,23140.78659,0.00000,0.01196,284.15324
60.40000,3.01991,23153.54496,0.00000,0.01219,284.30991
60.80000,3.04000,23164.44218,0.00000,0.01242,284.44372
61.20000,3.06003,23176.44358,0.00000,0.01265,284.59109
61.60000,3.08000,23186.62554,0.00000,0.01287,284.71611
62.00000,3.10009,23198.15606,0.00000,0.01310,284.85770
62.40000,3.12011,23206.36958,0.00000,0.01333,284.95856
62.80000,3.14014,23217.14312,0.00000,0.01356,285.09085
63.20000,3.16011,23228.65427,0.00000,0.01378,285.23220
63.60000,3.18008,23238.15525,0.00000,0.01401,285.34886
64.00000,3.19999,23248.49367,0.00000,0.01424,285.47581
64.40000,3.21990,23254.06373,0.00000,0.01446,285.54421
64.80000,3.23987,23264.22930,0.00000,0.01469,285.66904
65.20000,3.25996,23275.35450,0.00000,0.01491,285.80565
65.60000,3.28005,23288.90562,0.00000,0.01514,285.97205
66.00000,3.30002,23296.69744,0.00000,0.01537,286.06772
66.40000,3.32005,23307.74367,0.00000,0.01559,286.20336
66.80000,3.34002,23316.24180,0.00000,0.01581,286.30771
67.20000,3.36011,23325.83368,0.00000,0.01603,286.42550
67.60000,3.38014,23335.63566,0.00000,0.01626,286.54586
68.00000,3.40011,23343.57947,0.00000,0.01648,286.64340
68.40000,3.42008,23351.71998,0.00000,0.01670,286.74336
68.80000,3.43999,23360.80670,0.00000,0.01693,286.85494
69.20000,3.45990,23369.03661,0.00000,0.01715,286.95600
69.60000,3.47987,23376.69730,0.00000,0.01737,287.05007
70.00000,3.49996,23387.30544,0.00000,0.01759,287.18033
70.40000,3.51999,23396.13885,0.00000,0.01781,287.28880
70.80000,3.54002,23407.40114,0.00000,0.01803,287.42709
71.20000,3.55999,23417.53542,0.00000,0.01825,287.55153
71.60000,3.58007,23426.20343,0.00000,0.01846,287.65797
72.00000,3.60004,23433.84773,0.00000,0.01869,287.75184
72.40000,3.62001,23443.87919,0.00000,0.01891,287.87502
72.80000,3.64010,23453.48597,0.00000,0.01913,287.99298
73.20000,3.66007,23459.72955,0.00000,0.01935,288.06965
73.60000,3.67992,23467.27997,0.00000,0.01957,288.16236
74.00000,3.69989,23476.52316,0.00000,0.01978,288.27586
74.40000,3.71986,23485.67694,0.00000,0.02000,288.38826
74.80000,3.73995,23493.63267,0.00000,0.02022,288.48596
75.20000,3.76004,23504.37790,0.00000,0.02043,288.61790
75.60000,3.78001,23514.42873,0.00000,0.02065,288.74132
76.00000,3.79998,23525.10244,0.00000,0.02086,288.87238
76.40000,3.82001,23533.61696,0.00000,0.02108,288.97694
76.80000,3.84004,23540.28970,0.00000,0.02130,289.05887
77.20000,3.86007,23550.49253,0.00000,0.02151,289.18416
77.60000,3.88010,23558.39759,0.00000,0.02173,289.28122
78.00000,3.90001,23566.38759,0.00000,0.02194,289.37934
78.40000,3.91998,23573.45223,0.00000,0.02215,289.46609
78.80000,3.93995,23579.61237,0.00000,0.02236,289.54173
79.20000,3.95986,23586.83348,0.00000,0.02258,289.63040
79.60000,3.97995,23597.27919,0.00000,0.02279,289.75866
80.00000,3.99998,23606.65053,0.00000,0.02301,289.87374
80.40000,4.02007,23615.81624,0.00000,0.02322,289.98629
80.80000,4.04004,23623.86882,0.00000,0.02343,290.08517
81.20000,4.06001,23634.03141,0.00000,0.02365,290.20996
81.60000,4.08003,23641.18993,0.00000,0.02386,290.29786
82.00000,4.10000,23647.07291,0.00000,0.02406,290.37010
82.40000,4.12003,23655.56508,0.00000,0.02428,290.47438
82.80000,4.14006,23663.02162,0.00000,0.02448,290.56594
83.20000,4.15991,23670.94010,0.00000,0.02469,290.66317
83.60000,4.17988,23678.70063,0.00000,0.02490,290.75846
84.00000,4.19991,23686.40006,0.00000,0.02511,290.85301
84.40000,4.21994,23694.42582,0.00000,0.02532,290.95156
84.80000,4.24003,23705.67024,0.00000,0.02553,291.08963
85.20000,4.26000,23714.54835,0.00000,0.02574,291.19865
85.60000,4.28003,23722.17476,0.00000,0.02596,291.29230
86.00000,4.30006,23731.73982,0.00000,0.02616,291.40975
86.40000,4.32003,23738.02960,0.00000,0.02637,291.48698
86.80000,4.34000,23745.84675,0.00000,0.02658,291.58297
87.20000,4.36009,23750.97871,0.00000,0.02679,291.64599
87.60000,4.38006,23758.66026,0.00000,0.02699,291.74032
88.00000,4.39991,23766.02143,0.00000,0.02720,291.83071
88.40000,4.41994,23774.32585,0.00000,0.02740,291.93268
88.80000,4.43985,23781.51119,0.00000,0.02761,292.02091
89.20000,4.45994,23789.08694,0.00000,0.02782,292.11393
89.60000,4.47997,23798.27201,0.00000,0.02803,292.22672
90.00000,4.50006,23806.50043,0.00000,0.02823,292.32776
90.40000,4.52009,23817.28739,0.00000,0.02844,292.46022
90.80000,4.54006,23821.77860,0.00000,0.02865,292.51537
91.20000,4.56003,23828.04900,0.00000,0.02885,292.59236
91.60000,4.57999,23834.51462,0.00000,0.02906,292.67176
92.00000,4.60002,23842.99487,0.00000,0.02926,292.77589
92.40000,4.62005,23850.33518,0.00000,0.02946,292.86602
92.80000,4.64002,23857.59950,0.00000,0.02967,292.95522
93.20000,4.65993,23863.56294,0.00000,0.02987,293.02845
93.60000,4.67990,23872.09237,0.00000,0.03007,293.13318
94.00000,4.69993,23879.15552,0.00000,0.03028,293.21992
94.40000,4.72002,23887.86972,0.00000,0.03049,293.32692
94.80000,4.73999,23894.85091,0.00000,0.03069,293.41264
95.20000,4.76008,23904.44726,0.00000,0.03089,293.53048
95.60000,4.77999,23910.99185,0.00000,0.03110,293.61084
96.00000,4.80002,23918.58846,0.00000,0.03130,293.70413
96.40000,4.81999,23921.04119,0.00000,0.03150,293.73424
96.80000,4.84008,23930.46916,0.00000,0.03170,293.85001
97.20000,4.86011,23937.47419,0.00000,0.03190,293.93603
97.60000,4.88002,23943.44211,0.00000,0.03210,294.00931
98.00000,4.89999,23951.71076,0.00000,0.03230,294.11084
98.40000,4.91990,23957.48794,0.00000,0.03251,294.18178
98.80000,4.93987,23963.35453,0.00000,0.03271,294.25382
99.20000,4.95996,23971.08823,0.00000,0.03291,294.34879
99.60000,4.98005,23979.74730,0.00000,0.03311,294.45511
100.00000,5.00008,23986.21142,0.00000,0.03331,294.53449
100.40000,5.02011,23991.96178,0.00000,0.03350,294.60510
100.80000,5.04002,23997.74790,0.00000,0.03370,294.67615
101.20000,5.05998,24003.16894,0.00000,0.03391,294.74272
101.60000,5.08007,24009.99963,0.00000,0.03411,294.82659
102.00000,5.10004,24015.43707,0.00000,0.03430,294.89336
102.40000,5.12001,24022.47339,0.00000,0.03450,294.97976
102.80000,5.13992,24028.96285,0.00000,0.03469,295.05945
103.20000,5.15983,24036.05133,0.00000,0.03489,295.14649
103.60000,5.17992,24042.81944,0.00000,0.03509,295.22960
104.00000,5.19995,24049.05111,0.00000,0.03529,295.30612
104.40000,5.21998,24055.01157,0.00000,0.03548,295.37931
104.80000,5.24007,24062.63798,0.00000,0.03568,295.47296
105.20000,5.26004,24067.93088,0.00000,0.03587,295.53795
105.60001,5.28001,24074.96274,0.00000,0.03607,295.62430
106.00001,5.29998,24080.95896,0.00000,0.03626,295.69793
106.40001,5.32001,24086.72273,0.00000,0.03645,295.76870
106.80001,5.34004,24092.63998,0.00000,0.03665,295.84136
107.20001,5.36001,24098.61535,0.00000,0.03684,295.91473
107.60001,5.37986,24102.83387,0.00000,0.03703,295.96653
108.00001,5.39989,24109.75397,0.00000,0.03723,296.05151
108.40001,5.41986,24115.88281,0.00000,0.03742,296.12677
108.80001,5.43995,24122.46317,0.00000,0.03760,296.20757
109.20001,5.46010,24129.99421,0.00000,0.03779,296.30005
109.60001,5.48013,24135.87421,0.00000,0.03798,296.37225
110.00001,5.50004,24141.99412,0.00000,0.03818,296.44740
110.40001,5.52001,24147.73107,0.00000,0.03837,296.51784
110.80001,5.54003,24152.33999,0.00000,0.03855,296.57444
111.20001,5.56006,24155.19357,0.00000,0.03875,296.60948
111.60001,5.57997,24160.52818,0.00000,0.03893,296.67498
112.00001,5.60000,24167.61220,0.00000,0.03913,296.76197
112.40001,5.61997,24172.79780,0.00000,0.03931,296.82564
112.80001,5.63988,24175.81677,0.00000,0.03950,296.86272
113.20001,5.65985,24182.20043,0.00000,0.03968,296.94110
113.60001,5.67994,24188.71969,0.00000,0.03986,297.02115
114.00001,5.70009,24194.35978,0.00000,0.04005,297.09041
114.40001,5.72018,24200.49608,0.00000,0.04024,297.16576
114.80001,5.74009,24204.58943,0.00000,0.04042,297.21602
115.20001,5.76006,24211.88653,0.00000,0.04060,297.30563
115.60001,5.78003,24215.54625,0.00000,0.04078,297.35057
116.00001,5.80006,24218.00047,0.00000,0.04097,297.38070
116.40001,5.82003,24221.16250,0.00000,0.04115,297.41953
116.80001,5.84000,24226.71467,0.00000,0.04133,297.48771
117.20001,5.85991,24232.60659,0.00000,0.04151,297.56006
117.60001,5.87988,24237.82200,0.00000,0.04169,297.62410
118.00001,5.89997,24243.24006,0.00000,0.04187,297.69063
118.40001,5.92000,24248.14701,0.00000,0.04205,297.75088
118.80001,5.94015,24255.99545,0.00000,0.04224,297.84726
119.20001,5.96012,24260.18566,0.00000,0.04241,297.89871
119.60001,5.98015,24265.01662,0.00000,0.04260,297.95803
120.00001,6.00011,24270.62243,0.00000,0.04277,298.02687
120.40001,6.02002,24273.81277,0.00000,0.04295,298.06604
120.80001,6.03993,24276.87049,0.00000,0.04312,298.10359
121.20001,6.05996,24279.97589,0.00000,0.04331,298.14172
121.60001,6.07993,24281.79383,0.00000,0.04348,298.16404
122.00001,6.09996,24290.24875,0.00000,0.04366,298.26786
122.40001,6.11993,24295.59678,0.00000,0.04383,298.33353
122.80001,6.13990,24301.18173,0.00000,0.04401,298.40211
123.20001,6.15999,24304.94130,0.00000,0.04418,298.44828
123.60001,6.18008,24309.37290,0.00000,0.04436,298.50269
124.00001,6.20017,24316.23489,0.00000,0.04453,298.58696
124.40001,6.22014,24320.51748,0.00000,0.04471,298.63954
124.80001,6.24011,24324.64957,0.00000,0.04487,298.69028
125.20001,6.26002,24325.82676,0.00000,0.04505,298.70474
125.60001,6.27999,24328.88448,0.00000,0.04522,298.74228
126.00001,6.29990,24334.35768,0.00000,0.04539,298.80949
126.40001,6.31999,24339.02621,0.00000,0.04557,298.86682
126.80001,6.33996,24342.48179,0.00000,0.04573,298.90925
127.20001,6.35993,24347.34106,0.00000,0.04590,298.96892
127.60001,6.37996,24355.58587,0.00000,0.04607,299.07016
128.00001,6.39999,24359.25752,0.00000,0.04624,299.11524
128.40001,6.42008,24362.17368,0.00000,0.04641,299.15105
128.80001,6.44017,24366.48905,0.00000,0.04658,299.20404
129.20001,6.46014,24370.20689,0.00000,0.04675,299.24970
129.60001,6.47998,24374.37177,0.00000,0.04691,299.30084
130.00001,6.49995,24377.11507,0.00000,0.04708,299.33452
130.40001,6.51986,24378.26544,0.00000,0.04725,299.34865
130.80001,6.53989,24381.45578,0.00000,0.04742,299.38782
131.20001,6.55992,24387.32982,0.00000,0.04759,299.45995
131.60001,6.57995,24393.17852,0.00000,0.04775,299.53177
132.00001,6.59998,24398.18233,0.00000,0.04792,299.59321
132.40001,6.61995,24401.52019,0.00000,0.04809,299.63420
132.80001,6.63986,24404.84464,0.00000,0.04825,299.67502
133.20001,6.66001,24409.60109,0.00000,0.04842,299.73343
133.60001,6.68010,24413.74063,0.00000,0.04858,299.78426
134.00001,6.70013,24416.52715,0.00000,0.04875,299.81848
134.40001,6.72010,24422.91230,0.00000,0.04891,299.89688
134.80001,6.73995,24423.40553,0.00000,0.04908,299.90294
135.20001,6.75992,24426.16522,0.00000,0.04924,299.93683
135.60001,6.77989,24426.42152,0.00000,0.04940,299.93997
136.00001,6.79998,24433.14493,0.00000,0.04957,300.02253
136.40001,6.82001,24439.45110,0.00000,0.04974,300.09997
136.80001,6.83998,24444.01085,0.00000,0.04990,300.15596
137.20001,6.85995,24447.92241,0.00000,0.05006,300.20399
137.60001,6.87998,24451.49124,0.00000,0.05023,300.24781
138.00001,6.90001,24455.22994,0.00000,0.05040,300.29372
138.40001,6.92010,24459.66601,0.00000,0.05056,300.34819
138.80001,6.94013,24463.60141,0.00000,0.05073,300.39652
139.20001,6.96003,24466.08990,0.00000,0.05090,300.42707
139.60001,6.98000,24467.44144,0.00000,0.05106,300.44367
140.00001,6.99991,24469.61701,0.00000,0.05123,300.47038
140.40001,7.01994,24473.84447,0.00000,0.05140,300.52229
140.80001,7.03997,24478.91980,0.00000,0.05156,300.58462
141.20001,7.06000,24482.33068,0.00000,0.05173,300.62650
141.60001,7.07997,24486.62370,0.00000,0.05190,300.67921
142.00001,7.10000,24492.56629,0.00000,0.05206,300.75219
142.40001,7.11991,24495.06372,0.00000,0.05223,300.78285
142.80001,7.14000,24497.97094,0.00000,0.05240,300.81855
143.20001,7.16009,24500.70381,0.00000,0.05257,300.85211
143.60001,7.18006,24504.52149,0.00000,0.05273,300.89899
144.00001,7.20003,24507.49278,0.00000,0.05290,300.93547
144.40001,7.22000,24510.47003,0.00000,0.05307,300.97203
144.80001,7.23991,24511.27470,0.00000,0.05323,300.98191
145.20001,7.25994,24515.69438,0.00000,0.05340,301.03618
145.60001,7.27997,24518.13221,0.00000,0.05357,301.06612
146.00001,7.30000,24522.83949,0.00000,0.05374,301.12392
146.40001,7.32003,24528.64051,0.00000,0.05391,301.19515
146.80001,7.33994,24529.37365,0.00000,0.05408,301.20416
147.20001,7.35997,24532.57740,0.00000,0.05424,301.24350
147.60001,7.38006,24536.38315,0.00000,0.05441,301.29023
148.00001,7.40009,24540.17401,0.00000,0.05458,301.33678
148.40001,7.42018,24544.09748,0.00000,0.05475,301.38495
148.80001,7.44008,24546.42951,0.00000,0.05492,301.41359
149.20001,7.46005,24549.97897,0.00000,0.05509,301.45717
149.60001,7.47996,24552.39296,0.00000,0.05526,301.48682
150.00001,7.49999,24552.42127,0.00000,0.05542,301.48716
150.40001,7.51996,24555.08858,0.00000,0.05559,301.51992
150.80001,7.53999,24561.14441,0.00000,0.05577,301.59428
151.20001,7.55996,24565.90682,0.00000,0.05594,301.65276
151.60001,7.57987,24568.32826,0.00000,0.05611,301.68249
152.00001,7.60002,24571.08349,0.00000,0.05627,301.71632
152.40001,7.61999,24573.61072,0.00000,0.05645,301.74736
152.80001,7.64002,24577.13038,0.00000,0.05662,301.79058
153.20001,7.66005,24579.89454,0.00000,0.05679,301.82452
153.60001,7.68008,24583.87613,0.00000,0.05696,301.87341
154.00001,7.70005,24586.66116,0.00000,0.05713,301.90761
154.40001,7.72002,24589.05280,0.00000,0.05731,301.93698
154.80001,7.73987,24590.12866,0.00000,0.05748,301.95019
155.20001,7.75996,24592.76766,0.00000,0.05767,301.98259
155.60001,7.77993,24593.47844,0.00000,0.05784,301.99132
156.00001,7.79996,24599.51788,0.00000,0.05801,302.06548
156.40001,7.81999,24602.79763,0.00000,0.05818,302.10575
156.80001,7.84002,24606.64660,0.00000,0.05836,302.15302
157.20001,7.86005,24608.63292,0.00000,0.05853,302.17741
157.60001,7.88002,24609.02035,0.00000,0.05870,302.18216
158.00001,7.90010,24613.90942,0.00000,0.05888,302.24220
158.40001,7.92007,24616.56630,0.00000,0.05905,302.27482
158.80001,7.94004,24618.56902,0.00000,0.05923,302.29941
159.20001,7.96001,24619.84903,0.00000,0.05940,302.31513
159.60001,7.97992,24620.29308,0.00000,0.05957,302.32058
160.00001,7.99983,24621.91433,0.00000,0.05974,302.34049
160.40001,8.01992,24625.20748,0.00000,0.05992,302.38093
160.80001,8.04001,24628.57366,0.00000,0.06009,302.42226
161.20001,8.06004,24632.18421,0.00000,0.06026,302.46660
161.60001,8.08001,24635.21510,0.00000,0.06044,302.50382
162.00001,8.10004,24638.09252,0.00000,0.06061,302.53915
162.40001,8.11995,24637.49051,0.00000,0.06078,302.53176
162.80001,8.14016,24642.65078,0.00000,0.06095,302.59512
163.20001,8.16013,24643.57764,0.00000,0.06112,302.60650
163.60001,8.18004,24644.12749,0.00000,0.06129,302.61326
164.00001,8.19995,24645.83665,0.00000,0.06147,302.63424
164.40001,8.21986,24645.62505,0.00000,0.06164,302.63164
164.80001,8.23989,24648.13590,0.00000,0.06181,302.66248
165.20001,8.25992,24650.76447,0.00000,0.06198,302.69475
165.60001,8.28001,24655.94113,0.00000,0.06215,302.75832
166.00001,8.30004,24659.95550,0.00000,0.06232,302.80761
166.40001,8.32007,24661.03733,0.00000,0.06249,302.82090
166.80001,8.34004,24661.40538,0.00000,0.06265,302.82542
167.20001,8.36001,24664.32154,0.00000,0.06283,302.86122
167.60001,8.38009,24666.67891,0.00000,0.06300,302.89017
168.00001,8.40012,24668.33591,0.00000,0.06317,302.91052
168.40001,8.42003,24669.19422,0.00000,0.06334,302.92106
168.80001,8.43994,24671.12541,0.00000,0.06351,302.94477
169.20001,8.45991,24671.41151,0.00000,0.06368,302.94828
169.60001,8.47988,24672.96571,0.00000,0.06385,302.96737
170.00001,8.49991,24675.59725,0.00000,0.06402,302.99968
170.40001,8.52000,24680.47589,0.00000,0.06418,303.05959
170.80001,8.54009,24684.69441,0.00000,0.06436,303.11139
171.20001,8.56006,24685.66895,0.00000,0.06452,303.12336
171.60001,8.58009,24686.05191,0.00000,0.06470,303.12806
172.00001,8.60000,24685.58550,0.00000,0.06486,303.12233
172.40001,8.62009,24689.08727,0.00000,0.06504,303.16533
172.80001,8.64012,24689.70567,0.00000,0.06521,303.17292
173.20001,8.66009,24690.10055,0.00000,0.06537,303.17777
173.60001,8.68000,24690.29129,0.00000,0.06553,303.18012
174.00001,8.69985,24691.44613,0.00000,0.06570,303.19430
174.40001,8.71988,24694.62454,0.00000,0.06587,303.23332
174.80001,8.73991,24696.28751,0.00000,0.06604,303.25375
175.20001,8.76012,24700.19609,0.00000,0.06621,303.30174
175.60001,8.78009,24702.36570,0.00000,0.06638,303.32838
176.00001,8.80012,24704.34010,0.00000,0.06654,303.35263
176.40001,8.82009,24706.31599,0.00000,0.06671,303.37689
176.80001,8.84006,24705.99562,0.00000,0.06687,303.37295
177.20001,8.86009,24705.32209,0.00000,0.06704,303.36468
177.60001,8.88005,24705.19096,0.00000,0.06720,303.36307
178.00001,8.90002,24707.82548,0.00000,0.06737,303.39542
178.40001,8.91993,24708.77618,0.00000,0.06753,303.40710
178.80001,8.93984,24710.41530,0.00000,0.06769,303.42722
179.20001,8.95987,24712.27646,0.00000,0.06786,303.45008
179.60001,8.97996,24716.10159,0.00000,0.06803,303.49705
180.00001,9.00005,24719.38133,0.00000,0.06819,303.53732
180.40001,9.02008,24720.06977,0.00000,0.06836,303.54578
180.80001,9.04005,24720.45124,0.00000,0.06852,303.55046
181.20001,9.06008,24722.50015,0.00000,0.06868,303.57562
181.60001,9.07999,24723.55962,0.00000,0.06885,303.58863
182.00001,9.10002,24723.89042,0.00000,0.06901,303.59269
182.40001,9.12005,24724.71893,0.00000,0.06918,303.60286
182.80001,9.14008,24726.45044,0.00000,0.06934,303.62413
183.20001,9.15993,24728.31011,0.00000,0.06951,303.64696
183.60001,9.17990,24729.98500,0.00000,0.06967,303.66753
184.00001,9.19993,24731.51088,0.00000,0.06984,303.68626
184.40001,9.21990,24730.65704,0.00000,0.07000,303.67578
184.80001,9.24005,24735.79198,0.00000,0.07017,303.73883
185.20001,9.26008,24738.60830,0.00000,0.07033,303.77342
185.60001,9.28011,24738.66493,0.00000,0.07050,303.77411
186.00001,9.30008,24739.60668,0.00000,0.07066,303.78568
186.40001,9.31999,24738.21491,0.00000,0.07082,303.76859
186.80001,9.34002,24738.98381,0.00000,0.07098,303.77803
187.20001,9.35998,24739.35634,0.00000,0.07115,303.78260
187.60001,9.38001,24740.18335,0.00000,0.07131,303.79276
188.00001,9.39998,24741.15193,0.00000,0.07148,303.80465
188.40001,9.41989,24744.19922,0.00000,0.07164,303.84207
188.80001,9.43986,24745.24677,0.00000,0.07180,303.85493
189.20001,9.45989,24745.31829,0.00000,0.07197,303.85581
189.60001,9.47992,24746.45525,0.00000,0.07213,303.86977
190.00001,9.50007,24750.62311,0.00000,0.07230,303.92095
190.40001,9.52004,24751.78242,0.00000,0.07246,303.93519
190.80001,9.54007,24751.90908,0.00000,0.07262,303.93674
191.20001,9.56004,24751.63937,0.00000,0.07279,303.93343
191.60001,9.58001,24750.41002,0.00000,0.07295,303.91833
192.00001,9.59992,24751.11932,0.00000,0.07312,303.92704
192.40001,9.62007,24753.75533,0.00000,0.07328,303.95941
192.80001,9.63998,24753.55119,0.00000,0.07345,303.95690
193.20001,9.65995,24754.56893,0.00000,0.07361,303.96940
193.60001,9.67998,24756.96057,0.00000,0.07377,303.99877
194.00001,9.69989,24756.76537,0.00000,0.07393,303.99637
194.40001,9.71998,24758.79788,0.00000,0.07410,304.02133
194.80001,9.74007,24758.78447,0.00000,0.07426,304.02117
195.20001,9.76010,24761.62761,0.00000,0.07443,304.05608
195.60001,9.78007,24761.85858,0.00000,0.07459,304.05891
196.00001,9.80004,24763.16839,0.00000,0.07476,304.07500
196.40001,9.81995,24761.57844,0.00000,0.07492,304.05547
196.80001,9.83997,24761.73937,0.00000,0.07508,304.05745
197.20001,9.86006,24763.74656,0.00000,0.07525,304.08210
197.60001,9.87997,24763.95965,0.00000,0.07541,304.08471
198.00001,9.90000,24765.06382,0.00000,0.07558,304.09827
198.40001,9.91991,24763.09240,0.00000,0.07574,304.07406
198.80001,9.93994,24765.70755,0.00000,0.07591,304.10618
199.20001,9.95997,24767.30943,0.00000,0.07607,304.12585
199.60001,9.98006,24768.93067,0.00000,0.07624,304.14575
200.00001,10.00015,24770.34032,0.00000,0.07640,304.16306
200.40001,10.02006,24770.57427,0.00000,0.07656,304.16594
200.80001,10.03997,24770.51467,0.00000,0.07673,304.16520
201.20001,10.06000,24771.72911,0.00000,0.07690,304.18012
201.60001,10.07991,24768.43148,0.00000,0.07706,304.13962
202.00001,10.10006,24770.67560,0.00000,0.07723,304.16718
202.40001,10.12003,24770.95574,0.00000,0.07740,304.17062
202.80001,10.13994,24771.94965,0.00000,0.07756,304.18283
203.20001,10.15997,24773.51725,0.00000,0.07773,304.20207
203.60001,10.17988,24771.75891,0.00000,0.07789,304.18048
204.00001,10.19997,24773.42337,0.00000,0.07805,304.20092
204.40001,10.22006,24776.80892,0.00000,0.07822,304.24249
204.80001,10.24015,24777.82816,0.00000,0.07839,304.25501
205.20001,10.26006,24777.61954,0.00000,0.07856,304.25245
205.60001,10.28003,24777.24552,0.00000,0.07873,304.24785
206.00001,10.30000,24776.28738,0.00000,0.07889,304.23609
206.40001,10.31996,24775.72262,0.00000,0.07905,304.22915
206.80001,10.34005,24774.03581,0.00000,0.07922,304.20844
207.20001,10.36002,24774.18184,0.00000,0.07939,304.21023
207.60001,10.37999,24778.10830,0.00000,0.07956,304.25845
208.00001,10.39990,24776.39019,0.00000,0.07972,304.23735
208.40001,10.41987,24776.63010,0.00000,0.07989,304.24030
208.80001,10.43996,24777.84753,0.00000,0.08006,304.25525
209.20001,10.46011,24780.65044,0.00000,0.08022,304.28966
209.60001,10.48008,24780.27195,0.00000,0.08039,304.28502
210.00001,10.50005,24781.29864,0.00000,0.08056,304.29762
210.40001,10.52002,24781.18241,0.00000,0.08073,304.29620
210.80001,10.53999,24780.05141,0.00000,0.08089,304.28231
211.20001,10.56002,24777.48394,0.00000,0.08106,304.25078
211.60001,10.57999,24778.31393,0.00000,0.08123,304.26097
212.00001,10.60002,24778.37801,0.00000,0.08140,304.26176
212.40001,10.61993,24776.74335,0.00000,0.08157,304.24169
212.80001,10.63990,24779.48815,0.00000,0.08174,304.27539
213.20001,10.65987,24780.28834,0.00000,0.08190,304.28522
213.60001,10.68002,24782.42815,0.00000,0.08207,304.31149
214.00001,10.69999,24782.08840,0.00000,0.08224,304.30732
214.40001,10.72014,24782.11671,0.00000,0.08241,304.30767
214.80001,10.74005,24781.06022,0.00000,0.08258,304.29470
215.20001,10.76002,24782.65911,0.00000,0.08275,304.31433
215.60001,10.77999,24783.11062,0.00000,0.08292,304.31987
216.00001,10.79996,24779.90836,0.00000,0.08309,304.28055
216.40001,10.82004,24778.99790,0.00000,0.08326,304.26937
216.80001,10.83995,24778.42569,0.00000,0.08343,304.26235
217.20001,10.85992,24779.92326,0.00000,0.08359,304.28074
217.60001,10.87995,24780.97081,0.00000,0.08377,304.29360
218.00001,10.89992,24782.93926,0.00000,0.08394,304.31777
218.40001,10.91995,24781.62050,0.00000,0.08411,304.30158
218.80001,10.94004,24782.44752,0.00000,0.08428,304.31173
219.20001,10.96013,24783.78564,0.00000,0.08445,304.32816
219.60001,10.98010,24781.56835,0.00000,0.08462,304.30094
220.00001,11.00007,24779.96647,0.00000,0.08479,304.28127
220.40001,11.01998,24778.79077,0.00000,0.08496,304.26683
220.80001,11.04001,24778.87869,0.00000,0.08513,304.26791
221.20001,11.05998,24775.77180,0.00000,0.08530,304.22976
221.60001,11.07995,24776.94154,0.00000,0.08547,304.24412
222.00001,11.09998,24777.25893,0.00000,0.08564,304.24802
222.40001,11.11995,24778.88316,0.00000,0.08581,304.26796
222.80001,11.13992,24780.55954,0.00000,0.08599,304.28855
223.20001,11.16001,24779.21993,0.00000,0.08616,304.27210
223.60001,11.18004,24776.84170,0.00000,0.08633,304.24290
224.00001,11.20019,24778.59259,0.00000,0.08650,304.26440
224.40001,11.22010,24778.18578,0.00000,0.08667,304.25940
224.80001,11.24007,24777.21870,0.00000,0.08684,304.24753
225.20001,11.25998,24775.38288,0.00000,0.08701,304.22498
225.60001,11.27995,24773.19539,0.00000,0.08718,304.19812
226.00001,11.29985,24772.59487,0.00000,0.08735,304.19075
226.40001,11.31994,24773.99111,0.00000,0.08753,304.20789
226.80001,11.33991,24773.39208,0.00000,0.08770,304.20054
227.20001,11.35994,24773.73928,0.00000,0.08787,304.20480
227.60001,11.37997,24776.36635,0.00000,0.08804,304.23706
228.00001,11.40000,24775.44546,0.00000,0.08821,304.22575
228.40001,11.42003,24773.55599,0.00000,0.08838,304.20255
228.80001,11.44012,24772.90779,0.00000,0.08855,304.19459
229.20001,11.46015,24772.22234,0.00000,0.08873,304.18617
229.60001,11.48006,24771.84236,0.00000,0.08890,304.18151
230.00001,11.50003,24771.19565,0.00000,0.08907,304.17357
230.40001,11.51988,24767.80564,0.00000,0.08924,304.13194
230.80001,11.53991,24766.00409,0.00000,0.08940,304.10982
231.20001,11.55988,24766.53904,0.00000,0.08958,304.11639
231.60001,11.57997,24768.82935,0.00000,0.08975,304.14451
232.00001,11.60000,24768.09621,0.00000,0.08992,304.13551
232.40001,11.62003,24766.90263,0.00000,0.09010,304.12085
232.80001,11.64006,24766.44963,0.00000,0.09026,304.11529
233.20001,11.66003,24765.24860,0.00000,0.09043,304.10054
233.60001,11.68012,24765.44231,0.00000,0.09060,304.10292
234.00001,11.70015,24763.74656,0.00000,0.09078,304.08210
234.40001,11.72006,24760.29098,0.00000,0.09094,304.03966
234.80001,11.73996,24761.02859,0.00000,0.09112,304.04872
235.20001,11.75994,24760.60092,0.00000,0.09129,304.04347
235.60001,11.77985,24757.90232,0.00000,0.09145,304.01033
236.00001,11.79993,24758.11988,0.00000,0.09162,304.01300
236.40001,11.81996,24759.10038,0.00000,0.09180,304.02504
236.80001,11.83993,24759.01991,0.00000,0.09196,304.02406
237.20001,11.86002,24758.74126,0.00000,0.09213,304.02063
237.60001,11.87999,24757.17962,0.00000,0.09230,304.00146
238.00001,11.90002,24754.92954,0.00000,0.09247,303.97383
238.40001,11.92011,24755.66268,0.00000,0.09264,303.98283
238.80001,11.94014,24755.58221,0.00000,0.09281,303.98184
239.20001,11.95999,24753.18164,0.00000,0.09298,303.95237
239.60001,11.98002,24752.15942,0.00000,0.09315,303.93981
240.00001,11.99993,24750.60523,0.00000,0.09331,303.92073
240.40001,12.01984,24749.02719,0.00000,0.09348,303.90135
240.80001,12.03987,24747.74122,0.00000,0.09365,303.88556
241.20001,12.06002,24746.29730,0.00000,0.09382,303.86783
241.60001,12.08005,24749.14044,0.00000,0.09398,303.90274
242.00001,12.10002,24748.70980,0.00000,0.09416,303.89746
242.40001,12.11993,24746.34051,0.00000,0.09432,303.86836
242.80001,12.14002,24743.52866,0.00000,0.09449,303.83383
243.20001,12.16011,24742.49005,0.00000,0.09465,303.82108
243.60001,12.18008,24741.97596,0.00000,0.09482,303.81477
244.00001,12.20005,24741.64218,0.00000,0.09499,303.81067
244.40001,12.22002,24739.39210,0.00000,0.09516,303.78304
244.80001,12.23993,24737.12713,0.00000,0.09532,303.75523
245.20001,12.25989,24733.83993,0.00000,0.09548,303.71486
245.60001,12.27987,24733.91443,0.00000,0.09565,303.71578
246.00001,12.29995,24734.54028,0.00000,0.09581,303.72346
246.40001,12.31998,24733.84142,0.00000,0.09598,303.71488
246.80001,12.34001,24731.85509,0.00000,0.09614,303.69049
247.20001,12.36004,24732.14120,0.00000,0.09630,303.69400
247.60001,12.38001,24730.82989,0.00000,0.09646,303.67790
248.00001,12.40004,24728.91212,0.00000,0.09662,303.65435
248.40001,12.42013,24726.58902,0.00000,0.09679,303.62583
248.80001,12.44004,24724.08116,0.00000,0.09694,303.59503
249.20001,12.45995,24723.17219,0.00000,0.09710,303.58387
249.60001,12.47986,24721.64035,0.00000,0.09727,303.56506
250.00001,12.49989,24719.81049,0.00000,0.09742,303.54259
250.40001,12.51992,24716.10159,0.00000,0.09758,303.49705
250.80001,12.54001,24715.50703,0.00000,0.09774,303.48975
251.20001,12.55998,24715.31332,0.00000,0.09790,303.48737
251.60001,12.58001,24714.94675,0.00000,0.09805,303.48287
252.00001,12.60004,24713.51475,0.00000,0.09821,303.46528
252.40001,12.62001,24711.21848,0.00000,0.09836,303.43709
252.80001,12.64004,24710.06066,0.00000,0.09851,303.42287
253.20001,12.66007,24708.47219,0.00000,0.09866,303.40336
253.60001,12.68010,24705.03896,0.00000,0.09882,303.36121
254.00001,12.70000,24702.60561,0.00000,0.09897,303.33133
254.40001,12.71992,24701.94548,0.00000,0.09912,303.32322
254.80001,12.73994,24699.06360,0.00000,0.09927,303.28783
255.20001,12.75986,24693.57997,0.00000,0.09941,303.22050
255.60001,12.77994,24690.87690,0.00000,0.09955,303.18731
256.00001,12.80003,24691.73670,0.00000,0.09970,303.19786
256.40001,12.82000,24691.76054,0.00000,0.09984,303.19816
256.80001,12.84003,24689.44043,0.00000,0.09998,303.16967
257.20001,12.86000,24686.55556,0.00000,0.10012,303.13424
257.60001,12.87997,24680.72623,0.00000,0.10026,303.06266
258.00001,12.90000,24679.33893,0.00000,0.10039,303.04563
258.40001,12.91997,24675.62705,0.00000,0.10052,303.00005
258.80001,12.94006,24672.93441,0.00000,0.10066,302.96698
259.20001,12.95997,24667.02759,0.00000,0.10079,302.89445
259.60001,12.97994,24663.18011,0.00000,0.10092,302.84721
260.00001,12.99991,24659.20746,0.00000,0.10104,302.79843
260.40001,13.02000,24656.53569,0.00000,0.10116,302.76562
260.80001,13.04003,24654.29306,0.00000,0.10128,302.73808
261.20001,13.06006,24651.05951,0.00000,0.10140,302.69838
261.60001,13.08003,24647.03023,0.00000,0.10152,302.64890
262.00001,13.10000,24641.18153,0.00000,0.10163,302.57708
262.40001,13.12003,24634.16904,0.00000,0.10174,302.49097
262.80001,13.14006,24625.29987,0.00000,0.10184,302.38206
263.20001,13.16009,24618.78657,0.00000,0.10195,302.30209
263.60001,13.18005,24611.85604,0.00000,0.10205,302.21698
264.00001,13.20002,24600.99310,0.00000,0.10214,302.08359
264.40001,13.21993,24590.70981,0.00000,0.10222,301.95732
264.80001,13.23991,24579.14203,0.00000,0.10231,301.81528
265.20001,13.25987,24568.09878,0.00000,0.10239,301.67967
265.60001,13.28002,24556.82904,0.00000,0.10246,301.54129
266.00001,13.30005,24540.31706,0.00000,0.10254,301.33853
266.40001,13.32008,24520.76375,0.00000,0.10260,301.09843
266.80001,13.34005,24497.50900,0.00000,0.10265,300.81288
267.20001,13.36002,24468.26845,0.00000,0.10270,300.45382
267.60001,13.37999,24430.40162,0.00000,0.10274,299.98885
268.00001,13.40014,24363.75767,0.00000,0.10277,299.17050
268.40001,13.42017,24139.29999,0.00000,0.10274,296.41431
268.43201,13.42214,21115.99743,0.00000,0.09665,259.29020
268.44001,13.42358,15946.46126,0.00000,0.08297,195.81178
268.44401,13.42424,13202.60167,0.00000,0.07607,162.11904