File: scratch/college-stuff/ME Lab/ME lab Fall 2013/group3/group3.is_tens_RawData/Specimen_RawData_3.csv
Time,Extension,Load,Strain 2,Tensile strain,Tensile stress
(sec),(mm),(N),(mm/mm),(mm/mm),(MPa)
0.00000,0.00000,-0.28824,0.00000,0.00000,-0.00358
0.10000,0.00173,2.42270,0.00000,0.00000,0.03008
0.20000,0.00759,7.75617,0.00000,0.00001,0.09630
0.30000,0.01369,12.00698,0.00000,0.00002,0.14908
0.40000,0.01949,14.53447,0.00000,0.00002,0.18046
0.50000,0.02475,17.22407,0.00000,0.00002,0.21385
0.60000,0.03001,18.39936,0.00000,0.00002,0.22845
0.70000,0.03498,18.42765,0.00000,0.00002,0.22880
0.80000,0.04006,19.89743,0.00000,0.00002,0.24705
0.90000,0.04490,21.23329,0.00000,0.00001,0.26363
1.00000,0.05010,21.01593,0.00000,0.00001,0.26093
1.10000,0.05495,22.02832,0.00000,0.00001,0.27350
1.20000,0.06009,23.68975,0.00000,0.00001,0.29413
1.30000,0.06493,23.08937,0.00000,0.00001,0.28668
1.40000,0.07001,24.35484,0.00000,0.00000,0.30239
1.50000,0.07498,24.89575,0.00000,0.00001,0.30911
1.60000,0.08012,25.41357,0.00000,0.00001,0.31554
1.70000,0.08496,26.56065,0.00000,0.00001,0.32978
1.80000,0.09004,27.11396,0.00000,0.00001,0.33665
1.90000,0.09495,28.92991,0.00000,0.00001,0.35919
2.00000,0.10003,31.67641,0.00000,0.00000,0.39330
2.10000,0.10505,35.21789,0.00000,0.00000,0.43727
2.20000,0.11001,37.85836,0.00000,0.00000,0.47005
2.30000,0.11503,41.34810,0.00000,-0.00001,0.51338
2.40000,0.11994,44.15481,0.00000,-0.00001,0.54823
2.50000,0.12502,46.29009,0.00000,-0.00001,0.57474
2.60000,0.12998,50.73879,0.00000,-0.00001,0.62997
2.70000,0.13506,56.14675,0.00000,0.00000,0.69712
2.80000,0.13991,58.45819,0.00000,0.00000,0.72582
2.90000,0.14505,61.74802,0.00000,0.00000,0.76667
3.00000,0.14995,64.06388,0.00000,-0.00001,0.79542
3.10000,0.15515,66.64979,0.00000,0.00000,0.82753
3.20000,0.15994,68.08853,0.00000,-0.00001,0.84539
3.30000,0.16508,70.55406,0.00000,-0.00001,0.87600
3.40000,0.16992,73.93734,0.00000,-0.00001,0.91801
3.50000,0.17506,78.81771,0.00000,-0.00001,0.97860
3.60000,0.17991,85.06826,0.00000,-0.00001,1.05621
3.70000,0.18505,94.29301,0.00000,-0.00001,1.17075
3.80000,0.18995,101.90657,0.00000,-0.00001,1.26528
3.90000,0.19503,112.32834,0.00000,-0.00001,1.39467
4.00000,0.20006,122.98654,0.00000,-0.00001,1.52701
4.10000,0.20502,134.22020,0.00000,-0.00001,1.66648
4.20000,0.20998,146.68008,0.00000,-0.00001,1.82119
4.30000,0.21500,160.84546,0.00000,-0.00001,1.99706
4.40000,0.22003,174.85415,0.00000,-0.00001,2.17100
4.50000,0.22505,191.84506,0.00000,-0.00001,2.38196
4.60000,0.23001,211.54489,0.00000,0.00000,2.62655
4.70000,0.23497,232.25974,0.00000,0.00000,2.88375
4.80000,0.24005,255.80970,0.00000,0.00001,3.17614
4.90000,0.24502,276.91820,0.00000,0.00002,3.43823
5.00000,0.25010,299.71211,0.00000,0.00003,3.72124
5.10000,0.25494,322.05039,0.00000,0.00004,3.99859
5.20000,0.26008,347.23759,0.00000,0.00005,4.31131
5.30000,0.26499,371.77398,0.00000,0.00006,4.61596
5.40000,0.27013,399.55568,0.00000,0.00007,4.96090
5.50000,0.27497,429.68816,0.00000,0.00008,5.33502
5.60000,0.28005,465.46101,0.00000,0.00010,5.77918
5.70000,0.28490,501.17513,0.00000,0.00012,6.22261
5.80000,0.29010,538.51306,0.00000,0.00014,6.68620
5.90000,0.29500,577.53893,0.00000,0.00016,7.17074
6.00000,0.30008,618.77603,0.00000,0.00018,7.68275
6.10000,0.30493,659.58835,0.00000,0.00021,8.18947
6.20000,0.31001,699.71373,0.00000,0.00023,8.68767
6.30000,0.31491,739.57155,0.00000,0.00025,9.18255
6.40000,0.32005,779.34903,0.00000,0.00027,9.67643
6.50000,0.32496,822.08589,0.00000,0.00030,10.20705
6.60000,0.32998,863.71582,0.00000,0.00032,10.72393
6.70000,0.33494,907.14972,0.00000,0.00034,11.26320
6.80000,0.33996,947.87395,0.00000,0.00036,11.76884
6.90000,0.34505,991.65235,0.00000,0.00039,12.31239
7.00000,0.34995,1034.80713,0.00000,0.00042,12.84820
7.10000,0.35503,1081.47701,0.00000,0.00044,13.42766
7.20000,0.35987,1123.75850,0.00000,0.00047,13.95263
7.30000,0.36507,1170.18092,0.00000,0.00049,14.52901
7.40000,0.36992,1212.13561,0.00000,0.00052,15.04992
7.50000,0.37506,1258.82588,0.00000,0.00054,15.62963
7.60000,0.37984,1301.66011,0.00000,0.00057,16.16146
7.70000,0.38504,1347.43713,0.00000,0.00060,16.72983
7.80000,0.38989,1391.14084,0.00000,0.00062,17.27246
7.90000,0.39503,1435.91296,0.00000,0.00065,17.82835
8.00000,0.39987,1481.05873,0.00000,0.00067,18.38888
8.10000,0.40501,1524.88621,0.00000,0.00070,18.93304
8.20000,0.40992,1567.76141,0.00000,0.00072,19.46538
8.30000,0.41506,1611.96031,0.00000,0.00075,20.01416
8.40000,0.41996,1656.36092,0.00000,0.00077,20.56544
8.50000,0.42498,1701.44141,0.00000,0.00080,21.12516
8.60000,0.42995,1745.65762,0.00000,0.00083,21.67415
8.70000,0.43497,1786.45905,0.00000,0.00085,22.18074
8.80000,0.43999,1829.64336,0.00000,0.00088,22.71692
8.90000,0.44501,1872.75931,0.00000,0.00090,23.25225
9.00000,0.44998,1916.69632,0.00000,0.00093,23.79777
9.10000,0.45500,1957.74455,0.00000,0.00095,24.30743
9.20000,0.46002,2001.04546,0.00000,0.00098,24.84505
9.30000,0.46504,2041.36167,0.00000,0.00100,25.34562
9.40000,0.47001,2084.79501,0.00000,0.00103,25.88489
9.50000,0.47497,2123.49277,0.00000,0.00106,26.36536
9.60000,0.47999,2165.16852,0.00000,0.00108,26.88281
9.70000,0.48495,2203.19293,0.00000,0.00110,27.35492
9.80000,0.49009,2246.11405,0.00000,0.00113,27.88783
9.90000,0.49488,2285.58984,0.00000,0.00115,28.37797
10.00000,0.50002,2327.56659,0.00000,0.00117,28.89915
10.10000,0.50486,2364.56878,0.00000,0.00119,29.35857
10.20000,0.51012,2405.05580,0.00000,0.00122,29.86126
10.30000,0.51491,2443.67011,0.00000,0.00124,30.34070
10.40000,0.52005,2485.48742,0.00000,0.00127,30.85990
10.50000,0.52489,2524.51617,0.00000,0.00129,31.34449
10.60000,0.53003,2564.09086,0.00000,0.00132,31.83585
10.70000,0.53494,2602.42708,0.00000,0.00134,32.31183
10.80000,0.54008,2641.43236,0.00000,0.00136,32.79612
10.90000,0.54486,2678.97509,0.00000,0.00138,33.26225
11.00000,0.55000,2717.29734,0.00000,0.00141,33.73806
11.10000,0.55497,2755.73488,0.00000,0.00143,34.21531
11.20000,0.55999,2792.66611,0.00000,0.00145,34.67384
11.30000,0.56495,2831.73770,0.00000,0.00148,35.15896
11.40000,0.56997,2867.97751,0.00000,0.00150,35.60891
11.50000,0.57494,2907.02004,0.00000,0.00152,36.09367
11.60000,0.57996,2941.49593,0.00000,0.00154,36.52172
11.70000,0.58504,2979.01724,0.00000,0.00157,36.98759
11.80000,0.58994,3012.91626,0.00000,0.00159,37.40848
11.90000,0.59503,3050.03673,0.00000,0.00161,37.86937
12.00000,0.59987,3082.79358,0.00000,0.00163,38.27608
12.10000,0.60501,3120.81277,0.00000,0.00165,38.74813
12.20000,0.60985,3153.60501,0.00000,0.00168,39.15528
12.30000,0.61493,3189.51085,0.00000,0.00170,39.60108
12.40000,0.61984,3221.95478,0.00000,0.00172,40.00391
12.50000,0.62504,3257.18857,0.00000,0.00174,40.44137
12.60000,0.62994,3290.29597,0.00000,0.00176,40.85244
12.70000,0.63508,3324.29223,0.00000,0.00178,41.27453
12.80000,0.63993,3357.21560,0.00000,0.00179,41.68331
12.90000,0.64501,3389.05901,0.00000,0.00182,42.07868
13.00000,0.64991,3420.22218,0.00000,0.00184,42.46560
13.10000,0.65505,3453.03044,0.00000,0.00186,42.87295
13.20000,0.65990,3483.26936,0.00000,0.00188,43.24840
13.30000,0.66498,3514.28092,0.00000,0.00189,43.63344
13.40000,0.66988,3545.55622,0.00000,0.00191,44.02176
13.50000,0.67502,3575.63570,0.00000,0.00193,44.39522
13.60000,0.67999,3608.34263,0.00000,0.00195,44.80131
13.70000,0.68507,3636.89996,0.00000,0.00197,45.15588
13.80000,0.68997,3667.10760,0.00000,0.00199,45.53094
13.90000,0.69505,3695.55466,0.00000,0.00201,45.88414
14.00000,0.70008,3725.06641,0.00000,0.00203,46.25056
14.10000,0.70504,3751.55658,0.00000,0.00205,46.57946
14.20000,0.71000,3780.08969,0.00000,0.00206,46.93373
14.30000,0.71496,3803.62421,0.00000,0.00208,47.22594
14.40000,0.72004,3829.26427,0.00000,0.00209,47.54429
14.50000,0.72495,3851.98258,0.00000,0.00211,47.82636
14.60000,0.73009,3879.27294,0.00000,0.00213,48.16519
14.70000,0.73499,3904.83662,0.00000,0.00214,48.48259
14.80000,0.74013,3932.44103,0.00000,0.00216,48.82533
14.90000,0.74498,3957.03390,0.00000,0.00218,49.13068
15.00000,0.75006,3984.30154,0.00000,0.00220,49.46923
15.10000,0.75484,4009.21367,0.00000,0.00221,49.77854
15.20000,0.76004,4037.41449,0.00000,0.00223,50.12869
15.30000,0.76489,4062.51475,0.00000,0.00225,50.44033
15.40000,0.77003,4090.88284,0.00000,0.00226,50.79255
15.50000,0.77493,4116.98408,0.00000,0.00228,51.11662
15.60000,0.78001,4145.31641,0.00000,0.00230,51.46840
15.70000,0.78492,4173.60477,0.00000,0.00232,51.81963
15.80000,0.79000,4200.90221,0.00000,0.00233,52.15856
15.90000,0.79496,4227.97240,0.00000,0.00235,52.49466
16.00000,0.79998,4253.33604,0.00000,0.00237,52.80958
16.10000,0.80495,4281.29584,0.00000,0.00238,53.15673
16.20000,0.80997,4306.57230,0.00000,0.00240,53.47056
16.30000,0.81499,4334.28958,0.00000,0.00242,53.81470
16.40000,0.82001,4359.80633,0.00000,0.00243,54.13151
16.50000,0.82504,4386.51405,0.00000,0.00245,54.46312
16.60000,0.82994,4412.99751,0.00000,0.00247,54.79194
16.70000,0.83502,4439.33755,0.00000,0.00249,55.11898
16.80000,0.83992,4463.42416,0.00000,0.00250,55.41804
16.90000,0.84506,4491.38246,0.00000,0.00252,55.76517
17.00000,0.84991,4514.24234,0.00000,0.00254,56.04900
17.10000,0.85505,4541.38778,0.00000,0.00255,56.38604
17.20000,0.85989,4564.83848,0.00000,0.00257,56.67720
17.30000,0.86509,4592.49876,0.00000,0.00258,57.02063
17.40000,0.86994,4614.02349,0.00000,0.00260,57.28788
17.50000,0.87508,4638.64543,0.00000,0.00261,57.59359
17.60000,0.87986,4660.78706,0.00000,0.00263,57.86850
17.70000,0.88500,4685.76215,0.00000,0.00264,58.17859
17.80000,0.88991,4709.73775,0.00000,0.00266,58.47628
17.90000,0.89505,4733.39483,0.00000,0.00267,58.77000
18.00000,0.89995,4756.81946,0.00000,0.00269,59.06084
18.10000,0.90503,4780.45531,0.00000,0.00271,59.35431
18.20000,0.90994,4804.11686,0.00000,0.00272,59.64809
18.30000,0.91502,4827.03187,0.00000,0.00273,59.93260
18.40000,0.91998,4850.36373,0.00000,0.00275,60.22229
18.50000,0.92500,4872.51915,0.00000,0.00276,60.49738
18.60000,0.92991,4895.88082,0.00000,0.00278,60.78744
18.70000,0.93499,4918.03959,0.00000,0.00279,61.06256
18.80000,0.94001,4942.04201,0.00000,0.00281,61.36057
18.90000,0.94497,4964.87878,0.00000,0.00282,61.64412
19.00000,0.95000,4990.72932,0.00000,0.00284,61.96508
19.10000,0.95490,5012.16017,0.00000,0.00285,62.23116
19.20000,0.96004,5036.95309,0.00000,0.00287,62.53899
19.30000,0.96494,5058.72332,0.00000,0.00288,62.80929
19.40000,0.97002,5082.42324,0.00000,0.00290,63.10355
19.50000,0.97487,5105.46118,0.00000,0.00291,63.38959
19.60000,0.98007,5130.62701,0.00000,0.00293,63.70205
19.70000,0.98491,5152.54475,0.00000,0.00294,63.97418
19.80000,0.99011,5177.87077,0.00000,0.00296,64.28863
19.90000,0.99484,5199.66818,0.00000,0.00298,64.55927
20.00000,1.00004,5224.26553,0.00000,0.00299,64.86467
20.10000,1.00488,5248.18003,0.00000,0.00301,65.16160
20.20000,1.01008,5272.30203,0.00000,0.00303,65.46109
20.30000,1.01493,5296.20200,0.00000,0.00304,65.75784
20.40000,1.02001,5321.30972,0.00000,0.00305,66.06958
20.50000,1.02491,5346.25538,0.00000,0.00307,66.37930
20.60000,1.02999,5369.55707,0.00000,0.00308,66.66862
20.70000,1.03496,5394.14622,0.00000,0.00310,66.97392
20.80000,1.03998,5417.57010,0.00000,0.00312,67.26475
20.90000,1.04494,5443.15800,0.00000,0.00314,67.58245
21.00000,1.04990,5464.69316,0.00000,0.00315,67.84983
21.10000,1.05499,5489.84632,0.00000,0.00317,68.16213
21.20000,1.06001,5512.48342,0.00000,0.00318,68.44320
21.30000,1.06503,5537.74610,0.00000,0.00320,68.75686
21.40000,1.06993,5561.24896,0.00000,0.00322,69.04867
21.50000,1.07502,5587.72199,0.00000,0.00323,69.37736
21.60000,1.07992,5609.84425,0.00000,0.00325,69.65203
21.70000,1.08512,5635.20938,0.00000,0.00326,69.96697
21.80000,1.08996,5657.79880,0.00000,0.00328,70.24744
21.90000,1.09504,5682.62488,0.00000,0.00330,70.55568
22.00000,1.09989,5703.88250,0.00000,0.00331,70.81961
22.10000,1.10509,5729.28861,0.00000,0.00333,71.13506
22.20000,1.10993,5750.64197,0.00000,0.00334,71.40018
22.30000,1.11507,5776.34834,0.00000,0.00336,71.71935
22.40000,1.11992,5800.25166,0.00000,0.00338,72.01614
22.50000,1.12506,5824.67839,0.00000,0.00339,72.31942
22.60000,1.12996,5848.11457,0.00000,0.00341,72.61040
22.70000,1.13504,5873.18353,0.00000,0.00342,72.92166
22.80000,1.13995,5896.36229,0.00000,0.00344,73.20945
22.90000,1.14503,5921.70879,0.00000,0.00346,73.52415
23.00000,1.14993,5945.76336,0.00000,0.00347,73.82282
23.10000,1.15507,5970.09398,0.00000,0.00350,74.12491
23.20000,1.15998,5994.73529,0.00000,0.00351,74.43085
23.30000,1.16500,6019.17282,0.00000,0.00353,74.73427
23.40000,1.16996,6043.44197,0.00000,0.00354,75.03560
23.50000,1.17504,6065.98146,0.00000,0.00356,75.31545
23.60000,1.18007,6091.15586,0.00000,0.00358,75.62801
23.70000,1.18497,6113.86709,0.00000,0.00359,75.91000
23.80000,1.18999,6139.47846,0.00000,0.00361,76.22799
23.90000,1.19489,6162.73396,0.00000,0.00363,76.51673
24.00000,1.20003,6188.72084,0.00000,0.00365,76.83938
24.10000,1.20494,6212.23077,0.00000,0.00366,77.13128
24.20000,1.21008,6238.67735,0.00000,0.00367,77.45965
24.30000,1.21486,6262.41937,0.00000,0.00370,77.75443
24.40000,1.22006,6288.07843,0.00000,0.00371,78.07301
24.50000,1.22491,6311.11786,0.00000,0.00373,78.35907
24.60000,1.23011,6337.31186,0.00000,0.00375,78.68430
24.70000,1.23489,6360.54948,0.00000,0.00376,78.97281
24.80000,1.24003,6386.52667,0.00000,0.00378,79.29535
24.90000,1.24488,6411.45706,0.00000,0.00380,79.60489
25.00000,1.25008,6437.87906,0.00000,0.00381,79.93294
25.10000,1.25492,6461.84981,0.00000,0.00383,80.23056
25.20000,1.25994,6487.41722,0.00000,0.00385,80.54801
25.30000,1.26491,6512.32228,0.00000,0.00387,80.85723
25.40000,1.26999,6535.64930,0.00000,0.00388,81.14686
25.50000,1.27501,6560.67058,0.00000,0.00390,81.45753
25.60000,1.27997,6584.03635,0.00000,0.00392,81.74764
25.70000,1.28500,6611.74506,0.00000,0.00394,82.09167
25.80000,1.28996,6634.57215,0.00000,0.00395,82.37509
25.90000,1.29504,6661.36891,0.00000,0.00397,82.70780
26.00000,1.30000,6683.09927,0.00000,0.00399,82.97760
26.10000,1.30503,6709.75819,0.00000,0.00401,83.30860
26.20000,1.30993,6733.18952,0.00000,0.00402,83.59953
26.30000,1.31507,6760.94517,0.00000,0.00404,83.94414
26.40000,1.31991,6783.53906,0.00000,0.00406,84.22467
26.50000,1.32505,6810.15179,0.00000,0.00407,84.55509
26.60000,1.32990,6834.86536,0.00000,0.00409,84.86194
26.70000,1.33510,6861.40880,0.00000,0.00411,85.19150
26.80000,1.33994,6885.84968,0.00000,0.00413,85.49496
26.90000,1.34514,6910.91418,0.00000,0.00415,85.80616
27.00000,1.34993,6934.09368,0.00000,0.00417,86.09396
27.10000,1.35507,6959.99190,0.00000,0.00418,86.41551
27.20000,1.35991,6983.95446,0.00000,0.00420,86.71303
27.30000,1.36505,7009.77668,0.00000,0.00422,87.03364
27.40000,1.36996,7034.25854,0.00000,0.00423,87.33761
27.50000,1.37504,7059.60914,0.00000,0.00425,87.65237
27.60000,1.37994,7084.29590,0.00000,0.00427,87.95888
27.70000,1.38502,7109.93186,0.00000,0.00429,88.27717
27.80000,1.38999,7135.38229,0.00000,0.00431,88.59317
27.90000,1.39513,7159.82914,0.00000,0.00432,88.89670
28.00000,1.39997,7184.81019,0.00000,0.00435,89.20687
28.10000,1.40499,7209.45671,0.00000,0.00436,89.51288
28.20000,1.40996,7236.58428,0.00000,0.00438,89.84969
28.30000,1.41498,7261.31350,0.00000,0.00440,90.15673
28.40000,1.42000,7287.53582,0.00000,0.00442,90.48231
28.50000,1.42490,7311.40822,0.00000,0.00444,90.77871
28.60000,1.42999,7338.66468,0.00000,0.00446,91.11713
28.70000,1.43489,7361.66462,0.00000,0.00447,91.40270
28.80000,1.44009,7388.48075,0.00000,0.00449,91.73565
28.90000,1.44493,7411.75786,0.00000,0.00451,92.02466
29.00000,1.45007,7439.28477,0.00000,0.00453,92.36643
29.10000,1.45492,7464.13544,0.00000,0.00454,92.67498
29.20000,1.46012,7489.53745,0.00000,0.00457,92.99037
29.30000,1.46490,7513.81069,0.00000,0.00458,93.29175
29.40000,1.47004,7539.88475,0.00000,0.00460,93.61548
29.50000,1.47489,7564.28763,0.00000,0.00462,93.91847
29.60000,1.48003,7591.80561,0.00000,0.00464,94.26014
29.70000,1.48493,7616.36943,0.00000,0.00466,94.56512
29.80000,1.49001,7642.50755,0.00000,0.00468,94.88965
29.90000,1.49492,7667.93713,0.00000,0.00470,95.20539
30.00000,1.50000,7693.96424,0.00000,0.00472,95.52854
30.10000,1.50496,7719.96975,0.00000,0.00474,95.85143
30.20000,1.51004,7746.14215,0.00000,0.00475,96.17638
30.30000,1.51501,7770.99207,0.00000,0.00477,96.48492
30.40000,1.51997,7795.93736,0.00000,0.00479,96.79464
30.50000,1.52499,7822.85407,0.00000,0.00481,97.12884
30.60000,1.53001,7847.94614,0.00000,0.00483,97.44039
30.70000,1.53510,7873.34517,0.00000,0.00485,97.75574
30.80000,1.54000,7897.62512,0.00000,0.00487,98.05720
30.90000,1.54502,7924.52618,0.00000,0.00489,98.39121
31.00000,1.54992,7946.99341,0.00000,0.00491,98.67016
31.10000,1.55506,7974.81239,0.00000,0.00493,99.01556
31.20000,1.55991,7997.48600,0.00000,0.00495,99.29708
31.30000,1.56511,8025.16192,0.00000,0.00497,99.64070
31.40000,1.56989,8049.54916,0.00000,0.00498,99.94350
31.50000,1.57503,8076.60222,0.00000,0.00500,100.27939
31.60000,1.57988,8101.41414,0.00000,0.00502,100.58745
31.70000,1.58514,8128.60131,0.00000,0.00504,100.92501
31.80000,1.58992,8152.38357,0.00000,0.00506,101.22029
31.90000,1.59506,8178.94861,0.00000,0.00508,101.55012
32.00000,1.59991,8203.73595,0.00000,0.00510,101.85789
32.10000,1.60505,8229.53135,0.00000,0.00512,102.17816
32.20000,1.61001,8255.15836,0.00000,0.00514,102.49635
32.30000,1.61503,8280.34505,0.00000,0.00516,102.80907
32.40000,1.61994,8306.14343,0.00000,0.00518,103.12938
32.50000,1.62502,8330.83689,0.00000,0.00520,103.43598
32.60000,1.62998,8357.26336,0.00000,0.00522,103.76409
32.70000,1.63506,8381.74298,0.00000,0.00524,104.06803
32.80000,1.63997,8408.18062,0.00000,0.00526,104.39628
32.90000,1.64499,8433.45821,0.00000,0.00528,104.71013
33.00000,1.65001,8461.29805,0.00000,0.00530,105.05579
33.10000,1.65497,8485.19430,0.00000,0.00532,105.35248
33.20000,1.66006,8512.97155,0.00000,0.00534,105.69737
33.30000,1.66490,8536.31422,0.00000,0.00535,105.98719
33.40000,1.67004,8564.65697,0.00000,0.00538,106.33909
33.50000,1.67494,8588.43848,0.00000,0.00540,106.63437
33.60000,1.68008,8615.68898,0.00000,0.00542,106.97271
33.70000,1.68493,8639.73424,0.00000,0.00544,107.27126
33.80000,1.69007,8668.53967,0.00000,0.00546,107.62891
33.90000,1.69485,8693.69209,0.00000,0.00548,107.94120
34.00000,1.70005,8720.04852,0.00000,0.00550,108.26844
34.10000,1.70490,8744.80307,0.00000,0.00552,108.57579
34.20000,1.70998,8769.90184,0.00000,0.00554,108.88742
34.30000,1.71488,8795.37463,0.00000,0.00556,109.20369
34.40000,1.72002,8821.65730,0.00000,0.00558,109.53002
34.50000,1.72493,8846.03113,0.00000,0.00560,109.83265
34.60000,1.73007,8872.24823,0.00000,0.00562,110.15816
34.70000,1.73491,8898.55251,0.00000,0.00564,110.48475
34.80000,1.73999,8925.50722,0.00000,0.00566,110.81942
34.90000,1.74496,8952.02160,0.00000,0.00568,111.14863
35.00000,1.74998,8977.14719,0.00000,0.00570,111.46059
35.10000,1.75500,9002.32419,0.00000,0.00572,111.77319
35.20000,1.76002,9028.16206,0.00000,0.00574,112.09399
35.30000,1.76493,9055.37531,0.00000,0.00576,112.43187
35.40000,1.77001,9080.23641,0.00000,0.00577,112.74055
35.50000,1.77509,9108.93455,0.00000,0.00580,113.09686
35.60000,1.78005,9131.39209,0.00000,0.00582,113.37570
35.70000,1.78508,9158.72678,0.00000,0.00584,113.71509
35.80000,1.78998,9182.11192,0.00000,0.00586,114.00544
35.90000,1.79506,9207.79184,0.00000,0.00588,114.32428
36.00000,1.79996,9232.39738,0.00000,0.00590,114.62978
36.10000,1.80510,9260.19326,0.00000,0.00592,114.97490
36.20000,1.80995,9284.66693,0.00000,0.00594,115.27876
36.30000,1.81509,9312.35403,0.00000,0.00596,115.62253
36.40000,1.81993,9335.99919,0.00000,0.00598,115.91611
36.50000,1.82513,9363.10291,0.00000,0.00600,116.25263
36.60000,1.82998,9387.32848,0.00000,0.00602,116.55341
36.70000,1.83506,9413.83764,0.00000,0.00604,116.88255
36.80000,1.83990,9438.83061,0.00000,0.00606,117.19287
36.90000,1.84504,9465.30998,0.00000,0.00608,117.52163
37.00000,1.84995,9490.24260,0.00000,0.00610,117.83120
37.10000,1.85503,9517.65478,0.00000,0.00612,118.17155
37.20000,1.85993,9544.42099,0.00000,0.00614,118.50388
37.30000,1.86501,9570.14859,0.00000,0.00617,118.82331
37.40000,1.86998,9597.08691,0.00000,0.00619,119.15778
37.50000,1.87500,9620.46236,0.00000,0.00621,119.44801
37.60000,1.87996,9648.14350,0.00000,0.00623,119.79170
37.70000,1.88504,9672.85037,0.00000,0.00625,120.09846
37.80000,1.89001,9699.54431,0.00000,0.00627,120.42990
37.90000,1.89497,9724.33984,0.00000,0.00629,120.73776
38.00000,1.89999,9750.39452,0.00000,0.00632,121.06125
38.10000,1.90483,9774.61860,0.00000,0.00633,121.36202
38.20000,1.91004,9803.47544,0.00000,0.00636,121.72031
38.30000,1.91488,9826.51636,0.00000,0.00637,122.00639
38.40000,1.92008,9855.38736,0.00000,0.00640,122.36485
38.50000,1.92486,9879.11224,0.00000,0.00642,122.65942
38.60000,1.93000,9907.98771,0.00000,0.00644,123.01794
38.70000,1.93485,9934.00142,0.00000,0.00647,123.34092
38.80000,1.94011,9960.78551,0.00000,0.00648,123.67348
38.90000,1.94489,9984.37703,0.00000,0.00651,123.96639
39.00000,1.95003,10011.32280,0.00000,0.00652,124.30095
39.10000,1.95488,10036.39475,0.00000,0.00655,124.61224
39.20000,1.96002,10063.28836,0.00000,0.00657,124.94616
39.30000,1.96498,10088.18075,0.00000,0.00659,125.25522
39.40000,1.97000,10113.27058,0.00000,0.00661,125.56674
39.50000,1.97491,10140.65668,0.00000,0.00663,125.90676
39.60000,1.97999,10167.15541,0.00000,0.00666,126.23577
39.70000,1.98495,10193.18923,0.00000,0.00668,126.55901
39.80000,1.99003,10217.04674,0.00000,0.00670,126.85523
39.90000,1.99500,10243.14091,0.00000,0.00672,127.17921
40.00000,2.00002,10268.10780,0.00000,0.00674,127.48920
40.10000,2.00504,10296.05493,0.00000,0.00677,127.83619
40.20000,2.01006,10320.28571,0.00000,0.00678,128.13704
40.30000,2.01509,10346.68013,0.00000,0.00680,128.46476
40.40000,2.01999,10371.01820,0.00000,0.00683,128.76694
40.50000,2.02501,10399.71411,0.00000,0.00685,129.12323
40.60000,2.02997,10423.63718,0.00000,0.00687,129.42026
40.70000,2.03505,10451.27138,0.00000,0.00689,129.76337
40.80000,2.03996,10476.12131,0.00000,0.00691,130.07191
40.90000,2.04510,10502.20653,0.00000,0.00693,130.39578
41.00000,2.04994,10527.51392,0.00000,0.00695,130.71000
41.10000,2.05508,10555.87456,0.00000,0.00697,131.06212
41.20000,2.05999,10580.72224,0.00000,0.00699,131.37063
41.30000,2.06513,10606.65697,0.00000,0.00702,131.69264
41.40000,2.06991,10629.98697,0.00000,0.00704,131.98231
41.50000,2.07505,10658.18518,0.00000,0.00706,132.33242
41.60000,2.07990,10682.54113,0.00000,0.00708,132.63482
41.70000,2.08504,10709.46679,0.00000,0.00710,132.96913
41.80000,2.08994,10735.92901,0.00000,0.00712,133.29769
41.90000,2.09496,10762.16474,0.00000,0.00714,133.62343
42.00000,2.09993,10788.51745,0.00000,0.00717,133.95063
42.10000,2.10501,10814.16681,0.00000,0.00719,134.26909
42.20000,2.10997,10841.52684,0.00000,0.00721,134.60879
42.30000,2.11505,10866.36186,0.00000,0.00723,134.91715
42.40000,2.11996,10893.84258,0.00000,0.00725,135.25835
42.50000,2.12498,10919.64319,0.00000,0.00727,135.57869
42.60000,2.13000,10947.75721,0.00000,0.00730,135.92775
42.70000,2.13496,10972.38213,0.00000,0.00732,136.23350
42.80000,2.13999,11000.04241,0.00000,0.00734,136.57693
42.90000,2.14489,11023.87682,0.00000,0.00736,136.87286
43.00000,2.15003,11051.20853,0.00000,0.00739,137.21221
43.10000,2.15493,11076.76998,0.00000,0.00740,137.52958
43.20000,2.16013,11104.03836,0.00000,0.00743,137.86815
43.30000,2.16492,11128.25200,0.00000,0.00745,138.16878
43.40000,2.17006,11155.77742,0.00000,0.00747,138.51054
43.50000,2.17490,11181.30460,0.00000,0.00749,138.82749
43.60000,2.18010,11207.41740,0.00000,0.00751,139.15170
43.70000,2.18495,11232.44837,0.00000,0.00754,139.46249
43.80000,2.19003,11259.06929,0.00000,0.00756,139.79302
43.90000,2.19487,11283.35074,0.00000,0.00758,140.09450
44.00000,2.20001,11310.57665,0.00000,0.00761,140.43253
44.10000,2.20492,11336.01218,0.00000,0.00763,140.74834
44.20000,2.21006,11363.48471,0.00000,0.00765,141.08944
44.30000,2.21496,11389.17580,0.00000,0.00767,141.40842
44.40000,2.21998,11414.98461,0.00000,0.00769,141.72887
44.50000,2.22501,11441.21736,0.00000,0.00772,142.05457
44.60000,2.23003,11465.96223,0.00000,0.00774,142.36181
44.70000,2.23499,11492.31941,0.00000,0.00776,142.68906
44.80000,2.24001,11517.30344,0.00000,0.00778,142.99926
44.90000,2.24504,11544.52115,0.00000,0.00780,143.33720
45.00000,2.25000,11568.28031,0.00000,0.00782,143.63219
45.10000,2.25502,11596.38092,0.00000,0.00785,143.98109
45.20000,2.25998,11619.45537,0.00000,0.00787,144.26758
45.30000,2.26506,11648.25857,0.00000,0.00789,144.62520
45.40000,2.26997,11671.64519,0.00000,0.00791,144.91557
45.50000,2.27505,11698.94934,0.00000,0.00794,145.25458
45.60000,2.27995,11722.90370,0.00000,0.00796,145.55200
45.70000,2.28503,11751.31276,0.00000,0.00798,145.90473
45.80000,2.28982,11776.95915,0.00000,0.00800,146.22316
45.90000,2.29508,11805.85474,0.00000,0.00803,146.58192
46.00000,2.29986,11829.36877,0.00000,0.00805,146.87388
46.10000,2.30506,11857.58039,0.00000,0.00807,147.22415
46.20000,2.30985,11881.40363,0.00000,0.00809,147.51994
46.30000,2.31499,11908.68840,0.00000,0.00812,147.85871
46.40000,2.31989,11934.03229,0.00000,0.00814,148.17338
46.50000,2.32509,11960.58989,0.00000,0.00816,148.50312
46.60000,2.32994,11986.38529,0.00000,0.00818,148.82340
46.70000,2.33502,12012.63890,0.00000,0.00820,149.14936
46.80000,2.33992,12039.17786,0.00000,0.00823,149.47887
46.90000,2.34500,12064.31687,0.00000,0.00825,149.79100
47.00000,2.34997,12091.34087,0.00000,0.00827,150.12653
47.10000,2.35493,12115.48895,0.00000,0.00829,150.42635
47.20000,2.35995,12143.32134,0.00000,0.00832,150.77192
47.30000,2.36491,12167.56329,0.00000,0.00834,151.07291
47.40000,2.37000,12195.92765,0.00000,0.00836,151.42508
47.50000,2.37496,12220.59131,0.00000,0.00839,151.73131
47.60000,2.37998,12248.20986,0.00000,0.00841,152.07422
47.70000,2.38488,12273.73704,0.00000,0.00843,152.39117
47.80000,2.39003,12301.01287,0.00000,0.00845,152.72983
47.90000,2.39493,12326.24650,0.00000,0.00848,153.04313
48.00000,2.40007,12353.82482,0.00000,0.00850,153.38554
48.10000,2.40491,12380.10973,0.00000,0.00852,153.71189
48.20000,2.41005,12406.92064,0.00000,0.00855,154.04478
48.30000,2.41490,12431.56642,0.00000,0.00857,154.35078
48.40000,2.42010,12459.15219,0.00000,0.00859,154.69329
48.50000,2.42494,12482.32797,0.00000,0.00862,154.98104
48.60000,2.43002,12507.97361,0.00000,0.00864,155.29946
48.70000,2.43493,12534.18326,0.00000,0.00866,155.62488
48.80000,2.44007,12560.31245,0.00000,0.00868,155.94930
48.90000,2.44497,12586.30306,0.00000,0.00870,156.27200
49.00000,2.45005,12612.05822,0.00000,0.00873,156.59178
49.10000,2.45496,12640.33467,0.00000,0.00875,156.94286
49.20000,2.46004,12667.18358,0.00000,0.00877,157.27621
49.30000,2.46494,12691.80626,0.00000,0.00879,157.58193
49.40000,2.47002,12716.87150,0.00000,0.00882,157.89314
49.50000,2.47493,12742.86807,0.00000,0.00884,158.21592
49.60000,2.47995,12768.76032,0.00000,0.00886,158.53739
49.70000,2.48503,12796.11737,0.00000,0.00888,158.87706
49.80000,2.49005,12821.00230,0.00000,0.00891,159.18603
49.90000,2.49508,12848.59926,0.00000,0.00893,159.52868
50.00000,2.49992,12873.12806,0.00000,0.00895,159.83323
50.10000,2.50500,12901.32999,0.00000,0.00898,160.18338
50.20000,2.50990,12925.39388,0.00000,0.00900,160.48216
50.30000,2.51510,12953.82977,0.00000,0.00902,160.83522
50.40000,2.51989,12977.29164,0.00000,0.00904,161.12653
50.50000,2.52503,13005.94658,0.00000,0.00907,161.48231
50.60000,2.52987,13031.56614,0.00000,0.00909,161.80040
50.70000,2.53507,13057.76685,0.00000,0.00912,162.12571
50.80000,2.53992,13082.90660,0.00000,0.00914,162.43785
50.90000,2.54506,13109.12371,0.00000,0.00916,162.76336
51.00000,2.54990,13133.86261,0.00000,0.00918,163.07052
51.10000,2.55498,13162.45794,0.00000,0.00921,163.42556
51.20000,2.55989,13188.11774,0.00000,0.00923,163.74415
51.30000,2.56503,13214.82509,0.00000,0.00925,164.07575
51.40000,2.56987,13241.20909,0.00000,0.00927,164.40334
51.50000,2.57495,13267.51411,0.00000,0.00930,164.72994
51.60000,2.57992,13294.90989,0.00000,0.00932,165.07009
51.70000,2.58500,13320.04815,0.00000,0.00934,165.38220
51.80000,2.59002,13344.99419,0.00000,0.00937,165.69194
51.90000,2.59498,13369.30096,0.00000,0.00939,165.99373
52.00000,2.60001,13396.70420,0.00000,0.00941,166.33397
52.10000,2.60503,13421.28366,0.00000,0.00944,166.63915
52.20000,2.61005,13449.18907,0.00000,0.00946,166.98562
52.30000,2.61495,13471.90440,0.00000,0.00948,167.26766
52.40000,2.62004,13501.33419,0.00000,0.00951,167.63306
52.50000,2.62494,13524.86908,0.00000,0.00953,167.92527
52.60000,2.63008,13552.71488,0.00000,0.00955,168.27100
52.70000,2.63504,13576.74450,0.00000,0.00957,168.56936
52.80000,2.64012,13603.72901,0.00000,0.00960,168.90440
52.90000,2.64491,13628.57223,0.00000,0.00962,169.21285
53.00000,2.65005,13655.34067,0.00000,0.00965,169.54521
53.10000,2.65495,13681.38492,0.00000,0.00967,169.86858
53.20000,2.66009,13707.37702,0.00000,0.00971,170.19129
53.30000,2.66494,13731.62866,0.00000,0.00974,170.49240
53.40000,2.67002,13758.45671,0.00000,0.00976,170.82550
53.50000,2.67492,13784.01965,0.00000,0.00978,171.14289
53.60000,2.68006,13809.90893,0.00000,0.00981,171.46433
53.70000,2.68497,13836.45087,0.00000,0.00983,171.79388
53.80000,2.69005,13862.77676,0.00000,0.00985,172.12074
53.90000,2.69489,13889.08625,0.00000,0.00987,172.44740
54.00000,2.69997,13914.25729,0.00000,0.00990,172.75993
54.10000,2.70500,13940.60105,0.00000,0.00992,173.08701
54.20000,2.71008,13964.73199,0.00000,0.00994,173.38662
54.30000,2.71498,13991.21732,0.00000,0.00997,173.71547
54.40000,2.72000,14017.16322,0.00000,0.00999,174.03761
54.50000,2.72503,14045.26234,0.00000,0.01001,174.38649
54.60000,2.72999,14069.96101,0.00000,0.01003,174.69315
54.70000,2.73501,14096.95745,0.00000,0.01006,175.02834
54.80000,2.73985,14121.66655,0.00000,0.01008,175.33513
54.90000,2.74500,14149.94597,0.00000,0.01010,175.68625
55.00000,2.74990,14173.03085,0.00000,0.01012,175.97287
55.10000,2.75510,14201.58595,0.00000,0.01015,176.32741
55.20000,2.75994,14224.94352,0.00000,0.01017,176.61742
55.30000,2.76502,14253.01433,0.00000,0.01020,176.96595
55.40000,2.76993,14278.42975,0.00000,0.01022,177.28151
55.50000,2.77507,14304.69751,0.00000,0.01024,177.60765
55.60000,2.77997,14330.08760,0.00000,0.01026,177.92289
55.70000,2.78505,14356.54610,0.00000,0.01029,178.25140
55.80000,2.78984,14380.62340,0.00000,0.01031,178.55035
55.90000,2.79498,14406.82113,0.00000,0.01033,178.87562
56.00000,2.79994,14433.11125,0.00000,0.01036,179.20204
56.10000,2.80502,14459.20914,0.00000,0.01038,179.52607
56.20000,2.80993,14485.76599,0.00000,0.01040,179.85580
56.30000,2.81495,14510.60176,0.00000,0.01043,180.16416
56.40000,2.81991,14537.95284,0.00000,0.01045,180.50375
56.50000,2.82505,14563.06279,0.00000,0.01048,180.81552
56.60000,2.83002,14590.00707,0.00000,0.01050,181.15006
56.70000,2.83498,14614.13801,0.00000,0.01052,181.44967
56.80000,2.84000,14641.54422,0.00000,0.01055,181.78995
56.90000,2.84490,14666.13561,0.00000,0.01057,182.09528
57.00000,2.84999,14693.79365,0.00000,0.01059,182.43868
57.10000,2.85495,14717.93056,0.00000,0.01062,182.73836
57.20000,2.86003,14744.70943,0.00000,0.01064,183.07085
57.30000,2.86493,14768.48722,0.00000,0.01066,183.36608
57.40000,2.87007,14795.73846,0.00000,0.01069,183.70443
57.50000,2.87498,14818.89486,0.00000,0.01071,183.99194
57.60000,2.88012,14845.61116,0.00000,0.01073,184.32365
57.70000,2.88490,14871.29182,0.00000,0.01076,184.64250
57.80000,2.89004,14899.52654,0.00000,0.01078,184.99307
57.90000,2.89489,14923.72900,0.00000,0.01080,185.29356
58.00000,2.90009,14950.47212,0.00000,0.01082,185.62561
58.10000,2.90487,14974.76697,0.00000,0.01085,185.92725
58.20000,2.91001,15001.58906,0.00000,0.01087,186.26028
58.30000,2.91492,15027.16988,0.00000,0.01090,186.57789
58.40000,2.92006,15053.93535,0.00000,0.01092,186.91021
58.50000,2.92502,15081.05546,0.00000,0.01094,187.24694
58.60000,2.93004,15107.17124,0.00000,0.01097,187.57119
58.70000,2.93495,15133.43304,0.00000,0.01099,187.89726
58.80000,2.94003,15159.58756,0.00000,0.01101,188.22199
58.90000,2.94499,15185.71675,0.00000,0.01104,188.54641
59.00000,2.95007,15209.81491,0.00000,0.01106,188.84562
59.10000,2.95498,15235.79061,0.00000,0.01109,189.16813
59.20000,2.95994,15260.94675,0.00000,0.01111,189.48047
59.30000,2.96502,15289.69556,0.00000,0.01113,189.83742
59.40000,2.96998,15312.31403,0.00000,0.01115,190.11825
59.50000,2.97507,15340.34759,0.00000,0.01118,190.46632
59.60000,2.97997,15363.93762,0.00000,0.01120,190.75921
59.70000,2.98505,15391.81918,0.00000,0.01122,191.10539
59.80000,2.98995,15415.85028,0.00000,0.01125,191.40376
59.90000,2.99509,15444.19825,0.00000,0.01127,191.75573
60.00000,2.99988,15467.54986,0.00000,0.01130,192.04566
60.10000,3.00502,15496.88429,0.00000,0.01132,192.40988
60.20000,3.00980,15522.28630,0.00000,0.01134,192.72527
60.30000,3.01506,15548.81334,0.00000,0.01137,193.05463
60.40000,3.01991,15574.41205,0.00000,0.01139,193.37247
60.50000,3.02499,15599.74998,0.00000,0.01142,193.68707
60.60000,3.02989,15625.26375,0.00000,0.01144,194.00385
60.70000,3.03503,15652.12905,0.00000,0.01146,194.33741
60.80000,3.04000,15678.79468,0.00000,0.01149,194.66849
60.90000,3.04508,15704.66012,0.00000,0.01151,194.98963
61.00000,3.04998,15731.55373,0.00000,0.01154,195.32355
61.10000,3.05500,15756.01995,0.00000,0.01156,195.62732
61.20000,3.06003,15783.02681,0.00000,0.01159,195.96264
61.30000,3.06505,15807.74635,0.00000,0.01160,196.26956
61.40000,3.07001,15833.64755,0.00000,0.01163,196.59115
61.50000,3.07497,15858.30152,0.00000,0.01165,196.89725
61.60000,3.08000,15885.08636,0.00000,0.01168,197.22981
61.70000,3.08496,15910.25889,0.00000,0.01170,197.54236
61.80000,3.09010,15938.39377,0.00000,0.01172,197.89168
61.90000,3.09500,15962.49044,0.00000,0.01175,198.19086
62.00000,3.10009,15990.85480,0.00000,0.01177,198.54304
62.10000,3.10499,16015.54602,0.00000,0.01180,198.84960
62.20000,3.11007,16041.98813,0.00000,0.01182,199.17791
62.30000,3.11503,16066.32769,0.00000,0.01185,199.48011
62.40000,3.12011,16093.91719,0.00000,0.01187,199.82266
62.50000,3.12490,16118.51156,0.00000,0.01190,200.12803
62.60000,3.13010,16145.86711,0.00000,0.01192,200.46768
62.70000,3.13494,16169.46459,0.00000,0.01194,200.76066
62.80000,3.14014,16196.21217,0.00000,0.01197,201.09276
62.90000,3.14493,16220.44891,0.00000,0.01199,201.39369
63.00000,3.15007,16248.93844,0.00000,0.01202,201.74741
63.10000,3.15497,16274.20038,0.00000,0.01204,202.06107
63.20000,3.16011,16300.25208,0.00000,0.01206,202.38453
63.30000,3.16496,16326.48557,0.00000,0.01208,202.71024
63.40000,3.17004,16352.42552,0.00000,0.01211,203.03231
63.50000,3.17494,16379.28039,0.00000,0.01213,203.36574
63.60000,3.18002,16404.53786,0.00000,0.01216,203.67934
63.70000,3.18499,16429.81172,0.00000,0.01218,203.99314
63.80000,3.18995,16453.44645,0.00000,0.01220,204.28659
63.90000,3.19497,16481.38911,0.00000,0.01223,204.63353
64.00000,3.19999,16507.93254,0.00000,0.01225,204.96309
64.10000,3.20502,16536.06743,0.00000,0.01227,205.31242
64.20000,3.21004,16561.57374,0.00000,0.01230,205.62910
64.30000,3.21506,16587.26931,0.00000,0.01233,205.94814
64.40000,3.21990,16611.06050,0.00000,0.01235,206.24353
64.50000,3.22510,16638.66341,0.00000,0.01237,206.58625
64.60000,3.22995,16662.50229,0.00000,0.01240,206.88224
64.70000,3.23509,16688.35878,0.00000,0.01242,207.20327
64.80000,3.23987,16711.52264,0.00000,0.01244,207.49088
64.90000,3.24501,16739.56811,0.00000,0.01247,207.83909
65.00000,3.24986,16763.02105,0.00000,0.01249,208.13028
65.10000,3.25506,16790.94285,0.00000,0.01252,208.47696
65.20000,3.25990,16815.30029,0.00000,0.01254,208.77938
65.30000,3.26504,16842.27586,0.00000,0.01257,209.11431
65.40000,3.26989,16867.09374,0.00000,0.01259,209.42245
65.50000,3.27503,16892.88318,0.00000,0.01261,209.74266
65.60000,3.27999,16919.95412,0.00000,0.01264,210.07877
65.70000,3.28501,16945.27566,0.00000,0.01266,210.39316
65.80000,3.28992,16971.50916,0.00000,0.01269,210.71888
65.90000,3.29500,16995.54771,0.00000,0.01271,211.01734
66.00000,3.29996,17021.55620,0.00000,0.01273,211.34026
66.10000,3.30504,17045.69161,0.00000,0.01276,211.63993
66.20000,3.31007,17072.56138,0.00000,0.01278,211.97355
66.30000,3.31503,17096.23039,0.00000,0.01281,212.26742
66.40000,3.32005,17125.08947,0.00000,0.01284,212.62574
66.50000,3.32501,17148.49323,0.00000,0.01286,212.91632
66.60000,3.33010,17177.09750,0.00000,0.01288,213.27147
66.70000,3.33500,17199.59229,0.00000,0.01290,213.55077
66.80000,3.34002,17227.12219,0.00000,0.01293,213.89258
66.90000,3.34492,17250.84931,0.00000,0.01295,214.18718
67.00000,3.35007,17277.84872,0.00000,0.01298,214.52240
67.10000,3.35497,17301.85300,0.00000,0.01300,214.82044
67.20000,3.36011,17329.15491,0.00000,0.01303,215.15942
67.30000,3.36495,17354.83408,0.00000,0.01305,215.47825
67.40000,3.37009,17383.25655,0.00000,0.01308,215.83115
67.50000,3.37500,17408.34117,0.00000,0.01310,216.14260
67.60000,3.38008,17433.83408,0.00000,0.01312,216.45912
67.70000,3.38486,17457.77130,0.00000,0.01315,216.75633
67.80000,3.39006,17485.08066,0.00000,0.01317,217.09540
67.90000,3.39491,17510.59443,0.00000,0.01320,217.41218
68.00000,3.40011,17536.67444,0.00000,0.01322,217.73599
68.10000,3.40501,17562.40427,0.00000,0.01324,218.05545
68.20000,3.40997,17586.69615,0.00000,0.01327,218.35706
68.30000,3.41494,17613.50930,0.00000,0.01329,218.68998
68.40000,3.42002,17637.09635,0.00000,0.01332,218.98283
68.50000,3.42504,17663.48332,0.00000,0.01334,219.31045
68.60000,3.43000,17688.06875,0.00000,0.01336,219.61571
68.70000,3.43497,17715.33489,0.00000,0.01339,219.95425
68.80000,3.43993,17740.01718,0.00000,0.01341,220.26070
68.90000,3.44501,17767.39210,0.00000,0.01344,220.60059
69.00000,3.44991,17791.68546,0.00000,0.01347,220.90222
69.10000,3.45500,17818.76981,0.00000,0.01349,221.23850
69.20000,3.45990,17842.54313,0.00000,0.01351,221.53367
69.30000,3.46498,17869.11041,0.00000,0.01354,221.86353
69.40000,3.46988,17892.95822,0.00000,0.01356,222.15962
69.50000,3.47508,17919.74455,0.00000,0.01359,222.49220
69.60000,3.47987,17944.23461,0.00000,0.01361,222.79627
69.70000,3.48501,17971.21167,0.00000,0.01364,223.13122
69.80000,3.48985,17996.02658,0.00000,0.01366,223.43932
69.90000,3.49505,18022.17811,0.00000,0.01369,223.76402
70.00000,3.49996,18046.81420,0.00000,0.01371,224.06990
70.10000,3.50498,18072.17449,0.00000,0.01373,224.38478
70.20000,3.50988,18097.52584,0.00000,0.01376,224.69954
70.30000,3.51502,18123.15583,0.00000,0.01378,225.01777
70.40000,3.51999,18148.67556,0.00000,0.01381,225.33462
70.50000,3.52501,18174.35920,0.00000,0.01383,225.65351
70.60000,3.52991,18200.51521,0.00000,0.01386,225.97826
70.70000,3.53499,18226.83513,0.00000,0.01389,226.30505
70.80000,3.54002,18253.40986,0.00000,0.01391,226.63500
70.90000,3.54504,18277.53633,0.00000,0.01393,226.93456
71.00000,3.55000,18302.91748,0.00000,0.01397,227.24969
71.10000,3.55496,18327.57592,0.00000,0.01399,227.55585
71.20000,3.55999,18355.47090,0.00000,0.01401,227.90220
71.30000,3.56501,18379.48263,0.00000,0.01403,228.20033
71.40000,3.57009,18406.86053,0.00000,0.01406,228.54025
71.50000,3.57493,18430.19128,0.00000,0.01408,228.82993
71.60000,3.58007,18457.83144,0.00000,0.01411,229.17311
71.70000,3.58498,18481.42743,0.00000,0.01413,229.46608
71.80000,3.59006,18507.90828,0.00000,0.01416,229.79487
71.90000,3.59490,18530.89780,0.00000,0.01418,230.08030
72.00000,3.60004,18558.63184,0.00000,0.01421,230.42465
72.10000,3.60483,18583.90123,0.00000,0.01423,230.73840
72.20000,3.61003,18610.78888,0.00000,0.01426,231.07224
72.30000,3.61487,18635.52034,0.00000,0.01428,231.37930
72.40000,3.62001,18662.34094,0.00000,0.01431,231.71231
72.50000,3.62486,18685.71639,0.00000,0.01433,232.00254
72.60000,3.63000,18713.57560,0.00000,0.01436,232.34844
72.70000,3.63490,18738.93887,0.00000,0.01438,232.66335
72.80000,3.64010,18764.75811,0.00000,0.01441,232.98392
72.90000,3.64495,18791.26281,0.00000,0.01443,233.31301
73.00000,3.65003,18817.04628,0.00000,0.01446,233.63313
73.10000,3.65493,18843.33342,0.00000,0.01448,233.95952
73.20000,3.66001,18868.17068,0.00000,0.01451,234.26790
73.30000,3.66504,18893.55034,0.00000,0.01453,234.58301
73.40000,3.66994,18916.10622,0.00000,0.01456,234.86307
73.50000,3.67496,18942.29501,0.00000,0.01458,235.18823
73.60000,3.67992,18966.77762,0.00000,0.01461,235.49220
73.70000,3.68501,18992.72501,0.00000,0.01463,235.81437
73.80000,3.68991,19015.67876,0.00000,0.01465,236.09936
73.90000,3.69505,19044.85971,0.00000,0.01468,236.46167
74.00000,3.69989,19069.06217,0.00000,0.01471,236.76217
74.10000,3.70509,19096.75002,0.00000,0.01473,237.10595
74.20000,3.70994,19120.75728,0.00000,0.01476,237.40402
74.30000,3.71508,19145.44553,0.00000,0.01478,237.71055
74.40000,3.71992,19170.18741,0.00000,0.01480,238.01775
74.50000,3.72501,19196.83069,0.00000,0.01483,238.34855
74.60000,3.72991,19221.84974,0.00000,0.01486,238.65919
74.70000,3.73505,19247.37245,0.00000,0.01488,238.97608
74.80000,3.73995,19271.07722,0.00000,0.01490,239.27040
74.90000,3.74503,19297.24962,0.00000,0.01493,239.59536
75.00000,3.75000,19322.10624,0.00000,0.01496,239.90398
75.10000,3.75508,19348.01489,0.00000,0.01498,240.22566
75.20000,3.76004,19371.86867,0.00000,0.01500,240.52183
75.30000,3.76500,19396.74914,0.00000,0.01503,240.83075
75.40000,3.76991,19421.52679,0.00000,0.01505,241.13839
75.50000,3.77505,19447.82138,0.00000,0.01508,241.46486
75.60000,3.78001,19473.03414,0.00000,0.01510,241.77790
75.70000,3.78509,19497.34539,0.00000,0.01512,242.07975
75.80000,3.78994,19521.99191,0.00000,0.01515,242.38577
75.90000,3.79490,19546.00513,0.00000,0.01518,242.68391
76.00000,3.79998,19574.00292,0.00000,0.01520,243.03154
76.10000,3.80500,19598.44977,0.00000,0.01522,243.33507
76.20000,3.81009,19626.02288,0.00000,0.01525,243.67742
76.30000,3.81493,19649.61588,0.00000,0.01527,243.97035
76.40000,3.82001,19677.74481,0.00000,0.01530,244.31960
76.50000,3.82491,19700.61958,0.00000,0.01532,244.60361
76.60000,3.83012,19727.68903,0.00000,0.01535,244.93971
76.70000,3.83490,19749.56095,0.00000,0.01537,245.21127
76.80000,3.84004,19776.10439,0.00000,0.01540,245.54083
76.90000,3.84488,19800.22341,0.00000,0.01543,245.84030
77.00000,3.85008,19825.87874,0.00000,0.01545,246.15884
77.10000,3.85493,19850.80391,0.00000,0.01547,246.46831
77.20000,3.86007,19877.12979,0.00000,0.01550,246.79517
77.30000,3.86491,19900.98953,0.00000,0.01553,247.09141
77.40000,3.86999,19926.64486,0.00000,0.01555,247.40995
77.50000,3.87496,19951.95895,0.00000,0.01557,247.72425
77.60000,3.88004,19977.78416,0.00000,0.01560,248.04490
77.70000,3.88494,20002.28614,0.00000,0.01563,248.34912
77.80000,3.88996,20026.21591,0.00000,0.01565,248.64623
77.90000,3.89493,20053.02757,0.00000,0.01568,248.97912
78.00000,3.90001,20077.30752,0.00000,0.01570,249.28058
78.10000,3.90497,20102.53072,0.00000,0.01573,249.59376
78.20000,3.90993,20126.10734,0.00000,0.01575,249.88648
78.30000,3.91496,20152.14860,0.00000,0.01578,250.20981
78.40000,3.91998,20175.71628,0.00000,0.01580,250.50243
78.50000,3.92512,20202.47281,0.00000,0.01583,250.83464
78.60000,3.92996,20224.90799,0.00000,0.01585,251.11320
78.70000,3.93511,20251.64962,0.00000,0.01588,251.44522
78.80000,3.93995,20274.75238,0.00000,0.01590,251.73207
78.90000,3.94503,20301.12147,0.00000,0.01593,252.05947
79.00000,3.94993,20323.53431,0.00000,0.01595,252.33774
79.10000,3.95507,20348.56379,0.00000,0.01598,252.64851
79.20000,3.95986,20371.33127,0.00000,0.01600,252.93119
79.30000,3.96500,20396.67219,0.00000,0.01603,253.24583
79.40000,3.96990,20421.65846,0.00000,0.01605,253.55606
79.50000,3.97510,20448.76665,0.00000,0.01608,253.89263
79.60000,3.97995,20472.22555,0.00000,0.01611,254.18390
79.70000,3.98497,20497.45768,0.00000,0.01613,254.49718
79.80000,3.98993,20521.84790,0.00000,0.01616,254.80001
79.90000,3.99501,20546.69559,0.00000,0.01618,255.10852
80.00000,3.99998,20571.37489,0.00000,0.01620,255.41494
80.10000,4.00500,20595.10946,0.00000,0.01623,255.70963
80.20000,4.00990,20619.38196,0.00000,0.01626,256.01100
80.30000,4.01504,20644.95236,0.00000,0.01629,256.32848
80.40000,4.02001,20670.76862,0.00000,0.01631,256.64902
80.50000,4.02509,20694.29606,0.00000,0.01634,256.94114
80.60000,4.03005,20719.42836,0.00000,0.01637,257.25318
80.70000,4.03495,20743.13164,0.00000,0.01639,257.54748
80.80000,4.03998,20769.35023,0.00000,0.01642,257.87301
80.90000,4.04500,20791.84651,0.00000,0.01644,258.15233
81.00000,4.05008,20818.36760,0.00000,0.01647,258.48161
81.10000,4.05486,20840.21568,0.00000,0.01649,258.75288
81.20000,4.06001,20867.82008,0.00000,0.01651,259.09562
81.30000,4.06485,20890.57565,0.00000,0.01654,259.37815
81.40000,4.07005,20915.94040,0.00000,0.01656,259.69308
81.50000,4.07489,20938.24595,0.00000,0.01659,259.97003
81.60000,4.08003,20963.23967,0.00000,0.01661,260.28035
81.70000,4.08488,20985.91179,0.00000,0.01664,260.56185
81.80000,4.09008,21010.36459,0.00000,0.01667,260.86545
81.90000,4.09492,21033.15294,0.00000,0.01669,261.14840
82.00000,4.10000,21049.97188,0.00000,0.01671,261.35722
82.02400,4.10132,20627.92778,0.00000,0.01683,256.11711
82.02600,4.10150,20059.65412,0.00000,0.01712,249.06140
82.02800,4.10162,19273.96506,0.00000,0.01783,239.30625
82.03000,4.10186,18342.63653,0.00000,0.01920,227.74285
82.03200,4.10222,17300.78161,0.00000,0.02132,214.80714
82.03400,4.10246,16175.88252,0.00000,0.02406,200.84035
82.03600,4.10281,15002.69920,0.00000,0.02720,186.27406
82.03800,4.10323,13804.49384,0.00000,0.03065,171.39710
82.04000,4.10353,12595.57158,0.00000,0.03429,156.38708