File: scratch/college-stuff/ME Lab/ME lab Fall 2013/group3/group3.is_tens_RawData/Specimen_RawData_4.csv
Time,Extension,Load,Strain 2,Tensile strain,Tensile stress
(sec),(mm),(N),(mm/mm),(mm/mm),(MPa)
0.00000,0.00006,-0.40953,0.00000,0.00000,-0.00471
0.10000,0.00179,2.97014,0.00000,0.00000,0.03414
0.20000,0.00765,6.68929,0.00000,0.00000,0.07689
0.30000,0.01369,7.84613,0.00000,0.00000,0.09018
0.40000,0.01949,9.80147,0.00000,0.00000,0.11266
0.50000,0.02475,10.76005,0.00000,0.00000,0.12368
0.60000,0.03001,11.65381,0.00000,0.00000,0.13395
0.70000,0.03498,12.87556,0.00000,0.00000,0.14799
0.80000,0.04006,14.56745,0.00000,0.00001,0.16744
0.90000,0.04496,16.14099,0.00000,0.00001,0.18553
1.00000,0.05010,16.39681,0.00000,0.00000,0.18847
1.10000,0.05495,17.73646,0.00000,0.00001,0.20386
1.20000,0.06009,19.41496,0.00000,0.00000,0.22316
1.30000,0.06493,20.87928,0.00000,0.00000,0.23999
1.40000,0.07001,22.64019,0.00000,0.00000,0.26023
1.50000,0.07498,26.00698,0.00000,0.00000,0.29893
1.60000,0.08012,28.04769,0.00000,0.00000,0.32238
1.70000,0.08496,28.68610,0.00000,-0.00001,0.32972
1.80000,0.09004,29.54160,0.00000,0.00000,0.33955
1.90000,0.09495,30.42083,0.00000,-0.00001,0.34966
2.00000,0.10003,31.52477,0.00000,-0.00001,0.36235
2.10000,0.10505,33.21805,0.00000,-0.00001,0.38181
2.20000,0.11001,34.64114,0.00000,-0.00001,0.39817
2.30000,0.11498,37.08243,0.00000,-0.00001,0.42623
2.40000,0.11994,37.75360,0.00000,-0.00002,0.43394
2.50000,0.12502,39.91780,0.00000,-0.00002,0.45882
2.60000,0.12998,41.09290,0.00000,-0.00002,0.47233
2.70000,0.13506,42.30778,0.00000,-0.00002,0.48629
2.80000,0.13991,44.20379,0.00000,-0.00002,0.50808
2.90000,0.14505,46.32194,0.00000,-0.00002,0.53243
3.00000,0.14995,49.20940,0.00000,-0.00003,0.56562
3.10000,0.15515,51.12880,0.00000,-0.00003,0.58768
3.20000,0.15994,53.20571,0.00000,-0.00003,0.61155
3.30000,0.16508,56.07536,0.00000,-0.00004,0.64454
3.40000,0.16992,58.65104,0.00000,-0.00004,0.67414
3.50000,0.17506,62.89724,0.00000,-0.00004,0.72295
3.60000,0.17991,69.08216,0.00000,-0.00005,0.79404
3.70000,0.18505,76.23712,0.00000,-0.00005,0.87628
3.80000,0.18995,83.00638,0.00000,-0.00006,0.95408
3.90000,0.19503,87.67383,0.00000,-0.00006,1.00773
4.00000,0.20000,93.62767,0.00000,-0.00006,1.07617
4.10000,0.20502,99.44168,0.00000,-0.00007,1.14299
4.20000,0.20998,106.89293,0.00000,-0.00008,1.22864
4.30000,0.21500,115.77535,0.00000,-0.00008,1.33073
4.40000,0.22003,125.55222,0.00000,-0.00009,1.44311
4.50000,0.22505,135.26921,0.00000,-0.00009,1.55480
4.60000,0.23001,147.17220,0.00000,-0.00010,1.69161
4.70000,0.23497,159.47758,0.00000,-0.00010,1.83305
4.80000,0.24005,174.78814,0.00000,-0.00011,2.00903
4.90000,0.24502,190.01068,0.00000,-0.00011,2.18400
5.00000,0.25010,209.17144,0.00000,-0.00011,2.40424
5.10000,0.25494,229.90976,0.00000,-0.00011,2.64260
5.20000,0.26008,256.98766,0.00000,-0.00011,2.95384
5.30000,0.26499,287.03446,0.00000,-0.00010,3.29920
5.40000,0.27013,318.12319,0.00000,-0.00010,3.65654
5.50000,0.27491,348.24868,0.00000,-0.00009,4.00280
5.60000,0.28005,381.98745,0.00000,-0.00009,4.39060
5.70000,0.28490,416.91647,0.00000,-0.00008,4.79208
5.80000,0.29010,459.33812,0.00000,-0.00006,5.27968
5.90000,0.29500,498.51746,0.00000,-0.00005,5.73001
6.00000,0.30008,542.41447,0.00000,-0.00003,6.23456
6.10000,0.30493,586.09894,0.00000,-0.00002,6.73668
6.20000,0.31001,631.21920,0.00000,0.00000,7.25529
6.30000,0.31491,678.08903,0.00000,0.00002,7.79402
6.40000,0.32005,725.68436,0.00000,0.00004,8.34108
6.50000,0.32496,773.80133,0.00000,0.00006,8.89415
6.60000,0.32998,823.36906,0.00000,0.00007,9.46388
6.70000,0.33494,873.60293,0.00000,0.00010,10.04127
6.80000,0.33996,921.37046,0.00000,0.00012,10.59032
6.90000,0.34505,971.23915,0.00000,0.00014,11.16351
7.00000,0.35001,1020.28027,0.00000,0.00016,11.72720
7.10000,0.35503,1074.13502,0.00000,0.00018,12.34621
7.20000,0.35987,1121.45701,0.00000,0.00020,12.89013
7.30000,0.36507,1173.35459,0.00000,0.00022,13.48665
7.40000,0.36992,1220.14079,0.00000,0.00024,14.02441
7.50000,0.37506,1272.81817,0.00000,0.00027,14.62989
7.60000,0.37984,1321.55111,0.00000,0.00029,15.19003
7.70000,0.38504,1372.59979,0.00000,0.00031,15.77679
7.80000,0.38989,1422.03989,0.00000,0.00033,16.34506
7.90000,0.39503,1473.66347,0.00000,0.00035,16.93843
8.00000,0.39987,1523.61300,0.00000,0.00037,17.51255
8.10000,0.40501,1573.79657,0.00000,0.00040,18.08937
8.20000,0.40992,1622.97897,0.00000,0.00042,18.65467
8.30000,0.41506,1676.15525,0.00000,0.00044,19.26589
8.40000,0.41990,1725.74613,0.00000,0.00047,19.83589
8.50000,0.42498,1776.08225,0.00000,0.00049,20.41446
8.60000,0.42995,1825.48687,0.00000,0.00051,20.98232
8.70000,0.43497,1875.57731,0.00000,0.00053,21.55806
8.80000,0.43999,1926.22952,0.00000,0.00055,22.14026
8.90000,0.44501,1977.20565,0.00000,0.00058,22.72619
9.00000,0.44998,2028.13800,0.00000,0.00060,23.31161
9.10000,0.45500,2076.71989,0.00000,0.00062,23.87001
9.20000,0.46002,2126.43333,0.00000,0.00064,24.44143
9.30000,0.46504,2174.72818,0.00000,0.00067,24.99653
9.40000,0.47001,2226.73565,0.00000,0.00069,25.59431
9.50000,0.47497,2274.85318,0.00000,0.00071,26.14738
9.60000,0.47999,2326.81129,0.00000,0.00073,26.74459
9.70000,0.48495,2373.02557,0.00000,0.00075,27.27578
9.80000,0.49009,2422.94315,0.00000,0.00078,27.84954
9.90000,0.49494,2469.37312,0.00000,0.00080,28.38321
10.00000,0.50002,2522.13869,0.00000,0.00082,28.98970
10.10000,0.50486,2569.28839,0.00000,0.00085,29.53164
10.20000,0.51012,2618.11800,0.00000,0.00087,30.09290
10.30000,0.51491,2664.84395,0.00000,0.00089,30.62997
10.40000,0.52005,2715.97505,0.00000,0.00091,31.21767
10.50000,0.52489,2761.01008,0.00000,0.00093,31.73531
10.60000,0.53003,2811.18508,0.00000,0.00096,32.31203
10.70000,0.53494,2857.57314,0.00000,0.00098,32.84522
10.80000,0.54008,2906.50520,0.00000,0.00100,33.40765
10.90000,0.54486,2953.62640,0.00000,0.00102,33.94926
11.00000,0.54994,2999.66503,0.00000,0.00104,34.47843
11.10000,0.55491,3046.16224,0.00000,0.00107,35.01288
11.20000,0.55999,3093.18211,0.00000,0.00109,35.55333
11.30000,0.56495,3142.67054,0.00000,0.00111,36.12215
11.40000,0.56997,3187.98237,0.00000,0.00113,36.64297
11.50000,0.57494,3234.54477,0.00000,0.00115,37.17816
11.60000,0.57996,3278.07590,0.00000,0.00117,37.67851
11.70000,0.58504,3326.05392,0.00000,0.00120,38.22998
11.80000,0.58994,3369.15143,0.00000,0.00122,38.72534
11.90000,0.59497,3416.31025,0.00000,0.00123,39.26739
12.00000,0.59981,3457.65166,0.00000,0.00126,39.74257
12.10000,0.60501,3505.78912,0.00000,0.00128,40.29587
12.20000,0.60985,3548.60723,0.00000,0.00130,40.78803
12.30000,0.61493,3594.95953,0.00000,0.00132,41.32080
12.40000,0.61984,3637.01917,0.00000,0.00134,41.80424
12.50000,0.62504,3682.59214,0.00000,0.00136,42.32806
12.60000,0.62994,3725.21766,0.00000,0.00138,42.81800
12.70000,0.63508,3769.14591,0.00000,0.00140,43.32292
12.80000,0.63993,3813.62811,0.00000,0.00142,43.83420
12.90000,0.64501,3855.11108,0.00000,0.00144,44.31101
13.00000,0.64991,3897.05934,0.00000,0.00146,44.79317
13.10000,0.65505,3940.66237,0.00000,0.00148,45.29435
13.20000,0.65990,3982.63782,0.00000,0.00150,45.77681
13.30000,0.66492,4024.17965,0.00000,0.00152,46.25430
13.40000,0.66988,4065.74942,0.00000,0.00154,46.73211
13.50000,0.67496,4106.83863,0.00000,0.00156,47.20439
13.60000,0.67999,4150.33102,0.00000,0.00158,47.70430
13.70000,0.68501,4191.27680,0.00000,0.00160,48.17493
13.80000,0.68997,4232.51167,0.00000,0.00162,48.64889
13.90000,0.69505,4272.46727,0.00000,0.00163,49.10814
14.00000,0.70008,4312.65123,0.00000,0.00165,49.57002
14.10000,0.70504,4351.86476,0.00000,0.00167,50.02074
14.20000,0.71000,4394.03877,0.00000,0.00169,50.50550
14.30000,0.71496,4432.71883,0.00000,0.00171,50.95009
14.40000,0.72004,4473.07229,0.00000,0.00173,51.41391
14.50000,0.72495,4509.25939,0.00000,0.00175,51.82985
14.60000,0.73015,4552.14232,0.00000,0.00177,52.32275
14.70000,0.73499,4590.44576,0.00000,0.00179,52.76302
14.80000,0.74013,4629.34002,0.00000,0.00181,53.21007
14.90000,0.74498,4664.75636,0.00000,0.00182,53.61715
15.00000,0.75006,4704.37557,0.00000,0.00185,54.07254
15.10000,0.75484,4741.16430,0.00000,0.00186,54.49539
15.20000,0.76004,4782.29672,0.00000,0.00188,54.96817
15.30000,0.76489,4817.85201,0.00000,0.00189,55.37685
15.40000,0.77003,4855.64098,0.00000,0.00191,55.81120
15.50000,0.77493,4891.69508,0.00000,0.00193,56.22560
15.60000,0.78001,4929.97617,0.00000,0.00195,56.66561
15.70000,0.78492,4967.84113,0.00000,0.00197,57.10083
15.80000,0.79000,5005.86405,0.00000,0.00199,57.53787
15.90000,0.79496,5043.35575,0.00000,0.00201,57.96881
16.00000,0.79998,5077.93389,0.00000,0.00202,58.36625
16.10000,0.80489,5115.35741,0.00000,0.00204,58.79640
16.20000,0.80997,5150.28164,0.00000,0.00206,59.19782
16.30000,0.81493,5187.18697,0.00000,0.00207,59.62202
16.40000,0.82001,5220.84199,0.00000,0.00209,60.00885
16.50000,0.82504,5256.17301,0.00000,0.00211,60.41495
16.60000,0.82994,5289.80903,0.00000,0.00212,60.80156
16.70000,0.83496,5326.30682,0.00000,0.00214,61.22107
16.80000,0.83992,5358.68742,0.00000,0.00216,61.59326
16.90000,0.84506,5395.49328,0.00000,0.00218,62.01631
17.00000,0.84985,5426.13603,0.00000,0.00219,62.36852
17.10000,0.85505,5460.70635,0.00000,0.00221,62.76587
17.20000,0.85989,5492.21933,0.00000,0.00222,63.12809
17.30000,0.86509,5526.39551,0.00000,0.00224,63.52091
17.40000,0.86994,5557.17684,0.00000,0.00225,63.87471
17.50000,0.87502,5591.51098,0.00000,0.00227,64.26935
17.60000,0.87986,5623.57716,0.00000,0.00228,64.63793
17.70000,0.88500,5656.20400,0.00000,0.00231,65.01294
17.80000,0.88991,5687.03860,0.00000,0.00232,65.36736
17.90000,0.89505,5718.06505,0.00000,0.00233,65.72398
18.00000,0.89995,5747.57159,0.00000,0.00234,66.06313
18.10000,0.90503,5776.41092,0.00000,0.00236,66.39461
18.20000,0.90994,5805.63322,0.00000,0.00237,66.73050
18.30000,0.91502,5830.53231,0.00000,0.00239,67.01669
18.40000,0.91998,5857.21657,0.00000,0.00240,67.32340
18.50000,0.92500,5883.38487,0.00000,0.00241,67.62418
18.60000,0.92997,5910.44985,0.00000,0.00242,67.93527
18.70000,0.93505,5935.73749,0.00000,0.00244,68.22593
18.80000,0.94001,5963.49053,0.00000,0.00245,68.54492
18.90000,0.94497,5989.07433,0.00000,0.00246,68.83899
19.00000,0.95000,6018.02245,0.00000,0.00247,69.17172
19.10000,0.95490,6043.89347,0.00000,0.00249,69.46908
19.20000,0.96004,6072.04512,0.00000,0.00250,69.79266
19.30000,0.96494,6096.04195,0.00000,0.00252,70.06848
19.40000,0.97002,6124.83956,0.00000,0.00253,70.39948
19.50000,0.97487,6150.24045,0.00000,0.00254,70.69144
19.60000,0.98007,6178.75829,0.00000,0.00255,71.01923
19.70000,0.98491,6202.64895,0.00000,0.00256,71.29383
19.80000,0.99011,6230.72460,0.00000,0.00258,71.61654
19.90000,0.99484,6254.62905,0.00000,0.00259,71.89130
20.00000,1.00004,6282.19917,0.00000,0.00260,72.20819
20.10000,1.00488,6306.30255,0.00000,0.00262,72.48524
20.20000,1.01008,6332.91230,0.00000,0.00263,72.79109
20.30000,1.01493,6357.71751,0.00000,0.00264,73.07620
20.40000,1.02001,6385.34129,0.00000,0.00265,73.39372
20.50000,1.02491,6412.85405,0.00000,0.00267,73.70995
20.60000,1.02999,6439.94957,0.00000,0.00268,74.02139
20.70000,1.03496,6468.64027,0.00000,0.00269,74.35116
20.80000,1.03998,6494.03110,0.00000,0.00271,74.64301
20.90000,1.04494,6523.65759,0.00000,0.00272,74.98354
21.00000,1.04996,6550.05872,0.00000,0.00273,75.28699
21.10000,1.05499,6578.34709,0.00000,0.00275,75.61214
21.20000,1.06001,6604.43828,0.00000,0.00276,75.91204
21.30000,1.06503,6634.17429,0.00000,0.00278,76.25383
21.40000,1.06993,6660.53221,0.00000,0.00278,76.55679
21.50000,1.07502,6690.53942,0.00000,0.00280,76.90169
21.60000,1.07992,6715.28205,0.00000,0.00281,77.18609
21.70000,1.08512,6743.98988,0.00000,0.00283,77.51606
21.80000,1.08990,6769.64447,0.00000,0.00284,77.81093
21.90000,1.09504,6799.81336,0.00000,0.00285,78.15770
22.00000,1.09989,6825.15576,0.00000,0.00287,78.44898
22.10000,1.10509,6854.38216,0.00000,0.00288,78.78492
22.20000,1.10993,6880.06282,0.00000,0.00289,79.08009
22.30000,1.11507,6909.54477,0.00000,0.00291,79.41896
22.40000,1.11992,6935.70673,0.00000,0.00292,79.71967
22.50000,1.12506,6964.92791,0.00000,0.00293,80.05554
22.60000,1.12996,6991.49892,0.00000,0.00295,80.36095
22.70000,1.13504,7018.46853,0.00000,0.00296,80.67094
22.80000,1.13995,7047.99294,0.00000,0.00298,81.01030
22.90000,1.14503,7076.45863,0.00000,0.00299,81.33748
23.00000,1.14993,7102.30395,0.00000,0.00300,81.63455
23.10000,1.15507,7130.90450,0.00000,0.00301,81.96329
23.20000,1.15998,7158.22130,0.00000,0.00303,82.27727
23.30000,1.16500,7185.95088,0.00000,0.00304,82.59600
23.40000,1.17002,7214.14313,0.00000,0.00306,82.92004
23.50000,1.17504,7241.52327,0.00000,0.00307,83.23475
23.60000,1.18007,7270.05675,0.00000,0.00308,83.56272
23.70000,1.18497,7295.70910,0.00000,0.00310,83.85757
23.80000,1.18999,7326.22892,0.00000,0.00311,84.20837
23.90000,1.19489,7350.95963,0.00000,0.00313,84.49262
24.00000,1.20003,7380.77313,0.00000,0.00314,84.83530
24.10000,1.20494,7407.09156,0.00000,0.00315,85.13781
24.20000,1.21008,7437.74325,0.00000,0.00317,85.49012
24.30000,1.21486,7464.40291,0.00000,0.00318,85.79655
24.40000,1.22006,7494.64035,0.00000,0.00320,86.14410
24.50000,1.22491,7520.66597,0.00000,0.00321,86.44324
24.60000,1.23011,7551.40185,0.00000,0.00322,86.79653
24.70000,1.23489,7577.46473,0.00000,0.00324,87.09609
24.80000,1.24003,7607.16200,0.00000,0.00325,87.43744
24.90000,1.24488,7633.91256,0.00000,0.00326,87.74491
25.00000,1.25008,7663.43772,0.00000,0.00328,88.08428
25.10000,1.25492,7690.75677,0.00000,0.00329,88.39828
25.20000,1.25994,7717.98640,0.00000,0.00331,88.71126
25.30000,1.26491,7746.40143,0.00000,0.00332,89.03787
25.40000,1.26999,7773.23470,0.00000,0.00333,89.34629
25.50000,1.27495,7801.88143,0.00000,0.00335,89.67556
25.60000,1.27997,7828.84061,0.00000,0.00336,89.98543
25.70000,1.28500,7859.65323,0.00000,0.00338,90.33960
25.80000,1.28996,7885.89492,0.00000,0.00338,90.64122
25.90000,1.29504,7914.94399,0.00000,0.00341,90.97511
26.00000,1.30000,7940.98452,0.00000,0.00341,91.27443
26.10000,1.30503,7971.71667,0.00000,0.00343,91.62766
26.20000,1.30993,7997.65214,0.00000,0.00345,91.92577
26.30000,1.31501,8029.15692,0.00000,0.00346,92.28789
26.40000,1.31997,8054.93817,0.00000,0.00348,92.58422
26.50000,1.32505,8085.64350,0.00000,0.00349,92.93715
26.60000,1.32990,8113.61298,0.00000,0.00350,93.25863
26.70000,1.33510,8143.95100,0.00000,0.00352,93.60734
26.80000,1.34000,8171.54199,0.00000,0.00353,93.92447
26.90000,1.34514,8199.37885,0.00000,0.00355,94.24443
27.00000,1.34993,8225.82990,0.00000,0.00355,94.54846
27.10000,1.35507,8255.92205,0.00000,0.00358,94.89435
27.20000,1.35991,8283.82820,0.00000,0.00359,95.21510
27.30000,1.36511,8312.97711,0.00000,0.00360,95.55014
27.40000,1.36996,8339.26499,0.00000,0.00362,95.85230
27.50000,1.37504,8368.16430,0.00000,0.00362,96.18447
27.60000,1.37988,8396.54431,0.00000,0.00365,96.51067
27.70000,1.38502,8425.41829,0.00000,0.00365,96.84255
27.80000,1.38999,8454.57017,0.00000,0.00367,97.17763
27.90000,1.39513,8483.03288,0.00000,0.00369,97.50478
28.00000,1.39997,8510.94052,0.00000,0.00370,97.82555
28.10000,1.40499,8539.13203,0.00000,0.00372,98.14959
28.20000,1.40996,8567.72587,0.00000,0.00373,98.47825
28.30000,1.41498,8593.79992,0.00000,0.00374,98.77795
28.40000,1.42000,8624.29738,0.00000,0.00376,99.12849
28.50000,1.42490,8651.06136,0.00000,0.00376,99.43612
28.60000,1.42999,8684.16429,0.00000,0.00379,99.81660
28.70000,1.43489,8709.90530,0.00000,0.00379,100.11247
28.80000,1.44009,8740.62851,0.00000,0.00381,100.46561
28.90000,1.44493,8765.96570,0.00000,0.00383,100.75684
29.00000,1.45007,8797.30806,0.00000,0.00384,101.11709
29.10000,1.45492,8822.83077,0.00000,0.00386,101.41045
29.20000,1.46006,8852.27099,0.00000,0.00387,101.74884
29.30000,1.46490,8879.58333,0.00000,0.00388,102.06277
29.40000,1.47004,8910.99647,0.00000,0.00390,102.42383
29.50000,1.47483,8937.86326,0.00000,0.00391,102.73264
29.60000,1.48003,8968.73027,0.00000,0.00393,103.08743
29.70000,1.48487,8996.53211,0.00000,0.00394,103.40699
29.80000,1.49001,9026.20479,0.00000,0.00396,103.74805
29.90000,1.49492,9053.69371,0.00000,0.00397,104.06401
30.00000,1.50000,9083.16523,0.00000,0.00398,104.40276
30.10000,1.50496,9113.78190,0.00000,0.00400,104.75467
30.20000,1.51004,9140.94597,0.00000,0.00401,105.06690
30.30000,1.51495,9170.55830,0.00000,0.00403,105.40726
30.40000,1.51997,9197.43925,0.00000,0.00405,105.71623
30.50000,1.52499,9226.60604,0.00000,0.00406,106.05148
30.60000,1.53001,9255.34666,0.00000,0.00408,106.38183
30.70000,1.53504,9285.08118,0.00000,0.00409,106.72360
30.80000,1.54000,9312.03589,0.00000,0.00411,107.03342
30.90000,1.54502,9342.38136,0.00000,0.00412,107.38221
31.00000,1.54992,9369.20717,0.00000,0.00413,107.69055
31.10000,1.55506,9400.17924,0.00000,0.00415,108.04655
31.20000,1.55991,9425.47917,0.00000,0.00417,108.33735
31.30000,1.56511,9456.79322,0.00000,0.00418,108.69727
31.40000,1.56989,9483.97964,0.00000,0.00420,109.00976
31.50000,1.57503,9514.62463,0.00000,0.00421,109.36199
31.60000,1.57994,9543.02847,0.00000,0.00423,109.68847
31.70000,1.58514,9573.51625,0.00000,0.00424,110.03890
31.80000,1.58992,9600.36814,0.00000,0.00426,110.34754
31.90000,1.59500,9630.81568,0.00000,0.00427,110.69750
32.00000,1.59991,9658.45659,0.00000,0.00429,111.01521
32.10000,1.60505,9687.49821,0.00000,0.00430,111.34902
32.20000,1.61001,9716.72535,0.00000,0.00432,111.68496
32.30000,1.61503,9745.58368,0.00000,0.00434,112.01666
32.40000,1.61994,9774.75718,0.00000,0.00435,112.35198
32.50000,1.62502,9803.42850,0.00000,0.00436,112.68153
32.60000,1.62998,9831.82341,0.00000,0.00438,113.00791
32.70000,1.63506,9860.71080,0.00000,0.00439,113.33994
32.80000,1.63997,9890.96090,0.00000,0.00441,113.68764
32.90000,1.64499,9919.69407,0.00000,0.00442,114.01790
33.00000,1.65001,9950.94776,0.00000,0.00444,114.37713
33.10000,1.65497,9977.95239,0.00000,0.00445,114.68753
33.20000,1.66006,10008.53479,0.00000,0.00447,115.03904
33.30000,1.66490,10035.26002,0.00000,0.00448,115.34623
33.40000,1.67004,10066.73053,0.00000,0.00450,115.70795
33.50000,1.67494,10093.86778,0.00000,0.00451,116.01987
33.60000,1.68008,10125.83748,0.00000,0.00453,116.38733
33.70000,1.68493,10153.31149,0.00000,0.00454,116.70312
33.80000,1.69013,10185.43839,0.00000,0.00456,117.07239
33.90000,1.69491,10213.17095,0.00000,0.00457,117.39115
34.00000,1.70005,10242.09410,0.00000,0.00459,117.72360
34.10000,1.70490,10268.94525,0.00000,0.00461,118.03223
34.20000,1.70998,10299.00759,0.00000,0.00462,118.37776
34.30000,1.71488,10328.77043,0.00000,0.00464,118.71986
34.40000,1.72002,10358.27771,0.00000,0.00465,119.05902
34.50000,1.72493,10386.50200,0.00000,0.00467,119.38343
34.60000,1.73007,10416.49729,0.00000,0.00468,119.72820
34.70000,1.73491,10445.30720,0.00000,0.00469,120.05935
34.80000,1.73999,10475.20116,0.00000,0.00471,120.40295
34.90000,1.74496,10504.87757,0.00000,0.00473,120.74405
35.00000,1.74998,10533.22926,0.00000,0.00474,121.06993
35.10000,1.75500,10563.41603,0.00000,0.00476,121.41690
35.20000,1.76002,10591.71036,0.00000,0.00477,121.74212
35.30000,1.76493,10623.16373,0.00000,0.00478,122.10365
35.40000,1.77001,10650.38666,0.00000,0.00480,122.41655
35.50000,1.77509,10682.32208,0.00000,0.00482,122.78362
35.60000,1.78005,10708.83721,0.00000,0.00483,123.08839
35.70000,1.78508,10740.44257,0.00000,0.00485,123.45166
35.80000,1.78998,10767.68488,0.00000,0.00486,123.76479
35.90000,1.79506,10797.79193,0.00000,0.00488,124.11084
36.00000,1.79996,10825.47083,0.00000,0.00489,124.42898
36.10000,1.80510,10856.65226,0.00000,0.00491,124.78739
36.20000,1.80995,10883.53544,0.00000,0.00492,125.09638
36.30000,1.81509,10914.30634,0.00000,0.00494,125.45007
36.40000,1.81993,10942.10818,0.00000,0.00495,125.76962
36.50000,1.82513,10974.51672,0.00000,0.00498,126.14213
36.60000,1.82998,11002.51228,0.00000,0.00499,126.46391
36.70000,1.83506,11033.09765,0.00000,0.00501,126.81547
36.80000,1.83990,11062.27264,0.00000,0.00502,127.15081
36.90000,1.84504,11091.83803,0.00000,0.00504,127.49063
37.00000,1.84995,11120.91616,0.00000,0.00505,127.82486
37.10000,1.85503,11151.73548,0.00000,0.00507,128.17910
37.20000,1.85993,11181.99080,0.00000,0.00508,128.52686
37.30000,1.86501,11211.54800,0.00000,0.00510,128.86659
37.40000,1.86998,11242.47089,0.00000,0.00511,129.22202
37.50000,1.87500,11269.50905,0.00000,0.00513,129.53280
37.60000,1.87996,11301.36624,0.00000,0.00515,129.89897
37.70000,1.88504,11329.76040,0.00000,0.00516,130.22533
37.80000,1.89001,11360.84348,0.00000,0.00518,130.58261
37.90000,1.89503,11389.04393,0.00000,0.00520,130.90675
38.00000,1.89999,11419.87815,0.00000,0.00521,131.26116
38.10000,1.90489,11448.68731,0.00000,0.00523,131.59229
38.20000,1.91004,11480.55866,0.00000,0.00525,131.95862
38.30000,1.91488,11507.65866,0.00000,0.00526,132.27011
38.40000,1.92008,11539.82207,0.00000,0.00528,132.63980
38.50000,1.92486,11567.36985,0.00000,0.00529,132.95644
38.60000,1.93000,11601.62389,0.00000,0.00531,133.35016
38.70000,1.93485,11629.61647,0.00000,0.00533,133.67191
38.80000,1.94011,11660.75468,0.00000,0.00534,134.02981
38.90000,1.94489,11689.04006,0.00000,0.00535,134.35493
39.00000,1.95003,11720.95910,0.00000,0.00537,134.72181
39.10000,1.95488,11750.43881,0.00000,0.00539,135.06065
39.20000,1.96002,11781.75956,0.00000,0.00540,135.42066
39.30000,1.96498,11811.23927,0.00000,0.00542,135.75950
39.40000,1.97000,11840.39861,0.00000,0.00544,136.09466
39.50000,1.97491,11871.05253,0.00000,0.00545,136.44700
39.60000,1.97999,11900.19697,0.00000,0.00547,136.78199
39.70000,1.98495,11930.49252,0.00000,0.00548,137.13021
39.80000,1.99003,11959.16086,0.00000,0.00550,137.45972
39.90000,1.99500,11990.31696,0.00000,0.00552,137.81783
40.00000,2.00002,12020.11406,0.00000,0.00553,138.16032
40.10000,2.00498,12051.92432,0.00000,0.00555,138.52596
40.20000,2.01006,12080.55317,0.00000,0.00556,138.85502
40.30000,2.01503,12110.00085,0.00000,0.00558,139.19349
40.40000,2.01999,12138.56190,0.00000,0.00560,139.52178
40.50000,2.02501,12170.92648,0.00000,0.00562,139.89378
40.60000,2.02991,12200.47772,0.00000,0.00563,140.23344
40.70000,2.03505,12233.10381,0.00000,0.00564,140.60845
40.80000,2.03996,12261.37653,0.00000,0.00566,140.93342
40.90000,2.04504,12292.85523,0.00000,0.00568,141.29524
41.00000,2.04994,12321.84842,0.00000,0.00569,141.62849
41.10000,2.05508,12354.51177,0.00000,0.00571,142.00392
41.20000,2.05999,12383.03259,0.00000,0.00573,142.33174
41.30000,2.06513,12415.85165,0.00000,0.00574,142.70897
41.40000,2.06991,12442.89503,0.00000,0.00576,143.01981
41.50000,2.07505,12474.72465,0.00000,0.00578,143.38566
41.60000,2.07990,12502.57343,0.00000,0.00579,143.70576
41.70000,2.08510,12534.45446,0.00000,0.00581,144.07220
41.80000,2.08994,12563.94088,0.00000,0.00583,144.41112
41.90000,2.09496,12594.81311,0.00000,0.00584,144.76597
42.00000,2.09993,12626.60325,0.00000,0.00586,145.13137
42.10000,2.10507,12657.29964,0.00000,0.00587,145.48420
42.20000,2.10997,12688.54439,0.00000,0.00589,145.84333
42.30000,2.11505,12716.40658,0.00000,0.00591,146.16358
42.40000,2.11996,12749.13847,0.00000,0.00592,146.53980
42.50000,2.12498,12778.24193,0.00000,0.00594,146.87432
42.60000,2.13000,12809.86071,0.00000,0.00596,147.23775
42.70000,2.13496,12838.46647,0.00000,0.00597,147.56654
42.80000,2.13999,12870.33260,0.00000,0.00599,147.93282
42.90000,2.14489,12899.00392,0.00000,0.00601,148.26237
43.00000,2.15003,12932.06662,0.00000,0.00602,148.64239
43.10000,2.15493,12960.21193,0.00000,0.00604,148.96590
43.20000,2.16013,12992.49530,0.00000,0.00606,149.33697
43.30000,2.16492,13021.29477,0.00000,0.00607,149.66799
43.40000,2.17006,13052.39201,0.00000,0.00610,150.02543
43.50000,2.17490,13081.09462,0.00000,0.00611,150.35534
43.60000,2.18010,13112.15013,0.00000,0.00613,150.71229
43.70000,2.18495,13140.92427,0.00000,0.00614,151.04302
43.80000,2.18997,13172.49537,0.00000,0.00616,151.40590
43.90000,2.19487,13201.26057,0.00000,0.00617,151.73653
44.00000,2.20001,13234.44992,0.00000,0.00619,152.11802
44.10000,2.20492,13264.14645,0.00000,0.00621,152.45935
44.20000,2.21006,13294.42561,0.00000,0.00622,152.80738
44.30000,2.21496,13324.17876,0.00000,0.00624,153.14937
44.40000,2.21998,13353.73819,0.00000,0.00626,153.48913
44.50000,2.22501,13383.93092,0.00000,0.00627,153.83616
44.60000,2.23003,13413.34730,0.00000,0.00629,154.17428
44.70000,2.23499,13443.34036,0.00000,0.00631,154.51902
44.80000,2.24001,13473.80131,0.00000,0.00632,154.86914
44.90000,2.24498,13505.67937,0.00000,0.00634,155.23555
45.00000,2.25000,13533.58179,0.00000,0.00635,155.55627
45.10000,2.25502,13565.25123,0.00000,0.00637,155.92028
45.20000,2.25992,13592.10759,0.00000,0.00638,156.22897
45.30000,2.26501,13625.54580,0.00000,0.00641,156.61331
45.40000,2.26997,13654.20371,0.00000,0.00642,156.94271
45.50000,2.27505,13685.93127,0.00000,0.00644,157.30739
45.60000,2.27995,13713.98121,0.00000,0.00645,157.62979
45.70000,2.28503,13746.06043,0.00000,0.00647,157.99852
45.80000,2.28988,13774.47695,0.00000,0.00649,158.32514
45.90000,2.29508,13807.57391,0.00000,0.00650,158.70556
46.00000,2.29992,13836.83980,0.00000,0.00652,159.04194
46.10000,2.30506,13869.24386,0.00000,0.00654,159.41440
46.20000,2.30985,13898.31603,0.00000,0.00656,159.74856
46.30000,2.31499,13929.77089,0.00000,0.00657,160.11010
46.40000,2.31989,13959.54490,0.00000,0.00659,160.45233
46.50000,2.32509,13989.97009,0.00000,0.00661,160.80204
46.60000,2.32994,14019.67704,0.00000,0.00663,161.14349
46.70000,2.33502,14050.25870,0.00000,0.00664,161.49500
46.80000,2.33992,14082.67766,0.00000,0.00666,161.86763
46.90000,2.34500,14111.95397,0.00000,0.00667,162.20413
47.00000,2.34997,14143.15999,0.00000,0.00669,162.56282
47.10000,2.35499,14170.21751,0.00000,0.00671,162.87382
47.20000,2.35995,14203.11928,0.00000,0.00673,163.25199
47.30000,2.36491,14230.92484,0.00000,0.00674,163.57159
47.40000,2.37000,14263.10241,0.00000,0.00675,163.94144
47.50000,2.37496,14291.88848,0.00000,0.00677,164.27231
47.60000,2.37998,14324.53245,0.00000,0.00679,164.64753
47.70000,2.38488,14354.21854,0.00000,0.00681,164.98874
47.80000,2.39003,14385.38581,0.00000,0.00682,165.34698
47.90000,2.39487,14413.25992,0.00000,0.00684,165.66737
48.00000,2.40007,14445.95456,0.00000,0.00686,166.04316
48.10000,2.40491,14475.64662,0.00000,0.00687,166.38445
48.20000,2.40999,14506.40410,0.00000,0.00689,166.73798
48.30000,2.41490,14536.05592,0.00000,0.00691,167.07880
48.40000,2.42010,14566.43790,0.00000,0.00692,167.42801
48.50000,2.42494,14594.73073,0.00000,0.00694,167.75321
48.60000,2.43002,14624.39150,0.00000,0.00696,168.09414
48.70000,2.43493,14655.53790,0.00000,0.00698,168.45214
48.80000,2.44007,14686.18214,0.00000,0.00699,168.80436
48.90000,2.44503,14716.64160,0.00000,0.00701,169.15447
49.00000,2.45005,14746.87159,0.00000,0.00703,169.50193
49.10000,2.45496,14777.18502,0.00000,0.00704,169.85036
49.20000,2.46004,14807.90973,0.00000,0.00706,170.20351
49.30000,2.46494,14837.24266,0.00000,0.00708,170.54067
49.40000,2.47002,14867.88243,0.00000,0.00709,170.89284
49.50000,2.47493,14899.28514,0.00000,0.00711,171.25379
49.60000,2.47995,14930.28849,0.00000,0.00713,171.61014
49.70000,2.48503,14961.60924,0.00000,0.00715,171.97015
49.80000,2.48999,14989.41332,0.00000,0.00716,172.28973
49.90000,2.49508,15021.61324,0.00000,0.00718,172.65984
50.00000,2.49992,15050.11320,0.00000,0.00720,172.98742
50.10000,2.50500,15083.64677,0.00000,0.00721,173.37286
50.20000,2.50990,15112.03200,0.00000,0.00723,173.69912
50.30000,2.51510,15146.06327,0.00000,0.00725,174.09028
50.40000,2.51989,15173.01500,0.00000,0.00727,174.40007
50.50000,2.52503,15205.88696,0.00000,0.00728,174.77790
50.60000,2.52987,15235.48961,0.00000,0.00730,175.11815
50.70000,2.53507,15266.70903,0.00000,0.00732,175.47699
50.80000,2.53992,15296.45771,0.00000,0.00733,175.81893
50.90000,2.54506,15328.31937,0.00000,0.00735,176.18515
51.00000,2.54990,15357.88327,0.00000,0.00737,176.52496
51.10000,2.55504,15391.18290,0.00000,0.00739,176.90771
51.20000,2.55989,15420.15523,0.00000,0.00740,177.24072
51.30000,2.56509,15451.68757,0.00000,0.00742,177.60315
51.40000,2.56987,15481.24254,0.00000,0.00744,177.94286
51.50000,2.57495,15512.11625,0.00000,0.00746,178.29773
51.60000,2.57992,15544.28488,0.00000,0.00747,178.66748
51.70000,2.58506,15575.09601,0.00000,0.00749,179.02162
51.80000,2.59002,15604.78210,0.00000,0.00751,179.36284
51.90000,2.59498,15633.76337,0.00000,0.00752,179.69595
52.00000,2.60001,15664.36291,0.00000,0.00754,180.04766
52.10000,2.60497,15694.13245,0.00000,0.00756,180.38984
52.20000,2.61005,15728.82533,0.00000,0.00758,180.78860
52.30000,2.61495,15755.42390,0.00000,0.00759,181.09433
52.40000,2.62004,15788.50150,0.00000,0.00761,181.47453
52.50000,2.62494,15816.13123,0.00000,0.00763,181.79210
52.60000,2.63008,15848.77074,0.00000,0.00764,182.16727
52.70000,2.63504,15878.11261,0.00000,0.00766,182.50452
52.80000,2.64012,15909.47360,0.00000,0.00768,182.86499
52.90000,2.64491,15938.22539,0.00000,0.00769,183.19547
53.00000,2.65005,15970.09450,0.00000,0.00771,183.56177
53.10000,2.65495,16000.50181,0.00000,0.00773,183.91128
53.20000,2.66009,16031.47686,0.00000,0.00775,184.26731
53.30000,2.66494,16060.43726,0.00000,0.00777,184.60018
53.40000,2.67002,16091.71182,0.00000,0.00778,184.95965
53.50000,2.67492,16121.92243,0.00000,0.00780,185.30690
53.60000,2.68006,16153.29385,0.00000,0.00782,185.66748
53.70000,2.68497,16183.41804,0.00000,0.00783,186.01373
53.80000,2.68999,16213.48262,0.00000,0.00785,186.35930
53.90000,2.69489,16244.55750,0.00000,0.00787,186.71648
54.00000,2.70003,16275.08551,0.00000,0.00788,187.06737
54.10000,2.70500,16307.32566,0.00000,0.00790,187.43794
54.20000,2.71008,16337.79854,0.00000,0.00792,187.78820
54.30000,2.71498,16368.97177,0.00000,0.00794,188.14651
54.40000,2.72000,16398.67723,0.00000,0.00796,188.48794
54.50000,2.72497,16429.87430,0.00000,0.00798,188.84653
54.60000,2.72999,16458.89282,0.00000,0.00799,189.18007
54.70000,2.73501,16490.76045,0.00000,0.00801,189.54636
54.80000,2.73985,16519.40793,0.00000,0.00803,189.87563
54.90000,2.74500,16555.28396,0.00000,0.00805,190.28800
55.00000,2.74990,16583.70495,0.00000,0.00807,190.61467
55.10000,2.75510,16617.11484,0.00000,0.00808,190.99869
55.20000,2.75994,16646.03651,0.00000,0.00810,191.33111
55.30000,2.76502,16677.24848,0.00000,0.00812,191.68987
55.40000,2.76993,16706.81387,0.00000,0.00814,192.02969
55.50000,2.77507,16738.14058,0.00000,0.00815,192.38977
55.60000,2.77997,16768.31692,0.00000,0.00817,192.73662
55.70000,2.78505,16799.90739,0.00000,0.00819,193.09972
55.80000,2.78984,16829.21350,0.00000,0.00821,193.43657
55.90000,2.79498,16860.62515,0.00000,0.00822,193.79762
56.00000,2.79994,16891.82669,0.00000,0.00824,194.15625
56.10000,2.80502,16922.95969,0.00000,0.00826,194.51410
56.20000,2.80987,16953.32229,0.00000,0.00828,194.86309
56.30000,2.81495,16983.90543,0.00000,0.00829,195.21461
56.40000,2.81991,17015.81627,0.00000,0.00831,195.58140
56.50000,2.82505,17045.28630,0.00000,0.00833,195.92013
56.60000,2.83002,17075.78003,0.00000,0.00835,196.27063
56.70000,2.83498,17104.96098,0.00000,0.00836,196.60604
56.80000,2.84000,17139.33945,0.00000,0.00838,197.00118
56.90000,2.84490,17168.70070,0.00000,0.00840,197.33867
57.00000,2.84999,17201.06304,0.00000,0.00842,197.71064
57.10000,2.85495,17229.25305,0.00000,0.00843,198.03466
57.20000,2.86003,17261.20561,0.00000,0.00846,198.40193
57.30000,2.86493,17289.89035,0.00000,0.00847,198.73163
57.40000,2.87007,17321.29753,0.00000,0.00849,199.09263
57.50000,2.87498,17350.30264,0.00000,0.00850,199.42602
57.60000,2.88012,17382.89595,0.00000,0.00852,199.80065
57.70000,2.88490,17412.36746,0.00000,0.00854,200.13939
57.80000,2.89004,17445.36459,0.00000,0.00856,200.51867
57.90000,2.89495,17473.36984,0.00000,0.00858,200.84056
58.00000,2.90009,17506.17176,0.00000,0.00859,201.21759
58.10000,2.90487,17534.93994,0.00000,0.00861,201.54825
58.20000,2.90995,17567.45428,0.00000,0.00863,201.92198
58.30000,2.91486,17597.52333,0.00000,0.00865,202.26759
58.40000,2.92006,17630.02872,0.00000,0.00866,202.64121
58.50000,2.92502,17660.50607,0.00000,0.00868,202.99152
58.60000,2.93004,17691.14137,0.00000,0.00870,203.34365
58.70000,2.93495,17722.85998,0.00000,0.00872,203.70822
58.80000,2.94003,17753.70836,0.00000,0.00873,204.06280
58.90000,2.94499,17785.02315,0.00000,0.00875,204.42273
59.00000,2.95007,17814.91339,0.00000,0.00877,204.76630
59.10000,2.95498,17846.30120,0.00000,0.00879,205.12707
59.20000,2.95994,17874.80861,0.00000,0.00881,205.45474
59.30000,2.96502,17907.38106,0.00000,0.00882,205.82913
59.40000,2.96992,17935.83930,0.00000,0.00884,206.15623
59.50000,2.97507,17970.22521,0.00000,0.00886,206.55146
59.60000,2.97991,17999.00681,0.00000,0.00888,206.88228
59.70000,2.98505,18032.24385,0.00000,0.00889,207.26431
59.80000,2.98989,18060.91517,0.00000,0.00891,207.59386
59.90000,2.99504,18092.53842,0.00000,0.00893,207.95734
60.00000,2.99988,18121.37663,0.00000,0.00895,208.28881
60.10000,3.00502,18153.72854,0.00000,0.00897,208.66067
60.20000,3.00980,18183.33566,0.00000,0.00899,209.00098
60.30000,3.01506,18216.59654,0.00000,0.00900,209.38328
60.40000,3.01991,18246.56576,0.00000,0.00902,209.72775
60.50000,3.02499,18276.55882,0.00000,0.00904,210.07249
60.60000,3.02989,18306.19574,0.00000,0.00906,210.41314
60.70000,3.03503,18338.11700,0.00000,0.00907,210.78005
60.80000,3.04000,18369.21573,0.00000,0.00909,211.13750
60.90000,3.04502,18399.20878,0.00000,0.00911,211.48224
61.00000,3.04992,18430.18085,0.00000,0.00913,211.83824
61.10000,3.05500,18460.00999,0.00000,0.00914,212.18110
61.20000,3.06003,18492.15776,0.00000,0.00917,212.55061
61.30000,3.06505,18521.32231,0.00000,0.00918,212.88583
61.40000,3.07001,18552.76674,0.00000,0.00920,213.24725
61.50000,3.07497,18582.32319,0.00000,0.00922,213.58698
61.60000,3.08000,18614.86137,0.00000,0.00924,213.96097
61.70000,3.08496,18643.02456,0.00000,0.00925,214.28468
61.80000,3.09010,18676.08428,0.00000,0.00927,214.66467
61.90000,3.09500,18703.59480,0.00000,0.00929,214.98088
62.00000,3.10009,18736.75436,0.00000,0.00931,215.36202
62.10000,3.10499,18765.70880,0.00000,0.00933,215.69483
62.20000,3.11013,18797.99068,0.00000,0.00934,216.06588
62.30000,3.11503,18828.83161,0.00000,0.00936,216.42037
62.40000,3.12005,18860.08084,0.00000,0.00938,216.77955
62.50000,3.12490,18888.01605,0.00000,0.00939,217.10064
62.60000,3.13010,18921.09662,0.00000,0.00942,217.48087
62.70000,3.13494,18948.70251,0.00000,0.00943,217.79817
62.80000,3.14008,18980.32129,0.00000,0.00945,218.16160
62.90000,3.14493,19010.44250,0.00000,0.00947,218.50782
63.00000,3.15001,19043.05518,0.00000,0.00949,218.88267
63.10000,3.15497,19073.45802,0.00000,0.00951,219.23213
63.20000,3.16011,19104.63423,0.00000,0.00952,219.59047
63.30000,3.16490,19133.09842,0.00000,0.00954,219.91764
63.40000,3.17004,19164.21056,0.00000,0.00956,220.27524
63.50000,3.17488,19195.50747,0.00000,0.00957,220.63497
63.60000,3.18002,19226.42589,0.00000,0.00959,220.99035
63.70000,3.18499,19257.34729,0.00000,0.00961,221.34577
63.80000,3.18995,19285.77423,0.00000,0.00963,221.67251
63.90000,3.19491,19318.12316,0.00000,0.00965,222.04433
64.00000,3.19999,19348.59753,0.00000,0.00967,222.39461
64.10000,3.20502,19380.83172,0.00000,0.00968,222.76511
64.20000,3.21004,19409.81001,0.00000,0.00970,223.09819
64.30000,3.21506,19442.04718,0.00000,0.00972,223.46872
64.40000,3.21990,19469.14196,0.00000,0.00974,223.78015
64.50000,3.22510,19503.14343,0.00000,0.00976,224.17097
64.60000,3.22995,19530.28291,0.00000,0.00977,224.48291
64.70000,3.23509,19561.88977,0.00000,0.00979,224.84621
64.80000,3.23987,19589.58358,0.00000,0.00981,225.16452
64.90000,3.24501,19623.10225,0.00000,0.00983,225.54979
65.00000,3.24986,19652.78834,0.00000,0.00985,225.89100
65.10000,3.25512,19685.41443,0.00000,0.00986,226.26601
65.20000,3.25990,19714.62220,0.00000,0.00988,226.60173
65.30000,3.26504,19745.41545,0.00000,0.00990,226.95567
65.40000,3.26989,19774.72454,0.00000,0.00991,227.29255
65.50000,3.27503,19805.15420,0.00000,0.00993,227.64231
65.60000,3.27999,19838.09322,0.00000,0.00995,228.02091
65.70000,3.28501,19867.65712,0.00000,0.00997,228.36073
65.80000,3.28992,19898.06294,0.00000,0.00998,228.71021
65.90000,3.29500,19927.69837,0.00000,0.01000,229.05084
66.00000,3.29996,19959.46467,0.00000,0.01002,229.41597
66.10000,3.30504,19988.59346,0.00000,0.01004,229.75078
66.20000,3.31001,20018.97544,0.00000,0.01006,230.09999
66.30000,3.31503,20047.66613,0.00000,0.01007,230.42977
66.40000,3.32005,20081.28613,0.00000,0.01009,230.81620
66.50000,3.32501,20108.06352,0.00000,0.01011,231.12398
66.60000,3.33010,20139.90730,0.00000,0.01013,231.48999
66.70000,3.33500,20167.29861,0.00000,0.01015,231.80483
66.80000,3.34002,20199.76377,0.00000,0.01017,232.17799
66.90000,3.34492,20229.70021,0.00000,0.01018,232.52208
67.00000,3.35012,20262.51256,0.00000,0.01020,232.89923
67.10000,3.35497,20292.10329,0.00000,0.01022,233.23935
67.20000,3.36005,20323.67587,0.00000,0.01024,233.60225
67.30000,3.36495,20353.07139,0.00000,0.01025,233.94012
67.40000,3.37009,20384.61119,0.00000,0.01027,234.30264
67.50000,3.37500,20413.13499,0.00000,0.01029,234.63050
67.60000,3.38008,20445.14567,0.00000,0.01031,234.99843
67.70000,3.38486,20472.36264,0.00000,0.01033,235.31127
67.80000,3.39006,20506.26725,0.00000,0.01035,235.70097
67.90000,3.39491,20535.01308,0.00000,0.01036,236.03138
68.00000,3.40005,20565.93299,0.00000,0.01038,236.38677
68.10000,3.40501,20595.31808,0.00000,0.01040,236.72453
68.20000,3.41003,20623.55876,0.00000,0.01042,237.04913
68.30000,3.41494,20656.33833,0.00000,0.01044,237.42590
68.40000,3.42008,20684.78614,0.00000,0.01045,237.75288
68.50000,3.42504,20716.93689,0.00000,0.01047,238.12243
68.60000,3.43000,20745.18502,0.00000,0.01048,238.44711
68.70000,3.43491,20776.70842,0.00000,0.01051,238.80945
68.80000,3.43993,20805.65393,0.00000,0.01052,239.14215
68.90000,3.44501,20837.93879,0.00000,0.01054,239.51323
69.00000,3.44991,20865.81737,0.00000,0.01056,239.83367
69.10000,3.45500,20897.71330,0.00000,0.01058,240.20029
69.20000,3.45990,20925.79603,0.00000,0.01059,240.52307
69.30000,3.46498,20957.21513,0.00000,0.01061,240.88421
69.40000,3.46988,20985.55118,0.00000,0.01063,241.20990
69.50000,3.47508,21016.37870,0.00000,0.01065,241.56424
69.60000,3.47987,21044.53295,0.00000,0.01067,241.88785
69.70000,3.48501,21077.97563,0.00000,0.01069,242.27224
69.80000,3.48991,21105.56066,0.00000,0.01070,242.58931
69.90000,3.49505,21137.25990,0.00000,0.01072,242.95366
70.00000,3.49996,21167.03540,0.00000,0.01074,243.29590
70.10000,3.50498,21194.98998,0.00000,0.01076,243.61721
70.20000,3.50988,21225.92479,0.00000,0.01078,243.97278
70.30000,3.51496,21255.52446,0.00000,0.01079,244.31300
70.40000,3.51999,21286.40115,0.00000,0.01081,244.66790
70.50000,3.52501,21315.84585,0.00000,0.01083,245.00634
70.60000,3.52991,21345.76887,0.00000,0.01085,245.35028
70.70000,3.53499,21376.56808,0.00000,0.01087,245.70429
70.80000,3.54002,21406.73101,0.00000,0.01088,246.05099
70.90000,3.54504,21436.00285,0.00000,0.01090,246.38744
71.00000,3.55000,21466.05104,0.00000,0.01092,246.73282
71.10000,3.55502,21495.91595,0.00000,0.01094,247.07609
71.20000,3.55999,21528.04285,0.00000,0.01095,247.44536
71.30000,3.56501,21556.27459,0.00000,0.01097,247.76985
71.40000,3.57009,21586.73704,0.00000,0.01099,248.11999
71.50000,3.57493,21614.85404,0.00000,0.01102,248.44317
71.60000,3.58007,21647.25661,0.00000,0.01103,248.81561
71.70000,3.58498,21676.71323,0.00000,0.01105,249.15419
71.80000,3.59012,21708.97722,0.00000,0.01107,249.52503
71.90000,3.59490,21736.34768,0.00000,0.01109,249.83963
72.00000,3.59999,21767.43746,0.00000,0.01110,250.19698
72.10000,3.60483,21797.26511,0.00000,0.01112,250.53982
72.20000,3.61003,21829.58126,0.00000,0.01114,250.91127
72.30000,3.61487,21857.60438,0.00000,0.01116,251.23337
72.40000,3.62001,21889.01156,0.00000,0.01118,251.59436
72.50000,3.62480,21918.80941,0.00000,0.01119,251.93686
72.60000,3.63000,21950.89608,0.00000,0.01122,252.30567
72.70000,3.63490,21980.60751,0.00000,0.01123,252.64718
72.80000,3.64010,22011.67047,0.00000,0.01125,253.00422
72.90000,3.64495,22041.08834,0.00000,0.01127,253.34235
73.00000,3.65003,22071.54930,0.00000,0.01129,253.69247
73.10000,3.65493,22102.82385,0.00000,0.01131,254.05194
73.20000,3.66001,22132.19553,0.00000,0.01133,254.38954
73.30000,3.66504,22163.82325,0.00000,0.01134,254.75308
73.40000,3.66994,22190.88674,0.00000,0.01136,255.06415
73.50000,3.67496,22222.33564,0.00000,0.01138,255.42562
73.60000,3.67992,22249.65394,0.00000,0.01140,255.73962
73.70000,3.68501,22281.35169,0.00000,0.01141,256.10396
73.80000,3.68991,22308.20656,0.00000,0.01143,256.41263
73.90000,3.69505,22341.51363,0.00000,0.01145,256.79547
74.00000,3.69989,22369.91823,0.00000,0.01147,257.12195
74.10000,3.70509,22403.78261,0.00000,0.01149,257.51119
74.20000,3.70994,22431.67460,0.00000,0.01151,257.83178
74.30000,3.71508,22461.99399,0.00000,0.01152,258.18028
74.40000,3.71986,22490.49842,0.00000,0.01154,258.50791
74.50000,3.72501,22522.23343,0.00000,0.01156,258.87268
74.60000,3.72991,22551.54401,0.00000,0.01158,259.20957
74.70000,3.73505,22581.62349,0.00000,0.01159,259.55531
74.80000,3.73995,22609.58403,0.00000,0.01162,259.87669
74.90000,3.74503,22639.43106,0.00000,0.01163,260.21976
75.00000,3.74994,22670.68923,0.00000,0.01165,260.57904
75.10000,3.75508,22701.12634,0.00000,0.01167,260.92889
75.20000,3.76004,22730.39371,0.00000,0.01169,261.26529
75.30000,3.76500,22758.59863,0.00000,0.01170,261.58948
75.40000,3.76991,22789.23839,0.00000,0.01173,261.94166
75.50000,3.77505,22819.22102,0.00000,0.01174,262.28628
75.60000,3.78001,22848.68658,0.00000,0.01176,262.62496
75.70000,3.78503,22877.32661,0.00000,0.01177,262.95415
75.80000,3.78994,22908.01257,0.00000,0.01180,263.30686
75.90000,3.79490,22936.41269,0.00000,0.01181,263.63329
76.00000,3.79998,22969.97309,0.00000,0.01183,264.01904
76.10000,3.80500,22998.52371,0.00000,0.01185,264.34720
76.20000,3.81009,23031.02911,0.00000,0.01187,264.72082
76.30000,3.81493,23056.67996,0.00000,0.01188,265.01565
76.40000,3.82001,23089.81270,0.00000,0.01190,265.39649
76.50000,3.82491,23117.95354,0.00000,0.01192,265.71994
76.60000,3.83012,23150.68841,0.00000,0.01194,266.09620
76.70000,3.83490,23178.27195,0.00000,0.01196,266.41324
76.80000,3.84004,23208.59283,0.00000,0.01197,266.76176
76.90000,3.84488,23237.95706,0.00000,0.01199,267.09927
77.00000,3.85008,23268.57001,0.00000,0.01201,267.45114
77.10000,3.85499,23296.92543,0.00000,0.01202,267.77706
77.20000,3.86007,23329.01657,0.00000,0.01205,268.14592
77.30000,3.86491,23356.68057,0.00000,0.01206,268.46389
77.40000,3.86999,23387.90745,0.00000,0.01209,268.82281
77.50000,3.87496,23416.79782,0.00000,0.01210,269.15488
77.60000,3.88010,23446.66719,0.00000,0.01212,269.49820
77.70000,3.88494,23475.62611,0.00000,0.01214,269.83106
77.80000,3.88990,23503.80123,0.00000,0.01216,270.15491
77.90000,3.89493,23536.08906,0.00000,0.01218,270.52603
78.00000,3.90001,23565.55611,0.00000,0.01219,270.86472
78.10000,3.90497,23596.35085,0.00000,0.01221,271.21868
78.20000,3.90993,23624.75097,0.00000,0.01223,271.54512
78.30000,3.91496,23655.20149,0.00000,0.01225,271.89512
78.40000,3.91998,23683.41684,0.00000,0.01226,272.21943
78.50000,3.92512,23715.31576,0.00000,0.01229,272.58608
78.60000,3.92996,23741.37938,0.00000,0.01230,272.88565
78.70000,3.93505,23774.12021,0.00000,0.01232,273.26198
78.80000,3.93989,23801.90045,0.00000,0.01234,273.58129
78.90000,3.94503,23832.65346,0.00000,0.01235,273.93477
79.00000,3.94993,23861.04763,0.00000,0.01237,274.26113
79.10000,3.95507,23891.36553,0.00000,0.01239,274.60961
79.20000,3.95986,23918.55419,0.00000,0.01241,274.92212
79.30000,3.96500,23951.20114,0.00000,0.01243,275.29737
79.40000,3.96996,23980.08406,0.00000,0.01245,275.62935
79.50000,3.97510,24011.40034,0.00000,0.01247,275.98930
79.60000,3.97995,24039.68871,0.00000,0.01249,276.31445
79.70000,3.98497,24069.37182,0.00000,0.01251,276.65563
79.80000,3.98993,24099.36041,0.00000,0.01252,277.00032
79.90000,3.99507,24128.97646,0.00000,0.01254,277.34073
80.00000,3.99998,24159.75034,0.00000,0.01256,277.69445
80.10000,4.00500,24188.91490,0.00000,0.01258,278.02967
80.20000,4.00990,24219.63066,0.00000,0.01260,278.38272
80.30000,4.01504,24248.38543,0.00000,0.01262,278.71323
80.40000,4.02001,24278.50217,0.00000,0.01263,279.05939
80.50000,4.02509,24306.02759,0.00000,0.01265,279.37577
80.60000,4.02999,24335.93571,0.00000,0.01267,279.71954
80.70000,4.03495,24363.80237,0.00000,0.01268,280.03984
80.80000,4.03998,24395.61337,0.00000,0.01270,280.40548
80.90000,4.04500,24424.62444,0.00000,0.01272,280.73894
81.00000,4.05002,24455.70976,0.00000,0.01274,281.09623
81.10000,4.05486,24482.37538,0.00000,0.01276,281.40273
81.20000,4.06001,24515.17582,0.00000,0.01278,281.77974
81.30000,4.06485,24542.47326,0.00000,0.01279,282.09350
81.40000,4.07005,24574.10097,0.00000,0.01281,282.45703
81.50000,4.07489,24602.39083,0.00000,0.01283,282.78220
81.60000,4.08003,24633.60727,0.00000,0.01285,283.14101
81.70000,4.08488,24661.98802,0.00000,0.01287,283.46722
81.80000,4.09008,24693.56060,0.00000,0.01288,283.83011
81.90000,4.09492,24721.33487,0.00000,0.01290,284.14936
82.00000,4.10000,24750.24760,0.00000,0.01292,284.48168
82.10000,4.10485,24779.95306,0.00000,0.01293,284.82312
82.20000,4.10993,24809.86565,0.00000,0.01295,285.16694
82.30000,4.11495,24840.36088,0.00000,0.01297,285.51745
82.40000,4.12003,24869.04263,0.00000,0.01299,285.84712
82.50000,4.12488,24897.85403,0.00000,0.01301,286.17828
82.60000,4.12996,24926.48959,0.00000,0.01303,286.50742
82.70000,4.13492,24956.85071,0.00000,0.01305,286.85640
82.80000,4.14000,24985.70979,0.00000,0.01306,287.18811
82.90000,4.14497,25017.06481,0.00000,0.01308,287.54850
83.00000,4.14987,25043.30873,0.00000,0.01310,287.85015
83.10000,4.15501,25075.99592,0.00000,0.01312,288.22586
83.20000,4.15991,25102.32329,0.00000,0.01313,288.52847
83.30000,4.16506,25133.21042,0.00000,0.01316,288.88349
83.40000,4.16996,25160.61366,0.00000,0.01317,289.19847
83.50000,4.17498,25189.94212,0.00000,0.01319,289.53557
83.60000,4.17988,25219.21098,0.00000,0.01321,289.87199
83.70000,4.18508,25250.92661,0.00000,0.01323,290.23653
83.80000,4.18993,25278.29111,0.00000,0.01325,290.55106
83.90000,4.19507,25307.57785,0.00000,0.01327,290.88769
84.00000,4.19985,25336.03609,0.00000,0.01328,291.21479
84.10000,4.20500,25366.82189,0.00000,0.01330,291.56864
84.20000,4.20996,25396.60633,0.00000,0.01332,291.91099
84.30000,4.21516,25427.57094,0.00000,0.01334,292.26690
84.40000,4.21994,25455.47485,0.00000,0.01336,292.58763
84.50000,4.22496,25485.63480,0.00000,0.01338,292.93429
84.60000,4.22993,25515.92290,0.00000,0.01339,293.28242
84.70000,4.23507,25545.23945,0.00000,0.01341,293.61939
84.80000,4.24003,25575.41430,0.00000,0.01343,293.96622
84.90000,4.24499,25604.65932,0.00000,0.01345,294.30237
85.00000,4.24990,25636.31535,0.00000,0.01347,294.66623
85.10000,4.25498,25665.47692,0.00000,0.01349,295.00141
85.20000,4.26000,25695.32096,0.00000,0.01350,295.34444
85.30000,4.26502,25723.45138,0.00000,0.01353,295.66778
85.40000,4.26993,25753.58748,0.00000,0.01354,296.01416
85.50000,4.27495,25781.44372,0.00000,0.01356,296.33435
85.60000,4.28003,25812.71231,0.00000,0.01358,296.69375
85.70000,4.28499,25840.04402,0.00000,0.01360,297.00790
85.80000,4.29008,25871.20235,0.00000,0.01362,297.36604
85.90000,4.29486,25897.68767,0.00000,0.01364,297.67047
86.00000,4.30006,25930.02021,0.00000,0.01365,298.04210
86.10000,4.30496,25957.42941,0.00000,0.01367,298.35714
86.20000,4.31010,25986.49859,0.00000,0.01369,298.69127
86.30000,4.31489,26012.60543,0.00000,0.01371,298.99134
86.40000,4.32003,26044.72339,0.00000,0.01373,299.36051
86.50000,4.32481,26073.34554,0.00000,0.01375,299.68949
86.60000,4.33007,26104.70057,0.00000,0.01377,300.04989
86.70000,4.33492,26130.84018,0.00000,0.01378,300.35034
86.80000,4.33994,26160.96437,0.00000,0.01381,300.69659
86.90000,4.34478,26189.79216,0.00000,0.01382,301.02794
87.00000,4.34998,26220.94750,0.00000,0.01384,301.38604
87.10000,4.35501,26251.50084,0.00000,0.01386,301.73723
87.20000,4.36009,26278.53155,0.00000,0.01387,302.04792
87.30000,4.36493,26307.33550,0.00000,0.01389,302.37900
87.40000,4.36995,26335.65366,0.00000,0.01391,302.70449
87.50000,4.37504,26367.31267,0.00000,0.01393,303.06838
87.60000,4.38006,26394.54603,0.00000,0.01395,303.38140
87.70000,4.38502,26422.83142,0.00000,0.01397,303.70652
87.80000,4.38992,26450.87242,0.00000,0.01399,304.02882
87.90000,4.39501,26483.02913,0.00000,0.01401,304.39844
88.00000,4.39991,26509.70817,0.00000,0.01403,304.70509
88.10000,4.40517,26542.03176,0.00000,0.01404,305.07662
88.20000,4.40995,26567.02995,0.00000,0.01406,305.36395
88.30000,4.41504,26597.23461,0.00000,0.01408,305.71112
88.40000,4.41994,26625.51701,0.00000,0.01410,306.03620
88.50000,4.42508,26656.05247,0.00000,0.01412,306.38718
88.60000,4.42998,26684.80873,0.00000,0.01413,306.71771
88.70000,4.43501,26714.89418,0.00000,0.01415,307.06351
88.80000,4.43985,26741.07254,0.00000,0.01417,307.36441
88.90000,4.44505,26772.12656,0.00000,0.01419,307.72135
89.00000,4.44995,26799.71755,0.00000,0.01421,308.03848
89.10000,4.45509,26830.74772,0.00000,0.01422,308.39515
89.20000,4.45994,26858.02281,0.00000,0.01424,308.70865
89.30000,4.46502,26886.38866,0.00000,0.01426,309.03469
89.40000,4.46992,26915.16876,0.00000,0.01428,309.36549
89.50000,4.47512,26943.94588,0.00000,0.01430,309.69626
89.60000,4.47997,26971.82298,0.00000,0.01431,310.01668
89.70000,4.48499,26997.51854,0.00000,0.01433,310.31202
89.80000,4.48989,27027.42219,0.00000,0.01435,310.65574
89.90000,4.49503,27054.62277,0.00000,0.01437,310.96839
90.00000,4.50006,27085.27148,0.00000,0.01439,311.32067
90.10000,4.50496,27111.52434,0.00000,0.01440,311.62242
90.20000,4.50992,27140.78128,0.00000,0.01442,311.95870
90.30000,4.51494,27168.29777,0.00000,0.01444,312.27498
90.40000,4.52009,27199.37861,0.00000,0.01446,312.63222
90.50000,4.52505,27225.27385,0.00000,0.01448,312.92987
90.60000,4.53007,27255.89275,0.00000,0.01450,313.28180
90.70000,4.53485,27281.69858,0.00000,0.01452,313.57842
90.80000,4.54006,27311.05089,0.00000,0.01453,313.91580
90.90000,4.54490,27335.01792,0.00000,0.01454,314.19127
91.00000,4.55010,27352.32711,0.00000,0.01456,314.39023
91.08600,4.55423,27044.70158,0.00000,0.01451,310.85435
91.08800,4.55434,26482.39732,0.00000,0.01442,304.39117
91.09000,4.55452,25593.86492,0.00000,0.01443,294.17830
91.09200,4.55476,24469.22213,0.00000,0.01484,281.25155
91.09400,4.55512,23182.15519,0.00000,0.01586,266.45788
91.09600,4.55548,21770.24484,0.00000,0.01739,250.22925
91.09800,4.55602,20271.56204,0.00000,0.01917,233.00325
91.10000,4.55632,18725.39371,0.00000,0.02095,215.23144
91.10200,4.55686,17160.01481,0.00000,0.02256,197.23883
91.10400,4.55721,15597.49693,0.00000,0.02388,179.27910