File: scratch/college-stuff/ME Lab/ME lab Fall 2013/group16/group16.is_tens_RawData/Specimen_RawData_4.csv
Time,Extension,Load,Strain 2,Tensile strain,Tensile stress
(sec),(mm),(N),(mm/mm),(mm/mm),(MPa)
0.00000,0.00006,1.49040,0.00000,0.00000,0.01847
0.30000,0.01369,35.60772,0.00000,0.00001,0.44136
0.60000,0.02983,52.24008,0.00000,0.00001,0.64752
0.90000,0.04496,66.01620,0.00000,0.00001,0.81828
1.20000,0.06003,81.65603,0.00000,0.00001,1.01214
1.50000,0.07498,97.12870,0.00000,0.00001,1.20393
1.80000,0.09010,115.02533,0.00000,0.00000,1.42576
2.10000,0.10499,135.23762,0.00000,-0.00001,1.67629
2.40000,0.12006,158.43598,0.00000,-0.00001,1.96384
2.70000,0.13494,184.36478,0.00000,-0.00002,2.28523
3.00000,0.15001,214.85551,0.00000,-0.00002,2.66317
3.30000,0.16496,247.91018,0.00000,-0.00003,3.07289
3.60000,0.18003,284.40100,0.00000,-0.00004,3.52520
3.90000,0.19503,326.58777,0.00000,-0.00004,4.04811
4.20000,0.20992,376.94692,0.00000,-0.00005,4.67232
4.50000,0.22505,433.70584,0.00000,-0.00005,5.37586
4.80000,0.23988,499.79887,0.00000,-0.00006,6.19509
5.10000,0.25506,579.02955,0.00000,-0.00006,7.17717
5.40000,0.27001,669.25422,0.00000,-0.00007,8.29552
5.70000,0.28502,782.39962,0.00000,-0.00007,9.69797
6.00000,0.30008,920.42843,0.00000,-0.00006,11.40886
6.30000,0.31497,1077.47950,0.00000,-0.00004,13.35554
6.60000,0.33010,1249.44467,0.00000,-0.00002,15.48708
6.90000,0.34493,1423.47608,0.00000,0.00000,17.64422
7.20000,0.36005,1611.40542,0.00000,0.00002,19.97364
7.50000,0.37494,1799.85594,0.00000,0.00005,22.30952
7.80000,0.38995,2000.20820,0.00000,0.00008,24.79292
8.10000,0.40495,2205.59984,0.00000,0.00011,27.33878
8.40000,0.41996,2409.43190,0.00000,0.00014,29.86531
8.70000,0.43503,2623.61094,0.00000,0.00018,32.52010
9.00000,0.44986,2833.88644,0.00000,0.00021,35.12650
9.30000,0.46510,3049.50587,0.00000,0.00025,37.79914
9.60000,0.47987,3263.21758,0.00000,0.00028,40.44813
9.90000,0.49500,3473.87046,0.00000,0.00032,43.05921
10.20000,0.50994,3683.36588,0.00000,0.00036,45.65594
10.50000,0.52501,3890.49575,0.00000,0.00040,48.22335
10.80000,0.54008,4096.23496,0.00000,0.00043,50.77352
11.10000,0.55491,4297.07356,0.00000,0.00047,53.26295
11.40000,0.57009,4499.21750,0.00000,0.00051,55.76856
11.70000,0.58492,4694.21521,0.00000,0.00056,58.18559
12.00000,0.59999,4887.80998,0.00000,0.00062,60.58523
12.30000,0.61493,5074.79310,0.00000,0.00068,62.90291
12.60000,0.63006,5260.12629,0.00000,0.00072,65.20015
12.90000,0.64495,5438.15047,0.00000,0.00077,67.40679
13.20000,0.65996,5592.59802,0.00000,0.00081,69.32119
13.50000,0.67502,5744.52132,0.00000,0.00085,71.20431
13.80000,0.68991,5894.33424,0.00000,0.00089,73.06126
14.10000,0.70510,6043.75787,0.00000,0.00093,74.91339
14.40000,0.71993,6193.06937,0.00000,0.00098,76.76413
14.70000,0.73505,6340.57149,0.00000,0.00102,78.59245
15.00000,0.74994,6486.11337,0.00000,0.00107,80.39646
15.30000,0.76501,6628.97304,0.00000,0.00112,82.16723
15.60000,0.78007,6772.98158,0.00000,0.00116,83.95224
15.90000,0.79490,6902.75431,0.00000,0.00120,85.56080
16.20000,0.81003,7040.72788,0.00000,0.00123,87.27100
16.50000,0.82486,7174.46059,0.00000,0.00125,88.92864
16.80000,0.83998,7313.18668,0.00000,0.00128,90.64818
17.10000,0.85493,7451.01348,0.00000,0.00131,92.35656
17.40000,0.87000,7589.04889,0.00000,0.00133,94.06753
17.70000,0.88494,7729.68754,0.00000,0.00136,95.81077
18.00000,0.89995,7867.89134,0.00000,0.00138,97.52383
18.30000,0.91502,8011.42529,0.00000,0.00141,99.30296
18.60000,0.92991,8150.08432,0.00000,0.00143,101.02166
18.90000,0.94503,8293.07064,0.00000,0.00146,102.79400
19.20000,0.95986,8435.35587,0.00000,0.00148,104.55765
19.50000,0.97499,8576.97874,0.00000,0.00151,106.31309
19.80000,0.98993,8719.20362,0.00000,0.00154,108.07599
20.10000,1.00494,8861.08652,0.00000,0.00156,109.83465
20.40000,1.02001,9007.45466,0.00000,0.00159,111.64891
20.70000,1.03496,9147.22085,0.00000,0.00162,113.38134
21.00000,1.05002,9297.92374,0.00000,0.00165,115.24933
21.30000,1.06491,9439.25083,0.00000,0.00168,117.00110
21.60000,1.08004,9588.52246,0.00000,0.00170,118.85135
21.90000,1.09493,9735.79660,0.00000,0.00173,120.67683
22.20000,1.10999,9883.28606,0.00000,0.00176,122.50499
22.50000,1.12500,10033.54192,0.00000,0.00179,124.36744
22.80000,1.13995,10176.05066,0.00000,0.00182,126.13386
23.10000,1.15507,10329.21597,0.00000,0.00185,128.03237
23.40000,1.16984,10475.41797,0.00000,0.00188,129.84456
23.70000,1.18515,10627.73839,0.00000,0.00191,131.73260
24.00000,1.19992,10776.60620,0.00000,0.00194,133.57784
24.30000,1.21498,10927.53559,0.00000,0.00197,135.44864
24.60000,1.23005,11075.96979,0.00000,0.00200,137.28850
24.90000,1.24500,11223.74237,0.00000,0.00203,139.12017
25.20000,1.26000,11376.99932,0.00000,0.00206,141.01982
25.50000,1.27489,11526.22998,0.00000,0.00209,142.86956
25.80000,1.29008,11680.94501,0.00000,0.00212,144.78727
26.10000,1.30491,11827.20587,0.00000,0.00216,146.60020
26.40000,1.31997,11981.67875,0.00000,0.00219,148.51492
26.70000,1.33486,12134.06399,0.00000,0.00222,150.40376
27.00000,1.34999,12287.49603,0.00000,0.00225,152.30558
27.30000,1.36499,12442.34070,0.00000,0.00229,154.22490
27.60000,1.37994,12592.97431,0.00000,0.00232,156.09203
27.90000,1.39513,12749.04311,0.00000,0.00235,158.02653
28.20000,1.40990,12898.75209,0.00000,0.00238,159.88220
28.50000,1.42508,13053.10726,0.00000,0.00241,161.79546
28.80000,1.43991,13208.75585,0.00000,0.00244,163.72475
29.10000,1.45504,13364.30311,0.00000,0.00248,165.65278
29.40000,1.46998,13518.93097,0.00000,0.00251,167.56942
29.70000,1.48493,13670.67993,0.00000,0.00254,169.45037
30.00000,1.50000,13828.99582,0.00000,0.00257,171.41272
30.30000,1.51489,13981.30804,0.00000,0.00260,173.30066
30.60000,1.53001,14140.20061,0.00000,0.00263,175.27016
30.90000,1.54484,14293.40988,0.00000,0.00267,177.16921
31.20000,1.56003,14451.26086,0.00000,0.00270,179.12580
31.50000,1.57497,14608.60819,0.00000,0.00273,181.07615
31.80000,1.59004,14761.97541,0.00000,0.00277,182.97716
32.10000,1.60493,14920.34197,0.00000,0.00280,184.94014
32.40000,1.61994,15076.50763,0.00000,0.00284,186.87584
32.70000,1.63512,15234.01439,0.00000,0.00287,188.82817
33.00000,1.64989,15388.98051,0.00000,0.00291,190.74900
33.30000,1.66508,15545.62747,0.00000,0.00294,192.69066
33.60000,1.67997,15701.70969,0.00000,0.00297,194.62533
33.90000,1.69497,15858.49077,0.00000,0.00301,196.56866
34.20000,1.70998,16016.12121,0.00000,0.00305,198.52251
34.50000,1.72499,16171.44346,0.00000,0.00308,200.44776
34.80000,1.73999,16330.71303,0.00000,0.00312,202.42193
35.10000,1.75488,16485.54802,0.00000,0.00316,204.34114
35.40000,1.77001,16645.01578,0.00000,0.00320,206.31776
35.70000,1.78490,16800.12047,0.00000,0.00323,208.24031
36.00000,1.80002,16958.04000,0.00000,0.00327,210.19775
36.30000,1.81497,17116.32311,0.00000,0.00331,212.15970
36.60000,1.83004,17271.26986,0.00000,0.00335,214.08029
36.90000,1.84510,17430.44108,0.00000,0.00339,216.05324
37.20000,1.85993,17581.57313,0.00000,0.00342,217.92655
37.50000,1.87512,17740.80098,0.00000,0.00346,219.90021
37.80000,1.88995,17894.62715,0.00000,0.00350,221.80691
38.10000,1.90501,18048.67983,0.00000,0.00354,223.71642
38.40000,1.91990,18204.03934,0.00000,0.00358,225.64212
38.70000,1.93497,18356.89396,0.00000,0.00362,227.53678
39.00000,1.94997,18512.65281,0.00000,0.00366,229.46744
39.30000,1.96492,18663.09047,0.00000,0.00370,231.33214
39.60000,1.97999,18819.40514,0.00000,0.00375,233.26969
39.90000,1.99494,18970.75474,0.00000,0.00379,235.14569
40.20000,2.01006,19124.02511,0.00000,0.00383,237.04550
40.50000,2.02495,19269.11026,0.00000,0.00388,238.84386
40.80000,2.04002,19419.88319,0.00000,0.00392,240.71271
41.10000,2.05496,19571.83778,0.00000,0.00396,242.59621
41.40000,2.07003,19711.60918,0.00000,0.00401,244.32870
41.70000,2.08498,19860.07988,0.00000,0.00406,246.16902
42.00000,2.09993,19999.30739,0.00000,0.00411,247.89477
42.30000,2.11505,20142.59696,0.00000,0.00417,249.67087
42.60000,2.12988,20278.05597,0.00000,0.00421,251.34991
42.90000,2.14501,20418.92707,0.00000,0.00427,253.09603
43.20000,2.15996,20551.70983,0.00000,0.00433,254.74189
43.50000,2.17496,20683.03227,0.00000,0.00438,256.36966
43.80000,2.19003,20813.61413,0.00000,0.00444,257.98824
44.10000,2.20492,20931.79226,0.00000,0.00450,259.45308
44.40000,2.22004,21058.07811,0.00000,0.00456,261.01841
44.70000,2.23493,21166.98027,0.00000,0.00463,262.36827
45.00000,2.25000,21282.85319,0.00000,0.00470,263.80454
45.30000,2.26489,21383.89200,0.00000,0.00477,265.05693
45.60000,2.28007,21484.28410,0.00000,0.00485,266.30131
45.90000,2.29496,21576.45822,0.00000,0.00493,267.44382
46.20000,2.31003,21659.17009,0.00000,0.00501,268.46905
46.50000,2.32503,21741.81342,0.00000,0.00510,269.49343
46.80000,2.33992,21810.38558,0.00000,0.00519,270.34339
47.10000,2.35511,21880.22435,0.00000,0.00529,271.20905
47.40000,2.36994,21936.80853,0.00000,0.00539,271.91042
47.70000,2.38506,21992.02627,0.00000,0.00550,272.59486
48.00000,2.39995,22041.40574,0.00000,0.00560,273.20692
48.30000,2.41496,22086.62480,0.00000,0.00572,273.76742
48.60000,2.42996,22128.23927,0.00000,0.00584,274.28324
48.90000,2.44497,22164.25836,0.00000,0.00596,274.72970
49.20000,2.45998,22198.75306,0.00000,0.00609,275.15727
49.50000,2.47493,22230.01570,0.00000,0.00622,275.54478
49.80000,2.49005,22264.72944,0.00000,0.00636,275.97506
50.10000,2.50494,22288.91104,0.00000,0.00650,276.27479
50.40000,2.52013,22316.08331,0.00000,0.00664,276.61160
50.70000,2.53495,22339.86706,0.00000,0.00678,276.90640
51.00000,2.55002,22359.01505,0.00000,0.00693,277.14374
51.30000,2.56503,22384.24569,0.00000,0.00708,277.45648
51.60000,2.57992,22401.76797,0.00000,0.00724,277.67367
51.90000,2.59510,22424.50714,0.00000,0.00740,277.95553
52.20000,2.60993,22441.43784,0.00000,0.00756,278.16539
52.50000,2.62506,22459.60683,0.00000,0.00772,278.39060
52.80000,2.63995,22474.49458,0.00000,0.00788,278.57513
53.10000,2.65495,22492.05709,0.00000,0.00805,278.79282
53.40000,2.67002,22507.99686,0.00000,0.00822,278.99040
53.70000,2.68497,22519.66000,0.00000,0.00840,279.13497
54.00000,2.70003,22536.68904,0.00000,0.00857,279.34604
54.30000,2.71498,22547.13476,0.00000,0.00875,279.47552
54.60000,2.73005,22560.46236,0.00000,0.00892,279.64072
54.90000,2.74488,22573.01062,0.00000,0.00910,279.79626
55.20000,2.76012,22587.92520,0.00000,0.00928,279.98112
55.50000,2.77501,22601.34071,0.00000,0.00946,280.14741
55.80000,2.78996,22610.60476,0.00000,0.00965,280.26224
56.10000,2.80508,22626.55795,0.00000,0.00983,280.45998
56.40000,2.81997,22635.20658,0.00000,0.01001,280.56719
56.70000,2.83510,22647.85022,0.00000,0.01020,280.72391
57.00000,2.84987,22656.23957,0.00000,0.01039,280.82789
57.30000,2.86493,22670.96937,0.00000,0.01058,281.01047
57.60000,2.88000,22678.50786,0.00000,0.01076,281.10391
57.90000,2.89495,22688.56317,0.00000,0.01095,281.22855
58.20000,2.91001,22699.21899,0.00000,0.01113,281.36063
58.50000,2.92502,22707.96001,0.00000,0.01132,281.46898
58.80000,2.94009,22721.50815,0.00000,0.01152,281.63691
59.10000,2.95498,22725.69090,0.00000,0.01170,281.68875
59.40000,2.97010,22738.86353,0.00000,0.01189,281.85203
59.70000,2.98493,22744.58855,0.00000,0.01207,281.92299
60.00000,3.00012,22756.14291,0.00000,0.01225,282.06621
60.30000,3.01500,22765.22517,0.00000,0.01244,282.17879
60.60000,3.02989,22770.40333,0.00000,0.01263,282.24297
60.90000,3.04508,22784.67119,0.00000,0.01282,282.41982
61.20000,3.05991,22790.66741,0.00000,0.01300,282.49415
61.50000,3.07503,22798.90925,0.00000,0.01318,282.59631
61.80000,3.08992,22806.08267,0.00000,0.01337,282.68522
62.10000,3.10505,22816.02919,0.00000,0.01355,282.80851
62.40000,3.11999,22823.75693,0.00000,0.01374,282.90430
62.70000,3.13506,22832.75574,0.00000,0.01391,283.01584
63.00000,3.15007,22842.95857,0.00000,0.01409,283.14231
63.30000,3.16502,22847.53323,0.00000,0.01427,283.19901
63.60000,3.18008,22859.51823,0.00000,0.01446,283.34757
63.90000,3.19491,22862.21385,0.00000,0.01464,283.38098
64.20000,3.21010,22875.11826,0.00000,0.01482,283.54093
64.50000,3.22487,22881.01017,0.00000,0.01500,283.61396
64.80000,3.24005,22889.54556,0.00000,0.01517,283.71976
65.10000,3.25500,22898.68593,0.00000,0.01535,283.83306
65.40000,3.26995,22902.68689,0.00000,0.01553,283.88265
65.70000,3.28507,22914.20549,0.00000,0.01571,284.02542
66.00000,3.29990,22919.71296,0.00000,0.01589,284.09369
66.30000,3.31503,22928.79671,0.00000,0.01607,284.20628
66.60000,3.32992,22935.53203,0.00000,0.01624,284.28977
66.90000,3.34498,22943.65317,0.00000,0.01641,284.39043
67.20000,3.35999,22948.95351,0.00000,0.01659,284.45613
67.50000,3.37506,22957.04484,0.00000,0.01676,284.55642
67.80000,3.39006,22965.61301,0.00000,0.01693,284.66263
68.10000,3.40501,22970.36797,0.00000,0.01710,284.72157
68.40000,3.42008,22982.07581,0.00000,0.01728,284.86669
68.70000,3.43497,22984.98899,0.00000,0.01745,284.90280
69.00000,3.45015,22995.55540,0.00000,0.01763,285.03377
69.30000,3.46492,23001.83177,0.00000,0.01780,285.11157
69.60000,3.48011,23008.65799,0.00000,0.01797,285.19618
69.90000,3.49499,23017.41093,0.00000,0.01813,285.30467
70.20000,3.50994,23019.79959,0.00000,0.01830,285.33428
70.50000,3.52507,23030.23487,0.00000,0.01847,285.46363
70.80000,3.53996,23033.28216,0.00000,0.01864,285.50140
71.10000,3.55502,23043.56396,0.00000,0.01881,285.62884
71.40000,3.56997,23052.45697,0.00000,0.01898,285.73907
71.70000,3.58498,23057.54125,0.00000,0.01915,285.80209
72.00000,3.59993,23064.30489,0.00000,0.01931,285.88593
72.30000,3.61505,23071.78527,0.00000,0.01948,285.97865
72.60000,3.63000,23078.77094,0.00000,0.01965,286.06524
72.90000,3.64501,23084.52874,0.00000,0.01981,286.13661
73.20000,3.66007,23094.44100,0.00000,0.01998,286.25947
73.50000,3.67484,23096.15463,0.00000,0.02014,286.28071
73.80000,3.69003,23107.03993,0.00000,0.02030,286.41564
74.10000,3.70492,23113.07937,0.00000,0.02047,286.49050
74.40000,3.72004,23118.89976,0.00000,0.02064,286.56264
74.70000,3.73499,23127.51412,0.00000,0.02081,286.66942
75.00000,3.74988,23131.91742,0.00000,0.02097,286.72400
75.30000,3.76512,23140.64205,0.00000,0.02113,286.83214
75.60000,3.77989,23144.84417,0.00000,0.02129,286.88423
75.90000,3.79502,23151.67934,0.00000,0.02145,286.96895
76.20000,3.80997,23157.38946,0.00000,0.02161,287.03973
76.50000,3.82497,23165.77286,0.00000,0.02178,287.14364
76.80000,3.83992,23171.56941,0.00000,0.02194,287.21549
77.10000,3.85499,23179.72481,0.00000,0.02210,287.31658
77.40000,3.86999,23187.59710,0.00000,0.02226,287.41416
77.70000,3.88500,23190.11837,0.00000,0.02242,287.44541
78.00000,3.90007,23199.77134,0.00000,0.02258,287.56506
78.30000,3.91490,23203.98986,0.00000,0.02275,287.61735
78.60000,3.93008,23214.36554,0.00000,0.02291,287.74596
78.90000,3.94485,23220.12782,0.00000,0.02307,287.81738
79.20000,3.95998,23223.72347,0.00000,0.02322,287.86195
79.50000,3.97504,23232.68503,0.00000,0.02338,287.97303
79.80000,3.98993,23234.88146,0.00000,0.02354,288.00026
80.10000,4.00506,23244.44801,0.00000,0.02370,288.11884
80.40000,4.01989,23248.26419,0.00000,0.02386,288.16614
80.70000,4.03507,23257.73090,0.00000,0.02402,288.28348
81.00000,4.05002,23262.49182,0.00000,0.02418,288.34249
81.30000,4.06503,23271.15238,0.00000,0.02434,288.44984
81.60000,4.07998,23275.39474,0.00000,0.02450,288.50242
81.90000,4.09510,23282.55326,0.00000,0.02465,288.59116
82.20000,4.10999,23290.11858,0.00000,0.02482,288.68493
82.50000,4.12494,23294.19553,0.00000,0.02497,288.73546
82.80000,4.14006,23303.74122,0.00000,0.02513,288.85378
83.10000,4.15483,23303.00063,0.00000,0.02529,288.84460
83.40000,4.17008,23312.37793,0.00000,0.02545,288.96084
83.70000,4.18485,23317.89434,0.00000,0.02560,289.02921
84.00000,4.19997,23324.46873,0.00000,0.02576,289.11071
84.30000,4.21504,23333.94140,0.00000,0.02593,289.22812
84.60000,4.22999,23334.73414,0.00000,0.02608,289.23795
84.90000,4.24511,23342.28754,0.00000,0.02623,289.33157
85.20000,4.25994,23346.68189,0.00000,0.02638,289.38604
85.50000,4.27501,23353.83892,0.00000,0.02653,289.47475
85.80000,4.28996,23360.41927,0.00000,0.02669,289.55632
86.10000,4.30502,23368.57170,0.00000,0.02686,289.65737
86.40000,4.31991,23372.29997,0.00000,0.02702,289.70358
86.70000,4.33504,23376.07592,0.00000,0.02717,289.75039
87.00000,4.34998,23384.52041,0.00000,0.02732,289.85506
87.30000,4.36499,23388.10116,0.00000,0.02747,289.89944
87.60000,4.38006,23396.52181,0.00000,0.02763,290.00382
87.90000,4.39483,23399.60784,0.00000,0.02778,290.04207
88.20000,4.41007,23406.05706,0.00000,0.02794,290.12201
88.50000,4.42496,23412.27084,0.00000,0.02809,290.19903
88.80000,4.43997,23415.66384,0.00000,0.02825,290.24108
89.10000,4.45503,23424.33631,0.00000,0.02840,290.34858
89.40000,4.46998,23428.50864,0.00000,0.02855,290.40030
89.70000,4.48517,23435.96369,0.00000,0.02871,290.49270
90.00000,4.50000,23439.32241,0.00000,0.02886,290.53434
90.30000,4.51506,23446.48242,0.00000,0.02901,290.62309
90.60000,4.53001,23451.34318,0.00000,0.02916,290.68334
90.90000,4.54508,23459.63418,0.00000,0.02931,290.78610
91.20000,4.55996,23464.76912,0.00000,0.02946,290.84975
91.50000,4.57503,23470.08735,0.00000,0.02961,290.91567
91.80000,4.59004,23478.81496,0.00000,0.02977,291.02385
92.10000,4.60493,23478.67936,0.00000,0.02993,291.02217
92.40000,4.62005,23487.59919,0.00000,0.03008,291.13273
92.70000,4.63494,23491.45859,0.00000,0.03023,291.18057
93.00000,4.65007,23498.35336,0.00000,0.03038,291.26603
93.30000,4.66496,23504.46731,0.00000,0.03053,291.34182
93.60000,4.68002,23506.23310,0.00000,0.03067,291.36371
93.90000,4.69515,23514.84597,0.00000,0.03082,291.47046
94.20000,4.70998,23517.68613,0.00000,0.03097,291.50567
94.50000,4.72510,23525.55394,0.00000,0.03112,291.60319
94.80000,4.73993,23529.51169,0.00000,0.03127,291.65225
95.10000,4.75500,23535.96836,0.00000,0.03143,291.73228
95.40000,4.76995,23540.43573,0.00000,0.03157,291.78765
95.70000,4.78501,23544.64084,0.00000,0.03172,291.83978
96.00000,4.79996,23551.38659,0.00000,0.03187,291.92339
96.30000,4.81503,23554.51286,0.00000,0.03202,291.96214
96.60000,4.83003,23561.87552,0.00000,0.03217,292.05340
96.90000,4.84492,23564.42809,0.00000,0.03231,292.08504
97.20000,4.86017,23571.90847,0.00000,0.03246,292.17776
97.50000,4.87494,23573.66532,0.00000,0.03261,292.19954
97.80000,4.89006,23579.71370,0.00000,0.03275,292.27451
98.10000,4.90495,23586.28064,0.00000,0.03290,292.35591
98.40000,4.92002,23589.98209,0.00000,0.03305,292.40179
98.70000,4.93508,23597.80520,0.00000,0.03320,292.49876
99.00000,4.94991,23599.57248,0.00000,0.03334,292.52066
99.30000,4.96516,23606.02766,0.00000,0.03349,292.60068
99.60000,4.97993,23609.26867,0.00000,0.03363,292.64085
99.90000,4.99499,23616.59557,0.00000,0.03377,292.73167
100.20000,5.01000,23619.92598,0.00000,0.03392,292.77295
100.50000,5.02507,23625.91028,0.00000,0.03406,292.84712
100.80000,5.03996,23630.03343,0.00000,0.03421,292.89823
101.10000,5.05496,23632.69478,0.00000,0.03436,292.93122
101.40000,5.07003,23641.51180,0.00000,0.03451,293.04051
101.70000,5.08486,23641.15417,0.00000,0.03464,293.03607
102.00000,5.10004,23649.35875,0.00000,0.03479,293.13777
102.30000,5.11487,23652.33153,0.00000,0.03492,293.17462
102.60000,5.13006,23657.92096,0.00000,0.03507,293.24390
102.90000,5.14501,23662.99778,0.00000,0.03522,293.30683
103.20000,5.16001,23666.72605,0.00000,0.03536,293.35304
103.50000,5.17508,23675.31061,0.00000,0.03550,293.45945
103.80000,5.18991,23677.43701,0.00000,0.03564,293.48581
104.10000,5.20503,23684.31389,0.00000,0.03578,293.57105
104.40000,5.21992,23685.76229,0.00000,0.03593,293.58900
104.70000,5.23505,23693.73590,0.00000,0.03607,293.68783
105.00000,5.24994,23694.49735,0.00000,0.03622,293.69727
105.30001,5.26500,23701.52324,0.00000,0.03636,293.78436
105.60001,5.27989,23707.50904,0.00000,0.03650,293.85855
105.90001,5.29502,23708.55361,0.00000,0.03664,293.87150
106.20001,5.31002,23716.02654,0.00000,0.03678,293.96413
106.50001,5.32485,23714.42616,0.00000,0.03692,293.94429
106.80001,5.34010,23725.24589,0.00000,0.03707,294.07841
107.10001,5.35493,23729.15000,0.00000,0.03721,294.12680
107.40001,5.37005,23734.95102,0.00000,0.03736,294.19870
107.70001,5.38500,23738.58541,0.00000,0.03750,294.24375
108.00001,5.40001,23741.00834,0.00000,0.03764,294.27378
108.30001,5.41507,23747.46948,0.00000,0.03778,294.35387
108.60001,5.42990,23749.19802,0.00000,0.03791,294.37530
108.90001,5.44503,23755.49376,0.00000,0.03805,294.45333
109.20001,5.45998,23759.58413,0.00000,0.03820,294.50403
109.50001,5.47498,23764.08577,0.00000,0.03834,294.55983
109.80001,5.48993,23766.88868,0.00000,0.03848,294.59457
110.10001,5.50500,23771.82543,0.00000,0.03862,294.65577
110.40001,5.51994,23775.25419,0.00000,0.03876,294.69827
110.70001,5.53501,23780.69311,0.00000,0.03889,294.76568
111.00001,5.55002,23786.74448,0.00000,0.03903,294.84069
111.30001,5.56491,23786.65060,0.00000,0.03917,294.83953
111.60001,5.58009,23794.31725,0.00000,0.03932,294.93456
111.90001,5.59492,23797.71769,0.00000,0.03946,294.97671
112.20001,5.61005,23802.21933,0.00000,0.03960,295.03250
112.50001,5.62500,23807.39301,0.00000,0.03974,295.09663
112.80001,5.64000,23810.11993,0.00000,0.03987,295.13043
113.10001,5.65507,23816.56170,0.00000,0.04001,295.21028
113.40001,5.66990,23817.23076,0.00000,0.04015,295.21857
113.70001,5.68502,23823.30149,0.00000,0.04029,295.29382
114.00001,5.69991,23825.24014,0.00000,0.04043,295.31785
114.30001,5.71492,23831.47627,0.00000,0.04057,295.39515
114.60001,5.72999,23835.42508,0.00000,0.04071,295.44410
114.90001,5.74499,23838.43511,0.00000,0.04085,295.48140
115.20001,5.76000,23843.37783,0.00000,0.04099,295.54267
115.50001,5.77507,23845.99000,0.00000,0.04113,295.57505
115.80001,5.79013,23853.65665,0.00000,0.04127,295.67008
116.10001,5.80496,23855.41499,0.00000,0.04141,295.69187
116.40001,5.82009,23861.63175,0.00000,0.04155,295.76893
116.70001,5.83498,23866.82332,0.00000,0.04169,295.83328
117.00001,5.85010,23868.09587,0.00000,0.04182,295.84906
117.30001,5.86499,23873.37238,0.00000,0.04196,295.91446
117.60001,5.87994,23876.54036,0.00000,0.04211,295.95373
117.90001,5.89506,23882.11489,0.00000,0.04225,296.02282
118.20001,5.90989,23884.66746,0.00000,0.04239,296.05446
118.50001,5.92502,23888.87554,0.00000,0.04254,296.10662
118.80001,5.93997,23890.94830,0.00000,0.04267,296.13231
119.10001,5.95503,23896.39169,0.00000,0.04281,296.19979
119.40001,5.96998,23899.73998,0.00000,0.04295,296.24129
119.70001,5.98505,23903.99128,0.00000,0.04308,296.29398
120.00001,6.00000,23910.50756,0.00000,0.04322,296.37476
120.30001,6.01506,23911.32861,0.00000,0.04336,296.38493
120.60001,6.03007,23917.07748,0.00000,0.04351,296.45619
120.90001,6.04484,23917.05811,0.00000,0.04366,296.45595
121.20001,6.06014,23925.16732,0.00000,0.04380,296.55647
121.50001,6.07491,23928.04623,0.00000,0.04394,296.59215
121.80001,6.08998,23931.10096,0.00000,0.04408,296.63001
122.10001,6.10499,23937.17021,0.00000,0.04421,296.70524
122.40001,6.11999,23936.77235,0.00000,0.04436,296.70031
122.70001,6.13512,23942.38561,0.00000,0.04450,296.76989
123.00001,6.14989,23944.46433,0.00000,0.04464,296.79565
123.30001,6.16507,23949.34446,0.00000,0.04478,296.85614
123.60001,6.17996,23950.96719,0.00000,0.04492,296.87626
123.90001,6.19497,23955.97845,0.00000,0.04506,296.93837
124.20001,6.20998,23958.48036,0.00000,0.04520,296.96939
124.50001,6.22504,23962.02087,0.00000,0.04534,297.01327
124.80001,6.23999,23968.09757,0.00000,0.04549,297.08859
125.10001,6.25500,23969.21664,0.00000,0.04563,297.10246
125.40001,6.27006,23975.82084,0.00000,0.04576,297.18432
125.70001,6.28489,23975.68375,0.00000,0.04590,297.18262
126.00001,6.30014,23982.11211,0.00000,0.04604,297.26231
126.30001,6.31491,23983.23566,0.00000,0.04618,297.27623
126.60001,6.33003,23986.12648,0.00000,0.04632,297.31206
126.90001,6.34498,23991.06026,0.00000,0.04646,297.37322
127.20001,6.35987,23991.07963,0.00000,0.04661,297.37346
127.50001,6.37505,23998.36481,0.00000,0.04675,297.46376
127.80001,6.38994,23997.99675,0.00000,0.04688,297.45920
128.10001,6.40513,24004.23288,0.00000,0.04702,297.53650
128.40001,6.41996,24006.29669,0.00000,0.04716,297.56208
128.70001,6.43496,24011.03675,0.00000,0.04729,297.62083
129.00001,6.44997,24013.95589,0.00000,0.04744,297.65701
129.30001,6.46510,24016.65002,0.00000,0.04758,297.69041
129.60001,6.47998,24021.23064,0.00000,0.04771,297.74719
129.90001,6.49499,24020.73592,0.00000,0.04785,297.74105
130.20001,6.51006,24026.81559,0.00000,0.04799,297.81641
130.50001,6.52483,24027.66943,0.00000,0.04813,297.82700
130.80001,6.54013,24033.63585,0.00000,0.04827,297.90095
131.10001,6.55496,24035.53128,0.00000,0.04840,297.92445
131.40001,6.57003,24037.07653,0.00000,0.04855,297.94360
131.70001,6.58504,24041.00597,0.00000,0.04868,297.99230
132.00001,6.59992,24040.76904,0.00000,0.04882,297.98937
132.30001,6.61505,24047.48797,0.00000,0.04895,298.07265
132.60001,6.62994,24048.81418,0.00000,0.04909,298.08909
132.90001,6.64500,24053.62874,0.00000,0.04922,298.14877
133.20001,6.66001,24054.89385,0.00000,0.04936,298.16445
133.50001,6.67502,24059.85296,0.00000,0.04949,298.22592
133.80001,6.68991,24062.03896,0.00000,0.04964,298.25301
134.10001,6.70503,24066.29920,0.00000,0.04977,298.30582
134.40001,6.72004,24070.94389,0.00000,0.04991,298.36339
134.70001,6.73499,24069.24665,0.00000,0.05004,298.34235
135.00001,6.75011,24075.19966,0.00000,0.05018,298.41614
135.30001,6.76488,24076.56163,0.00000,0.05031,298.43302
135.60001,6.78007,24081.25550,0.00000,0.05044,298.49120
135.90001,6.79490,24084.51289,0.00000,0.05058,298.53158
136.20001,6.80990,24085.75714,0.00000,0.05072,298.54700
136.50001,6.82503,24090.80863,0.00000,0.05086,298.60962
136.80001,6.83992,24089.96224,0.00000,0.05099,298.59913
137.10001,6.85504,24095.66939,0.00000,0.05112,298.66987
137.40001,6.86993,24097.86284,0.00000,0.05126,298.69706
137.70001,6.88506,24104.37912,0.00000,0.05139,298.77783
138.00001,6.90001,24103.79946,0.00000,0.05153,298.77064
138.30001,6.91507,24108.64681,0.00000,0.05166,298.83072
138.60001,6.92996,24110.37385,0.00000,0.05180,298.85213
138.90001,6.94509,24112.28418,0.00000,0.05194,298.87581
139.20001,6.95997,24117.70672,0.00000,0.05207,298.94302
139.50001,6.97486,24117.56366,0.00000,0.05220,298.94125
139.80001,6.99011,24123.99054,0.00000,0.05234,299.02091
140.10001,7.00488,24122.51830,0.00000,0.05247,299.00266
140.40001,7.02006,24124.32730,0.00000,0.05260,299.02509
140.70001,7.03495,24129.16273,0.00000,0.05274,299.08502
141.00001,7.04996,24130.84656,0.00000,0.05288,299.10589
141.30001,7.06515,24137.99167,0.00000,0.05301,299.19446
141.60001,7.07997,24137.97379,0.00000,0.05315,299.19424
141.90001,7.09504,24139.83643,0.00000,0.05328,299.21732
142.20001,7.11005,24142.25787,0.00000,0.05342,299.24734
142.50001,7.12505,24145.91461,0.00000,0.05355,299.29266
142.80001,7.13994,24147.01730,0.00000,0.05368,299.30633
143.10001,7.15507,24151.35950,0.00000,0.05382,299.36016
143.40001,7.16996,24152.40407,0.00000,0.05396,299.37310
143.70001,7.18508,24154.89405,0.00000,0.05409,299.40397
144.00001,7.20003,24158.56570,0.00000,0.05422,299.44948
144.30001,7.21492,24157.95177,0.00000,0.05436,299.44187
144.60001,7.23010,24164.42633,0.00000,0.05449,299.52212
144.90001,7.24481,24163.79154,0.00000,0.05462,299.51425
145.20001,7.26006,24168.45560,0.00000,0.05476,299.57206
145.50001,7.27501,24170.68630,0.00000,0.05490,299.59971
145.80001,7.28995,24170.21394,0.00000,0.05504,299.59386
146.10001,7.30508,24176.79131,0.00000,0.05517,299.67539
146.40001,7.32003,24177.59746,0.00000,0.05530,299.68538
146.70001,7.33503,24181.20503,0.00000,0.05543,299.73010
147.00001,7.35004,24182.43140,0.00000,0.05556,299.74530
147.30001,7.36511,24187.17295,0.00000,0.05570,299.80407
147.60001,7.38000,24185.53382,0.00000,0.05584,299.78375
147.90001,7.39506,24189.64058,0.00000,0.05598,299.83466
148.20001,7.40995,24192.54780,0.00000,0.05612,299.87069
148.50001,7.42502,24192.59548,0.00000,0.05625,299.87128
148.80001,7.44003,24198.14169,0.00000,0.05638,299.94003
149.10001,7.45485,24193.84271,0.00000,0.05652,299.88674
149.40001,7.47004,24199.88066,0.00000,0.05665,299.96158
149.70001,7.48493,24201.66433,0.00000,0.05678,299.98369
150.00001,7.49999,24204.01871,0.00000,0.05692,300.01288
150.30001,7.51500,24207.84533,0.00000,0.05705,300.06031
150.60001,7.53001,24209.00613,0.00000,0.05719,300.07469
150.90001,7.54513,24213.59122,0.00000,0.05732,300.13153
151.20001,7.56002,24212.66884,0.00000,0.05746,300.12009
151.50001,7.57503,24215.77275,0.00000,0.05760,300.15857
151.80001,7.59004,24217.21965,0.00000,0.05774,300.17650
152.10001,7.60504,24221.56185,0.00000,0.05787,300.23033
152.40001,7.61987,24219.76626,0.00000,0.05801,300.20807
152.70001,7.63506,24224.29621,0.00000,0.05814,300.26422
153.00001,7.64995,24226.19462,0.00000,0.05827,300.28775
153.30001,7.66501,24224.48695,0.00000,0.05840,300.26658
153.60001,7.68008,24231.81683,0.00000,0.05854,300.35744
153.90001,7.69491,24229.75153,0.00000,0.05867,300.33184
154.20001,7.71015,24234.81494,0.00000,0.05881,300.39460
154.50001,7.72492,24236.61500,0.00000,0.05895,300.41691
154.80001,7.73999,24236.88173,0.00000,0.05909,300.42022
155.10001,7.75506,24242.31172,0.00000,0.05923,300.48752
155.40001,7.77000,24242.30725,0.00000,0.05936,300.48747
155.70001,7.78507,24246.78206,0.00000,0.05950,300.54293
156.00001,7.79996,24244.53646,0.00000,0.05963,300.51510
156.30001,7.81508,24249.15582,0.00000,0.05977,300.57236
156.60001,7.82997,24247.36470,0.00000,0.05991,300.55016
156.90001,7.84504,24253.67385,0.00000,0.06004,300.62836
157.20001,7.85987,24252.66951,0.00000,0.06018,300.61591
157.50001,7.87505,24256.88058,0.00000,0.06032,300.66811
157.80001,7.89000,24258.48544,0.00000,0.06045,300.68800
158.10001,7.90495,24256.62428,0.00000,0.06059,300.66493
158.40001,7.92007,24261.81734,0.00000,0.06072,300.72930
158.70001,7.93484,24260.99926,0.00000,0.06086,300.71916
159.00001,7.95009,24265.90323,0.00000,0.06100,300.77994
159.30001,7.96492,24267.46339,0.00000,0.06114,300.79928
159.60001,7.98004,24270.56581,0.00000,0.06127,300.83774
159.90001,7.99505,24271.12013,0.00000,0.06141,300.84461
160.20001,8.01000,24272.61174,0.00000,0.06155,300.86310
160.50001,8.02507,24275.79761,0.00000,0.06168,300.90259
160.80001,8.03995,24276.26997,0.00000,0.06182,300.90844
161.10001,8.05496,24280.51978,0.00000,0.06196,300.96112
161.40001,8.06991,24278.92238,0.00000,0.06210,300.94132
161.70001,8.08503,24283.53429,0.00000,0.06224,300.99848
162.00001,8.09986,24281.36468,0.00000,0.06237,300.97159
162.30001,8.11505,24284.28233,0.00000,0.06251,301.00776
162.60001,8.12994,24289.99543,0.00000,0.06264,301.07857
162.90001,8.14494,24287.79900,0.00000,0.06278,301.05135
163.20001,8.16007,24293.39439,0.00000,0.06292,301.12070
163.50001,8.17484,24292.05477,0.00000,0.06306,301.10410
163.80001,8.19008,24297.35363,0.00000,0.06320,301.16978
164.10001,8.20497,24298.65003,0.00000,0.06334,301.18585
164.40001,8.22004,24299.30866,0.00000,0.06348,301.19401
164.70001,8.23499,24301.90742,0.00000,0.06362,301.22622
165.00001,8.25005,24304.10385,0.00000,0.06376,301.25345
165.30001,8.26506,24305.00239,0.00000,0.06390,301.26458
165.60001,8.28001,24305.19760,0.00000,0.06405,301.26700
165.90001,8.29501,24308.04670,0.00000,0.06418,301.30232
166.20001,8.31002,24307.31356,0.00000,0.06433,301.29323
166.50001,8.32503,24310.26697,0.00000,0.06447,301.32984
166.80001,8.33986,24310.32658,0.00000,0.06460,301.33058
167.10001,8.35504,24313.69275,0.00000,0.06475,301.37230
167.40001,8.36999,24315.96220,0.00000,0.06489,301.40043
167.70001,8.38494,24314.70603,0.00000,0.06503,301.38486
168.00001,8.40007,24320.84382,0.00000,0.06518,301.46094
168.30001,8.41489,24319.37754,0.00000,0.06532,301.44277
168.60001,8.43014,24322.26241,0.00000,0.06546,301.47853
168.90001,8.44491,24320.85276,0.00000,0.06560,301.46105
169.20001,8.46003,24323.66163,0.00000,0.06574,301.49587
169.50001,8.47504,24326.18886,0.00000,0.06589,301.52719
169.80001,8.48993,24325.10406,0.00000,0.06603,301.51375
170.10001,8.50500,24330.79332,0.00000,0.06618,301.58427
170.40001,8.51994,24329.47308,0.00000,0.06632,301.56790
170.70001,8.53501,24331.11370,0.00000,0.06647,301.58824
171.00001,8.54996,24329.63103,0.00000,0.06661,301.56986
171.30001,8.56496,24333.34440,0.00000,0.06675,301.61589
171.60001,8.57991,24335.17426,0.00000,0.06689,301.63857
171.90001,8.59504,24335.74796,0.00000,0.06704,301.64568
172.20001,8.60999,24339.49858,0.00000,0.06718,301.69217
172.50001,8.62493,24337.01903,0.00000,0.06733,301.66144
172.80001,8.64018,24342.68892,0.00000,0.06748,301.73172
173.10001,8.65495,24342.71127,0.00000,0.06762,301.73199
173.40001,8.67007,24344.22821,0.00000,0.06776,301.75080
173.70001,8.68496,24345.26831,0.00000,0.06791,301.76369
174.00001,8.70003,24345.64978,0.00000,0.06805,301.76842
174.30001,8.71498,24345.40391,0.00000,0.06820,301.76537
174.60001,8.72992,24346.55726,0.00000,0.06834,301.77966
174.90001,8.74505,24349.70737,0.00000,0.06849,301.81871
175.20001,8.75994,24347.38278,0.00000,0.06864,301.78990
175.50001,8.77500,24352.80383,0.00000,0.06878,301.85709
175.80001,8.78995,24351.83227,0.00000,0.06893,301.84505
176.10001,8.80502,24354.73800,0.00000,0.06907,301.88107
176.40001,8.81997,24356.12977,0.00000,0.06922,301.89832
176.70001,8.83509,24357.01787,0.00000,0.06937,301.90933
177.00001,8.85004,24360.79681,0.00000,0.06952,301.95617
177.30001,8.86499,24356.27431,0.00000,0.06966,301.90011
177.60001,8.88017,24361.20212,0.00000,0.06981,301.96119
177.90001,8.89494,24359.91317,0.00000,0.06995,301.94521
178.20001,8.91007,24361.69088,0.00000,0.07011,301.96725
178.50001,8.92496,24363.50286,0.00000,0.07026,301.98971
178.80001,8.94002,24363.83814,0.00000,0.07041,301.99386
179.10001,8.95503,24365.51750,0.00000,0.07056,302.01468
179.40001,8.96998,24363.96331,0.00000,0.07071,301.99542
179.70001,8.98505,24366.63657,0.00000,0.07085,302.02855
180.00001,8.99999,24365.11815,0.00000,0.07099,302.00973
180.30001,9.01506,24369.32772,0.00000,0.07114,302.06191
180.60001,9.02989,24368.90602,0.00000,0.07129,302.05668
180.90001,9.04501,24371.07265,0.00000,0.07145,302.08354
181.20001,9.05990,24372.11573,0.00000,0.07161,302.09647
181.50001,9.07515,24371.76853,0.00000,0.07176,302.09216
181.80001,9.09004,24373.19160,0.00000,0.07191,302.10980
182.10001,9.10492,24370.03255,0.00000,0.07206,302.07064
182.40001,9.12011,24376.08689,0.00000,0.07221,302.14569
182.70001,9.13494,24374.45372,0.00000,0.07236,302.12545
183.00001,9.15012,24377.11954,0.00000,0.07251,302.15849
183.30001,9.16495,24376.91838,0.00000,0.07266,302.15600
183.60001,9.18002,24377.62171,0.00000,0.07281,302.16471
183.90001,9.19503,24378.92705,0.00000,0.07297,302.18089
184.20001,9.20991,24377.62469,0.00000,0.07312,302.16475
184.50001,9.22498,24380.78672,0.00000,0.07327,302.20394
184.80001,9.23999,24380.55873,0.00000,0.07343,302.20112
185.10001,9.25505,24382.82818,0.00000,0.07358,302.22925
185.40001,9.26988,24381.46770,0.00000,0.07373,302.21239
185.70001,9.28501,24384.99629,0.00000,0.07389,302.25612
186.00001,9.29996,24385.88589,0.00000,0.07404,302.26715
186.30001,9.31508,24385.02908,0.00000,0.07419,302.25653
186.60001,9.33003,24387.81857,0.00000,0.07435,302.29111
186.90001,9.34498,24383.34525,0.00000,0.07452,302.23566
187.20001,9.36011,24386.85149,0.00000,0.07467,302.27912
187.50001,9.37487,24385.18852,0.00000,0.07482,302.25851
187.80001,9.39006,24387.97802,0.00000,0.07497,302.29308
188.10001,9.40501,24387.20316,0.00000,0.07513,302.28348
188.40001,9.42001,24388.64857,0.00000,0.07529,302.30139
188.70001,9.43502,24390.50674,0.00000,0.07545,302.32443
189.00001,9.44991,24389.16862,0.00000,0.07560,302.30784
189.30001,9.46504,24391.44850,0.00000,0.07576,302.33610
189.60001,9.47998,24391.39336,0.00000,0.07593,302.33542
189.90001,9.49505,24393.85802,0.00000,0.07608,302.36597
190.20001,9.50994,24389.79894,0.00000,0.07624,302.31565
190.50001,9.52506,24391.63029,0.00000,0.07640,302.33835
190.80001,9.53989,24391.66456,0.00000,0.07656,302.33878
191.10001,9.55508,24392.02815,0.00000,0.07672,302.34328
191.40001,9.57009,24396.81590,0.00000,0.07688,302.40263
191.70001,9.58491,24392.51095,0.00000,0.07705,302.34927
192.00001,9.60016,24393.91315,0.00000,0.07721,302.36665
192.30001,9.61493,24391.95961,0.00000,0.07737,302.34243
192.60001,9.62999,24393.31561,0.00000,0.07753,302.35924
192.90001,9.64494,24396.08723,0.00000,0.07769,302.39360
193.20001,9.65995,24395.15889,0.00000,0.07786,302.38209
193.50001,9.67502,24396.97832,0.00000,0.07802,302.40464
193.80001,9.68990,24394.03385,0.00000,0.07818,302.36814
194.10001,9.70503,24397.06177,0.00000,0.07835,302.40568
194.40001,9.71998,24394.91153,0.00000,0.07852,302.37902
194.70001,9.73510,24397.76808,0.00000,0.07869,302.41443
195.00001,9.74993,24393.62854,0.00000,0.07885,302.36312
195.30001,9.76506,24395.20061,0.00000,0.07902,302.38261
195.60001,9.77995,24395.76685,0.00000,0.07918,302.38963
195.90001,9.79507,24393.87888,0.00000,0.07935,302.36622
196.20001,9.81008,24398.14061,0.00000,0.07952,302.41905
196.50001,9.82485,24392.54522,0.00000,0.07969,302.34969
196.80001,9.84015,24396.75033,0.00000,0.07986,302.40182
197.10001,9.85486,24393.85653,0.00000,0.08003,302.36595
197.40001,9.86999,24393.40353,0.00000,0.08019,302.36033
197.70001,9.88494,24394.84596,0.00000,0.08036,302.37821
198.00001,9.90000,24393.62854,0.00000,0.08053,302.36312
198.30001,9.91501,24395.59102,0.00000,0.08070,302.38745
198.60001,9.92996,24393.90272,0.00000,0.08087,302.36652
198.90001,9.94509,24395.39284,0.00000,0.08105,302.38499
199.20001,9.96003,24392.81791,0.00000,0.08121,302.35307
199.50001,9.97510,24394.42575,0.00000,0.08139,302.37300
199.80001,9.98987,24391.83146,0.00000,0.08156,302.34085
200.10001,10.00511,24393.80586,0.00000,0.08174,302.36532
200.40001,10.01988,24393.55254,0.00000,0.08192,302.36218
200.70001,10.03501,24389.53817,0.00000,0.08209,302.31242
201.00001,10.05008,24393.75967,0.00000,0.08227,302.36475
201.30001,10.06490,24389.36383,0.00000,0.08245,302.31026
201.60001,10.08015,24391.82848,0.00000,0.08262,302.34081
201.90001,10.09492,24390.70791,0.00000,0.08281,302.32692
202.20001,10.10998,24391.35164,0.00000,0.08299,302.33490
202.50001,10.12499,24391.16985,0.00000,0.08317,302.33264
202.80001,10.14000,24388.94361,0.00000,0.08335,302.30505
203.10001,10.15501,24389.34296,0.00000,0.08353,302.31000
203.40001,10.17007,24386.13474,0.00000,0.08371,302.27023
203.70001,10.18502,24387.56526,0.00000,0.08390,302.28797
204.00001,10.20003,24386.16753,0.00000,0.08409,302.27064
204.30001,10.21509,24386.21223,0.00000,0.08427,302.27119
204.60001,10.22992,24383.02487,0.00000,0.08445,302.23169
204.90001,10.24511,24382.30962,0.00000,0.08465,302.22282
205.20001,10.25994,24382.18594,0.00000,0.08483,302.22129
205.50001,10.27500,24378.39061,0.00000,0.08502,302.17424
205.80001,10.29007,24380.77778,0.00000,0.08521,302.20383
206.10001,10.30484,24375.79036,0.00000,0.08540,302.14201
206.40001,10.32008,24376.77383,0.00000,0.08559,302.15420
206.70001,10.33497,24376.16736,0.00000,0.08579,302.14669
207.00001,10.34998,24375.07361,0.00000,0.08598,302.13313
207.30001,10.36505,24375.58472,0.00000,0.08617,302.13946
207.60001,10.38005,24373.35998,0.00000,0.08637,302.11189
207.90001,10.39500,24371.30511,0.00000,0.08657,302.08642
208.20001,10.41007,24368.29209,0.00000,0.08676,302.04907
208.50001,10.42502,24369.02672,0.00000,0.08697,302.05818
208.80001,10.43996,24363.23762,0.00000,0.08716,301.98642
209.10001,10.45509,24365.48620,0.00000,0.08737,302.01429
209.40001,10.46986,24360.56435,0.00000,0.08757,301.95328
209.70001,10.48504,24358.99526,0.00000,0.08776,301.93384
210.00001,10.49999,24358.13695,0.00000,0.08796,301.92320
210.30001,10.51494,24351.72051,0.00000,0.08817,301.84366
210.60001,10.53007,24355.78406,0.00000,0.08838,301.89403
210.90001,10.54483,24351.50743,0.00000,0.08858,301.84102
211.20001,10.56008,24349.98602,0.00000,0.08879,301.82216
211.50001,10.57497,24347.18609,0.00000,0.08900,301.78746
211.80001,10.58997,24342.91840,0.00000,0.08921,301.73456
212.10001,10.60510,24341.93492,0.00000,0.08942,301.72237
212.40001,10.62005,24337.70597,0.00000,0.08964,301.66995
212.70001,10.63500,24334.98055,0.00000,0.08985,301.63617
213.00001,10.65006,24331.60841,0.00000,0.09007,301.59437
213.30001,10.66507,24329.06777,0.00000,0.09028,301.56288
213.60001,10.67996,24319.56530,0.00000,0.09050,301.44509
213.90001,10.69508,24321.13290,0.00000,0.09072,301.46453
214.20001,10.70991,24314.66430,0.00000,0.09094,301.38435
214.50001,10.72510,24313.23975,0.00000,0.09116,301.36669
214.80001,10.73999,24310.38767,0.00000,0.09138,301.33134
215.10001,10.75493,24301.25326,0.00000,0.09160,301.21811
215.40001,10.77012,24301.13554,0.00000,0.09182,301.21665
215.70001,10.78483,24292.59419,0.00000,0.09204,301.11078
216.00001,10.80007,24288.97917,0.00000,0.09227,301.06597
216.30001,10.81496,24282.96655,0.00000,0.09249,300.99145
216.60001,10.83003,24277.85546,0.00000,0.09272,300.92809
216.90001,10.84504,24271.17974,0.00000,0.09294,300.84535
217.20001,10.86004,24263.85880,0.00000,0.09316,300.75460
217.50001,10.87499,24261.18851,0.00000,0.09339,300.72150
217.80001,10.89000,24253.58593,0.00000,0.09361,300.62727
218.10001,10.90507,24248.40331,0.00000,0.09384,300.56303
218.40001,10.91989,24236.91750,0.00000,0.09406,300.42066
218.70001,10.93508,24233.26969,0.00000,0.09428,300.37545
219.00001,10.94997,24224.10399,0.00000,0.09449,300.26184
219.30001,10.96503,24213.94587,0.00000,0.09471,300.13592
219.60001,10.97998,24209.98663,0.00000,0.09493,300.08685
219.90001,10.99493,24197.01368,0.00000,0.09514,299.92605
220.20001,11.01012,24191.48237,0.00000,0.09536,299.85748
220.50001,11.02488,24179.24255,0.00000,0.09557,299.70577
220.80001,11.04007,24170.21543,0.00000,0.09577,299.59388
221.10001,11.05496,24158.38689,0.00000,0.09598,299.44726
221.40001,11.06996,24147.19611,0.00000,0.09617,299.30855
221.70001,11.08497,24133.59284,0.00000,0.09637,299.13993
222.00001,11.10004,24120.82106,0.00000,0.09656,298.98163
222.30001,11.11499,24106.86463,0.00000,0.09675,298.80863
222.60001,11.12999,24089.02049,0.00000,0.09692,298.58745
222.90001,11.14506,24075.55282,0.00000,0.09709,298.42052
223.20001,11.15989,24052.86878,0.00000,0.09725,298.13935
223.50001,11.17502,24037.49228,0.00000,0.09741,297.94875
223.80001,11.18990,24013.04096,0.00000,0.09755,297.64567
224.10001,11.20503,23987.34540,0.00000,0.09768,297.32717
224.40001,11.22004,23963.74494,0.00000,0.09781,297.03464
224.70001,11.23492,23931.38111,0.00000,0.09792,296.63349
225.00001,11.25011,23897.90714,0.00000,0.09802,296.21857
225.30001,11.26494,23802.80048,0.00000,0.09807,295.03971
225.38401,11.26954,22205.25146,0.00000,0.09441,275.23782
225.39001,11.27038,18903.34189,0.00000,0.08547,234.31010
225.39601,11.27140,14892.60942,0.00000,0.07496,184.59639
225.39801,11.27175,13535.03615,0.00000,0.07123,167.76905