File: scratch/college-stuff/ME Lab/ME lab Fall 2013/group7/group7.is_tens_RawData/Specimen_RawData_3.csv
Time,Extension,Load,Strain 2,Tensile strain,Tensile stress
(sec),(mm),(N),(mm/mm),(mm/mm),(MPa)
0.00000,0.00000,-0.32163,0.00000,0.00000,-0.00398
0.10000,0.00167,1.04247,0.00000,0.00000,0.01289
0.20000,0.00735,4.83762,0.00000,0.00001,0.05981
0.30000,0.01357,9.47068,0.00000,0.00001,0.11710
0.40000,0.01943,13.14867,0.00000,0.00002,0.16257
0.50000,0.02469,17.41302,0.00000,0.00002,0.21530
0.60000,0.03001,19.19551,0.00000,0.00002,0.23734
0.70000,0.03498,21.55093,0.00000,0.00002,0.26646
0.80000,0.04012,24.50783,0.00000,0.00002,0.30302
0.90000,0.04496,25.78645,0.00000,0.00002,0.31883
1.00000,0.05004,27.48478,0.00000,0.00002,0.33983
1.10000,0.05501,28.00096,0.00000,0.00002,0.34621
1.20000,0.06009,30.13099,0.00000,0.00003,0.37254
1.30000,0.06499,31.25823,0.00000,0.00002,0.38648
1.40000,0.07001,32.62193,0.00000,0.00002,0.40334
1.50000,0.07498,34.02196,0.00000,0.00002,0.42065
1.60000,0.08006,34.68070,0.00000,0.00002,0.42880
1.70000,0.08508,35.74253,0.00000,0.00002,0.44192
1.80000,0.08998,36.01990,0.00000,0.00002,0.44535
1.90000,0.09501,36.90916,0.00000,0.00002,0.45635
2.00000,0.09997,37.95442,0.00000,0.00002,0.46927
2.10000,0.10511,38.53097,0.00000,0.00002,0.47640
2.20000,0.10995,40.15924,0.00000,0.00002,0.49653
2.30000,0.11509,42.74414,0.00000,0.00002,0.52849
2.40000,0.11988,45.21729,0.00000,0.00003,0.55907
2.50000,0.12508,48.66266,0.00000,0.00002,0.60167
2.60000,0.12992,51.81300,0.00000,0.00003,0.64062
2.70000,0.13512,54.95528,0.00000,0.00003,0.67947
2.80000,0.13991,57.85548,0.00000,0.00003,0.71533
2.90000,0.14505,60.60928,0.00000,0.00003,0.74938
3.00000,0.14995,63.21160,0.00000,0.00003,0.78156
3.10000,0.15509,65.44999,0.00000,0.00004,0.80923
3.20000,0.16000,69.39173,0.00000,0.00004,0.85797
3.30000,0.16502,73.90109,0.00000,0.00004,0.91372
3.40000,0.16992,78.23395,0.00000,0.00004,0.96729
3.50000,0.17500,81.29495,0.00000,0.00005,1.00514
3.60000,0.17997,83.38385,0.00000,0.00004,1.03097
3.70000,0.18499,87.76047,0.00000,0.00005,1.08508
3.80000,0.19001,90.64893,0.00000,0.00004,1.12079
3.90000,0.19503,93.16204,0.00000,0.00005,1.15187
4.00000,0.20006,97.88808,0.00000,0.00005,1.21030
4.10000,0.20502,103.93524,0.00000,0.00005,1.28507
4.20000,0.21004,110.93641,0.00000,0.00005,1.37163
4.30000,0.21494,119.87187,0.00000,0.00006,1.48211
4.40000,0.22009,131.08933,0.00000,0.00007,1.62080
4.50000,0.22499,141.41331,0.00000,0.00008,1.74845
4.60000,0.23013,154.11549,0.00000,0.00009,1.90550
4.70000,0.23491,166.49966,0.00000,0.00009,2.05862
4.80000,0.24005,181.24023,0.00000,0.00010,2.24088
4.90000,0.24496,195.65152,0.00000,0.00012,2.41906
5.00000,0.25016,214.21700,0.00000,0.00013,2.64860
5.10000,0.25494,231.95285,0.00000,0.00014,2.86789
5.20000,0.26008,252.03002,0.00000,0.00015,3.11613
5.30000,0.26499,271.14849,0.00000,0.00017,3.35251
5.40000,0.27007,291.67535,0.00000,0.00017,3.60631
5.50000,0.27497,309.79246,0.00000,0.00019,3.83031
5.60000,0.28005,329.72372,0.00000,0.00020,4.07674
5.70000,0.28490,350.67601,0.00000,0.00021,4.33580
5.80000,0.29004,373.07406,0.00000,0.00022,4.61273
5.90000,0.29506,397.53630,0.00000,0.00024,4.91519
6.00000,0.30014,422.53057,0.00000,0.00025,5.22422
6.10000,0.30505,450.27249,0.00000,0.00027,5.56722
6.20000,0.31001,478.20364,0.00000,0.00028,5.91257
6.30000,0.31497,508.67321,0.00000,0.00030,6.28930
6.40000,0.31999,539.18622,0.00000,0.00031,6.66656
6.50000,0.32508,573.74104,0.00000,0.00033,7.09380
6.60000,0.32992,605.79637,0.00000,0.00035,7.49014
6.70000,0.33500,642.08386,0.00000,0.00037,7.93880
6.80000,0.33990,674.66423,0.00000,0.00039,8.34163
6.90000,0.34510,710.78744,0.00000,0.00041,8.78826
7.00000,0.34995,743.55500,0.00000,0.00043,9.19340
7.10000,0.35509,779.07755,0.00000,0.00045,9.63261
7.20000,0.35987,813.59493,0.00000,0.00046,10.05938
7.30000,0.36501,851.20155,0.00000,0.00048,10.52436
7.40000,0.36992,884.99095,0.00000,0.00050,10.94213
7.50000,0.37506,919.98745,0.00000,0.00053,11.37483
7.60000,0.37990,953.55771,0.00000,0.00054,11.78990
7.70000,0.38498,988.63309,0.00000,0.00056,12.22358
7.80000,0.38995,1024.30452,0.00000,0.00058,12.66462
7.90000,0.39503,1059.37971,0.00000,0.00060,13.09830
8.00000,0.39993,1093.62276,0.00000,0.00062,13.52168
8.10000,0.40495,1126.60537,0.00000,0.00064,13.92948
8.20000,0.40992,1159.60734,0.00000,0.00066,14.33752
8.30000,0.41500,1190.87193,0.00000,0.00067,14.72408
8.40000,0.42002,1223.62785,0.00000,0.00069,15.12908
8.50000,0.42498,1254.13220,0.00000,0.00070,15.50624
8.60000,0.43001,1286.91820,0.00000,0.00072,15.91161
8.70000,0.43491,1316.12197,0.00000,0.00074,16.27269
8.80000,0.44005,1347.40314,0.00000,0.00076,16.65945
8.90000,0.44495,1377.19493,0.00000,0.00077,17.02780
9.00000,0.45004,1410.19840,0.00000,0.00079,17.43586
9.10000,0.45488,1438.04112,0.00000,0.00080,17.78011
9.20000,0.46008,1469.87773,0.00000,0.00082,18.17374
9.30000,0.46498,1497.95013,0.00000,0.00084,18.52083
9.40000,0.47012,1528.65779,0.00000,0.00085,18.90051
9.50000,0.47491,1555.13464,0.00000,0.00087,19.22787
9.60000,0.48005,1584.38738,0.00000,0.00089,19.58955
9.70000,0.48489,1611.71053,0.00000,0.00090,19.92738
9.80000,0.49009,1641.27275,0.00000,0.00092,20.29289
9.90000,0.49494,1669.85877,0.00000,0.00093,20.64633
10.00000,0.50002,1698.41629,0.00000,0.00095,20.99942
10.10000,0.50486,1723.38262,0.00000,0.00096,21.30811
10.20000,0.51006,1751.34800,0.00000,0.00098,21.65387
10.30000,0.51497,1777.22331,0.00000,0.00099,21.97380
10.40000,0.52005,1803.16921,0.00000,0.00101,22.29460
10.50000,0.52495,1829.55712,0.00000,0.00102,22.62086
10.60000,0.53003,1853.31479,0.00000,0.00104,22.91460
10.70000,0.53500,1879.70921,0.00000,0.00105,23.24095
10.80000,0.54002,1902.89151,0.00000,0.00106,23.52758
10.90000,0.54492,1927.96048,0.00000,0.00108,23.83753
11.00000,0.54994,1949.88083,0.00000,0.00109,24.10856
11.10000,0.55497,1974.69983,0.00000,0.00110,24.41542
11.20000,0.55993,1995.54898,0.00000,0.00111,24.67320
11.30000,0.56507,2020.29254,0.00000,0.00113,24.97914
11.40000,0.56991,2041.31510,0.00000,0.00114,25.23906
11.50000,0.57506,2065.29200,0.00000,0.00115,25.53551
11.60000,0.57990,2084.29918,0.00000,0.00116,25.77052
11.70000,0.58510,2107.33525,0.00000,0.00118,26.05534
11.80000,0.58988,2126.53466,0.00000,0.00119,26.29273
11.90000,0.59503,2148.55857,0.00000,0.00120,26.56503
12.00000,0.59981,2167.14535,0.00000,0.00121,26.79484
12.10000,0.60501,2188.51492,0.00000,0.00122,27.05906
12.20000,0.60985,2208.05146,0.00000,0.00123,27.30061
12.30000,0.61493,2229.44673,0.00000,0.00124,27.56514
12.40000,0.61990,2248.66811,0.00000,0.00125,27.80280
12.50000,0.62498,2268.31771,0.00000,0.00127,28.04575
12.60000,0.62994,2287.63856,0.00000,0.00128,28.28463
12.70000,0.63502,2306.04224,0.00000,0.00129,28.51218
12.80000,0.63999,2324.14659,0.00000,0.00130,28.73602
12.90000,0.64501,2340.13014,0.00000,0.00131,28.93365
13.00000,0.64997,2356.72537,0.00000,0.00132,29.13883
13.10000,0.65499,2371.26835,0.00000,0.00132,29.31864
13.20000,0.66002,2388.22773,0.00000,0.00134,29.52833
13.30000,0.66498,2402.27003,0.00000,0.00134,29.70195
13.40000,0.66994,2421.31520,0.00000,0.00136,29.93743
13.50000,0.67496,2437.05250,0.00000,0.00136,30.13201
13.60000,0.68011,2456.88353,0.00000,0.00137,30.37720
13.70000,0.68507,2473.67006,0.00000,0.00139,30.58475
13.80000,0.69009,2491.39853,0.00000,0.00139,30.80395
13.90000,0.69499,2507.40554,0.00000,0.00140,31.00186
14.00000,0.70013,2526.16480,0.00000,0.00141,31.23380
14.10000,0.70504,2542.04813,0.00000,0.00142,31.43018
14.20000,0.71012,2561.17471,0.00000,0.00143,31.66667
14.30000,0.71490,2578.24399,0.00000,0.00144,31.87771
14.40000,0.72010,2597.80474,0.00000,0.00146,32.11957
14.50000,0.72495,2613.90582,0.00000,0.00146,32.31864
14.60000,0.73015,2632.59262,0.00000,0.00147,32.54969
14.70000,0.73499,2651.66387,0.00000,0.00148,32.78549
14.80000,0.74007,2670.95342,0.00000,0.00150,33.02398
14.90000,0.74492,2687.13459,0.00000,0.00150,33.22405
15.00000,0.75012,2707.85410,0.00000,0.00152,33.48023
15.10000,0.75490,2725.15547,0.00000,0.00153,33.69414
15.20000,0.75998,2744.77042,0.00000,0.00154,33.93667
15.30000,0.76489,2763.93872,0.00000,0.00155,34.17367
15.40000,0.76997,2782.09969,0.00000,0.00156,34.39821
15.50000,0.77499,2801.24657,0.00000,0.00157,34.63494
15.60000,0.78001,2820.11479,0.00000,0.00158,34.86823
15.70000,0.78498,2842.20371,0.00000,0.00159,35.14134
15.80000,0.78994,2860.30229,0.00000,0.00160,35.36512
15.90000,0.79502,2882.46460,0.00000,0.00162,35.63913
16.00000,0.79998,2900.61217,0.00000,0.00163,35.86351
16.10000,0.80501,2922.42449,0.00000,0.00164,36.13320
16.20000,0.80991,2941.41453,0.00000,0.00165,36.36800
16.30000,0.81505,2962.68892,0.00000,0.00166,36.63104
16.40000,0.81989,2980.45222,0.00000,0.00167,36.85066
16.50000,0.82509,3001.45205,0.00000,0.00169,37.11031
16.60000,0.82994,3020.26104,0.00000,0.00170,37.34286
16.70000,0.83502,3042.52189,0.00000,0.00171,37.61810
16.80000,0.83986,3061.29437,0.00000,0.00172,37.85021
16.90000,0.84506,3083.81822,0.00000,0.00173,38.12869
17.00000,0.84991,3103.63993,0.00000,0.00175,38.37377
17.10000,0.85505,3125.14007,0.00000,0.00176,38.63960
17.20000,0.85995,3145.83741,0.00000,0.00177,38.89551
17.30000,0.86503,3167.39716,0.00000,0.00178,39.16207
17.40000,0.87000,3186.80815,0.00000,0.00180,39.40207
17.50000,0.87508,3207.89404,0.00000,0.00181,39.66278
17.60000,0.87998,3227.50993,0.00000,0.00182,39.90531
17.70000,0.88500,3248.38497,0.00000,0.00183,40.16342
17.80000,0.89003,3270.41261,0.00000,0.00185,40.43577
17.90000,0.89505,3291.32937,0.00000,0.00186,40.69439
18.00000,0.90001,3313.32348,0.00000,0.00187,40.96632
18.10000,0.90503,3333.52312,0.00000,0.00188,41.21607
18.20000,0.91006,3356.15836,0.00000,0.00190,41.49594
18.30000,0.91502,3375.87073,0.00000,0.00190,41.73967
18.40000,0.92010,3396.97003,0.00000,0.00192,42.00054
18.50000,0.92500,3416.92753,0.00000,0.00193,42.24730
18.60000,0.93003,3439.07326,0.00000,0.00195,42.52111
18.70000,0.93493,3459.84735,0.00000,0.00196,42.77796
18.80000,0.94007,3482.01543,0.00000,0.00197,43.05205
18.90000,0.94491,3502.04520,0.00000,0.00198,43.29970
19.00000,0.95000,3525.44077,0.00000,0.00200,43.58897
19.10000,0.95484,3545.87771,0.00000,0.00201,43.84165
19.20000,0.95998,3568.84561,0.00000,0.00203,44.12563
19.30000,0.96494,3589.91474,0.00000,0.00204,44.38613
19.40000,0.97008,3612.19347,0.00000,0.00205,44.66159
19.50000,0.97487,3633.39707,0.00000,0.00206,44.92375
19.60000,0.98001,3657.14058,0.00000,0.00208,45.21732
19.70000,0.98491,3677.28509,0.00000,0.00209,45.46639
19.80000,0.99005,3701.02897,0.00000,0.00210,45.75996
19.90000,0.99496,3722.29777,0.00000,0.00212,46.02293
20.00000,0.99998,3744.15182,0.00000,0.00213,46.29314
20.10000,1.00494,3767.24750,0.00000,0.00214,46.57869
20.20000,1.01002,3788.51332,0.00000,0.00215,46.84163
20.30000,1.01505,3811.58479,0.00000,0.00217,47.12689
20.40000,1.02001,3832.60176,0.00000,0.00218,47.38674
20.50000,1.02497,3856.08412,0.00000,0.00220,47.67708
20.60000,1.02993,3876.64400,0.00000,0.00221,47.93129
20.70000,1.03508,3901.43804,0.00000,0.00222,48.23784
20.80000,1.03992,3922.43527,0.00000,0.00224,48.49745
20.90000,1.04500,3947.64319,0.00000,0.00225,48.80913
21.00000,1.04990,3968.13788,0.00000,0.00227,49.06253
21.10000,1.05499,3992.15929,0.00000,0.00228,49.35953
21.20000,1.05989,4013.12746,0.00000,0.00229,49.61878
21.30000,1.06509,4037.51358,0.00000,0.00230,49.92030
21.40000,1.06987,4058.98467,0.00000,0.00232,50.18577
21.50000,1.07507,4084.15012,0.00000,0.00233,50.49692
21.60000,1.07986,4105.31871,0.00000,0.00235,50.75865
21.70000,1.08512,4129.74618,0.00000,0.00236,51.06067
21.80000,1.08996,4152.45444,0.00000,0.00237,51.34144
21.90000,1.09504,4176.39650,0.00000,0.00239,51.63746
22.00000,1.09989,4198.62904,0.00000,0.00240,51.91235
22.10000,1.10503,4221.08993,0.00000,0.00241,52.19006
22.20000,1.10993,4243.68344,0.00000,0.00243,52.46940
22.30000,1.11501,4266.14396,0.00000,0.00245,52.74711
22.40000,1.11998,4289.12602,0.00000,0.00246,53.03126
22.50000,1.12500,4311.66179,0.00000,0.00247,53.30990
22.60000,1.13002,4335.40307,0.00000,0.00249,53.60344
22.70000,1.13504,4358.29051,0.00000,0.00250,53.88642
22.80000,1.14001,4383.47980,0.00000,0.00251,54.19786
22.90000,1.14497,4406.44883,0.00000,0.00253,54.48185
23.00000,1.14999,4429.59107,0.00000,0.00254,54.76799
23.10000,1.15495,4451.00963,0.00000,0.00255,55.03281
23.20000,1.16004,4476.37402,0.00000,0.00257,55.34642
23.30000,1.16494,4498.46275,0.00000,0.00258,55.61953
23.40000,1.17008,4523.65912,0.00000,0.00260,55.93106
23.50000,1.17492,4544.82771,0.00000,0.00261,56.19279
23.60000,1.18007,4569.79573,0.00000,0.00262,56.50150
23.70000,1.18497,4590.37460,0.00000,0.00264,56.75593
23.80000,1.19005,4615.23086,0.00000,0.00265,57.06326
23.90000,1.19489,4635.33588,0.00000,0.00267,57.31184
24.00000,1.20003,4660.34673,0.00000,0.00268,57.62108
24.10000,1.20494,4683.20288,0.00000,0.00270,57.90367
24.20000,1.21008,4707.97643,0.00000,0.00271,58.20998
24.30000,1.21492,4732.59576,0.00000,0.00273,58.51437
24.40000,1.22000,4756.99343,0.00000,0.00274,58.81603
24.50000,1.22491,4780.91948,0.00000,0.00275,59.11185
24.60000,1.23005,4804.03043,0.00000,0.00277,59.39760
24.70000,1.23495,4827.46735,0.00000,0.00279,59.68738
24.80000,1.23997,4850.95792,0.00000,0.00280,59.97782
24.90000,1.24494,4874.12401,0.00000,0.00282,60.26425
25.00000,1.25002,4896.95407,0.00000,0.00283,60.54652
25.10000,1.25504,4921.53652,0.00000,0.00285,60.85046
25.20000,1.25994,4943.43601,0.00000,0.00286,61.12123
25.30000,1.26497,4970.17801,0.00000,0.00288,61.45187
25.40000,1.26993,4992.07191,0.00000,0.00289,61.72257
25.50000,1.27501,5018.02154,0.00000,0.00291,62.04341
25.60000,1.27997,5039.13276,0.00000,0.00292,62.30443
25.70000,1.28506,5064.77877,0.00000,0.00294,62.62152
25.80000,1.28990,5085.91123,0.00000,0.00295,62.88281
25.90000,1.29510,5111.37433,0.00000,0.00297,63.19764
26.00000,1.29994,5132.97878,0.00000,0.00298,63.46476
26.10000,1.30509,5158.40612,0.00000,0.00300,63.77914
26.20000,1.30987,5181.50404,0.00000,0.00301,64.06473
26.30000,1.31501,5207.07965,0.00000,0.00303,64.38095
26.40000,1.31991,5230.42530,0.00000,0.00304,64.66960
26.50000,1.32499,5253.91325,0.00000,0.00306,64.96001
26.60000,1.32990,5277.63255,0.00000,0.00307,65.25327
26.70000,1.33498,5304.24528,0.00000,0.00309,65.58232
26.80000,1.33994,5328.72453,0.00000,0.00311,65.88498
26.90000,1.34508,5352.73068,0.00000,0.00312,66.18180
27.00000,1.34999,5376.76811,0.00000,0.00314,66.47900
27.10000,1.35501,5400.73365,0.00000,0.00315,66.77531
27.20000,1.35997,5425.06985,0.00000,0.00317,67.07621
27.30000,1.36505,5448.03590,0.00000,0.00318,67.36016
27.40000,1.37002,5470.52436,0.00000,0.00320,67.63821
27.50000,1.37504,5493.87485,0.00000,0.00321,67.92692
27.60000,1.37994,5518.27028,0.00000,0.00323,68.22855
27.70000,1.38496,5541.39391,0.00000,0.00325,68.51445
27.80000,1.39005,5568.54010,0.00000,0.00326,68.85009
27.90000,1.39501,5592.59467,0.00000,0.00328,69.14750
28.00000,1.40009,5618.03244,0.00000,0.00330,69.46202
28.10000,1.40493,5641.09720,0.00000,0.00331,69.74719
28.20000,1.41002,5666.41316,0.00000,0.00333,70.06020
28.30000,1.41492,5689.05547,0.00000,0.00334,70.34016
28.40000,1.42012,5714.84044,0.00000,0.00336,70.65896
28.50000,1.42490,5736.88410,0.00000,0.00337,70.93151
28.60000,1.43005,5763.56314,0.00000,0.00339,71.26138
28.70000,1.43483,5786.54110,0.00000,0.00341,71.54548
28.80000,1.44009,5812.31378,0.00000,0.00342,71.86414
28.90000,1.44493,5834.99335,0.00000,0.00344,72.14455
29.00000,1.45007,5861.20598,0.00000,0.00346,72.46864
29.10000,1.45492,5885.09254,0.00000,0.00347,72.76398
29.20000,1.46006,5908.85542,0.00000,0.00349,73.05779
29.30000,1.46496,5932.98003,0.00000,0.00350,73.35607
29.40000,1.47004,5957.01449,0.00000,0.00352,73.65323
29.50000,1.47495,5982.92500,0.00000,0.00353,73.97359
29.60000,1.47997,6008.22531,0.00000,0.00355,74.28641
29.70000,1.48493,6032.04742,0.00000,0.00357,74.58095
29.80000,1.49001,6055.95075,0.00000,0.00358,74.87649
29.90000,1.49498,6080.46688,0.00000,0.00360,75.17961
30.00000,1.49994,6104.90181,0.00000,0.00361,75.48173
30.10000,1.50496,6130.81977,0.00000,0.00363,75.80218
30.20000,1.50992,6153.86255,0.00000,0.00364,76.08708
30.30000,1.51507,6181.75641,0.00000,0.00366,76.43197
30.40000,1.51997,6204.43672,0.00000,0.00368,76.71239
30.50000,1.52505,6230.40795,0.00000,0.00369,77.03350
30.60000,1.52989,6253.63216,0.00000,0.00371,77.32065
30.70000,1.53504,6278.61395,0.00000,0.00373,77.62953
30.80000,1.53994,6301.82177,0.00000,0.00374,77.91647
30.90000,1.54508,6327.10904,0.00000,0.00376,78.22912
31.00000,1.54986,6349.80500,0.00000,0.00377,78.50974
31.10000,1.55501,6376.04743,0.00000,0.00380,78.83420
31.20000,1.55991,6399.88258,0.00000,0.00381,79.12891
31.30000,1.56505,6426.34407,0.00000,0.00383,79.45608
31.40000,1.56995,6451.22007,0.00000,0.00385,79.76365
31.50000,1.57497,6475.68330,0.00000,0.00385,80.06611
31.60000,1.57988,6500.24042,0.00000,0.00388,80.36974
31.70000,1.58508,6525.77728,0.00000,0.00389,80.68548
31.80000,1.58998,6550.29342,0.00000,0.00391,80.98860
31.90000,1.59500,6573.91474,0.00000,0.00393,81.28066
32.00000,1.59997,6600.96556,0.00000,0.00394,81.61512
32.10000,1.60499,6624.53100,0.00000,0.00396,81.90649
32.20000,1.61001,6650.81814,0.00000,0.00397,82.23150
32.30000,1.61503,6674.10046,0.00000,0.00400,82.51937
32.40000,1.62006,6700.54406,0.00000,0.00401,82.84632
32.50000,1.62496,6723.52165,0.00000,0.00403,83.13042
32.60000,1.63004,6748.44459,0.00000,0.00405,83.43857
32.70000,1.63500,6771.85282,0.00000,0.00406,83.72799
32.80000,1.64009,6799.34621,0.00000,0.00409,84.06792
32.90000,1.64493,6823.34304,0.00000,0.00410,84.36462
33.00000,1.65007,6850.50637,0.00000,0.00412,84.70047
33.10000,1.65491,6872.58169,0.00000,0.00413,84.97341
33.20000,1.66012,6899.72267,0.00000,0.00415,85.30899
33.30000,1.66490,6922.51250,0.00000,0.00417,85.59076
33.40000,1.67004,6949.07606,0.00000,0.00418,85.91920
33.50000,1.67488,6973.88276,0.00000,0.00420,86.22591
33.60000,1.68008,6999.29595,0.00000,0.00423,86.54012
33.70000,1.68499,7024.87156,0.00000,0.00424,86.85634
33.80000,1.69007,7051.42841,0.00000,0.00426,87.18470
33.90000,1.69491,7075.66887,0.00000,0.00427,87.48441
34.00000,1.69999,7100.36457,0.00000,0.00429,87.78975
34.10000,1.70490,7124.40833,0.00000,0.00431,88.08703
34.20000,1.70998,7149.16363,0.00000,0.00432,88.39311
34.30000,1.71488,7174.98958,0.00000,0.00435,88.71242
34.40000,1.71996,7198.82175,0.00000,0.00435,89.00708
34.50000,1.72499,7225.28547,0.00000,0.00438,89.33428
34.60000,1.73001,7250.26801,0.00000,0.00440,89.64317
34.70000,1.73503,7276.51045,0.00000,0.00441,89.96764
34.80000,1.73993,7299.55584,0.00000,0.00443,90.25257
34.90000,1.74502,7326.44722,0.00000,0.00445,90.58506
35.00000,1.74992,7349.72656,0.00000,0.00447,90.87289
35.10000,1.75500,7375.07939,0.00000,0.00448,91.18635
35.20000,1.75996,7399.44726,0.00000,0.00450,91.48764
35.30000,1.76499,7427.24612,0.00000,0.00452,91.83135
35.40000,1.76989,7451.67509,0.00000,0.00453,92.13339
35.50000,1.77515,7478.61639,0.00000,0.00456,92.46650
35.60000,1.77999,7500.91746,0.00000,0.00457,92.74223
35.70000,1.78513,7527.64940,0.00000,0.00459,93.07275
35.80000,1.78992,7550.74397,0.00000,0.00461,93.35829
35.90000,1.79500,7575.97089,0.00000,0.00462,93.67020
36.00000,1.79990,7599.93121,0.00000,0.00464,93.96645
36.10000,1.80516,7626.37705,0.00000,0.00466,94.29343
36.20000,1.80995,7650.87306,0.00000,0.00468,94.59630
36.30000,1.81503,7676.92924,0.00000,0.00470,94.91846
36.40000,1.81993,7701.02367,0.00000,0.00471,95.21637
36.50000,1.82507,7726.81311,0.00000,0.00473,95.53523
36.60000,1.83004,7751.18843,0.00000,0.00475,95.83661
36.70000,1.83506,7777.10080,0.00000,0.00477,96.15699
36.80000,1.83996,7803.89979,0.00000,0.00479,96.48834
36.90000,1.84498,7827.52484,0.00000,0.00480,96.78044
37.00000,1.85001,7855.33562,0.00000,0.00482,97.12430
37.10000,1.85497,7878.71629,0.00000,0.00484,97.41338
37.20000,1.85999,7906.74761,0.00000,0.00486,97.75996
37.30000,1.86495,7930.18490,0.00000,0.00487,98.04974
37.40000,1.87004,7956.40796,0.00000,0.00490,98.37397
37.50000,1.87494,7979.80055,0.00000,0.00491,98.66320
37.60000,1.88008,8007.24998,0.00000,0.00493,99.00259
37.70000,1.88492,8031.46288,0.00000,0.00495,99.30196
37.80000,1.89007,8058.63664,0.00000,0.00497,99.63794
37.90000,1.89491,8082.26988,0.00000,0.00499,99.93014
38.00000,1.90005,8108.91911,0.00000,0.00501,100.25964
38.10000,1.90483,8133.02249,0.00000,0.00503,100.55765
38.20000,1.90998,8160.52705,0.00000,0.00504,100.89772
38.30000,1.91482,8183.15148,0.00000,0.00506,101.17745
38.40000,1.92002,8209.72472,0.00000,0.00509,101.50601
38.50000,1.92492,8233.46078,0.00000,0.00510,101.79948
38.60000,1.93000,8261.15087,0.00000,0.00513,102.14185
38.70000,1.93485,8286.77043,0.00000,0.00514,102.45861
38.80000,1.93999,8312.38702,0.00000,0.00516,102.77534
38.90000,1.94495,8338.25618,0.00000,0.00518,103.09519
39.00000,1.94997,8364.77876,0.00000,0.00520,103.42311
39.10000,1.95494,8390.94520,0.00000,0.00522,103.74664
39.20000,1.95996,8416.24811,0.00000,0.00524,104.05949
39.30000,1.96498,8442.61423,0.00000,0.00526,104.38548
39.40000,1.97000,8465.76318,0.00000,0.00527,104.67170
39.50000,1.97503,8493.57769,0.00000,0.00529,105.01560
39.60000,1.97999,8517.60656,0.00000,0.00531,105.31270
39.70000,1.98501,8544.27218,0.00000,0.00533,105.64239
39.80000,1.99003,8567.17899,0.00000,0.00534,105.92561
39.90000,1.99512,8592.26882,0.00000,0.00537,106.23583
40.00000,2.00002,8618.05379,0.00000,0.00538,106.55464
40.10000,2.00510,8646.21773,0.00000,0.00540,106.90286
40.20000,2.00994,8670.84041,0.00000,0.00542,107.20730
40.30000,2.01509,8698.03801,0.00000,0.00544,107.54357
40.40000,2.01999,8720.79805,0.00000,0.00546,107.82498
40.50000,2.02507,8748.91877,0.00000,0.00548,108.17267
40.60000,2.02991,8773.26652,0.00000,0.00550,108.47371
40.70000,2.03505,8799.70193,0.00000,0.00552,108.80056
40.80000,2.03996,8823.52591,0.00000,0.00554,109.09512
40.90000,2.04504,8849.64243,0.00000,0.00555,109.41803
41.00000,2.04994,8875.65017,0.00000,0.00558,109.73959
41.10000,2.05502,8902.37167,0.00000,0.00559,110.06998
41.20000,2.05993,8927.70216,0.00000,0.00561,110.38317
41.30000,2.06507,8953.43423,0.00000,0.00563,110.70132
41.40000,2.06997,8978.79377,0.00000,0.00565,111.01487
41.50000,2.07505,9004.50647,0.00000,0.00567,111.33278
41.60000,2.07996,9030.45982,0.00000,0.00569,111.65367
41.70000,2.08504,9055.21587,0.00000,0.00571,111.95976
41.80000,2.09000,9082.78152,0.00000,0.00573,112.30059
41.90000,2.09496,9106.17933,0.00000,0.00574,112.58988
42.00000,2.09999,9134.39840,0.00000,0.00577,112.93878
42.10000,2.10495,9158.21269,0.00000,0.00578,113.23323
42.20000,2.11003,9185.41625,0.00000,0.00580,113.56957
42.30000,2.11493,9209.53304,0.00000,0.00582,113.86776
42.40000,2.12008,9237.85791,0.00000,0.00585,114.21797
42.50000,2.12492,9263.92451,0.00000,0.00586,114.54026
42.60000,2.13006,9291.81799,0.00000,0.00589,114.88514
42.70000,2.13490,9316.15010,0.00000,0.00590,115.18598
42.80000,2.14005,9343.15547,0.00000,0.00593,115.51988
42.90000,2.14483,9367.15975,0.00000,0.00594,115.81667
43.00000,2.15003,9393.58771,0.00000,0.00596,116.14343
43.10000,2.15487,9418.16568,0.00000,0.00598,116.44732
43.20000,2.16007,9444.67634,0.00000,0.00601,116.77510
43.30000,2.16498,9469.90922,0.00000,0.00602,117.08708
43.40000,2.17006,9496.90640,0.00000,0.00605,117.42087
43.50000,2.17496,9522.99535,0.00000,0.00606,117.74344
43.60000,2.18004,9548.52849,0.00000,0.00609,118.05914
43.70000,2.18501,9575.24627,0.00000,0.00610,118.38948
43.80000,2.19003,9600.17070,0.00000,0.00612,118.69765
43.90000,2.19493,9626.13747,0.00000,0.00615,119.01870
44.00000,2.20001,9649.99795,0.00000,0.00616,119.31372
44.10000,2.20498,9676.92286,0.00000,0.00619,119.64662
44.20000,2.21000,9702.60575,0.00000,0.00620,119.96417
44.30000,2.21508,9729.74896,0.00000,0.00623,120.29977
44.40000,2.21998,9754.02296,0.00000,0.00624,120.59989
44.50000,2.22507,9780.23335,0.00000,0.00626,120.92396
44.60000,2.22997,9804.78451,0.00000,0.00629,121.22752
44.70000,2.23511,9831.62746,0.00000,0.00631,121.55941
44.80000,2.23995,9856.10560,0.00000,0.00632,121.86206
44.90000,2.24510,9884.86558,0.00000,0.00635,122.21765
45.00000,2.24994,9907.21434,0.00000,0.00636,122.49397
45.10000,2.25508,9935.13316,0.00000,0.00639,122.83916
45.20000,2.25992,9958.47136,0.00000,0.00640,123.12772
45.30000,2.26512,9986.27320,0.00000,0.00642,123.47146
45.40000,2.26991,10009.57191,0.00000,0.00645,123.75953
45.50000,2.27505,10036.10045,0.00000,0.00647,124.08753
45.60000,2.27995,10060.75963,0.00000,0.00649,124.39242
45.70000,2.28503,10087.30456,0.00000,0.00650,124.72063
45.80000,2.28988,10115.24871,0.00000,0.00653,125.06613
45.90000,2.29502,10141.47997,0.00000,0.00655,125.39046
46.00000,2.29992,10167.12487,0.00000,0.00656,125.70754
46.10000,2.30500,10192.98211,0.00000,0.00659,126.02724
46.20000,2.30997,10218.41168,0.00000,0.00660,126.34165
46.30000,2.31499,10243.71907,0.00000,0.00663,126.65455
46.40000,2.31995,10270.37874,0.00000,0.00665,126.98418
46.50000,2.32503,10295.19513,0.00000,0.00667,127.29101
46.60000,2.33000,10322.26682,0.00000,0.00669,127.62573
46.70000,2.33496,10346.68759,0.00000,0.00671,127.92767
46.80000,2.33998,10375.34177,0.00000,0.00672,128.28195
46.90000,2.34494,10398.20611,0.00000,0.00674,128.56465
47.00000,2.35003,10425.56465,0.00000,0.00677,128.90292
47.10000,2.35493,10448.35001,0.00000,0.00678,129.18464
47.20000,2.36007,10476.64657,0.00000,0.00681,129.53450
47.30000,2.36485,10501.18804,0.00000,0.00682,129.83793
47.40000,2.37000,10528.04589,0.00000,0.00685,130.17001
47.50000,2.37490,10553.47174,0.00000,0.00687,130.48437
47.60000,2.38010,10580.50022,0.00000,0.00689,130.81856
47.70000,2.38488,10606.52509,0.00000,0.00691,131.14033
47.80000,2.39003,10632.90611,0.00000,0.00693,131.46651
47.90000,2.39487,10658.25373,0.00000,0.00695,131.77991
48.00000,2.40001,10684.87093,0.00000,0.00697,132.10901
48.10000,2.40497,10710.79373,0.00000,0.00699,132.42952
48.20000,2.40999,10737.35431,0.00000,0.00701,132.75792
48.30000,2.41490,10763.91786,0.00000,0.00703,133.08635
48.40000,2.42004,10789.48900,0.00000,0.00705,133.40252
48.50000,2.42494,10813.73543,0.00000,0.00707,133.70230
48.60000,2.43002,10838.79545,0.00000,0.00709,134.01215
48.70000,2.43499,10864.90005,0.00000,0.00712,134.33491
48.80000,2.44001,10889.78127,0.00000,0.00714,134.64254
48.90000,2.44503,10916.02817,0.00000,0.00716,134.96706
49.00000,2.45005,10941.59931,0.00000,0.00718,135.28323
49.10000,2.45502,10969.31249,0.00000,0.00720,135.62588
49.20000,2.45998,10993.99701,0.00000,0.00722,135.93108
49.30000,2.46500,11020.62836,0.00000,0.00724,136.26035
49.40000,2.46996,11044.34356,0.00000,0.00726,136.55357
49.50000,2.47505,11071.24612,0.00000,0.00728,136.88620
49.60000,2.47989,11096.74126,0.00000,0.00730,137.20142
49.70000,2.48509,11124.89328,0.00000,0.00732,137.54950
49.80000,2.48993,11149.25370,0.00000,0.00735,137.85069
49.90000,2.49508,11176.88119,0.00000,0.00737,138.19228
50.00000,2.49992,11201.21479,0.00000,0.00739,138.49315
50.10000,2.50500,11228.54948,0.00000,0.00741,138.83111
50.20000,2.50984,11252.81304,0.00000,0.00743,139.13111
50.30000,2.51510,11279.40565,0.00000,0.00745,139.45991
50.40000,2.51995,11303.45613,0.00000,0.00747,139.75727
50.50000,2.52503,11330.43692,0.00000,0.00749,140.09086
50.60000,2.52987,11356.11013,0.00000,0.00752,140.40829
50.70000,2.53501,11382.91880,0.00000,0.00754,140.73976
50.80000,2.53998,11408.33497,0.00000,0.00756,141.05400
50.90000,2.54512,11434.60199,0.00000,0.00758,141.37877
51.00000,2.54996,11460.53523,0.00000,0.00760,141.69941
51.10000,2.55498,11486.95648,0.00000,0.00762,142.02609
51.20000,2.55995,11513.92832,0.00000,0.00764,142.35957
51.30000,2.56503,11537.98178,0.00000,0.00766,142.65697
51.40000,2.56999,11565.62269,0.00000,0.00768,142.99873
51.50000,2.57495,11589.31255,0.00000,0.00770,143.29163
51.60000,2.57998,11617.88851,0.00000,0.00773,143.64495
51.70000,2.58494,11642.13568,0.00000,0.00775,143.94474
51.80000,2.59008,11669.52178,0.00000,0.00777,144.28335
51.90000,2.59498,11693.30701,0.00000,0.00779,144.57743
52.00000,2.60007,11719.84971,0.00000,0.00781,144.90561
52.10000,2.60491,11743.95755,0.00000,0.00783,145.20368
52.20000,2.61011,11773.40671,0.00000,0.00785,145.56779
52.30000,2.61495,11796.92894,0.00000,0.00787,145.85863
52.40000,2.62010,11823.78605,0.00000,0.00790,146.19069
52.50000,2.62494,11847.77245,0.00000,0.00792,146.48726
52.60000,2.63008,11874.62360,0.00000,0.00794,146.81925
52.70000,2.63498,11900.08745,0.00000,0.00796,147.13409
52.80000,2.64006,11925.95437,0.00000,0.00798,147.45391
52.90000,2.64497,11950.44145,0.00000,0.00800,147.75667
53.00000,2.64999,11978.23212,0.00000,0.00802,148.10028
53.10000,2.65495,12004.64740,0.00000,0.00804,148.42688
53.20000,2.66003,12029.96075,0.00000,0.00807,148.73986
53.30000,2.66500,12055.56691,0.00000,0.00809,149.05646
53.40000,2.67002,12081.00021,0.00000,0.00811,149.37092
53.50000,2.67492,12107.28437,0.00000,0.00813,149.69590
53.60000,2.68000,12131.31323,0.00000,0.00815,149.99299
53.70000,2.68503,12157.70170,0.00000,0.00817,150.31926
53.80000,2.68999,12182.92788,0.00000,0.00819,150.63116
53.90000,2.69495,12209.07122,0.00000,0.00822,150.95440
54.00000,2.69997,12234.19756,0.00000,0.00824,151.26507
54.10000,2.70506,12261.30277,0.00000,0.00826,151.60020
54.20000,2.71002,12285.38081,0.00000,0.00828,151.89790
54.30000,2.71510,12312.67154,0.00000,0.00830,152.23533
54.40000,2.71994,12337.75020,0.00000,0.00832,152.54540
54.50000,2.72503,12364.87925,0.00000,0.00834,152.88083
54.60000,2.72993,12390.12182,0.00000,0.00836,153.19293
54.70000,2.73507,12417.27099,0.00000,0.00838,153.52861
54.80000,2.73985,12440.57491,0.00000,0.00841,153.81674
54.90000,2.74505,12468.79920,0.00000,0.00843,154.16571
55.00000,2.74990,12493.09704,0.00000,0.00845,154.46613
55.10000,2.75504,12518.87679,0.00000,0.00847,154.78487
55.20000,2.75994,12544.70646,0.00000,0.00850,155.10424
55.30000,2.76508,12572.13205,0.00000,0.00851,155.44333
55.40000,2.76993,12599.73198,0.00000,0.00854,155.78458
55.50000,2.77501,12624.72123,0.00000,0.00856,156.09355
55.60000,2.77997,12650.83849,0.00000,0.00858,156.41646
55.70000,2.78505,12676.05424,0.00000,0.00860,156.72823
55.80000,2.78996,12702.37863,0.00000,0.00862,157.05371
55.90000,2.79498,12727.11605,0.00000,0.00864,157.35957
56.00000,2.79994,12753.47471,0.00000,0.00866,157.68547
56.10000,2.80496,12778.03630,0.00000,0.00868,157.98915
56.20000,2.80999,12805.64964,0.00000,0.00871,158.33057
56.30000,2.81495,12830.52564,0.00000,0.00873,158.63814
56.40000,2.81997,12858.52790,0.00000,0.00875,158.98436
56.50000,2.82493,12883.69596,0.00000,0.00877,159.29554
56.60000,2.83008,12911.08131,0.00000,0.00880,159.63414
56.70000,2.83492,12935.53710,0.00000,0.00881,159.93651
56.80000,2.84000,12962.86434,0.00000,0.00884,160.27439
56.90000,2.84484,12987.36632,0.00000,0.00886,160.57733
57.00000,2.84999,13014.53114,0.00000,0.00889,160.91320
57.10000,2.85489,13038.88708,0.00000,0.00890,161.21434
57.20000,2.86003,13066.48999,0.00000,0.00893,161.55563
57.30000,2.86487,13089.42437,0.00000,0.00895,161.83919
57.40000,2.87002,13115.62806,0.00000,0.00897,162.16318
57.50000,2.87498,13140.00338,0.00000,0.00899,162.46456
57.60000,2.88012,13167.17565,0.00000,0.00902,162.80052
57.70000,2.88496,13192.20811,0.00000,0.00903,163.11002
57.80000,2.88999,13219.80804,0.00000,0.00906,163.45127
57.90000,2.89495,13245.88954,0.00000,0.00908,163.77375
58.00000,2.90003,13271.40480,0.00000,0.00910,164.08922
58.10000,2.90493,13295.82632,0.00000,0.00913,164.39117
58.20000,2.90995,13320.81705,0.00000,0.00915,164.70016
58.30000,2.91492,13348.40059,0.00000,0.00917,165.04120
58.40000,2.92000,13371.88333,0.00000,0.00919,165.33155
58.50000,2.92502,13399.31041,0.00000,0.00922,165.67066
58.60000,2.93004,13425.01342,0.00000,0.00924,165.98845
58.70000,2.93501,13453.62067,0.00000,0.00926,166.34216
58.80000,2.93997,13477.78738,0.00000,0.00928,166.64096
58.90000,2.94505,13505.42903,0.00000,0.00930,166.98272
59.00000,2.94995,13528.49156,0.00000,0.00933,167.26787
59.10000,2.95504,13556.23454,0.00000,0.00935,167.61089
59.20000,2.95988,13578.92752,0.00000,0.00937,167.89147
59.30000,2.96508,13608.09803,0.00000,0.00939,168.25213
59.40000,2.96992,13631.57183,0.00000,0.00941,168.54237
59.50000,2.97513,13658.65022,0.00000,0.00944,168.87717
59.60000,2.97991,13683.02703,0.00000,0.00945,169.17857
59.70000,2.98505,13710.61355,0.00000,0.00948,169.51965
59.80000,2.98989,13735.34054,0.00000,0.00950,169.82538
59.90000,2.99504,13761.80351,0.00000,0.00952,170.15257
60.00000,2.99994,13787.54377,0.00000,0.00955,170.47082
60.10000,3.00496,13814.15427,0.00000,0.00957,170.79984
60.20000,3.00986,13841.36081,0.00000,0.00959,171.13622
60.30000,3.01494,13866.36496,0.00000,0.00961,171.44538
60.40000,3.01997,13893.29582,0.00000,0.00963,171.77835
60.50000,3.02499,13917.90956,0.00000,0.00966,172.08268
60.60000,3.02995,13943.76904,0.00000,0.00968,172.40241
60.70000,3.03497,13967.91935,0.00000,0.00970,172.70101
60.80000,3.04000,13996.76353,0.00000,0.00972,173.05764
60.90000,3.04502,14020.70373,0.00000,0.00974,173.35364
61.00000,3.05004,14048.81924,0.00000,0.00977,173.70126
61.10000,3.05494,14072.16787,0.00000,0.00978,173.98995
61.20000,3.06003,14100.60227,0.00000,0.00981,174.34152
61.30000,3.06493,14124.91053,0.00000,0.00983,174.64207
61.40000,3.07007,14151.12168,0.00000,0.00985,174.96614
61.50000,3.07491,14175.09913,0.00000,0.00987,175.26260
61.60000,3.08006,14202.66181,0.00000,0.00990,175.60339
61.70000,3.08490,14227.26959,0.00000,0.00992,175.90764
61.80000,3.09010,14254.62514,0.00000,0.00994,176.24587
61.90000,3.09494,14280.83926,0.00000,0.00996,176.56999
62.00000,3.10009,14307.47807,0.00000,0.00999,176.89935
62.10000,3.10493,14332.72809,0.00000,0.01001,177.21155
62.20000,3.11007,14357.87380,0.00000,0.01003,177.52245
62.30000,3.11497,14383.83609,0.00000,0.01005,177.84345
62.40000,3.12005,14409.70898,0.00000,0.01007,178.16335
62.50000,3.12490,14435.43434,0.00000,0.01010,178.48142
62.60000,3.13004,14463.59754,0.00000,0.01012,178.82963
62.70000,3.13494,14487.75828,0.00000,0.01014,179.12836
62.80000,3.14008,14513.79061,0.00000,0.01017,179.45022
62.90000,3.14499,14539.62922,0.00000,0.01018,179.76970
63.00000,3.15001,14565.44995,0.00000,0.01021,180.08895
63.10000,3.15497,14592.18264,0.00000,0.01023,180.41947
63.20000,3.16005,14617.18976,0.00000,0.01025,180.72866
63.30000,3.16502,14644.02378,0.00000,0.01028,181.06044
63.40000,3.16998,14669.51072,0.00000,0.01030,181.37557
63.50000,3.17500,14698.29530,0.00000,0.01032,181.73146
63.60000,3.17990,14722.70489,0.00000,0.01035,182.03327
63.70000,3.18505,14749.51506,0.00000,0.01037,182.36475
63.80000,3.18995,14773.62067,0.00000,0.01039,182.66279
63.90000,3.19503,14800.74674,0.00000,0.01042,182.99818
64.00000,3.19987,14825.73301,0.00000,0.01044,183.30712
64.10000,3.20508,14854.28810,0.00000,0.01046,183.66018
64.20000,3.20998,14879.28182,0.00000,0.01048,183.96920
64.30000,3.21512,14905.85059,0.00000,0.01051,184.29770
64.40000,3.21984,14929.65966,0.00000,0.01053,184.59208
64.50000,3.22505,14957.27599,0.00000,0.01055,184.93353
64.60000,3.22989,14981.24450,0.00000,0.01057,185.22988
64.70000,3.23509,15008.23200,0.00000,0.01060,185.56356
64.80000,3.23987,15033.23466,0.00000,0.01062,185.87269
64.90000,3.24495,15059.29381,0.00000,0.01064,186.19489
65.00000,3.24986,15085.94751,0.00000,0.01067,186.52444
65.10000,3.25500,15112.10799,0.00000,0.01069,186.84789
65.20000,3.25996,15138.55904,0.00000,0.01071,187.17494
65.30000,3.26498,15163.91486,0.00000,0.01073,187.48844
65.40000,3.26995,15190.18263,0.00000,0.01076,187.81322
65.50000,3.27491,15213.97978,0.00000,0.01077,188.10745
65.60000,3.27999,15242.14745,0.00000,0.01080,188.45571
65.70000,3.28501,15266.74181,0.00000,0.01082,188.75980
65.80000,3.29004,15294.38198,0.00000,0.01084,189.10155
65.90000,3.29494,15318.12996,0.00000,0.01086,189.39517
66.00000,3.30002,15346.25739,0.00000,0.01089,189.74294
66.10000,3.30498,15369.77291,0.00000,0.01091,190.03369
66.20000,3.31013,15396.30443,0.00000,0.01094,190.36173
66.30000,3.31497,15421.11188,0.00000,0.01095,190.66845
66.40000,3.32011,15449.36150,0.00000,0.01098,191.01773
66.50000,3.32495,15473.04243,0.00000,0.01100,191.31053
66.60000,3.33010,15500.14615,0.00000,0.01102,191.64564
66.70000,3.33494,15525.35444,0.00000,0.01105,191.95732
66.80000,3.34002,15551.84722,0.00000,0.01107,192.28488
66.90000,3.34492,15576.64871,0.00000,0.01109,192.59153
67.00000,3.35007,15602.92542,0.00000,0.01112,192.91642
67.10000,3.35491,15628.05623,0.00000,0.01113,193.22714
67.20000,3.36005,15655.18677,0.00000,0.01116,193.56258
67.30000,3.36495,15682.98936,0.00000,0.01119,193.90634
67.40000,3.37003,15709.42551,0.00000,0.01121,194.23320
67.50000,3.37500,15735.36694,0.00000,0.01123,194.55394
67.60000,3.38008,15760.46646,0.00000,0.01125,194.86427
67.70000,3.38498,15784.91926,0.00000,0.01128,195.16661
67.80000,3.39000,15810.39131,0.00000,0.01129,195.48155
67.90000,3.39497,15837.45182,0.00000,0.01132,195.81613
68.00000,3.39999,15860.85558,0.00000,0.01134,196.10550
68.10000,3.40507,15888.75204,0.00000,0.01137,196.45041
68.20000,3.40997,15912.15432,0.00000,0.01139,196.73976
68.30000,3.41506,15940.75263,0.00000,0.01141,197.09335
68.40000,3.41996,15964.39928,0.00000,0.01143,197.38572
68.50000,3.42510,15992.70552,0.00000,0.01146,197.73570
68.60000,3.43000,16015.70696,0.00000,0.01148,198.02010
68.70000,3.43503,16043.67942,0.00000,0.01150,198.36595
68.80000,3.43987,16067.96533,0.00000,0.01152,198.66622
68.90000,3.44507,16095.05564,0.00000,0.01155,199.00117
69.00000,3.44985,16119.39818,0.00000,0.01157,199.30215
69.10000,3.45500,16145.72853,0.00000,0.01159,199.62770
69.20000,3.45984,16171.74298,0.00000,0.01161,199.94934
69.30000,3.46498,16198.20595,0.00000,0.01164,200.27654
69.40000,3.46988,16222.28473,0.00000,0.01166,200.57425
69.50000,3.47503,16250.12010,0.00000,0.01169,200.91841
69.60000,3.47993,16275.56533,0.00000,0.01171,201.23302
69.70000,3.48501,16303.04605,0.00000,0.01173,201.57279
69.80000,3.48991,16328.60303,0.00000,0.01175,201.88878
69.90000,3.49499,16353.09905,0.00000,0.01178,202.19165
70.00000,3.50008,16379.88985,0.00000,0.01180,202.52290
70.10000,3.50498,16402.80783,0.00000,0.01182,202.80626
70.20000,3.50994,16429.79085,0.00000,0.01185,203.13988
70.30000,3.51496,16454.31072,0.00000,0.01186,203.44304
70.40000,3.51999,16480.83478,0.00000,0.01189,203.77099
70.50000,3.52501,16505.40382,0.00000,0.01191,204.07477
70.60000,3.53003,16533.29581,0.00000,0.01194,204.41963
70.70000,3.53499,16560.04637,0.00000,0.01196,204.75037
70.80000,3.54008,16587.71634,0.00000,0.01198,205.09249
70.90000,3.54504,16611.50455,0.00000,0.01201,205.38661
71.00000,3.55012,16637.90345,0.00000,0.01203,205.71301
71.10000,3.55496,16661.70508,0.00000,0.01205,206.00729
71.20000,3.56005,16689.55684,0.00000,0.01208,206.35166
71.30000,3.56495,16713.91428,0.00000,0.01209,206.65281
71.40000,3.57009,16741.14913,0.00000,0.01212,206.98955
71.50000,3.57493,16764.90009,0.00000,0.01214,207.28321
71.60000,3.58007,16792.52386,0.00000,0.01217,207.62475
71.70000,3.58492,16818.11959,0.00000,0.01219,207.94122
71.80000,3.59006,16845.47216,0.00000,0.01222,208.27941
71.90000,3.59496,16869.70443,0.00000,0.01224,208.57902
72.00000,3.60004,16895.25247,0.00000,0.01226,208.89490
72.10000,3.60489,16922.67805,0.00000,0.01228,209.23399
72.20000,3.61003,16949.67449,0.00000,0.01231,209.56778
72.30000,3.61493,16975.08246,0.00000,0.01233,209.88193
72.40000,3.62001,17000.41294,0.00000,0.01236,210.19512
72.50000,3.62492,17026.82227,0.00000,0.01238,210.52165
72.60000,3.62994,17051.64611,0.00000,0.01240,210.82857
72.70000,3.63496,17079.63496,0.00000,0.01242,211.17463
72.80000,3.64004,17104.29788,0.00000,0.01244,211.47956
72.90000,3.64507,17133.23593,0.00000,0.01247,211.83736
73.00000,3.64997,17158.07319,0.00000,0.01249,212.14445
73.10000,3.65499,17186.54782,0.00000,0.01252,212.49651
73.20000,3.65989,17209.31828,0.00000,0.01254,212.77805
73.30000,3.66510,17236.55462,0.00000,0.01257,213.11480
73.40000,3.66994,17258.82739,0.00000,0.01259,213.39018
73.50000,3.67508,17286.98313,0.00000,0.01261,213.73831
73.60000,3.67986,17309.34680,0.00000,0.01263,214.01481
73.70000,3.68507,17337.43995,0.00000,0.01266,214.36216
73.80000,3.68991,17360.68428,0.00000,0.01268,214.64955
73.90000,3.69511,17389.65809,0.00000,0.01270,215.00779
74.00000,3.69995,17415.39687,0.00000,0.01273,215.32603
74.10000,3.70504,17442.02226,0.00000,0.01275,215.65523
74.20000,3.71000,17468.69683,0.00000,0.01277,215.98503
74.30000,3.71508,17493.27481,0.00000,0.01280,216.28892
74.40000,3.71998,17519.50234,0.00000,0.01282,216.61320
74.50000,3.72501,17545.26198,0.00000,0.01284,216.93170
74.60000,3.72997,17572.05576,0.00000,0.01287,217.26298
74.70000,3.73505,17597.07034,0.00000,0.01289,217.57226
74.80000,3.74001,17622.36506,0.00000,0.01291,217.88501
74.90000,3.74503,17647.43775,0.00000,0.01293,218.19501
75.00000,3.75000,17675.22693,0.00000,0.01296,218.53860
75.10000,3.75508,17699.86898,0.00000,0.01298,218.84327
75.20000,3.76010,17726.55398,0.00000,0.01300,219.17321
75.30000,3.76506,17750.33176,0.00000,0.01303,219.46720
75.40000,3.76997,17777.25369,0.00000,0.01305,219.80007
75.50000,3.77499,17802.33830,0.00000,0.01307,220.11022
75.60000,3.78007,17829.22894,0.00000,0.01310,220.44270
75.70000,3.78497,17852.18418,0.00000,0.01312,220.72652
75.80000,3.79006,17880.22667,0.00000,0.01314,221.07324
75.90000,3.79484,17903.11635,0.00000,0.01316,221.35625
76.00000,3.80004,17931.58501,0.00000,0.01319,221.70824
76.10000,3.80494,17957.53390,0.00000,0.01321,222.02907
76.20000,3.81009,17984.95501,0.00000,0.01324,222.36811
76.30000,3.81493,18009.51809,0.00000,0.01326,222.67181
76.40000,3.82001,18036.94367,0.00000,0.01329,223.01091
76.50000,3.82491,18062.54089,0.00000,0.01331,223.32739
76.60000,3.83006,18088.21112,0.00000,0.01334,223.64478
76.70000,3.83496,18113.88880,0.00000,0.01336,223.96226
76.80000,3.84004,18138.84526,0.00000,0.01338,224.27083
76.90000,3.84494,18165.81041,0.00000,0.01341,224.60423
77.00000,3.85002,18191.56408,0.00000,0.01343,224.92265
77.10000,3.85499,18216.93331,0.00000,0.01345,225.23632
77.20000,3.86007,18243.18022,0.00000,0.01347,225.56084
77.30000,3.86497,18268.00704,0.00000,0.01350,225.86780
77.40000,3.86999,18292.88006,0.00000,0.01352,226.17533
77.50000,3.87496,18319.27449,0.00000,0.01355,226.50168
77.60000,3.88004,18343.33837,0.00000,0.01357,226.79921
77.70000,3.88506,18372.66535,0.00000,0.01359,227.16181
77.80000,3.88996,18395.33448,0.00000,0.01362,227.44209
77.90000,3.89505,18422.82563,0.00000,0.01364,227.78200
78.00000,3.89995,18447.62415,0.00000,0.01366,228.08861
78.10000,3.90503,18473.58197,0.00000,0.01369,228.40955
78.20000,3.90987,18497.89768,0.00000,0.01371,228.71020
78.30000,3.91502,18525.65855,0.00000,0.01373,229.05343
78.40000,3.91986,18548.22785,0.00000,0.01375,229.33248
78.50000,3.92512,18576.67714,0.00000,0.01378,229.68423
78.60000,3.92996,18600.55774,0.00000,0.01380,229.97950
78.70000,3.93511,18626.37103,0.00000,0.01382,230.29866
78.80000,3.93995,18651.51972,0.00000,0.01385,230.60960
78.90000,3.94503,18676.85169,0.00000,0.01387,230.92280
79.00000,3.94993,18700.98561,0.00000,0.01389,231.22120
79.10000,3.95501,18726.64690,0.00000,0.01392,231.53848
79.20000,3.95992,18750.94920,0.00000,0.01394,231.83895
79.30000,3.96500,18778.09465,0.00000,0.01396,232.17458
79.40000,3.96996,18805.25500,0.00000,0.01399,232.51040
79.50000,3.97504,18829.44852,0.00000,0.01401,232.80953
79.60000,3.98007,18855.59708,0.00000,0.01403,233.13283
79.70000,3.98497,18878.81607,0.00000,0.01406,233.41992
79.80000,3.98999,18905.91681,0.00000,0.01408,233.75499
79.90000,3.99501,18929.27289,0.00000,0.01411,234.04377
80.00000,4.00004,18956.47198,0.00000,0.01413,234.38006
80.10000,4.00500,18980.20804,0.00000,0.01415,234.67354
80.20000,4.01002,19009.17441,0.00000,0.01417,235.03168
80.30000,4.01492,19032.54986,0.00000,0.01419,235.32070
80.40000,4.02007,19059.37493,0.00000,0.01422,235.65237
80.50000,4.02503,19084.14364,0.00000,0.01425,235.95861
80.60000,4.03011,19109.40260,0.00000,0.01427,236.27092
80.70000,4.03495,19133.29959,0.00000,0.01429,236.56638
80.80000,4.04004,19159.65825,0.00000,0.01432,236.89228
80.90000,4.04494,19183.19315,0.00000,0.01434,237.18327
81.00000,4.05014,19211.06577,0.00000,0.01436,237.52789
81.10000,4.05486,19233.86306,0.00000,0.01438,237.80976
81.20000,4.06001,19261.47342,0.00000,0.01441,238.15114
81.30000,4.06485,19286.35389,0.00000,0.01443,238.45876
81.40000,4.06999,19311.35505,0.00000,0.01446,238.76788
81.50000,4.07495,19337.32033,0.00000,0.01448,239.08892
81.60000,4.08003,19362.26785,0.00000,0.01450,239.39737
81.70000,4.08488,19388.40300,0.00000,0.01453,239.72051
81.80000,4.09002,19414.42341,0.00000,0.01455,240.04223
81.90000,4.09498,19439.48120,0.00000,0.01458,240.35205
82.00000,4.10000,19462.22335,0.00000,0.01460,240.63323
82.10000,4.10497,19489.07077,0.00000,0.01462,240.96518
82.20000,4.10993,19511.19304,0.00000,0.01464,241.23870
82.30000,4.11495,19538.16414,0.00000,0.01467,241.57217
82.40000,4.11997,19561.71095,0.00000,0.01469,241.86331
82.50000,4.12500,19587.27837,0.00000,0.01472,242.17943
82.60000,4.12990,19612.71316,0.00000,0.01474,242.49391
82.70000,4.13504,19640.23262,0.00000,0.01476,242.83416
82.80000,4.13994,19662.58883,0.00000,0.01478,243.11058
82.90000,4.14509,19688.84915,0.00000,0.01481,243.43526
83.00000,4.14987,19711.37226,0.00000,0.01483,243.71374
83.10000,4.15501,19736.64016,0.00000,0.01486,244.02615
83.20000,4.15985,19761.07359,0.00000,0.01488,244.32825
83.30000,4.16500,19785.81399,0.00000,0.01490,244.63415
83.40000,4.16990,19810.12225,0.00000,0.01492,244.93470
83.50000,4.17498,19835.46615,0.00000,0.01495,245.24805
83.60000,4.17988,19860.57758,0.00000,0.01497,245.55853
83.70000,4.18497,19886.29252,0.00000,0.01499,245.87647
83.80000,4.18993,19910.38024,0.00000,0.01502,246.17430
83.90000,4.19507,19935.18472,0.00000,0.01504,246.48098
84.00000,4.19997,19959.98621,0.00000,0.01507,246.78763
84.10000,4.20494,19984.61783,0.00000,0.01509,247.09218
84.20000,4.20996,20009.49979,0.00000,0.01511,247.39982
84.30000,4.21510,20034.85262,0.00000,0.01513,247.71329
84.40000,4.22000,20058.96866,0.00000,0.01516,248.01146
84.50000,4.22502,20082.53336,0.00000,0.01518,248.30282
84.60000,4.22993,20108.57314,0.00000,0.01520,248.62478
84.70000,4.23501,20132.46566,0.00000,0.01522,248.92019
84.80000,4.24003,20158.61720,0.00000,0.01525,249.24353
84.90000,4.24499,20182.74516,0.00000,0.01527,249.54185
85.00000,4.24996,20209.59854,0.00000,0.01530,249.87387
85.10000,4.25492,20235.06165,0.00000,0.01532,250.18870
85.20000,4.26000,20261.65724,0.00000,0.01534,250.51753
85.30000,4.26496,20284.51264,0.00000,0.01537,250.80011
85.40000,4.27005,20310.41682,0.00000,0.01539,251.12040
85.50000,4.27489,20333.00549,0.00000,0.01542,251.39969
85.60000,4.28009,20358.23464,0.00000,0.01544,251.71162
85.70000,4.28493,20382.14207,0.00000,0.01546,252.00722
85.80000,4.29008,20408.40387,0.00000,0.01549,252.33192
85.90000,4.29486,20431.10430,0.00000,0.01551,252.61259
86.00000,4.30006,20459.16468,0.00000,0.01554,252.95953
86.10000,4.30490,20482.93203,0.00000,0.01556,253.25340
86.20000,4.31010,20508.33404,0.00000,0.01558,253.56747
86.30000,4.31495,20532.30852,0.00000,0.01561,253.86389
86.40000,4.32003,20556.80305,0.00000,0.01563,254.16675
86.50000,4.32487,20582.59547,0.00000,0.01565,254.48565
86.60000,4.32995,20606.78005,0.00000,0.01568,254.78467
86.70000,4.33498,20631.25670,0.00000,0.01570,255.08730
86.80000,4.33994,20655.15220,0.00000,0.01572,255.38275
86.90000,4.34490,20682.45709,0.00000,0.01575,255.72035
87.00000,4.34992,20705.03682,0.00000,0.01577,255.99953
87.10000,4.35501,20732.86474,0.00000,0.01580,256.34359
87.20000,4.36003,20754.00651,0.00000,0.01582,256.60499
87.30000,4.36505,20779.76763,0.00000,0.01584,256.92351
87.40000,4.36989,20802.36226,0.00000,0.01586,257.20287
87.50000,4.37504,20829.84596,0.00000,0.01589,257.54268
87.60000,4.38000,20851.78345,0.00000,0.01591,257.81392
87.70000,4.38508,20874.75359,0.00000,0.01593,258.09792
87.80000,4.38986,20895.21885,0.00000,0.01595,258.35096
87.90000,4.39501,20921.12601,0.00000,0.01598,258.67128
88.00000,4.39985,20943.17675,0.00000,0.01599,258.94392
88.10000,4.40511,20967.22871,0.00000,0.01602,259.24130
88.20000,4.41001,20990.24951,0.00000,0.01604,259.52593
88.30000,4.41510,21013.62646,0.00000,0.01606,259.81496
88.37000,4.41850,20580.75219,0.00000,0.01590,254.46286
88.37200,4.41868,20000.10014,0.00000,0.01554,247.28360
88.37400,4.41892,19207.19594,0.00000,0.01508,237.48004
88.37600,4.41910,18271.44623,0.00000,0.01489,225.91032
88.37800,4.41940,17224.63369,0.00000,0.01526,212.96741
88.38000,4.41982,16094.70397,0.00000,0.01611,198.99682
88.38200,4.42012,14919.92027,0.00000,0.01725,184.47166
88.38400,4.42042,13726.12566,0.00000,0.01859,169.71144
88.38600,4.42084,12525.64490,0.00000,0.02004,154.86856