File: scratch/college-stuff/ME Lab/ME lab Fall 2013/group7/group7.is_tens_RawData/Specimen_RawData_5.csv
Time,Extension,Load,Strain 2,Tensile strain,Tensile stress
(sec),(mm),(N),(mm/mm),(mm/mm),(MPa)
0.00000,0.00006,-0.89465,0.00000,0.00000,-0.01098
0.40000,0.01943,71.98665,0.00000,0.00002,0.88360
0.80000,0.04006,109.49994,0.00000,0.00002,1.34406
1.20000,0.06009,154.74230,0.00000,0.00002,1.89938
1.60000,0.08006,205.99496,0.00000,0.00003,2.52848
2.00000,0.09997,261.83012,0.00000,0.00003,3.21383
2.40000,0.11988,332.49063,0.00000,0.00003,4.08115
2.80000,0.13991,422.46720,0.00000,0.00002,5.18557
3.20000,0.15994,521.51545,0.00000,-0.00004,6.40133
3.60000,0.17997,635.76452,0.00000,-0.00017,7.80368
4.00000,0.20006,771.63326,0.00000,-0.00025,9.47140
4.40000,0.22009,935.13373,0.00000,-0.00039,11.47829
4.80000,0.24005,1123.25829,0.00000,-0.00060,13.78742
5.20000,0.26002,1327.17090,0.00000,-0.00098,16.29034
5.60000,0.27999,1536.49990,0.00000,-0.00149,18.85975
6.00000,0.30008,1755.10067,0.00000,-0.00189,21.54296
6.40000,0.31999,1995.41915,0.00000,-0.00209,24.49275
6.80000,0.33984,2256.66985,0.00000,-0.00216,27.69946
7.20000,0.35987,2534.65511,0.00000,-0.00219,31.11159
7.60000,0.37984,2815.98903,0.00000,-0.00222,34.56482
8.00000,0.39993,3102.16341,0.00000,-0.00224,38.07746
8.40000,0.41996,3389.24564,0.00000,-0.00225,41.60125
8.80000,0.43999,3676.42157,0.00000,-0.00224,45.12619
9.20000,0.46008,3963.18361,0.00000,-0.00223,48.64605
9.60000,0.48005,4247.89973,0.00000,-0.00221,52.14079
10.00000,0.50002,4530.66863,0.00000,-0.00218,55.61163
10.40000,0.52005,4813.32280,0.00000,-0.00215,59.08107
10.80000,0.54002,5087.43040,0.00000,-0.00212,62.44560
11.20000,0.55993,5344.90123,0.00000,-0.00207,65.60592
11.60000,0.57990,5600.73145,0.00000,-0.00204,68.74611
12.00000,0.59975,5851.71282,0.00000,-0.00202,71.82677
12.40000,0.61984,6088.43192,0.00000,-0.00199,74.73238
12.80000,0.63999,6311.71390,0.00000,-0.00196,77.47305
13.20000,0.66002,6534.24710,0.00000,-0.00192,80.20453
13.60000,0.68005,6760.11369,0.00000,-0.00189,82.97693
14.00000,0.70013,6984.54827,0.00000,-0.00185,85.73175
14.40000,0.72004,7208.87408,0.00000,-0.00181,88.48523
14.80000,0.74007,7429.82104,0.00000,-0.00177,91.19724
15.20000,0.75998,7645.22925,0.00000,-0.00173,93.84127
15.60000,0.77995,7835.75326,0.00000,-0.00170,96.17985
16.00000,0.79998,8021.09540,0.00000,-0.00167,98.45483
16.40000,0.81989,8207.64080,0.00000,-0.00163,100.74458
16.80000,0.83986,8395.61298,0.00000,-0.00160,103.05184
17.20000,0.85989,8587.12420,0.00000,-0.00156,105.40254
17.60000,0.87992,8776.33616,0.00000,-0.00153,107.72502
18.00000,0.90001,8967.62684,0.00000,-0.00150,110.07302
18.40000,0.92004,9157.95714,0.00000,-0.00146,112.40923
18.80000,0.94007,9348.43644,0.00000,-0.00143,114.74726
19.20000,0.96004,9538.89266,0.00000,-0.00140,117.08501
19.60000,0.98001,9732.99667,0.00000,-0.00136,119.46754
20.00000,0.99998,9922.54838,0.00000,-0.00133,121.79419
20.40000,1.02001,10115.15111,0.00000,-0.00129,124.15829
20.80000,1.03992,10310.75045,0.00000,-0.00126,126.55917
21.20000,1.05989,10508.25566,0.00000,-0.00122,128.98345
21.60000,1.07992,10703.46460,0.00000,-0.00119,131.37954
22.00000,1.09989,10900.94745,0.00000,-0.00115,133.80354
22.40000,1.11998,11100.01132,0.00000,-0.00112,136.24694
22.80000,1.13995,11297.40551,0.00000,-0.00108,138.66986
23.20000,1.16004,11494.30722,0.00000,-0.00104,141.08672
23.60000,1.18007,11692.84657,0.00000,-0.00101,143.52369
24.00000,1.20003,11892.99896,0.00000,-0.00097,145.98046
24.40000,1.22000,12092.44877,0.00000,-0.00093,148.42861
24.80000,1.23997,12293.48034,0.00000,-0.00090,150.89616
25.20000,1.25994,12492.88842,0.00000,-0.00086,153.34380
25.60000,1.27991,12692.80910,0.00000,-0.00082,155.79772
26.00000,1.29988,12894.35178,0.00000,-0.00078,158.27155
26.40000,1.31991,13101.71336,0.00000,-0.00074,160.81681
26.80000,1.33994,13305.47482,0.00000,-0.00070,163.31788
27.20000,1.35997,13506.66881,0.00000,-0.00066,165.78743
27.60000,1.37994,13710.08307,0.00000,-0.00062,168.28424
28.00000,1.40003,13913.24401,0.00000,-0.00058,170.77793
28.40000,1.42012,14119.85904,0.00000,-0.00054,173.31403
28.80000,1.44009,14323.37016,0.00000,-0.00050,175.81202
29.20000,1.46006,14526.75164,0.00000,-0.00046,178.30842
29.60000,1.47997,14731.89741,0.00000,-0.00042,180.82648
30.00000,1.49994,14934.99875,0.00000,-0.00038,183.31945
30.40000,1.51991,15139.97614,0.00000,-0.00034,185.83544
30.80000,1.53994,15344.80006,0.00000,-0.00029,188.34955
31.20000,1.55991,15553.09892,0.00000,-0.00026,190.90631
31.60000,1.57994,15758.38625,0.00000,-0.00021,193.42611
32.00000,1.59991,15966.64339,0.00000,-0.00017,195.98236
32.40000,1.62000,16173.21521,0.00000,-0.00013,198.51792
32.80000,1.64009,16378.86763,0.00000,-0.00009,201.04220
33.20000,1.66006,16584.63776,0.00000,-0.00004,203.56792
33.60000,1.68008,16792.92470,0.00000,0.00000,206.12454
34.00000,1.69999,16998.64864,0.00000,0.00005,208.64969
34.40000,1.71996,17203.44424,0.00000,0.00009,211.16345
34.80000,1.73993,17410.02649,0.00000,0.00013,213.69914
35.20000,1.75990,17615.47774,0.00000,0.00017,216.22095
35.60000,1.77999,17820.33592,0.00000,0.00023,218.73548
36.00000,1.79996,18023.78446,0.00000,0.00027,221.23271
36.40000,1.81993,18229.04944,0.00000,0.00032,223.75223
36.80000,1.83996,18434.85832,0.00000,0.00037,226.27843
37.20000,1.85993,18638.71366,0.00000,0.00042,228.78065
37.60000,1.88002,18838.41753,0.00000,0.00047,231.23191
38.00000,1.89999,19036.55380,0.00000,0.00052,233.66393
38.40000,1.92002,19234.77054,0.00000,0.00057,236.09694
38.80000,1.93999,19431.02926,0.00000,0.00063,238.50592
39.20000,1.95996,19621.81926,0.00000,0.00068,240.84777
39.60000,1.97999,19812.16818,0.00000,0.00074,243.18420
40.00000,1.99996,19996.65350,0.00000,0.00080,245.44866
40.40000,2.01993,20178.85447,0.00000,0.00086,247.68509
40.80000,2.03996,20362.15067,0.00000,0.00092,249.93495
41.20000,2.05999,20535.75367,0.00000,0.00099,252.06584
41.60000,2.07996,20707.85016,0.00000,0.00106,254.17824
42.00000,2.09993,20872.02221,0.00000,0.00112,256.19337
42.40000,2.12002,21030.29341,0.00000,0.00120,258.13606
42.80000,2.14005,21181.02461,0.00000,0.00127,259.98621
43.20000,2.16007,21326.38544,0.00000,0.00135,261.77044
43.60000,2.18004,21460.03991,0.00000,0.00143,263.41098
44.00000,2.20001,21587.13937,0.00000,0.00151,264.97106
44.40000,2.21998,21703.89295,0.00000,0.00160,266.40415
44.80000,2.23995,21810.67318,0.00000,0.00169,267.71482
45.20000,2.25992,21911.89528,0.00000,0.00178,268.95727
45.60000,2.27995,22006.13469,0.00000,0.00187,270.11401
46.00000,2.29992,22092.21423,0.00000,0.00197,271.17060
46.40000,2.31995,22171.77451,0.00000,0.00208,272.14716
46.80000,2.33998,22241.70715,0.00000,0.00219,273.00554
47.20000,2.36001,22306.48100,0.00000,0.00230,273.80061
47.60000,2.38004,22367.54596,0.00000,0.00243,274.55015
48.00000,2.40007,22421.66549,0.00000,0.00256,275.21444
48.40000,2.42004,22471.26848,0.00000,0.00269,275.82329
48.80000,2.44007,22516.48456,0.00000,0.00283,276.37830
49.20000,2.46004,22560.76187,0.00000,0.00298,276.92178
49.60000,2.47989,22598.80900,0.00000,0.00313,277.38879
50.00000,2.49992,22632.77769,0.00000,0.00330,277.80574
50.40000,2.51995,22667.04291,0.00000,0.00347,278.22632
50.80000,2.53998,22698.97461,0.00000,0.00365,278.61827
51.20000,2.55995,22730.04651,0.00000,0.00383,278.99966
51.60000,2.57998,22759.22447,0.00000,0.00401,279.35780
52.00000,2.60007,22782.12756,0.00000,0.00419,279.63893
52.40000,2.62004,22806.41049,0.00000,0.00437,279.93699
52.80000,2.64006,22828.66687,0.00000,0.00456,280.21017
53.20000,2.66003,22849.18129,0.00000,0.00473,280.46198
53.60000,2.68006,22868.69884,0.00000,0.00491,280.70155
54.00000,2.69997,22886.26134,0.00000,0.00509,280.91712
54.40000,2.71994,22903.90879,0.00000,0.00527,281.13373
54.80000,2.73985,22919.22271,0.00000,0.00545,281.32170
55.20000,2.75994,22938.10844,0.00000,0.00562,281.55351
55.60000,2.77997,22955.04212,0.00000,0.00581,281.76137
56.00000,2.80000,22970.13253,0.00000,0.00599,281.94659
56.40000,2.81997,22987.08707,0.00000,0.00617,282.15470
56.80000,2.84000,22999.70835,0.00000,0.00636,282.30962
57.20000,2.85997,23011.82896,0.00000,0.00656,282.45840
57.60000,2.88012,23025.31004,0.00000,0.00675,282.62387
58.00000,2.90009,23039.07871,0.00000,0.00695,282.79287
58.40000,2.92000,23050.43787,0.00000,0.00715,282.93230
58.80000,2.93997,23062.77007,0.00000,0.00735,283.08367
59.20000,2.95988,23072.78961,0.00000,0.00755,283.20666
59.60000,2.97991,23085.00707,0.00000,0.00775,283.35662
60.00000,2.99988,23097.92042,0.00000,0.00796,283.51512
60.40000,3.01997,23111.33295,0.00000,0.00816,283.67976
60.80000,3.04006,23124.53091,0.00000,0.00836,283.84175
61.20000,3.06009,23135.70082,0.00000,0.00856,283.97886
61.60000,3.08006,23146.73513,0.00000,0.00876,284.11430
62.00000,3.10009,23156.95882,0.00000,0.00897,284.23979
62.40000,3.12005,23167.50437,0.00000,0.00917,284.36923
62.80000,3.14008,23178.20638,0.00000,0.00937,284.50059
63.20000,3.16011,23188.85326,0.00000,0.00956,284.63128
63.60000,3.17996,23198.50177,0.00000,0.00976,284.74971
64.00000,3.19987,23209.35279,0.00000,0.00996,284.88290
64.40000,3.21984,23215.91377,0.00000,0.01016,284.96343
64.80000,3.23987,23228.46651,0.00000,0.01035,285.11751
65.20000,3.25996,23240.37403,0.00000,0.01055,285.26367
65.60000,3.28005,23251.85239,0.00000,0.01074,285.40456
66.00000,3.30002,23259.22400,0.00000,0.01095,285.49504
66.40000,3.32011,23270.18827,0.00000,0.01115,285.62962
66.80000,3.34002,23278.25129,0.00000,0.01134,285.72859
67.20000,3.36005,23288.44368,0.00000,0.01154,285.85370
67.60000,3.38008,23297.54531,0.00000,0.01174,285.96542
68.00000,3.40005,23305.92871,0.00000,0.01194,286.06832
68.40000,3.41996,23315.00500,0.00000,0.01214,286.17973
68.80000,3.43987,23325.85454,0.00000,0.01234,286.31290
69.20000,3.45984,23334.50019,0.00000,0.01254,286.41902
69.60000,3.47993,23343.68080,0.00000,0.01273,286.53171
70.00000,3.50008,23354.69127,0.00000,0.01294,286.66685
70.40000,3.52005,23365.08781,0.00000,0.01314,286.79447
70.80000,3.54014,23378.40050,0.00000,0.01334,286.95787
71.20000,3.56011,23386.78092,0.00000,0.01353,287.06074
71.60000,3.58007,23395.08235,0.00000,0.01373,287.16263
72.00000,3.59999,23403.92172,0.00000,0.01393,287.27113
72.40000,3.62001,23413.24538,0.00000,0.01413,287.38558
72.80000,3.64004,23422.01620,0.00000,0.01433,287.49323
73.20000,3.65995,23428.23893,0.00000,0.01452,287.56961
73.60000,3.67992,23436.86223,0.00000,0.01472,287.67546
74.00000,3.69995,23449.10651,0.00000,0.01492,287.82575
74.40000,3.71998,23457.14271,0.00000,0.01512,287.92439
74.80000,3.74001,23465.01201,0.00000,0.01531,288.02098
75.20000,3.76010,23475.72148,0.00000,0.01550,288.15244
75.60000,3.78007,23485.17030,0.00000,0.01570,288.26842
76.00000,3.80004,23495.03636,0.00000,0.01589,288.38952
76.40000,3.82001,23503.27373,0.00000,0.01610,288.49063
76.80000,3.84004,23509.87047,0.00000,0.01629,288.57160
77.20000,3.86007,23518.11230,0.00000,0.01649,288.67276
77.60000,3.88004,23526.94273,0.00000,0.01668,288.78115
78.00000,3.89995,23535.22629,0.00000,0.01688,288.88283
78.40000,3.91992,23541.81260,0.00000,0.01707,288.96367
78.80000,3.93995,23550.91721,0.00000,0.01727,289.07543
79.20000,3.95986,23558.20388,0.00000,0.01746,289.16487
79.60000,3.98007,23571.81162,0.00000,0.01765,289.33189
80.00000,4.00004,23580.90132,0.00000,0.01784,289.44347
80.40000,4.02007,23589.07759,0.00000,0.01803,289.54383
80.80000,4.04010,23597.41479,0.00000,0.01822,289.64616
81.20000,4.06001,23605.76838,0.00000,0.01841,289.74870
81.60000,4.08003,23612.89412,0.00000,0.01860,289.83616
82.00000,4.10000,23619.14366,0.00000,0.01879,289.91287
82.40000,4.11997,23627.64031,0.00000,0.01898,290.01716
82.80000,4.13994,23636.91926,0.00000,0.01917,290.13106
83.20000,4.15991,23645.28924,0.00000,0.01936,290.23380
83.60000,4.17988,23652.54313,0.00000,0.01955,290.32283
84.00000,4.19997,23661.17388,0.00000,0.01973,290.42877
84.40000,4.22000,23669.48873,0.00000,0.01992,290.53083
84.80000,4.24009,23680.92686,0.00000,0.02011,290.67123
85.20000,4.26006,23688.93325,0.00000,0.02030,290.76950
85.60000,4.28009,23696.61927,0.00000,0.02049,290.86384
86.00000,4.30006,23705.45268,0.00000,0.02068,290.97227
86.40000,4.32003,23712.18204,0.00000,0.02086,291.05487
86.80000,4.33994,23717.32295,0.00000,0.02105,291.11797
87.20000,4.36003,23724.73031,0.00000,0.02123,291.20889
87.60000,4.38000,23732.93489,0.00000,0.02142,291.30960
88.00000,4.39985,23740.34524,0.00000,0.02160,291.40056
88.40000,4.41994,23749.81642,0.00000,0.02178,291.51681
88.80000,4.43991,23756.91831,0.00000,0.02196,291.60398
89.20000,4.46000,23765.92606,0.00000,0.02213,291.71455
89.60000,4.48009,23774.04571,0.00000,0.02231,291.81421
90.00000,4.50012,23782.33373,0.00000,0.02248,291.91595
90.40000,4.52009,23791.42791,0.00000,0.02265,292.02757
90.80000,4.54000,23796.11433,0.00000,0.02281,292.08510
91.20000,4.55996,23802.30427,0.00000,0.02298,292.16107
91.60000,4.57999,23808.09337,0.00000,0.02315,292.23213
92.00000,4.60002,23816.67048,0.00000,0.02331,292.33741
92.40000,4.61993,23823.62783,0.00000,0.02347,292.42281
92.80000,4.63996,23830.75505,0.00000,0.02363,292.51029
93.20000,4.65993,23837.78691,0.00000,0.02377,292.59661
93.60000,4.67996,23846.22097,0.00000,0.02390,292.70013
94.00000,4.69999,23853.93977,0.00000,0.02399,292.79487
94.40000,4.72008,23861.70775,0.00000,0.02407,292.89022
94.80000,4.74005,23869.13896,0.00000,0.02417,292.98144
95.20000,4.76008,23876.27661,0.00000,0.02430,293.06905
95.60000,4.77993,23882.00015,0.00000,0.02445,293.13930
96.00000,4.79996,23889.72193,0.00000,0.02461,293.23408
96.40000,4.81999,23891.82597,0.00000,0.02475,293.25991
96.80000,4.84008,23901.00360,0.00000,0.02489,293.37256
97.20000,4.86005,23906.97598,0.00000,0.02503,293.44587
97.60000,4.87996,23914.18070,0.00000,0.02513,293.53430
98.00000,4.89999,23924.17341,0.00000,0.02521,293.65696
98.40000,4.91990,23929.18020,0.00000,0.02531,293.71841
98.80000,4.93999,23935.64284,0.00000,0.02539,293.79774
99.20000,4.96002,23942.41542,0.00000,0.02545,293.88087
99.60000,4.98011,23953.04143,0.00000,0.02542,294.01130
100.00000,5.00008,23957.73083,0.00000,0.02510,294.06886
100.40000,5.02005,23963.63169,0.00000,0.02507,294.14129
100.80000,5.04002,23969.95723,0.00000,0.02508,294.21893
101.20000,5.05998,23975.14433,0.00000,0.02516,294.28260
101.60000,5.08007,23981.83346,0.00000,0.02527,294.36470
102.00000,5.09998,23987.97870,0.00000,0.02540,294.44013
102.40000,5.11995,23995.88972,0.00000,0.02555,294.53724
102.80000,5.13986,24003.16596,0.00000,0.02570,294.62655
103.20000,5.15989,24010.11437,0.00000,0.02585,294.71184
103.60000,5.17998,24017.25054,0.00000,0.02599,294.79943
104.00000,5.20007,24022.30948,0.00000,0.02614,294.86153
104.40000,5.22010,24028.37127,0.00000,0.02629,294.93593
104.80000,5.24007,24034.54185,0.00000,0.02644,295.01167
105.20000,5.25998,24040.26687,0.00000,0.02659,295.08194
105.60001,5.28001,24045.64470,0.00000,0.02673,295.14795
106.00001,5.29998,24051.27585,0.00000,0.02688,295.21707
106.40001,5.32001,24058.21979,0.00000,0.02703,295.30231
106.80001,5.33998,24063.27426,0.00000,0.02719,295.36435
107.20001,5.35995,24068.25721,0.00000,0.02735,295.42551
107.60001,5.37992,24073.99267,0.00000,0.02751,295.49591
108.00001,5.39989,24080.68329,0.00000,0.02766,295.57803
108.40001,5.41998,24087.46332,0.00000,0.02780,295.66126
108.80001,5.44007,24091.97688,0.00000,0.02795,295.71666
109.20001,5.46016,24097.39941,0.00000,0.02809,295.78322
109.60001,5.48013,24102.61184,0.00000,0.02824,295.84720
110.00001,5.49998,24108.26236,0.00000,0.02840,295.91655
110.40001,5.52001,24113.52545,0.00000,0.02855,295.98115
110.80001,5.53997,24115.99606,0.00000,0.02871,296.01148
111.20001,5.56000,24119.78692,0.00000,0.02886,296.05801
111.60001,5.57991,24125.20498,0.00000,0.02901,296.12451
112.00001,5.59994,24133.50046,0.00000,0.02917,296.22634
112.40001,5.61991,24138.93640,0.00000,0.02932,296.29306
112.80001,5.63994,24143.13108,0.00000,0.02948,296.34455
113.20001,5.65997,24147.97693,0.00000,0.02964,296.40403
113.60001,5.68006,24153.22214,0.00000,0.02979,296.46841
114.00001,5.70009,24158.76687,0.00000,0.02995,296.53647
114.40001,5.72012,24163.52332,0.00000,0.03010,296.59485
114.80001,5.74003,24167.90724,0.00000,0.03026,296.64866
115.20001,5.76000,24173.60097,0.00000,0.03041,296.71855
115.60001,5.77997,24177.00589,0.00000,0.03056,296.76034
116.00001,5.80000,24179.48097,0.00000,0.03071,296.79072
116.40001,5.81997,24184.80068,0.00000,0.03086,296.85602
116.80001,5.83994,24190.09656,0.00000,0.03101,296.92103
117.20001,5.85991,24196.91384,0.00000,0.03116,297.00470
117.60001,5.87988,24203.38988,0.00000,0.03132,297.08419
118.00001,5.90003,24207.07494,0.00000,0.03147,297.12943
118.40001,5.92006,24211.83139,0.00000,0.03162,297.18781
118.80001,5.94015,24217.63837,0.00000,0.03177,297.25909
119.20001,5.96012,24222.63771,0.00000,0.03192,297.32045
119.60001,5.98003,24227.84418,0.00000,0.03207,297.38436
120.00001,6.00006,24231.22823,0.00000,0.03222,297.42590
120.40001,6.01996,24233.78974,0.00000,0.03237,297.45734
120.80001,6.03987,24238.20943,0.00000,0.03252,297.51159
121.20001,6.05990,24242.65891,0.00000,0.03267,297.56620
121.60001,6.07993,24247.18887,0.00000,0.03283,297.62180
122.00001,6.09996,24254.31162,0.00000,0.03297,297.70923
122.40001,6.11993,24261.20192,0.00000,0.03312,297.79381
122.80001,6.13996,24265.14477,0.00000,0.03327,297.84220
123.20001,6.16005,24269.09506,0.00000,0.03342,297.89069
123.60001,6.18014,24273.85300,0.00000,0.03357,297.94909
124.00001,6.20011,24279.69575,0.00000,0.03371,298.02081
124.40001,6.22008,24284.35832,0.00000,0.03386,298.07804
124.80001,6.24005,24287.63360,0.00000,0.03400,298.11824
125.20001,6.25990,24288.57237,0.00000,0.03415,298.12977
125.60001,6.27993,24293.72519,0.00000,0.03430,298.19301
126.00001,6.29990,24298.53380,0.00000,0.03445,298.25204
126.40001,6.31999,24304.73417,0.00000,0.03459,298.32814
126.80001,6.33996,24309.28499,0.00000,0.03475,298.38400
127.20001,6.35999,24314.36330,0.00000,0.03490,298.44634
127.60001,6.38008,24320.34165,0.00000,0.03505,298.51972
128.00001,6.40005,24322.35926,0.00000,0.03520,298.54448
128.40001,6.42014,24327.84140,0.00000,0.03535,298.61177
128.80001,6.44017,24330.98406,0.00000,0.03550,298.65035
129.20001,6.46007,24335.74647,0.00000,0.03566,298.70880
129.60001,6.47998,24338.14555,0.00000,0.03582,298.73825
130.00001,6.49990,24340.37179,0.00000,0.03597,298.76558
130.40001,6.51986,24342.53544,0.00000,0.03612,298.79213
130.80001,6.53995,24347.49007,0.00000,0.03627,298.85295
131.20001,6.55998,24353.86330,0.00000,0.03643,298.93118
131.60001,6.57995,24359.70306,0.00000,0.03658,299.00286
132.00001,6.60004,24365.49217,0.00000,0.03673,299.07392
132.40001,6.62001,24368.95967,0.00000,0.03689,299.11648
132.80001,6.63998,24370.87297,0.00000,0.03704,299.13996
133.20001,6.66007,24376.52797,0.00000,0.03719,299.20938
133.60001,6.68010,24379.35621,0.00000,0.03734,299.24409
134.00001,6.70007,24382.67916,0.00000,0.03750,299.28488
134.40001,6.72004,24386.70546,0.00000,0.03765,299.33430
134.80001,6.73995,24388.26412,0.00000,0.03780,299.35343
135.20001,6.75986,24392.24422,0.00000,0.03796,299.40228
135.60001,6.77989,24395.14101,0.00000,0.03811,299.43784
136.00001,6.79998,24400.73639,0.00000,0.03826,299.50652
136.40001,6.82001,24406.80116,0.00000,0.03841,299.58096
136.80001,6.84004,24410.84385,0.00000,0.03856,299.63059
137.20001,6.86001,24414.65259,0.00000,0.03872,299.67734
137.60001,6.88004,24418.23334,0.00000,0.03887,299.72129
138.00001,6.90013,24421.73362,0.00000,0.03903,299.76425
138.40001,6.92010,24423.62458,0.00000,0.03918,299.78746
138.80001,6.94007,24429.00240,0.00000,0.03934,299.85347
139.20001,6.95997,24429.76981,0.00000,0.03949,299.86289
139.60001,6.97994,24432.09440,0.00000,0.03965,299.89142
140.00001,6.99985,24435.95082,0.00000,0.03980,299.93876
140.40001,7.01988,24440.14698,0.00000,0.03996,299.99027
140.80001,7.04003,24444.85128,0.00000,0.04012,300.04801
141.20001,7.06000,24448.45289,0.00000,0.04027,300.09222
141.60001,7.07997,24452.83681,0.00000,0.04043,300.14603
142.00001,7.10000,24457.30418,0.00000,0.04059,300.20086
142.40001,7.12003,24460.35296,0.00000,0.04075,300.23828
142.80001,7.14006,24460.92665,0.00000,0.04091,300.24533
143.20001,7.16009,24463.37193,0.00000,0.04107,300.27534
143.60001,7.18000,24466.44306,0.00000,0.04123,300.31304
144.00001,7.19991,24469.97911,0.00000,0.04138,300.35644
144.40001,7.21988,24472.93997,0.00000,0.04154,300.39278
144.80001,7.23985,24475.10511,0.00000,0.04170,300.41936
145.20001,7.25994,24477.80818,0.00000,0.04186,300.45254
145.60001,7.27997,24482.47522,0.00000,0.04202,300.50982
146.00001,7.30000,24486.98431,0.00000,0.04217,300.56517
146.40001,7.32009,24492.67209,0.00000,0.04234,300.63498
146.80001,7.34000,24494.08621,0.00000,0.04250,300.65234
147.20001,7.36003,24495.53162,0.00000,0.04265,300.67008
147.60001,7.38006,24498.34496,0.00000,0.04281,300.70462
148.00001,7.40003,24500.29850,0.00000,0.04297,300.72860
148.40001,7.42006,24503.48139,0.00000,0.04312,300.76766
148.80001,7.44003,24505.45579,0.00000,0.04329,300.79190
149.20001,7.45994,24508.93372,0.00000,0.04344,300.83459
149.60001,7.47990,24511.98250,0.00000,0.04360,300.87201
150.00001,7.49993,24512.36993,0.00000,0.04376,300.87677
150.40001,7.51996,24515.57666,0.00000,0.04392,300.91613
150.80001,7.53999,24521.79939,0.00000,0.04408,300.99251
151.20001,7.55996,24526.02237,0.00000,0.04424,301.04434
151.60001,7.57999,24527.99231,0.00000,0.04439,301.06852
152.00001,7.60008,24530.24387,0.00000,0.04455,301.09616
152.40001,7.61999,24530.22599,0.00000,0.04470,301.09594
152.80001,7.64002,24535.14040,0.00000,0.04486,301.15626
153.20001,7.66005,24537.22358,0.00000,0.04502,301.18183
153.60001,7.68002,24539.18904,0.00000,0.04518,301.20596
154.00001,7.69999,24542.43451,0.00000,0.04533,301.24579
154.40001,7.71996,24544.94685,0.00000,0.04549,301.27663
154.80001,7.73987,24546.13894,0.00000,0.04564,301.29126
155.20001,7.75996,24548.88970,0.00000,0.04580,301.32503
155.60001,7.77999,24550.61674,0.00000,0.04595,301.34623
156.00001,7.80002,24556.47886,0.00000,0.04611,301.41818
156.40001,7.82005,24559.19832,0.00000,0.04627,301.45156
156.80001,7.84008,24562.25306,0.00000,0.04642,301.48906
157.20001,7.86005,24563.44813,0.00000,0.04657,301.50372
157.60001,7.88002,24563.88474,0.00000,0.04673,301.50908
158.00001,7.90010,24568.01683,0.00000,0.04688,301.55980
158.40001,7.92007,24570.73480,0.00000,0.04704,301.59316
158.80001,7.94004,24572.71218,0.00000,0.04720,301.61744
159.20001,7.95995,24574.41688,0.00000,0.04735,301.63836
159.60001,7.97992,24574.22167,0.00000,0.04751,301.63596
160.00001,7.99989,24577.46565,0.00000,0.04766,301.67578
160.40001,8.01998,24581.80636,0.00000,0.04781,301.72906
160.80001,8.04007,24584.45430,0.00000,0.04797,301.76156
161.20001,8.06004,24586.04872,0.00000,0.04812,301.78114
161.60001,8.08007,24590.19870,0.00000,0.04828,301.83207
162.00001,8.09998,24592.24612,0.00000,0.04844,301.85720
162.40001,8.12001,24592.86004,0.00000,0.04859,301.86474
162.80001,8.14010,24595.97290,0.00000,0.04874,301.90295
163.20001,8.16007,24597.31847,0.00000,0.04889,301.91947
163.60001,8.17992,24597.75954,0.00000,0.04904,301.92488
164.00001,8.19995,24600.26443,0.00000,0.04920,301.95563
164.40001,8.21986,24602.58305,0.00000,0.04935,301.98409
164.80001,8.23989,24604.18493,0.00000,0.04950,302.00375
165.20001,8.26004,24607.91022,0.00000,0.04966,302.04947
165.60001,8.28007,24611.84710,0.00000,0.04981,302.09780
166.00001,8.30010,24614.34603,0.00000,0.04996,302.12847
166.40001,8.32007,24614.61872,0.00000,0.05011,302.13182
166.80001,8.33998,24617.54233,0.00000,0.05027,302.16770
167.20001,8.36001,24619.00711,0.00000,0.05041,302.18568
167.60001,8.38009,24621.05006,0.00000,0.05056,302.21076
168.00001,8.40007,24621.02473,0.00000,0.05072,302.21045
168.40001,8.41998,24622.03950,0.00000,0.05086,302.22290
168.80001,8.43988,24623.20775,0.00000,0.05102,302.23724
169.20001,8.45991,24624.84241,0.00000,0.05117,302.25731
169.60001,8.47988,24626.66929,0.00000,0.05132,302.27973
170.00001,8.50003,24629.98629,0.00000,0.05147,302.32045
170.40001,8.52006,24633.86357,0.00000,0.05162,302.36804
170.80001,8.54009,24637.24911,0.00000,0.05176,302.40959
171.20001,8.56006,24638.41736,0.00000,0.05192,302.42393
171.60001,8.58003,24637.52478,0.00000,0.05207,302.41298
172.00001,8.60000,24638.08507,0.00000,0.05222,302.41985
172.40001,8.62009,24639.99987,0.00000,0.05237,302.44336
172.80001,8.64006,24640.53631,0.00000,0.05252,302.44994
173.20001,8.65997,24642.21865,0.00000,0.05267,302.47059
173.60001,8.67994,24642.47793,0.00000,0.05282,302.47377
174.00001,8.69985,24645.33150,0.00000,0.05296,302.50880
174.40001,8.71994,24647.33571,0.00000,0.05311,302.53340
174.80001,8.74003,24650.53201,0.00000,0.05326,302.57263
175.20001,8.76012,24653.16951,0.00000,0.05341,302.60501
175.60001,8.78009,24654.95020,0.00000,0.05355,302.62687
176.00001,8.80012,24656.55357,0.00000,0.05369,302.64655
176.40001,8.82003,24658.34171,0.00000,0.05384,302.66849
176.80001,8.84000,24657.92745,0.00000,0.05398,302.66341
177.20001,8.86009,24657.16004,0.00000,0.05412,302.65399
177.60001,8.87999,24656.94994,0.00000,0.05426,302.65141
178.00001,8.89990,24660.11047,0.00000,0.05441,302.69021
178.40001,8.91987,24661.69447,0.00000,0.05454,302.70965
178.80001,8.93984,24663.52284,0.00000,0.05468,302.73209
179.20001,8.95993,24666.35853,0.00000,0.05482,302.76690
179.60001,8.98002,24669.03627,0.00000,0.05496,302.79976
180.00001,9.00011,24671.05240,0.00000,0.05510,302.82451
180.40001,9.02014,24672.03587,0.00000,0.05524,302.83658
180.80001,9.04011,24672.88375,0.00000,0.05538,302.84699
181.20001,9.06002,24672.78540,0.00000,0.05551,302.84578
181.60001,9.07999,24674.80302,0.00000,0.05565,302.87055
182.00001,9.10002,24674.96395,0.00000,0.05579,302.87252
182.40001,9.11999,24675.20088,0.00000,0.05593,302.87543
182.80001,9.13996,24676.59563,0.00000,0.05607,302.89255
183.20001,9.15993,24679.53861,0.00000,0.05621,302.92868
183.60001,9.17990,24681.73504,0.00000,0.05635,302.95564
184.00001,9.19999,24683.12085,0.00000,0.05649,302.97265
184.40001,9.22002,24683.39801,0.00000,0.05664,302.97605
184.80001,9.24017,24687.76852,0.00000,0.05678,303.02969
185.20001,9.26014,24688.45546,0.00000,0.05692,303.03813
185.60001,9.28011,24688.44801,0.00000,0.05706,303.03803
186.00001,9.30008,24688.98743,0.00000,0.05720,303.04465
186.40001,9.31999,24687.64186,0.00000,0.05734,303.02814
186.80001,9.34002,24687.26784,0.00000,0.05749,303.02355
187.20001,9.35998,24688.76690,0.00000,0.05765,303.04195
187.60001,9.37996,24690.48500,0.00000,0.05780,303.06304
188.00001,9.39992,24692.70229,0.00000,0.05795,303.09025
188.40001,9.41995,24696.08486,0.00000,0.05811,303.13177
188.80001,9.43992,24696.91634,0.00000,0.05827,303.14198
189.20001,9.46001,24696.90144,0.00000,0.05842,303.14180
189.60001,9.48004,24697.55709,0.00000,0.05858,303.14984
190.00001,9.50013,24699.16493,0.00000,0.05874,303.16958
190.40001,9.52004,24700.27208,0.00000,0.05890,303.18317
190.80001,9.54001,24700.76382,0.00000,0.05905,303.18920
191.20001,9.55998,24699.60749,0.00000,0.05921,303.17501
191.60001,9.57995,24698.77303,0.00000,0.05936,303.16477
192.00001,9.59992,24700.57905,0.00000,0.05951,303.18694
192.40001,9.61995,24702.80528,0.00000,0.05967,303.21426
192.80001,9.63998,24704.01973,0.00000,0.05982,303.22917
193.20001,9.65995,24704.74094,0.00000,0.05997,303.23802
193.60001,9.67998,24706.78538,0.00000,0.06012,303.26312
194.00001,9.69995,24706.84052,0.00000,0.06026,303.26379
194.40001,9.72010,24707.99834,0.00000,0.06041,303.27800
194.80001,9.74019,24708.12947,0.00000,0.06056,303.27961
195.20001,9.76010,24708.83578,0.00000,0.06071,303.28828
195.60001,9.78007,24708.56905,0.00000,0.06086,303.28501
196.00001,9.79998,24708.68081,0.00000,0.06100,303.28638
196.40001,9.81995,24707.49915,0.00000,0.06115,303.27188
196.80001,9.83997,24708.81045,0.00000,0.06130,303.28797
197.20001,9.86000,24710.49875,0.00000,0.06145,303.30870
197.60001,9.87991,24711.18420,0.00000,0.06159,303.31711
198.00001,9.89994,24712.86207,0.00000,0.06175,303.33770
198.40001,9.91991,24711.77131,0.00000,0.06190,303.32432
198.80001,9.94000,24713.41640,0.00000,0.06205,303.34451
199.20001,9.96003,24714.75154,0.00000,0.06220,303.36090
199.60001,9.98012,24715.44892,0.00000,0.06235,303.36946
200.00001,10.00009,24715.06298,0.00000,0.06250,303.36472
200.40001,10.02006,24714.69045,0.00000,0.06265,303.36015
200.80001,10.03991,24714.55187,0.00000,0.06279,303.35845
201.20001,10.05994,24714.94526,0.00000,0.06294,303.36327
201.60001,10.07991,24714.67257,0.00000,0.06308,303.35993
202.00001,10.09994,24715.88850,0.00000,0.06322,303.37485
202.40001,10.11997,24716.65740,0.00000,0.06337,303.38429
202.80001,10.13988,24717.02695,0.00000,0.06351,303.38883
203.20001,10.15997,24718.36954,0.00000,0.06367,303.40531
203.60001,10.17994,24716.77959,0.00000,0.06381,303.38579
204.00001,10.20009,24717.79734,0.00000,0.06395,303.39828
204.40001,10.22012,24720.37375,0.00000,0.06410,303.42991
204.80001,10.24009,24721.13669,0.00000,0.06425,303.43927
205.20001,10.26000,24720.10851,0.00000,0.06440,303.42665
205.60001,10.28003,24720.54213,0.00000,0.06455,303.43197
206.00001,10.29994,24719.08331,0.00000,0.06469,303.41407
206.40001,10.31991,24717.61256,0.00000,0.06484,303.39601
206.80001,10.33999,24718.03427,0.00000,0.06498,303.40119
207.20001,10.35996,24718.52154,0.00000,0.06514,303.40717
207.60001,10.37999,24720.47955,0.00000,0.06529,303.43120
208.00001,10.39990,24719.39176,0.00000,0.06544,303.41785
208.40001,10.41987,24719.71065,0.00000,0.06559,303.42177
208.80001,10.44002,24719.20103,0.00000,0.06575,303.41551
209.20001,10.46017,24721.23653,0.00000,0.06591,303.44050
209.60001,10.48002,24720.14576,0.00000,0.06606,303.42711
210.00001,10.49999,24721.86685,0.00000,0.06621,303.44823
210.40001,10.52002,24721.80873,0.00000,0.06637,303.44752
210.80001,10.53999,24719.18762,0.00000,0.06652,303.41535
211.20001,10.55996,24717.81671,0.00000,0.06667,303.39852
211.60001,10.57999,24719.01774,0.00000,0.06682,303.41326
212.00001,10.60002,24719.19507,0.00000,0.06697,303.41544
212.40001,10.61993,24718.13709,0.00000,0.06712,303.40245
212.80001,10.63996,24720.65985,0.00000,0.06727,303.43342
213.20001,10.65999,24720.89678,0.00000,0.06741,303.43633
213.60001,10.68008,24722.36454,0.00000,0.06757,303.45434
214.00001,10.70005,24720.53766,0.00000,0.06770,303.43192
214.40001,10.72008,24722.45097,0.00000,0.06785,303.45540
214.80001,10.74005,24721.13222,0.00000,0.06798,303.43922
215.20001,10.76002,24720.74032,0.00000,0.06811,303.43441
215.60001,10.77999,24721.65376,0.00000,0.06825,303.44562
216.00001,10.79996,24718.49918,0.00000,0.06839,303.40690
216.40001,10.81998,24717.91208,0.00000,0.06852,303.39969
216.80001,10.83995,24717.11636,0.00000,0.06867,303.38992
217.20001,10.85998,24719.39623,0.00000,0.06881,303.41791
217.60001,10.88001,24722.68641,0.00000,0.06896,303.45829
218.00001,10.90004,24721.64780,0.00000,0.06910,303.44554
218.40001,10.92001,24719.14142,0.00000,0.06924,303.41478
218.80001,10.94010,24720.27838,0.00000,0.06938,303.42874
219.20001,10.96007,24720.75075,0.00000,0.06953,303.43453
219.60001,10.98004,24719.25020,0.00000,0.06968,303.41611
220.00001,11.00001,24716.77065,0.00000,0.06983,303.38568
220.40001,11.01998,24715.08533,0.00000,0.06998,303.36499
220.80001,11.03995,24716.85857,0.00000,0.07014,303.38676
221.20001,11.05998,24714.44160,0.00000,0.07029,303.35709
221.60001,11.07995,24715.28500,0.00000,0.07044,303.36744
222.00001,11.09998,24715.71118,0.00000,0.07059,303.37268
222.40001,11.12001,24718.98049,0.00000,0.07075,303.41280
222.80001,11.13998,24717.47696,0.00000,0.07091,303.39435
223.20001,11.16013,24716.66336,0.00000,0.07106,303.38436
223.60001,11.18004,24714.07354,0.00000,0.07122,303.35257
224.00001,11.20007,24715.54428,0.00000,0.07138,303.37063
224.40001,11.22004,24715.64561,0.00000,0.07155,303.37187
224.80001,11.24001,24714.02586,0.00000,0.07171,303.35199
225.20001,11.25998,24711.53438,0.00000,0.07188,303.32141
225.60001,11.27989,24709.25748,0.00000,0.07204,303.29346
226.00001,11.29991,24709.93847,0.00000,0.07221,303.30182
226.40001,11.32000,24710.82360,0.00000,0.07237,303.31268
226.80001,11.33997,24711.65359,0.00000,0.07254,303.32287
227.20001,11.35994,24710.20818,0.00000,0.07271,303.30513
227.60001,11.38003,24713.34189,0.00000,0.07288,303.34359
228.00001,11.40000,24710.72823,0.00000,0.07305,303.31151
228.40001,11.42003,24708.74786,0.00000,0.07322,303.28720
228.80001,11.44012,24708.13990,0.00000,0.07339,303.27974
229.20001,11.46009,24706.71684,0.00000,0.07355,303.26227
229.60001,11.48006,24706.90608,0.00000,0.07372,303.26460
230.00001,11.49997,24705.56796,0.00000,0.07388,303.24817
230.40001,11.51988,24702.10344,0.00000,0.07405,303.20565
230.80001,11.53991,24701.56550,0.00000,0.07422,303.19904
231.20001,11.55994,24703.51756,0.00000,0.07439,303.22300
231.60001,11.57997,24704.18960,0.00000,0.07455,303.23125
232.00001,11.60000,24703.76790,0.00000,0.07472,303.22608
232.40001,11.62003,24701.66832,0.00000,0.07488,303.20031
232.80001,11.64006,24699.66859,0.00000,0.07504,303.17576
233.20001,11.66003,24699.39142,0.00000,0.07521,303.17236
233.60001,11.68012,24698.35728,0.00000,0.07538,303.15967
234.00001,11.70015,24696.71369,0.00000,0.07555,303.13949
234.40001,11.72000,24692.85280,0.00000,0.07572,303.09210
234.80001,11.73991,24693.27152,0.00000,0.07589,303.09724
235.20001,11.75988,24692.32976,0.00000,0.07605,303.08568
235.60001,11.77985,24690.91117,0.00000,0.07622,303.06827
236.00001,11.79993,24691.29264,0.00000,0.07638,303.07295
236.40001,11.82002,24692.92879,0.00000,0.07654,303.09303
236.80001,11.83999,24691.45805,0.00000,0.07670,303.07498
237.20001,11.86008,24690.69213,0.00000,0.07687,303.06558
237.60001,11.88005,24688.83246,0.00000,0.07703,303.04275
238.00001,11.90002,24684.21310,0.00000,0.07719,302.98605
238.40001,11.92011,24685.46331,0.00000,0.07735,303.00140
238.80001,11.94002,24683.71987,0.00000,0.07750,302.98000
239.20001,11.95993,24682.25211,0.00000,0.07765,302.96198
239.60001,11.97996,24681.96899,0.00000,0.07780,302.95851
240.00001,11.99987,24679.70699,0.00000,0.07796,302.93074
240.40001,12.01984,24678.75630,0.00000,0.07810,302.91907
240.80001,12.03999,24678.30330,0.00000,0.07825,302.91351
241.20001,12.06008,24676.10240,0.00000,0.07840,302.88650
241.60001,12.08011,24677.65510,0.00000,0.07854,302.90556
242.00001,12.10008,24677.14250,0.00000,0.07869,302.89926
242.40001,12.12005,24673.79868,0.00000,0.07884,302.85822
242.80001,12.14002,24670.48615,0.00000,0.07900,302.81756
243.20001,12.16011,24669.08842,0.00000,0.07916,302.80040
243.60001,12.18008,24666.89348,0.00000,0.07932,302.77346
244.00001,12.19999,24666.42559,0.00000,0.07949,302.76772
244.40001,12.21990,24663.22035,0.00000,0.07965,302.72838
244.80001,12.23987,24661.39495,0.00000,0.07981,302.70597
245.20001,12.25989,24659.42353,0.00000,0.07998,302.68177
245.60001,12.27992,24660.24309,0.00000,0.08014,302.69183
246.00001,12.30001,24659.58893,0.00000,0.08030,302.68380
246.40001,12.31998,24656.98868,0.00000,0.08044,302.65189
246.80001,12.34007,24654.48081,0.00000,0.08058,302.62110
247.20001,12.36004,24652.70162,0.00000,0.08069,302.59927
247.60001,12.38001,24650.25634,0.00000,0.08076,302.56925
248.00001,12.40004,24646.96616,0.00000,0.08083,302.52887
248.40001,12.42007,24643.78029,0.00000,0.08093,302.48976
248.80001,12.43998,24641.16514,0.00000,0.08104,302.45766
249.20001,12.45989,24639.79423,0.00000,0.08113,302.44083
249.60001,12.47986,24638.43971,0.00000,0.08117,302.42421
250.00001,12.49989,24634.92602,0.00000,0.08116,302.38108
250.40001,12.51998,24631.73419,0.00000,0.08117,302.34190
250.80001,12.54001,24629.41557,0.00000,0.08126,302.31344
251.20001,12.56004,24626.83022,0.00000,0.08135,302.28171
251.60001,12.58007,24624.61293,0.00000,0.08139,302.25449
252.00001,12.60010,24620.99940,0.00000,0.08129,302.21014
252.40001,12.62001,24615.93896,0.00000,0.08118,302.14802
252.80001,12.64004,24612.55044,0.00000,0.08103,302.10643
253.20001,12.66001,24607.95343,0.00000,0.08077,302.05000
253.60001,12.67998,24601.56530,0.00000,0.08080,301.97159
254.00001,12.69989,24597.97114,0.00000,0.08089,301.92748
254.40001,12.71985,24591.47125,0.00000,0.08099,301.84769
254.80001,12.73994,24587.72659,0.00000,0.08109,301.80173
255.20001,12.75991,24578.85593,0.00000,0.08120,301.69285
255.60001,12.78000,24573.09961,0.00000,0.08131,301.62219
256.00001,12.80009,24568.98689,0.00000,0.08141,301.57171
256.40001,12.82006,24563.56287,0.00000,0.08151,301.50513
256.80001,12.84003,24554.46422,0.00000,0.08161,301.39345
257.20001,12.86000,24545.61442,0.00000,0.08171,301.28482
257.60001,12.87997,24533.27030,0.00000,0.08180,301.13331
258.00001,12.90000,24525.08360,0.00000,0.08189,301.03282
258.40001,12.91991,24511.70981,0.00000,0.08198,300.86866
258.80001,12.93994,24499.87382,0.00000,0.08206,300.72338
259.20001,12.95991,24486.54324,0.00000,0.08214,300.55976
259.60001,12.97994,24473.71334,0.00000,0.08221,300.40228
260.00001,12.99991,24458.69148,0.00000,0.08227,300.21789
260.40001,13.02006,24443.18533,0.00000,0.08233,300.02756
260.80001,13.04009,24425.62282,0.00000,0.08239,299.81199
261.20001,13.06006,24406.18426,0.00000,0.08243,299.57339
261.60001,13.08003,24383.59857,0.00000,0.08248,299.29616
262.00001,13.10000,24357.94175,0.00000,0.08251,298.98124
262.40001,13.12003,24328.45384,0.00000,0.08255,298.61929
262.80001,13.14006,24295.73238,0.00000,0.08258,298.21765
263.20001,13.15997,24264.15086,0.00000,0.08260,297.83000
263.60001,13.18000,24227.28390,0.00000,0.08262,297.37748
264.00001,13.19990,24183.44021,0.00000,0.08263,296.83932
264.40001,13.21993,24136.20651,0.00000,0.08264,296.25955
264.80001,13.23996,24084.07778,0.00000,0.08264,295.61970
265.20001,13.25993,24024.56105,0.00000,0.08264,294.88916
265.60001,13.28008,23956.43741,0.00000,0.08264,294.05298
266.00001,13.30011,23876.36602,0.00000,0.08262,293.07014
266.40001,13.32008,23785.22605,0.00000,0.08261,291.95145
266.80001,13.33999,23667.18203,0.00000,0.08258,290.50252
267.20001,13.36002,23492.02186,0.00000,0.08254,288.35252
267.60001,13.38005,23263.06850,0.00000,0.08249,285.54223
268.00001,13.40014,22785.97355,0.00000,0.08237,279.68614
268.08001,13.40439,20888.50290,0.00000,0.07908,256.39566
268.08801,13.40564,16352.13643,0.00000,0.07066,200.71409
268.09401,13.40678,12465.86218,0.00000,0.06362,153.01206