File: scratch/college-stuff/ME Lab/ME lab Fall 2013/group7/group7.is_tens_RawData/Specimen_RawData_1.csv
Time,Extension,Load,Strain 2,Tensile strain,Tensile stress
(sec),(mm),(N),(mm/mm),(mm/mm),(MPa)
0.00000,0.00006,0.05274,0.00000,0.00000,0.00064
0.10000,0.00161,2.03922,0.00000,0.00000,0.02462
0.20000,0.00735,6.61984,0.00000,0.00001,0.07993
0.30000,0.01357,8.72686,0.00000,0.00001,0.10537
0.40000,0.01943,11.87263,0.00000,0.00001,0.14336
0.50000,0.02469,12.89248,0.00000,0.00001,0.15567
0.60000,0.03001,14.07481,0.00000,0.00001,0.16995
0.70000,0.03498,14.80858,0.00000,0.00001,0.17881
0.80000,0.04012,15.76308,0.00000,0.00001,0.19034
0.90000,0.04496,16.86704,0.00000,0.00001,0.20367
1.00000,0.05004,17.70713,0.00000,0.00001,0.21381
1.10000,0.05495,18.75509,0.00000,0.00001,0.22646
1.20000,0.06009,19.58984,0.00000,0.00001,0.23654
1.30000,0.06499,20.19736,0.00000,0.00001,0.24388
1.40000,0.07001,22.29588,0.00000,0.00001,0.26922
1.50000,0.07498,23.42754,0.00000,0.00001,0.28288
1.60000,0.08006,25.62219,0.00000,0.00000,0.30938
1.70000,0.08508,28.14714,0.00000,0.00001,0.33987
1.80000,0.08998,30.90745,0.00000,0.00001,0.37320
1.90000,0.09507,33.55166,0.00000,0.00001,0.40513
2.00000,0.09997,35.08995,0.00000,0.00001,0.42370
2.10000,0.10511,37.91330,0.00000,0.00001,0.45780
2.20000,0.10995,41.06050,0.00000,0.00001,0.49580
2.30000,0.11509,42.96249,0.00000,0.00001,0.51876
2.40000,0.11988,46.61324,0.00000,0.00001,0.56284
2.50000,0.12508,51.36299,0.00000,0.00001,0.62020
2.60000,0.12992,55.81749,0.00000,0.00001,0.67398
2.70000,0.13512,59.45525,0.00000,0.00001,0.71791
2.80000,0.13991,62.97462,0.00000,0.00001,0.76041
2.90000,0.14505,65.76621,0.00000,0.00001,0.79411
3.00000,0.14995,68.64975,0.00000,0.00001,0.82893
3.10000,0.15509,71.31674,0.00000,0.00001,0.86113
3.20000,0.16000,76.43995,0.00000,0.00001,0.92300
3.30000,0.16502,84.05814,0.00000,0.00001,1.01498
3.40000,0.16992,91.44350,0.00000,0.00002,1.10416
3.50000,0.17506,102.15384,0.00000,0.00002,1.23349
3.60000,0.17997,112.26780,0.00000,0.00003,1.35561
3.70000,0.18499,123.61333,0.00000,0.00003,1.49260
3.80000,0.19001,136.04711,0.00000,0.00004,1.64274
3.90000,0.19503,149.10034,0.00000,0.00004,1.80035
4.00000,0.20012,162.59099,0.00000,0.00004,1.96325
4.10000,0.20502,176.75675,0.00000,0.00005,2.13430
4.20000,0.21004,192.96150,0.00000,0.00005,2.32997
4.30000,0.21494,211.13404,0.00000,0.00006,2.54940
4.40000,0.22009,229.26673,0.00000,0.00006,2.76835
4.50000,0.22499,247.10582,0.00000,0.00007,2.98375
4.60000,0.23013,268.26430,0.00000,0.00008,3.23923
4.70000,0.23491,289.23869,0.00000,0.00008,3.49250
4.80000,0.24005,313.84777,0.00000,0.00009,3.78964
4.90000,0.24496,336.55523,0.00000,0.00010,4.06383
5.00000,0.25010,361.76224,0.00000,0.00011,4.36820
5.10000,0.25494,386.30890,0.00000,0.00012,4.66460
5.20000,0.26008,412.88547,0.00000,0.00013,4.98550
5.30000,0.26499,439.73234,0.00000,0.00014,5.30967
5.40000,0.27007,466.45780,0.00000,0.00015,5.63238
5.50000,0.27497,493.77098,0.00000,0.00016,5.96218
5.60000,0.28005,522.64323,0.00000,0.00018,6.31081
5.70000,0.28490,551.48960,0.00000,0.00019,6.65912
5.80000,0.29004,585.19109,0.00000,0.00020,7.06606
5.90000,0.29500,624.17556,0.00000,0.00022,7.53679
6.00000,0.30008,662.66339,0.00000,0.00025,8.00152
6.10000,0.30499,702.62500,0.00000,0.00027,8.48405
6.20000,0.31001,743.20412,0.00000,0.00029,8.97403
6.30000,0.31497,785.53483,0.00000,0.00031,9.48517
6.40000,0.31999,827.04565,0.00000,0.00033,9.98640
6.50000,0.32508,867.95585,0.00000,0.00035,10.48038
6.60000,0.32992,906.09007,0.00000,0.00038,10.94084
6.70000,0.33500,948.96518,0.00000,0.00040,11.45855
6.80000,0.33984,989.36427,0.00000,0.00042,11.94636
6.90000,0.34510,1036.13324,0.00000,0.00044,12.51109
7.00000,0.34989,1078.19866,0.00000,0.00046,13.01902
7.10000,0.35509,1122.71560,0.00000,0.00049,13.55655
7.20000,0.35987,1164.77376,0.00000,0.00051,14.06439
7.30000,0.36501,1209.91897,0.00000,0.00054,14.60951
7.40000,0.36992,1253.78100,0.00000,0.00056,15.13914
7.50000,0.37506,1299.20421,0.00000,0.00058,15.68761
7.60000,0.37984,1344.66095,0.00000,0.00061,16.23649
7.70000,0.38498,1390.40537,0.00000,0.00063,16.78885
7.80000,0.38995,1437.12778,0.00000,0.00066,17.35301
7.90000,0.39503,1481.23717,0.00000,0.00068,17.88562
8.00000,0.39993,1525.95853,0.00000,0.00071,18.42562
8.10000,0.40495,1570.69843,0.00000,0.00074,18.96585
8.20000,0.40992,1617.05073,0.00000,0.00076,19.52554
8.30000,0.41506,1660.91695,0.00000,0.00078,20.05522
8.40000,0.42002,1705.38239,0.00000,0.00080,20.59213
8.50000,0.42498,1748.61550,0.00000,0.00083,21.11416
8.60000,0.43001,1794.75211,0.00000,0.00085,21.67125
8.70000,0.43491,1838.80646,0.00000,0.00088,22.20320
8.80000,0.43999,1885.65217,0.00000,0.00091,22.76885
8.90000,0.44495,1930.28767,0.00000,0.00093,23.30781
9.00000,0.45004,1977.78586,0.00000,0.00096,23.88134
9.10000,0.45488,2021.45278,0.00000,0.00098,24.40861
9.20000,0.46008,2068.75559,0.00000,0.00101,24.97978
9.30000,0.46498,2111.06203,0.00000,0.00103,25.49062
9.40000,0.47012,2157.18076,0.00000,0.00106,26.04750
9.50000,0.47491,2200.44702,0.00000,0.00108,26.56993
9.60000,0.48005,2246.82037,0.00000,0.00111,27.12988
9.70000,0.48489,2291.03863,0.00000,0.00114,27.66380
9.80000,0.49009,2335.56814,0.00000,0.00116,28.20149
9.90000,0.49488,2378.08414,0.00000,0.00119,28.71486
10.00000,0.50002,2422.72653,0.00000,0.00121,29.25391
10.10000,0.50486,2467.43374,0.00000,0.00124,29.79374
10.20000,0.51006,2512.43208,0.00000,0.00126,30.33708
10.30000,0.51497,2556.50990,0.00000,0.00129,30.86931
10.40000,0.52005,2600.89822,0.00000,0.00132,31.40529
10.50000,0.52495,2645.26904,0.00000,0.00134,31.94106
10.60000,0.52997,2688.90020,0.00000,0.00136,32.46790
10.70000,0.53494,2733.75530,0.00000,0.00139,33.00951
10.80000,0.54002,2775.74454,0.00000,0.00142,33.51652
10.90000,0.54492,2820.75740,0.00000,0.00144,34.06004
11.00000,0.54994,2863.43899,0.00000,0.00147,34.57541
11.10000,0.55497,2908.31067,0.00000,0.00149,35.11723
11.20000,0.55993,2948.90869,0.00000,0.00152,35.60744
11.30000,0.56501,2993.32310,0.00000,0.00154,36.14374
11.40000,0.56991,3034.89733,0.00000,0.00157,36.64574
11.50000,0.57506,3079.52110,0.00000,0.00160,37.18456
11.60000,0.57990,3120.08243,0.00000,0.00162,37.67433
11.70000,0.58510,3164.14200,0.00000,0.00164,38.20634
11.80000,0.58988,3203.53061,0.00000,0.00167,38.68195
11.90000,0.59503,3247.03828,0.00000,0.00169,39.20729
12.00000,0.59981,3286.75956,0.00000,0.00172,39.68692
12.10000,0.60501,3329.48044,0.00000,0.00174,40.20277
12.20000,0.60985,3370.32080,0.00000,0.00177,40.69590
12.30000,0.61493,3411.58770,0.00000,0.00179,41.19419
12.40000,0.61990,3452.53386,0.00000,0.00182,41.68861
12.50000,0.62498,3493.73929,0.00000,0.00184,42.18616
12.60000,0.62994,3534.25778,0.00000,0.00186,42.67541
12.70000,0.63502,3573.63708,0.00000,0.00188,43.15090
12.80000,0.63999,3613.57704,0.00000,0.00191,43.63317
12.90000,0.64501,3652.05109,0.00000,0.00193,44.09774
13.00000,0.64997,3692.30621,0.00000,0.00195,44.58381
13.10000,0.65499,3729.91264,0.00000,0.00197,45.03790
13.20000,0.66002,3769.53855,0.00000,0.00200,45.51637
13.30000,0.66492,3805.60160,0.00000,0.00202,45.95183
13.40000,0.67000,3844.18517,0.00000,0.00204,46.41771
13.50000,0.67496,3881.30583,0.00000,0.00207,46.86594
13.60000,0.68011,3921.74609,0.00000,0.00209,47.35425
13.70000,0.68501,3958.28001,0.00000,0.00211,47.79539
13.80000,0.69009,3996.18819,0.00000,0.00214,48.25312
13.90000,0.69499,4031.97370,0.00000,0.00215,48.68522
14.00000,0.70013,4069.97874,0.00000,0.00218,49.14412
14.10000,0.70504,4106.07494,0.00000,0.00220,49.57998
14.20000,0.71012,4145.35776,0.00000,0.00222,50.05431
14.30000,0.71490,4180.97749,0.00000,0.00225,50.48441
14.40000,0.72004,4217.84446,0.00000,0.00227,50.92957
14.50000,0.72495,4250.91684,0.00000,0.00229,51.32891
14.60000,0.73009,4287.65193,0.00000,0.00231,51.77248
14.70000,0.73499,4324.33635,0.00000,0.00233,52.21544
14.80000,0.74007,4361.39219,0.00000,0.00236,52.66288
14.90000,0.74498,4395.13288,0.00000,0.00238,53.07029
15.00000,0.75012,4430.88114,0.00000,0.00240,53.50194
15.10000,0.75490,4463.67450,0.00000,0.00242,53.89792
15.20000,0.75998,4499.62057,0.00000,0.00244,54.33196
15.30000,0.76489,4534.21362,0.00000,0.00247,54.74966
15.40000,0.77003,4566.70821,0.00000,0.00248,55.14203
15.50000,0.77499,4601.20328,0.00000,0.00251,55.55855
15.60000,0.77995,4632.67490,0.00000,0.00253,55.93856
15.70000,0.78498,4668.29874,0.00000,0.00255,56.36871
15.80000,0.79000,4700.05162,0.00000,0.00257,56.75212
15.90000,0.79502,4736.60938,0.00000,0.00259,57.19355
16.00000,0.79998,4767.49428,0.00000,0.00261,57.56648
16.10000,0.80501,4802.30190,0.00000,0.00263,57.98677
16.20000,0.80991,4832.68984,0.00000,0.00265,58.35370
16.30000,0.81505,4865.51598,0.00000,0.00267,58.75007
16.40000,0.81989,4894.49501,0.00000,0.00268,59.09998
16.50000,0.82509,4928.70994,0.00000,0.00270,59.51312
16.60000,0.82988,4959.71590,0.00000,0.00273,59.88751
16.70000,0.83502,4993.00361,0.00000,0.00275,60.28945
16.80000,0.83986,5023.28202,0.00000,0.00276,60.65506
16.90000,0.84506,5054.69255,0.00000,0.00279,61.03433
17.00000,0.84991,5083.92006,0.00000,0.00280,61.38725
17.10000,0.85505,5115.49115,0.00000,0.00282,61.76846
17.20000,0.85995,5145.88244,0.00000,0.00284,62.13543
17.30000,0.86509,5176.19066,0.00000,0.00286,62.50140
17.40000,0.87000,5205.18087,0.00000,0.00288,62.85145
17.50000,0.87508,5234.75595,0.00000,0.00290,63.20856
17.60000,0.87998,5262.88114,0.00000,0.00291,63.54817
17.70000,0.88500,5290.52578,0.00000,0.00293,63.88197
17.80000,0.88997,5318.09442,0.00000,0.00295,64.21485
17.90000,0.89505,5341.60137,0.00000,0.00296,64.49870
18.00000,0.90001,5368.00697,0.00000,0.00298,64.81754
18.10000,0.90503,5391.41074,0.00000,0.00299,65.10013
18.20000,0.91006,5417.29331,0.00000,0.00301,65.41266
18.30000,0.91502,5440.03136,0.00000,0.00302,65.68722
18.40000,0.92010,5465.77983,0.00000,0.00304,65.99812
18.50000,0.92500,5489.87798,0.00000,0.00306,66.28910
18.60000,0.93003,5515.32991,0.00000,0.00308,66.59643
18.70000,0.93493,5540.02486,0.00000,0.00308,66.89462
18.80000,0.94007,5568.07443,0.00000,0.00310,67.23331
18.90000,0.94491,5592.09362,0.00000,0.00312,67.52334
19.00000,0.95000,5620.13462,0.00000,0.00314,67.86193
19.10000,0.95484,5643.86100,0.00000,0.00315,68.14842
19.20000,0.96004,5670.62497,0.00000,0.00317,68.47159
19.30000,0.96494,5694.66390,0.00000,0.00319,68.76185
19.40000,0.97002,5720.82959,0.00000,0.00320,69.07780
19.50000,0.97487,5745.79909,0.00000,0.00322,69.37930
19.60000,0.98001,5772.34551,0.00000,0.00324,69.69984
19.70000,0.98491,5797.17867,0.00000,0.00325,69.99969
19.80000,0.99005,5822.69132,0.00000,0.00327,70.30775
19.90000,0.99496,5847.53193,0.00000,0.00328,70.60770
20.00000,0.99998,5873.16789,0.00000,0.00330,70.91725
20.10000,1.00494,5899.63682,0.00000,0.00332,71.23685
20.20000,1.01002,5924.65959,0.00000,0.00333,71.53900
20.30000,1.01505,5950.34957,0.00000,0.00335,71.84920
20.40000,1.02001,5974.37471,0.00000,0.00336,72.13930
20.50000,1.02497,6002.72752,0.00000,0.00338,72.48165
20.60000,1.02993,6024.91274,0.00000,0.00340,72.74953
20.70000,1.03502,6052.70863,0.00000,0.00341,73.08516
20.80000,1.03998,6075.58712,0.00000,0.00343,73.36142
20.90000,1.04500,6103.15315,0.00000,0.00345,73.69427
21.00000,1.04990,6127.69052,0.00000,0.00347,73.99055
21.10000,1.05505,6153.78283,0.00000,0.00348,74.30561
21.20000,1.05989,6179.33087,0.00000,0.00350,74.61410
21.30000,1.06509,6206.71734,0.00000,0.00351,74.94479
21.40000,1.06987,6230.78085,0.00000,0.00353,75.23535
21.50000,1.07507,6257.51838,0.00000,0.00355,75.55820
21.60000,1.07992,6279.85299,0.00000,0.00356,75.82788
21.70000,1.08512,6305.34738,0.00000,0.00358,76.13572
21.80000,1.08996,6329.47683,0.00000,0.00360,76.42708
21.90000,1.09504,6353.86258,0.00000,0.00361,76.72153
22.00000,1.09989,6376.91766,0.00000,0.00363,76.99992
22.10000,1.10503,6399.99360,0.00000,0.00364,77.27856
22.20000,1.10993,6423.13212,0.00000,0.00366,77.55795
22.30000,1.11501,6446.47479,0.00000,0.00367,77.83981
22.40000,1.11998,6470.10356,0.00000,0.00369,78.12512
22.50000,1.12500,6493.07445,0.00000,0.00371,78.40249
22.60000,1.13002,6516.49237,0.00000,0.00372,78.68525
22.70000,1.13504,6539.08178,0.00000,0.00374,78.95802
22.80000,1.14001,6564.08593,0.00000,0.00375,79.25994
22.90000,1.14497,6587.92406,0.00000,0.00377,79.54778
23.00000,1.14999,6612.92747,0.00000,0.00378,79.84969
23.10000,1.15495,6634.50435,0.00000,0.00379,80.11022
23.20000,1.16004,6659.51893,0.00000,0.00382,80.41227
23.30000,1.16494,6682.36986,0.00000,0.00383,80.68819
23.40000,1.17008,6707.96037,0.00000,0.00385,80.99719
23.50000,1.17492,6729.25115,0.00000,0.00386,81.25427
23.60000,1.18007,6754.68147,0.00000,0.00388,81.56134
23.70000,1.18491,6777.99881,0.00000,0.00390,81.84289
23.80000,1.19005,6804.08776,0.00000,0.00390,82.15791
23.90000,1.19489,6828.30364,0.00000,0.00392,82.45031
24.00000,1.20003,6853.56930,0.00000,0.00394,82.75539
24.10000,1.20494,6876.15201,0.00000,0.00396,83.02807
24.20000,1.21008,6902.26480,0.00000,0.00398,83.34337
24.30000,1.21492,6925.87048,0.00000,0.00399,83.62841
24.40000,1.22000,6950.43057,0.00000,0.00401,83.92496
24.50000,1.22497,6976.21405,0.00000,0.00402,84.23629
24.60000,1.23005,7001.67641,0.00000,0.00404,84.54375
24.70000,1.23495,7027.19912,0.00000,0.00405,84.85193
24.80000,1.24003,7052.33142,0.00000,0.00407,85.15540
24.90000,1.24494,7077.66637,0.00000,0.00409,85.46131
25.00000,1.25002,7101.09696,0.00000,0.00410,85.74423
25.10000,1.25504,7127.65083,0.00000,0.00412,86.06486
25.20000,1.25994,7150.08676,0.00000,0.00413,86.33577
25.30000,1.26503,7177.33800,0.00000,0.00415,86.66482
25.40000,1.26993,7199.84546,0.00000,0.00417,86.93660
25.50000,1.27501,7227.17270,0.00000,0.00419,87.26657
25.60000,1.27991,7249.49539,0.00000,0.00421,87.53611
25.70000,1.28506,7276.66765,0.00000,0.00422,87.86421
25.80000,1.28990,7298.88305,0.00000,0.00424,88.13245
25.90000,1.29510,7325.14113,0.00000,0.00425,88.44951
26.00000,1.29988,7348.55011,0.00000,0.00427,88.73217
26.10000,1.30509,7374.58915,0.00000,0.00429,89.04659
26.20000,1.30987,7399.41224,0.00000,0.00430,89.34632
26.30000,1.31501,7427.61269,0.00000,0.00433,89.68684
26.40000,1.31991,7451.61101,0.00000,0.00434,89.97661
26.50000,1.32499,7476.08095,0.00000,0.00436,90.27208
26.60000,1.32990,7501.17376,0.00000,0.00438,90.57507
26.70000,1.33498,7528.49504,0.00000,0.00439,90.90497
26.80000,1.33994,7552.74221,0.00000,0.00441,91.19775
26.90000,1.34508,7577.66142,0.00000,0.00443,91.49864
27.00000,1.34999,7601.58300,0.00000,0.00445,91.78749
27.10000,1.35501,7626.89486,0.00000,0.00446,92.09313
27.20000,1.35997,7653.03746,0.00000,0.00448,92.40879
27.30000,1.36505,7678.10792,0.00000,0.00450,92.71151
27.40000,1.36996,7702.04812,0.00000,0.00452,93.00059
27.50000,1.37504,7726.41301,0.00000,0.00453,93.29479
27.60000,1.37994,7751.79863,0.00000,0.00455,93.60131
27.70000,1.38496,7776.97936,0.00000,0.00457,93.90536
27.80000,1.39005,7803.53174,0.00000,0.00459,94.22598
27.90000,1.39501,7829.08723,0.00000,0.00460,94.53456
28.00000,1.40003,7855.34233,0.00000,0.00462,94.85158
28.10000,1.40493,7879.73404,0.00000,0.00464,95.14611
28.20000,1.41002,7906.43096,0.00000,0.00466,95.46847
28.30000,1.41492,7929.65740,0.00000,0.00467,95.74892
28.40000,1.42012,7956.33793,0.00000,0.00469,96.07108
28.50000,1.42484,7978.69861,0.00000,0.00471,96.34108
28.60000,1.43005,8006.72248,0.00000,0.00473,96.67946
28.70000,1.43489,8030.92495,0.00000,0.00474,96.97170
28.80000,1.44009,8057.50638,0.00000,0.00476,97.29267
28.90000,1.44493,8082.26764,0.00000,0.00478,97.59166
29.00000,1.45007,8109.20224,0.00000,0.00480,97.91688
29.10000,1.45492,8133.75041,0.00000,0.00482,98.21330
29.20000,1.46006,8158.97733,0.00000,0.00484,98.51791
29.30000,1.46496,8183.86674,0.00000,0.00485,98.81844
29.40000,1.47004,8208.96253,0.00000,0.00487,99.12147
29.50000,1.47495,8234.62307,0.00000,0.00489,99.43131
29.60000,1.47997,8260.88712,0.00000,0.00491,99.74845
29.70000,1.48493,8287.21970,0.00000,0.00493,100.06641
29.80000,1.48995,8312.04578,0.00000,0.00494,100.36618
29.90000,1.49498,8338.59965,0.00000,0.00496,100.68681
30.00000,1.49994,8363.32291,0.00000,0.00498,100.98534
30.10000,1.50502,8391.46450,0.00000,0.00500,101.32514
30.20000,1.50998,8415.68112,0.00000,0.00501,101.61755
30.30000,1.51507,8443.99184,0.00000,0.00503,101.95940
30.40000,1.51997,8467.61540,0.00000,0.00505,102.24465
30.50000,1.52505,8494.38533,0.00000,0.00507,102.56789
30.60000,1.52989,8518.18249,0.00000,0.00509,102.85523
30.70000,1.53510,8544.66930,0.00000,0.00510,103.17506
30.80000,1.53994,8567.98142,0.00000,0.00512,103.45655
30.90000,1.54508,8594.75359,0.00000,0.00514,103.77981
31.00000,1.54986,8619.07154,0.00000,0.00516,104.07345
31.10000,1.55506,8647.99619,0.00000,0.00518,104.42271
31.20000,1.55991,8673.59787,0.00000,0.00520,104.73184
31.30000,1.56505,8700.03328,0.00000,0.00522,105.05104
31.40000,1.56995,8725.88754,0.00000,0.00524,105.36323
31.50000,1.57497,8750.85667,0.00000,0.00526,105.66473
31.60000,1.57994,8776.05602,0.00000,0.00527,105.96900
31.70000,1.58508,8802.70079,0.00000,0.00529,106.29073
31.80000,1.58998,8827.98955,0.00000,0.00531,106.59609
31.90000,1.59500,8853.69405,0.00000,0.00533,106.90646
32.00000,1.59997,8880.70017,0.00000,0.00535,107.23256
32.10000,1.60499,8905.69538,0.00000,0.00537,107.53437
32.20000,1.61001,8933.80716,0.00000,0.00539,107.87381
32.30000,1.61503,8958.17578,0.00000,0.00541,108.16806
32.40000,1.62000,8985.19978,0.00000,0.00543,108.49437
32.50000,1.62496,9010.18009,0.00000,0.00545,108.79600
32.60000,1.63004,9036.29139,0.00000,0.00546,109.11129
32.70000,1.63500,9060.85372,0.00000,0.00548,109.40787
32.80000,1.64009,9089.06311,0.00000,0.00550,109.74850
32.90000,1.64493,9113.09198,0.00000,0.00552,110.03864
33.00000,1.65007,9141.02271,0.00000,0.00554,110.37590
33.10000,1.65491,9164.24394,0.00000,0.00556,110.65629
33.20000,1.66012,9192.70292,0.00000,0.00558,110.99992
33.30000,1.66490,9217.65566,0.00000,0.00560,111.30122
33.40000,1.67004,9246.63916,0.00000,0.00562,111.65119
33.50000,1.67488,9271.87130,0.00000,0.00563,111.95587
33.60000,1.68008,9301.08353,0.00000,0.00566,112.30860
33.70000,1.68493,9325.55348,0.00000,0.00567,112.60407
33.80000,1.69007,9351.81603,0.00000,0.00569,112.92118
33.90000,1.69491,9377.10628,0.00000,0.00572,113.22656
34.00000,1.69999,9402.36971,0.00000,0.00573,113.53161
34.10000,1.70490,9427.68902,0.00000,0.00575,113.83733
34.20000,1.70998,9452.38471,0.00000,0.00577,114.13553
34.30000,1.71488,9480.53598,0.00000,0.00579,114.47545
34.40000,1.71996,9507.13605,0.00000,0.00581,114.79664
34.50000,1.72499,9534.77249,0.00000,0.00583,115.13034
34.60000,1.73001,9558.94142,0.00000,0.00585,115.42218
34.70000,1.73503,9585.65995,0.00000,0.00587,115.74480
34.80000,1.73999,9610.76319,0.00000,0.00589,116.04791
34.90000,1.74502,9637.82445,0.00000,0.00591,116.37467
35.00000,1.74992,9662.06044,0.00000,0.00592,116.66732
35.10000,1.75500,9689.34223,0.00000,0.00594,116.99674
35.20000,1.75990,9714.35308,0.00000,0.00596,117.29874
35.30000,1.76499,9741.92321,0.00000,0.00599,117.63164
35.40000,1.76989,9767.28275,0.00000,0.00600,117.93785
35.50000,1.77515,9795.04734,0.00000,0.00602,118.27310
35.60000,1.77999,9818.29315,0.00000,0.00604,118.55379
35.70000,1.78513,9846.74394,0.00000,0.00606,118.89733
35.80000,1.78992,9871.40536,0.00000,0.00608,119.19511
35.90000,1.79500,9897.74391,0.00000,0.00610,119.51314
36.00000,1.79996,9922.89707,0.00000,0.00612,119.81686
36.10000,1.80510,9949.33844,0.00000,0.00614,120.13614
36.20000,1.80995,9974.59888,0.00000,0.00615,120.44115
36.30000,1.81503,10001.03578,0.00000,0.00618,120.76037
36.40000,1.81993,10025.67634,0.00000,0.00619,121.05790
36.50000,1.82507,10052.74057,0.00000,0.00621,121.38470
36.60000,1.83004,10078.56429,0.00000,0.00623,121.69651
36.70000,1.83506,10106.90555,0.00000,0.00625,122.03873
36.80000,1.83996,10133.83940,0.00000,0.00627,122.36395
36.90000,1.84498,10158.51796,0.00000,0.00629,122.66193
37.00000,1.85001,10186.66029,0.00000,0.00632,123.00175
37.10000,1.85497,10210.18922,0.00000,0.00633,123.28585
37.20000,1.85993,10237.81002,0.00000,0.00635,123.61937
37.30000,1.86495,10262.30603,0.00000,0.00637,123.91515
37.40000,1.87004,10290.44390,0.00000,0.00639,124.25491
37.50000,1.87494,10314.85125,0.00000,0.00642,124.54963
37.60000,1.88008,10343.51811,0.00000,0.00643,124.89577
37.70000,1.88492,10367.89715,0.00000,0.00645,125.19014
37.80000,1.89007,10395.49112,0.00000,0.00648,125.52333
37.90000,1.89491,10418.84422,0.00000,0.00650,125.80532
38.00000,1.90005,10445.73784,0.00000,0.00651,126.13005
38.10000,1.90477,10470.39703,0.00000,0.00654,126.42781
38.20000,1.90998,10498.72488,0.00000,0.00656,126.76986
38.30000,1.91482,10523.29987,0.00000,0.00658,127.06660
38.40000,1.92002,10551.30586,0.00000,0.00660,127.40476
38.50000,1.92486,10575.69981,0.00000,0.00662,127.69932
38.60000,1.93000,10603.22970,0.00000,0.00664,128.03173
38.70000,1.93491,10629.48555,0.00000,0.00666,128.34877
38.80000,1.93999,10656.51029,0.00000,0.00668,128.67509
38.90000,1.94495,10681.78564,0.00000,0.00670,128.98028
39.00000,1.94997,10708.81337,0.00000,0.00672,129.30663
39.10000,1.95494,10736.55635,0.00000,0.00674,129.64162
39.20000,1.95996,10762.36889,0.00000,0.00676,129.95331
39.30000,1.96504,10789.61492,0.00000,0.00678,130.28230
39.40000,1.97000,10812.01434,0.00000,0.00680,130.55276
39.50000,1.97503,10840.82201,0.00000,0.00682,130.90061
39.60000,1.97999,10864.83523,0.00000,0.00684,131.19056
39.70000,1.98501,10893.32029,0.00000,0.00687,131.53452
39.80000,1.99003,10917.83494,0.00000,0.00688,131.83052
39.90000,1.99512,10945.37675,0.00000,0.00690,132.16309
40.00000,2.00002,10970.10896,0.00000,0.00693,132.46172
40.10000,2.00510,10998.29376,0.00000,0.00695,132.80205
40.20000,2.01000,11022.42768,0.00000,0.00696,133.09346
40.30000,2.01515,11049.49564,0.00000,0.00699,133.42030
40.40000,2.01999,11073.40306,0.00000,0.00700,133.70898
40.50000,2.02507,11101.09240,0.00000,0.00702,134.04332
40.60000,2.02991,11126.81702,0.00000,0.00705,134.35394
40.70000,2.03505,11154.66729,0.00000,0.00707,134.69022
40.80000,2.03996,11180.42320,0.00000,0.00709,135.00122
40.90000,2.04504,11206.79155,0.00000,0.00710,135.31961
41.00000,2.04994,11232.80749,0.00000,0.00713,135.63375
41.10000,2.05502,11258.76755,0.00000,0.00715,135.94721
41.20000,2.05999,11284.73207,0.00000,0.00716,136.26073
41.30000,2.06507,11310.63253,0.00000,0.00719,136.57347
41.40000,2.06991,11335.97419,0.00000,0.00721,136.87947
41.50000,2.07505,11363.67172,0.00000,0.00722,137.21391
41.60000,2.07996,11389.05585,0.00000,0.00725,137.52042
41.70000,2.08504,11414.49139,0.00000,0.00727,137.82755
41.80000,2.09000,11442.38338,0.00000,0.00729,138.16434
41.90000,2.09496,11466.37648,0.00000,0.00731,138.45405
42.00000,2.09999,11495.56935,0.00000,0.00733,138.80654
42.10000,2.10495,11519.73978,0.00000,0.00735,139.09840
42.20000,2.11009,11548.48859,0.00000,0.00737,139.44553
42.30000,2.11499,11573.06433,0.00000,0.00739,139.74228
42.40000,2.12002,11600.50556,0.00000,0.00741,140.07363
42.50000,2.12492,11625.75111,0.00000,0.00743,140.37846
42.60000,2.13006,11653.06792,0.00000,0.00746,140.70831
42.70000,2.13490,11677.67048,0.00000,0.00747,141.00538
42.80000,2.14005,11705.70031,0.00000,0.00750,141.34383
42.90000,2.14483,11730.29914,0.00000,0.00751,141.64086
43.00000,2.15003,11758.83040,0.00000,0.00754,141.98537
43.10000,2.15493,11783.92544,0.00000,0.00755,142.28838
43.20000,2.16007,11811.13347,0.00000,0.00758,142.61691
43.30000,2.16498,11835.85078,0.00000,0.00760,142.91537
43.40000,2.17006,11861.42862,0.00000,0.00762,143.22422
43.50000,2.17496,11887.70905,0.00000,0.00764,143.54155
43.60000,2.18004,11912.79441,0.00000,0.00766,143.84445
43.70000,2.18501,11939.66046,0.00000,0.00768,144.16885
43.80000,2.18997,11965.71290,0.00000,0.00771,144.48343
43.90000,2.19493,11992.18109,0.00000,0.00773,144.80303
44.00000,2.20001,12018.43321,0.00000,0.00774,145.12001
44.10000,2.20498,12045.81037,0.00000,0.00777,145.45059
44.20000,2.21000,12070.14620,0.00000,0.00779,145.74444
44.30000,2.21508,12097.77370,0.00000,0.00781,146.07803
44.40000,2.21998,12122.15051,0.00000,0.00783,146.37238
44.50000,2.22507,12149.28776,0.00000,0.00785,146.70005
44.60000,2.22997,12173.68990,0.00000,0.00787,146.99471
44.70000,2.23511,12200.74296,0.00000,0.00789,147.32137
44.80000,2.23995,12224.33522,0.00000,0.00791,147.60624
44.90000,2.24510,12253.04529,0.00000,0.00793,147.95290
45.00000,2.24994,12276.04672,0.00000,0.00796,148.23064
45.10000,2.25508,12303.94766,0.00000,0.00798,148.56754
45.20000,2.25992,12328.42505,0.00000,0.00800,148.86310
45.30000,2.26506,12357.71328,0.00000,0.00802,149.21675
45.40000,2.26991,12382.76437,0.00000,0.00804,149.51923
45.50000,2.27505,12409.07758,0.00000,0.00806,149.83696
45.60000,2.27995,12434.26874,0.00000,0.00809,150.14114
45.70000,2.28503,12460.26829,0.00000,0.00811,150.45508
45.80000,2.28988,12485.41027,0.00000,0.00813,150.75866
45.90000,2.29502,12511.78533,0.00000,0.00815,151.07714
46.00000,2.29992,12537.79233,0.00000,0.00817,151.39116
46.10000,2.30500,12564.88562,0.00000,0.00819,151.71831
46.20000,2.30997,12592.84317,0.00000,0.00821,152.05589
46.30000,2.31499,12619.44920,0.00000,0.00823,152.37715
46.40000,2.31995,12646.53653,0.00000,0.00825,152.70423
46.50000,2.32503,12671.67777,0.00000,0.00827,153.00780
46.60000,2.33000,12697.27051,0.00000,0.00830,153.31683
46.70000,2.33496,12721.28820,0.00000,0.00831,153.60684
46.80000,2.33998,12749.10718,0.00000,0.00834,153.94275
46.90000,2.34494,12773.66579,0.00000,0.00836,154.23929
47.00000,2.35009,12801.72169,0.00000,0.00838,154.57805
47.10000,2.35493,12824.92727,0.00000,0.00840,154.85826
47.20000,2.36001,12854.06053,0.00000,0.00842,155.21004
47.30000,2.36485,12878.25108,0.00000,0.00844,155.50213
47.40000,2.37000,12905.97022,0.00000,0.00847,155.83683
47.50000,2.37490,12929.81356,0.00000,0.00849,156.12474
47.60000,2.38004,12957.66830,0.00000,0.00851,156.46108
47.70000,2.38488,12984.92253,0.00000,0.00853,156.79017
47.80000,2.39003,13012.04562,0.00000,0.00855,157.11767
47.90000,2.39487,13036.91715,0.00000,0.00857,157.41799
48.00000,2.40007,13062.90627,0.00000,0.00860,157.73180
48.10000,2.40497,13088.88793,0.00000,0.00862,158.04553
48.20000,2.40999,13114.85320,0.00000,0.00864,158.35905
48.30000,2.41490,13140.98388,0.00000,0.00866,158.67457
48.40000,2.42004,13166.79418,0.00000,0.00868,158.98623
48.50000,2.42494,13193.27056,0.00000,0.00870,159.30592
48.60000,2.43002,13218.98252,0.00000,0.00872,159.61639
48.70000,2.43499,13246.95200,0.00000,0.00874,159.95412
48.80000,2.44001,13271.03674,0.00000,0.00877,160.24493
48.90000,2.44503,13297.22852,0.00000,0.00878,160.56119
49.00000,2.45005,13321.34306,0.00000,0.00881,160.85237
49.10000,2.45502,13347.99379,0.00000,0.00882,161.17417
49.20000,2.45998,13373.49415,0.00000,0.00885,161.48209
49.30000,2.46500,13400.78264,0.00000,0.00887,161.81159
49.40000,2.46996,13425.85832,0.00000,0.00889,162.11437
49.50000,2.47505,13453.43292,0.00000,0.00891,162.44733
49.60000,2.47989,13478.57565,0.00000,0.00893,162.75092
49.70000,2.48509,13507.86686,0.00000,0.00896,163.10461
49.80000,2.48993,13530.98154,0.00000,0.00898,163.38371
49.90000,2.49508,13558.33113,0.00000,0.00900,163.71395
50.00000,2.49992,13582.08209,0.00000,0.00902,164.00074
50.10000,2.50500,13610.48371,0.00000,0.00904,164.34368
50.20000,2.50990,13635.47146,0.00000,0.00906,164.64541
50.30000,2.51510,13663.08182,0.00000,0.00909,164.97879
50.40000,2.51995,13687.36774,0.00000,0.00911,165.27204
50.50000,2.52503,13714.00952,0.00000,0.00913,165.59374
50.60000,2.52987,13741.11027,0.00000,0.00915,165.92097
50.70000,2.53501,13767.06064,0.00000,0.00917,166.23432
50.80000,2.53998,13793.21963,0.00000,0.00919,166.55018
50.90000,2.54506,13819.80926,0.00000,0.00922,166.87124
51.00000,2.54996,13845.55846,0.00000,0.00924,167.18216
51.10000,2.55498,13872.34181,0.00000,0.00926,167.50556
51.20000,2.55995,13898.76455,0.00000,0.00928,167.82461
51.30000,2.56503,13923.44385,0.00000,0.00931,168.12261
51.40000,2.56999,13949.47320,0.00000,0.00933,168.43691
51.50000,2.57489,13974.28215,0.00000,0.00934,168.73647
51.60000,2.57998,14003.04884,0.00000,0.00937,169.08382
51.70000,2.58500,14028.58347,0.00000,0.00939,169.39215
51.80000,2.59008,14056.71090,0.00000,0.00941,169.73178
51.90000,2.59498,14081.05791,0.00000,0.00943,170.02577
52.00000,2.60007,14107.79804,0.00000,0.00946,170.34865
52.10000,2.60491,14131.27929,0.00000,0.00948,170.63218
52.20000,2.61011,14159.15340,0.00000,0.00950,170.96875
52.30000,2.61489,14182.11162,0.00000,0.00952,171.24597
52.40000,2.62010,14209.94103,0.00000,0.00955,171.58200
52.50000,2.62494,14236.02700,0.00000,0.00957,171.89699
52.60000,2.63008,14262.90870,0.00000,0.00959,172.22158
52.70000,2.63498,14289.79784,0.00000,0.00961,172.54626
52.80000,2.64006,14315.16111,0.00000,0.00964,172.85251
52.90000,2.64491,14340.00582,0.00000,0.00966,173.15251
53.00000,2.64999,14365.83102,0.00000,0.00968,173.46434
53.10000,2.65495,14392.52198,0.00000,0.00970,173.78663
53.20000,2.66003,14418.53940,0.00000,0.00973,174.10078
53.30000,2.66494,14444.93234,0.00000,0.00975,174.41947
53.40000,2.66996,14470.98255,0.00000,0.00976,174.73402
53.50000,2.67498,14496.88077,0.00000,0.00979,175.04674
53.60000,2.68000,14521.45576,0.00000,0.00981,175.34348
53.70000,2.68497,14548.23911,0.00000,0.00983,175.66688
53.80000,2.68999,14573.42803,0.00000,0.00986,175.97103
53.90000,2.69495,14600.12496,0.00000,0.00988,176.29339
54.00000,2.69997,14625.05311,0.00000,0.00990,176.59439
54.10000,2.70506,14653.35190,0.00000,0.00993,176.93609
54.20000,2.71002,14677.83153,0.00000,0.00994,177.23168
54.30000,2.71504,14704.53590,0.00000,0.00997,177.55413
54.40000,2.71994,14729.38955,0.00000,0.00999,177.85423
54.50000,2.72503,14756.45006,0.00000,0.01001,178.18098
54.60000,2.72993,14779.88660,0.00000,0.01003,178.46397
54.70000,2.73507,14808.04533,0.00000,0.01005,178.80398
54.80000,2.73985,14831.48485,0.00000,0.01007,179.08701
54.90000,2.74505,14861.08750,0.00000,0.01010,179.44446
55.00000,2.74990,14885.89346,0.00000,0.01012,179.74398
55.10000,2.75504,14912.62615,0.00000,0.01014,180.06678
55.20000,2.75994,14937.11323,0.00000,0.01016,180.36245
55.30000,2.76508,14963.30947,0.00000,0.01018,180.67877
55.40000,2.76993,14988.30318,0.00000,0.01021,180.98056
55.50000,2.77501,15014.35339,0.00000,0.01023,181.29511
55.60000,2.77997,15041.13823,0.00000,0.01025,181.61853
55.70000,2.78505,15067.10798,0.00000,0.01027,181.93211
55.80000,2.78990,15093.33849,0.00000,0.01029,182.24884
55.90000,2.79498,15118.42310,0.00000,0.01032,182.55173
56.00000,2.79994,15145.15132,0.00000,0.01034,182.87447
56.10000,2.80496,15169.27779,0.00000,0.01036,183.16579
56.20000,2.80999,15196.31594,0.00000,0.01038,183.49227
56.30000,2.81489,15220.51692,0.00000,0.01040,183.78449
56.40000,2.81997,15248.50577,0.00000,0.01043,184.12245
56.50000,2.82493,15273.80943,0.00000,0.01045,184.42799
56.60000,2.83008,15301.16051,0.00000,0.01047,184.75824
56.70000,2.83492,15325.47325,0.00000,0.01049,185.05182
56.80000,2.84000,15353.49488,0.00000,0.01052,185.39017
56.90000,2.84484,15376.53357,0.00000,0.01053,185.66836
57.00000,2.84999,15403.63282,0.00000,0.01056,185.99558
57.10000,2.85489,15427.74886,0.00000,0.01058,186.28677
57.20000,2.86003,15455.11782,0.00000,0.01061,186.61725
57.30000,2.86487,15480.31569,0.00000,0.01063,186.92151
57.40000,2.87002,15506.13940,0.00000,0.01065,187.23332
57.50000,2.87498,15530.61157,0.00000,0.01067,187.52882
57.60000,2.88012,15556.09405,0.00000,0.01069,187.83651
57.70000,2.88496,15581.17718,0.00000,0.01072,188.13939
57.80000,2.88999,15606.81611,0.00000,0.01074,188.44897
57.90000,2.89495,15633.19415,0.00000,0.01076,188.76748
58.00000,2.90003,15659.09386,0.00000,0.01078,189.08021
58.10000,2.90493,15684.88181,0.00000,0.01081,189.39160
58.20000,2.90995,15710.75469,0.00000,0.01083,189.70401
58.30000,2.91492,15738.16389,0.00000,0.01085,190.03497
58.40000,2.92000,15762.02959,0.00000,0.01087,190.32314
58.50000,2.92502,15788.75184,0.00000,0.01090,190.64581
58.60000,2.93004,15812.72632,0.00000,0.01092,190.93529
58.70000,2.93507,15839.23399,0.00000,0.01094,191.25537
58.80000,2.93997,15863.66296,0.00000,0.01096,191.55034
58.90000,2.94505,15891.43574,0.00000,0.01098,191.88569
59.00000,2.94995,15915.23737,0.00000,0.01101,192.17309
59.10000,2.95504,15943.29476,0.00000,0.01103,192.51188
59.20000,2.95988,15967.34375,0.00000,0.01105,192.80227
59.30000,2.96508,15994.53390,0.00000,0.01108,193.13058
59.40000,2.96992,16018.17459,0.00000,0.01110,193.41604
59.50000,2.97513,16046.01443,0.00000,0.01112,193.75220
59.60000,2.97991,16068.70443,0.00000,0.01115,194.02617
59.70000,2.98505,16097.59480,0.00000,0.01117,194.37502
59.80000,2.98989,16122.06846,0.00000,0.01119,194.67053
59.90000,2.99504,16148.64022,0.00000,0.01122,194.99138
60.00000,2.99994,16173.29270,0.00000,0.01124,195.28905
60.10000,3.00496,16199.01806,0.00000,0.01126,195.59968
60.20000,3.00986,16226.31252,0.00000,0.01128,195.92926
60.30000,3.01494,16251.83970,0.00000,0.01130,196.23749
60.40000,3.01997,16278.25648,0.00000,0.01133,196.55647
60.50000,3.02499,16304.06231,0.00000,0.01135,196.86807
60.60000,3.02989,16329.82790,0.00000,0.01137,197.17918
60.70000,3.03497,16354.51317,0.00000,0.01139,197.47725
60.80000,3.04000,16381.53195,0.00000,0.01142,197.80350
60.90000,3.04502,16403.96714,0.00000,0.01144,198.07440
61.00000,3.05004,16431.52386,0.00000,0.01146,198.40714
61.10000,3.05494,16454.22727,0.00000,0.01148,198.68128
61.20000,3.06009,16482.26976,0.00000,0.01151,199.01989
61.30000,3.06499,16508.26484,0.00000,0.01153,199.33377
61.40000,3.07007,16535.62933,0.00000,0.01155,199.66419
61.50000,3.07491,16561.10883,0.00000,0.01157,199.97185
61.60000,3.08006,16587.50325,0.00000,0.01159,200.29056
61.70000,3.08490,16611.07689,0.00000,0.01162,200.57521
61.80000,3.09010,16638.15975,0.00000,0.01165,200.90223
61.90000,3.09494,16662.26089,0.00000,0.01167,201.19324
62.00000,3.10009,16689.31395,0.00000,0.01169,201.51990
62.10000,3.10493,16714.86497,0.00000,0.01171,201.82842
62.20000,3.11007,16740.47709,0.00000,0.01174,202.13768
62.30000,3.11497,16765.41418,0.00000,0.01176,202.43880
62.40000,3.12005,16791.89503,0.00000,0.01178,202.75855
62.50000,3.12490,16817.56973,0.00000,0.01180,203.06856
62.60000,3.13004,16844.55127,0.00000,0.01183,203.39436
62.70000,3.13494,16869.04132,0.00000,0.01185,203.69007
62.80000,3.14008,16894.91421,0.00000,0.01187,204.00248
62.90000,3.14499,16921.77057,0.00000,0.01190,204.32677
63.00000,3.15001,16947.64942,0.00000,0.01192,204.63925
63.10000,3.15497,16974.02894,0.00000,0.01194,204.95777
63.20000,3.16005,16997.22260,0.00000,0.01196,205.23783
63.30000,3.16502,17023.78243,0.00000,0.01199,205.55854
63.40000,3.16998,17047.80012,0.00000,0.01201,205.84855
63.50000,3.17500,17076.12276,0.00000,0.01204,206.19053
63.60000,3.17990,17100.70819,0.00000,0.01206,206.48740
63.70000,3.18505,17129.68796,0.00000,0.01208,206.83732
63.80000,3.18995,17153.03212,0.00000,0.01210,207.11920
63.90000,3.19503,17179.70818,0.00000,0.01213,207.44131
64.00000,3.19987,17204.05221,0.00000,0.01215,207.73526
64.10000,3.20508,17231.41670,0.00000,0.01218,208.06568
64.20000,3.20998,17255.06037,0.00000,0.01220,208.35117
64.30000,3.21512,17280.92879,0.00000,0.01222,208.66352
64.40000,3.21984,17303.89297,0.00000,0.01224,208.94081
64.50000,3.22505,17332.24690,0.00000,0.01227,209.28318
64.60000,3.22989,17356.56261,0.00000,0.01229,209.57679
64.70000,3.23509,17382.72458,0.00000,0.01231,209.89269
64.80000,3.23987,17407.04626,0.00000,0.01233,210.18637
64.90000,3.24495,17431.84328,0.00000,0.01236,210.48578
65.00000,3.24986,17456.70438,0.00000,0.01238,210.78598
65.10000,3.25500,17483.21354,0.00000,0.01240,211.10607
65.20000,3.25996,17508.33690,0.00000,0.01243,211.40943
65.30000,3.26498,17533.51688,0.00000,0.01245,211.71347
65.40000,3.26995,17560.52822,0.00000,0.01247,212.03963
65.50000,3.27497,17582.31968,0.00000,0.01249,212.30275
65.60000,3.28005,17610.79133,0.00000,0.01252,212.64654
65.70000,3.28501,17633.88366,0.00000,0.01254,212.92538
65.80000,3.29004,17660.02476,0.00000,0.01257,213.24103
65.90000,3.29494,17682.94871,0.00000,0.01259,213.51783
66.00000,3.30002,17709.89001,0.00000,0.01261,213.84314
66.10000,3.30498,17732.82588,0.00000,0.01263,214.12008
66.20000,3.31013,17759.80741,0.00000,0.01266,214.44588
66.30000,3.31497,17782.75669,0.00000,0.01268,214.72299
66.40000,3.32011,17810.41026,0.00000,0.01270,215.05690
66.50000,3.32495,17832.24791,0.00000,0.01273,215.32058
66.60000,3.33010,17857.46217,0.00000,0.01275,215.62504
66.70000,3.33494,17880.76460,0.00000,0.01277,215.90641
66.80000,3.34002,17906.28135,0.00000,0.01280,216.21452
66.90000,3.34486,17931.37193,0.00000,0.01282,216.51749
67.00000,3.35007,17957.93921,0.00000,0.01284,216.83828
67.10000,3.35491,17983.05213,0.00000,0.01287,217.14151
67.20000,3.36005,18008.57782,0.00000,0.01289,217.44973
67.30000,3.36495,18033.06937,0.00000,0.01291,217.74546
67.40000,3.37003,18059.29244,0.00000,0.01293,218.06210
67.50000,3.37500,18083.62454,0.00000,0.01296,218.35590
67.60000,3.38008,18108.49458,0.00000,0.01298,218.65620
67.70000,3.38492,18132.50929,0.00000,0.01300,218.94618
67.80000,3.39000,18158.33002,0.00000,0.01303,219.25796
67.90000,3.39497,18185.66769,0.00000,0.01305,219.58805
68.00000,3.40005,18207.93450,0.00000,0.01307,219.85692
68.10000,3.40507,18235.60447,0.00000,0.01310,220.19103
68.20000,3.40997,18256.01459,0.00000,0.01312,220.43748
68.30000,3.41500,18283.51468,0.00000,0.01314,220.76953
68.40000,3.41996,18306.76943,0.00000,0.01317,221.05033
68.50000,3.42510,18333.24134,0.00000,0.01319,221.36997
68.60000,3.42994,18357.20390,0.00000,0.01321,221.65932
68.70000,3.43503,18383.30925,0.00000,0.01324,221.97453
68.80000,3.43987,18407.48340,0.00000,0.01326,222.26643
68.90000,3.44507,18434.28165,0.00000,0.01328,222.59001
69.00000,3.44985,18456.95376,0.00000,0.01330,222.86377
69.10000,3.45500,18481.99069,0.00000,0.01333,223.16609
69.20000,3.45984,18507.35992,0.00000,0.01335,223.47242
69.30000,3.46498,18532.89902,0.00000,0.01338,223.78080
69.40000,3.46988,18558.09242,0.00000,0.01340,224.08500
69.50000,3.47503,18583.16809,0.00000,0.01342,224.38779
69.60000,3.47993,18607.30499,0.00000,0.01345,224.67923
69.70000,3.48501,18632.96628,0.00000,0.01347,224.98909
69.80000,3.48991,18657.04954,0.00000,0.01349,225.27989
69.90000,3.49505,18681.25945,0.00000,0.01352,225.57222
70.00000,3.50002,18706.17568,0.00000,0.01354,225.87308
70.10000,3.50498,18730.12185,0.00000,0.01356,226.16222
70.20000,3.50994,18756.85602,0.00000,0.01358,226.48503
70.30000,3.51496,18780.52503,0.00000,0.01361,226.77083
70.40000,3.51999,18806.66614,0.00000,0.01363,227.08648
70.50000,3.52501,18829.43362,0.00000,0.01366,227.36139
70.60000,3.53003,18855.22008,0.00000,0.01368,227.67275
70.70000,3.53499,18879.42553,0.00000,0.01370,227.96503
70.80000,3.54008,18905.61432,0.00000,0.01373,228.28125
70.90000,3.54504,18928.24620,0.00000,0.01375,228.55453
71.00000,3.55012,18954.24724,0.00000,0.01378,228.86849
71.10000,3.55496,18979.50619,0.00000,0.01380,229.17348
71.20000,3.56005,19006.03771,0.00000,0.01383,229.49385
71.30000,3.56495,19029.00338,0.00000,0.01385,229.77115
71.40000,3.57009,19055.37993,0.00000,0.01387,230.08964
71.50000,3.57493,19078.63915,0.00000,0.01389,230.37049
71.60000,3.58007,19104.40475,0.00000,0.01392,230.68161
71.70000,3.58492,19128.13634,0.00000,0.01394,230.96816
71.80000,3.59006,19153.25522,0.00000,0.01397,231.27147
71.90000,3.59496,19178.29663,0.00000,0.01399,231.57384
72.00000,3.59999,19203.21584,0.00000,0.01402,231.87473
72.10000,3.60483,19228.19316,0.00000,0.01404,232.17633
72.20000,3.61003,19253.91108,0.00000,0.01406,232.48686
72.30000,3.61493,19278.86754,0.00000,0.01409,232.78821
72.40000,3.62001,19302.20723,0.00000,0.01411,233.07003
72.50000,3.62492,19327.71504,0.00000,0.01413,233.37803
72.60000,3.62994,19352.59104,0.00000,0.01416,233.67840
72.70000,3.63496,19379.48912,0.00000,0.01418,234.00319
72.80000,3.64004,19403.42933,0.00000,0.01421,234.29226
72.90000,3.64507,19429.09509,0.00000,0.01423,234.60217
73.00000,3.64997,19451.74634,0.00000,0.01425,234.87568
73.10000,3.65499,19477.76973,0.00000,0.01428,235.18991
73.20000,3.65989,19499.69530,0.00000,0.01430,235.45466
73.30000,3.66510,19525.96009,0.00000,0.01432,235.77180
73.40000,3.66994,19547.12868,0.00000,0.01435,236.02740
73.50000,3.67508,19575.19650,0.00000,0.01437,236.36632
73.60000,3.67986,19598.00720,0.00000,0.01439,236.64175
73.70000,3.68507,19624.60726,0.00000,0.01442,236.96294
73.80000,3.68991,19646.19160,0.00000,0.01444,237.22357
73.90000,3.69511,19672.62924,0.00000,0.01447,237.54280
74.00000,3.69995,19696.69461,0.00000,0.01449,237.83338
74.10000,3.70509,19721.85820,0.00000,0.01451,238.13723
74.20000,3.70994,19745.85652,0.00000,0.01454,238.42700
74.30000,3.71508,19769.32883,0.00000,0.01456,238.71042
74.40000,3.71998,19794.28679,0.00000,0.01459,239.01178
74.50000,3.72495,19819.34458,0.00000,0.01461,239.31435
74.60000,3.72997,19845.08336,0.00000,0.01464,239.62514
74.70000,3.73505,19869.04740,0.00000,0.01466,239.91450
74.80000,3.74001,19892.56144,0.00000,0.01468,240.19843
74.90000,3.74503,19916.47631,0.00000,0.01471,240.48720
75.00000,3.75006,19943.17025,0.00000,0.01473,240.80952
75.10000,3.75508,19965.83194,0.00000,0.01476,241.08316
75.20000,3.76010,19990.98510,0.00000,0.01478,241.38687
75.30000,3.76500,20013.81665,0.00000,0.01480,241.66256
75.40000,3.76997,20038.73885,0.00000,0.01483,241.96349
75.50000,3.77499,20061.87886,0.00000,0.01485,242.24290
75.60000,3.78007,20087.51333,0.00000,0.01488,242.55243
75.70000,3.78497,20109.19452,0.00000,0.01490,242.81423
75.80000,3.79006,20134.75001,0.00000,0.01493,243.12281
75.90000,3.79484,20157.18073,0.00000,0.01495,243.39365
76.00000,3.80004,20184.39621,0.00000,0.01498,243.72227
76.10000,3.80494,20208.44668,0.00000,0.01500,244.01268
76.20000,3.81015,20234.65335,0.00000,0.01503,244.32912
76.30000,3.81493,20256.69366,0.00000,0.01504,244.59525
76.40000,3.82001,20282.15230,0.00000,0.01507,244.90266
76.50000,3.82491,20304.40122,0.00000,0.01510,245.17131
76.60000,3.83012,20329.49179,0.00000,0.01512,245.47427
76.70000,3.83496,20351.40097,0.00000,0.01514,245.73882
76.80000,3.84004,20374.95077,0.00000,0.01517,246.02318
76.90000,3.84494,20399.58984,0.00000,0.01519,246.32069
77.00000,3.85002,20421.19652,0.00000,0.01522,246.58159
77.05600,3.85289,19978.98817,0.00000,0.01528,241.24201
77.05800,3.85319,19404.31744,0.00000,0.01537,234.30299
77.06000,3.85325,18624.80789,0.00000,0.01558,224.89058
77.06200,3.85343,17708.21810,0.00000,0.01594,213.82295
77.06400,3.85385,16686.02079,0.00000,0.01641,201.48014
77.06600,3.85409,15584.88160,0.00000,0.01691,188.18412
77.06800,3.85445,14440.26083,0.00000,0.01739,174.36307
77.07000,3.85475,13276.75432,0.00000,0.01779,160.31397
77.07200,3.85511,12107.13014,0.00000,0.01802,146.19101