File: scratch/college-stuff/ME Lab/ME lab Fall 2013/group8/group8.is_tens_RawData/Specimen_RawData_4.csv
Time,Extension,Load,Strain 2,Tensile strain,Tensile stress
(sec),(mm),(N),(mm/mm),(mm/mm),(MPa)
0.00000,0.00006,-0.05258,0.00000,0.00000,-0.00062
0.20000,0.00741,8.72927,0.00000,0.00001,0.10363
0.40000,0.01943,13.45386,0.00000,0.00000,0.15971
0.60000,0.03001,16.35001,0.00000,0.00001,0.19409
0.80000,0.04012,17.92421,0.00000,0.00001,0.21278
1.00000,0.05004,19.18716,0.00000,0.00000,0.22777
1.20000,0.06009,21.35711,0.00000,0.00000,0.25353
1.40000,0.07001,24.49424,0.00000,0.00000,0.29077
1.60000,0.08006,30.03059,0.00000,0.00000,0.35650
1.80000,0.08998,35.19103,0.00000,0.00000,0.41776
2.00000,0.09997,39.85053,0.00000,0.00000,0.47307
2.20000,0.10995,44.73968,0.00000,-0.00001,0.53111
2.40000,0.11988,51.60220,0.00000,-0.00001,0.61257
2.60000,0.12992,61.77676,0.00000,-0.00001,0.73336
2.80000,0.13991,69.40985,0.00000,0.00000,0.82397
3.00000,0.14995,75.15899,0.00000,-0.00001,0.89222
3.20000,0.15994,85.42379,0.00000,0.00000,1.01407
3.40000,0.16992,103.27530,0.00000,-0.00001,1.22599
3.60000,0.17997,124.36755,0.00000,0.00000,1.47638
3.80000,0.19001,148.53723,0.00000,-0.00001,1.76330
4.00000,0.20006,182.43205,0.00000,0.00000,2.16566
4.20000,0.21004,219.55017,0.00000,0.00000,2.60630
4.40000,0.22009,261.35172,0.00000,0.00001,3.10252
4.60000,0.23013,304.05826,0.00000,0.00002,3.60950
4.80000,0.24005,352.59458,0.00000,0.00003,4.18568
5.00000,0.25016,413.40990,0.00000,0.00005,4.90762
5.20000,0.26008,481.63356,0.00000,0.00008,5.71751
5.40000,0.27007,553.38307,0.00000,0.00012,6.56925
5.60000,0.28005,631.07517,0.00000,0.00015,7.49154
5.80000,0.29004,709.06398,0.00000,0.00018,8.41735
6.00000,0.30008,789.78995,0.00000,0.00022,9.37565
6.20000,0.31001,872.33428,0.00000,0.00026,10.35554
6.40000,0.31999,953.30942,0.00000,0.00029,11.31680
6.60000,0.32992,1038.85932,0.00000,0.00033,12.33237
6.80000,0.33990,1122.82047,0.00000,0.00037,13.32908
7.00000,0.34995,1206.35387,0.00000,0.00041,14.32071
7.20000,0.35987,1291.58087,0.00000,0.00045,15.33245
7.40000,0.36992,1374.12874,0.00000,0.00050,16.31238
7.60000,0.37984,1456.14361,0.00000,0.00053,17.28598
7.80000,0.38995,1534.96014,0.00000,0.00057,18.22162
8.00000,0.39993,1614.44973,0.00000,0.00062,19.16525
8.20000,0.40992,1693.74403,0.00000,0.00065,20.10656
8.40000,0.42002,1769.45738,0.00000,0.00069,21.00535
8.60000,0.43001,1845.95510,0.00000,0.00073,21.91346
8.80000,0.44005,1921.93463,0.00000,0.00076,22.81542
9.00000,0.45004,1996.83327,0.00000,0.00080,23.70455
9.20000,0.46008,2069.46917,0.00000,0.00084,24.56681
9.40000,0.47012,2141.31176,0.00000,0.00088,25.41966
9.60000,0.48005,2211.57707,0.00000,0.00091,26.25379
9.80000,0.49009,2280.80768,0.00000,0.00094,27.07563
10.00000,0.50002,2346.62462,0.00000,0.00098,27.85695
10.20000,0.51006,2410.47200,0.00000,0.00101,28.61488
10.40000,0.52005,2475.96167,0.00000,0.00104,29.39232
10.60000,0.53003,2537.75232,0.00000,0.00107,30.12584
10.80000,0.54002,2597.88018,0.00000,0.00110,30.83962
11.00000,0.54994,2656.49799,0.00000,0.00113,31.53548
11.20000,0.55993,2711.16681,0.00000,0.00116,32.18445
11.40000,0.56991,2761.33176,0.00000,0.00118,32.77996
11.60000,0.57990,2810.56501,0.00000,0.00121,33.36442
11.80000,0.58988,2863.68113,0.00000,0.00124,33.99496
12.00000,0.59981,2916.86412,0.00000,0.00126,34.62630
12.20000,0.60985,2971.98109,0.00000,0.00128,35.28060
12.40000,0.61990,3028.17542,0.00000,0.00131,35.94768
12.60000,0.62994,3084.83727,0.00000,0.00134,36.62032
12.80000,0.63999,3140.56538,0.00000,0.00137,37.28187
13.00000,0.64997,3195.03509,0.00000,0.00140,37.92849
13.20000,0.66002,3250.74047,0.00000,0.00142,38.58977
13.40000,0.67000,3306.73382,0.00000,0.00145,39.25447
13.60000,0.68011,3363.09224,0.00000,0.00148,39.92351
13.80000,0.69009,3419.13439,0.00000,0.00150,40.58879
14.00000,0.70013,3475.82139,0.00000,0.00154,41.26172
14.20000,0.71012,3532.76990,0.00000,0.00156,41.93776
14.40000,0.72004,3588.88842,0.00000,0.00159,42.60395
14.60000,0.73015,3643.94300,0.00000,0.00162,43.25750
14.80000,0.74007,3702.47327,0.00000,0.00165,43.95232
15.00000,0.75012,3757.88845,0.00000,0.00168,44.61016
15.20000,0.75998,3812.31047,0.00000,0.00170,45.25621
15.40000,0.77003,3869.34094,0.00000,0.00173,45.93322
15.60000,0.77995,3926.60871,0.00000,0.00176,46.61305
15.80000,0.78994,3983.00290,0.00000,0.00179,47.28251
16.00000,0.79998,4038.90125,0.00000,0.00182,47.94608
16.20000,0.80991,4096.66561,0.00000,0.00185,48.63181
16.40000,0.81989,4153.77095,0.00000,0.00188,49.30971
16.60000,0.82988,4209.65478,0.00000,0.00191,49.97311
16.80000,0.83986,4265.89921,0.00000,0.00194,50.64079
17.00000,0.84991,4322.04269,0.00000,0.00197,51.30727
17.20000,0.85995,4379.95680,0.00000,0.00200,51.99478
17.40000,0.87000,4436.14125,0.00000,0.00203,52.66175
17.60000,0.87992,4490.87173,0.00000,0.00206,53.31146
17.80000,0.88997,4548.73554,0.00000,0.00209,53.99836
18.00000,0.90001,4603.88474,0.00000,0.00211,54.65304
18.20000,0.91006,4659.09727,0.00000,0.00215,55.30847
18.40000,0.92010,4715.44750,0.00000,0.00217,55.97741
18.60000,0.93003,4771.76905,0.00000,0.00220,56.64601
18.80000,0.94007,4824.88461,0.00000,0.00224,57.27655
19.00000,0.95000,4878.42970,0.00000,0.00226,57.91218
19.20000,0.96004,4933.10429,0.00000,0.00229,58.56123
19.40000,0.97002,4988.82271,0.00000,0.00232,59.22267
19.60000,0.98001,5043.43361,0.00000,0.00235,59.87096
19.80000,0.99005,5096.45194,0.00000,0.00237,60.50034
20.00000,0.99998,5149.14431,0.00000,0.00240,61.12586
20.20000,1.01002,5202.48562,0.00000,0.00243,61.75907
20.40000,1.02001,5254.46907,0.00000,0.00245,62.37617
20.60000,1.02993,5308.48503,0.00000,0.00248,63.01740
20.80000,1.03992,5361.72464,0.00000,0.00251,63.64941
21.00000,1.04990,5414.94600,0.00000,0.00254,64.28121
21.20000,1.05995,5466.44516,0.00000,0.00256,64.89256
21.40000,1.06987,5518.34293,0.00000,0.00259,65.50864
21.60000,1.07986,5569.81266,0.00000,0.00262,66.11964
21.80000,1.08996,5620.26501,0.00000,0.00265,66.71856
22.00000,1.09989,5666.36994,0.00000,0.00267,67.26588
22.20000,1.10993,5711.63446,0.00000,0.00269,67.80322
22.40000,1.11998,5759.93247,0.00000,0.00272,68.37657
22.60000,1.13002,5808.94873,0.00000,0.00275,68.95844
22.80000,1.14001,5857.45610,0.00000,0.00277,69.53428
23.00000,1.14999,5907.99972,0.00000,0.00280,70.13428
23.20000,1.16004,5959.51639,0.00000,0.00283,70.74584
23.40000,1.17008,6010.98575,0.00000,0.00285,71.35684
23.60000,1.18012,6059.37466,0.00000,0.00288,71.93126
23.80000,1.19005,6109.85383,0.00000,0.00291,72.53051
24.00000,1.20009,6162.77047,0.00000,0.00294,73.15868
24.20000,1.21008,6215.61445,0.00000,0.00297,73.78600
24.40000,1.22000,6266.81298,0.00000,0.00300,74.39378
24.60000,1.23005,6318.00666,0.00000,0.00303,75.00150
24.80000,1.23997,6371.68065,0.00000,0.00305,75.63867
25.00000,1.25002,6424.32570,0.00000,0.00308,76.26362
25.20000,1.25994,6476.08638,0.00000,0.00310,76.87808
25.40000,1.26993,6527.69357,0.00000,0.00313,77.49071
25.60000,1.27997,6579.00795,0.00000,0.00316,78.09987
25.80000,1.28990,6632.13804,0.00000,0.00319,78.73058
26.00000,1.29994,6683.54481,0.00000,0.00322,79.34083
26.20000,1.30987,6736.38284,0.00000,0.00325,79.96808
26.40000,1.31991,6791.54471,0.00000,0.00327,80.62291
26.60000,1.32990,6844.43265,0.00000,0.00331,81.25074
26.80000,1.33994,6898.05746,0.00000,0.00333,81.88733
27.00000,1.34999,6949.42623,0.00000,0.00336,82.49713
27.20000,1.35997,7004.61641,0.00000,0.00339,83.15230
27.40000,1.36996,7056.66766,0.00000,0.00341,83.77020
27.60000,1.37994,7109.06237,0.00000,0.00345,84.39218
27.80000,1.38999,7163.14316,0.00000,0.00348,85.03418
28.00000,1.40003,7216.81193,0.00000,0.00350,85.67128
28.20000,1.41002,7271.65714,0.00000,0.00353,86.32236
28.40000,1.42012,7324.82597,0.00000,0.00356,86.95353
28.60000,1.43005,7378.69442,0.00000,0.00359,87.59300
28.80000,1.44009,7433.42713,0.00000,0.00363,88.24274
29.00000,1.45007,7487.14954,0.00000,0.00365,88.88048
29.20000,1.46000,7539.64111,0.00000,0.00368,89.50361
29.40000,1.47004,7593.54755,0.00000,0.00370,90.14354
29.60000,1.47997,7648.19309,0.00000,0.00374,90.79224
29.80000,1.48995,7702.09730,0.00000,0.00378,91.43214
30.00000,1.49994,7756.30474,0.00000,0.00380,92.07564
30.20000,1.50998,7812.55737,0.00000,0.00383,92.74342
30.40000,1.51991,7866.28798,0.00000,0.00386,93.38126
30.60000,1.52989,7920.17356,0.00000,0.00389,94.02094
30.80000,1.53994,7972.52655,0.00000,0.00392,94.64243
31.00000,1.54986,8027.37474,0.00000,0.00395,95.29353
31.20000,1.55991,8083.34649,0.00000,0.00398,95.95798
31.40000,1.56989,8137.91528,0.00000,0.00401,96.60577
31.60000,1.57994,8191.26070,0.00000,0.00404,97.23903
31.80000,1.58998,8247.53642,0.00000,0.00408,97.90709
32.00000,1.59997,8303.20120,0.00000,0.00411,98.56789
32.20000,1.61001,8357.90783,0.00000,0.00413,99.21731
32.40000,1.62000,8413.22765,0.00000,0.00417,99.87402
32.60000,1.63004,8467.57814,0.00000,0.00420,100.51922
32.80000,1.64009,8522.25572,0.00000,0.00423,101.16830
33.00000,1.65007,8576.96533,0.00000,0.00426,101.81776
33.20000,1.66006,8633.77452,0.00000,0.00429,102.49215
33.40000,1.67004,8690.77668,0.00000,0.00432,103.16882
33.60000,1.68008,8745.00275,0.00000,0.00435,103.81255
33.80000,1.69007,8799.90011,0.00000,0.00438,104.46424
34.00000,1.69999,8854.75054,0.00000,0.00442,105.11537
34.20000,1.70998,8909.52274,0.00000,0.00445,105.76557
34.40000,1.71996,8966.78641,0.00000,0.00448,106.44536
34.60000,1.73001,9021.46026,0.00000,0.00450,107.09439
34.80000,1.73993,9077.17496,0.00000,0.00454,107.75579
35.00000,1.74992,9133.11914,0.00000,0.00457,108.41990
35.20000,1.75990,9188.10815,0.00000,0.00460,109.07268
35.40000,1.76989,9245.72349,0.00000,0.00463,109.75664
35.60000,1.77999,9303.61822,0.00000,0.00466,110.44391
35.80000,1.78992,9358.57520,0.00000,0.00470,111.09631
36.00000,1.79990,9412.01076,0.00000,0.00473,111.73064
36.20000,1.80995,9468.55247,0.00000,0.00476,112.40186
36.40000,1.81993,9526.19463,0.00000,0.00479,113.08613
36.60000,1.82998,9582.43161,0.00000,0.00483,113.75372
36.80000,1.83996,9639.89124,0.00000,0.00486,114.43583
37.00000,1.85001,9697.37768,0.00000,0.00489,115.11826
37.20000,1.85999,9754.93640,0.00000,0.00493,115.80154
37.40000,1.87004,9811.68747,0.00000,0.00496,116.47524
37.60000,1.88008,9869.86235,0.00000,0.00499,117.16583
37.80000,1.89007,9926.52848,0.00000,0.00503,117.83852
38.00000,1.90005,9981.36029,0.00000,0.00506,118.48943
38.20000,1.90998,10038.31103,0.00000,0.00509,119.16550
38.40000,1.92002,10096.06421,0.00000,0.00513,119.85109
38.60000,1.93000,10154.64216,0.00000,0.00516,120.54647
38.80000,1.94005,10211.25093,0.00000,0.00519,121.21848
39.00000,1.94997,10267.87758,0.00000,0.00523,121.89070
39.20000,1.95996,10326.33930,0.00000,0.00526,122.58470
39.40000,1.97000,10381.99067,0.00000,0.00529,123.24535
39.60000,1.97999,10440.31531,0.00000,0.00533,123.93772
39.80000,1.99003,10496.98666,0.00000,0.00536,124.61047
40.00000,1.99996,10554.41126,0.00000,0.00539,125.29216
40.20000,2.01000,10612.05864,0.00000,0.00543,125.97650
40.40000,2.01999,10668.09371,0.00000,0.00546,126.64169
40.60000,2.02991,10726.21793,0.00000,0.00550,127.33169
40.80000,2.03996,10785.37777,0.00000,0.00553,128.03398
41.00000,2.04994,10841.75408,0.00000,0.00556,128.70323
41.20000,2.05999,10899.71811,0.00000,0.00560,129.39132
41.40000,2.06991,10957.38038,0.00000,0.00563,130.07584
41.60000,2.07996,11014.52187,0.00000,0.00566,130.75417
41.80000,2.09000,11071.82279,0.00000,0.00570,131.43439
42.00000,2.09999,11131.43787,0.00000,0.00573,132.14209
42.20000,2.11009,11189.89736,0.00000,0.00576,132.83606
42.40000,2.12002,11246.78329,0.00000,0.00580,133.51136
42.60000,2.13006,11304.64822,0.00000,0.00583,134.19828
42.80000,2.14005,11363.46087,0.00000,0.00587,134.89645
43.00000,2.15003,11420.61055,0.00000,0.00590,135.57487
43.20000,2.16007,11477.91222,0.00000,0.00594,136.25511
43.40000,2.17006,11535.85389,0.00000,0.00597,136.94294
43.60000,2.18004,11592.97600,0.00000,0.00601,137.62104
43.80000,2.18997,11649.72335,0.00000,0.00604,138.29469
44.00000,2.20001,11706.65920,0.00000,0.00607,138.97058
44.20000,2.21000,11765.57690,0.00000,0.00611,139.66999
44.40000,2.21998,11823.49771,0.00000,0.00614,140.35758
44.60000,2.23003,11878.89203,0.00000,0.00618,141.01517
44.80000,2.23995,11935.57084,0.00000,0.00621,141.68800
45.00000,2.24994,11994.52132,0.00000,0.00624,142.38781
45.20000,2.25992,12052.13293,0.00000,0.00628,143.07172
45.40000,2.26991,12109.73859,0.00000,0.00632,143.75556
45.60000,2.27995,12168.25098,0.00000,0.00635,144.45017
45.80000,2.28988,12226.82223,0.00000,0.00639,145.14547
46.00000,2.29992,12285.66319,0.00000,0.00642,145.84398
46.20000,2.30997,12345.20674,0.00000,0.00645,146.55082
46.40000,2.31995,12404.94400,0.00000,0.00649,147.25997
46.60000,2.33000,12461.18248,0.00000,0.00653,147.92758
46.80000,2.33998,12520.94507,0.00000,0.00656,148.63702
47.00000,2.35009,12579.89556,0.00000,0.00660,149.33683
47.20000,2.36001,12638.57633,0.00000,0.00664,150.03343
47.40000,2.37000,12696.02627,0.00000,0.00667,150.71543
47.60000,2.38004,12753.00086,0.00000,0.00670,151.39177
47.80000,2.39003,12813.68732,0.00000,0.00674,152.11219
48.00000,2.40007,12872.35320,0.00000,0.00678,152.80861
48.20000,2.40999,12931.77158,0.00000,0.00681,153.51397
48.40000,2.42004,12990.26608,0.00000,0.00685,154.20837
48.60000,2.43002,13045.86828,0.00000,0.00688,154.86842
48.80000,2.44001,13103.79207,0.00000,0.00692,155.55604
49.00000,2.45005,13162.11820,0.00000,0.00696,156.24844
49.20000,2.45998,13222.48429,0.00000,0.00699,156.96505
49.40000,2.46996,13280.88790,0.00000,0.00703,157.65836
49.60000,2.47989,13338.41234,0.00000,0.00706,158.34124
49.80000,2.48993,13397.95738,0.00000,0.00710,159.04810
50.00000,2.49992,13457.50690,0.00000,0.00714,159.75502
50.20000,2.50990,13516.48271,0.00000,0.00717,160.45512
50.40000,2.51995,13575.71036,0.00000,0.00721,161.15822
50.60000,2.52987,13636.33871,0.00000,0.00724,161.87794
50.80000,2.53998,13695.65427,0.00000,0.00728,162.58208
51.00000,2.54996,13754.89831,0.00000,0.00732,163.28537
51.20000,2.55995,13818.42494,0.00000,0.00736,164.03950
51.40000,2.56999,13875.89425,0.00000,0.00739,164.72172
51.60000,2.57998,13934.72552,0.00000,0.00742,165.42011
51.80000,2.59008,13994.26460,0.00000,0.00746,166.12690
52.00000,2.60007,14053.42966,0.00000,0.00750,166.82926
52.20000,2.61011,14113.20567,0.00000,0.00754,167.53886
52.40000,2.62010,14170.82548,0.00000,0.00757,168.22287
52.60000,2.63008,14231.36294,0.00000,0.00761,168.94152
52.80000,2.64006,14290.35217,0.00000,0.00764,169.64178
53.00000,2.64999,14348.17016,0.00000,0.00768,170.32814
53.20000,2.66003,14407.74351,0.00000,0.00772,171.03534
53.40000,2.66996,14467.84288,0.00000,0.00775,171.74879
53.60000,2.68000,14525.93952,0.00000,0.00779,172.43845
53.80000,2.69005,14584.51301,0.00000,0.00783,173.13378
54.00000,2.69997,14644.20408,0.00000,0.00786,173.84238
54.20000,2.71002,14703.80425,0.00000,0.00791,174.54990
54.40000,2.71994,14761.55668,0.00000,0.00794,175.23548
54.60000,2.72993,14820.92887,0.00000,0.00798,175.94029
54.80000,2.73985,14881.33818,0.00000,0.00801,176.65742
55.00000,2.74990,14941.25724,0.00000,0.00805,177.36872
55.20000,2.75994,15000.82761,0.00000,0.00809,178.07588
55.40000,2.76993,15061.91939,0.00000,0.00813,178.80111
55.60000,2.77997,15122.13051,0.00000,0.00817,179.51588
55.80000,2.78990,15179.88294,0.00000,0.00820,180.20146
56.00000,2.79994,15240.00317,0.00000,0.00825,180.91515
56.20000,2.80999,15300.61960,0.00000,0.00828,181.63474
56.40000,2.81997,15361.03040,0.00000,0.00832,182.35188
56.60000,2.83008,15421.62597,0.00000,0.00836,183.07121
56.80000,2.84006,15482.75799,0.00000,0.00839,183.79691
57.00000,2.84999,15540.98725,0.00000,0.00843,184.48816
57.20000,2.86003,15598.62942,0.00000,0.00847,185.17243
57.40000,2.87002,15659.09535,0.00000,0.00851,185.89023
57.60000,2.88012,15719.55234,0.00000,0.00855,186.60792
57.80000,2.88999,15777.83525,0.00000,0.00858,187.29980
58.00000,2.90003,15835.71434,0.00000,0.00862,187.98688
58.20000,2.90995,15896.98792,0.00000,0.00865,188.71427
58.40000,2.92000,15957.46875,0.00000,0.00869,189.43224
58.60000,2.93004,16017.42804,0.00000,0.00873,190.14402
58.80000,2.93997,16077.93272,0.00000,0.00877,190.86228
59.00000,2.94995,16136.53153,0.00000,0.00881,191.55791
59.20000,2.95988,16194.71461,0.00000,0.00884,192.24860
59.40000,2.96986,16256.70493,0.00000,0.00888,192.98449
59.60000,2.97991,16316.93244,0.00000,0.00892,193.69946
59.80000,2.98989,16376.85448,0.00000,0.00896,194.41080
60.00000,2.99994,16435.97037,0.00000,0.00899,195.11257
60.20000,3.00986,16497.62094,0.00000,0.00904,195.84442
60.40000,3.01997,16558.66802,0.00000,0.00907,196.56912
60.60000,3.02989,16616.96136,0.00000,0.00911,197.26112
60.80000,3.04000,16676.74333,0.00000,0.00915,197.97080
61.00000,3.05004,16736.52828,0.00000,0.00919,198.68051
61.20000,3.06003,16795.74847,0.00000,0.00923,199.38352
61.40000,3.07007,16854.60657,0.00000,0.00926,200.08223
61.60000,3.08006,16915.57765,0.00000,0.00930,200.80602
61.80000,3.09010,16974.31356,0.00000,0.00934,201.50328
62.00000,3.10009,17032.83936,0.00000,0.00938,202.19804
62.20000,3.11007,17093.00131,0.00000,0.00942,202.91223
62.40000,3.12005,17154.26594,0.00000,0.00946,203.63950
62.60000,3.13004,17213.96297,0.00000,0.00950,204.34817
62.80000,3.14008,17271.00760,0.00000,0.00954,205.02535
63.00000,3.15001,17331.49886,0.00000,0.00957,205.74345
63.20000,3.16005,17391.30765,0.00000,0.00961,206.45344
63.40000,3.16998,17450.31178,0.00000,0.00965,207.15388
63.60000,3.17990,17511.24710,0.00000,0.00969,207.87725
63.80000,3.18995,17570.78916,0.00000,0.00973,208.58408
64.00000,3.19987,17631.72150,0.00000,0.00976,209.30741
64.20000,3.20998,17690.58406,0.00000,0.00981,210.00617
64.40000,3.21984,17750.05460,0.00000,0.00984,210.71215
64.60000,3.22989,17810.54586,0.00000,0.00988,211.43025
64.80000,3.23987,17868.02709,0.00000,0.00992,212.11261
65.00000,3.24986,17927.80906,0.00000,0.00996,212.82229
65.20000,3.25996,17988.57749,0.00000,0.01000,213.54367
65.40000,3.26995,18046.90957,0.00000,0.01004,214.23614
65.60000,3.28005,18107.01340,0.00000,0.01008,214.94964
65.80000,3.28998,18165.41553,0.00000,0.01012,215.64293
66.00000,3.30002,18223.78635,0.00000,0.01015,216.33586
66.20000,3.31013,18281.74591,0.00000,0.01019,217.02390
66.40000,3.32011,18340.57719,0.00000,0.01023,217.72229
66.60000,3.33010,18399.08659,0.00000,0.01027,218.41686
66.80000,3.34002,18457.44699,0.00000,0.01031,219.10966
67.00000,3.35007,18516.55990,0.00000,0.01034,219.81139
67.20000,3.36005,18577.08693,0.00000,0.01038,220.52991
67.40000,3.37003,18637.34722,0.00000,0.01042,221.24527
67.60000,3.38008,18694.97299,0.00000,0.01046,221.92935
67.80000,3.39000,18754.31240,0.00000,0.01050,222.63377
68.00000,3.40005,18814.00794,0.00000,0.01053,223.34242
68.20000,3.40997,18870.56828,0.00000,0.01057,224.01385
68.40000,3.41996,18929.57687,0.00000,0.01061,224.71434
68.60000,3.42994,18990.03685,0.00000,0.01065,225.43207
68.80000,3.43987,19050.69798,0.00000,0.01069,226.15218
69.00000,3.44985,19108.78718,0.00000,0.01073,226.84176
69.20000,3.45984,19167.91201,0.00000,0.01076,227.54364
69.40000,3.46988,19227.76401,0.00000,0.01080,228.25415
69.60000,3.47993,19286.82029,0.00000,0.01084,228.95521
69.80000,3.48991,19346.22824,0.00000,0.01089,229.66044
70.00000,3.50002,19406.35741,0.00000,0.01092,230.37424
70.20000,3.50994,19464.15007,0.00000,0.01097,231.06030
70.40000,3.51999,19522.44043,0.00000,0.01100,231.75227
70.60000,3.53003,19582.53682,0.00000,0.01104,232.46568
70.80000,3.54008,19644.02348,0.00000,0.01108,233.19559
71.00000,3.55012,19701.95174,0.00000,0.01112,233.88326
71.20000,3.56005,19761.40887,0.00000,0.01116,234.58908
71.40000,3.57015,19821.83307,0.00000,0.01120,235.30638
71.60000,3.58007,19882.03675,0.00000,0.01125,236.02106
71.80000,3.59006,19943.00485,0.00000,0.01128,236.74482
72.00000,3.60004,20001.20580,0.00000,0.01132,237.43573
72.20000,3.61003,20061.92952,0.00000,0.01136,238.15658
72.40000,3.62001,20119.91143,0.00000,0.01140,238.84489
72.60000,3.62994,20181.87940,0.00000,0.01144,239.58052
72.80000,3.64004,20243.58213,0.00000,0.01148,240.31299
73.00000,3.64997,20301.67729,0.00000,0.01152,241.00265
73.20000,3.65989,20360.77827,0.00000,0.01156,241.70424
73.40000,3.66994,20420.12662,0.00000,0.01160,242.40877
73.60000,3.67986,20480.41075,0.00000,0.01164,243.12440
73.80000,3.68991,20538.56850,0.00000,0.01168,243.81480
74.00000,3.69995,20599.50382,0.00000,0.01172,244.53817
74.20000,3.70994,20660.33632,0.00000,0.01176,245.26031
74.40000,3.71998,20718.88745,0.00000,0.01180,245.95538
74.60000,3.72991,20778.93168,0.00000,0.01184,246.66817
74.80000,3.74001,20838.70023,0.00000,0.01188,247.37768
75.00000,3.75000,20898.05305,0.00000,0.01192,248.08226
75.20000,3.76010,20954.52994,0.00000,0.01196,248.75271
75.40000,3.76997,21012.19445,0.00000,0.01199,249.43725
75.60000,3.78007,21073.31306,0.00000,0.01203,250.16279
75.80000,3.79006,21131.65259,0.00000,0.01208,250.85534
76.00000,3.80004,21190.19628,0.00000,0.01212,251.55032
76.20000,3.81009,21249.50886,0.00000,0.01216,252.25442
76.40000,3.82001,21309.07327,0.00000,0.01220,252.96151
76.60000,3.83006,21367.83153,0.00000,0.01224,253.65904
76.80000,3.83998,21425.70466,0.00000,0.01228,254.34605
77.00000,3.85002,21485.81296,0.00000,0.01232,255.05960
77.20000,3.86007,21544.66361,0.00000,0.01236,255.75822
77.40000,3.86999,21602.74237,0.00000,0.01240,256.44768
77.60000,3.88004,21663.41841,0.00000,0.01244,257.16797
77.80000,3.88990,21722.05895,0.00000,0.01248,257.86410
78.00000,3.89995,21781.76790,0.00000,0.01252,258.57291
78.20000,3.90987,21839.86604,0.00000,0.01256,259.26259
78.40000,3.91986,21899.49155,0.00000,0.01260,259.97041
78.60000,3.92996,21957.68505,0.00000,0.01264,260.66123
78.80000,3.93995,22015.83982,0.00000,0.01268,261.35159
79.00000,3.94993,22076.40260,0.00000,0.01272,262.07054
79.20000,3.95986,22132.79158,0.00000,0.01276,262.73993
79.40000,3.96996,22192.16079,0.00000,0.01281,263.44471
79.60000,3.98007,22251.22750,0.00000,0.01284,264.14589
79.80000,3.98999,22310.60117,0.00000,0.01288,264.85072
80.00000,4.00004,22368.36702,0.00000,0.01292,265.53647
80.20000,4.01002,22427.51718,0.00000,0.01296,266.23864
80.40000,4.02007,22486.81784,0.00000,0.01300,266.94260
80.60000,4.03011,22545.21996,0.00000,0.01304,267.63590
80.80000,4.04004,22602.53727,0.00000,0.01308,268.31632
81.00000,4.05014,22660.78293,0.00000,0.01313,269.00776
81.20000,4.06001,22721.23545,0.00000,0.01317,269.72539
81.40000,4.06999,22778.56171,0.00000,0.01321,270.40592
81.60000,4.08003,22835.46329,0.00000,0.01325,271.08140
81.80000,4.09002,22896.22277,0.00000,0.01329,271.80268
82.00000,4.10000,22953.94391,0.00000,0.01333,272.48789
82.20000,4.10993,23011.68293,0.00000,0.01337,273.17331
82.40000,4.11997,23069.47410,0.00000,0.01341,273.85936
82.60000,4.12990,23128.25769,0.00000,0.01345,274.55718
82.80000,4.13994,23185.40514,0.00000,0.01349,275.23558
83.00000,4.14987,23242.39016,0.00000,0.01353,275.91206
83.20000,4.15991,23303.04235,0.00000,0.01357,276.63206
83.40000,4.16996,23361.95260,0.00000,0.01361,277.33139
83.60000,4.17982,23416.93342,0.00000,0.01365,277.98407
83.80000,4.18993,23475.14331,0.00000,0.01370,278.67509
84.00000,4.19991,23535.18754,0.00000,0.01374,279.38787
84.20000,4.20996,23593.28419,0.00000,0.01378,280.07754
84.40000,4.21994,23649.81771,0.00000,0.01382,280.74866
84.60000,4.22993,23708.38374,0.00000,0.01386,281.44390
84.80000,4.24003,23767.47429,0.00000,0.01390,282.14537
85.00000,4.24996,23827.51256,0.00000,0.01394,282.85809
85.20000,4.26006,23885.91021,0.00000,0.01398,283.55133
85.40000,4.27005,23945.27793,0.00000,0.01402,284.25609
85.60000,4.28009,24002.71147,0.00000,0.01406,284.93788
85.80000,4.29008,24059.48043,0.00000,0.01410,285.61179
86.00000,4.30000,24119.33392,0.00000,0.01415,286.32232
86.20000,4.31010,24177.58256,0.00000,0.01419,287.01379
86.40000,4.32003,24233.10429,0.00000,0.01423,287.67289
86.60000,4.32995,24290.78072,0.00000,0.01427,288.35757
86.80000,4.33994,24346.78823,0.00000,0.01431,289.02244
87.00000,4.34992,24405.83855,0.00000,0.01435,289.72343
87.20000,4.36003,24463.65803,0.00000,0.01440,290.40981
87.40000,4.36989,24520.20198,0.00000,0.01444,291.08105
87.60000,4.38000,24578.10938,0.00000,0.01448,291.76847
87.80000,4.38986,24631.98006,0.00000,0.01452,292.40798
88.00000,4.39985,24690.84710,0.00000,0.01456,293.10679
88.20000,4.40995,24748.21657,0.00000,0.01460,293.78783
88.40000,4.41994,24806.06288,0.00000,0.01464,294.47453
88.60000,4.42998,24862.70368,0.00000,0.01468,295.14691
88.80000,4.43985,24918.36399,0.00000,0.01472,295.80766
89.00000,4.44995,24979.02364,0.00000,0.01476,296.52775
89.20000,4.46000,25036.60321,0.00000,0.01480,297.21129
89.40000,4.47004,25092.11600,0.00000,0.01484,297.87028
89.60000,4.48009,25148.18907,0.00000,0.01488,298.53593
89.80000,4.49001,25206.25293,0.00000,0.01492,299.22521
90.00000,4.50006,25261.39617,0.00000,0.01496,299.87982
90.20000,4.50998,25317.17122,0.00000,0.01501,300.54193
90.40000,4.52009,25375.53310,0.00000,0.01505,301.23475
90.60000,4.53007,25431.90122,0.00000,0.01509,301.90390
90.80000,4.54000,25486.16827,0.00000,0.01513,302.54810
91.00000,4.55004,25542.10722,0.00000,0.01517,303.21216
91.20000,4.55996,25599.05052,0.00000,0.01521,303.88814
91.40000,4.57001,25654.96266,0.00000,0.01525,304.55187
91.60000,4.57999,25708.46081,0.00000,0.01529,305.18696
91.80000,4.58992,25763.37457,0.00000,0.01533,305.83884
92.00000,4.60002,25822.61264,0.00000,0.01538,306.54206
92.20000,4.60989,25875.77701,0.00000,0.01541,307.17318
92.40000,4.61993,25931.10800,0.00000,0.01545,307.83002
92.60000,4.62986,25985.92043,0.00000,0.01550,308.48070
92.80000,4.63990,26043.26308,0.00000,0.01554,309.16142
93.00000,4.65001,26097.40198,0.00000,0.01558,309.80410
93.20000,4.65993,26152.64952,0.00000,0.01562,310.45995
93.40000,4.66998,26208.33814,0.00000,0.01566,311.12103
93.60000,4.67990,26264.77182,0.00000,0.01570,311.79096
93.80000,4.69001,26321.59591,0.00000,0.01574,312.46553
94.00000,4.69993,26374.84372,0.00000,0.01578,313.09763
94.20000,4.70998,26424.92652,0.00000,0.01582,313.69217
94.40000,4.72008,26472.24665,0.00000,0.01586,314.25391
94.47400,4.72367,25230.20208,0.00000,0.01544,299.50951
94.47800,4.72415,23077.72338,0.00000,0.01467,273.95729
94.48200,4.72486,20356.60148,0.00000,0.01443,241.65465
94.48600,4.72576,17373.60805,0.00000,0.01500,206.24333
94.48800,4.72612,15857.89919,0.00000,0.01539,188.25024