File: scratch/college-stuff/ME Lab/ME lab Fall 2013/group8/group8.is_tens_RawData/Specimen_RawData_2.csv
Time,Extension,Load,Strain 2,Tensile strain,Tensile stress
(sec),(mm),(N),(mm/mm),(mm/mm),(MPa)
0.00000,0.00000,-0.45885,0.00000,0.00000,-0.00562
0.40000,0.01943,25.80133,0.00000,0.00000,0.31623
0.80000,0.04006,48.17985,0.00000,0.00000,0.59051
1.20000,0.06009,78.02426,0.00000,0.00001,0.95630
1.60000,0.08006,104.01558,0.00000,0.00000,1.27486
2.00000,0.09997,158.52028,0.00000,0.00000,1.94289
2.40000,0.11988,229.13516,0.00000,-0.00001,2.80838
2.80000,0.13991,318.16845,0.00000,-0.00002,3.89961
3.20000,0.15994,445.42537,0.00000,-0.00002,5.45933
3.60000,0.17997,604.78882,0.00000,-0.00002,7.41255
4.00000,0.20006,787.44953,0.00000,-0.00001,9.65132
4.40000,0.22009,979.33160,0.00000,-0.00001,12.00311
4.80000,0.24005,1221.99962,0.00000,0.00001,14.97736
5.20000,0.26002,1501.87919,0.00000,0.00005,18.40768
5.60000,0.27999,1781.07563,0.00000,0.00009,21.82964
6.00000,0.30008,2051.62130,0.00000,0.00013,25.14556
6.40000,0.31999,2334.36693,0.00000,0.00016,28.61101
6.80000,0.33984,2626.34344,0.00000,0.00021,32.18961
7.20000,0.35987,2926.03858,0.00000,0.00025,35.86280
7.60000,0.37984,3222.14626,0.00000,0.00030,39.49202
8.00000,0.39993,3518.87122,0.00000,0.00035,43.12881
8.40000,0.41996,3808.08935,0.00000,0.00039,46.67360
8.80000,0.44005,4096.08968,0.00000,0.00045,50.20345
9.20000,0.46008,4377.76819,0.00000,0.00049,53.65583
9.60000,0.48005,4651.63328,0.00000,0.00054,57.01244
10.00000,0.50002,4921.14201,0.00000,0.00059,60.31565
10.40000,0.51999,5184.68432,0.00000,0.00063,63.54574
10.80000,0.54002,5439.40440,0.00000,0.00067,66.66770
11.20000,0.55993,5679.44609,0.00000,0.00072,69.60976
11.60000,0.57990,5902.69752,0.00000,0.00075,72.34602
12.00000,0.59981,6084.98976,0.00000,0.00079,74.58028
12.40000,0.61984,6263.04075,0.00000,0.00082,76.76255
12.80000,0.63999,6437.59966,0.00000,0.00085,78.90202
13.20000,0.66002,6609.18579,0.00000,0.00088,81.00505
13.60000,0.68005,6785.74294,0.00000,0.00091,83.16901
14.00000,0.70013,6960.72578,0.00000,0.00094,85.31368
14.40000,0.72010,7138.75815,0.00000,0.00098,87.49572
14.80000,0.74007,7316.66237,0.00000,0.00100,89.67619
15.20000,0.75998,7493.91690,0.00000,0.00103,91.84870
15.60000,0.77995,7672.79342,0.00000,0.00107,94.04109
16.00000,0.79998,7853.60858,0.00000,0.00110,96.25724
16.40000,0.81989,8035.01606,0.00000,0.00113,98.48064
16.80000,0.83986,8216.96594,0.00000,0.00116,100.71070
17.20000,0.85995,8403.66408,0.00000,0.00120,102.99895
17.60000,0.87992,8586.48121,0.00000,0.00123,105.23964
18.00000,0.90001,8773.75379,0.00000,0.00126,107.53493
18.40000,0.92004,8959.77169,0.00000,0.00130,109.81485
18.80000,0.94007,9145.12873,0.00000,0.00133,112.08667
19.20000,0.96004,9334.40402,0.00000,0.00137,114.40651
19.60000,0.98001,9524.06228,0.00000,0.00140,116.73104
20.00000,0.99998,9709.54150,0.00000,0.00143,119.00435
20.40000,1.02001,9899.34057,0.00000,0.00147,121.33061
20.80000,1.03992,10090.02104,0.00000,0.00150,123.66768
21.20000,1.05989,10282.51350,0.00000,0.00153,126.02695
21.60000,1.07992,10474.78542,0.00000,0.00157,128.38352
22.00000,1.09989,10668.01399,0.00000,0.00160,130.75181
22.40000,1.11992,10864.58713,0.00000,0.00164,133.16110
22.80000,1.13995,11057.85072,0.00000,0.00168,135.52982
23.20000,1.16004,11250.82746,0.00000,0.00171,137.89502
23.60000,1.18007,11446.94611,0.00000,0.00175,140.29874
24.00000,1.20003,11642.72055,0.00000,0.00179,142.69824
24.40000,1.22000,11839.29816,0.00000,0.00182,145.10758
24.80000,1.23997,12039.01321,0.00000,0.00186,147.55537
25.20000,1.25994,12233.76021,0.00000,0.00190,149.94227
25.60000,1.27991,12431.66700,0.00000,0.00193,152.36791
26.00000,1.29988,12631.26135,0.00000,0.00197,154.81422
26.40000,1.31991,12833.28682,0.00000,0.00201,157.29033
26.80000,1.33994,13035.78019,0.00000,0.00205,159.77218
27.20000,1.35997,13236.69702,0.00000,0.00209,162.23470
27.60000,1.37994,13435.71097,0.00000,0.00213,164.67390
28.00000,1.40003,13637.64852,0.00000,0.00216,167.14894
28.40000,1.42012,13842.89563,0.00000,0.00220,169.66454
28.80000,1.44009,14042.39386,0.00000,0.00224,172.10967
29.20000,1.46006,14245.86028,0.00000,0.00228,174.60345
29.60000,1.47997,14449.39673,0.00000,0.00232,177.09808
30.00000,1.49994,14651.48479,0.00000,0.00236,179.57496
30.40000,1.51991,14854.98399,0.00000,0.00240,182.06913
30.80000,1.53994,15057.87224,0.00000,0.00244,184.55582
31.20000,1.55991,15263.22961,0.00000,0.00249,187.07277
31.60000,1.57988,15468.00733,0.00000,0.00252,189.58261
32.00000,1.59991,15676.07373,0.00000,0.00257,192.13276
32.40000,1.62000,15880.39845,0.00000,0.00261,194.63706
32.80000,1.64009,16085.41459,0.00000,0.00265,197.14982
33.20000,1.66006,16292.53179,0.00000,0.00269,199.68834
33.60000,1.68008,16498.63869,0.00000,0.00273,202.21448
34.00000,1.69999,16701.66552,0.00000,0.00278,204.70286
34.40000,1.71996,16910.37267,0.00000,0.00282,207.26087
34.80000,1.73993,17115.27556,0.00000,0.00286,209.77225
35.20000,1.75990,17320.36322,0.00000,0.00291,212.28589
35.60000,1.77999,17527.62347,0.00000,0.00296,214.82616
36.00000,1.79996,17732.37884,0.00000,0.00300,217.33573
36.40000,1.81993,17938.23242,0.00000,0.00305,219.85876
36.80000,1.83996,18146.38525,0.00000,0.00310,222.40997
37.20000,1.85993,18353.88392,0.00000,0.00314,224.95317
37.60000,1.88002,18559.19808,0.00000,0.00319,227.46959
38.00000,1.89999,18763.13537,0.00000,0.00324,229.96913
38.40000,1.92002,18967.01306,0.00000,0.00329,232.46794
38.80000,1.94005,19172.95456,0.00000,0.00334,234.99205
39.20000,1.95996,19375.51200,0.00000,0.00338,237.47468
39.60000,1.97999,19573.58271,0.00000,0.00343,239.90232
40.00000,1.99996,19770.30337,0.00000,0.00348,242.31342
40.40000,2.01993,19968.00452,0.00000,0.00353,244.73653
40.80000,2.03996,20167.03635,0.00000,0.00358,247.17595
41.20000,2.05999,20358.85453,0.00000,0.00364,249.52696
41.60000,2.07996,20551.27621,0.00000,0.00370,251.88536
42.00000,2.09993,20740.99183,0.00000,0.00376,254.21060
42.40000,2.12002,20924.79765,0.00000,0.00382,256.46340
42.80000,2.14005,21105.86911,0.00000,0.00388,258.68269
43.20000,2.16013,21283.59079,0.00000,0.00394,260.86093
43.60000,2.18004,21453.58026,0.00000,0.00401,262.94439
44.00000,2.20001,21617.88493,0.00000,0.00408,264.95818
44.40000,2.21998,21776.78943,0.00000,0.00416,266.90578
44.80000,2.23995,21928.02429,0.00000,0.00424,268.75938
45.20000,2.25992,22072.47019,0.00000,0.00432,270.52977
45.60000,2.27995,22210.33573,0.00000,0.00440,272.21951
46.00000,2.29992,22342.87709,0.00000,0.00449,273.84400
46.40000,2.31995,22464.23215,0.00000,0.00459,275.33138
46.80000,2.33998,22572.61425,0.00000,0.00469,276.65976
47.20000,2.36001,22673.67244,0.00000,0.00480,277.89837
47.60000,2.38004,22761.66081,0.00000,0.00492,278.97679
48.00000,2.40007,22839.35249,0.00000,0.00505,279.92902
48.40000,2.42004,22910.75438,0.00000,0.00519,280.80415
48.80000,2.44001,22971.36188,0.00000,0.00534,281.54698
49.20000,2.45998,23024.01811,0.00000,0.00550,282.19236
49.60000,2.47989,23070.63490,0.00000,0.00566,282.76371
50.00000,2.49992,23112.27173,0.00000,0.00584,283.27403
50.40000,2.51995,23151.05945,0.00000,0.00603,283.74943
50.80000,2.53998,23185.96840,0.00000,0.00622,284.17729
51.20000,2.55995,23218.97149,0.00000,0.00642,284.58179
51.60000,2.57998,23246.59973,0.00000,0.00661,284.92042
52.00000,2.60007,23270.86478,0.00000,0.00682,285.21782
52.40000,2.62010,23295.12835,0.00000,0.00703,285.51520
52.80000,2.64006,23316.91682,0.00000,0.00724,285.78225
53.20000,2.66009,23337.36867,0.00000,0.00746,286.03292
53.60000,2.68006,23353.19072,0.00000,0.00767,286.22684
54.00000,2.69997,23370.76962,0.00000,0.00789,286.44230
54.40000,2.71994,23385.43236,0.00000,0.00811,286.62201
54.80000,2.73985,23399.10418,0.00000,0.00835,286.78958
55.20000,2.76000,23417.02431,0.00000,0.00857,287.00921
55.60000,2.77997,23431.08058,0.00000,0.00880,287.18149
56.00000,2.80000,23445.62262,0.00000,0.00903,287.35973
56.40000,2.81997,23460.51931,0.00000,0.00927,287.54231
56.80000,2.84006,23472.51326,0.00000,0.00950,287.68931
57.20000,2.86003,23483.28382,0.00000,0.00973,287.82132
57.60000,2.88012,23495.63539,0.00000,0.00996,287.97270
58.00000,2.90009,23509.07475,0.00000,0.01020,288.13742
58.40000,2.92000,23519.95856,0.00000,0.01043,288.27082
58.80000,2.93997,23530.86621,0.00000,0.01067,288.40451
59.20000,2.95988,23539.64299,0.00000,0.01090,288.51208
59.60000,2.97991,23551.54008,0.00000,0.01114,288.65790
60.00000,2.99988,23563.80373,0.00000,0.01138,288.80821
60.40000,3.01997,23575.78725,0.00000,0.01161,288.95508
60.80000,3.04006,23586.35068,0.00000,0.01184,289.08455
61.20000,3.06009,23595.74139,0.00000,0.01208,289.19965
61.60000,3.08006,23605.53741,0.00000,0.01232,289.31971
62.00000,3.10009,23615.29917,0.00000,0.01256,289.43936
62.40000,3.12005,23624.03870,0.00000,0.01279,289.54647
62.80000,3.14008,23633.90476,0.00000,0.01302,289.66739
63.20000,3.16005,23642.90804,0.00000,0.01325,289.77774
63.60000,3.17996,23651.78764,0.00000,0.01349,289.88657
64.00000,3.19987,23662.58055,0.00000,0.01372,290.01886
64.40000,3.21984,23668.13123,0.00000,0.01396,290.08689
64.80000,3.23987,23679.07763,0.00000,0.01419,290.22105
65.20000,3.25996,23691.18780,0.00000,0.01443,290.36948
65.60000,3.28005,23703.30691,0.00000,0.01466,290.51802
66.00000,3.30002,23708.97681,0.00000,0.01488,290.58751
66.40000,3.32011,23720.95436,0.00000,0.01511,290.73431
66.80000,3.34002,23728.19185,0.00000,0.01534,290.82302
67.20000,3.36005,23738.45875,0.00000,0.01557,290.94885
67.60000,3.38008,23746.31166,0.00000,0.01580,291.04510
68.00000,3.40005,23754.48942,0.00000,0.01603,291.14533
68.40000,3.41996,23762.73125,0.00000,0.01625,291.24635
68.80000,3.43987,23772.88789,0.00000,0.01648,291.37083
69.20000,3.45984,23781.12078,0.00000,0.01670,291.47174
69.60000,3.47993,23789.66510,0.00000,0.01693,291.57646
70.00000,3.50008,23801.01085,0.00000,0.01715,291.71552
70.40000,3.52005,23810.39560,0.00000,0.01738,291.83054
70.80000,3.54014,23821.15424,0.00000,0.01760,291.96241
71.20000,3.56005,23828.49902,0.00000,0.01782,292.05243
71.60000,3.58007,23837.25494,0.00000,0.01804,292.15974
72.00000,3.60004,23845.20620,0.00000,0.01826,292.25720
72.40000,3.62001,23854.58201,0.00000,0.01849,292.37211
72.80000,3.64004,23863.30962,0.00000,0.01871,292.47908
73.20000,3.65995,23868.82752,0.00000,0.01893,292.54671
73.60000,3.67992,23876.94269,0.00000,0.01914,292.64617
74.00000,3.69995,23888.33910,0.00000,0.01936,292.78585
74.40000,3.71998,23896.84319,0.00000,0.01959,292.89008
74.80000,3.74001,23905.63041,0.00000,0.01981,292.99778
75.20000,3.76010,23915.51435,0.00000,0.02003,293.11892
75.60000,3.78007,23924.70837,0.00000,0.02024,293.23161
76.00000,3.80004,23934.07226,0.00000,0.02045,293.34638
76.40000,3.82001,23941.34849,0.00000,0.02067,293.43556
76.80000,3.84004,23947.68447,0.00000,0.02089,293.51321
77.20000,3.86007,23956.91723,0.00000,0.02110,293.62638
77.60000,3.88004,23965.31552,0.00000,0.02132,293.72931
78.00000,3.89995,23972.42785,0.00000,0.02153,293.81648
78.40000,3.91992,23980.68756,0.00000,0.02174,293.91771
78.80000,3.93995,23988.61498,0.00000,0.02196,294.01488
79.20000,3.95992,23995.57531,0.00000,0.02217,294.10019
79.60000,3.98007,24007.51710,0.00000,0.02238,294.24655
80.00000,4.00004,24015.52349,0.00000,0.02259,294.34468
80.40000,4.02007,24024.37925,0.00000,0.02280,294.45322
80.80000,4.04010,24031.45283,0.00000,0.02302,294.53992
81.20000,4.06001,24039.57993,0.00000,0.02322,294.63953
81.60000,4.08003,24047.31959,0.00000,0.02343,294.73439
82.00000,4.10000,24052.84345,0.00000,0.02364,294.80209
82.40000,4.11997,24060.38642,0.00000,0.02385,294.89454
82.80000,4.13994,24069.34351,0.00000,0.02406,295.00432
83.20000,4.15991,24078.12625,0.00000,0.02426,295.11197
83.60000,4.17988,24086.18927,0.00000,0.02446,295.21079
84.00000,4.19991,24094.69336,0.00000,0.02467,295.31502
84.40000,4.22000,24103.59532,0.00000,0.02488,295.42413
84.80000,4.24009,24114.71903,0.00000,0.02509,295.56046
85.20000,4.26006,24122.75523,0.00000,0.02529,295.65896
85.60000,4.28009,24130.02849,0.00000,0.02550,295.74810
86.00000,4.30006,24138.15111,0.00000,0.02570,295.84766
86.40000,4.32003,24144.29486,0.00000,0.02591,295.92296
86.80000,4.33994,24150.52652,0.00000,0.02612,295.99933
87.20000,4.36003,24157.23950,0.00000,0.02632,296.08161
87.60000,4.38000,24166.54080,0.00000,0.02653,296.19561
88.00000,4.39985,24173.13159,0.00000,0.02673,296.27639
88.40000,4.41994,24182.73389,0.00000,0.02694,296.39408
88.80000,4.43991,24188.97450,0.00000,0.02713,296.47057
89.20000,4.46000,24198.18640,0.00000,0.02734,296.58347
89.60000,4.48009,24205.91265,0.00000,0.02754,296.67817
90.00000,4.50006,24212.51833,0.00000,0.02774,296.75913
90.40000,4.52009,24222.24879,0.00000,0.02794,296.87839
90.80000,4.54000,24226.71318,0.00000,0.02814,296.93311
91.20000,4.55996,24232.24747,0.00000,0.02834,297.00094
91.60000,4.57999,24237.93077,0.00000,0.02854,297.07060
92.00000,4.60002,24246.39016,0.00000,0.02874,297.17428
92.40000,4.61993,24253.85416,0.00000,0.02894,297.26576
92.80000,4.63996,24261.80542,0.00000,0.02915,297.36322
93.20000,4.65993,24268.88198,0.00000,0.02935,297.44995
93.60000,4.67996,24276.21931,0.00000,0.02956,297.53988
94.00000,4.69999,24283.98728,0.00000,0.02975,297.63509
94.40000,4.72008,24292.88775,0.00000,0.02996,297.74418
94.80000,4.73999,24300.25637,0.00000,0.03016,297.83449
95.20000,4.76008,24307.11538,0.00000,0.03036,297.91856
95.60000,4.77993,24313.20697,0.00000,0.03056,297.99322
96.00000,4.79996,24321.54715,0.00000,0.03076,298.09544
96.40000,4.81999,24323.71974,0.00000,0.03097,298.12207
96.80000,4.84008,24331.91687,0.00000,0.03116,298.22253
97.20000,4.86005,24340.23470,0.00000,0.03136,298.32448
97.60000,4.87996,24347.26506,0.00000,0.03156,298.41065
98.00000,4.89993,24356.34285,0.00000,0.03176,298.52191
98.40000,4.91990,24362.33163,0.00000,0.03196,298.59531
98.80000,4.93999,24368.02536,0.00000,0.03216,298.66509
99.20000,4.96008,24376.40429,0.00000,0.03237,298.76779
99.60000,4.98011,24384.91136,0.00000,0.03256,298.87206
100.00000,5.00008,24389.23568,0.00000,0.03276,298.92506
100.40000,5.02005,24395.12461,0.00000,0.03295,298.99724
100.80000,5.04002,24400.75576,0.00000,0.03315,299.06625
101.20000,5.05998,24407.07237,0.00000,0.03334,299.14367
101.60000,5.08001,24413.52904,0.00000,0.03354,299.22281
102.00000,5.09998,24419.20638,0.00000,0.03373,299.29239
102.40000,5.11995,24427.14125,0.00000,0.03392,299.38964
102.80000,5.13986,24433.79462,0.00000,0.03411,299.47119
103.20000,5.15989,24441.13046,0.00000,0.03431,299.56110
103.60000,5.17998,24447.38299,0.00000,0.03450,299.63774
104.00000,5.20007,24453.18401,0.00000,0.03469,299.70884
104.40000,5.22010,24459.19365,0.00000,0.03488,299.78249
104.80000,5.24007,24465.59072,0.00000,0.03507,299.86090
105.20000,5.25998,24472.23663,0.00000,0.03527,299.94235
105.60001,5.28001,24477.51164,0.00000,0.03546,300.00701
106.00001,5.29998,24483.06084,0.00000,0.03565,300.07502
106.40001,5.32001,24488.34628,0.00000,0.03584,300.13980
106.80001,5.33998,24494.59434,0.00000,0.03603,300.21638
107.20001,5.35995,24499.76951,0.00000,0.03623,300.27981
107.60001,5.37992,24507.13068,0.00000,0.03642,300.37003
108.00001,5.39989,24513.12393,0.00000,0.03661,300.44349
108.40001,5.41998,24520.46275,0.00000,0.03680,300.53343
108.80001,5.44007,24525.85250,0.00000,0.03699,300.59949
109.20001,5.46016,24533.18983,0.00000,0.03718,300.68942
109.60001,5.48013,24537.39345,0.00000,0.03737,300.74094
110.00001,5.49998,24544.32547,0.00000,0.03756,300.82591
110.40001,5.52001,24549.68393,0.00000,0.03775,300.89158
110.80001,5.53997,24553.18123,0.00000,0.03794,300.93445
111.20001,5.56000,24557.98686,0.00000,0.03812,300.99335
111.60001,5.57991,24562.68221,0.00000,0.03831,301.05089
112.00001,5.59994,24572.31581,0.00000,0.03850,301.16897
112.40001,5.61997,24576.70867,0.00000,0.03868,301.22281
112.80001,5.63994,24581.15518,0.00000,0.03887,301.27731
113.20001,5.65997,24587.64166,0.00000,0.03905,301.35681
113.60001,5.68006,24592.83173,0.00000,0.03924,301.42042
114.00001,5.70009,24597.86683,0.00000,0.03942,301.48213
114.40001,5.72006,24602.51898,0.00000,0.03960,301.53915
114.80001,5.74003,24607.14430,0.00000,0.03978,301.59584
115.20001,5.76000,24612.97214,0.00000,0.03996,301.66727
115.60001,5.77997,24615.28927,0.00000,0.04014,301.69567
116.00001,5.80000,24620.79227,0.00000,0.04032,301.76312
116.40001,5.81997,24624.50415,0.00000,0.04049,301.80861
116.80001,5.84000,24631.09642,0.00000,0.04067,301.88941
117.20001,5.85991,24637.27891,0.00000,0.04085,301.96518
117.60001,5.87994,24642.42131,0.00000,0.04103,302.02821
118.00001,5.90003,24647.59797,0.00000,0.04120,302.09166
118.40001,5.92006,24652.76420,0.00000,0.04139,302.15498
118.80001,5.94015,24659.01375,0.00000,0.04157,302.23157
119.20001,5.96012,24663.76275,0.00000,0.04175,302.28978
119.60001,5.98003,24668.84404,0.00000,0.04192,302.35206
120.00001,6.00006,24673.18475,0.00000,0.04209,302.40526
120.40001,6.01990,24675.92806,0.00000,0.04227,302.43888
120.80001,6.03987,24680.38797,0.00000,0.04245,302.49355
121.20001,6.05990,24684.77339,0.00000,0.04262,302.54730
121.60001,6.07993,24690.62507,0.00000,0.04281,302.61902
122.00001,6.09990,24697.47066,0.00000,0.04298,302.70292
122.40001,6.11993,24704.48613,0.00000,0.04316,302.78890
122.80001,6.13996,24708.66889,0.00000,0.04335,302.84017
123.20001,6.16005,24711.31980,0.00000,0.04353,302.87266
123.60001,6.18014,24717.04036,0.00000,0.04370,302.94277
124.00001,6.20011,24723.47468,0.00000,0.04388,303.02164
124.40001,6.22008,24727.70512,0.00000,0.04406,303.07349
124.80001,6.24005,24731.37081,0.00000,0.04424,303.11841
125.20001,6.25990,24732.90861,0.00000,0.04442,303.13726
125.60001,6.27993,24736.89169,0.00000,0.04460,303.18608
126.00001,6.29990,24743.41244,0.00000,0.04478,303.26600
126.40001,6.31999,24749.08382,0.00000,0.04495,303.33551
126.80001,6.33996,24753.05647,0.00000,0.04512,303.38420
127.20001,6.35999,24758.62354,0.00000,0.04530,303.45244
127.60001,6.38008,24765.85507,0.00000,0.04548,303.54107
128.00001,6.40005,24768.15432,0.00000,0.04565,303.56925
128.40001,6.42020,24772.88693,0.00000,0.04583,303.62725
128.80001,6.44017,24776.56752,0.00000,0.04601,303.67236
129.20001,6.46007,24781.37165,0.00000,0.04618,303.73125
129.60001,6.47998,24785.27129,0.00000,0.04636,303.77904
130.00001,6.49995,24787.17864,0.00000,0.04653,303.80242
130.40001,6.51986,24789.52408,0.00000,0.04671,303.83117
130.80001,6.53995,24794.57557,0.00000,0.04688,303.89308
131.20001,6.55998,24801.93824,0.00000,0.04706,303.98332
131.60001,6.57995,24807.59919,0.00000,0.04724,304.05270
132.00001,6.60004,24813.58945,0.00000,0.04742,304.12612
132.40001,6.62001,24815.89168,0.00000,0.04760,304.15434
132.80001,6.63998,24818.32951,0.00000,0.04777,304.18422
133.20001,6.66007,24824.53883,0.00000,0.04794,304.26032
133.60001,6.68010,24827.61592,0.00000,0.04812,304.29804
134.00001,6.70007,24830.56337,0.00000,0.04830,304.33416
134.40001,6.72004,24834.84745,0.00000,0.04847,304.38667
134.80001,6.73989,24834.79381,0.00000,0.04865,304.38601
135.20001,6.75986,24838.95272,0.00000,0.04883,304.43699
135.60001,6.77989,24841.91507,0.00000,0.04900,304.47329
136.00001,6.79998,24847.41062,0.00000,0.04917,304.54065
136.40001,6.82001,24853.10435,0.00000,0.04935,304.61043
136.80001,6.84004,24857.24986,0.00000,0.04953,304.66124
137.20001,6.86001,24861.11671,0.00000,0.04971,304.70864
137.60001,6.88004,24863.54709,0.00000,0.04989,304.73842
138.00001,6.90007,24867.70749,0.00000,0.05007,304.78942
138.40001,6.92010,24870.12446,0.00000,0.05024,304.81904
138.80001,6.94007,24875.70494,0.00000,0.05043,304.88744
139.20001,6.95997,24876.11324,0.00000,0.05060,304.89244
139.60001,6.97988,24878.76713,0.00000,0.05078,304.92497
140.00001,6.99985,24882.52372,0.00000,0.05095,304.97101
140.40001,7.01988,24887.73912,0.00000,0.05113,305.03493
140.80001,7.03997,24891.87866,0.00000,0.05131,305.08567
141.20001,7.06000,24895.81704,0.00000,0.05148,305.13394
141.60001,7.07997,24900.73591,0.00000,0.05166,305.19423
142.00001,7.10000,24905.06768,0.00000,0.05184,305.24732
142.40001,7.11997,24907.63813,0.00000,0.05201,305.27882
142.80001,7.14006,24909.17742,0.00000,0.05219,305.29769
143.20001,7.16009,24911.77917,0.00000,0.05236,305.32958
143.60001,7.18000,24915.30329,0.00000,0.05253,305.37277
144.00001,7.19991,24918.76334,0.00000,0.05271,305.41518
144.40001,7.21988,24922.07736,0.00000,0.05288,305.45580
144.80001,7.23985,24924.77596,0.00000,0.05305,305.48887
145.20001,7.25994,24929.30889,0.00000,0.05322,305.54443
145.60001,7.28003,24934.09067,0.00000,0.05339,305.60304
146.00001,7.30000,24938.43585,0.00000,0.05357,305.65629
146.40001,7.32003,24943.33088,0.00000,0.05375,305.71629
146.80001,7.34000,24945.52583,0.00000,0.05392,305.74319
147.20001,7.36003,24947.59113,0.00000,0.05409,305.76850
147.60001,7.38006,24950.07664,0.00000,0.05427,305.79897
148.00001,7.40003,24952.04061,0.00000,0.05444,305.82304
148.40001,7.42006,24954.86438,0.00000,0.05461,305.85765
148.80001,7.43997,24956.50798,0.00000,0.05479,305.87779
149.20001,7.45994,24960.67882,0.00000,0.05496,305.92891
149.60001,7.47990,24963.59646,0.00000,0.05513,305.96467
150.00001,7.49993,24964.24168,0.00000,0.05531,305.97258
150.40001,7.51996,24968.14728,0.00000,0.05548,306.02045
150.80001,7.53999,24973.74415,0.00000,0.05566,306.08905
151.20001,7.56002,24978.84035,0.00000,0.05583,306.15151
151.60001,7.57999,24979.59137,0.00000,0.05600,306.16071
152.00001,7.60002,24981.60750,0.00000,0.05617,306.18542
152.40001,7.61999,24981.47935,0.00000,0.05633,306.18385
152.80001,7.64002,24985.65167,0.00000,0.05651,306.23499
153.20001,7.66005,24987.77956,0.00000,0.05668,306.26107
153.60001,7.68002,24991.13977,0.00000,0.05685,306.30226
154.00001,7.69999,24993.04563,0.00000,0.05702,306.32561
154.40001,7.71996,24996.01394,0.00000,0.05719,306.36200
154.80001,7.73987,24997.94960,0.00000,0.05736,306.38572
155.20001,7.75996,25001.29640,0.00000,0.05753,306.42674
155.60001,7.77999,25002.33054,0.00000,0.05770,306.43941
156.00001,7.80002,25007.78139,0.00000,0.05786,306.50622
156.40001,7.82005,25009.53972,0.00000,0.05803,306.52777
156.80001,7.84002,25013.24415,0.00000,0.05820,306.57318
157.20001,7.86005,25015.28263,0.00000,0.05836,306.59816
157.60001,7.88002,25016.24227,0.00000,0.05853,306.60992
158.00001,7.90010,25019.71424,0.00000,0.05870,306.65248
158.40001,7.92007,25021.56496,0.00000,0.05887,306.67516
158.80001,7.93998,25024.02663,0.00000,0.05903,306.70533
159.20001,7.95995,25026.42572,0.00000,0.05919,306.73474
159.60001,7.97992,25026.64328,0.00000,0.05936,306.73740
160.00001,7.99989,25029.66821,0.00000,0.05953,306.77448
160.40001,8.01998,25034.16240,0.00000,0.05969,306.82956
160.80001,8.04007,25037.34827,0.00000,0.05986,306.86861
161.20001,8.06004,25038.93971,0.00000,0.06003,306.88811
161.60001,8.08007,25042.29248,0.00000,0.06019,306.92921
162.00001,8.10004,25044.67964,0.00000,0.06036,306.95846
162.40001,8.12001,25045.68100,0.00000,0.06052,306.97074
162.80001,8.14010,25047.63603,0.00000,0.06069,306.99470
163.20001,8.16007,25048.89369,0.00000,0.06085,307.01011
163.60001,8.17992,25050.47619,0.00000,0.06102,307.02951
164.00001,8.19995,25053.53391,0.00000,0.06119,307.06699
164.40001,8.21986,25053.38490,0.00000,0.06135,307.06516
164.80001,8.23995,25057.04761,0.00000,0.06151,307.11005
165.20001,8.25998,25060.54640,0.00000,0.06168,307.15293
165.60001,8.28007,25065.60683,0.00000,0.06185,307.21496
166.00001,8.30004,25067.66617,0.00000,0.06202,307.24020
166.40001,8.32007,25069.46921,0.00000,0.06218,307.26230
166.80001,8.33998,25071.53451,0.00000,0.06235,307.28761
167.20001,8.36001,25073.62068,0.00000,0.06252,307.31318
167.60001,8.38009,25075.65022,0.00000,0.06269,307.33805
168.00001,8.40007,25077.60227,0.00000,0.06285,307.36198
168.40001,8.41998,25079.02086,0.00000,0.06302,307.37936
168.80001,8.43988,25079.89109,0.00000,0.06319,307.39003
169.20001,8.45991,25082.65674,0.00000,0.06336,307.42393
169.60001,8.47988,25085.13629,0.00000,0.06352,307.45432
170.00001,8.50003,25088.22381,0.00000,0.06369,307.49216
170.40001,8.52006,25092.45574,0.00000,0.06386,307.54403
170.80001,8.54009,25095.11113,0.00000,0.06403,307.57657
171.20001,8.56006,25096.75026,0.00000,0.06421,307.59666
171.60001,8.58003,25097.76354,0.00000,0.06437,307.60908
172.00001,8.60000,25097.94235,0.00000,0.06454,307.61127
172.40001,8.62009,25099.85566,0.00000,0.06471,307.63472
172.80001,8.64006,25101.87924,0.00000,0.06488,307.65953
173.20001,8.65997,25101.45009,0.00000,0.06505,307.65427
173.60001,8.67988,25102.46933,0.00000,0.06523,307.66676
174.00001,8.69985,25105.69394,0.00000,0.06539,307.70628
174.40001,8.71988,25109.09140,0.00000,0.06556,307.74792
174.80001,8.74003,25113.03127,0.00000,0.06573,307.79621
175.20001,8.76012,25115.27240,0.00000,0.06591,307.82368
175.60001,8.78009,25115.65983,0.00000,0.06608,307.82843
176.00001,8.80012,25119.01855,0.00000,0.06624,307.86959
176.40001,8.82003,25120.23151,0.00000,0.06642,307.88446
176.80001,8.84000,25120.06760,0.00000,0.06659,307.88245
177.20001,8.86009,25119.26591,0.00000,0.06676,307.87263
177.60001,8.87999,25119.66228,0.00000,0.06693,307.87748
178.00001,8.89990,25123.48294,0.00000,0.06710,307.92431
178.40001,8.91987,25124.99094,0.00000,0.06727,307.94279
178.80001,8.93984,25127.06220,0.00000,0.06745,307.96818
179.20001,8.95993,25128.57020,0.00000,0.06761,307.98666
179.60001,8.98002,25133.43990,0.00000,0.06779,308.04635
180.00001,9.00011,25135.10287,0.00000,0.06796,308.06673
180.40001,9.02014,25136.34562,0.00000,0.06814,308.08196
180.80001,9.04011,25136.93273,0.00000,0.06831,308.08916
181.20001,9.06002,25138.79538,0.00000,0.06848,308.11199
181.60001,9.07999,25140.23483,0.00000,0.06866,308.12963
182.00001,9.10002,25139.80567,0.00000,0.06883,308.12437
182.40001,9.11999,25140.48815,0.00000,0.06901,308.13273
182.80001,9.13996,25142.53557,0.00000,0.06918,308.15783
183.20001,9.15993,25146.28172,0.00000,0.06936,308.20374
183.60001,9.17990,25148.94307,0.00000,0.06954,308.23636
184.00001,9.19999,25149.68216,0.00000,0.06971,308.24542
184.40001,9.22002,25149.86396,0.00000,0.06989,308.24765
184.80001,9.24017,25154.18530,0.00000,0.07007,308.30061
185.20001,9.26014,25155.16281,0.00000,0.07025,308.31259
185.60001,9.28011,25154.76346,0.00000,0.07043,308.30770
186.00001,9.30008,25155.52640,0.00000,0.07060,308.31705
186.40001,9.31999,25153.95880,0.00000,0.07078,308.29784
186.80001,9.34002,25154.86181,0.00000,0.07096,308.30890
187.20001,9.35998,25155.80952,0.00000,0.07113,308.32052
187.60001,9.38001,25157.77349,0.00000,0.07131,308.34459
188.00001,9.39992,25159.47521,0.00000,0.07149,308.36545
188.40001,9.41995,25163.51342,0.00000,0.07167,308.41494
188.80001,9.43992,25164.43431,0.00000,0.07184,308.42623
189.20001,9.46001,25165.25686,0.00000,0.07203,308.43631
189.60001,9.48004,25166.79168,0.00000,0.07220,308.45512
190.00001,9.50013,25168.18345,0.00000,0.07238,308.47218
190.40001,9.52004,25168.67816,0.00000,0.07256,308.47824
190.80001,9.54001,25169.05665,0.00000,0.07274,308.48288
191.20001,9.55998,25167.60826,0.00000,0.07291,308.46513
191.60001,9.58001,25168.11788,0.00000,0.07310,308.47138
192.00001,9.59992,25170.21596,0.00000,0.07327,308.49709
192.40001,9.61995,25172.51372,0.00000,0.07346,308.52525
192.80001,9.63998,25173.97404,0.00000,0.07363,308.54315
193.20001,9.65995,25174.44193,0.00000,0.07381,308.54889
193.60001,9.67998,25176.61452,0.00000,0.07399,308.57551
194.00001,9.69995,25177.00493,0.00000,0.07417,308.58030
194.40001,9.72004,25178.55465,0.00000,0.07436,308.59929
194.80001,9.74019,25179.46362,0.00000,0.07454,308.61043
195.20001,9.76010,25180.80771,0.00000,0.07472,308.62691
195.60001,9.78007,25179.52323,0.00000,0.07490,308.61116
196.00001,9.79998,25180.15802,0.00000,0.07508,308.61895
196.40001,9.81995,25178.91526,0.00000,0.07526,308.60371
196.80001,9.83997,25180.29511,0.00000,0.07544,308.62063
197.20001,9.86000,25182.92964,0.00000,0.07562,308.65292
197.60001,9.87991,25183.52568,0.00000,0.07580,308.66022
198.00001,9.89994,25185.18567,0.00000,0.07598,308.68057
198.40001,9.91991,25184.37803,0.00000,0.07616,308.67067
198.80001,9.94000,25186.20789,0.00000,0.07634,308.69310
199.20001,9.96003,25186.70261,0.00000,0.07653,308.69916
199.60001,9.98012,25187.53409,0.00000,0.07671,308.70935
200.00001,10.00009,25187.51919,0.00000,0.07689,308.70917
200.40001,10.02006,25187.49535,0.00000,0.07707,308.70887
200.80001,10.03991,25187.12878,0.00000,0.07725,308.70438
201.20001,10.05994,25188.53247,0.00000,0.07744,308.72159
201.60001,10.07991,25187.25395,0.00000,0.07762,308.70592
202.00001,10.09994,25189.00335,0.00000,0.07780,308.72736
202.40001,10.11997,25189.90338,0.00000,0.07799,308.73839
202.80001,10.13988,25190.41598,0.00000,0.07817,308.74467
203.20001,10.15997,25192.79122,0.00000,0.07835,308.77378
203.60001,10.17994,25190.89580,0.00000,0.07854,308.75055
204.00001,10.20009,25192.23392,0.00000,0.07872,308.76695
204.40001,10.22012,25194.72539,0.00000,0.07890,308.79749
204.80001,10.24003,25195.76252,0.00000,0.07908,308.81020
205.20001,10.26000,25194.53168,0.00000,0.07926,308.79512
205.60001,10.27997,25193.96842,0.00000,0.07945,308.78821
206.00001,10.29994,25193.88199,0.00000,0.07963,308.78715
206.40001,10.31991,25194.26644,0.00000,0.07982,308.79186
206.80001,10.33999,25193.79854,0.00000,0.08000,308.78613
207.20001,10.35996,25194.71645,0.00000,0.08019,308.79738
207.60001,10.37999,25197.91126,0.00000,0.08037,308.83654
208.00001,10.39990,25195.85788,0.00000,0.08056,308.81137
208.40001,10.41987,25196.26915,0.00000,0.08074,308.81641
208.80001,10.44002,25197.57450,0.00000,0.08093,308.83241
209.20001,10.46011,25198.36426,0.00000,0.08111,308.84209
209.60001,10.48002,25198.34638,0.00000,0.08130,308.84187
210.00001,10.49999,25199.46694,0.00000,0.08148,308.85560
210.40001,10.52002,25199.54145,0.00000,0.08167,308.85652
210.80001,10.53999,25197.46721,0.00000,0.08185,308.83109
211.20001,10.55996,25196.37942,0.00000,0.08204,308.81776
211.60001,10.57999,25197.19005,0.00000,0.08223,308.82770
212.00001,10.60002,25198.11690,0.00000,0.08241,308.83906
212.40001,10.61993,25196.81156,0.00000,0.08260,308.82306
212.80001,10.63996,25199.08547,0.00000,0.08278,308.85093
213.20001,10.65999,25200.22094,0.00000,0.08297,308.86485
213.60001,10.68008,25201.69020,0.00000,0.08316,308.88285
214.00001,10.70005,25200.81997,0.00000,0.08334,308.87219
214.40001,10.72008,25201.07329,0.00000,0.08353,308.87529
214.80001,10.74005,25199.56529,0.00000,0.08373,308.85681
215.20001,10.76002,25200.33419,0.00000,0.08391,308.86623
215.60001,10.77992,25200.46532,0.00000,0.08411,308.86784
216.00001,10.79989,25197.48509,0.00000,0.08429,308.83131
216.40001,10.81998,25197.87550,0.00000,0.08448,308.83610
216.80001,10.83995,25197.49105,0.00000,0.08467,308.83139
217.20001,10.85998,25198.87984,0.00000,0.08486,308.84841
217.60001,10.88001,25201.48754,0.00000,0.08505,308.88037
218.00001,10.90004,25201.11501,0.00000,0.08523,308.87580
218.40001,10.92001,25199.35966,0.00000,0.08542,308.85429
218.80001,10.94010,25200.85573,0.00000,0.08561,308.87263
219.20001,10.96013,25201.21634,0.00000,0.08581,308.87705
219.60001,10.98004,25198.48347,0.00000,0.08600,308.84355
220.00001,11.00001,25197.05892,0.00000,0.08619,308.82609
220.40001,11.01992,25195.24992,0.00000,0.08638,308.80392
220.80001,11.03995,25196.81454,0.00000,0.08657,308.82309
221.20001,11.05998,25194.72837,0.00000,0.08676,308.79753
221.60001,11.07995,25195.63138,0.00000,0.08695,308.80859
222.00001,11.09998,25196.52843,0.00000,0.08713,308.81959
222.40001,11.12001,25199.88120,0.00000,0.08732,308.86068
222.80001,11.13998,25198.16458,0.00000,0.08751,308.83964
223.20001,11.16013,25197.62516,0.00000,0.08771,308.83303
223.60001,11.18004,25196.01285,0.00000,0.08789,308.81327
224.00001,11.20007,25197.13342,0.00000,0.08809,308.82700
224.40001,11.22004,25196.31088,0.00000,0.08828,308.81692
224.80001,11.24001,25195.07110,0.00000,0.08848,308.80173
225.20001,11.25998,25193.66145,0.00000,0.08867,308.78445
225.60001,11.27989,25190.38022,0.00000,0.08887,308.74423
226.00001,11.29991,25193.31872,0.00000,0.08907,308.78025
226.40001,11.31994,25194.71645,0.00000,0.08927,308.79738
226.80001,11.33997,25195.49429,0.00000,0.08947,308.80691
227.20001,11.35994,25194.60618,0.00000,0.08967,308.79603
227.60001,11.37997,25196.57910,0.00000,0.08987,308.82021
228.00001,11.40000,25193.84921,0.00000,0.09007,308.78675
228.40001,11.42003,25193.43495,0.00000,0.09027,308.78167
228.80001,11.44012,25191.70642,0.00000,0.09048,308.76049
229.20001,11.46009,25191.16700,0.00000,0.09068,308.75388
229.60001,11.48006,25190.95838,0.00000,0.09088,308.75132
230.00001,11.49997,25190.74678,0.00000,0.09108,308.74873
230.40001,11.51982,25187.21223,0.00000,0.09129,308.70540
230.80001,11.53991,25186.31518,0.00000,0.09149,308.69441
231.20001,11.55994,25188.68744,0.00000,0.09170,308.72349
231.60001,11.57997,25190.12988,0.00000,0.09190,308.74116
232.00001,11.60000,25189.70370,0.00000,0.09211,308.73594
232.40001,11.62003,25186.88440,0.00000,0.09231,308.70139
232.80001,11.64006,25185.85324,0.00000,0.09252,308.68875
233.20001,11.66003,25186.42843,0.00000,0.09273,308.69580
233.60001,11.68012,25184.66711,0.00000,0.09294,308.67421
234.00001,11.70015,25182.75976,0.00000,0.09314,308.65083
234.40001,11.72000,25180.12226,0.00000,0.09335,308.61851
234.80001,11.73985,25179.82423,0.00000,0.09356,308.61485
235.20001,11.75988,25179.79145,0.00000,0.09377,308.61445
235.60001,11.77985,25179.01659,0.00000,0.09398,308.60496
236.00001,11.79993,25179.35634,0.00000,0.09419,308.60912
236.40001,11.82002,25180.42028,0.00000,0.09440,308.62216
236.80001,11.83999,25179.97921,0.00000,0.09461,308.61675
237.20001,11.86008,25179.75569,0.00000,0.09482,308.61401
237.60001,11.88005,25176.77844,0.00000,0.09504,308.57752
238.00001,11.90002,25174.63863,0.00000,0.09524,308.55130
238.40001,11.92011,25174.68631,0.00000,0.09545,308.55188
238.80001,11.94008,25173.36905,0.00000,0.09566,308.53574
239.20001,11.95993,25171.77165,0.00000,0.09587,308.51616
239.60001,11.97996,25171.99218,0.00000,0.09609,308.51886
240.00001,11.99987,25170.21000,0.00000,0.09631,308.49702
240.40001,12.01984,25170.03417,0.00000,0.09653,308.49486
240.80001,12.03999,25170.15040,0.00000,0.09674,308.49629
241.20001,12.06008,25168.33246,0.00000,0.09697,308.47401
241.60001,12.08011,25170.47226,0.00000,0.09719,308.50023
242.00001,12.10008,25169.10732,0.00000,0.09741,308.48350
242.40001,12.12005,25167.15825,0.00000,0.09763,308.45961
242.80001,12.14002,25163.87701,0.00000,0.09785,308.41940
243.20001,12.16011,25162.15444,0.00000,0.09807,308.39829
243.60001,12.18002,25161.28123,0.00000,0.09829,308.38758
244.00001,12.19999,25161.79085,0.00000,0.09852,308.39383
244.40001,12.21996,25159.72257,0.00000,0.09875,308.36848
244.80001,12.23987,25157.65727,0.00000,0.09898,308.34317
245.20001,12.25989,25155.75290,0.00000,0.09920,308.31983
245.60001,12.27992,25156.86452,0.00000,0.09943,308.33345
246.00001,12.30001,25156.80194,0.00000,0.09966,308.33268
246.40001,12.31998,25155.34759,0.00000,0.09989,308.31486
246.80001,12.34007,25153.16904,0.00000,0.10012,308.28816
247.20001,12.36004,25152.25112,0.00000,0.10035,308.27691
247.60001,12.38001,25150.11728,0.00000,0.10058,308.25075
248.00001,12.40004,25147.99237,0.00000,0.10082,308.22471
248.40001,12.42013,25146.15357,0.00000,0.10106,308.20217
248.80001,12.43998,25144.49954,0.00000,0.10129,308.18190
249.20001,12.45989,25144.56511,0.00000,0.10153,308.18270
249.60001,12.47986,25143.56673,0.00000,0.10177,308.17047
250.00001,12.49989,25140.75041,0.00000,0.10201,308.13595
250.40001,12.51998,25139.25433,0.00000,0.10225,308.11761
250.80001,12.54001,25139.40334,0.00000,0.10249,308.11944
251.20001,12.56004,25138.36920,0.00000,0.10274,308.10676
251.60001,12.58007,25136.99532,0.00000,0.10298,308.08992
252.00001,12.60010,25135.86879,0.00000,0.10322,308.07612
252.40001,12.62001,25133.51738,0.00000,0.10347,308.04730
252.80001,12.64004,25132.88260,0.00000,0.10372,308.03952
253.20001,12.66001,25130.91266,0.00000,0.10398,308.01537
253.60001,12.67998,25127.31850,0.00000,0.10423,307.97132
254.00001,12.69989,25125.89097,0.00000,0.10448,307.95382
254.40001,12.71985,25124.42768,0.00000,0.10473,307.93589
254.80001,12.73994,25124.08197,0.00000,0.10499,307.93165
255.20001,12.75991,25119.87984,0.00000,0.10525,307.88015
255.60001,12.78000,25118.56854,0.00000,0.10550,307.86408
256.00001,12.80009,25119.13180,0.00000,0.10576,307.87098
256.40001,12.82006,25118.43443,0.00000,0.10602,307.86243
256.80001,12.84003,25116.92643,0.00000,0.10627,307.84395
257.20001,12.86000,25114.12203,0.00000,0.10653,307.80958
257.60001,12.87997,25109.64870,0.00000,0.10679,307.75475
258.00001,12.90000,25108.53112,0.00000,0.10706,307.74105
258.40001,12.91991,25105.73864,0.00000,0.10732,307.70683
258.80001,12.93994,25105.33333,0.00000,0.10759,307.70186
259.20001,12.95991,25100.71695,0.00000,0.10786,307.64528
259.60001,12.97994,25099.55466,0.00000,0.10814,307.63104
260.00001,12.99991,25097.51320,0.00000,0.10841,307.60601
260.40001,13.02006,25097.58770,0.00000,0.10869,307.60693
260.80001,13.04009,25096.67873,0.00000,0.10896,307.59579
261.20001,13.06006,25094.82801,0.00000,0.10924,307.57310
261.60001,13.08003,25094.11871,0.00000,0.10953,307.56441
262.00001,13.09994,25090.41429,0.00000,0.10981,307.51901
262.40001,13.11997,25086.70688,0.00000,0.11010,307.47357
262.80001,13.14006,25082.16798,0.00000,0.11038,307.41794
263.20001,13.15997,25080.40369,0.00000,0.11067,307.39631
263.60001,13.18000,25080.43647,0.00000,0.11096,307.39671
264.00001,13.19990,25076.41613,0.00000,0.11126,307.34744
264.40001,13.21993,25074.10645,0.00000,0.11155,307.31913
264.80001,13.23996,25072.49117,0.00000,0.11184,307.29933
265.20001,13.25993,25070.84608,0.00000,0.11214,307.27917
265.60001,13.28008,25071.96963,0.00000,0.11244,307.29294
266.00001,13.30011,25068.58110,0.00000,0.11274,307.25141
266.40001,13.32002,25065.91678,0.00000,0.11305,307.21875
266.80001,13.33999,25061.04112,0.00000,0.11336,307.15900
267.20001,13.36002,25056.59461,0.00000,0.11367,307.10450
267.60001,13.37999,25054.55911,0.00000,0.11398,307.07955
268.00001,13.40008,25052.31500,0.00000,0.11429,307.05205
268.40001,13.42005,25049.51060,0.00000,0.11460,307.01767
268.80001,13.43990,25045.35317,0.00000,0.11492,306.96672
269.20001,13.45993,25044.60812,0.00000,0.11523,306.95759
269.60001,13.47990,25041.08548,0.00000,0.11555,306.91441
270.00001,13.49999,25039.70861,0.00000,0.11587,306.89754
270.40001,13.52014,25038.18572,0.00000,0.11620,306.87887
270.80001,13.54011,25035.42006,0.00000,0.11653,306.84497
271.20001,13.56008,25032.68123,0.00000,0.11686,306.81141
271.60001,13.57999,25026.35717,0.00000,0.11718,306.73390
272.00001,13.60002,25024.17862,0.00000,0.11752,306.70719
272.40001,13.62005,25019.96756,0.00000,0.11785,306.65558
272.80001,13.64008,25017.25852,0.00000,0.11819,306.62238
273.20001,13.65993,25012.62128,0.00000,0.11853,306.56554
273.60001,13.67996,25011.16693,0.00000,0.11887,306.54772
274.00001,13.69987,25008.77380,0.00000,0.11921,306.51839
274.40001,13.71989,25006.58929,0.00000,0.11956,306.49161
274.80001,13.73998,25003.74019,0.00000,0.11991,306.45669
275.20001,13.76007,24999.12828,0.00000,0.12026,306.40017
275.60001,13.78010,24996.54442,0.00000,0.12061,306.36850
276.00001,13.80007,24992.66118,0.00000,0.12097,306.32090
276.40001,13.81998,24986.86761,0.00000,0.12133,306.24989
276.80001,13.84001,24981.74012,0.00000,0.12169,306.18705
277.20001,13.85998,24976.27884,0.00000,0.12204,306.12011
277.60001,13.88001,24974.24334,0.00000,0.12241,306.09517
278.00001,13.89998,24970.76988,0.00000,0.12277,306.05259
278.40001,13.91989,24967.06247,0.00000,0.12314,306.00715
278.80001,13.93998,24964.22827,0.00000,0.12351,305.97242
279.20001,13.95995,24959.02032,0.00000,0.12388,305.90859
279.60001,13.97998,24953.51434,0.00000,0.12426,305.84110
280.00001,14.00013,24951.51460,0.00000,0.12464,305.81659
280.40001,14.02010,24944.87613,0.00000,0.12501,305.73523
280.80001,14.04007,24939.42380,0.00000,0.12538,305.66840
281.20001,14.06004,24934.26651,0.00000,0.12577,305.60519
281.60001,14.08001,24930.01372,0.00000,0.12614,305.55307
282.00001,14.09992,24920.76904,0.00000,0.12652,305.43976
282.40001,14.12007,24917.20617,0.00000,0.12690,305.39609
282.80001,14.13998,24910.92235,0.00000,0.12728,305.31908
283.20001,14.15994,24907.99725,0.00000,0.12766,305.28322
283.60001,14.17991,24903.22739,0.00000,0.12804,305.22476
284.00001,14.19995,24897.03298,0.00000,0.12842,305.14884
284.40001,14.21997,24890.86986,0.00000,0.12880,305.07330
284.80001,14.24006,24885.54567,0.00000,0.12917,305.00805
285.20001,14.26009,24879.33636,0.00000,0.12954,304.93194
285.60001,14.28006,24870.16916,0.00000,0.12991,304.81959
286.00001,14.30003,24864.60805,0.00000,0.13027,304.75143
286.40001,14.32000,24855.94600,0.00000,0.13063,304.64526
286.80001,14.33991,24847.46128,0.00000,0.13099,304.54127
287.20001,14.35988,24839.62923,0.00000,0.13133,304.44528
287.60001,14.37997,24831.81804,0.00000,0.13167,304.34954
288.00001,14.39994,24822.90864,0.00000,0.13200,304.24034
288.40001,14.41991,24815.19878,0.00000,0.13232,304.14585
288.80001,14.43994,24803.34938,0.00000,0.13262,304.00061
289.20001,14.46003,24791.09019,0.00000,0.13292,303.85036
289.60001,14.48012,24774.30403,0.00000,0.13318,303.64462
290.00001,14.50021,24759.22108,0.00000,0.13344,303.45976
290.40001,14.52012,24740.68850,0.00000,0.13366,303.23262
290.80001,14.54003,24719.25467,0.00000,0.13387,302.96991
291.20001,14.56000,24692.12711,0.00000,0.13405,302.63743
291.60001,14.57985,24661.71980,0.00000,0.13421,302.26474
292.00001,14.60000,24630.56296,0.00000,0.13434,301.88287
292.40001,14.61997,24593.03290,0.00000,0.13445,301.42288
292.80001,14.63993,24549.97599,0.00000,0.13454,300.89516
293.20001,14.65996,24502.30271,0.00000,0.13461,300.31086
293.60001,14.67999,24447.80320,0.00000,0.13466,299.64289
294.00001,14.70002,24385.38373,0.00000,0.13469,298.87785
294.40001,14.72011,24308.21508,0.00000,0.13471,297.93203
294.80001,14.74014,24229.69043,0.00000,0.13472,296.96960
295.20001,14.76011,24137.36135,0.00000,0.13472,295.83798
295.60001,14.78002,24003.97360,0.00000,0.13470,294.20312
296.00001,14.79999,23803.92849,0.00000,0.13465,291.75128
296.24401,14.81231,22972.58526,0.00000,0.13344,281.56198
296.25201,14.81327,19066.50066,0.00000,0.12275,233.68731
296.26001,14.81470,13744.08007,0.00000,0.10838,168.45341