File: scratch/college-stuff/ME Lab/ME lab Fall 2013/group18/group18.is_tens_RawData/Specimen_RawData_4.csv
Time,Extension,Load,Strain 2,Tensile strain,Tensile stress
(sec),(mm),(N),(mm/mm),(mm/mm),(MPa)
0.00000,0.00000,0.39212,0.00000,0.00000,0.00474
0.20000,0.00759,3.93653,0.00000,0.00000,0.04759
0.40000,0.01943,8.60646,0.00000,0.00001,0.10404
0.60000,0.03001,12.56408,0.00000,0.00000,0.15189
0.80000,0.04006,15.26656,0.00000,0.00001,0.18456
1.00000,0.05010,18.11245,0.00000,0.00001,0.21896
1.20000,0.06009,22.44405,0.00000,0.00001,0.27132
1.40000,0.07007,29.26695,0.00000,0.00001,0.35381
1.60000,0.08012,33.09603,0.00000,0.00001,0.40010
1.80000,0.09004,34.65544,0.00000,0.00002,0.41895
2.00000,0.10009,39.34722,0.00000,0.00002,0.47567
2.20000,0.11001,44.04120,0.00000,0.00002,0.53241
2.40000,0.12000,47.05915,0.00000,0.00002,0.56889
2.60000,0.12998,51.84090,0.00000,0.00002,0.62670
2.80000,0.13991,58.02892,0.00000,0.00002,0.70151
3.00000,0.14995,65.40898,0.00000,0.00003,0.79072
3.20000,0.15988,72.74126,0.00000,0.00003,0.87936
3.40000,0.16992,88.86839,0.00000,0.00003,1.07432
3.60000,0.17991,112.97981,0.00000,0.00004,1.36581
3.80000,0.18989,139.92349,0.00000,0.00005,1.69153
4.00000,0.20000,165.82509,0.00000,0.00006,2.00465
4.20000,0.20998,194.07779,0.00000,0.00007,2.34619
4.40000,0.21997,232.28324,0.00000,0.00009,2.80806
4.60000,0.22995,273.89005,0.00000,0.00011,3.31104
4.80000,0.23994,316.58132,0.00000,0.00013,3.82713
5.00000,0.25004,364.15067,0.00000,0.00015,4.40219
5.20000,0.26008,413.65451,0.00000,0.00018,5.00064
5.40000,0.27007,464.29425,0.00000,0.00020,5.61282
5.60000,0.28005,511.89959,0.00000,0.00022,6.18832
5.80000,0.29010,556.22472,0.00000,0.00024,6.72416
6.00000,0.30008,599.78343,0.00000,0.00026,7.25074
6.20000,0.31007,644.58605,0.00000,0.00028,7.79236
6.40000,0.32005,687.80137,0.00000,0.00030,8.31478
6.60000,0.32998,728.51852,0.00000,0.00032,8.80701
6.80000,0.34002,768.21940,0.00000,0.00034,9.28695
7.00000,0.34995,806.07217,0.00000,0.00036,9.74455
7.20000,0.35993,842.51761,0.00000,0.00037,10.18514
7.40000,0.37004,876.56034,0.00000,0.00039,10.59668
7.60000,0.37996,906.73594,0.00000,0.00041,10.96147
7.80000,0.38995,933.55346,0.00000,0.00042,11.28566
8.00000,0.39987,958.03682,0.00000,0.00043,11.58164
8.20000,0.40992,981.03248,0.00000,0.00044,11.85963
8.40000,0.41996,1002.67222,0.00000,0.00045,12.12124
8.60000,0.42995,1024.57991,0.00000,0.00046,12.38608
8.80000,0.43993,1044.60316,0.00000,0.00047,12.62814
9.00000,0.44992,1063.80461,0.00000,0.00048,12.86026
9.20000,0.45996,1082.84475,0.00000,0.00049,13.09044
9.40000,0.47001,1100.99399,0.00000,0.00049,13.30984
9.60000,0.47999,1115.10511,0.00000,0.00050,13.48043
9.80000,0.49003,1129.80930,0.00000,0.00051,13.65819
10.00000,0.50002,1144.46990,0.00000,0.00051,13.83542
10.20000,0.51006,1158.11676,0.00000,0.00052,14.00039
10.40000,0.52005,1172.41293,0.00000,0.00053,14.17322
10.60000,0.53009,1186.29830,0.00000,0.00054,14.34108
10.80000,0.54008,1202.60501,0.00000,0.00054,14.53821
11.00000,0.55006,1218.83228,0.00000,0.00055,14.73438
11.20000,0.56005,1237.97497,0.00000,0.00056,14.96579
11.40000,0.56997,1259.32824,0.00000,0.00057,15.22393
11.60000,0.58002,1280.23978,0.00000,0.00058,15.47673
11.80000,0.59000,1300.67235,0.00000,0.00059,15.72374
12.00000,0.59993,1321.41849,0.00000,0.00060,15.97454
12.20000,0.60991,1344.60367,0.00000,0.00061,16.25482
12.40000,0.61990,1368.12320,0.00000,0.00063,16.53915
12.60000,0.62994,1392.71440,0.00000,0.00064,16.83643
12.80000,0.63993,1417.76204,0.00000,0.00064,17.13923
13.00000,0.64997,1443.37378,0.00000,0.00066,17.44885
13.20000,0.65996,1471.02382,0.00000,0.00067,17.78311
13.40000,0.66994,1498.01597,0.00000,0.00069,18.10941
13.60000,0.67993,1525.65772,0.00000,0.00070,18.44357
13.80000,0.68997,1556.90508,0.00000,0.00072,18.82132
14.00000,0.70002,1588.34364,0.00000,0.00074,19.20138
14.20000,0.70994,1620.10398,0.00000,0.00075,19.58533
14.40000,0.72004,1653.74428,0.00000,0.00077,19.99200
14.60000,0.73003,1688.18124,0.00000,0.00079,20.40831
14.80000,0.74001,1721.38233,0.00000,0.00080,20.80967
15.00000,0.75012,1753.76944,0.00000,0.00082,21.20120
15.20000,0.76004,1787.73981,0.00000,0.00084,21.61186
15.40000,0.77009,1820.36869,0.00000,0.00086,22.00631
15.60000,0.78001,1852.92885,0.00000,0.00088,22.39993
15.80000,0.79006,1888.61154,0.00000,0.00089,22.83129
16.00000,0.80004,1921.98716,0.00000,0.00091,23.23477
16.20000,0.81003,1958.63079,0.00000,0.00092,23.67775
16.40000,0.82001,1996.44305,0.00000,0.00094,24.13486
16.60000,0.83000,2034.15304,0.00000,0.00096,24.59074
16.80000,0.84004,2073.50533,0.00000,0.00099,25.06646
17.00000,0.84997,2112.54377,0.00000,0.00100,25.53840
17.20000,0.85995,2152.81229,0.00000,0.00103,26.02520
17.40000,0.86994,2191.15838,0.00000,0.00105,26.48876
17.60000,0.87992,2232.28950,0.00000,0.00107,26.98599
17.80000,0.88997,2272.66587,0.00000,0.00109,27.47410
18.00000,0.89989,2313.73757,0.00000,0.00111,27.97061
18.20000,0.90994,2353.57303,0.00000,0.00113,28.45218
18.40000,0.91998,2392.99852,0.00000,0.00115,28.92879
18.60000,0.92991,2431.87156,0.00000,0.00117,29.39873
18.80000,0.93995,2472.56476,0.00000,0.00119,29.89066
19.00000,0.94994,2514.79670,0.00000,0.00121,30.40120
19.20000,0.95992,2554.86406,0.00000,0.00124,30.88558
19.40000,0.97002,2597.42718,0.00000,0.00126,31.40012
19.60000,0.98001,2636.06701,0.00000,0.00128,31.86723
19.80000,0.99011,2676.24464,0.00000,0.00130,32.35294
20.00000,1.00004,2715.56098,0.00000,0.00132,32.82823
20.20000,1.01008,2753.46730,0.00000,0.00134,33.28648
20.40000,1.02001,2791.15885,0.00000,0.00136,33.74213
20.60000,1.03005,2829.67146,0.00000,0.00138,34.20770
20.80000,1.04004,2868.11478,0.00000,0.00140,34.67244
21.00000,1.05002,2907.02228,0.00000,0.00142,35.14279
21.20000,1.06007,2943.46940,0.00000,0.00145,35.58340
21.40000,1.06999,2980.27992,0.00000,0.00147,36.02840
21.60000,1.08004,3015.36657,0.00000,0.00149,36.45256
21.80000,1.08996,3052.24769,0.00000,0.00150,36.89841
22.00000,1.09995,3089.99363,0.00000,0.00152,37.35472
22.20000,1.10993,3127.76230,0.00000,0.00154,37.81130
22.40000,1.11992,3166.03333,0.00000,0.00156,38.27396
22.60000,1.12996,3204.27604,0.00000,0.00159,38.73627
22.80000,1.13989,3243.95485,0.00000,0.00161,39.21595
23.00000,1.14993,3283.58226,0.00000,0.00163,39.69500
23.20000,1.15992,3325.05628,0.00000,0.00165,40.19638
23.40000,1.16996,3366.04342,0.00000,0.00167,40.69187
23.60000,1.18001,3406.62114,0.00000,0.00169,41.18241
23.80000,1.18999,3446.88259,0.00000,0.00172,41.66913
24.00000,1.20003,3488.27429,0.00000,0.00174,42.16951
24.20000,1.21002,3530.32574,0.00000,0.00176,42.67786
24.40000,1.22000,3569.96171,0.00000,0.00178,43.15702
24.60000,1.23005,3610.82666,0.00000,0.00181,43.65103
24.80000,1.24009,3652.60281,0.00000,0.00183,44.15606
25.00000,1.25008,3693.47818,0.00000,0.00185,44.65020
25.20000,1.26000,3735.46295,0.00000,0.00187,45.15775
25.40000,1.27005,3777.68576,0.00000,0.00189,45.66818
25.60000,1.28003,3818.91280,0.00000,0.00192,46.16657
25.80000,1.29002,3859.98674,0.00000,0.00194,46.66311
26.00000,1.30006,3902.73966,0.00000,0.00197,47.17995
26.20000,1.30999,3946.15754,0.00000,0.00199,47.70483
26.40000,1.32003,3989.55420,0.00000,0.00201,48.22945
26.60000,1.32996,4032.24304,0.00000,0.00204,48.74551
26.80000,1.33994,4074.72588,0.00000,0.00206,49.25908
27.00000,1.34999,4119.37051,0.00000,0.00208,49.79879
27.20000,1.35991,4163.40046,0.00000,0.00211,50.33106
27.40000,1.36996,4207.40210,0.00000,0.00213,50.86299
27.60000,1.37988,4250.69295,0.00000,0.00216,51.38633
27.80000,1.38993,4295.44710,0.00000,0.00218,51.92736
28.00000,1.39991,4339.47071,0.00000,0.00220,52.45956
28.20000,1.40996,4384.60708,0.00000,0.00223,53.00521
28.40000,1.42000,4428.58711,0.00000,0.00225,53.53688
28.60000,1.42999,4473.54391,0.00000,0.00228,54.08036
28.80000,1.44003,4518.04735,0.00000,0.00231,54.61836
29.00000,1.45001,4562.05681,0.00000,0.00233,55.15039
29.20000,1.46006,4606.42315,0.00000,0.00236,55.68673
29.40000,1.47010,4650.59988,0.00000,0.00238,56.22078
29.60000,1.48003,4694.87309,0.00000,0.00241,56.75600
29.80000,1.49007,4739.57136,0.00000,0.00243,57.29635
30.00000,1.50000,4786.28315,0.00000,0.00245,57.86105
30.20000,1.51004,4830.82756,0.00000,0.00248,58.39954
30.40000,1.52003,4875.54558,0.00000,0.00251,58.94013
30.60000,1.53001,4919.15792,0.00000,0.00254,59.46736
30.80000,1.54006,4964.66756,0.00000,0.00256,60.01752
31.00000,1.54998,5011.05264,0.00000,0.00258,60.57827
31.20000,1.55997,5057.04917,0.00000,0.00261,61.13432
31.40000,1.56995,5102.85199,0.00000,0.00264,61.68803
31.60000,1.57994,5148.06546,0.00000,0.00266,62.23461
31.80000,1.58992,5194.32314,0.00000,0.00269,62.79381
32.00000,1.59985,5239.86071,0.00000,0.00271,63.34431
32.20000,1.60995,5285.24518,0.00000,0.00274,63.89296
32.40000,1.61994,5333.46571,0.00000,0.00277,64.47590
32.60000,1.62998,5379.02080,0.00000,0.00280,65.02661
32.80000,1.63991,5424.85379,0.00000,0.00282,65.58068
33.00000,1.64995,5470.54894,0.00000,0.00285,66.13309
33.20000,1.66000,5516.38417,0.00000,0.00288,66.68719
33.40000,1.66992,5562.90634,0.00000,0.00290,67.24959
33.60000,1.68003,5610.17133,0.00000,0.00293,67.82097
33.80000,1.69001,5658.11694,0.00000,0.00296,68.40059
34.00000,1.70005,5703.03686,0.00000,0.00299,68.94362
34.20000,1.71004,5747.87967,0.00000,0.00301,69.48572
34.40000,1.72002,5794.01888,0.00000,0.00304,70.04349
34.60000,1.73007,5840.11525,0.00000,0.00306,70.60075
34.80000,1.74005,5888.11412,0.00000,0.00309,71.18101
35.00000,1.75004,5934.44668,0.00000,0.00312,71.74112
35.20000,1.76002,5982.35503,0.00000,0.00315,72.32028
35.40000,1.77001,6027.41688,0.00000,0.00318,72.86503
35.60000,1.78005,6074.26763,0.00000,0.00320,73.43140
35.80000,1.79004,6120.90379,0.00000,0.00323,73.99518
36.00000,1.80002,6166.58106,0.00000,0.00326,74.54737
36.20000,1.80995,6215.70498,0.00000,0.00328,75.14123
36.40000,1.81987,6262.77328,0.00000,0.00331,75.71023
36.60000,1.82986,6309.05107,0.00000,0.00334,76.26968
36.80000,1.83990,6356.36896,0.00000,0.00337,76.84171
37.00000,1.84995,6405.21869,0.00000,0.00340,77.43225
37.20000,1.85987,6453.44034,0.00000,0.00343,78.01520
37.40000,1.86992,6501.63367,0.00000,0.00346,78.59780
37.60000,1.87990,6548.38607,0.00000,0.00349,79.16299
37.80000,1.88995,6595.88352,0.00000,0.00351,79.73718
38.00000,1.89999,6644.72654,0.00000,0.00354,80.32764
38.20000,1.90998,6692.56598,0.00000,0.00357,80.90597
38.40000,1.92002,6740.15880,0.00000,0.00360,81.48131
38.60000,1.93000,6788.58906,0.00000,0.00364,82.06678
38.80000,1.94011,6837.55279,0.00000,0.00366,82.65870
39.00000,1.95009,6886.52545,0.00000,0.00369,83.25073
39.20000,1.96014,6934.82384,0.00000,0.00372,83.83461
39.40000,1.97006,6979.99522,0.00000,0.00375,84.38068
39.60000,1.98005,7029.18917,0.00000,0.00378,84.97538
39.80000,1.99009,7077.89138,0.00000,0.00381,85.56414
40.00000,2.00002,7127.08086,0.00000,0.00384,86.15879
40.20000,2.01006,7175.02013,0.00000,0.00387,86.73832
40.40000,2.01999,7223.64560,0.00000,0.00390,87.32615
40.60000,2.02997,7274.31998,0.00000,0.00393,87.93875
40.80000,2.03996,7322.34344,0.00000,0.00396,88.51930
41.00000,2.04988,7371.65734,0.00000,0.00399,89.11546
41.20000,2.05993,7420.51825,0.00000,0.00402,89.70613
41.40000,2.06991,7470.75081,0.00000,0.00405,90.31339
41.60000,2.07990,7519.48655,0.00000,0.00409,90.90255
41.80000,2.08988,7568.89880,0.00000,0.00412,91.49990
42.00000,2.09987,7618.64185,0.00000,0.00415,92.10124
42.20000,2.10991,7668.66356,0.00000,0.00418,92.70594
42.40000,2.11996,7718.22184,0.00000,0.00421,93.30505
42.60000,2.13000,7767.65868,0.00000,0.00424,93.90269
42.80000,2.14005,7818.15797,0.00000,0.00428,94.51317
43.00000,2.15003,7866.67392,0.00000,0.00431,95.09968
43.20000,2.16007,7915.23904,0.00000,0.00434,95.68678
43.40000,2.17012,7964.28993,0.00000,0.00437,96.27975
43.60000,2.18016,8013.42949,0.00000,0.00440,96.87380
43.80000,2.19009,8063.58382,0.00000,0.00444,97.48011
44.00000,2.20007,8114.14644,0.00000,0.00447,98.09136
44.20000,2.21006,8164.09588,0.00000,0.00450,98.69519
44.40000,2.22004,8214.60336,0.00000,0.00453,99.30577
44.60000,2.23009,8263.70046,0.00000,0.00456,99.89930
44.80000,2.24001,8313.75271,0.00000,0.00459,100.50438
45.00000,2.25000,8363.38997,0.00000,0.00463,101.10444
45.20000,2.25998,8412.82755,0.00000,0.00466,101.70209
45.40000,2.26991,8462.65331,0.00000,0.00469,102.30443
45.60000,2.27995,8512.95590,0.00000,0.00472,102.91254
45.80000,2.28994,8564.89688,0.00000,0.00476,103.54045
46.00000,2.29992,8613.77195,0.00000,0.00479,104.13129
46.20000,2.30985,8663.89126,0.00000,0.00483,104.73718
46.40000,2.31989,8715.21458,0.00000,0.00487,105.35763
46.60000,2.32988,8764.91517,0.00000,0.00489,105.95845
46.80000,2.33992,8813.72690,0.00000,0.00492,106.54854
47.00000,2.34997,8862.22422,0.00000,0.00495,107.13482
47.20000,2.35995,8914.64278,0.00000,0.00499,107.76850
47.40000,2.37000,8965.00275,0.00000,0.00503,108.37730
47.60000,2.37998,9014.61840,0.00000,0.00506,108.97710
47.80000,2.39003,9065.44551,0.00000,0.00509,109.59155
48.00000,2.40007,9116.56246,0.00000,0.00512,110.20949
48.20000,2.41005,9166.09541,0.00000,0.00516,110.80830
48.40000,2.42010,9214.81103,0.00000,0.00519,111.39721
48.60000,2.43008,9265.91009,0.00000,0.00523,112.01495
48.80000,2.44007,9317.90769,0.00000,0.00526,112.64354
49.00000,2.45005,9369.18184,0.00000,0.00529,113.26339
49.20000,2.46004,9418.60899,0.00000,0.00533,113.86091
49.40000,2.47008,9468.95555,0.00000,0.00536,114.46955
49.60000,2.48001,9520.46961,0.00000,0.00540,115.09230
49.80000,2.48999,9570.57774,0.00000,0.00543,115.69805
50.00000,2.49998,9620.80806,0.00000,0.00547,116.30528
50.20000,2.51002,9671.30214,0.00000,0.00550,116.91570
50.40000,2.51995,9720.74419,0.00000,0.00554,117.51341
50.60000,2.52987,9772.00270,0.00000,0.00557,118.13307
50.80000,2.53992,9821.74724,0.00000,0.00561,118.73442
51.00000,2.54984,9874.83338,0.00000,0.00565,119.37618
51.20000,2.55995,9926.98297,0.00000,0.00567,120.00661
51.40000,2.56987,9975.99736,0.00000,0.00571,120.59914
51.60000,2.57998,10026.94219,0.00000,0.00574,121.21501
51.80000,2.58996,10075.60268,0.00000,0.00578,121.80327
52.00000,2.59995,10127.38273,0.00000,0.00582,122.42923
52.20000,2.61005,10179.51518,0.00000,0.00586,123.05946
52.40000,2.62004,10230.07259,0.00000,0.00588,123.67064
52.60000,2.63008,10280.43777,0.00000,0.00592,124.27950
52.80000,2.64006,10331.43774,0.00000,0.00596,124.89604
53.00000,2.65005,10383.85183,0.00000,0.00600,125.52967
53.20000,2.66009,10434.55377,0.00000,0.00604,126.14260
53.40000,2.67008,10484.90405,0.00000,0.00607,126.75128
53.60000,2.68012,10534.60538,0.00000,0.00610,127.35212
53.80000,2.69005,10585.53383,0.00000,0.00613,127.96779
54.00000,2.70003,10636.53082,0.00000,0.00618,128.58429
54.20000,2.71002,10686.57190,0.00000,0.00621,129.18923
54.40000,2.72006,10739.98064,0.00000,0.00625,129.83489
54.60000,2.73005,10790.45013,0.00000,0.00628,130.44501
54.80000,2.73997,10841.55962,0.00000,0.00631,131.06287
55.00000,2.74996,10891.72363,0.00000,0.00635,131.66930
55.20000,2.75994,10942.69753,0.00000,0.00640,132.28552
55.40000,2.76987,10993.49931,0.00000,0.00643,132.89965
55.60000,2.77991,11043.35561,0.00000,0.00646,133.50236
55.80000,2.78984,11093.40414,0.00000,0.00650,134.10740
56.00000,2.79994,11145.94638,0.00000,0.00653,134.74258
56.20000,2.80987,11196.34211,0.00000,0.00657,135.35181
56.40000,2.81991,11247.71237,0.00000,0.00662,135.97282
56.60000,2.82996,11300.04302,0.00000,0.00665,136.60544
56.80000,2.83994,11352.05328,0.00000,0.00669,137.23419
57.00000,2.84993,11402.53246,0.00000,0.00671,137.84443
57.20000,2.85997,11455.25873,0.00000,0.00676,138.48183
57.40000,2.87002,11505.51662,0.00000,0.00680,139.08940
57.60000,2.88006,11555.70522,0.00000,0.00684,139.69612
57.80000,2.89004,11608.55591,0.00000,0.00687,140.33503
58.00000,2.90009,11659.02764,0.00000,0.00690,140.94518
58.20000,2.91007,11711.33295,0.00000,0.00694,141.57750
58.40000,2.92006,11762.47075,0.00000,0.00698,142.19570
58.60000,2.92998,11814.70305,0.00000,0.00703,142.82713
58.80000,2.94009,11865.60616,0.00000,0.00707,143.44249
59.00000,2.95007,11914.73305,0.00000,0.00709,144.03639
59.20000,2.96000,11964.77935,0.00000,0.00712,144.64139
59.40000,2.96998,12015.60423,0.00000,0.00717,145.25581
59.60000,2.97991,12067.15256,0.00000,0.00721,145.87897
59.80000,2.98989,12118.83500,0.00000,0.00726,146.50376
60.00000,2.99994,12169.38943,0.00000,0.00729,147.11491
60.20000,3.00986,12222.38615,0.00000,0.00732,147.75558
60.40000,3.01991,12273.30938,0.00000,0.00735,148.37119
60.60000,3.02989,12324.99108,0.00000,0.00740,148.99597
60.80000,3.03994,12374.85632,0.00000,0.00744,149.59878
61.00000,3.04992,12427.76066,0.00000,0.00748,150.23834
61.20000,3.05997,12478.52147,0.00000,0.00751,150.85199
61.40000,3.07001,12529.42979,0.00000,0.00754,151.46741
61.60000,3.07994,12581.17408,0.00000,0.00758,152.09295
61.80000,3.08998,12634.19241,0.00000,0.00763,152.73388
62.00000,3.10003,12687.31505,0.00000,0.00768,153.37608
62.20000,3.11007,12737.37550,0.00000,0.00771,153.98125
62.40000,3.11999,12787.29290,0.00000,0.00774,154.58470
62.60000,3.13010,12839.35606,0.00000,0.00778,155.21409
62.80000,3.14008,12889.38820,0.00000,0.00782,155.81892
63.00000,3.15007,12942.79844,0.00000,0.00786,156.46460
63.20000,3.16011,12993.63524,0.00000,0.00790,157.07916
63.40000,3.16998,13046.01431,0.00000,0.00793,157.71237
63.60000,3.18002,13097.85396,0.00000,0.00798,158.33905
63.80000,3.19001,13146.62993,0.00000,0.00801,158.92870
64.00000,3.19993,13198.37123,0.00000,0.00805,159.55420
64.20000,3.20998,13249.89796,0.00000,0.00810,160.17710
64.40000,3.21996,13300.52763,0.00000,0.00814,160.78916
64.60000,3.22995,13350.76988,0.00000,0.00817,161.39654
64.80000,3.23993,13401.76463,0.00000,0.00821,162.01301
65.00000,3.24992,13454.41788,0.00000,0.00824,162.64953
65.20000,3.25990,13506.43486,0.00000,0.00829,163.27836
65.40000,3.26989,13559.00913,0.00000,0.00833,163.91393
65.60000,3.27999,13610.11118,0.00000,0.00837,164.53170
65.80000,3.28998,13662.04470,0.00000,0.00841,165.15952
66.00000,3.29996,13712.55219,0.00000,0.00844,165.77010
66.20000,3.30995,13762.80338,0.00000,0.00848,166.37758
66.40000,3.31999,13816.70833,0.00000,0.00852,167.02923
66.60000,3.33004,13868.70146,0.00000,0.00857,167.65778
66.80000,3.33996,13920.66330,0.00000,0.00861,168.28594
67.00000,3.35001,13971.62378,0.00000,0.00864,168.90200
67.20000,3.35999,14023.22054,0.00000,0.00868,169.52575
67.40000,3.37003,14076.15840,0.00000,0.00872,170.16571
67.60000,3.38014,14127.08908,0.00000,0.00876,170.78141
67.80000,3.39006,14177.36858,0.00000,0.00880,171.38923
68.00000,3.40005,14226.90004,0.00000,0.00884,171.98801
68.20000,3.40997,14277.74280,0.00000,0.00888,172.60265
68.40000,3.41996,14329.24122,0.00000,0.00892,173.22521
68.60000,3.43000,14378.76970,0.00000,0.00896,173.82395
68.80000,3.43999,14429.99542,0.00000,0.00900,174.44322
69.00000,3.44997,14480.56698,0.00000,0.00904,175.05458
69.20000,3.45990,14531.71670,0.00000,0.00907,175.67292
69.40000,3.46988,14581.05445,0.00000,0.00911,176.26936
69.60000,3.47993,14632.41726,0.00000,0.00915,176.89028
69.80000,3.48997,14685.00048,0.00000,0.00920,177.52596
70.00000,3.49996,14735.39025,0.00000,0.00924,178.13512
70.20000,3.50994,14787.30291,0.00000,0.00928,178.76268
70.40000,3.51993,14838.57483,0.00000,0.00931,179.38251
70.60000,3.52991,14892.64518,0.00000,0.00935,180.03616
70.80000,3.53996,14943.80683,0.00000,0.00940,180.65465
71.00000,3.54994,14994.67790,0.00000,0.00943,181.26963
71.20000,3.55993,15045.79633,0.00000,0.00948,181.88759
71.40000,3.56997,15097.90719,0.00000,0.00951,182.51756
71.60000,3.57996,15149.70511,0.00000,0.00956,183.14374
71.80000,3.59006,15200.12766,0.00000,0.00959,183.75329
72.00000,3.59999,15251.51581,0.00000,0.00964,184.37452
72.20000,3.61003,15303.21985,0.00000,0.00968,184.99957
72.40000,3.62007,15353.98662,0.00000,0.00972,185.61329
72.60000,3.63006,15404.26463,0.00000,0.00976,186.22109
72.80000,3.64004,15455.06269,0.00000,0.00980,186.83519
73.00000,3.65003,15507.14970,0.00000,0.00984,187.46486
73.20000,3.66007,15558.38138,0.00000,0.00988,188.08420
73.40000,3.67006,15607.99927,0.00000,0.00992,188.68403
73.60000,3.67998,15657.96435,0.00000,0.00996,189.28805
73.80000,3.68997,15709.76526,0.00000,0.01000,189.91427
74.00000,3.69995,15762.26354,0.00000,0.01005,190.54892
74.20000,3.71000,15812.92599,0.00000,0.01008,191.16137
74.40000,3.71992,15864.29477,0.00000,0.01013,191.78236
74.60000,3.72997,15915.21949,0.00000,0.01017,192.39799
74.80000,3.73989,15967.23050,0.00000,0.01021,193.02675
75.00000,3.74994,16019.95677,0.00000,0.01025,193.66415
75.20000,3.75998,16069.48972,0.00000,0.01029,194.26295
75.40000,3.76997,16122.35904,0.00000,0.01033,194.90209
75.60000,3.77995,16171.37343,0.00000,0.01037,195.49462
75.80000,3.78988,16222.11784,0.00000,0.01041,196.10806
76.00000,3.79992,16275.29711,0.00000,0.01045,196.75094
76.20000,3.80997,16326.34550,0.00000,0.01049,197.36806
76.40000,3.82001,16378.69924,0.00000,0.01053,198.00097
76.60000,3.83006,16427.44243,0.00000,0.01058,198.59022
76.80000,3.84010,16478.88571,0.00000,0.01062,199.21211
77.00000,3.85008,16529.06239,0.00000,0.01066,199.81869
77.20000,3.86001,16581.55769,0.00000,0.01070,200.45331
77.40000,3.87005,16631.86401,0.00000,0.01074,201.06146
77.60000,3.88004,16681.53554,0.00000,0.01078,201.66193
77.80000,3.89002,16731.90892,0.00000,0.01082,202.27089
78.00000,3.90007,16781.98725,0.00000,0.01087,202.87629
78.20000,3.90999,16832.74806,0.00000,0.01091,203.48993
78.40000,3.92004,16883.12292,0.00000,0.01095,204.09891
78.60000,3.93002,16932.90621,0.00000,0.01099,204.70074
78.80000,3.94001,16984.54469,0.00000,0.01103,205.32499
79.00000,3.94999,17034.24305,0.00000,0.01108,205.92579
79.20000,3.95992,17084.46145,0.00000,0.01112,206.53288
79.40000,3.96996,17136.30110,0.00000,0.01116,207.15956
79.60000,3.97989,17187.14386,0.00000,0.01120,207.77420
79.80000,3.98993,17239.31283,0.00000,0.01124,208.40486
80.00000,3.99992,17287.90402,0.00000,0.01128,208.99228
80.20000,4.00990,17339.35326,0.00000,0.01132,209.61425
80.40000,4.02001,17390.61624,0.00000,0.01136,210.23396
80.60000,4.02993,17441.68550,0.00000,0.01141,210.85133
80.80000,4.03998,17491.75936,0.00000,0.01144,211.45667
81.00000,4.05002,17542.53060,0.00000,0.01149,212.07044
81.20000,4.06001,17593.07086,0.00000,0.01153,212.68142
81.40000,4.07005,17643.12238,0.00000,0.01157,213.28649
81.60000,4.07998,17692.02948,0.00000,0.01162,213.87772
81.80000,4.09008,17743.06744,0.00000,0.01166,214.49472
82.00000,4.10006,17792.64659,0.00000,0.01170,215.09408
82.20000,4.11005,17842.40305,0.00000,0.01174,215.69558
82.40000,4.12003,17890.91676,0.00000,0.01178,216.28206
82.60000,4.12996,17940.50485,0.00000,0.01182,216.88153
82.80000,4.14006,17991.98240,0.00000,0.01186,217.50383
83.00000,4.14999,18042.37962,0.00000,0.01190,218.11308
83.20000,4.16003,18092.35513,0.00000,0.01195,218.71723
83.40000,4.17002,18141.62284,0.00000,0.01199,219.31283
83.60000,4.17994,18192.53117,0.00000,0.01203,219.92825
83.80000,4.18999,18243.31135,0.00000,0.01208,220.54213
84.00000,4.19991,18293.36435,0.00000,0.01212,221.14722
84.20000,4.20996,18342.86004,0.00000,0.01216,221.74557
84.40000,4.21982,18392.71784,0.00000,0.01220,222.34830
84.60000,4.22987,18442.93028,0.00000,0.01225,222.95531
84.80000,4.23991,18492.83278,0.00000,0.01229,223.55858
85.00000,4.24990,18543.40732,0.00000,0.01234,224.16997
85.20000,4.26000,18592.89259,0.00000,0.01237,224.76820
85.40000,4.26993,18643.85456,0.00000,0.01242,225.38427
85.60000,4.28003,18692.88981,0.00000,0.01246,225.97706
85.80000,4.28996,18740.21888,0.00000,0.01251,226.54921
86.00000,4.30000,18791.24194,0.00000,0.01254,227.16603
86.20000,4.31010,18841.58850,0.00000,0.01259,227.77466
86.40000,4.32003,18892.16453,0.00000,0.01263,228.38607
86.60000,4.33013,18940.06729,0.00000,0.01267,228.96517
86.80000,4.33994,18988.38282,0.00000,0.01272,229.54925
87.00000,4.35004,19041.00329,0.00000,0.01276,230.18538
87.20000,4.35997,19089.19364,0.00000,0.01280,230.76795
87.40000,4.37001,19137.75206,0.00000,0.01285,231.35496
87.60000,4.38006,19187.06894,0.00000,0.01289,231.95115
87.80000,4.38998,19235.49175,0.00000,0.01293,232.53653
88.00000,4.40003,19284.44505,0.00000,0.01298,233.12833
88.20000,4.40995,19332.44318,0.00000,0.01302,233.70857
88.40000,4.42000,19382.81059,0.00000,0.01306,234.31746
88.60000,4.42998,19432.07383,0.00000,0.01310,234.91300
88.80000,4.43991,19480.62927,0.00000,0.01315,235.49998
89.00000,4.44995,19528.58716,0.00000,0.01319,236.07974
89.20000,4.45988,19577.47787,0.00000,0.01323,236.67078
89.40000,4.46992,19627.44743,0.00000,0.01328,237.27486
89.60000,4.47991,19677.33502,0.00000,0.01332,237.87795
89.80000,4.48989,19726.73386,0.00000,0.01337,238.47512
90.00000,4.49994,19775.72888,0.00000,0.01341,239.06742
90.20000,4.50992,19822.85827,0.00000,0.01346,239.63717
90.40000,4.52003,19873.14373,0.00000,0.01349,240.24506
90.60000,4.53001,19921.25958,0.00000,0.01354,240.82673
90.80000,4.54006,19971.31705,0.00000,0.01358,241.43187
91.00000,4.55010,20018.51797,0.00000,0.01362,242.00248
91.20000,4.56003,20065.31954,0.00000,0.01366,242.56826
91.40000,4.57007,20113.86901,0.00000,0.01371,243.15517
91.60000,4.58005,20161.59743,0.00000,0.01375,243.73216
91.80000,4.59010,20211.49993,0.00000,0.01380,244.33543
92.00000,4.60002,20258.98397,0.00000,0.01384,244.90946
92.20000,4.61007,20306.62596,0.00000,0.01389,245.48540
92.40000,4.62011,20352.28014,0.00000,0.01394,246.03731
92.60000,4.63004,20394.09131,0.00000,0.01397,246.54276
92.79400,4.63972,19837.88759,0.00000,0.01404,239.81885
92.79800,4.64020,18378.10278,0.00000,0.01419,222.17162
92.80200,4.64068,16388.21363,0.00000,0.01446,198.11598
92.80600,4.64140,14109.10040,0.00000,0.01441,170.56394
92.81000,4.64206,11779.45361,0.00000,0.01367,142.40100