File: scratch/college-stuff/ME Lab/ME lab Fall 2013/group18/group18.is_tens_RawData/Specimen_RawData_3.csv
Time,Extension,Load,Strain 2,Tensile strain,Tensile stress
(sec),(mm),(N),(mm/mm),(mm/mm),(MPa)
0.00000,0.00000,0.02935,0.00000,0.00000,0.00036
0.40000,0.01943,44.03624,0.00000,0.00001,0.54178
0.80000,0.04006,87.81978,0.00000,0.00002,1.08046
1.20000,0.06009,142.82498,0.00000,0.00002,1.75720
1.60000,0.08012,196.91337,0.00000,0.00003,2.42265
2.00000,0.10009,258.31847,0.00000,0.00003,3.17813
2.40000,0.12000,334.99734,0.00000,0.00003,4.12152
2.80000,0.13991,419.42168,0.00000,0.00003,5.16021
3.20000,0.15988,509.53557,0.00000,0.00004,6.26889
3.60000,0.17991,612.98851,0.00000,0.00004,7.54169
4.00000,0.20000,746.33993,0.00000,0.00005,9.18233
4.40000,0.21997,907.65422,0.00000,0.00007,11.16701
4.80000,0.23994,1109.09147,0.00000,0.00009,13.64532
5.20000,0.26008,1342.19341,0.00000,0.00011,16.51321
5.60000,0.28005,1592.74749,0.00000,0.00014,19.59581
6.00000,0.30002,1851.65796,0.00000,0.00017,22.78122
6.40000,0.32005,2128.25853,0.00000,0.00021,26.18428
6.80000,0.33996,2416.43898,0.00000,0.00025,29.72981
7.20000,0.35993,2717.89152,0.00000,0.00030,33.43863
7.60000,0.37990,3027.76452,0.00000,0.00035,37.25104
8.00000,0.39987,3340.83214,0.00000,0.00039,41.10276
8.40000,0.41990,3663.58161,0.00000,0.00045,45.07359
8.80000,0.43993,3988.33342,0.00000,0.00050,49.06906
9.20000,0.45996,4314.60142,0.00000,0.00056,53.08319
9.60000,0.47999,4642.40536,0.00000,0.00061,57.11621
10.00000,0.49996,4972.06263,0.00000,0.00067,61.17203
10.40000,0.52005,5301.07915,0.00000,0.00073,65.21997
10.80000,0.54002,5627.37882,0.00000,0.00078,69.23448
11.20000,0.55999,5947.82457,0.00000,0.00084,73.17698
11.60000,0.57996,6272.86807,0.00000,0.00090,77.17603
12.00000,0.59993,6593.58650,0.00000,0.00096,81.12188
12.40000,0.61990,6915.55887,0.00000,0.00102,85.08316
12.80000,0.63993,7233.46770,0.00000,0.00107,88.99444
13.20000,0.65990,7550.21721,0.00000,0.00113,92.89145
13.60000,0.67987,7864.24950,0.00000,0.00118,96.75504
14.00000,0.70002,8180.21744,0.00000,0.00124,100.64244
14.40000,0.71999,8487.19031,0.00000,0.00130,104.41917
14.80000,0.74001,8788.69444,0.00000,0.00135,108.12862
15.20000,0.76004,9083.28518,0.00000,0.00141,111.75302
15.60000,0.78001,9370.08411,0.00000,0.00147,115.28155
16.00000,0.80004,9650.99260,0.00000,0.00152,118.73761
16.40000,0.82001,9921.84803,0.00000,0.00158,122.06998
16.80000,0.84004,10185.12473,0.00000,0.00164,125.30911
17.20000,0.86001,10413.36283,0.00000,0.00169,128.11716
17.60000,0.87992,10605.89924,0.00000,0.00173,130.48597
18.00000,0.89989,10802.55657,0.00000,0.00178,132.90547
18.40000,0.91992,11001.75679,0.00000,0.00182,135.35626
18.80000,0.93995,11201.38541,0.00000,0.00186,137.81232
19.20000,0.95992,11404.70058,0.00000,0.00189,140.31374
19.60000,0.98001,11605.33428,0.00000,0.00193,142.78216
20.00000,1.00004,11806.94103,0.00000,0.00197,145.26256
20.40000,1.02001,12009.11030,0.00000,0.00201,147.74988
20.80000,1.03998,12214.44532,0.00000,0.00205,150.27615
21.20000,1.06001,12415.32266,0.00000,0.00209,152.74757
21.60000,1.08004,12617.11568,0.00000,0.00213,155.23026
22.00000,1.09995,12821.15728,0.00000,0.00217,157.74062
22.40000,1.11986,13026.14957,0.00000,0.00220,160.26267
22.80000,1.13989,13233.42472,0.00000,0.00225,162.81280
23.20000,1.15992,13439.54951,0.00000,0.00228,165.34879
23.60000,1.18001,13645.50591,0.00000,0.00233,167.88270
24.00000,1.19998,13854.02977,0.00000,0.00237,170.44820
24.40000,1.22006,14061.92183,0.00000,0.00241,173.00593
24.80000,1.24003,14269.35196,0.00000,0.00245,175.55797
25.20000,1.26000,14473.01358,0.00000,0.00249,178.06365
25.60000,1.27997,14679.94303,0.00000,0.00253,180.60954
26.00000,1.30000,14886.53123,0.00000,0.00257,183.15122
26.40000,1.32009,15095.40975,0.00000,0.00261,185.72108
26.80000,1.33994,15301.63586,0.00000,0.00266,188.25832
27.20000,1.35997,15510.03307,0.00000,0.00270,190.82226
27.60000,1.37988,15720.00831,0.00000,0.00274,193.40561
28.00000,1.39985,15929.56781,0.00000,0.00279,195.98386
28.40000,1.41994,16137.80558,0.00000,0.00283,198.54584
28.80000,1.44003,16346.24302,0.00000,0.00288,201.11027
29.20000,1.46006,16555.82786,0.00000,0.00292,203.68883
29.60000,1.48003,16763.17155,0.00000,0.00297,206.23981
30.00000,1.50000,16969.77615,0.00000,0.00301,208.78169
30.40000,1.52003,17175.76534,0.00000,0.00306,211.31601
30.80000,1.54000,17380.76508,0.00000,0.00310,213.83815
31.20000,1.55997,17587.22812,0.00000,0.00315,216.37830
31.60000,1.58000,17792.48416,0.00000,0.00320,218.90359
32.00000,1.59991,17997.99055,0.00000,0.00324,221.43197
32.40000,1.61988,18202.79658,0.00000,0.00329,223.95173
32.80000,1.63985,18406.19445,0.00000,0.00334,226.45416
33.20000,1.65994,18607.90402,0.00000,0.00339,228.93583
33.60000,1.68003,18807.57064,0.00000,0.00345,231.39236
34.00000,1.70011,19006.38938,0.00000,0.00350,233.83845
34.40000,1.72002,19199.26554,0.00000,0.00355,236.21144
34.80000,1.74005,19392.48294,0.00000,0.00361,238.58862
35.20000,1.76002,19583.71550,0.00000,0.00367,240.94138
35.60000,1.78005,19770.18714,0.00000,0.00373,243.23557
36.00000,1.80002,19951.90382,0.00000,0.00380,245.47126
36.40000,1.81993,20133.55196,0.00000,0.00387,247.70610
36.80000,1.83990,20308.93266,0.00000,0.00394,249.86384
37.20000,1.85981,20479.89517,0.00000,0.00402,251.96721
37.60000,1.87990,20644.50830,0.00000,0.00410,253.99247
38.00000,1.89993,20802.29968,0.00000,0.00418,255.93381
38.40000,1.92002,20954.52994,0.00000,0.00427,257.80672
38.80000,1.94011,21096.05670,0.00000,0.00436,259.54794
39.20000,1.96014,21230.61866,0.00000,0.00446,261.20348
39.60000,1.98005,21354.77513,0.00000,0.00456,262.73099
40.00000,2.00002,21469.85233,0.00000,0.00467,264.14681
40.40000,2.01993,21573.64041,0.00000,0.00479,265.42373
40.80000,2.03996,21669.29394,0.00000,0.00492,266.60057
41.20000,2.05999,21759.83787,0.00000,0.00506,267.71454
41.60000,2.07990,21841.41427,0.00000,0.00520,268.71819
42.00000,2.09987,21919.36076,0.00000,0.00535,269.67717
42.40000,2.11990,21987.78689,0.00000,0.00551,270.51903
42.80000,2.14005,22052.53690,0.00000,0.00567,271.31566
43.20000,2.16001,22110.25804,0.00000,0.00583,272.02581
43.60000,2.18016,22167.92405,0.00000,0.00599,272.73529
44.00000,2.20007,22218.48965,0.00000,0.00617,273.35740
44.40000,2.22004,22262.72374,0.00000,0.00635,273.90162
44.80000,2.24001,22305.21888,0.00000,0.00652,274.42444
45.20000,2.25992,22342.80407,0.00000,0.00670,274.88686
45.60000,2.27995,22379.66508,0.00000,0.00690,275.34037
46.00000,2.29992,22412.36120,0.00000,0.00709,275.74263
46.40000,2.31995,22444.93067,0.00000,0.00728,276.14334
46.80000,2.33992,22475.15917,0.00000,0.00747,276.51525
47.20000,2.35995,22503.97652,0.00000,0.00766,276.86979
47.60000,2.37998,22530.07144,0.00000,0.00786,277.19084
48.00000,2.40007,22554.75968,0.00000,0.00806,277.49458
48.40000,2.42016,22577.20679,0.00000,0.00827,277.77075
48.80000,2.44013,22600.28124,0.00000,0.00847,278.05464
49.20000,2.46004,22620.09233,0.00000,0.00867,278.29838
49.60000,2.48001,22638.93336,0.00000,0.00887,278.53018
50.00000,2.49998,22654.53190,0.00000,0.00908,278.72210
50.40000,2.51995,22671.28676,0.00000,0.00929,278.92823
50.80000,2.53992,22687.47091,0.00000,0.00950,279.12735
51.20000,2.56001,22705.94835,0.00000,0.00971,279.35468
51.60000,2.57998,22722.34857,0.00000,0.00992,279.55645
52.00000,2.59995,22738.45822,0.00000,0.01014,279.75465
52.40000,2.62004,22753.95244,0.00000,0.01035,279.94528
52.80000,2.64000,22766.72870,0.00000,0.01056,280.10247
53.20000,2.66015,22782.97096,0.00000,0.01078,280.30230
53.60000,2.68018,22795.22568,0.00000,0.01099,280.45307
54.00000,2.70009,22807.09445,0.00000,0.01121,280.59910
54.40000,2.72006,22822.67064,0.00000,0.01142,280.79073
54.80000,2.73997,22830.56229,0.00000,0.01164,280.88782
55.20000,2.75994,22842.34464,0.00000,0.01185,281.03278
55.60000,2.77991,22853.98543,0.00000,0.01206,281.17600
56.00000,2.79994,22868.26074,0.00000,0.01228,281.35163
56.40000,2.81997,22879.33528,0.00000,0.01249,281.48788
56.80000,2.84000,22892.34847,0.00000,0.01271,281.64799
57.20000,2.85997,22903.17416,0.00000,0.01292,281.78118
57.60000,2.88000,22914.00284,0.00000,0.01314,281.91440
58.00000,2.90009,22924.80916,0.00000,0.01335,282.04736
58.40000,2.92012,22936.23388,0.00000,0.01357,282.18792
58.80000,2.94009,22946.58422,0.00000,0.01378,282.31526
59.20000,2.96006,22955.29693,0.00000,0.01399,282.42245
59.60000,2.97991,22965.16299,0.00000,0.01421,282.54384
60.00000,2.99994,22974.40171,0.00000,0.01442,282.65750
60.40000,3.01997,22985.68040,0.00000,0.01463,282.79626
60.80000,3.03994,22995.88025,0.00000,0.01484,282.92175
61.20000,3.05997,23007.14701,0.00000,0.01506,283.06037
61.60000,3.07994,23018.26775,0.00000,0.01527,283.19719
62.00000,3.10003,23030.04414,0.00000,0.01549,283.34208
62.40000,3.11999,23036.67217,0.00000,0.01569,283.42362
62.80000,3.14008,23047.37568,0.00000,0.01590,283.55531
63.20000,3.16011,23057.30432,0.00000,0.01611,283.67746
63.60000,3.18008,23067.70533,0.00000,0.01633,283.80543
64.00000,3.19999,23073.82226,0.00000,0.01654,283.88069
64.40000,3.21996,23081.25794,0.00000,0.01674,283.97217
64.80000,3.23993,23090.91091,0.00000,0.01695,284.09093
65.20000,3.25990,23101.26424,0.00000,0.01716,284.21831
65.60000,3.27999,23112.20020,0.00000,0.01736,284.35286
66.00000,3.29996,23121.24819,0.00000,0.01757,284.46418
66.40000,3.31999,23133.31366,0.00000,0.01778,284.61262
66.80000,3.33996,23142.72672,0.00000,0.01799,284.72843
67.20000,3.35999,23152.24856,0.00000,0.01820,284.84558
67.60000,3.38008,23160.73030,0.00000,0.01840,284.94993
68.00000,3.40011,23169.43854,0.00000,0.01861,285.05707
68.40000,3.42002,23179.14367,0.00000,0.01881,285.17647
68.80000,3.43999,23186.55103,0.00000,0.01901,285.26761
69.20000,3.45990,23194.48590,0.00000,0.01922,285.36523
69.60000,3.47993,23203.28057,0.00000,0.01942,285.47343
70.00000,3.49996,23213.05275,0.00000,0.01963,285.59366
70.40000,3.51993,23221.29905,0.00000,0.01983,285.69512
70.80000,3.54002,23232.27674,0.00000,0.02003,285.83018
71.20000,3.55993,23240.95964,0.00000,0.02023,285.93700
71.60000,3.57996,23250.81527,0.00000,0.02044,286.05826
72.00000,3.59999,23258.88127,0.00000,0.02065,286.15750
72.40000,3.62007,23267.76087,0.00000,0.02085,286.26674
72.80000,3.64004,23275.35599,0.00000,0.02105,286.36019
73.20000,3.66007,23282.94516,0.00000,0.02125,286.45356
73.60000,3.68004,23290.07238,0.00000,0.02145,286.54124
74.00000,3.69995,23299.72386,0.00000,0.02165,286.65999
74.40000,3.71992,23308.64221,0.00000,0.02185,286.76971
74.80000,3.73989,23314.52072,0.00000,0.02205,286.84204
75.20000,3.76004,23324.94408,0.00000,0.02225,286.97028
75.60000,3.77995,23333.64040,0.00000,0.02245,287.07727
76.00000,3.79992,23345.20817,0.00000,0.02266,287.21959
76.40000,3.82001,23353.38891,0.00000,0.02286,287.32024
76.80000,3.84004,23360.94379,0.00000,0.02305,287.41319
77.20000,3.86001,23368.00247,0.00000,0.02324,287.50003
77.60000,3.88010,23376.76734,0.00000,0.02344,287.60787
78.00000,3.90007,23385.27888,0.00000,0.02365,287.71258
78.40000,3.92004,23391.76089,0.00000,0.02384,287.79233
78.80000,3.94001,23401.61502,0.00000,0.02404,287.91357
79.20000,3.95992,23408.89871,0.00000,0.02423,288.00318
79.60000,3.97989,23415.74132,0.00000,0.02443,288.08737
80.00000,3.99998,23425.67593,0.00000,0.02463,288.20960
80.40000,4.02001,23434.31115,0.00000,0.02482,288.31584
80.80000,4.04004,23444.21744,0.00000,0.02502,288.43771
81.20000,4.06001,23452.27599,0.00000,0.02521,288.53686
81.60000,4.07998,23459.75637,0.00000,0.02540,288.62889
82.00000,4.10006,23465.40391,0.00000,0.02560,288.69837
82.40000,4.12003,23474.04510,0.00000,0.02580,288.80469
82.80000,4.14006,23482.69373,0.00000,0.02599,288.91109
83.20000,4.16003,23489.91483,0.00000,0.02618,288.99994
83.60000,4.17994,23496.77533,0.00000,0.02638,289.08434
84.00000,4.19991,23504.53734,0.00000,0.02656,289.17984
84.40000,4.21982,23509.66781,0.00000,0.02676,289.24296
84.80000,4.23991,23519.23287,0.00000,0.02695,289.36064
85.20000,4.26000,23527.02916,0.00000,0.02715,289.45656
85.60000,4.28003,23536.25447,0.00000,0.02734,289.57006
86.00000,4.30000,23544.56186,0.00000,0.02753,289.67227
86.40000,4.32003,23552.80370,0.00000,0.02772,289.77367
86.80000,4.34000,23557.68234,0.00000,0.02792,289.83369
87.20000,4.36003,23564.51899,0.00000,0.02810,289.91780
87.60000,4.38006,23572.78913,0.00000,0.02829,290.01955
88.00000,4.40003,23580.40810,0.00000,0.02848,290.11329
88.40000,4.42000,23588.29975,0.00000,0.02867,290.21038
88.80000,4.43991,23593.75209,0.00000,0.02887,290.27746
89.20000,4.45988,23600.07763,0.00000,0.02906,290.35529
89.60000,4.47991,23608.73967,0.00000,0.02924,290.46186
90.00000,4.50000,23617.50305,0.00000,0.02943,290.56967
90.40000,4.52003,23625.75978,0.00000,0.02962,290.67126
90.80000,4.54006,23632.22837,0.00000,0.02981,290.75084
91.20000,4.56003,23639.05758,0.00000,0.03000,290.83486
91.60000,4.58005,23645.92999,0.00000,0.03018,290.91941
92.00000,4.60002,23652.57889,0.00000,0.03037,291.00122
92.40000,4.62017,23660.72685,0.00000,0.03056,291.10146
92.80000,4.64008,23664.66522,0.00000,0.03074,291.14992
93.20000,4.65999,23671.20385,0.00000,0.03093,291.23036
93.60000,4.67984,23678.98375,0.00000,0.03111,291.32608
94.00000,4.69987,23684.25280,0.00000,0.03129,291.39091
94.40000,4.71990,23690.75119,0.00000,0.03147,291.47086
94.80000,4.73993,23697.55358,0.00000,0.03166,291.55455
95.20000,4.76002,23708.50891,0.00000,0.03185,291.68933
95.60000,4.77999,23715.08032,0.00000,0.03204,291.77018
96.00000,4.80008,23722.35507,0.00000,0.03222,291.85968
96.40000,4.82005,23726.41861,0.00000,0.03239,291.90968
96.80000,4.84002,23732.56385,0.00000,0.03257,291.98528
97.20000,4.86011,23741.08732,0.00000,0.03275,292.09015
97.60000,4.88002,23744.82900,0.00000,0.03294,292.13618
98.00000,4.89993,23752.61039,0.00000,0.03312,292.23192
98.40000,4.91990,23759.22352,0.00000,0.03330,292.31328
98.80000,4.93987,23763.90100,0.00000,0.03348,292.37083
99.20000,4.95990,23769.76907,0.00000,0.03366,292.44303
99.60000,4.97999,23777.10938,0.00000,0.03383,292.53333
100.00000,5.00008,23784.83266,0.00000,0.03402,292.62835
100.40000,5.02016,23792.19234,0.00000,0.03419,292.71890
100.80000,5.04007,23798.42550,0.00000,0.03437,292.79559
101.20000,5.06004,23803.49189,0.00000,0.03455,292.85792
101.60000,5.08001,23809.36444,0.00000,0.03473,292.93017
102.00000,5.10004,23814.60667,0.00000,0.03490,292.99467
102.40000,5.12001,23819.47786,0.00000,0.03508,293.05460
102.80000,5.13998,23825.95092,0.00000,0.03525,293.13424
103.20000,5.15983,23829.28878,0.00000,0.03542,293.17530
103.60000,5.17986,23835.72161,0.00000,0.03560,293.25445
104.00000,5.19995,23842.41372,0.00000,0.03577,293.33678
104.40000,5.21998,23850.00885,0.00000,0.03595,293.43023
104.80000,5.24013,23857.49221,0.00000,0.03613,293.52230
105.20000,5.26010,23861.84931,0.00000,0.03630,293.57590
105.60001,5.28007,23868.52801,0.00000,0.03647,293.65807
106.00001,5.30004,23874.37671,0.00000,0.03664,293.73003
106.40001,5.32001,23878.67719,0.00000,0.03681,293.78294
106.80001,5.33998,23881.23721,0.00000,0.03698,293.81443
107.20001,5.36007,23887.55679,0.00000,0.03716,293.89218
107.60001,5.37992,23891.03472,0.00000,0.03733,293.93497
108.00001,5.39989,23898.99939,0.00000,0.03749,294.03296
108.40001,5.41992,23904.95092,0.00000,0.03766,294.10619
108.80001,5.43995,23910.76833,0.00000,0.03783,294.17776
109.20001,5.46004,23917.13709,0.00000,0.03801,294.25612
109.60001,5.48013,23923.27487,0.00000,0.03818,294.33163
110.00001,5.50009,23928.63780,0.00000,0.03835,294.39761
110.40001,5.52012,23935.68456,0.00000,0.03851,294.48431
110.80001,5.54009,23939.45158,0.00000,0.03868,294.53065
111.20001,5.56000,23943.27819,0.00000,0.03885,294.57773
111.60001,5.58003,23948.27753,0.00000,0.03902,294.63924
112.00001,5.60000,23952.70765,0.00000,0.03919,294.69375
112.40001,5.61991,23957.99905,0.00000,0.03936,294.75885
112.80001,5.63994,23964.14280,0.00000,0.03952,294.83443
113.20001,5.65991,23972.33546,0.00000,0.03969,294.93523
113.60001,5.67994,23976.64934,0.00000,0.03986,294.98830
114.00001,5.69997,23981.32831,0.00000,0.04003,295.04587
114.40001,5.72006,23987.41245,0.00000,0.04020,295.12072
114.80001,5.74009,23994.79449,0.00000,0.04037,295.21155
115.20001,5.76006,23999.16947,0.00000,0.04053,295.26537
115.60001,5.78003,24002.07967,0.00000,0.04070,295.30118
116.00001,5.80006,24005.92566,0.00000,0.04086,295.34849
116.40001,5.81997,24007.66164,0.00000,0.04103,295.36985
116.80001,5.83994,24013.96334,0.00000,0.04120,295.44738
117.20001,5.85991,24019.88357,0.00000,0.04136,295.52022
117.60001,5.87988,24025.26587,0.00000,0.04153,295.58644
118.00001,5.89991,24030.43211,0.00000,0.04169,295.65000
118.40001,5.91994,24035.44337,0.00000,0.04185,295.71166
118.80001,5.93997,24039.97481,0.00000,0.04202,295.76741
119.20001,5.96006,24046.73696,0.00000,0.04218,295.85060
119.60001,5.98009,24051.32651,0.00000,0.04235,295.90707
120.00001,6.00006,24056.18280,0.00000,0.04251,295.96682
120.40001,6.02002,24060.03624,0.00000,0.04268,296.01423
120.80001,6.03987,24062.02555,0.00000,0.04284,296.03870
121.20001,6.05996,24066.99955,0.00000,0.04301,296.09990
121.60001,6.07999,24072.25221,0.00000,0.04317,296.16452
122.00001,6.09996,24077.30222,0.00000,0.04334,296.22665
122.40001,6.11993,24082.45355,0.00000,0.04350,296.29003
122.80001,6.13996,24088.56153,0.00000,0.04366,296.36518
123.20001,6.15993,24091.23331,0.00000,0.04383,296.39805
123.60001,6.17996,24095.83628,0.00000,0.04399,296.45468
124.00001,6.20005,24100.89374,0.00000,0.04416,296.51690
124.40001,6.22008,24107.00023,0.00000,0.04434,296.59203
124.80001,6.24011,24109.99388,0.00000,0.04450,296.62886
125.20001,6.26002,24112.94580,0.00000,0.04467,296.66518
125.60001,6.27999,24116.86331,0.00000,0.04482,296.71338
126.00001,6.29996,24119.69304,0.00000,0.04498,296.74819
126.40001,6.31999,24124.47482,0.00000,0.04515,296.80702
126.80001,6.34002,24129.76772,0.00000,0.04531,296.87214
127.20001,6.35999,24133.63010,0.00000,0.04548,296.91966
127.60001,6.37990,24137.88289,0.00000,0.04564,296.97198
128.00001,6.39993,24143.40973,0.00000,0.04581,297.03998
128.40001,6.41996,24147.42857,0.00000,0.04596,297.08943
128.80001,6.44005,24151.45785,0.00000,0.04612,297.13900
129.20001,6.46014,24155.85816,0.00000,0.04629,297.19314
129.60001,6.48004,24161.03631,0.00000,0.04645,297.25684
130.00001,6.50001,24164.68412,0.00000,0.04661,297.30172
130.40001,6.51998,24167.25010,0.00000,0.04677,297.33329
130.80001,6.54001,24171.21679,0.00000,0.04693,297.38210
131.20001,6.55998,24175.37272,0.00000,0.04710,297.43323
131.60001,6.58001,24181.05602,0.00000,0.04726,297.50315
132.00001,6.59998,24183.15113,0.00000,0.04743,297.52893
132.40001,6.61995,24187.37859,0.00000,0.04759,297.58094
132.80001,6.63980,24191.91003,0.00000,0.04775,297.63669
133.20001,6.65995,24198.02845,0.00000,0.04790,297.71196
133.60001,6.68004,24200.11610,0.00000,0.04806,297.73765
134.00001,6.70013,24205.19441,0.00000,0.04822,297.80013
134.40001,6.72010,24209.74076,0.00000,0.04839,297.85606
134.80001,6.74001,24213.80281,0.00000,0.04856,297.90604
135.20001,6.75998,24217.32694,0.00000,0.04872,297.94940
135.60001,6.78001,24217.91703,0.00000,0.04888,297.95666
136.00001,6.79998,24222.44102,0.00000,0.04904,298.01232
136.40001,6.81995,24226.68040,0.00000,0.04920,298.06447
136.80001,6.84004,24231.34148,0.00000,0.04936,298.12182
137.20001,6.85995,24234.44390,0.00000,0.04953,298.15999
137.60001,6.87998,24237.35708,0.00000,0.04969,298.19583
138.00001,6.89995,24241.85872,0.00000,0.04985,298.25121
138.40001,6.92004,24246.48106,0.00000,0.05001,298.30808
138.80001,6.94013,24251.74862,0.00000,0.05017,298.37289
139.20001,6.96009,24254.93896,0.00000,0.05033,298.41214
139.60001,6.98006,24258.61508,0.00000,0.05050,298.45737
140.00001,7.00003,24262.80975,0.00000,0.05065,298.50898
140.40001,7.02000,24263.88115,0.00000,0.05081,298.52216
140.80001,7.03991,24265.35189,0.00000,0.05097,298.54025
141.20001,7.06000,24267.92234,0.00000,0.05113,298.57188
141.60001,7.07991,24273.33593,0.00000,0.05129,298.63848
142.00001,7.09994,24278.74058,0.00000,0.05146,298.70498
142.40001,7.11991,24282.23193,0.00000,0.05162,298.74793
142.80001,7.13994,24285.58618,0.00000,0.05178,298.78920
143.20001,7.16003,24288.24604,0.00000,0.05194,298.82192
143.60001,7.18006,24292.76407,0.00000,0.05210,298.87751
144.00001,7.20003,24296.38207,0.00000,0.05225,298.92202
144.40001,7.22006,24299.03895,0.00000,0.05241,298.95471
144.80001,7.24003,24301.23985,0.00000,0.05258,298.98179
145.20001,7.25994,24301.36949,0.00000,0.05274,298.98338
145.60001,7.27997,24305.95160,0.00000,0.05290,299.03976
146.00001,7.29994,24306.89931,0.00000,0.05305,299.05142
146.40001,7.31997,24312.09534,0.00000,0.05321,299.11535
146.80001,7.33994,24315.67758,0.00000,0.05337,299.15942
147.20001,7.35997,24320.81252,0.00000,0.05353,299.22260
147.60001,7.38000,24324.87458,0.00000,0.05369,299.27257
148.00001,7.40003,24326.09051,0.00000,0.05385,299.28753
148.40001,7.42011,24328.55964,0.00000,0.05401,299.31791
148.80001,7.44014,24333.68415,0.00000,0.05417,299.38096
149.20001,7.46011,24335.82693,0.00000,0.05433,299.40732
149.60001,7.48002,24336.06833,0.00000,0.05448,299.41029
150.00001,7.49999,24338.63878,0.00000,0.05465,299.44191
150.40001,7.51990,24338.80568,0.00000,0.05480,299.44397
150.80001,7.53993,24343.94807,0.00000,0.05496,299.50724
151.20001,7.55996,24348.15913,0.00000,0.05511,299.55904
151.60001,7.57993,24351.01867,0.00000,0.05527,299.59423
152.00001,7.59996,24355.47411,0.00000,0.05543,299.64904
152.40001,7.61999,24359.06529,0.00000,0.05559,299.69322
152.80001,7.64002,24361.22000,0.00000,0.05575,299.71973
153.20001,7.66011,24364.06165,0.00000,0.05590,299.75470
153.60001,7.68014,24367.38461,0.00000,0.05606,299.79558
154.00001,7.70005,24368.78234,0.00000,0.05621,299.81277
154.40001,7.72002,24371.35875,0.00000,0.05637,299.84447
154.80001,7.73993,24370.91321,0.00000,0.05653,299.83899
155.20001,7.75990,24371.95182,0.00000,0.05668,299.85177
155.60001,7.77993,24376.95563,0.00000,0.05684,299.91333
156.00001,7.79996,24381.94156,0.00000,0.05700,299.97467
156.40001,7.81999,24386.33889,0.00000,0.05717,300.02878
156.80001,7.84002,24390.15657,0.00000,0.05732,300.07575
157.20001,7.86005,24391.83444,0.00000,0.05748,300.09639
157.60001,7.88008,24393.11743,0.00000,0.05764,300.11217
158.00001,7.90010,24395.33472,0.00000,0.05780,300.13945
158.40001,7.92013,24397.61311,0.00000,0.05796,300.16748
158.80001,7.94010,24400.60675,0.00000,0.05811,300.20432
159.20001,7.96001,24401.55745,0.00000,0.05827,300.21601
159.60001,7.97998,24403.08630,0.00000,0.05842,300.23482
160.00001,7.99983,24404.00273,0.00000,0.05858,300.24610
160.40001,8.01992,24407.25118,0.00000,0.05874,300.28606
160.80001,8.04001,24411.35645,0.00000,0.05889,300.33657
161.20001,8.06004,24415.08472,0.00000,0.05905,300.38244
161.60001,8.08001,24417.39589,0.00000,0.05920,300.41087
162.00001,8.10004,24420.40145,0.00000,0.05936,300.44785
162.40001,8.12007,24421.67252,0.00000,0.05951,300.46349
162.80001,8.14010,24423.11794,0.00000,0.05967,300.48127
163.20001,8.16013,24425.45444,0.00000,0.05983,300.51002
163.60001,8.18004,24426.63610,0.00000,0.05998,300.52456
164.00001,8.20001,24427.43480,0.00000,0.06013,300.53438
164.40001,8.21998,24428.71183,0.00000,0.06028,300.55010
164.80001,8.23989,24430.20493,0.00000,0.06044,300.56847
165.20001,8.25992,24434.75872,0.00000,0.06059,300.62449
165.60001,8.28001,24438.55703,0.00000,0.06075,300.67122
166.00001,8.30004,24440.17678,0.00000,0.06091,300.69115
166.40001,8.32007,24443.16000,0.00000,0.06106,300.72785
166.80001,8.33998,24444.73803,0.00000,0.06121,300.74727
167.20001,8.36007,24447.50369,0.00000,0.06136,300.78130
167.60001,8.38004,24449.21732,0.00000,0.06151,300.80238
168.00001,8.40012,24449.57197,0.00000,0.06166,300.80674
168.40001,8.42009,24452.16179,0.00000,0.06181,300.83860
168.80001,8.44000,24453.71896,0.00000,0.06197,300.85776
169.20001,8.45991,24455.41173,0.00000,0.06212,300.87859
169.60001,8.47988,24457.02404,0.00000,0.06228,300.89843
170.00001,8.49991,24458.18484,0.00000,0.06243,300.91271
170.40001,8.51988,24461.48396,0.00000,0.06258,300.95330
170.80001,8.54003,24464.49101,0.00000,0.06274,300.99029
171.20001,8.56000,24467.67986,0.00000,0.06289,301.02953
171.60001,8.58003,24469.56336,0.00000,0.06304,301.05270
172.00001,8.60006,24469.41584,0.00000,0.06319,301.05088
172.40001,8.62003,24470.80016,0.00000,0.06333,301.06792
172.80001,8.64012,24474.14845,0.00000,0.06349,301.10911
173.20001,8.66009,24474.22743,0.00000,0.06364,301.11008
173.60001,8.68000,24474.77728,0.00000,0.06380,301.11685
174.00001,8.69997,24478.67990,0.00000,0.06395,301.16486
174.40001,8.71988,24480.20577,0.00000,0.06410,301.18363
174.80001,8.73985,24479.74831,0.00000,0.06426,301.17801
175.20001,8.76000,24481.49920,0.00000,0.06441,301.19955
175.60001,8.78003,24484.84153,0.00000,0.06456,301.24067
176.00001,8.80006,24487.35088,0.00000,0.06471,301.27154
176.40001,8.82003,24488.90507,0.00000,0.06486,301.29066
176.80001,8.84006,24492.51115,0.00000,0.06501,301.33503
177.20001,8.86003,24493.82544,0.00000,0.06517,301.35120
177.60001,8.88005,24494.81934,0.00000,0.06532,301.36343
178.00001,8.90002,24494.52430,0.00000,0.06547,301.35980
178.40001,8.91999,24497.62076,0.00000,0.06562,301.39789
178.80001,8.93990,24498.37476,0.00000,0.06577,301.40717
179.20001,8.95987,24500.02879,0.00000,0.06593,301.42752
179.60001,8.97996,24502.78550,0.00000,0.06608,301.46144
180.00001,8.99993,24501.78564,0.00000,0.06624,301.44913
180.40001,9.02002,24503.81219,0.00000,0.06639,301.47407
180.80001,9.03999,24506.99359,0.00000,0.06654,301.51321
181.20001,9.06002,24508.60143,0.00000,0.06669,301.53299
181.60001,9.08005,24511.57719,0.00000,0.06685,301.56960
182.00001,9.10002,24512.24327,0.00000,0.06700,301.57780
182.40001,9.11999,24511.07800,0.00000,0.06715,301.56346
182.80001,9.14008,24515.04469,0.00000,0.06731,301.61226
183.20001,9.15999,24515.82253,0.00000,0.06746,301.62183
183.60001,9.17996,24515.99389,0.00000,0.06761,301.62394
184.00001,9.19993,24514.83905,0.00000,0.06776,301.60973
184.40001,9.21990,24516.72256,0.00000,0.06792,301.63291
184.80001,9.23993,24520.06340,0.00000,0.06808,301.67401
185.20001,9.26002,24521.14224,0.00000,0.06823,301.68728
185.60001,9.28005,24524.15824,0.00000,0.06839,301.72439
186.00001,9.30008,24525.44570,0.00000,0.06853,301.74023
186.40001,9.32005,24526.72422,0.00000,0.06868,301.75596
186.80001,9.33996,24527.67938,0.00000,0.06884,301.76771
187.20001,9.36005,24528.63604,0.00000,0.06899,301.77948
187.60001,9.38007,24528.78952,0.00000,0.06914,301.78137
188.00001,9.40004,24529.49733,0.00000,0.06930,301.79008
188.40001,9.41995,24530.86674,0.00000,0.06945,301.80692
188.80001,9.43992,24531.84575,0.00000,0.06961,301.81897
189.20001,9.45995,24532.59528,0.00000,0.06975,301.82819
189.60001,9.47980,24531.33613,0.00000,0.06991,301.81270
190.00001,9.50001,24536.71992,0.00000,0.07006,301.87894
190.40001,9.52004,24538.48422,0.00000,0.07021,301.90064
190.80001,9.54007,24540.47799,0.00000,0.07037,301.92517
191.20001,9.56004,24540.62253,0.00000,0.07052,301.92695
191.60001,9.58001,24542.01877,0.00000,0.07067,301.94413
192.00001,9.59998,24541.02188,0.00000,0.07082,301.93186
192.40001,9.62001,24542.43898,0.00000,0.07098,301.94930
192.80001,9.64004,24542.09924,0.00000,0.07113,301.94512
193.20001,9.66001,24541.75800,0.00000,0.07128,301.94092
193.60001,9.67992,24544.20328,0.00000,0.07144,301.97100
194.00001,9.69989,24545.97056,0.00000,0.07159,301.99275
194.40001,9.71992,24545.50266,0.00000,0.07174,301.98699
194.80001,9.74007,24548.21616,0.00000,0.07189,302.02038
195.20001,9.76010,24550.19355,0.00000,0.07205,302.04470
195.60001,9.78007,24551.56147,0.00000,0.07220,302.06153
196.00001,9.80009,24551.86248,0.00000,0.07235,302.06524
196.40001,9.82000,24549.93427,0.00000,0.07251,302.04151
196.80001,9.83997,24551.36329,0.00000,0.07266,302.05910
197.20001,9.86000,24552.57475,0.00000,0.07280,302.07400
197.60001,9.88009,24552.03533,0.00000,0.07296,302.06736
198.00001,9.90006,24551.47356,0.00000,0.07311,302.06045
198.40001,9.91991,24551.65833,0.00000,0.07326,302.06273
198.80001,9.93988,24554.37332,0.00000,0.07342,302.09613
199.20001,9.95991,24554.78311,0.00000,0.07357,302.10117
199.60001,9.98000,24558.70658,0.00000,0.07372,302.14944
200.00001,10.00003,24558.90030,0.00000,0.07387,302.15182
200.40001,10.02012,24559.53360,0.00000,0.07402,302.15962
200.80001,10.04003,24560.98497,0.00000,0.07417,302.17747
201.20001,10.06000,24561.80453,0.00000,0.07432,302.18756
201.60001,10.07997,24560.20117,0.00000,0.07448,302.16783
202.00001,10.10000,24558.57992,0.00000,0.07463,302.14788
202.40001,10.12009,24560.84490,0.00000,0.07478,302.17575
202.80001,10.13994,24560.69589,0.00000,0.07493,302.17392
203.20001,10.15985,24562.37823,0.00000,0.07509,302.19461
203.60001,10.17994,24562.93106,0.00000,0.07524,302.20142
204.00001,10.19991,24564.25130,0.00000,0.07539,302.21766
204.40001,10.21994,24566.00666,0.00000,0.07554,302.23926
204.80001,10.24009,24567.93189,0.00000,0.07569,302.26294
205.20001,10.26012,24566.95884,0.00000,0.07584,302.25097
205.60001,10.28009,24567.62344,0.00000,0.07599,302.25915
206.00001,10.30000,24567.90358,0.00000,0.07615,302.26259
206.40001,10.31996,24568.67248,0.00000,0.07630,302.27205
206.80001,10.34005,24567.76351,0.00000,0.07646,302.26087
207.20001,10.36002,24568.10027,0.00000,0.07661,302.26501
207.60001,10.37993,24569.22084,0.00000,0.07676,302.27880
208.00001,10.39990,24571.30849,0.00000,0.07691,302.30448
208.40001,10.41987,24572.29942,0.00000,0.07706,302.31668
208.80001,10.43990,24571.71530,0.00000,0.07722,302.30949
209.20001,10.45999,24573.47512,0.00000,0.07737,302.33114
209.60001,10.48008,24574.92203,0.00000,0.07753,302.34894
210.00001,10.50011,24575.82504,0.00000,0.07768,302.36005
210.40001,10.52008,24576.02620,0.00000,0.07784,302.36253
210.80001,10.53999,24573.34250,0.00000,0.07799,302.32951
211.20001,10.56002,24574.05329,0.00000,0.07814,302.33825
211.60001,10.57999,24574.77599,0.00000,0.07830,302.34715
212.00001,10.59996,24575.69093,0.00000,0.07845,302.35840
212.40001,10.61999,24576.67589,0.00000,0.07861,302.37052
212.80001,10.63990,24576.67887,0.00000,0.07877,302.37056
213.20001,10.65987,24579.68444,0.00000,0.07892,302.40753
213.60001,10.67990,24580.36542,0.00000,0.07908,302.41591
214.00001,10.69999,24579.68593,0.00000,0.07924,302.40755
214.40001,10.72014,24578.97961,0.00000,0.07940,302.39886
214.80001,10.74017,24580.65599,0.00000,0.07956,302.41949
215.20001,10.76007,24580.86312,0.00000,0.07972,302.42204
215.60001,10.77999,24582.16846,0.00000,0.07987,302.43810
216.00001,10.80001,24579.75298,0.00000,0.08003,302.40838
216.40001,10.81993,24578.27628,0.00000,0.08019,302.39021
216.80001,10.83995,24580.45781,0.00000,0.08035,302.41705
217.20001,10.85992,24580.39820,0.00000,0.08051,302.41632
217.60001,10.87995,24581.03895,0.00000,0.08068,302.42420
218.00001,10.89992,24582.07458,0.00000,0.08084,302.43694
218.40001,10.91989,24583.17280,0.00000,0.08100,302.45045
218.80001,10.94004,24583.23538,0.00000,0.08116,302.45122
219.20001,10.96007,24580.31327,0.00000,0.08132,302.41527
219.60001,10.98016,24581.71993,0.00000,0.08148,302.43258
220.00001,11.00013,24583.29946,0.00000,0.08164,302.45201
220.40001,11.02004,24581.40552,0.00000,0.08180,302.42871
220.80001,11.04001,24581.92557,0.00000,0.08197,302.43511
221.20001,11.05998,24579.36108,0.00000,0.08213,302.40356
221.60001,11.07995,24579.04965,0.00000,0.08229,302.39972
222.00001,11.09998,24580.84375,0.00000,0.08245,302.42180
222.40001,11.11989,24582.26532,0.00000,0.08262,302.43929
222.80001,11.13992,24582.21167,0.00000,0.08278,302.43863
223.20001,11.16001,24580.53380,0.00000,0.08294,302.41798
223.60001,11.18004,24581.36231,0.00000,0.08310,302.42818
224.00001,11.20007,24581.11942,0.00000,0.08327,302.42519
224.40001,11.22016,24582.40092,0.00000,0.08343,302.44096
224.80001,11.24013,24581.78252,0.00000,0.08360,302.43335
225.20001,11.26004,24581.15369,0.00000,0.08376,302.42561
225.60001,11.28000,24581.11346,0.00000,0.08393,302.42512
226.00001,11.29991,24578.71735,0.00000,0.08409,302.39564
226.40001,11.31988,24579.21654,0.00000,0.08425,302.40178
226.80001,11.33997,24578.97812,0.00000,0.08445,302.39884
227.20001,11.35994,24578.64434,0.00000,0.08461,302.39474
227.60001,11.37991,24581.44128,0.00000,0.08478,302.42915
228.00001,11.39994,24579.57566,0.00000,0.08494,302.40620
228.40001,11.41997,24577.82775,0.00000,0.08510,302.38469
228.80001,11.44006,24578.87232,0.00000,0.08526,302.39754
229.20001,11.46015,24580.16276,0.00000,0.08544,302.41342
229.60001,11.48012,24581.43085,0.00000,0.08560,302.42902
230.00001,11.50003,24580.01077,0.00000,0.08577,302.41155
230.40001,11.52000,24577.14826,0.00000,0.08593,302.37633
230.80001,11.53991,24575.12617,0.00000,0.08610,302.35145
231.20001,11.55988,24574.10842,0.00000,0.08626,302.33893
231.60001,11.57997,24575.88762,0.00000,0.08643,302.36082
232.00001,11.60006,24576.78318,0.00000,0.08659,302.37184
232.40001,11.62003,24575.83696,0.00000,0.08676,302.36020
232.80001,11.63994,24574.94438,0.00000,0.08692,302.34922
233.20001,11.66003,24575.81908,0.00000,0.08709,302.35998
233.60001,11.68006,24574.99802,0.00000,0.08725,302.34988
234.00001,11.70015,24574.79686,0.00000,0.08742,302.34740
234.40001,11.72006,24574.47201,0.00000,0.08758,302.34341
234.80001,11.73996,24572.14296,0.00000,0.08776,302.31475
235.20001,11.76000,24572.37095,0.00000,0.08792,302.31756
235.60001,11.77990,24569.49204,0.00000,0.08808,302.28214
236.00001,11.79993,24568.82298,0.00000,0.08824,302.27390
236.40001,11.81996,24567.88719,0.00000,0.08840,302.26239
236.80001,11.83999,24569.56804,0.00000,0.08857,302.28307
237.20001,11.85996,24568.80808,0.00000,0.08874,302.27372
237.60001,11.87999,24570.34588,0.00000,0.08891,302.29264
238.00001,11.89996,24569.95845,0.00000,0.08907,302.28787
238.40001,11.91999,24569.73046,0.00000,0.08923,302.28507
238.80001,11.94008,24569.39071,0.00000,0.08940,302.28089
239.20001,11.96005,24567.28965,0.00000,0.08956,302.25504
239.60001,11.98002,24567.30455,0.00000,0.08973,302.25522
240.00001,11.99999,24564.50313,0.00000,0.08989,302.22076
240.40001,12.01990,24562.73437,0.00000,0.09006,302.19900
240.80001,12.03993,24561.82092,0.00000,0.09022,302.18776
241.20001,12.06002,24561.61827,0.00000,0.09038,302.18526
241.60001,12.07999,24563.62844,0.00000,0.09055,302.21000
242.00001,12.10002,24562.69413,0.00000,0.09071,302.19850
242.40001,12.11999,24564.27813,0.00000,0.09088,302.21799
242.80001,12.14002,24562.40654,0.00000,0.09104,302.19496
243.20001,12.15999,24560.00000,0.00000,0.09120,302.16535
243.60001,12.18008,24559.79884,0.00000,0.09137,302.16288
244.00001,12.20017,24560.84937,0.00000,0.09154,302.17580
244.40001,12.22007,24557.19858,0.00000,0.09170,302.13089
244.80001,12.24004,24554.79503,0.00000,0.09186,302.10132
245.20001,12.25995,24552.71482,0.00000,0.09202,302.07572
245.60001,12.27992,24552.32441,0.00000,0.09218,302.07092
246.00001,12.29989,24550.70615,0.00000,0.09234,302.05101
246.40001,12.31998,24551.63300,0.00000,0.09250,302.06241
246.80001,12.33995,24552.86533,0.00000,0.09267,302.07758
247.20001,12.35998,24553.48372,0.00000,0.09283,302.08518
247.60001,12.38001,24553.37495,0.00000,0.09299,302.08385
248.00001,12.39998,24549.44104,0.00000,0.09315,302.03545
248.40001,12.42007,24548.26534,0.00000,0.09332,302.02098
248.80001,12.44004,24546.21643,0.00000,0.09347,301.99577
249.20001,12.46001,24546.51147,0.00000,0.09363,301.99940
249.60001,12.48004,24544.20775,0.00000,0.09379,301.97106
250.00001,12.49995,24541.14556,0.00000,0.09396,301.93339
250.40001,12.51986,24539.57647,0.00000,0.09412,301.91408
250.80001,12.53995,24540.02649,0.00000,0.09427,301.91962
251.20001,12.55998,24540.38709,0.00000,0.09443,301.92405
251.60001,12.58001,24541.11427,0.00000,0.09459,301.93300
252.00001,12.60004,24539.34103,0.00000,0.09475,301.91118
252.40001,12.62001,24539.32166,0.00000,0.09491,301.91095
252.80001,12.64004,24538.14894,0.00000,0.09507,301.89652
253.20001,12.66007,24534.05857,0.00000,0.09522,301.84619
253.60001,12.68010,24532.30917,0.00000,0.09538,301.82467
254.00001,12.70012,24530.85929,0.00000,0.09553,301.80683
254.40001,12.72009,24530.21556,0.00000,0.09568,301.79891
254.80001,12.73989,24527.01926,0.00000,0.09584,301.75959
255.20001,12.75991,24524.84816,0.00000,0.09599,301.73288
255.60001,12.77988,24522.54444,0.00000,0.09615,301.70453
256.00001,12.79997,24524.87350,0.00000,0.09629,301.73319
256.40001,12.81994,24525.08509,0.00000,0.09645,301.73579
256.80001,12.84003,24522.55189,0.00000,0.09660,301.70462
257.20001,12.86006,24520.93810,0.00000,0.09675,301.68477
257.60001,12.88003,24517.86697,0.00000,0.09690,301.64699
258.00001,12.90006,24517.13085,0.00000,0.09704,301.63793
258.40001,12.92009,24514.71090,0.00000,0.09719,301.60816
258.80001,12.94012,24512.38036,0.00000,0.09734,301.57948
259.20001,12.96003,24509.36139,0.00000,0.09750,301.54234
259.60001,12.97994,24509.30178,0.00000,0.09764,301.54161
260.00001,12.99985,24507.02488,0.00000,0.09778,301.51359
260.40001,13.01988,24503.71236,0.00000,0.09792,301.47284
260.80001,13.03997,24503.86733,0.00000,0.09806,301.47475
261.20001,13.06000,24502.97773,0.00000,0.09821,301.46380
261.60001,13.08003,24502.76762,0.00000,0.09834,301.46122
262.00001,13.10006,24499.62050,0.00000,0.09848,301.42250
262.40001,13.12003,24494.91322,0.00000,0.09861,301.36458
262.80001,13.14012,24492.55437,0.00000,0.09874,301.33556
263.20001,13.16003,24489.90047,0.00000,0.09888,301.30291
263.60001,13.18011,24489.55923,0.00000,0.09901,301.29871
264.00001,13.20002,24486.41211,0.00000,0.09914,301.25999
264.40001,13.21987,24482.69874,0.00000,0.09927,301.21431
264.80001,13.23991,24479.79003,0.00000,0.09940,301.17852
265.20001,13.25976,24475.33906,0.00000,0.09952,301.12376
265.60001,13.27990,24475.03358,0.00000,0.09964,301.12000
266.00001,13.29999,24471.73744,0.00000,0.09976,301.07945
266.40001,13.32008,24470.66754,0.00000,0.09988,301.06628
266.80001,13.34005,24466.76940,0.00000,0.10000,301.01832
267.20001,13.36008,24462.34226,0.00000,0.10011,300.96386
267.60001,13.38005,24456.14189,0.00000,0.10023,300.88757
268.00001,13.40002,24452.68631,0.00000,0.10033,300.84506
268.40001,13.42011,24448.22043,0.00000,0.10044,300.79011
268.80001,13.44002,24442.79641,0.00000,0.10054,300.72338
269.20001,13.45999,24438.49593,0.00000,0.10065,300.67047
269.60001,13.47990,24431.93793,0.00000,0.10074,300.58979
270.00001,13.49987,24424.53504,0.00000,0.10083,300.49871
270.40001,13.51996,24420.79335,0.00000,0.10093,300.45267
270.80001,13.54005,24414.98935,0.00000,0.10101,300.38127
271.20001,13.56008,24406.50463,0.00000,0.10110,300.27688
271.60001,13.58011,24399.14793,0.00000,0.10118,300.18637
272.00001,13.60008,24391.43062,0.00000,0.10126,300.09142
272.40001,13.62005,24381.51985,0.00000,0.10133,299.96949
272.80001,13.64008,24368.79873,0.00000,0.10140,299.81298
273.20001,13.66011,24354.39825,0.00000,0.10146,299.63581
273.60001,13.68002,24341.71587,0.00000,0.10152,299.47977
274.00001,13.69993,24327.26771,0.00000,0.10158,299.30201
274.40001,13.71989,24310.55456,0.00000,0.10163,299.09639
274.80001,13.73992,24291.28289,0.00000,0.10168,298.85929
275.20001,13.76001,24270.33931,0.00000,0.10172,298.60162
275.60001,13.78004,24247.71786,0.00000,0.10176,298.32330
276.00001,13.80013,24223.66589,0.00000,0.10180,298.02739
276.40001,13.82010,24191.57326,0.00000,0.10182,297.63255
276.80001,13.84013,24159.88743,0.00000,0.10184,297.24271
277.20001,13.86004,24121.55420,0.00000,0.10186,296.77109
277.60001,13.88001,24082.03632,0.00000,0.10187,296.28490
278.00001,13.90010,24037.34177,0.00000,0.10188,295.73501
278.40001,13.92007,23985.76587,0.00000,0.10188,295.10047
278.80001,13.93992,23930.32312,0.00000,0.10189,294.41835
279.20001,13.95989,23867.91259,0.00000,0.10188,293.65050
279.60001,13.97992,23801.07343,0.00000,0.10187,292.82817
280.00001,14.00001,23726.33070,0.00000,0.10186,291.90860
280.40001,14.02004,23647.06695,0.00000,0.10185,290.93340
280.80001,14.04013,23553.89893,0.00000,0.10183,289.78714
281.20001,14.06010,23445.18900,0.00000,0.10181,288.44967
281.60001,14.08007,23318.09402,0.00000,0.10178,286.88600
282.00001,14.10004,23178.64895,0.00000,0.10175,285.17039
282.40001,14.12007,23004.11463,0.00000,0.10170,283.02306
282.80001,14.14009,22743.39348,0.00000,0.10163,279.81537
283.09001,14.15462,21686.35130,0.00000,0.10039,266.81042
283.09801,14.15564,17762.86662,0.00000,0.09436,218.53921
283.10601,14.15702,12644.98979,0.00000,0.08961,155.57320