File: scratch/college-stuff/ME Lab/ME lab Fall 2013/group13/group13.is_tens_RawData/Specimen_RawData_2.csv
Time,Extension,Load,Strain 2,Tensile strain,Tensile stress
(sec),(mm),(N),(mm/mm),(mm/mm),(MPa)
0.00000,0.00000,-0.20360,0.00000,0.00000,-0.00253
0.30000,0.01345,7.98341,0.00000,0.00000,0.09911
0.60000,0.02989,16.12953,0.00000,0.00000,0.20024
0.90000,0.04502,20.62493,0.00000,0.00000,0.25605
1.20000,0.05997,32.94582,0.00000,0.00001,0.40901
1.50000,0.07504,39.49324,0.00000,0.00000,0.49030
1.80000,0.08998,48.94534,0.00000,0.00000,0.60764
2.10000,0.10511,59.69784,0.00000,0.00000,0.74113
2.40000,0.11994,69.73933,0.00000,0.00000,0.86580
2.70000,0.13506,85.06643,0.00000,-0.00001,1.05608
3.00000,0.14995,101.84179,0.00000,-0.00001,1.26434
3.30000,0.16496,122.81362,0.00000,-0.00002,1.52470
3.60000,0.18009,158.07680,0.00000,-0.00002,1.96248
3.90000,0.19491,212.46949,0.00000,-0.00002,2.63775
4.20000,0.21010,270.91589,0.00000,-0.00002,3.36335
4.50000,0.22493,340.90851,0.00000,-0.00002,4.23229
4.80000,0.24000,448.38609,0.00000,-0.00002,5.56660
5.10000,0.25500,590.88222,0.00000,-0.00001,7.33565
5.40000,0.27001,749.80771,0.00000,0.00001,9.30867
5.70000,0.28502,918.40122,0.00000,0.00003,11.40171
6.00000,0.29996,1094.30235,0.00000,0.00004,13.58548
6.30000,0.31503,1282.62406,0.00000,0.00007,15.92345
6.60000,0.32992,1471.21595,0.00000,0.00010,18.26477
6.90000,0.34505,1664.79684,0.00000,0.00012,20.66802
7.20000,0.35993,1842.82362,0.00000,0.00015,22.87818
7.50000,0.37500,2016.76562,0.00000,0.00018,25.03762
7.80000,0.38995,2186.80594,0.00000,0.00020,27.14863
8.10000,0.40495,2353.88391,0.00000,0.00023,29.22286
8.40000,0.42008,2515.11279,0.00000,0.00025,31.22448
8.70000,0.43491,2667.71037,0.00000,0.00028,33.11894
9.00000,0.45004,2814.84220,0.00000,0.00029,34.94554
9.30000,0.46492,2948.84890,0.00000,0.00031,36.60920
9.60000,0.47999,3087.14639,0.00000,0.00033,38.32613
9.90000,0.49494,3225.97697,0.00000,0.00035,40.04967
10.20000,0.50994,3366.84175,0.00000,0.00037,41.79847
10.50000,0.52501,3511.76150,0.00000,0.00039,43.59761
10.80000,0.53990,3647.75844,0.00000,0.00042,45.28598
11.10000,0.55503,3791.79306,0.00000,0.00044,47.07413
11.40000,0.56991,3931.19715,0.00000,0.00046,48.80480
11.70000,0.58498,4073.60159,0.00000,0.00047,50.57271
12.00000,0.59987,4218.20395,0.00000,0.00050,52.36791
12.30000,0.61493,4360.49700,0.00000,0.00052,54.13444
12.60000,0.63000,4508.44951,0.00000,0.00055,55.97124
12.90000,0.64489,4650.20537,0.00000,0.00057,57.73110
13.20000,0.66002,4799.65471,0.00000,0.00060,59.58647
13.50000,0.67490,4940.87040,0.00000,0.00062,61.33963
13.80000,0.69009,5092.32730,0.00000,0.00065,63.21993
14.10000,0.70498,5239.56157,0.00000,0.00067,65.04780
14.40000,0.72004,5390.29874,0.00000,0.00070,66.91917
14.70000,0.73499,5535.67782,0.00000,0.00073,68.72401
15.00000,0.75000,5683.21943,0.00000,0.00075,70.55570
15.30000,0.76501,5832.65387,0.00000,0.00077,72.41089
15.60000,0.77989,5975.90804,0.00000,0.00080,74.18936
15.90000,0.79508,6123.45077,0.00000,0.00083,76.02106
16.20000,0.80985,6265.35118,0.00000,0.00085,77.78272
16.50000,0.82504,6402.84941,0.00000,0.00087,79.48972
16.80000,0.83986,6531.09998,0.00000,0.00090,81.08192
17.10000,0.85505,6660.96136,0.00000,0.00092,82.69412
17.40000,0.87000,6793.01843,0.00000,0.00094,84.33357
17.70000,0.88494,6921.45154,0.00000,0.00096,85.92803
18.00000,0.90007,7055.08068,0.00000,0.00099,87.58700
18.30000,0.91490,7185.13876,0.00000,0.00101,89.20164
18.60000,0.93009,7321.42478,0.00000,0.00103,90.89360
18.90000,0.94491,7453.96316,0.00000,0.00106,92.53903
19.20000,0.95998,7590.75135,0.00000,0.00108,94.23722
19.50000,0.97493,7724.82306,0.00000,0.00110,95.90168
19.80000,0.98999,7860.82670,0.00000,0.00113,97.59013
20.10000,1.00500,7999.16312,0.00000,0.00115,99.30754
20.40000,1.01995,8134.25779,0.00000,0.00118,100.98471
20.70000,1.03508,8274.22217,0.00000,0.00120,102.72233
21.00000,1.04990,8412.42746,0.00000,0.00122,104.43811
21.30000,1.06503,8551.21315,0.00000,0.00125,106.16110
21.60000,1.07992,8691.64467,0.00000,0.00127,107.90452
21.90000,1.09504,8826.08816,0.00000,0.00130,109.57361
22.20000,1.10999,8969.15346,0.00000,0.00132,111.34972
22.50000,1.12494,9107.16578,0.00000,0.00135,113.06311
22.80000,1.14013,9250.31528,0.00000,0.00137,114.84028
23.10000,1.15489,9389.86167,0.00000,0.00140,116.57271
23.40000,1.17008,9536.07783,0.00000,0.00142,118.38794
23.70000,1.18497,9674.16614,0.00000,0.00145,120.10227
24.00000,1.19998,9819.43160,0.00000,0.00147,121.90571
24.30000,1.21498,9963.84993,0.00000,0.00150,123.69862
24.60000,1.22999,10106.14336,0.00000,0.00152,125.46516
24.90000,1.24500,10254.98733,0.00000,0.00155,127.31302
25.20000,1.25988,10394.69838,0.00000,0.00158,129.04750
25.50000,1.27507,10541.68567,0.00000,0.00160,130.87231
25.80000,1.28996,10682.60893,0.00000,0.00163,132.62183
26.10000,1.30503,10829.19315,0.00000,0.00166,134.44164
26.40000,1.31991,10978.67116,0.00000,0.00168,136.29737
26.70000,1.33498,11120.48551,0.00000,0.00171,138.05796
27.00000,1.35005,11270.46496,0.00000,0.00174,139.91991
27.30000,1.36499,11415.78332,0.00000,0.00177,141.72400
27.60000,1.38006,11566.07941,0.00000,0.00179,143.58989
27.90000,1.39489,11711.92527,0.00000,0.00182,145.40053
28.20000,1.41002,11866.10162,0.00000,0.00185,147.31459
28.50000,1.42490,12014.50974,0.00000,0.00187,149.15704
28.80000,1.43997,12162.54458,0.00000,0.00190,150.99485
29.10000,1.45498,12314.60348,0.00000,0.00193,152.88262
29.40000,1.46998,12462.95869,0.00000,0.00196,154.72441
29.70000,1.48499,12615.60917,0.00000,0.00199,156.61953
30.00000,1.49988,12763.89360,0.00000,0.00202,158.46044
30.30000,1.51507,12918.29944,0.00000,0.00205,160.37735
30.60000,1.52995,13066.61367,0.00000,0.00208,162.21863
30.90000,1.54502,13217.03494,0.00000,0.00210,164.08608
31.20000,1.55997,13368.15804,0.00000,0.00213,165.96223
31.50000,1.57497,13519.59705,0.00000,0.00216,167.84231
31.80000,1.59004,13674.14296,0.00000,0.00219,169.76095
32.10000,1.60493,13824.04119,0.00000,0.00222,171.62190
32.40000,1.62012,13978.33675,0.00000,0.00225,173.53744
32.70000,1.63494,14128.69841,0.00000,0.00228,175.40414
33.00000,1.65001,14284.46919,0.00000,0.00230,177.33800
33.30000,1.66490,14436.34629,0.00000,0.00234,179.22351
33.60000,1.67997,14591.58361,0.00000,0.00237,181.15074
33.90000,1.69491,14747.06829,0.00000,0.00240,183.08104
34.20000,1.70998,14897.31520,0.00000,0.00242,184.94632
34.50000,1.72499,15053.50173,0.00000,0.00246,186.88534
34.80000,1.73987,15202.46118,0.00000,0.00248,188.73463
35.10000,1.75500,15359.06345,0.00000,0.00252,190.67881
35.40000,1.76989,15513.02820,0.00000,0.00255,192.59024
35.70000,1.78502,15666.80223,0.00000,0.00258,194.49930
36.00000,1.79996,15822.21538,0.00000,0.00261,196.42872
36.30000,1.81497,15975.76439,0.00000,0.00264,198.33499
36.60000,1.83004,16134.33212,0.00000,0.00268,200.30357
36.90000,1.84492,16286.79633,0.00000,0.00271,202.19637
37.20000,1.86005,16445.24336,0.00000,0.00274,204.16345
37.50000,1.87488,16598.93841,0.00000,0.00277,206.07153
37.80000,1.89001,16755.94598,0.00000,0.00281,208.02074
38.10000,1.90489,16906.37618,0.00000,0.00284,209.88829
38.40000,1.91996,17063.47466,0.00000,0.00288,211.83863
38.70000,1.93491,17223.83648,0.00000,0.00291,213.82948
39.00000,1.94997,17373.16251,0.00000,0.00294,215.68333
39.30000,1.96504,17533.30082,0.00000,0.00298,217.67140
39.60000,1.97987,17680.42445,0.00000,0.00301,219.49790
39.90000,1.99512,17841.38680,0.00000,0.00304,221.49621
40.20000,2.00994,17995.91333,0.00000,0.00308,223.41462
40.50000,2.02507,18150.87944,0.00000,0.00311,225.33848
40.80000,2.03996,18306.55783,0.00000,0.00314,227.27119
41.10000,2.05496,18459.80138,0.00000,0.00318,229.17367
41.40000,2.07003,18616.46473,0.00000,0.00321,231.11860
41.70000,2.08486,18765.42121,0.00000,0.00325,232.96786
42.00000,2.10005,18922.58972,0.00000,0.00328,234.91906
42.30000,2.11493,19076.44868,0.00000,0.00332,236.82918
42.60000,2.13000,19229.10213,0.00000,0.00336,238.72434
42.90000,2.14489,19380.37574,0.00000,0.00339,240.60236
43.20000,2.16001,19531.10099,0.00000,0.00343,242.47358
43.50000,2.17496,19682.99896,0.00000,0.00347,244.35935
43.80000,2.18997,19828.81427,0.00000,0.00351,246.16961
44.10000,2.20504,19982.08314,0.00000,0.00355,248.07240
44.40000,2.21992,20125.57387,0.00000,0.00358,249.85380
44.70000,2.23511,20277.18872,0.00000,0.00362,251.73606
45.00000,2.24988,20418.01065,0.00000,0.00367,253.48433
45.30000,2.26506,20563.64715,0.00000,0.00371,255.29237
45.60000,2.27995,20707.58939,0.00000,0.00375,257.07937
45.90000,2.29496,20847.01359,0.00000,0.00379,258.81029
46.20000,2.31003,20986.93103,0.00000,0.00384,260.54733
46.50000,2.32491,21121.38718,0.00000,0.00388,262.21657
46.80000,2.34004,21255.66602,0.00000,0.00393,263.88360
47.10000,2.35487,21384.33456,0.00000,0.00398,265.48099
47.40000,2.36994,21515.31279,0.00000,0.00402,267.10705
47.70000,2.38494,21639.90438,0.00000,0.00408,268.65382
48.00000,2.39995,21760.20592,0.00000,0.00413,270.14734
48.30000,2.41496,21880.09620,0.00000,0.00418,271.63574
48.60000,2.43002,21991.75060,0.00000,0.00423,273.02190
48.90000,2.44509,22105.95012,0.00000,0.00429,274.43966
49.20000,2.45992,22208.39262,0.00000,0.00435,275.71146
49.50000,2.47511,22311.45352,0.00000,0.00440,276.99093
49.80000,2.48993,22406.30686,0.00000,0.00446,278.16851
50.10000,2.50506,22493.62320,0.00000,0.00452,279.25252
50.40000,2.51995,22579.36150,0.00000,0.00459,280.31694
50.70000,2.53495,22655.67929,0.00000,0.00466,281.26441
51.00000,2.55002,22731.23562,0.00000,0.00473,282.20242
51.30000,2.56485,22798.39814,0.00000,0.00480,283.03623
51.60000,2.58004,22860.67307,0.00000,0.00488,283.80935
51.90000,2.59498,22916.66418,0.00000,0.00495,284.50447
52.20000,2.61005,22972.18293,0.00000,0.00503,285.19372
52.50000,2.62500,23020.31666,0.00000,0.00512,285.79129
52.80000,2.64006,23065.49102,0.00000,0.00521,286.35211
53.10000,2.65501,23111.20778,0.00000,0.00530,286.91968
53.40000,2.67002,23145.95878,0.00000,0.00540,287.35110
53.70000,2.68509,23184.67349,0.00000,0.00550,287.83173
54.00000,2.69985,23215.31177,0.00000,0.00561,288.21210
54.30000,2.71516,23251.29807,0.00000,0.00573,288.65886
54.60000,2.72987,23277.78935,0.00000,0.00585,288.98774
54.90000,2.74500,23306.14030,0.00000,0.00598,289.33971
55.20000,2.76000,23333.82815,0.00000,0.00611,289.68345
55.50000,2.77501,23354.63166,0.00000,0.00624,289.94172
55.80000,2.79014,23379.85039,0.00000,0.00637,290.25480
56.10000,2.80490,23397.99404,0.00000,0.00651,290.48005
56.40000,2.82003,23419.42936,0.00000,0.00665,290.74617
56.70000,2.83492,23434.49891,0.00000,0.00679,290.93325
57.00000,2.84993,23452.61425,0.00000,0.00695,291.15815
57.30000,2.86493,23467.71359,0.00000,0.00710,291.34560
57.60000,2.88006,23483.05732,0.00000,0.00725,291.53609
57.90000,2.89501,23500.62728,0.00000,0.00741,291.75422
58.20000,2.91001,23510.62447,0.00000,0.00757,291.87833
58.50000,2.92508,23528.43583,0.00000,0.00774,292.09945
58.80000,2.93991,23537.49126,0.00000,0.00790,292.21188
59.10000,2.95516,23553.05105,0.00000,0.00806,292.40505
59.40000,2.96992,23561.62965,0.00000,0.00823,292.51155
59.70000,2.98505,23573.75175,0.00000,0.00839,292.66204
60.00000,3.00000,23586.21061,0.00000,0.00856,292.81671
60.30000,3.01489,23593.31101,0.00000,0.00872,292.90486
60.60000,3.03001,23606.96644,0.00000,0.00890,293.07439
60.90000,3.04496,23614.24714,0.00000,0.00907,293.16478
61.20000,3.06009,23627.15602,0.00000,0.00924,293.32504
61.50000,3.07497,23633.94946,0.00000,0.00941,293.40938
61.80000,3.08998,23645.02102,0.00000,0.00958,293.54683
62.10000,3.10499,23653.67562,0.00000,0.00975,293.65427
62.40000,3.12011,23661.72224,0.00000,0.00993,293.75417
62.70000,3.13500,23671.72837,0.00000,0.01010,293.87839
63.00000,3.15001,23676.26727,0.00000,0.01028,293.93474
63.30000,3.16508,23687.83504,0.00000,0.01045,294.07835
63.60000,3.17984,23693.43340,0.00000,0.01062,294.14786
63.90000,3.19509,23702.97909,0.00000,0.01079,294.26636
64.20000,3.20998,23711.42060,0.00000,0.01097,294.37116
64.50000,3.22499,23717.97413,0.00000,0.01114,294.45252
64.80000,3.24005,23726.77475,0.00000,0.01132,294.56178
65.10000,3.25494,23731.27043,0.00000,0.01149,294.61759
65.40000,3.27007,23742.51485,0.00000,0.01166,294.75719
65.70000,3.28495,23747.39349,0.00000,0.01183,294.81776
66.00000,3.30002,23758.23110,0.00000,0.01200,294.95230
66.30000,3.31497,23763.44502,0.00000,0.01218,295.01703
66.60000,3.33004,23772.77464,0.00000,0.01235,295.13286
66.90000,3.34492,23779.28048,0.00000,0.01252,295.21363
67.20000,3.36005,23787.09763,0.00000,0.01269,295.31067
67.50000,3.37506,23796.68355,0.00000,0.01286,295.42968
67.80000,3.38994,23797.60891,0.00000,0.01303,295.44117
68.10000,3.40513,23809.84128,0.00000,0.01321,295.59303
68.40000,3.41990,23814.63200,0.00000,0.01338,295.65251
68.70000,3.43509,23823.02284,0.00000,0.01355,295.75668
69.00000,3.44991,23830.20222,0.00000,0.01371,295.84581
69.30000,3.46492,23836.60823,0.00000,0.01388,295.92534
69.60000,3.48005,23845.30306,0.00000,0.01405,296.03328
69.90000,3.49493,23848.33097,0.00000,0.01422,296.07087
70.20000,3.51006,23857.52797,0.00000,0.01439,296.18505
70.50000,3.52495,23863.08163,0.00000,0.01455,296.25400
70.80000,3.54008,23873.17866,0.00000,0.01472,296.37935
71.10000,3.55496,23876.84435,0.00000,0.01489,296.42486
71.40000,3.57003,23886.55841,0.00000,0.01505,296.54545
71.70000,3.58492,23891.39980,0.00000,0.01522,296.60556
72.00000,3.60004,23898.49722,0.00000,0.01539,296.69367
72.30000,3.61493,23908.37520,0.00000,0.01556,296.81630
72.60000,3.62988,23910.66551,0.00000,0.01572,296.84474
72.90000,3.64513,23921.05013,0.00000,0.01589,296.97366
73.20000,3.65983,23922.68628,0.00000,0.01605,296.99397
73.50000,3.67502,23930.50492,0.00000,0.01621,297.09104
73.80000,3.68997,23939.29064,0.00000,0.01638,297.20011
74.10000,3.70498,23945.96040,0.00000,0.01654,297.28291
74.40000,3.72010,23955.40625,0.00000,0.01670,297.40018
74.70000,3.73499,23959.66053,0.00000,0.01686,297.45300
75.00000,3.75006,23965.54947,0.00000,0.01703,297.52611
75.30000,3.76500,23970.93326,0.00000,0.01719,297.59295
75.60000,3.78007,23980.74269,0.00000,0.01736,297.71473
75.90000,3.79490,23983.67375,0.00000,0.01752,297.75112
76.20000,3.81009,23994.05539,0.00000,0.01767,297.88000
76.50000,3.82491,23997.77323,0.00000,0.01783,297.92616
76.80000,3.84004,24003.71432,0.00000,0.01799,297.99991
77.10000,3.85505,24012.01576,0.00000,0.01815,298.10297
77.40000,3.86993,24015.58310,0.00000,0.01832,298.14726
77.70000,3.88512,24026.99441,0.00000,0.01849,298.28893
78.00000,3.89983,24028.68718,0.00000,0.01864,298.30995
78.30000,3.91508,24036.97819,0.00000,0.01880,298.41288
78.60000,3.93002,24043.18154,0.00000,0.01895,298.48989
78.90000,3.94497,24047.64593,0.00000,0.01911,298.54531
79.20000,3.96010,24056.87124,0.00000,0.01927,298.65984
79.50000,3.97504,24061.01972,0.00000,0.01943,298.71135
79.80000,3.99005,24068.50457,0.00000,0.01959,298.80427
80.10000,4.00500,24073.10009,0.00000,0.01975,298.86132
80.40000,4.02013,24082.90952,0.00000,0.01991,298.98310
80.70000,4.03495,24084.40262,0.00000,0.02006,299.00164
81.00000,4.05008,24094.49816,0.00000,0.02022,299.12697
81.30000,4.06497,24100.27385,0.00000,0.02037,299.19868
81.60000,4.08003,24103.73241,0.00000,0.02053,299.24161
81.90000,4.09504,24113.36601,0.00000,0.02068,299.36121
82.20000,4.10987,24114.01421,0.00000,0.02083,299.36926
82.50000,4.12506,24123.34830,0.00000,0.02099,299.48514
82.80000,4.13988,24129.35495,0.00000,0.02114,299.55971
83.10000,4.15501,24136.42704,0.00000,0.02130,299.64751
83.40000,4.16996,24143.99236,0.00000,0.02146,299.74143
83.70000,4.18497,24150.58315,0.00000,0.02162,299.82325
84.00000,4.20009,24157.70590,0.00000,0.02177,299.91168
84.30000,4.21498,24160.09307,0.00000,0.02192,299.94132
84.60000,4.23005,24169.02781,0.00000,0.02207,300.05224
84.90000,4.24499,24174.15529,0.00000,0.02222,300.11590
85.20000,4.26006,24181.04410,0.00000,0.02238,300.20142
85.50000,4.27489,24183.86191,0.00000,0.02253,300.23640
85.80000,4.29008,24193.85314,0.00000,0.02269,300.36044
86.10000,4.30496,24199.49174,0.00000,0.02284,300.43044
86.40000,4.32003,24202.47346,0.00000,0.02299,300.46746
86.70000,4.33504,24213.41836,0.00000,0.02315,300.60334
87.00000,4.34986,24215.75487,0.00000,0.02330,300.63234
87.30000,4.36517,24223.54519,0.00000,0.02345,300.72906
87.60000,4.37994,24228.76209,0.00000,0.02361,300.79382
87.90000,4.39501,24233.40827,0.00000,0.02375,300.85151
88.20000,4.41001,24241.62775,0.00000,0.02391,300.95355
88.50000,4.42496,24245.73153,0.00000,0.02406,301.00450
88.80000,4.44003,24254.38464,0.00000,0.02421,301.11192
89.10000,4.45497,24255.77044,0.00000,0.02437,301.12913
89.40000,4.47004,24263.84985,0.00000,0.02452,301.22943
89.70000,4.48499,24265.99413,0.00000,0.02467,301.25605
90.00000,4.50006,24276.77810,0.00000,0.02482,301.38993
90.30000,4.51488,24278.90450,0.00000,0.02497,301.41633
90.60000,4.53007,24285.92145,0.00000,0.02512,301.50344
90.90000,4.54496,24292.00113,0.00000,0.02527,301.57892
91.20000,4.55996,24293.79076,0.00000,0.02542,301.60114
91.50000,4.57509,24303.33942,0.00000,0.02558,301.71968
91.80000,4.58986,24305.84878,0.00000,0.02572,301.75084
92.10000,4.60511,24314.69560,0.00000,0.02587,301.86067
92.40000,4.61993,24320.21350,0.00000,0.02602,301.92917
92.70000,4.63506,24325.90425,0.00000,0.02617,301.99982
93.00000,4.65001,24331.92432,0.00000,0.02632,302.07456
93.30000,4.66502,24336.53176,0.00000,0.02647,302.13176
93.60000,4.68002,24343.91379,0.00000,0.02662,302.22340
93.90000,4.69497,24346.99982,0.00000,0.02677,302.26172
94.20000,4.70998,24355.23421,0.00000,0.02692,302.36394
94.50000,4.72492,24356.12082,0.00000,0.02707,302.37495
94.80000,4.73999,24364.83204,0.00000,0.02721,302.48310
95.10000,4.75488,24368.02983,0.00000,0.02736,302.52280
95.40000,4.77001,24374.54611,0.00000,0.02751,302.60370
95.70000,4.78495,24383.31246,0.00000,0.02766,302.71253
96.00000,4.79996,24384.76682,0.00000,0.02781,302.73058
96.30000,4.81509,24393.20683,0.00000,0.02796,302.83536
96.60000,4.82985,24396.25561,0.00000,0.02810,302.87321
96.90000,4.84516,24404.17707,0.00000,0.02825,302.97156
97.20000,4.85999,24408.82623,0.00000,0.02840,303.02927
97.50000,4.87506,24414.84183,0.00000,0.02855,303.10396
97.80000,4.88994,24420.37016,0.00000,0.02870,303.17259
98.10000,4.90501,24427.54358,0.00000,0.02885,303.26165
98.40000,4.92008,24431.44321,0.00000,0.02899,303.31006
98.70000,4.93496,24436.39040,0.00000,0.02914,303.37148
99.00000,4.95003,24441.78164,0.00000,0.02928,303.43841
99.30000,4.96498,24444.63223,0.00000,0.02943,303.47380
99.60000,4.97999,24453.77707,0.00000,0.02958,303.58733
99.90000,4.99487,24455.99437,0.00000,0.02973,303.61485
100.20000,5.01006,24462.60005,0.00000,0.02987,303.69686
100.50000,5.02501,24469.66320,0.00000,0.03002,303.78455
100.80000,5.03996,24470.90596,0.00000,0.03016,303.79998
101.10000,5.05508,24479.88093,0.00000,0.03031,303.91140
101.40000,5.06991,24482.54079,0.00000,0.03046,303.94442
101.70000,5.08510,24488.07657,0.00000,0.03060,304.01315
102.00000,5.09992,24491.44423,0.00000,0.03076,304.05496
102.30000,5.11505,24497.52092,0.00000,0.03090,304.13040
102.60000,5.13000,24503.11780,0.00000,0.03105,304.19988
102.90000,5.14495,24507.94876,0.00000,0.03119,304.25985
103.20000,5.16001,24515.36655,0.00000,0.03134,304.35194
103.50000,5.17496,24517.95042,0.00000,0.03148,304.38402
103.80000,5.19003,24523.53388,0.00000,0.03163,304.45334
104.10000,5.20491,24524.49948,0.00000,0.03177,304.46533
104.40000,5.21998,24532.75174,0.00000,0.03192,304.56778
104.70000,5.23487,24537.96417,0.00000,0.03206,304.63249
105.00000,5.25000,24541.73565,0.00000,0.03221,304.67931
105.30001,5.26500,24549.35759,0.00000,0.03235,304.77393
105.60001,5.28001,24551.23663,0.00000,0.03249,304.79726
105.90001,5.29514,24559.54701,0.00000,0.03264,304.90043
106.20001,5.30990,24562.08766,0.00000,0.03278,304.93198
106.50001,5.32509,24569.45777,0.00000,0.03293,305.02347
106.80001,5.33992,24572.77179,0.00000,0.03307,305.06462
107.10001,5.35505,24578.45956,0.00000,0.03321,305.13523
107.40001,5.36999,24580.78116,0.00000,0.03335,305.16405
107.70001,5.38494,24585.37668,0.00000,0.03350,305.22110
108.00001,5.40007,24592.84216,0.00000,0.03364,305.31378
108.30001,5.41490,24594.11025,0.00000,0.03379,305.32953
108.60001,5.43002,24602.59944,0.00000,0.03393,305.43492
108.90001,5.44497,24604.36225,0.00000,0.03407,305.45680
109.20001,5.46004,24610.07833,0.00000,0.03421,305.52777
109.50001,5.47498,24616.33086,0.00000,0.03435,305.60539
109.80001,5.49011,24620.31096,0.00000,0.03449,305.65480
110.10001,5.50506,24628.33971,0.00000,0.03463,305.75448
110.40001,5.52001,24627.36815,0.00000,0.03478,305.74242
110.70001,5.53513,24635.46246,0.00000,0.03492,305.84290
111.00001,5.54990,24636.89595,0.00000,0.03507,305.86070
111.30001,5.56509,24642.20673,0.00000,0.03521,305.92663
111.60001,5.57991,24647.35359,0.00000,0.03535,305.99053
111.90001,5.59504,24651.54231,0.00000,0.03549,306.04253
112.20001,5.60999,24656.11994,0.00000,0.03563,306.09936
112.50001,5.62500,24658.34916,0.00000,0.03577,306.12704
112.80001,5.64006,24664.42287,0.00000,0.03591,306.20244
113.10001,5.65495,24666.91434,0.00000,0.03605,306.23337
113.40001,5.67008,24674.98034,0.00000,0.03619,306.33351
113.70001,5.68490,24676.16051,0.00000,0.03633,306.34816
114.00001,5.69997,24682.88243,0.00000,0.03647,306.43161
114.30001,5.71486,24686.82826,0.00000,0.03661,306.48060
114.60001,5.73011,24690.63997,0.00000,0.03675,306.52792
114.90001,5.74499,24696.20407,0.00000,0.03689,306.59700
115.20001,5.75994,24697.13688,0.00000,0.03703,306.60858
115.50001,5.77513,24706.94184,0.00000,0.03717,306.73030
115.80001,5.78995,24705.24311,0.00000,0.03731,306.70921
116.10001,5.80514,24712.00824,0.00000,0.03744,306.79320
116.40001,5.81997,24714.09589,0.00000,0.03757,306.81912
116.70001,5.83504,24720.36630,0.00000,0.03771,306.89696
117.00001,5.84998,24723.62667,0.00000,0.03785,306.93744
117.30001,5.86493,24727.55313,0.00000,0.03799,306.98619
117.60001,5.88000,24733.55830,0.00000,0.03813,307.06074
117.90001,5.89500,24734.72804,0.00000,0.03827,307.07526
118.20001,5.91007,24741.74500,0.00000,0.03841,307.16237
118.50001,5.92490,24743.35730,0.00000,0.03854,307.18239
118.80001,5.94003,24750.12392,0.00000,0.03867,307.26640
119.10001,5.95497,24753.85219,0.00000,0.03881,307.31268
119.40001,5.97010,24756.95908,0.00000,0.03895,307.35125
119.70001,5.98499,24762.67368,0.00000,0.03909,307.42220
120.00001,5.99994,24761.77663,0.00000,0.03922,307.41106
120.30001,6.01506,24768.04703,0.00000,0.03936,307.48891
120.60001,6.02983,24770.05571,0.00000,0.03949,307.51385
120.90001,6.04502,24777.11439,0.00000,0.03963,307.60148
121.20001,6.05996,24778.61345,0.00000,0.03976,307.62009
121.50001,6.07503,24784.88088,0.00000,0.03989,307.69790
121.80001,6.09004,24788.42586,0.00000,0.04003,307.74191
122.10001,6.10493,24790.84134,0.00000,0.04017,307.77189
122.40001,6.12005,24797.61243,0.00000,0.04030,307.85595
122.70001,6.13500,24799.80141,0.00000,0.04043,307.88313
123.00001,6.15007,24805.61435,0.00000,0.04057,307.95530
123.30001,6.16495,24803.76661,0.00000,0.04070,307.93236
123.60001,6.18008,24809.85373,0.00000,0.04084,308.00793
123.90001,6.19491,24813.09325,0.00000,0.04097,308.04814
124.20001,6.21010,24818.09556,0.00000,0.04110,308.11025
124.50001,6.22504,24824.32127,0.00000,0.04124,308.18754
124.80001,6.23999,24824.90391,0.00000,0.04137,308.19477
125.10001,6.25512,24829.67526,0.00000,0.04150,308.25401
125.40001,6.26988,24831.08938,0.00000,0.04163,308.27156
125.70001,6.28495,24835.22147,0.00000,0.04176,308.32286
126.00001,6.29990,24839.15091,0.00000,0.04189,308.37164
126.30001,6.31491,24843.19210,0.00000,0.04203,308.42181
126.60001,6.33003,24848.32108,0.00000,0.04216,308.48549
126.90001,6.34498,24848.75619,0.00000,0.04229,308.49089
127.20001,6.36005,24855.10558,0.00000,0.04242,308.56972
127.50001,6.37499,24855.27247,0.00000,0.04255,308.57179
127.80001,6.39012,24862.98978,0.00000,0.04268,308.66760
128.10001,6.40489,24862.17469,0.00000,0.04281,308.65748
128.40001,6.42008,24868.32440,0.00000,0.04294,308.73383
128.70001,6.43496,24871.08260,0.00000,0.04307,308.76807
129.00001,6.45009,24872.45351,0.00000,0.04321,308.78509
129.30001,6.46504,24879.29165,0.00000,0.04333,308.86998
129.60001,6.47987,24878.60918,0.00000,0.04346,308.86151
129.90001,6.49517,24885.41603,0.00000,0.04359,308.94601
130.20001,6.50988,24886.35629,0.00000,0.04372,308.95769
130.50001,6.52501,24889.71651,0.00000,0.04385,308.99940
130.80001,6.53995,24894.63836,0.00000,0.04398,309.06051
131.10001,6.55496,24896.81393,0.00000,0.04411,309.08752
131.40001,6.57003,24902.27073,0.00000,0.04424,309.15526
131.70001,6.58492,24902.70138,0.00000,0.04437,309.16061
132.00001,6.60010,24909.24448,0.00000,0.04450,309.24184
132.30001,6.61505,24909.51717,0.00000,0.04462,309.24522
132.60001,6.63006,24914.36750,0.00000,0.04475,309.30544
132.90001,6.64488,24916.44919,0.00000,0.04488,309.33128
133.20001,6.66013,24920.81821,0.00000,0.04501,309.38552
133.50001,6.67490,24924.53456,0.00000,0.04514,309.43166
133.80001,6.68997,24924.92497,0.00000,0.04527,309.43651
134.10001,6.70503,24932.72573,0.00000,0.04539,309.53335
134.40001,6.71992,24932.33532,0.00000,0.04552,309.52850
134.70001,6.73511,24937.28101,0.00000,0.04565,309.58990
135.00001,6.74993,24940.86027,0.00000,0.04577,309.63434
135.30001,6.76500,24944.61834,0.00000,0.04590,309.68100
135.60001,6.78001,24947.69692,0.00000,0.04603,309.71921
135.90001,6.79502,24949.98276,0.00000,0.04617,309.74759
136.20001,6.81002,24952.78716,0.00000,0.04630,309.78241
136.50001,6.82503,24955.27714,0.00000,0.04642,309.81332
136.80001,6.84010,24960.24370,0.00000,0.04655,309.87498
137.10001,6.85498,24960.47020,0.00000,0.04668,309.87779
137.40001,6.87011,24965.96724,0.00000,0.04680,309.94604
137.70001,6.88494,24967.53484,0.00000,0.04692,309.96550
138.00001,6.90013,24971.94558,0.00000,0.04705,310.02026
138.30001,6.91495,24974.26569,0.00000,0.04718,310.04906
138.60001,6.93002,24974.86919,0.00000,0.04731,310.05655
138.90001,6.94509,24981.19026,0.00000,0.04744,310.13503
139.20001,6.95986,24979.98029,0.00000,0.04757,310.12000
139.50001,6.97510,24986.02271,0.00000,0.04769,310.19502
139.80001,6.98993,24988.95526,0.00000,0.04782,310.23143
140.10001,7.00500,24992.21414,0.00000,0.04794,310.27188
140.40001,7.02000,24997.50555,0.00000,0.04807,310.33758
140.70001,7.03501,25000.14007,0.00000,0.04820,310.37028
141.00001,7.05002,25002.36928,0.00000,0.04833,310.39796
141.30001,7.06509,25003.73721,0.00000,0.04845,310.41494
141.60001,7.08003,25010.01954,0.00000,0.04858,310.49293
141.90001,7.09498,25007.61449,0.00000,0.04870,310.46308
142.20001,7.11005,25014.41240,0.00000,0.04883,310.54747
142.50001,7.12487,25014.06968,0.00000,0.04896,310.54322
142.80001,7.14006,25018.45658,0.00000,0.04908,310.59768
143.10001,7.15495,25022.27426,0.00000,0.04921,310.64507
143.40001,7.16990,25021.70801,0.00000,0.04934,310.63804
143.70001,7.18502,25030.68149,0.00000,0.04947,310.74945
144.00001,7.19985,25030.76196,0.00000,0.04959,310.75045
144.30001,7.21510,25036.21578,0.00000,0.04972,310.81815
144.60001,7.22992,25037.23502,0.00000,0.04984,310.83081
144.90001,7.24499,25041.01694,0.00000,0.04997,310.87776
145.20001,7.26006,25043.23721,0.00000,0.05010,310.90532
145.50001,7.27507,25046.26513,0.00000,0.05022,310.94291
145.80001,7.28995,25048.69401,0.00000,0.05036,310.97307
146.10001,7.30502,25051.11396,0.00000,0.05048,311.00311
146.40001,7.32009,25056.33533,0.00000,0.05062,311.06793
146.70001,7.33491,25052.22857,0.00000,0.05074,311.01695
147.00001,7.35010,25061.49113,0.00000,0.05087,311.13194
147.30001,7.36487,25059.97717,0.00000,0.05099,311.11315
147.60001,7.38012,25065.74094,0.00000,0.05112,311.18470
147.90001,7.39500,25068.47978,0.00000,0.05124,311.21870
148.20001,7.40995,25068.20560,0.00000,0.05137,311.21530
148.50001,7.42514,25075.45650,0.00000,0.05150,311.30532
148.80001,7.43985,25075.00947,0.00000,0.05163,311.29977
149.10001,7.45503,25078.42481,0.00000,0.05176,311.34217
149.40001,7.46992,25080.68979,0.00000,0.05189,311.37029
149.70001,7.48505,25083.37796,0.00000,0.05202,311.40366
150.00001,7.50005,25085.81877,0.00000,0.05214,311.43396
150.30001,7.51506,25087.52346,0.00000,0.05227,311.45513
150.60001,7.53001,25090.85834,0.00000,0.05240,311.49653
150.90001,7.54507,25092.68820,0.00000,0.05253,311.51924
151.20001,7.56008,25097.77844,0.00000,0.05266,311.58244
151.50001,7.57491,25094.78331,0.00000,0.05278,311.54525
151.80001,7.59004,25100.01957,0.00000,0.05291,311.61026
152.10001,7.60492,25101.51863,0.00000,0.05304,311.62887
152.40001,7.61999,25102.43058,0.00000,0.05317,311.64019
152.70001,7.63494,25109.38644,0.00000,0.05330,311.72655
153.00001,7.64995,25109.55632,0.00000,0.05343,311.72866
153.30001,7.66513,25114.11309,0.00000,0.05356,311.78523
153.60001,7.67990,25114.24422,0.00000,0.05369,311.78686
153.90001,7.69509,25117.35260,0.00000,0.05382,311.82545
154.20001,7.71003,25119.16757,0.00000,0.05394,311.84798
154.50001,7.72498,25122.07627,0.00000,0.05407,311.88409
154.80001,7.73999,25123.89421,0.00000,0.05420,311.90666
155.10001,7.75506,25125.67341,0.00000,0.05432,311.92875
155.40001,7.76994,25128.50761,0.00000,0.05445,311.96393
155.70001,7.78495,25127.99501,0.00000,0.05459,311.95757
156.00001,7.80008,25133.72898,0.00000,0.05471,312.02875
156.30001,7.81485,25133.03459,0.00000,0.05484,312.02013
156.60001,7.83003,25138.52715,0.00000,0.05497,312.08832
156.90001,7.84486,25139.77289,0.00000,0.05510,312.10379
157.20001,7.86005,25140.83385,0.00000,0.05522,312.11696
157.50001,7.87505,25145.48600,0.00000,0.05535,312.17472
157.80001,7.88994,25145.18201,0.00000,0.05548,312.17094
158.10001,7.90513,25149.92952,0.00000,0.05561,312.22988
158.40001,7.91995,25151.63124,0.00000,0.05574,312.25101
158.70001,7.93508,25151.65210,0.00000,0.05587,312.25127
159.00001,7.94997,25152.75180,0.00000,0.05600,312.26492
159.30001,7.96504,25157.04334,0.00000,0.05612,312.31820
159.60001,7.97998,25156.81088,0.00000,0.05626,312.31531
159.90001,7.99505,25161.37064,0.00000,0.05638,312.37192
160.20001,8.00994,25163.55217,0.00000,0.05651,312.39900
160.50001,8.02501,25164.49690,0.00000,0.05664,312.41073
160.80001,8.04007,25168.16556,0.00000,0.05677,312.45628
161.10001,8.05484,25165.76648,0.00000,0.05690,312.42649
161.40001,8.07003,25171.20838,0.00000,0.05702,312.49405
161.70001,8.08491,25175.09758,0.00000,0.05715,312.54234
162.00001,8.10004,25175.03202,0.00000,0.05728,312.54152
162.30001,8.11505,25178.34604,0.00000,0.05741,312.58266
162.60001,8.12994,25177.30892,0.00000,0.05754,312.56979
162.90001,8.14518,25182.72698,0.00000,0.05767,312.63705
163.20001,8.15995,25180.53055,0.00000,0.05780,312.60978
163.50001,8.17502,25185.57310,0.00000,0.05792,312.67239
163.80001,8.19002,25185.84132,0.00000,0.05805,312.67572
164.10001,8.20503,25188.75897,0.00000,0.05818,312.71194
164.40001,8.21998,25188.46691,0.00000,0.05830,312.70831
164.70001,8.23493,25188.81261,0.00000,0.05842,312.71260
165.00001,8.24999,25195.04726,0.00000,0.05856,312.79001
165.30001,8.26494,25193.92371,0.00000,0.05869,312.77606
165.60001,8.28007,25199.73516,0.00000,0.05881,312.84820
165.90001,8.29483,25197.86656,0.00000,0.05894,312.82501
166.20001,8.31008,25202.02994,0.00000,0.05906,312.87669
166.50001,8.32497,25203.79722,0.00000,0.05919,312.89863
166.80001,8.34004,25204.33664,0.00000,0.05931,312.90533
167.10001,8.35504,25209.51927,0.00000,0.05944,312.96967
167.40001,8.36999,25210.53255,0.00000,0.05957,312.98225
167.70001,8.38512,25211.42066,0.00000,0.05970,312.99328
168.00001,8.39994,25210.94978,0.00000,0.05982,312.98743
168.30001,8.41507,25214.76150,0.00000,0.05995,313.03475
168.60001,8.43002,25214.01644,0.00000,0.06008,313.02550
168.90001,8.44503,25217.07416,0.00000,0.06020,313.06346
169.20001,8.45997,25218.40632,0.00000,0.06033,313.08000
169.50001,8.47504,25220.53123,0.00000,0.06045,313.10638
169.80001,8.49005,25225.09992,0.00000,0.06058,313.16310
170.10001,8.50500,25222.11373,0.00000,0.06071,313.12603
170.40001,8.52012,25228.90866,0.00000,0.06083,313.21039
170.70001,8.53483,25226.08042,0.00000,0.06096,313.17527
171.00001,8.55008,25231.78458,0.00000,0.06108,313.24609
171.30001,8.56490,25230.50904,0.00000,0.06120,313.23025
171.60001,8.58003,25231.01568,0.00000,0.06133,313.23654
171.90001,8.59504,25235.50987,0.00000,0.06146,313.29234
172.20001,8.60999,25233.00648,0.00000,0.06158,313.26126
172.50001,8.62511,25238.72256,0.00000,0.06171,313.33222
172.80001,8.64000,25236.42182,0.00000,0.06184,313.30366
173.10001,8.65507,25239.19940,0.00000,0.06196,313.33814
173.40001,8.66995,25239.50636,0.00000,0.06208,313.34195
173.70001,8.68502,25242.55216,0.00000,0.06220,313.37977
174.00001,8.69997,25243.18397,0.00000,0.06233,313.38761
174.30001,8.71498,25245.51153,0.00000,0.06244,313.41651
174.60001,8.72998,25249.23086,0.00000,0.06257,313.46268
174.90001,8.74505,25248.24440,0.00000,0.06270,313.45043
175.20001,8.76006,25250.30077,0.00000,0.06282,313.47596
175.50001,8.77489,25250.36335,0.00000,0.06295,313.47674
175.80001,8.79007,25253.19457,0.00000,0.06307,313.51189
176.10001,8.80496,25255.37014,0.00000,0.06320,313.53890
176.40001,8.82003,25254.59826,0.00000,0.06331,313.52932
176.70001,8.83503,25258.39508,0.00000,0.06344,313.57645
177.00001,8.84998,25257.04503,0.00000,0.06356,313.55969
177.30001,8.86511,25260.28454,0.00000,0.06368,313.59991
177.60001,8.87987,25257.86757,0.00000,0.06380,313.56990
177.90001,8.89500,25263.90254,0.00000,0.06392,313.64483
178.20001,8.91001,25263.63134,0.00000,0.06405,313.64146
178.50001,8.92502,25265.75625,0.00000,0.06417,313.66784
178.80001,8.93996,25267.60697,0.00000,0.06430,313.69082
179.10001,8.95497,25266.60562,0.00000,0.06441,313.67838
179.40001,8.97004,25271.88063,0.00000,0.06454,313.74387
179.70001,8.98499,25270.29216,0.00000,0.06466,313.72415
180.00001,9.00005,25273.75817,0.00000,0.06478,313.76718
180.30001,9.01488,25273.19491,0.00000,0.06491,313.76019
180.60001,9.03013,25274.49727,0.00000,0.06503,313.77636
180.90001,9.04495,25275.53141,0.00000,0.06515,313.78920
181.20001,9.06002,25276.99769,0.00000,0.06527,313.80740
181.50001,9.07509,25280.17759,0.00000,0.06539,313.84688
181.80001,9.08992,25279.96004,0.00000,0.06551,313.84418
182.10001,9.10504,25281.19087,0.00000,0.06564,313.85946
182.40001,9.11993,25280.31468,0.00000,0.06576,313.84858
182.70001,9.13500,25284.77609,0.00000,0.06588,313.90397
183.00001,9.14994,25284.12640,0.00000,0.06601,313.89590
183.30001,9.16495,25287.15432,0.00000,0.06613,313.93349
183.60001,9.17996,25287.25863,0.00000,0.06625,313.93479
183.90001,9.19503,25288.34343,0.00000,0.06637,313.94825
184.20001,9.21003,25290.25972,0.00000,0.06649,313.97204
184.50001,9.22492,25289.09743,0.00000,0.06661,313.95761
184.80001,9.24017,25294.41416,0.00000,0.06674,314.02362
185.10001,9.25494,25291.39817,0.00000,0.06685,313.98618
185.40001,9.27006,25294.86716,0.00000,0.06698,314.02924
185.70001,9.28501,25295.85063,0.00000,0.06711,314.04145
186.00001,9.30002,25292.92405,0.00000,0.06723,314.00512
186.30001,9.31508,25298.53582,0.00000,0.06735,314.07479
186.60001,9.32985,25297.35565,0.00000,0.06747,314.06014
186.90001,9.34504,25301.19717,0.00000,0.06759,314.10783
187.20001,9.35993,25300.86040,0.00000,0.06771,314.10365
187.50001,9.37499,25302.36542,0.00000,0.06784,314.12233
187.80001,9.39000,25302.49059,0.00000,0.06796,314.12389
188.10001,9.40501,25304.11780,0.00000,0.06809,314.14409
188.40001,9.42001,25305.85229,0.00000,0.06821,314.16562
188.70001,9.43502,25305.73010,0.00000,0.06833,314.16410
189.00001,9.45009,25310.14979,0.00000,0.06845,314.21897
189.30001,9.46498,25305.61090,0.00000,0.06857,314.16262
189.60001,9.48010,25309.10969,0.00000,0.06870,314.20606
189.90001,9.49487,25308.47788,0.00000,0.06882,314.19822
190.20001,9.51012,25311.02598,0.00000,0.06894,314.22985
190.50001,9.52494,25311.75911,0.00000,0.06906,314.23895
190.80001,9.53989,25312.31344,0.00000,0.06918,314.24583
191.10001,9.55508,25316.14304,0.00000,0.06931,314.29338
191.40001,9.56997,25314.65292,0.00000,0.06943,314.27488
191.70001,9.58509,25317.01624,0.00000,0.06955,314.30422
192.00001,9.59992,25316.97452,0.00000,0.06967,314.30370
192.30001,9.61499,25320.65511,0.00000,0.06979,314.34939
192.60001,9.62999,25320.29450,0.00000,0.06992,314.34492
192.90001,9.64506,25318.65835,0.00000,0.07005,314.32461
193.20001,9.66001,25320.78922,0.00000,0.07017,314.35106
193.50001,9.67508,25318.71498,0.00000,0.07029,314.32531
193.80001,9.69008,25324.50855,0.00000,0.07041,314.39723
194.10001,9.70491,25319.70441,0.00000,0.07053,314.33759
194.40001,9.72010,25325.44732,0.00000,0.07065,314.40889
194.70001,9.73493,25323.50421,0.00000,0.07077,314.38477
195.00001,9.75011,25325.03307,0.00000,0.07090,314.40375
195.30001,9.76500,25326.55597,0.00000,0.07102,314.42265
195.60001,9.78001,25327.25930,0.00000,0.07114,314.43138
195.90001,9.79507,25330.96373,0.00000,0.07126,314.47737
196.20001,9.80990,25327.91495,0.00000,0.07139,314.43952
196.50001,9.82503,25328.98784,0.00000,0.07151,314.45284
196.80001,9.83997,25329.87297,0.00000,0.07163,314.46383
197.10001,9.85498,25331.32732,0.00000,0.07176,314.48189
197.40001,9.86993,25331.38692,0.00000,0.07188,314.48263
197.70001,9.88506,25333.08268,0.00000,0.07200,314.50368
198.00001,9.90000,25334.66816,0.00000,0.07212,314.52336
198.30001,9.91507,25331.84290,0.00000,0.07224,314.48829
198.60001,9.93008,25334.75161,0.00000,0.07236,314.52440
198.90001,9.94497,25332.20649,0.00000,0.07248,314.49280
199.20001,9.96009,25336.82883,0.00000,0.07261,314.55019
199.50001,9.97492,25336.76028,0.00000,0.07273,314.54934
199.80001,9.99005,25336.33709,0.00000,0.07285,314.54408
200.10001,10.00499,25338.91797,0.00000,0.07298,314.57612
200.40001,10.01994,25335.69932,0.00000,0.07310,314.53616
200.70001,10.03507,25339.36501,0.00000,0.07322,314.58167
201.00001,10.04990,25339.12659,0.00000,0.07334,314.57871
201.30001,10.06496,25341.27235,0.00000,0.07346,314.60535
201.60001,10.07997,25342.98897,0.00000,0.07359,314.62666
201.90001,10.09504,25343.82045,0.00000,0.07371,314.63699
202.20001,10.10998,25342.29755,0.00000,0.07383,314.61808
202.50001,10.12505,25342.18431,0.00000,0.07395,314.61667
202.80001,10.14000,25344.97678,0.00000,0.07408,314.65134
203.10001,10.15501,25343.07539,0.00000,0.07420,314.62774
203.40001,10.17007,25345.82317,0.00000,0.07433,314.66185
203.70001,10.18490,25342.24093,0.00000,0.07445,314.61738
204.00001,10.20015,25347.06295,0.00000,0.07457,314.67724
204.30001,10.21485,25347.53978,0.00000,0.07469,314.68316
204.60001,10.23004,25348.31166,0.00000,0.07481,314.69274
204.90001,10.24499,25350.84188,0.00000,0.07494,314.72416
205.20001,10.25988,25347.76330,0.00000,0.07506,314.68594
205.50001,10.27512,25351.71807,0.00000,0.07518,314.73503
205.80001,10.28989,25349.43223,0.00000,0.07531,314.70665
206.10001,10.30496,25350.54386,0.00000,0.07543,314.72046
206.40001,10.31991,25349.12229,0.00000,0.07555,314.70281
206.70001,10.33503,25353.60456,0.00000,0.07568,314.75845
207.00001,10.34998,25349.86138,0.00000,0.07580,314.71198
207.30001,10.36511,25351.92370,0.00000,0.07592,314.73759
207.60001,10.37999,25354.31981,0.00000,0.07604,314.76733
207.90001,10.39506,25351.51541,0.00000,0.07617,314.73252
208.20001,10.41007,25355.19004,0.00000,0.07629,314.77814
208.50001,10.42478,25351.58098,0.00000,0.07642,314.73333
208.80001,10.44014,25356.93645,0.00000,0.07654,314.79982
209.10001,10.45491,25354.58207,0.00000,0.07666,314.77059
209.40001,10.46998,25353.35422,0.00000,0.07679,314.75535
209.70001,10.48498,25356.06325,0.00000,0.07691,314.78898
210.00001,10.49993,25356.23610,0.00000,0.07704,314.79112
210.30001,10.51512,25358.48618,0.00000,0.07716,314.81906
210.60001,10.52995,25356.55200,0.00000,0.07729,314.79505
210.90001,10.54507,25355.88443,0.00000,0.07741,314.78676
211.20001,10.56002,25354.96950,0.00000,0.07753,314.77540
211.50001,10.57503,25356.68612,0.00000,0.07766,314.79671
211.80001,10.58991,25355.74436,0.00000,0.07778,314.78502
212.10001,10.60510,25357.93483,0.00000,0.07791,314.81221
212.40001,10.61999,25359.70807,0.00000,0.07803,314.83423
212.70001,10.63494,25356.12881,0.00000,0.07816,314.78979
213.00001,10.65006,25360.91805,0.00000,0.07829,314.84925
213.30001,10.66489,25358.16729,0.00000,0.07841,314.81510
213.60001,10.68014,25361.74059,0.00000,0.07854,314.85946
213.90001,10.69490,25361.30846,0.00000,0.07866,314.85410
214.20001,10.70997,25359.70509,0.00000,0.07878,314.83419
214.50001,10.72504,25361.56774,0.00000,0.07891,314.85731
214.80001,10.73993,25358.57260,0.00000,0.07903,314.82013
215.10001,10.75505,25360.53658,0.00000,0.07916,314.84451
215.40001,10.76994,25361.75251,0.00000,0.07928,314.85961
215.70001,10.78501,25360.81374,0.00000,0.07941,314.84795
216.00001,10.79996,25359.34150,0.00000,0.07953,314.82968
216.30001,10.81508,25361.78827,0.00000,0.07966,314.86005
216.60001,10.82997,25359.84814,0.00000,0.07979,314.83597
216.90001,10.84504,25359.68721,0.00000,0.07991,314.83397
217.20001,10.85998,25364.95924,0.00000,0.08004,314.89942
217.50001,10.87493,25360.86738,0.00000,0.08016,314.84862
217.80001,10.89006,25363.64794,0.00000,0.08028,314.88314
218.10001,10.90483,25360.24749,0.00000,0.08041,314.84092
218.40001,10.92001,25360.77201,0.00000,0.08053,314.84744
218.70001,10.93496,25363.30521,0.00000,0.08066,314.87888
219.00001,10.95003,25361.56476,0.00000,0.08078,314.85728
219.30001,10.96509,25364.64930,0.00000,0.08091,314.89557
219.60001,10.97998,25360.90016,0.00000,0.08103,314.84903
219.90001,10.99517,25363.37972,0.00000,0.08116,314.87981
220.20001,11.01000,25360.80778,0.00000,0.08129,314.84788
220.50001,11.02506,25361.97007,0.00000,0.08141,314.86231
220.80001,11.04001,25362.38730,0.00000,0.08154,314.86749
221.10001,11.05508,25362.35452,0.00000,0.08166,314.86708
221.40001,11.06991,25360.99255,0.00000,0.08178,314.85017
221.70001,11.08503,25361.13560,0.00000,0.08191,314.85195
222.00001,11.10004,25363.83569,0.00000,0.08203,314.88547
222.30001,11.11493,25359.37130,0.00000,0.08216,314.83005
222.60001,11.13011,25362.87010,0.00000,0.08229,314.87348
222.90001,11.14488,25361.26971,0.00000,0.08241,314.85361
223.20001,11.16007,25362.55121,0.00000,0.08254,314.86952
223.50001,11.17502,25362.26809,0.00000,0.08266,314.86601
223.80001,11.19002,25359.44283,0.00000,0.08279,314.83093
224.10001,11.20509,25362.70022,0.00000,0.08291,314.87137
224.40001,11.21998,25360.10444,0.00000,0.08303,314.83915
224.70001,11.23510,25361.12964,0.00000,0.08315,314.85188
225.00001,11.24993,25358.16729,0.00000,0.08328,314.81510
225.30001,11.26506,25360.70645,0.00000,0.08340,314.84662
225.60001,11.27995,25359.31766,0.00000,0.08353,314.82938
225.90001,11.29507,25361.77039,0.00000,0.08365,314.85983
226.20001,11.30990,25362.06543,0.00000,0.08377,314.86349
226.50001,11.32509,25360.84950,0.00000,0.08389,314.84840
226.80001,11.34009,25363.09958,0.00000,0.08402,314.87633
227.10001,11.35486,25357.01692,0.00000,0.08414,314.80082
227.40001,11.37005,25360.85844,0.00000,0.08426,314.84851
227.70001,11.38487,25359.20739,0.00000,0.08438,314.82801
228.00001,11.40006,25360.70347,0.00000,0.08451,314.84658
228.30001,11.41495,25359.86602,0.00000,0.08463,314.83619
228.60001,11.43002,25358.04510,0.00000,0.08476,314.81358
228.90001,11.44508,25358.56366,0.00000,0.08487,314.82002
229.20001,11.45997,25356.42385,0.00000,0.08499,314.79345
229.50001,11.47504,25358.18517,0.00000,0.08512,314.81532
229.80001,11.48999,25356.06027,0.00000,0.08524,314.78894
230.10001,11.50505,25360.08060,0.00000,0.08536,314.83885
230.40001,11.51994,25355.44634,0.00000,0.08548,314.78132
230.70001,11.53507,25356.95136,0.00000,0.08561,314.80000
231.00001,11.54995,25356.10199,0.00000,0.08573,314.78946
231.30001,11.56502,25354.30491,0.00000,0.08585,314.76715
231.60001,11.58003,25357.76496,0.00000,0.08596,314.81010
231.90001,11.59492,25352.53167,0.00000,0.08608,314.74513
232.20001,11.61010,25353.87576,0.00000,0.08621,314.76182
232.50001,11.62493,25350.48723,0.00000,0.08632,314.71975
232.80001,11.64006,25352.67174,0.00000,0.08644,314.74687
233.10001,11.65500,25351.99821,0.00000,0.08656,314.73851
233.40001,11.67001,25351.17865,0.00000,0.08668,314.72834
233.70001,11.68502,25352.01311,0.00000,0.08680,314.73870
234.00001,11.69997,25348.78254,0.00000,0.08692,314.69859
234.30001,11.71503,25349.41435,0.00000,0.08703,314.70643
234.60001,11.72992,25346.61293,0.00000,0.08715,314.67165
234.90001,11.74499,25348.74976,0.00000,0.08726,314.69818
235.20001,11.75994,25346.18974,0.00000,0.08738,314.66640
235.50001,11.77506,25345.02447,0.00000,0.08749,314.65193
235.80001,11.78989,25344.88738,0.00000,0.08761,314.65023
236.10001,11.80502,25342.30053,0.00000,0.08773,314.61812
236.40001,11.82002,25345.65628,0.00000,0.08784,314.65978
236.70001,11.83491,25342.24391,0.00000,0.08795,314.61741
237.00001,11.85010,25342.60452,0.00000,0.08807,314.62189
237.30001,11.86493,25340.08920,0.00000,0.08818,314.59066
237.60001,11.87999,25337.27884,0.00000,0.08829,314.55577
237.90001,11.89494,25338.48286,0.00000,0.08840,314.57072
238.20001,11.91001,25335.74402,0.00000,0.08851,314.53672
238.50001,11.92507,25337.38911,0.00000,0.08862,314.55714
238.80001,11.93996,25336.20298,0.00000,0.08873,314.54242
239.10001,11.95503,25335.85131,0.00000,0.08884,314.53805
239.40001,11.96998,25332.29291,0.00000,0.08895,314.49387
239.70001,11.98504,25333.45520,0.00000,0.08905,314.50830
240.00001,11.99993,25329.10705,0.00000,0.08916,314.45432
240.30001,12.01500,25328.47822,0.00000,0.08927,314.44652
240.60001,12.02994,25328.04906,0.00000,0.08938,314.44119
240.90001,12.04495,25321.23029,0.00000,0.08948,314.35654
241.20001,12.06008,25324.49961,0.00000,0.08958,314.39712
241.50001,12.07491,25320.03522,0.00000,0.08968,314.34170
241.80001,12.09021,25320.20211,0.00000,0.08979,314.34377
242.10001,12.10492,25318.32755,0.00000,0.08988,314.32050
242.40001,12.11999,25314.80193,0.00000,0.08998,314.27673
242.70001,12.13499,25314.29529,0.00000,0.09007,314.27044
243.00001,12.15000,25310.58788,0.00000,0.09017,314.22441
243.30001,12.16501,25310.17661,0.00000,0.09027,314.21931
243.60001,12.17996,25305.24433,0.00000,0.09036,314.15807
243.90001,12.19502,25305.91488,0.00000,0.09045,314.16640
244.20001,12.20991,25300.46105,0.00000,0.09054,314.09869
244.50001,12.22504,25298.19906,0.00000,0.09063,314.07061
244.80001,12.23993,25293.86878,0.00000,0.09072,314.01685
245.10001,12.25505,25291.21637,0.00000,0.09081,313.98392
245.40001,12.27000,25287.52685,0.00000,0.09089,313.93812
245.70001,12.28501,25280.58589,0.00000,0.09097,313.85195
246.00001,12.30007,25279.96302,0.00000,0.09106,313.84421
246.30001,12.31484,25271.00146,0.00000,0.09113,313.73296
246.60001,12.33015,25270.26832,0.00000,0.09121,313.72386
246.90001,12.34492,25262.98761,0.00000,0.09128,313.63347
247.20001,12.36004,25257.30729,0.00000,0.09135,313.56295
247.50001,12.37499,25251.59121,0.00000,0.09142,313.49198
247.80001,12.38994,25242.77568,0.00000,0.09148,313.38254
248.10001,12.40500,25236.02545,0.00000,0.09155,313.29874
248.40001,12.41995,25224.70355,0.00000,0.09161,313.15818
248.70001,12.43508,25218.90998,0.00000,0.09167,313.08625
249.00001,12.44997,25205.20389,0.00000,0.09172,312.91610
249.30001,12.46503,25197.33012,0.00000,0.09178,312.81835
249.60001,12.47992,25184.48830,0.00000,0.09183,312.65892
249.90001,12.49505,25168.26391,0.00000,0.09187,312.45750
250.20001,12.51000,25155.04956,0.00000,0.09192,312.29344
250.50001,12.52512,25134.27138,0.00000,0.09198,312.03549
250.80001,12.54007,25114.39621,0.00000,0.09201,311.78874
251.10001,12.55490,25084.61475,0.00000,0.09204,311.41901
251.40001,12.57014,25050.04704,0.00000,0.09206,310.98987
251.70001,12.58497,24979.38424,0.00000,0.09207,310.11260
252.00001,12.60004,24864.50821,0.00000,0.09206,308.68645
252.30001,12.61504,24471.43048,0.00000,0.09200,303.80649
252.47401,12.62389,23708.67580,0.00000,0.09183,294.33709
252.50601,12.62551,22062.08110,0.00000,0.09009,273.89504
252.51201,12.62635,18791.27026,0.00000,0.08810,233.28877
252.51801,12.62748,14830.50287,0.00000,0.08866,184.11686
252.52001,12.62784,13487.04696,0.00000,0.08918,167.43821