File: scratch/college-stuff/ME Lab/ME lab Fall 2013/group13/group13.is_tens_RawData/Specimen_RawData_4.csv
Time,Extension,Load,Strain 2,Tensile strain,Tensile stress
(sec),(mm),(N),(mm/mm),(mm/mm),(MPa)
0.00000,0.00000,-0.46499,0.00000,-0.00001,-0.00559
0.10000,0.00155,1.75757,0.00000,0.00000,0.02112
0.20000,0.00711,6.69624,0.00000,0.00000,0.08046
0.30000,0.01351,10.49762,0.00000,0.00001,0.12613
0.40000,0.01937,13.40805,0.00000,0.00001,0.16110
0.50000,0.02469,14.05676,0.00000,0.00001,0.16890
0.60000,0.02989,14.79025,0.00000,0.00001,0.17771
0.70000,0.03498,16.19824,0.00000,0.00001,0.19463
0.80000,0.04006,17.06989,0.00000,0.00001,0.20510
0.90000,0.04502,18.82746,0.00000,0.00001,0.22622
1.00000,0.04998,19.05043,0.00000,0.00000,0.22890
1.10000,0.05501,20.05006,0.00000,0.00001,0.24091
1.20000,0.05997,21.75147,0.00000,0.00001,0.26135
1.30000,0.06505,22.80061,0.00000,0.00001,0.27395
1.40000,0.06995,23.87933,0.00000,0.00001,0.28692
1.50000,0.07504,24.28468,0.00000,0.00001,0.29179
1.60000,0.07994,25.00484,0.00000,0.00001,0.30044
1.70000,0.08514,26.90851,0.00000,0.00001,0.32331
1.80000,0.08998,28.71918,0.00000,0.00001,0.34507
1.90000,0.09513,33.12404,0.00000,0.00001,0.39799
2.00000,0.09997,36.62194,0.00000,0.00001,0.44002
2.10000,0.10511,40.64254,0.00000,0.00001,0.48833
2.20000,0.10995,42.47804,0.00000,0.00002,0.51038
2.30000,0.11509,45.23906,0.00000,0.00001,0.54356
2.40000,0.11994,48.59620,0.00000,0.00001,0.58389
2.50000,0.12502,55.28190,0.00000,0.00002,0.66422
2.60000,0.12998,59.92602,0.00000,0.00001,0.72002
2.70000,0.13512,63.64267,0.00000,0.00002,0.76468
2.80000,0.14003,67.14294,0.00000,0.00002,0.80674
2.90000,0.14499,70.23484,0.00000,0.00002,0.84389
3.00000,0.14995,72.95109,0.00000,0.00002,0.87652
3.10000,0.15503,76.54732,0.00000,0.00002,0.91973
3.20000,0.16006,80.79206,0.00000,0.00002,0.97073
3.30000,0.16496,86.40190,0.00000,0.00002,1.03814
3.40000,0.16998,95.03391,0.00000,0.00003,1.14185
3.50000,0.17494,105.07392,0.00000,0.00003,1.26249
3.60000,0.18009,115.54533,0.00000,0.00002,1.38830
3.70000,0.18499,127.57814,0.00000,0.00002,1.53288
3.80000,0.19013,144.91462,0.00000,0.00003,1.74118
3.90000,0.19491,161.72538,0.00000,0.00003,1.94317
4.00000,0.20012,179.22248,0.00000,0.00003,2.15340
4.10000,0.20496,198.64941,0.00000,0.00004,2.38682
4.20000,0.21010,220.54168,0.00000,0.00004,2.64986
4.30000,0.21494,242.78176,0.00000,0.00005,2.91708
4.40000,0.22003,266.68077,0.00000,0.00006,3.20423
4.50000,0.22493,289.89031,0.00000,0.00006,3.48309
4.60000,0.23013,312.77498,0.00000,0.00007,3.75806
4.70000,0.23497,334.49621,0.00000,0.00007,4.01904
4.80000,0.24000,358.03281,0.00000,0.00008,4.30184
4.90000,0.24490,382.88319,0.00000,0.00009,4.60042
5.00000,0.25004,407.55528,0.00000,0.00009,4.89686
5.10000,0.25500,435.25747,0.00000,0.00010,5.22971
5.20000,0.26002,463.78057,0.00000,0.00011,5.57242
5.30000,0.26499,495.63963,0.00000,0.00013,5.95522
5.40000,0.27001,529.64897,0.00000,0.00014,6.36385
5.50000,0.27503,566.34196,0.00000,0.00016,6.80472
5.60000,0.28005,601.77846,0.00000,0.00017,7.23050
5.70000,0.28502,640.95971,0.00000,0.00019,7.70127
5.80000,0.28992,677.57238,0.00000,0.00021,8.14118
5.90000,0.29506,716.23996,0.00000,0.00023,8.60578
6.00000,0.29996,752.36284,0.00000,0.00025,9.03980
6.10000,0.30511,789.56597,0.00000,0.00027,9.48681
6.20000,0.30995,827.51065,0.00000,0.00028,9.94272
6.30000,0.31503,866.79766,0.00000,0.00030,10.41476
6.40000,0.31987,901.70419,0.00000,0.00032,10.83417
6.50000,0.32514,939.47481,0.00000,0.00034,11.28799
6.60000,0.32986,975.07471,0.00000,0.00035,11.71573
6.70000,0.33500,1013.49698,0.00000,0.00037,12.17739
6.80000,0.33984,1051.03757,0.00000,0.00039,12.62844
6.90000,0.34505,1088.61215,0.00000,0.00040,13.07991
7.00000,0.34995,1125.71325,0.00000,0.00042,13.52569
7.10000,0.35503,1161.13089,0.00000,0.00044,13.95124
7.20000,0.35993,1197.65066,0.00000,0.00046,14.39003
7.30000,0.36496,1232.67276,0.00000,0.00047,14.81083
7.40000,0.36998,1271.09382,0.00000,0.00049,15.27247
7.50000,0.37506,1306.63412,0.00000,0.00052,15.69949
7.60000,0.37996,1342.55281,0.00000,0.00053,16.13106
7.70000,0.38498,1377.38278,0.00000,0.00055,16.54955
7.80000,0.38995,1414.61948,0.00000,0.00057,16.99696
7.90000,0.39497,1448.48684,0.00000,0.00059,17.40388
8.00000,0.40005,1486.04745,0.00000,0.00061,17.85518
8.10000,0.40495,1519.34708,0.00000,0.00062,18.25528
8.20000,0.40998,1554.53393,0.00000,0.00064,18.67806
8.30000,0.41494,1586.84552,0.00000,0.00065,19.06629
8.40000,0.42008,1622.55317,0.00000,0.00068,19.49533
8.50000,0.42492,1657.31180,0.00000,0.00069,19.91296
8.60000,0.43007,1693.35864,0.00000,0.00071,20.34607
8.70000,0.43491,1726.37608,0.00000,0.00073,20.74278
8.80000,0.44005,1759.33335,0.00000,0.00074,21.13877
8.90000,0.44489,1790.91841,0.00000,0.00076,21.51827
9.00000,0.45004,1824.23573,0.00000,0.00078,21.91859
9.10000,0.45488,1856.28254,0.00000,0.00080,22.30364
9.20000,0.46002,1889.02654,0.00000,0.00081,22.69706
9.30000,0.46492,1919.99208,0.00000,0.00083,23.06912
9.40000,0.47006,1952.07689,0.00000,0.00084,23.45463
9.50000,0.47497,1982.33575,0.00000,0.00086,23.81819
9.60000,0.47999,2013.19214,0.00000,0.00087,24.18894
9.70000,0.48489,2041.61797,0.00000,0.00089,24.53048
9.80000,0.48997,2071.89620,0.00000,0.00090,24.89428
9.90000,0.49494,2100.90186,0.00000,0.00092,25.24279
10.00000,0.50002,2127.98826,0.00000,0.00093,25.56824
10.10000,0.50492,2157.20236,0.00000,0.00095,25.91925
10.20000,0.50994,2181.37894,0.00000,0.00096,26.20974
10.30000,0.51503,2204.58601,0.00000,0.00098,26.48858
10.40000,0.52005,2225.95055,0.00000,0.00098,26.74528
10.50000,0.52507,2249.88554,0.00000,0.00100,27.03286
10.60000,0.52991,2272.49786,0.00000,0.00101,27.30455
10.70000,0.53500,2297.63091,0.00000,0.00102,27.60653
10.80000,0.53990,2319.11633,0.00000,0.00103,27.86468
10.90000,0.54510,2344.11471,0.00000,0.00104,28.16504
11.00000,0.54988,2365.98011,0.00000,0.00106,28.42776
11.10000,0.55503,2391.34636,0.00000,0.00107,28.73254
11.20000,0.55987,2413.58411,0.00000,0.00108,28.99973
11.30000,0.56507,2437.89665,0.00000,0.00110,29.29186
11.40000,0.56991,2460.70754,0.00000,0.00110,29.56593
11.50000,0.57506,2488.30114,0.00000,0.00112,29.89748
11.60000,0.57990,2510.78177,0.00000,0.00113,30.16759
11.70000,0.58504,2535.04738,0.00000,0.00115,30.45914
11.80000,0.58994,2560.10722,0.00000,0.00115,30.76024
11.90000,0.59503,2583.47262,0.00000,0.00117,31.04098
12.00000,0.59987,2607.93250,0.00000,0.00118,31.33487
12.10000,0.60489,2630.97752,0.00000,0.00119,31.61176
12.20000,0.60991,2656.47173,0.00000,0.00121,31.91808
12.30000,0.61499,2680.28826,0.00000,0.00123,32.20424
12.40000,0.61996,2706.00710,0.00000,0.00124,32.51326
12.50000,0.62498,2730.38428,0.00000,0.00125,32.80616
12.60000,0.63000,2755.11220,0.00000,0.00126,33.10327
12.70000,0.63496,2779.50093,0.00000,0.00128,33.39630
12.80000,0.64005,2805.86090,0.00000,0.00129,33.71302
12.90000,0.64495,2827.80919,0.00000,0.00130,33.97674
13.00000,0.65003,2854.44167,0.00000,0.00132,34.29673
13.10000,0.65493,2878.61247,0.00000,0.00133,34.58715
13.20000,0.66008,2904.71595,0.00000,0.00134,34.90079
13.30000,0.66492,2927.98094,0.00000,0.00135,35.18032
13.40000,0.67006,2953.06053,0.00000,0.00137,35.48166
13.50000,0.67490,2976.47882,0.00000,0.00138,35.76304
13.60000,0.68005,3002.69406,0.00000,0.00139,36.07802
13.70000,0.68501,3025.63384,0.00000,0.00140,36.35364
13.80000,0.69015,3051.29066,0.00000,0.00142,36.66192
13.90000,0.69493,3076.14785,0.00000,0.00144,36.96058
14.00000,0.70002,3101.69403,0.00000,0.00145,37.26752
14.10000,0.70498,3126.45361,0.00000,0.00146,37.56502
14.20000,0.71012,3152.14582,0.00000,0.00148,37.87371
14.30000,0.71496,3176.67462,0.00000,0.00149,38.16843
14.40000,0.72004,3201.81325,0.00000,0.00150,38.47048
14.50000,0.72489,3225.22186,0.00000,0.00151,38.75174
14.60000,0.73003,3249.73017,0.00000,0.00153,39.04621
14.70000,0.73505,3275.78448,0.00000,0.00154,39.35926
14.80000,0.74007,3299.94224,0.00000,0.00155,39.64952
14.90000,0.74498,3326.07552,0.00000,0.00157,39.96352
15.00000,0.75000,3349.11346,0.00000,0.00158,40.24032
15.10000,0.75508,3374.56018,0.00000,0.00160,40.54607
15.20000,0.75998,3397.93786,0.00000,0.00161,40.82696
15.30000,0.76501,3424.19744,0.00000,0.00162,41.14247
15.40000,0.76991,3447.04613,0.00000,0.00163,41.41700
15.50000,0.77505,3473.24051,0.00000,0.00165,41.73174
15.60000,0.77995,3495.80459,0.00000,0.00166,42.00285
15.70000,0.78504,3524.05943,0.00000,0.00167,42.34234
15.80000,0.78988,3546.79674,0.00000,0.00169,42.61553
15.90000,0.79508,3573.36327,0.00000,0.00170,42.93473
16.00000,0.79992,3596.34310,0.00000,0.00171,43.21084
16.10000,0.80513,3621.12932,0.00000,0.00172,43.50865
16.20000,0.80991,3644.43660,0.00000,0.00174,43.78869
16.30000,0.81505,3671.48183,0.00000,0.00175,44.11365
16.40000,0.81989,3694.12191,0.00000,0.00176,44.38567
16.50000,0.82504,3719.65617,0.00000,0.00178,44.69247
16.60000,0.82994,3743.53081,0.00000,0.00179,44.97933
16.70000,0.83496,3766.80791,0.00000,0.00180,45.25901
16.80000,0.83986,3791.39669,0.00000,0.00182,45.55445
16.90000,0.84500,3814.49871,0.00000,0.00183,45.83203
17.00000,0.84997,3838.38825,0.00000,0.00184,46.11906
17.10000,0.85505,3862.21297,0.00000,0.00185,46.40532
17.20000,0.86001,3886.17516,0.00000,0.00187,46.69323
17.30000,0.86497,3908.53807,0.00000,0.00188,46.96193
17.40000,0.87000,3935.67756,0.00000,0.00189,47.28802
17.50000,0.87502,3957.20601,0.00000,0.00191,47.54669
17.60000,0.88004,3981.91586,0.00000,0.00192,47.84358
17.70000,0.88494,4003.00771,0.00000,0.00193,48.09700
17.80000,0.89003,4027.50000,0.00000,0.00194,48.39128
17.90000,0.89493,4048.22454,0.00000,0.00195,48.64029
18.00000,0.90013,4071.70802,0.00000,0.00197,48.92245
18.10000,0.90497,4094.28291,0.00000,0.00198,49.19369
18.20000,0.91012,4118.95365,0.00000,0.00199,49.49012
18.30000,0.91490,4139.18495,0.00000,0.00200,49.73320
18.40000,0.92010,4161.68571,0.00000,0.00202,50.00355
18.50000,0.92494,4182.37336,0.00000,0.00203,50.25212
18.60000,0.93009,4205.06373,0.00000,0.00204,50.52475
18.70000,0.93493,4225.90449,0.00000,0.00205,50.77516
18.80000,0.94001,4247.06638,0.00000,0.00206,51.02942
18.90000,0.94491,4267.54728,0.00000,0.00207,51.27550
19.00000,0.95000,4288.69799,0.00000,0.00208,51.52963
19.10000,0.95490,4309.78388,0.00000,0.00210,51.78298
19.20000,0.95998,4331.21622,0.00000,0.00211,52.04050
19.30000,0.96494,4353.98407,0.00000,0.00212,52.31406
19.40000,0.97002,4374.83750,0.00000,0.00213,52.56462
19.50000,0.97499,4396.29368,0.00000,0.00214,52.82242
19.60000,0.98001,4418.26098,0.00000,0.00216,53.08636
19.70000,0.98497,4440.29681,0.00000,0.00216,53.35113
19.80000,0.98999,4459.34609,0.00000,0.00217,53.58001
19.90000,0.99508,4483.84210,0.00000,0.00219,53.87433
20.00000,0.99992,4502.02040,0.00000,0.00220,54.09275
20.10000,1.00506,4526.96830,0.00000,0.00221,54.39250
20.20000,1.00990,4546.67918,0.00000,0.00222,54.62933
20.30000,1.01505,4570.44542,0.00000,0.00224,54.91489
20.40000,1.01995,4590.80376,0.00000,0.00225,55.15950
20.50000,1.02509,4614.18368,0.00000,0.00226,55.44041
20.60000,1.02987,4635.39362,0.00000,0.00228,55.69526
20.70000,1.03508,4658.18904,0.00000,0.00229,55.96915
20.80000,1.03992,4680.11536,0.00000,0.00230,56.23260
20.90000,1.04506,4704.62404,0.00000,0.00231,56.52707
21.00000,1.04990,4727.47721,0.00000,0.00232,56.80166
21.10000,1.05499,4751.07506,0.00000,0.00234,57.08519
21.20000,1.05989,4773.63132,0.00000,0.00235,57.35621
21.30000,1.06503,4798.18955,0.00000,0.00236,57.65128
21.40000,1.06999,4820.07191,0.00000,0.00238,57.91421
21.50000,1.07502,4843.68391,0.00000,0.00239,58.19791
21.60000,1.07992,4865.25409,0.00000,0.00240,58.45708
21.70000,1.08500,4887.22809,0.00000,0.00242,58.72110
21.80000,1.09002,4910.26789,0.00000,0.00243,58.99793
21.90000,1.09504,4931.43015,0.00000,0.00244,59.25220
22.00000,1.10001,4956.28417,0.00000,0.00246,59.55083
22.10000,1.10497,4978.48168,0.00000,0.00247,59.81753
22.20000,1.10999,5002.36191,0.00000,0.00247,60.10446
22.30000,1.11501,5024.71700,0.00000,0.00249,60.37306
22.40000,1.12010,5048.31076,0.00000,0.00250,60.65654
22.50000,1.12500,5070.20541,0.00000,0.00251,60.91961
22.60000,1.13008,5094.72117,0.00000,0.00253,61.21418
22.70000,1.13498,5115.19983,0.00000,0.00255,61.46023
22.80000,1.14013,5140.13097,0.00000,0.00256,61.75978
22.90000,1.14497,5160.78845,0.00000,0.00257,62.00799
23.00000,1.15011,5185.85853,0.00000,0.00258,62.30921
23.10000,1.15489,5208.50085,0.00000,0.00260,62.58126
23.20000,1.16010,5232.98308,0.00000,0.00261,62.87542
23.30000,1.16494,5254.47987,0.00000,0.00262,63.13371
23.40000,1.17008,5278.84364,0.00000,0.00263,63.42645
23.50000,1.17498,5301.32353,0.00000,0.00265,63.69655
23.60000,1.18007,5326.11236,0.00000,0.00266,63.99439
23.70000,1.18497,5348.45479,0.00000,0.00267,64.26284
23.80000,1.19005,5373.07188,0.00000,0.00269,64.55862
23.90000,1.19495,5397.14545,0.00000,0.00270,64.84787
24.00000,1.20003,5420.77683,0.00000,0.00271,65.13180
24.10000,1.20494,5443.48434,0.00000,0.00273,65.40464
24.20000,1.21008,5465.96348,0.00000,0.00274,65.67473
24.30000,1.21498,5489.37321,0.00000,0.00275,65.95601
24.40000,1.21994,5511.74395,0.00000,0.00277,66.22479
24.50000,1.22497,5537.19699,0.00000,0.00278,66.53062
24.60000,1.22999,5559.57295,0.00000,0.00280,66.79947
24.70000,1.23507,5586.58019,0.00000,0.00281,67.12397
24.80000,1.23997,5609.02692,0.00000,0.00282,67.39367
24.90000,1.24506,5635.35616,0.00000,0.00284,67.71002
25.00000,1.24990,5656.74119,0.00000,0.00285,67.96697
25.10000,1.25510,5681.44694,0.00000,0.00286,68.26381
25.20000,1.25994,5703.03835,0.00000,0.00288,68.52324
25.30000,1.26509,5728.68250,0.00000,0.00289,68.83136
25.40000,1.26987,5749.35302,0.00000,0.00290,69.07972
25.50000,1.27507,5774.45664,0.00000,0.00291,69.38134
25.60000,1.27991,5796.24362,0.00000,0.00293,69.64312
25.70000,1.28512,5821.04549,0.00000,0.00294,69.94112
25.80000,1.28996,5844.04096,0.00000,0.00296,70.21741
25.90000,1.29504,5869.61545,0.00000,0.00297,70.52470
26.00000,1.29994,5893.64320,0.00000,0.00298,70.81340
26.10000,1.30503,5916.54032,0.00000,0.00300,71.08851
26.20000,1.30999,5940.83406,0.00000,0.00301,71.38040
26.30000,1.31495,5964.62227,0.00000,0.00303,71.66623
26.40000,1.31991,5990.20682,0.00000,0.00304,71.97363
26.50000,1.32499,6013.73650,0.00000,0.00305,72.25634
26.60000,1.33002,6038.01347,0.00000,0.00307,72.54804
26.70000,1.33504,6060.37788,0.00000,0.00308,72.81675
26.80000,1.34000,6087.60901,0.00000,0.00309,73.14394
26.90000,1.34502,6109.53905,0.00000,0.00310,73.40743
27.00000,1.35011,6134.30962,0.00000,0.00312,73.70506
27.10000,1.35501,6156.43337,0.00000,0.00313,73.97088
27.20000,1.36003,6181.60479,0.00000,0.00314,74.27332
27.30000,1.36499,6205.61801,0.00000,0.00316,74.56184
27.40000,1.37008,6232.03516,0.00000,0.00318,74.87925
27.50000,1.37498,6253.31104,0.00000,0.00319,75.13488
27.60000,1.38012,6278.55584,0.00000,0.00320,75.43821
27.70000,1.38490,6300.06194,0.00000,0.00321,75.69661
27.80000,1.39011,6326.41017,0.00000,0.00323,76.01319
27.90000,1.39489,6347.90361,0.00000,0.00324,76.27143
28.00000,1.40009,6374.60127,0.00000,0.00326,76.59221
28.10000,1.40493,6396.46649,0.00000,0.00327,76.85493
28.20000,1.41002,6423.12616,0.00000,0.00329,77.17525
28.30000,1.41492,6448.09082,0.00000,0.00330,77.47520
28.40000,1.42006,6471.96174,0.00000,0.00331,77.76202
28.50000,1.42496,6496.73343,0.00000,0.00333,78.05966
28.60000,1.43005,6519.74007,0.00000,0.00334,78.33609
28.70000,1.43495,6545.23075,0.00000,0.00336,78.64236
28.80000,1.43997,6568.70902,0.00000,0.00337,78.92446
28.90000,1.44499,6593.24825,0.00000,0.00338,79.21930
29.00000,1.45007,6618.31349,0.00000,0.00340,79.52047
29.10000,1.45504,6642.64485,0.00000,0.00341,79.81281
29.20000,1.46000,6665.46300,0.00000,0.00343,80.08698
29.30000,1.46502,6690.81137,0.00000,0.00344,80.39154
29.40000,1.46998,6714.05792,0.00000,0.00346,80.67086
29.50000,1.47507,6740.05896,0.00000,0.00347,80.98326
29.60000,1.47991,6762.41517,0.00000,0.00348,81.25188
29.70000,1.48505,6788.56149,0.00000,0.00350,81.56603
29.80000,1.48989,6812.26179,0.00000,0.00351,81.85080
29.90000,1.49504,6839.12560,0.00000,0.00353,82.17357
30.00000,1.49988,6861.71949,0.00000,0.00354,82.44504
30.10000,1.50508,6888.38884,0.00000,0.00356,82.76548
30.20000,1.50992,6910.53867,0.00000,0.00357,83.03162
30.30000,1.51513,6936.83401,0.00000,0.00358,83.34756
30.40000,1.51997,6958.83632,0.00000,0.00360,83.61192
30.50000,1.52511,6984.07441,0.00000,0.00361,83.91516
30.60000,1.52995,7007.74267,0.00000,0.00363,84.19954
30.70000,1.53498,7032.82207,0.00000,0.00364,84.50088
30.80000,1.53994,7056.98878,0.00000,0.00366,84.79124
30.90000,1.54502,7080.84852,0.00000,0.00367,85.07792
31.00000,1.54992,7105.25289,0.00000,0.00368,85.37115
31.10000,1.55501,7129.35701,0.00000,0.00371,85.66076
31.20000,1.55997,7153.73382,0.00000,0.00372,85.95366
31.30000,1.56505,7177.09213,0.00000,0.00373,86.23431
31.40000,1.57007,7202.68786,0.00000,0.00375,86.54185
31.50000,1.57503,7226.03351,0.00000,0.00376,86.82235
31.60000,1.58000,7254.13337,0.00000,0.00378,87.15998
31.70000,1.58502,7276.83753,0.00000,0.00379,87.43278
31.80000,1.59004,7302.99875,0.00000,0.00380,87.74711
31.90000,1.59500,7326.14323,0.00000,0.00382,88.02519
32.00000,1.60003,7352.30297,0.00000,0.00384,88.33951
32.10000,1.60487,7376.39666,0.00000,0.00385,88.62900
32.20000,1.61007,7401.66232,0.00000,0.00387,88.93257
32.30000,1.61497,7425.23447,0.00000,0.00388,89.21580
32.40000,1.62012,7452.31882,0.00000,0.00390,89.54122
32.50000,1.62496,7476.09735,0.00000,0.00391,89.82692
32.60000,1.63004,7501.57014,0.00000,0.00393,90.13299
32.70000,1.63494,7524.54102,0.00000,0.00393,90.40899
32.80000,1.64009,7550.50555,0.00000,0.00396,90.72096
32.90000,1.64493,7574.18051,0.00000,0.00397,91.00542
33.00000,1.65007,7600.26202,0.00000,0.00399,91.31879
33.10000,1.65491,7625.26765,0.00000,0.00400,91.61924
33.20000,1.66000,7649.30695,0.00000,0.00402,91.90808
33.30000,1.66496,7675.93980,0.00000,0.00403,92.22808
33.40000,1.67004,7700.00219,0.00000,0.00405,92.51719
33.50000,1.67494,7725.01081,0.00000,0.00407,92.81767
33.60000,1.67997,7750.69818,0.00000,0.00408,93.12631
33.70000,1.68493,7776.37810,0.00000,0.00409,93.43486
33.80000,1.69001,7798.96900,0.00000,0.00411,93.70630
33.90000,1.69497,7826.46909,0.00000,0.00413,94.03672
34.00000,1.69993,7850.88092,0.00000,0.00414,94.33003
34.10000,1.70496,7877.88779,0.00000,0.00416,94.65452
34.20000,1.70992,7900.02644,0.00000,0.00417,94.92052
34.30000,1.71500,7926.42236,0.00000,0.00419,95.23768
34.40000,1.71990,7949.31874,0.00000,0.00420,95.51278
34.50000,1.72505,7974.95916,0.00000,0.00422,95.82086
34.60000,1.72995,7998.02914,0.00000,0.00423,96.09805
34.70000,1.73509,8023.18901,0.00000,0.00425,96.40035
34.80000,1.73993,8046.89229,0.00000,0.00426,96.68515
34.90000,1.74508,8074.95713,0.00000,0.00429,97.02235
35.00000,1.74986,8098.75429,0.00000,0.00430,97.30828
35.10000,1.75500,8124.69050,0.00000,0.00432,97.61991
35.20000,1.75990,8149.71924,0.00000,0.00433,97.92064
35.30000,1.76505,8174.56841,0.00000,0.00434,98.21921
35.40000,1.76989,8199.40493,0.00000,0.00437,98.51762
35.50000,1.77497,8224.37406,0.00000,0.00437,98.81763
35.60000,1.77993,8249.07571,0.00000,0.00439,99.11443
35.70000,1.78508,8274.90985,0.00000,0.00441,99.42483
35.80000,1.78998,8301.06139,0.00000,0.00442,99.73905
35.90000,1.79500,8324.94199,0.00000,0.00444,100.02598
36.00000,1.79996,8349.85524,0.00000,0.00445,100.32531
36.10000,1.80504,8375.18200,0.00000,0.00447,100.62962
36.20000,1.81001,8400.95654,0.00000,0.00449,100.93931
36.30000,1.81503,8425.07705,0.00000,0.00450,101.22912
36.40000,1.81999,8451.63167,0.00000,0.00452,101.54818
36.50000,1.82495,8475.43105,0.00000,0.00453,101.83414
36.60000,1.83004,8502.64952,0.00000,0.00456,102.16117
36.70000,1.83500,8526.52416,0.00000,0.00456,102.44803
36.80000,1.84002,8553.49749,0.00000,0.00459,102.77212
36.90000,1.84492,8576.34917,0.00000,0.00460,103.04669
37.00000,1.85001,8603.68386,0.00000,0.00462,103.37512
37.10000,1.85491,8627.54136,0.00000,0.00463,103.66177
37.20000,1.86011,8654.82837,0.00000,0.00465,103.98963
37.30000,1.86489,8679.53971,0.00000,0.00467,104.28655
37.40000,1.87004,8706.90942,0.00000,0.00468,104.61540
37.50000,1.87488,8730.48082,0.00000,0.00470,104.89861
37.60000,1.88008,8757.44969,0.00000,0.00471,105.22265
37.70000,1.88492,8781.33923,0.00000,0.00473,105.50969
37.80000,1.89007,8806.69877,0.00000,0.00475,105.81439
37.90000,1.89491,8830.47730,0.00000,0.00476,106.10009
38.00000,1.89999,8854.89210,0.00000,0.00478,106.39344
38.10000,1.90489,8879.30617,0.00000,0.00479,106.68678
38.20000,1.90998,8906.00234,0.00000,0.00481,107.00754
38.30000,1.91488,8932.50108,0.00000,0.00483,107.32593
38.40000,1.91996,8958.16535,0.00000,0.00484,107.63429
38.50000,1.92492,8983.76256,0.00000,0.00486,107.94185
38.60000,1.92994,9009.16681,0.00000,0.00488,108.24709
38.70000,1.93497,9035.91216,0.00000,0.00489,108.56844
38.80000,1.93993,9059.95741,0.00000,0.00491,108.85735
38.90000,1.94501,9087.57448,0.00000,0.00493,109.18917
39.00000,1.94997,9109.89717,0.00000,0.00494,109.45738
39.10000,1.95506,9136.68349,0.00000,0.00496,109.77923
39.20000,1.95990,9159.55305,0.00000,0.00497,110.05401
39.30000,1.96504,9186.97417,0.00000,0.00499,110.38348
39.40000,1.96988,9210.02030,0.00000,0.00500,110.66038
39.50000,1.97503,9235.27628,0.00000,0.00502,110.96384
39.60000,1.97987,9259.54431,0.00000,0.00504,111.25543
39.70000,1.98507,9287.57787,0.00000,0.00506,111.59225
39.80000,1.98991,9312.52912,0.00000,0.00507,111.89205
39.90000,1.99512,9338.66650,0.00000,0.00509,112.20610
40.00000,2.00002,9363.20797,0.00000,0.00510,112.50097
40.10000,2.00510,9388.28290,0.00000,0.00512,112.80225
40.20000,2.00994,9412.88024,0.00000,0.00514,113.09779
40.30000,2.01503,9439.09809,0.00000,0.00515,113.41280
40.40000,2.01999,9464.36003,0.00000,0.00517,113.71633
40.50000,2.02507,9489.69200,0.00000,0.00519,114.02070
40.60000,2.02991,9515.99553,0.00000,0.00520,114.33674
40.70000,2.03499,9541.57338,0.00000,0.00522,114.64407
40.80000,2.03990,9567.74354,0.00000,0.00523,114.95851
40.90000,2.04504,9594.00237,0.00000,0.00526,115.27401
41.00000,2.05000,9619.22407,0.00000,0.00527,115.57706
41.10000,2.05502,9643.20451,0.00000,0.00529,115.86519
41.20000,2.05999,9669.54827,0.00000,0.00531,116.18171
41.30000,2.06501,9693.39013,0.00000,0.00532,116.46818
41.40000,2.07003,9720.47970,0.00000,0.00534,116.79366
41.50000,2.07499,9743.86632,0.00000,0.00535,117.07466
41.60000,2.08002,9771.63017,0.00000,0.00538,117.40825
41.70000,2.08492,9794.92739,0.00000,0.00539,117.68817
41.80000,2.09006,9821.20931,0.00000,0.00541,118.00395
41.90000,2.09490,9845.51907,0.00000,0.00543,118.29604
42.00000,2.10005,9873.50494,0.00000,0.00544,118.63230
42.10000,2.10489,9898.86150,0.00000,0.00546,118.93696
42.20000,2.11009,9927.18786,0.00000,0.00548,119.27731
42.30000,2.11493,9950.45528,0.00000,0.00550,119.55687
42.40000,2.12008,9976.90633,0.00000,0.00551,119.87469
42.50000,2.12486,10001.51113,0.00000,0.00553,120.17032
42.60000,2.13000,10027.66564,0.00000,0.00555,120.48457
42.70000,2.13484,10051.23854,0.00000,0.00556,120.76780
42.80000,2.13999,10076.92814,0.00000,0.00558,121.07647
42.90000,2.14489,10102.82561,0.00000,0.00560,121.38763
43.00000,2.14997,10129.38917,0.00000,0.00562,121.70680
43.10000,2.15487,10155.82532,0.00000,0.00563,122.02444
43.20000,2.16001,10181.08577,0.00000,0.00565,122.32795
43.30000,2.16498,10206.29406,0.00000,0.00567,122.63083
43.40000,2.17000,10229.31114,0.00000,0.00568,122.90738
43.50000,2.17502,10255.08568,0.00000,0.00571,123.21707
43.60000,2.17992,10278.76064,0.00000,0.00572,123.50153
43.70000,2.18507,10305.84499,0.00000,0.00574,123.82695
43.80000,2.18997,10330.53845,0.00000,0.00576,124.12365
43.90000,2.19505,10356.81888,0.00000,0.00577,124.43942
44.00000,2.19989,10381.95342,0.00000,0.00579,124.74141
44.10000,2.20504,10409.93929,0.00000,0.00581,125.07767
44.20000,2.20994,10432.59576,0.00000,0.00583,125.34989
44.30000,2.21514,10459.68980,0.00000,0.00584,125.67543
44.40000,2.21992,10484.55909,0.00000,0.00586,125.97424
44.50000,2.22507,10511.74179,0.00000,0.00588,126.30085
44.60000,2.22991,10536.09475,0.00000,0.00589,126.59346
44.70000,2.23511,10562.94218,0.00000,0.00591,126.91603
44.80000,2.23995,10588.31811,0.00000,0.00593,127.22093
44.90000,2.24510,10613.51672,0.00000,0.00595,127.52370
45.00000,2.24988,10638.33684,0.00000,0.00597,127.82192
45.10000,2.25502,10664.21196,0.00000,0.00598,128.13281
45.20000,2.25992,10688.60367,0.00000,0.00600,128.42588
45.30000,2.26506,10714.38491,0.00000,0.00601,128.73565
45.40000,2.26997,10742.02210,0.00000,0.00604,129.06772
45.50000,2.27499,10767.62527,0.00000,0.00605,129.37534
45.60000,2.27995,10794.31847,0.00000,0.00607,129.69607
45.70000,2.28503,10818.90911,0.00000,0.00609,129.99153
45.80000,2.29000,10845.51960,0.00000,0.00610,130.31126
45.90000,2.29502,10869.86586,0.00000,0.00612,130.60379
46.00000,2.29998,10897.54850,0.00000,0.00614,130.93640
46.10000,2.30494,10921.33224,0.00000,0.00615,131.22217
46.20000,2.31003,10950.51095,0.00000,0.00618,131.57276
46.30000,2.31493,10972.94912,0.00000,0.00619,131.84235
46.40000,2.32001,11001.56307,0.00000,0.00621,132.18616
46.50000,2.32491,11025.11063,0.00000,0.00622,132.46909
46.60000,2.33006,11052.59135,0.00000,0.00625,132.79927
46.70000,2.33496,11074.79408,0.00000,0.00626,133.06604
46.80000,2.34010,11102.51546,0.00000,0.00628,133.39912
46.90000,2.34488,11127.05842,0.00000,0.00630,133.69401
47.00000,2.35009,11153.28521,0.00000,0.00631,134.00913
47.10000,2.35487,11178.31692,0.00000,0.00634,134.30989
47.20000,2.36001,11203.87986,0.00000,0.00635,134.61704
47.30000,2.36485,11230.55220,0.00000,0.00637,134.93751
47.40000,2.36994,11255.36114,0.00000,0.00639,135.23560
47.50000,2.37484,11280.56943,0.00000,0.00641,135.53848
47.60000,2.37998,11306.45946,0.00000,0.00642,135.84955
47.70000,2.38494,11332.58119,0.00000,0.00644,136.16341
47.80000,2.39003,11358.99648,0.00000,0.00646,136.48080
47.90000,2.39493,11386.50551,0.00000,0.00648,136.81132
48.00000,2.39995,11410.36376,0.00000,0.00650,137.09799
48.10000,2.40503,11437.48611,0.00000,0.00652,137.42387
48.20000,2.40999,11460.49649,0.00000,0.00653,137.70034
48.30000,2.41502,11487.93548,0.00000,0.00655,138.03003
48.40000,2.41992,11511.56276,0.00000,0.00656,138.31391
48.50000,2.42500,11538.19039,0.00000,0.00659,138.63385
48.60000,2.42996,11562.74974,0.00000,0.00660,138.92894
48.70000,2.43511,11590.89729,0.00000,0.00662,139.26714
48.80000,2.43995,11615.26740,0.00000,0.00664,139.55995
48.90000,2.44509,11641.60892,0.00000,0.00665,139.87645
49.00000,2.44999,11666.24352,0.00000,0.00668,140.17244
49.10000,2.45514,11692.58878,0.00000,0.00669,140.48898
49.20000,2.45998,11716.82999,0.00000,0.00671,140.78024
49.30000,2.46512,11745.07439,0.00000,0.00673,141.11961
49.40000,2.46990,11769.62256,0.00000,0.00675,141.41456
49.50000,2.47505,11798.51294,0.00000,0.00676,141.76168
49.60000,2.47995,11822.90539,0.00000,0.00678,142.05476
49.70000,2.48503,11849.47714,0.00000,0.00681,142.37403
49.80000,2.48993,11875.76950,0.00000,0.00682,142.68994
49.90000,2.49502,11900.30575,0.00000,0.00684,142.98474
50.00000,2.49992,11926.18757,0.00000,0.00686,143.29572
50.10000,2.50506,11951.12318,0.00000,0.00687,143.59533
50.20000,2.50990,11978.40720,0.00000,0.00690,143.92315
50.30000,2.51505,12004.93425,0.00000,0.00691,144.24188
50.40000,2.51995,12030.73561,0.00000,0.00693,144.55189
50.50000,2.52503,12055.43429,0.00000,0.00695,144.84865
50.60000,2.52999,12082.70714,0.00000,0.00697,145.17634
50.70000,2.53495,12106.77177,0.00000,0.00699,145.46548
50.80000,2.54004,12134.87089,0.00000,0.00701,145.80310
50.90000,2.54500,12159.36020,0.00000,0.00702,146.09734
51.00000,2.55002,12185.87831,0.00000,0.00704,146.41596
51.10000,2.55492,12211.28926,0.00000,0.00706,146.72128
51.20000,2.56001,12237.39237,0.00000,0.00708,147.03491
51.30000,2.56485,12263.32709,0.00000,0.00710,147.34652
51.40000,2.57011,12290.37866,0.00000,0.00712,147.67156
51.50000,2.57489,12313.10442,0.00000,0.00713,147.94461
51.60000,2.58004,12341.81896,0.00000,0.00716,148.28962
51.70000,2.58488,12365.54682,0.00000,0.00717,148.57472
51.80000,2.59002,12393.22871,0.00000,0.00719,148.90732
51.90000,2.59492,12418.94811,0.00000,0.00721,149.21634
52.00000,2.60007,12443.95748,0.00000,0.00723,149.51684
52.10000,2.60491,12469.21197,0.00000,0.00725,149.82028
52.20000,2.61005,12494.13118,0.00000,0.00726,150.11969
52.30000,2.61495,12520.21343,0.00000,0.00729,150.43307
52.40000,2.62004,12545.26228,0.00000,0.00730,150.73404
52.50000,2.62500,12570.17851,0.00000,0.00732,151.03341
52.60000,2.63002,12596.93503,0.00000,0.00734,151.35490
52.70000,2.63498,12623.74669,0.00000,0.00736,151.67704
52.80000,2.64000,12648.37682,0.00000,0.00738,151.97298
52.90000,2.64503,12676.35673,0.00000,0.00740,152.30917
53.00000,2.64999,12699.72324,0.00000,0.00742,152.58992
53.10000,2.65501,12727.84173,0.00000,0.00744,152.92777
53.20000,2.65997,12751.11139,0.00000,0.00746,153.20736
53.30000,2.66506,12778.53698,0.00000,0.00748,153.53688
53.40000,2.67002,12803.33549,0.00000,0.00749,153.83484
53.50000,2.67504,12830.54799,0.00000,0.00751,154.16181
53.60000,2.68000,12855.72797,0.00000,0.00753,154.46435
53.70000,2.68509,12882.91216,0.00000,0.00755,154.79097
53.80000,2.68993,12907.17423,0.00000,0.00757,155.08249
53.90000,2.69513,12933.86668,0.00000,0.00759,155.40320
54.00000,2.69991,12958.82463,0.00000,0.00761,155.70308
54.10000,2.70512,12986.39178,0.00000,0.00762,156.03430
54.20000,2.70996,13011.01595,0.00000,0.00765,156.33017
54.30000,2.71510,13038.98245,0.00000,0.00766,156.66619
54.40000,2.72000,13062.59334,0.00000,0.00768,156.94988
54.50000,2.72503,13090.29311,0.00000,0.00770,157.28270
54.60000,2.72993,13115.19593,0.00000,0.00772,157.58191
54.70000,2.73501,13140.11514,0.00000,0.00774,157.88132
54.80000,2.73991,13166.59749,0.00000,0.00776,158.19951
54.90000,2.74500,13193.08132,0.00000,0.00777,158.51772
55.00000,2.74996,13220.97629,0.00000,0.00780,158.85289
55.10000,2.75498,13246.27101,0.00000,0.00781,159.15681
55.20000,2.76000,13273.79495,0.00000,0.00784,159.48751
55.30000,2.76502,13298.84231,0.00000,0.00785,159.78846
55.40000,2.76999,13324.43655,0.00000,0.00787,160.09598
55.50000,2.77495,13347.98783,0.00000,0.00789,160.37896
55.60000,2.78003,13375.34487,0.00000,0.00791,160.70766
55.70000,2.78499,13399.25975,0.00000,0.00793,160.99500
55.80000,2.79008,13427.18154,0.00000,0.00795,161.33049
55.90000,2.79492,13451.81465,0.00000,0.00797,161.62646
56.00000,2.80000,13479.52932,0.00000,0.00798,161.95946
56.10000,2.80490,13505.33068,0.00000,0.00800,162.26947
56.20000,2.81005,13531.24380,0.00000,0.00803,162.58082
56.30000,2.81495,13555.59230,0.00000,0.00804,162.87337
56.40000,2.82009,13582.75712,0.00000,0.00806,163.19976
56.50000,2.82487,13607.67484,0.00000,0.00808,163.49915
56.60000,2.83002,13633.17668,0.00000,0.00810,163.80556
56.70000,2.83492,13659.02871,0.00000,0.00812,164.11618
56.80000,2.84006,13684.80772,0.00000,0.00814,164.42592
56.90000,2.84484,13710.18440,0.00000,0.00816,164.73083
57.00000,2.84993,13735.76373,0.00000,0.00817,165.03817
57.10000,2.85489,13762.44277,0.00000,0.00819,165.35872
57.20000,2.86003,13787.38880,0.00000,0.00821,165.65846
57.30000,2.86493,13813.61037,0.00000,0.00823,165.97351
57.40000,2.87002,13840.27749,0.00000,0.00825,166.29392
57.50000,2.87504,13867.59132,0.00000,0.00827,166.62211
57.60000,2.88006,13891.65223,0.00000,0.00829,166.91120
57.70000,2.88508,13918.34915,0.00000,0.00830,167.23197
57.80000,2.88999,13942.28041,0.00000,0.00833,167.51951
57.90000,2.89501,13969.62702,0.00000,0.00835,167.84809
58.00000,2.89997,13994.17669,0.00000,0.00837,168.14306
58.10000,2.90505,14021.66337,0.00000,0.00839,168.47332
58.20000,2.90995,14045.57675,0.00000,0.00840,168.76064
58.30000,2.91504,14074.30321,0.00000,0.00843,169.10579
58.40000,2.91988,14099.19113,0.00000,0.00844,169.40483
58.50000,2.92502,14127.01458,0.00000,0.00846,169.73913
58.60000,2.92998,14150.69848,0.00000,0.00848,170.02370
58.70000,2.93513,14177.47736,0.00000,0.00850,170.34545
58.80000,2.93991,14202.26395,0.00000,0.00853,170.64327
58.90000,2.94511,14230.46440,0.00000,0.00854,170.98210
59.00000,2.94989,14253.97396,0.00000,0.00856,171.26458
59.10000,2.95510,14281.47405,0.00000,0.00858,171.59500
59.20000,2.95994,14306.05203,0.00000,0.00860,171.89031
59.30000,2.96508,14332.80408,0.00000,0.00862,172.21174
59.40000,2.96992,14357.77098,0.00000,0.00863,172.51172
59.50000,2.97501,14382.79301,0.00000,0.00866,172.81237
59.60000,2.97997,14408.21439,0.00000,0.00867,173.11781
59.70000,2.98505,14434.35550,0.00000,0.00870,173.43190
59.80000,2.98989,14461.03752,0.00000,0.00871,173.75249
59.90000,2.99498,14486.60493,0.00000,0.00873,174.05969
60.00000,2.99994,14513.68779,0.00000,0.00876,174.38509
60.10000,3.00502,14537.24355,0.00000,0.00877,174.66812
60.20000,3.00998,14564.74811,0.00000,0.00880,174.99860
60.30000,3.01489,14588.62126,0.00000,0.00881,175.28544
60.40000,3.02003,14617.07652,0.00000,0.00883,175.62733
60.50000,3.02493,14640.23441,0.00000,0.00885,175.90558
60.60000,3.03007,14668.39612,0.00000,0.00887,176.24395
60.70000,3.03485,14692.87723,0.00000,0.00889,176.53809
60.80000,3.04006,14719.66505,0.00000,0.00891,176.85996
60.90000,3.04490,14744.07017,0.00000,0.00893,177.15319
61.00000,3.05010,14771.05319,0.00000,0.00895,177.47740
61.10000,3.05494,14794.93529,0.00000,0.00897,177.76434
61.20000,3.06009,14822.24315,0.00000,0.00899,178.09245
61.30000,3.06499,14847.00888,0.00000,0.00900,178.39002
61.40000,3.07007,14872.64782,0.00000,0.00903,178.69808
61.50000,3.07491,14899.12868,0.00000,0.00904,179.01625
61.60000,3.07994,14923.97487,0.00000,0.00906,179.31478
61.70000,3.08484,14950.16813,0.00000,0.00909,179.62950
61.80000,3.08998,14975.98588,0.00000,0.00910,179.93971
61.90000,3.09494,15001.33425,0.00000,0.00913,180.24427
62.00000,3.10009,15026.14319,0.00000,0.00914,180.54236
62.10000,3.10499,15054.03370,0.00000,0.00917,180.87747
62.20000,3.11001,15079.51915,0.00000,0.00918,181.18368
62.30000,3.11497,15105.75563,0.00000,0.00920,181.49892
62.40000,3.12005,15131.45864,0.00000,0.00923,181.80775
62.50000,3.12496,15158.51021,0.00000,0.00924,182.13278
62.60000,3.12998,15182.86616,0.00000,0.00926,182.42542
62.70000,3.13494,15210.01011,0.00000,0.00928,182.75156
62.80000,3.13996,15233.35576,0.00000,0.00930,183.03206
62.90000,3.14505,15260.50121,0.00000,0.00932,183.35822
63.00000,3.15001,15284.04355,0.00000,0.00934,183.64109
63.10000,3.15509,15313.31539,0.00000,0.00937,183.99279
63.20000,3.15993,15337.50892,0.00000,0.00938,184.28348
63.30000,3.16508,15364.26842,0.00000,0.00941,184.60500
63.40000,3.16992,15387.02697,0.00000,0.00942,184.87845
63.50000,3.17506,15414.16943,0.00000,0.00944,185.20458
63.60000,3.17984,15440.30458,0.00000,0.00946,185.51860
63.70000,3.18505,15468.71662,0.00000,0.00948,185.85997
63.80000,3.18995,15492.83862,0.00000,0.00950,186.14980
63.90000,3.19509,15518.88883,0.00000,0.00952,186.46280
64.00000,3.19987,15542.64575,0.00000,0.00954,186.74825
64.10000,3.20502,15569.20707,0.00000,0.00956,187.06739
64.20000,3.20992,15594.22910,0.00000,0.00958,187.36803
64.30000,3.21506,15620.53263,0.00000,0.00961,187.68407
64.40000,3.21990,15644.59205,0.00000,0.00962,187.97315
64.50000,3.22499,15670.96710,0.00000,0.00964,188.29006
64.60000,3.22995,15697.47031,0.00000,0.00966,188.60850
64.70000,3.23497,15722.65923,0.00000,0.00968,188.91115
64.80000,3.23999,15749.41427,0.00000,0.00970,189.23262
64.90000,3.24495,15772.83591,0.00000,0.00972,189.51403
65.00000,3.24998,15799.20202,0.00000,0.00975,189.83083
65.10000,3.25494,15822.26902,0.00000,0.00975,190.10798
65.20000,3.26008,15849.84809,0.00000,0.00978,190.43935
65.30000,3.26498,15873.64823,0.00000,0.00980,190.72531
65.40000,3.27007,15900.65509,0.00000,0.00982,191.04981
65.50000,3.27485,15924.19595,0.00000,0.00984,191.33266
65.60000,3.28005,15951.98661,0.00000,0.00986,191.66657
65.70000,3.28489,15975.77929,0.00000,0.00988,191.95244
65.80000,3.29010,16003.32111,0.00000,0.00990,192.28336
65.90000,3.29488,16027.20022,0.00000,0.00992,192.57027
66.00000,3.30002,16053.98357,0.00000,0.00994,192.89208
66.10000,3.30492,16079.34535,0.00000,0.00996,193.19681
66.20000,3.31007,16104.38973,0.00000,0.00998,193.49772
66.30000,3.31497,16130.05698,0.00000,0.01000,193.80612
66.40000,3.31999,16154.87039,0.00000,0.01002,194.10426
66.50000,3.32495,16180.47357,0.00000,0.01004,194.41189
66.60000,3.32998,16205.43301,0.00000,0.01006,194.71178
66.70000,3.33500,16231.47577,0.00000,0.01008,195.02469
66.80000,3.34002,16257.31587,0.00000,0.01010,195.33516
66.90000,3.34492,16282.98461,0.00000,0.01012,195.64358
67.00000,3.35001,16310.03618,0.00000,0.01013,195.96861
67.10000,3.35497,16336.64072,0.00000,0.01016,196.28827
67.20000,3.36005,16361.00560,0.00000,0.01018,196.58102
67.30000,3.36501,16386.09469,0.00000,0.01020,196.88247
67.40000,3.36997,16410.35974,0.00000,0.01022,197.17402
67.50000,3.37506,16437.18481,0.00000,0.01024,197.49633
67.60000,3.37996,16460.20859,0.00000,0.01026,197.77296
67.70000,3.38504,16487.79213,0.00000,0.01028,198.10439
67.80000,3.38994,16510.84423,0.00000,0.01030,198.38136
67.90000,3.39503,16538.91802,0.00000,0.01032,198.71867
68.00000,3.39987,16561.68401,0.00000,0.01034,198.99221
68.10000,3.40507,16589.71757,0.00000,0.01036,199.32904
68.20000,3.40991,16612.86801,0.00000,0.01037,199.60720
68.30000,3.41512,16638.96590,0.00000,0.01040,199.92077
68.40000,3.41990,16662.88525,0.00000,0.01042,200.20817
68.50000,3.42510,16689.18133,0.00000,0.01044,200.52412
68.60000,3.42994,16713.17965,0.00000,0.01046,200.81246
68.70000,3.43509,16738.85137,0.00000,0.01047,201.12092
68.80000,3.43987,16764.52011,0.00000,0.01050,201.42933
68.90000,3.44495,16789.58535,0.00000,0.01051,201.73050
69.00000,3.44985,16814.89795,0.00000,0.01054,202.03463
69.10000,3.45500,16839.50275,0.00000,0.01056,202.33026
69.20000,3.45990,16864.58141,0.00000,0.01058,202.63159
69.30000,3.46492,16888.67509,0.00000,0.01060,202.92108
69.40000,3.46988,16915.25728,0.00000,0.01061,203.24047
69.50000,3.47497,16939.37778,0.00000,0.01063,203.53028
69.60000,3.48005,16966.84062,0.00000,0.01066,203.86026
69.70000,3.48501,16989.53807,0.00000,0.01068,204.13297
69.80000,3.49003,17015.29771,0.00000,0.01070,204.44248
69.90000,3.49493,17038.22911,0.00000,0.01072,204.71800
70.00000,3.50008,17063.96341,0.00000,0.01074,205.02721
70.10000,3.50498,17087.44466,0.00000,0.01075,205.30934
70.20000,3.51006,17112.91075,0.00000,0.01078,205.61532
70.30000,3.51484,17137.97897,0.00000,0.01080,205.91652
70.40000,3.52005,17165.14677,0.00000,0.01082,206.24295
70.50000,3.52489,17189.14956,0.00000,0.01084,206.53135
70.60000,3.53009,17215.23404,0.00000,0.01086,206.84476
70.70000,3.53493,17240.59433,0.00000,0.01088,207.14947
70.80000,3.54008,17265.94716,0.00000,0.01090,207.45409
70.90000,3.54492,17289.51931,0.00000,0.01092,207.73731
71.00000,3.55006,17314.97198,0.00000,0.01094,208.04313
71.10000,3.55496,17339.99401,0.00000,0.01095,208.34377
71.20000,3.56005,17366.04571,0.00000,0.01098,208.65679
71.30000,3.56489,17390.56855,0.00000,0.01099,208.95144
71.40000,3.57003,17416.65006,0.00000,0.01102,209.26481
71.50000,3.57499,17441.00451,0.00000,0.01104,209.55744
71.60000,3.58007,17465.31278,0.00000,0.01106,209.84951
71.70000,3.58492,17490.54939,0.00000,0.01108,210.15273
71.80000,3.59000,17515.32555,0.00000,0.01109,210.45042
71.90000,3.59496,17540.13151,0.00000,0.01112,210.74847
72.00000,3.59999,17564.84360,0.00000,0.01114,211.04539
72.10000,3.60495,17590.39164,0.00000,0.01116,211.35236
72.20000,3.60991,17613.37817,0.00000,0.01118,211.62854
72.30000,3.61493,17641.23440,0.00000,0.01120,211.96324
72.40000,3.61989,17663.97059,0.00000,0.01122,212.23642
72.50000,3.62504,17690.42462,0.00000,0.01124,212.55427
72.60000,3.62988,17713.78070,0.00000,0.01126,212.83490
72.70000,3.63502,17741.23460,0.00000,0.01128,213.16477
72.80000,3.63986,17764.35226,0.00000,0.01129,213.44253
72.90000,3.64513,17791.61990,0.00000,0.01132,213.77016
73.00000,3.64991,17813.21764,0.00000,0.01134,214.02966
73.10000,3.65505,17839.77151,0.00000,0.01136,214.34871
73.20000,3.65983,17862.27673,0.00000,0.01138,214.61911
73.30000,3.66504,17888.33290,0.00000,0.01140,214.93218
73.40000,3.66994,17911.10039,0.00000,0.01142,215.20574
73.50000,3.67502,17935.09126,0.00000,0.01143,215.49400
73.60000,3.67992,17961.34859,0.00000,0.01146,215.80948
73.70000,3.68495,17986.24694,0.00000,0.01148,216.10864
73.80000,3.68991,18011.83969,0.00000,0.01150,216.41615
73.90000,3.69505,18035.74562,0.00000,0.01152,216.70338
74.00000,3.70001,18061.28770,0.00000,0.01154,217.01027
74.10000,3.70498,18084.96118,0.00000,0.01157,217.29472
74.20000,3.71000,18111.21106,0.00000,0.01158,217.61011
74.30000,3.71496,18133.56578,0.00000,0.01160,217.87871
74.40000,3.72010,18161.91077,0.00000,0.01162,218.21928
74.50000,3.72495,18184.34298,0.00000,0.01164,218.48881
74.60000,3.72997,18211.89970,0.00000,0.01167,218.81991
74.70000,3.73493,18236.19902,0.00000,0.01168,219.11187
74.80000,3.74007,18262.60388,0.00000,0.01171,219.42913
74.90000,3.74497,18285.06738,0.00000,0.01172,219.69904
75.00000,3.75006,18311.05351,0.00000,0.01175,220.01126
75.10000,3.75496,18334.88941,0.00000,0.01177,220.29766
75.20000,3.76010,18361.54610,0.00000,0.01179,220.61794
75.30000,3.76500,18385.06758,0.00000,0.01181,220.90056
75.40000,3.77015,18410.74228,0.00000,0.01183,221.20905
75.50000,3.77493,18434.35317,0.00000,0.01185,221.49274
75.60000,3.78007,18460.59561,0.00000,0.01187,221.80805
75.70000,3.78491,18483.59406,0.00000,0.01189,222.08438
75.80000,3.79006,18509.26131,0.00000,0.01192,222.39277
75.90000,3.79490,18533.76776,0.00000,0.01193,222.68722
76.00000,3.79992,18558.34872,0.00000,0.01195,222.98257
76.10000,3.80494,18584.46300,0.00000,0.01197,223.29634
76.20000,3.81003,18610.23903,0.00000,0.01200,223.60604
76.30000,3.81505,18635.24020,0.00000,0.01202,223.90644
76.40000,3.82007,18660.18325,0.00000,0.01204,224.20613
76.50000,3.82491,18683.34115,0.00000,0.01206,224.48438
76.60000,3.83000,18708.01449,0.00000,0.01208,224.78084
76.70000,3.83496,18733.82181,0.00000,0.01210,225.09092
76.80000,3.84004,18756.50883,0.00000,0.01212,225.36351
76.90000,3.84500,18783.08058,0.00000,0.01215,225.68277
77.00000,3.84991,18806.75554,0.00000,0.01216,225.96723
77.10000,3.85499,18832.95327,0.00000,0.01218,226.28200
77.20000,3.86001,18855.49426,0.00000,0.01221,226.55284
77.30000,3.86509,18881.01846,0.00000,0.01222,226.85952
77.40000,3.86993,18903.39702,0.00000,0.01224,227.12840
77.50000,3.87502,18928.14338,0.00000,0.01227,227.42573
77.60000,3.87992,18952.15958,0.00000,0.01228,227.71429
77.70000,3.88512,18977.90283,0.00000,0.01231,228.02360
77.80000,3.88990,19000.71800,0.00000,0.01232,228.29773
77.90000,3.89505,19027.69208,0.00000,0.01235,228.62183
78.00000,3.89983,19050.71288,0.00000,0.01236,228.89843
78.10000,3.90503,19076.31010,0.00000,0.01239,229.20599
78.20000,3.90993,19099.81370,0.00000,0.01241,229.48839
78.30000,3.91508,19123.77179,0.00000,0.01243,229.77625
78.40000,3.91992,19146.33363,0.00000,0.01245,230.04734
78.50000,3.92500,19172.10072,0.00000,0.01247,230.35693
78.60000,3.92996,19195.36740,0.00000,0.01249,230.63649
78.70000,3.93505,19219.45661,0.00000,0.01251,230.92592
78.80000,3.94001,19243.29996,0.00000,0.01253,231.21241
78.90000,3.94497,19267.06284,0.00000,0.01256,231.49792
79.00000,3.94999,19292.70327,0.00000,0.01257,231.80600
79.10000,3.95501,19315.90587,0.00000,0.01260,232.08478
79.20000,3.96010,19341.78621,0.00000,0.01262,232.39574
79.30000,3.96500,19364.79062,0.00000,0.01264,232.67214
79.40000,3.97008,19391.92116,0.00000,0.01266,232.99812
79.50000,3.97498,19414.20734,0.00000,0.01268,233.26590
79.60000,3.98013,19440.53769,0.00000,0.01270,233.58226
79.70000,3.98503,19462.51988,0.00000,0.01272,233.84638
79.80000,3.99005,19487.88315,0.00000,0.01274,234.15113
79.90000,3.99495,19510.85031,0.00000,0.01276,234.42708
80.00000,4.00010,19536.32981,0.00000,0.01278,234.73322
80.10000,4.00500,19559.60840,0.00000,0.01280,235.01292
80.20000,4.01014,19585.15793,0.00000,0.01282,235.31990
80.30000,4.01492,19608.16532,0.00000,0.01285,235.59634
80.40000,4.02007,19634.85181,0.00000,0.01287,235.91699
80.50000,4.02497,19658.47462,0.00000,0.01289,236.20082
80.60000,4.03011,19682.94978,0.00000,0.01291,236.49489
80.70000,4.03495,19705.41775,0.00000,0.01293,236.76485
80.80000,4.03998,19729.80052,0.00000,0.01295,237.05782
80.90000,4.04488,19752.38174,0.00000,0.01297,237.32913
81.00000,4.05008,19776.17294,0.00000,0.01299,237.61499
81.10000,4.05492,19799.66909,0.00000,0.01301,237.89730
81.20000,4.06001,19823.00282,0.00000,0.01303,238.17766
81.30000,4.06497,19848.88613,0.00000,0.01306,238.48866
81.40000,4.06993,19871.73557,0.00000,0.01308,238.76320
81.50000,4.07501,19898.08679,0.00000,0.01310,239.07981
81.60000,4.08003,19919.38800,0.00000,0.01311,239.33575
81.70000,4.08494,19943.71563,0.00000,0.01314,239.62805
81.80000,4.08990,19965.41470,0.00000,0.01316,239.88877
81.90000,4.09504,19991.33974,0.00000,0.01318,240.20027
82.00000,4.09994,20012.34293,0.00000,0.01320,240.45262
82.10000,4.10509,20036.65119,0.00000,0.01322,240.74469
82.20000,4.10987,20059.07297,0.00000,0.01324,241.01410
82.30000,4.11501,20084.73277,0.00000,0.01326,241.32240
82.40000,4.11985,20104.89106,0.00000,0.01328,241.56461
82.50000,4.12506,20129.95183,0.00000,0.01330,241.86572
82.60000,4.12990,20151.90870,0.00000,0.01332,242.12954
82.70000,4.13504,20176.77873,0.00000,0.01335,242.42836
82.80000,4.13988,20200.90818,0.00000,0.01337,242.71828
82.90000,4.14503,20225.14343,0.00000,0.01339,243.00947
83.00000,4.14993,20249.03148,0.00000,0.01341,243.29649
83.10000,4.15501,20271.65592,0.00000,0.01343,243.56833
83.20000,4.15997,20294.86001,0.00000,0.01345,243.84713
83.30000,4.16500,20316.57547,0.00000,0.01347,244.10804
83.40000,4.16996,20337.11374,0.00000,0.01349,244.35482
83.50000,4.17504,20359.16597,0.00000,0.01351,244.61978
83.60000,4.17994,20381.29121,0.00000,0.01353,244.88562
83.70000,4.18497,20401.72368,0.00000,0.01355,245.13112
83.80000,4.18999,20428.00039,0.00000,0.01357,245.44684
83.90000,4.19501,20448.12590,0.00000,0.01359,245.68865
84.00000,4.20009,20460.60562,0.00000,0.01360,245.83860
84.02800,4.20147,19937.60020,0.00000,0.01326,239.55457
84.03000,4.20159,19329.15747,0.00000,0.01272,232.24400
84.03200,4.20183,18528.03826,0.00000,0.01200,222.61838
84.03400,4.20201,17596.30144,0.00000,0.01132,211.42336
84.03600,4.20230,16560.32503,0.00000,0.01078,198.97588
84.03800,4.20266,15450.15424,0.00000,0.01031,185.63694
84.04000,4.20296,14302.86765,0.00000,0.00985,171.85205
84.04200,4.20332,13139.19574,0.00000,0.00933,157.87028
84.04400,4.20374,11969.59317,0.00000,0.00866,143.81725