File: scratch/college-stuff/ME Lab/ME lab Fall 2013/group13/group13.is_tens_RawData/Specimen_RawData_1.csv
Time,Extension,Load,Strain 2,Tensile strain,Tensile stress
(sec),(mm),(N),(mm/mm),(mm/mm),(MPa)
0.00000,0.00000,-0.28091,0.00000,0.00000,-0.00345
0.30000,0.01345,17.38237,0.00000,0.00000,0.21361
0.60000,0.02989,26.98021,0.00000,0.00000,0.33156
0.90000,0.04502,33.74559,0.00000,0.00000,0.41470
1.20000,0.05997,42.44727,0.00000,0.00000,0.52164
1.50000,0.07504,59.24143,0.00000,0.00000,0.72802
1.80000,0.08998,74.59638,0.00000,0.00000,0.91672
2.10000,0.10511,93.90053,0.00000,-0.00001,1.15394
2.40000,0.11994,121.80143,0.00000,-0.00001,1.49682
2.70000,0.13512,152.58401,0.00000,-0.00001,1.87511
3.00000,0.14995,181.37086,0.00000,-0.00001,2.22887
3.30000,0.16496,226.53919,0.00000,-0.00001,2.78394
3.60000,0.18009,285.52634,0.00000,-0.00002,3.50884
3.90000,0.19491,352.15912,0.00000,-0.00001,4.32769
4.20000,0.21010,436.96300,0.00000,-0.00001,5.36984
4.50000,0.22493,537.62058,0.00000,-0.00001,6.60683
4.80000,0.24000,648.70953,0.00000,0.00000,7.97200
5.10000,0.25500,774.23323,0.00000,0.00000,9.51456
5.40000,0.27001,913.08961,0.00000,0.00002,11.22097
5.70000,0.28502,1059.84788,0.00000,0.00002,13.02448
6.00000,0.29996,1208.25181,0.00000,0.00004,14.84822
6.30000,0.31503,1373.23616,0.00000,0.00005,16.87572
6.60000,0.32992,1570.25978,0.00000,0.00008,19.29694
6.90000,0.34505,1789.63561,0.00000,0.00011,21.99286
7.20000,0.35993,2009.43016,0.00000,0.00015,24.69391
7.50000,0.37500,2226.41397,0.00000,0.00018,27.36043
7.80000,0.38995,2443.37767,0.00000,0.00021,30.02670
8.10000,0.40489,2650.54479,0.00000,0.00024,32.57258
8.40000,0.42008,2875.65291,0.00000,0.00027,35.33894
8.70000,0.43491,3099.40055,0.00000,0.00031,38.08857
9.00000,0.45004,3329.93716,0.00000,0.00035,40.92164
9.30000,0.46486,3556.30182,0.00000,0.00038,43.70344
9.60000,0.47993,3786.49011,0.00000,0.00042,46.53223
9.90000,0.49494,4014.42796,0.00000,0.00046,49.33336
10.20000,0.50994,4240.91257,0.00000,0.00049,52.11663
10.50000,0.52501,4473.41204,0.00000,0.00053,54.97382
10.80000,0.53990,4694.44953,0.00000,0.00057,57.69015
11.10000,0.55503,4923.43307,0.00000,0.00061,60.50413
11.40000,0.56991,5144.14944,0.00000,0.00065,63.21652
11.70000,0.58498,5366.05678,0.00000,0.00069,65.94354
12.00000,0.59987,5584.97943,0.00000,0.00072,68.63388
12.30000,0.61493,5797.38393,0.00000,0.00076,71.24413
12.60000,0.63000,6015.22066,0.00000,0.00080,73.92112
12.90000,0.64489,6221.43038,0.00000,0.00083,76.45524
13.20000,0.66002,6426.20847,0.00000,0.00087,78.97176
13.50000,0.67484,6618.11382,0.00000,0.00090,81.33009
13.80000,0.69009,6787.76279,0.00000,0.00093,83.41491
14.10000,0.70498,6947.55018,0.00000,0.00096,85.37853
14.40000,0.72004,7111.59706,0.00000,0.00099,87.39451
14.70000,0.73499,7271.29504,0.00000,0.00101,89.35704
15.00000,0.75000,7429.49769,0.00000,0.00104,91.30119
15.30000,0.76501,7593.12436,0.00000,0.00107,93.31200
15.60000,0.77989,7747.63301,0.00000,0.00110,95.21076
15.90000,0.79508,7910.86927,0.00000,0.00113,97.21678
16.20000,0.80985,8063.74475,0.00000,0.00115,99.09546
16.50000,0.82504,8220.10711,0.00000,0.00118,101.01700
16.80000,0.83986,8371.27864,0.00000,0.00120,102.87475
17.10000,0.85505,8512.69290,0.00000,0.00123,104.61259
17.40000,0.87000,8656.94359,0.00000,0.00125,106.38529
17.70000,0.88494,8793.91432,0.00000,0.00128,108.06853
18.00000,0.90013,8939.73932,0.00000,0.00130,109.86057
18.30000,0.91496,9079.54350,0.00000,0.00132,111.57863
18.60000,0.93003,9223.21603,0.00000,0.00135,113.34422
18.90000,0.94491,9366.92208,0.00000,0.00137,115.11023
19.20000,0.95998,9513.57707,0.00000,0.00140,116.91247
19.50000,0.97493,9657.94325,0.00000,0.00142,118.68659
19.80000,0.98999,9801.67687,0.00000,0.00145,120.45293
20.10000,1.00500,9951.96030,0.00000,0.00147,122.29977
20.40000,1.01995,10093.04896,0.00000,0.00150,124.03361
20.70000,1.03502,10242.13508,0.00000,0.00152,125.86573
21.00000,1.04990,10389.16856,0.00000,0.00155,127.67263
21.30000,1.06503,10537.15050,0.00000,0.00158,129.49118
21.60000,1.07992,10683.76452,0.00000,0.00161,131.29292
21.90000,1.09504,10828.37954,0.00000,0.00163,133.07010
22.20000,1.10999,10978.76802,0.00000,0.00166,134.91822
22.50000,1.12494,11124.80611,0.00000,0.00168,136.71289
22.80000,1.14007,11275.35105,0.00000,0.00171,138.56294
23.10000,1.15489,11422.96568,0.00000,0.00174,140.37697
23.40000,1.17008,11576.53630,0.00000,0.00176,142.26421
23.70000,1.18497,11722.84484,0.00000,0.00179,144.06219
24.00000,1.19998,11875.22262,0.00000,0.00182,145.93477
24.30000,1.21498,12027.64660,0.00000,0.00184,147.80791
24.60000,1.22999,12178.17217,0.00000,0.00187,149.65772
24.90000,1.24500,12334.63809,0.00000,0.00190,151.58053
25.20000,1.25988,12479.72250,0.00000,0.00193,153.36347
25.50000,1.27507,12635.75256,0.00000,0.00196,155.28093
25.80000,1.28996,12784.13385,0.00000,0.00198,157.10439
26.10000,1.30503,12938.17908,0.00000,0.00201,158.99745
26.40000,1.31991,13093.52070,0.00000,0.00204,160.90645
26.70000,1.33498,13243.98369,0.00000,0.00207,162.75549
27.00000,1.35011,13399.28359,0.00000,0.00210,164.66397
27.30000,1.36493,13550.81350,0.00000,0.00213,166.52612
27.60000,1.38006,13705.80345,0.00000,0.00216,168.43080
27.90000,1.39495,13858.80858,0.00000,0.00219,170.31108
28.20000,1.41002,14015.81615,0.00000,0.00222,172.24055
28.50000,1.42490,14168.65140,0.00000,0.00224,174.11874
28.80000,1.43997,14323.94534,0.00000,0.00227,176.02715
29.10000,1.45498,14481.05872,0.00000,0.00230,177.95792
29.40000,1.46998,14632.60502,0.00000,0.00233,179.82027
29.70000,1.48499,14790.77935,0.00000,0.00236,181.76408
30.00000,1.49988,14943.68315,0.00000,0.00239,183.64312
30.30000,1.51507,15103.84977,0.00000,0.00242,185.61141
30.60000,1.52989,15254.15927,0.00000,0.00244,187.45856
30.90000,1.54502,15410.43818,0.00000,0.00247,189.37908
31.20000,1.55997,15566.45781,0.00000,0.00250,191.29640
31.50000,1.57497,15722.10193,0.00000,0.00253,193.20912
31.80000,1.59004,15879.87840,0.00000,0.00256,195.14803
32.10000,1.60487,16034.69253,0.00000,0.00259,197.05055
32.40000,1.62012,16191.71947,0.00000,0.00263,198.98025
32.70000,1.63488,16346.50081,0.00000,0.00266,200.88236
33.00000,1.65001,16505.76293,0.00000,0.00269,202.83954
33.30000,1.66496,16661.17311,0.00000,0.00272,204.74937
33.60000,1.67997,16819.38618,0.00000,0.00275,206.69366
33.90000,1.69491,16976.13001,0.00000,0.00279,208.61988
34.20000,1.70998,17129.72522,0.00000,0.00281,210.50742
34.50000,1.72505,17288.58501,0.00000,0.00285,212.45965
34.80000,1.73987,17438.73954,0.00000,0.00288,214.30490
35.10000,1.75500,17598.61559,0.00000,0.00291,216.26962
35.40000,1.76989,17754.40872,0.00000,0.00294,218.18416
35.70000,1.78502,17910.14671,0.00000,0.00298,220.09803
36.00000,1.79996,18066.69086,0.00000,0.00301,222.02180
36.30000,1.81503,18221.64357,0.00000,0.00305,223.92601
36.60000,1.83004,18380.40501,0.00000,0.00308,225.87704
36.90000,1.84486,18533.79309,0.00000,0.00311,227.76202
37.20000,1.86005,18690.82302,0.00000,0.00315,229.69177
37.50000,1.87488,18842.46618,0.00000,0.00319,231.55531
37.80000,1.89007,19000.30822,0.00000,0.00322,233.49503
38.10000,1.90483,19146.97438,0.00000,0.00325,235.29742
38.40000,1.91990,19302.69599,0.00000,0.00329,237.21108
38.70000,1.93491,19457.63528,0.00000,0.00333,239.11513
39.00000,1.94997,19602.54461,0.00000,0.00336,240.89593
39.30000,1.96504,19755.94908,0.00000,0.00341,242.78112
39.60000,1.97987,19898.21494,0.00000,0.00344,244.52942
39.90000,1.99512,20049.11155,0.00000,0.00348,246.38379
40.20000,2.00994,20193.67218,0.00000,0.00352,248.16030
40.50000,2.02507,20337.78131,0.00000,0.00356,249.93126
40.80000,2.03996,20480.65066,0.00000,0.00360,251.68698
41.10000,2.05502,20616.22590,0.00000,0.00365,253.35307
41.40000,2.07003,20756.42645,0.00000,0.00369,255.07599
41.70000,2.08486,20888.60422,0.00000,0.00374,256.70033
42.00000,2.09999,21022.79365,0.00000,0.00378,258.34938
42.30000,2.11493,21153.20861,0.00000,0.00382,259.95206
42.60000,2.13000,21281.97849,0.00000,0.00388,261.53451
42.90000,2.14489,21402.92376,0.00000,0.00393,263.02081
43.20000,2.16001,21523.53376,0.00000,0.00398,264.50299
43.50000,2.17496,21639.57506,0.00000,0.00403,265.92902
43.80000,2.18997,21750.03737,0.00000,0.00409,267.28649
44.10000,2.20504,21860.14503,0.00000,0.00415,268.63961
44.40000,2.21992,21960.89178,0.00000,0.00420,269.87768
44.70000,2.23511,22064.50850,0.00000,0.00427,271.15103
45.00000,2.24988,22157.73612,0.00000,0.00433,272.29671
45.30000,2.26506,22247.49327,0.00000,0.00439,273.39973
45.60000,2.28001,22333.83805,0.00000,0.00446,274.46083
45.90000,2.29496,22412.22858,0.00000,0.00454,275.42417
46.20000,2.31003,22488.43461,0.00000,0.00461,276.36067
46.50000,2.32491,22552.54686,0.00000,0.00470,277.14854
46.80000,2.34004,22617.58000,0.00000,0.00478,277.94773
47.10000,2.35487,22673.36994,0.00000,0.00487,278.63334
47.40000,2.36994,22730.88545,0.00000,0.00496,279.34015
47.70000,2.38494,22779.68079,0.00000,0.00507,279.93979
48.00000,2.40001,22821.66481,0.00000,0.00517,280.45574
48.30000,2.41496,22864.66509,0.00000,0.00528,280.98417
48.60000,2.43002,22900.96581,0.00000,0.00539,281.43027
48.90000,2.44509,22940.53137,0.00000,0.00550,281.91649
49.20000,2.45992,22970.53933,0.00000,0.00562,282.28526
49.50000,2.47511,23003.66014,0.00000,0.00575,282.69228
49.80000,2.48993,23030.30789,0.00000,0.00588,283.01975
50.10000,2.50506,23055.93789,0.00000,0.00601,283.33472
50.40000,2.52001,23080.83624,0.00000,0.00615,283.64070
50.70000,2.53495,23102.94956,0.00000,0.00628,283.91245
51.00000,2.55002,23126.47104,0.00000,0.00642,284.20150
51.30000,2.56491,23145.36572,0.00000,0.00656,284.43370
51.60000,2.58004,23166.46874,0.00000,0.00670,284.69304
51.90000,2.59498,23182.97327,0.00000,0.00684,284.89586
52.20000,2.61005,23201.33150,0.00000,0.00699,285.12146
52.50000,2.62500,23217.42624,0.00000,0.00714,285.31925
52.80000,2.64006,23233.73109,0.00000,0.00730,285.51962
53.10000,2.65501,23251.52904,0.00000,0.00745,285.73834
53.40000,2.67002,23261.86001,0.00000,0.00760,285.86530
53.70000,2.68509,23278.48375,0.00000,0.00775,286.06959
54.00000,2.69985,23289.26623,0.00000,0.00790,286.20210
54.30000,2.71510,23307.25640,0.00000,0.00806,286.42318
54.60000,2.72987,23317.73937,0.00000,0.00822,286.55200
54.90000,2.74500,23330.85835,0.00000,0.00838,286.71322
55.20000,2.76000,23344.38562,0.00000,0.00854,286.87946
55.50000,2.77495,23351.67229,0.00000,0.00870,286.96900
55.80000,2.79008,23365.85820,0.00000,0.00885,287.14334
56.10000,2.80490,23374.23861,0.00000,0.00901,287.24632
56.40000,2.82003,23386.62595,0.00000,0.00918,287.39855
56.70000,2.83492,23394.11378,0.00000,0.00934,287.49057
57.00000,2.84993,23405.65324,0.00000,0.00949,287.63238
57.30000,2.86493,23414.90686,0.00000,0.00965,287.74609
57.60000,2.88006,23424.23201,0.00000,0.00981,287.86069
57.90000,2.89501,23436.18572,0.00000,0.00998,288.00759
58.20000,2.91001,23441.78259,0.00000,0.01015,288.07637
58.50000,2.92508,23455.41865,0.00000,0.01031,288.24394
58.80000,2.93991,23460.47908,0.00000,0.01048,288.30613
59.10000,2.95516,23472.18990,0.00000,0.01064,288.45005
59.40000,2.96992,23478.11162,0.00000,0.01080,288.52282
59.70000,2.98505,23487.30564,0.00000,0.01096,288.63580
60.00000,3.00000,23497.69771,0.00000,0.01112,288.76351
60.30000,3.01494,23502.62552,0.00000,0.01129,288.82407
60.60000,3.03001,23514.29462,0.00000,0.01145,288.96747
60.90000,3.04496,23519.48768,0.00000,0.01162,289.03129
61.20000,3.06009,23530.73955,0.00000,0.01178,289.16956
61.50000,3.07497,23536.19039,0.00000,0.01194,289.23655
61.80000,3.08998,23546.58097,0.00000,0.01211,289.36424
62.10000,3.10499,23554.87943,0.00000,0.01227,289.46622
62.40000,3.12011,23561.65349,0.00000,0.01243,289.54947
62.70000,3.13500,23571.82950,0.00000,0.01259,289.67452
63.00000,3.15001,23573.50439,0.00000,0.01276,289.69510
63.30000,3.16508,23586.18677,0.00000,0.01292,289.85096
63.60000,3.17984,23590.31886,0.00000,0.01308,289.90174
63.90000,3.19509,23598.49662,0.00000,0.01325,290.00223
64.20000,3.20992,23607.09459,0.00000,0.01341,290.10789
64.50000,3.22505,23613.30092,0.00000,0.01358,290.18416
64.80000,3.24005,23621.57106,0.00000,0.01373,290.28579
65.10000,3.25494,23625.33659,0.00000,0.01389,290.33207
65.40000,3.27007,23635.26523,0.00000,0.01405,290.45408
65.70000,3.28495,23639.76985,0.00000,0.01422,290.50944
66.00000,3.30002,23650.09934,0.00000,0.01438,290.63638
66.30000,3.31497,23653.30011,0.00000,0.01454,290.67571
66.60000,3.33004,23662.22739,0.00000,0.01470,290.78542
66.90000,3.34486,23668.50674,0.00000,0.01486,290.86259
67.20000,3.36005,23675.60714,0.00000,0.01502,290.94984
67.50000,3.37506,23685.00382,0.00000,0.01518,291.06532
67.80000,3.39000,23685.84573,0.00000,0.01534,291.07567
68.10000,3.40513,23696.13051,0.00000,0.01550,291.20206
68.40000,3.41990,23700.31476,0.00000,0.01566,291.25348
68.70000,3.43509,23709.14221,0.00000,0.01582,291.36196
69.00000,3.44991,23715.98929,0.00000,0.01598,291.44610
69.30000,3.46492,23721.03035,0.00000,0.01614,291.50805
69.60000,3.48005,23729.79373,0.00000,0.01630,291.61574
69.90000,3.49493,23733.74403,0.00000,0.01646,291.66429
70.20000,3.51006,23742.73092,0.00000,0.01662,291.77473
70.50000,3.52495,23747.96867,0.00000,0.01677,291.83910
70.80000,3.54008,23756.99580,0.00000,0.01693,291.95003
71.10000,3.55496,23760.34558,0.00000,0.01709,291.99120
71.40000,3.57003,23768.90630,0.00000,0.01725,292.09640
71.70000,3.58492,23773.70596,0.00000,0.01740,292.15538
72.00000,3.60004,23780.70801,0.00000,0.01756,292.24143
72.30000,3.61493,23789.67255,0.00000,0.01772,292.35160
72.60000,3.62988,23791.75276,0.00000,0.01788,292.37716
72.90000,3.64513,23802.65892,0.00000,0.01803,292.51119
73.20000,3.65983,23802.56802,0.00000,0.01819,292.51007
73.50000,3.67502,23810.16314,0.00000,0.01834,292.60340
73.80000,3.68991,23818.62253,0.00000,0.01850,292.70736
74.10000,3.70498,23825.03599,0.00000,0.01866,292.78618
74.40000,3.72010,23833.41640,0.00000,0.01882,292.88916
74.70000,3.73499,23836.88390,0.00000,0.01896,292.93178
75.00000,3.75006,23843.55813,0.00000,0.01912,293.01380
75.30000,3.76506,23849.37108,0.00000,0.01927,293.08523
75.60000,3.78007,23856.49383,0.00000,0.01943,293.17276
75.90000,3.79484,23860.00752,0.00000,0.01958,293.21594
76.20000,3.81009,23869.29393,0.00000,0.01974,293.33006
76.50000,3.82491,23872.78974,0.00000,0.01990,293.37302
76.80000,3.84004,23877.85017,0.00000,0.02005,293.43521
77.10000,3.85499,23886.70444,0.00000,0.02020,293.54402
77.40000,3.86987,23889.32556,0.00000,0.02035,293.57623
77.70000,3.88512,23900.48802,0.00000,0.02051,293.71341
78.00000,3.89983,23901.80975,0.00000,0.02066,293.72965
78.30000,3.91508,23909.98155,0.00000,0.02081,293.83007
78.60000,3.92996,23915.25805,0.00000,0.02096,293.89492
78.90000,3.94497,23921.10378,0.00000,0.02111,293.96676
79.20000,3.96010,23930.45723,0.00000,0.02127,294.08170
79.50000,3.97504,23933.77870,0.00000,0.02142,294.12252
79.80000,3.99005,23940.46038,0.00000,0.02158,294.20463
80.10000,4.00500,23944.15438,0.00000,0.02173,294.25002
80.40000,4.02013,23953.77755,0.00000,0.02188,294.36828
80.70000,4.03495,23955.07991,0.00000,0.02202,294.38429
81.00000,4.05008,23963.82242,0.00000,0.02217,294.49173
81.30000,4.06497,23971.03757,0.00000,0.02233,294.58039
81.60000,4.08003,23973.39493,0.00000,0.02248,294.60936
81.90000,4.09504,23983.31910,0.00000,0.02264,294.73132
82.20000,4.10987,23981.40132,0.00000,0.02279,294.70775
82.50000,4.12506,23990.83972,0.00000,0.02293,294.82374
82.80000,4.13988,23996.83595,0.00000,0.02308,294.89743
83.10000,4.15501,24003.16894,0.00000,0.02322,294.97526
83.40000,4.16996,24009.48703,0.00000,0.02337,295.05290
83.70000,4.18497,24014.57876,0.00000,0.02353,295.11547
84.00000,4.20009,24021.64638,0.00000,0.02368,295.20232
84.30000,4.21498,24024.73837,0.00000,0.02383,295.24032
84.60000,4.23005,24032.12935,0.00000,0.02398,295.33115
84.90000,4.24499,24036.61460,0.00000,0.02412,295.38627
85.20000,4.26006,24043.76119,0.00000,0.02428,295.47409
85.50000,4.27489,24045.26472,0.00000,0.02443,295.49257
85.80000,4.29008,24053.07293,0.00000,0.02458,295.58853
86.10000,4.30496,24059.02892,0.00000,0.02472,295.66172
86.40000,4.32003,24061.29241,0.00000,0.02487,295.68954
86.70000,4.33504,24071.69044,0.00000,0.02502,295.81732
87.00000,4.34986,24073.45474,0.00000,0.02516,295.83900
87.30000,4.36511,24082.64726,0.00000,0.02531,295.95197
87.60000,4.37994,24087.51398,0.00000,0.02546,296.01177
87.90000,4.39501,24091.48812,0.00000,0.02561,296.06061
88.20000,4.41001,24099.16520,0.00000,0.02576,296.15495
88.50000,4.42496,24104.04533,0.00000,0.02590,296.21493
88.80000,4.44003,24110.65698,0.00000,0.02605,296.29618
89.10000,4.45497,24111.92656,0.00000,0.02619,296.31178
89.40000,4.47004,24120.49472,0.00000,0.02634,296.41707
89.70000,4.48499,24122.72543,0.00000,0.02648,296.44449
90.00000,4.50006,24131.87176,0.00000,0.02663,296.55689
90.30000,4.51488,24135.59407,0.00000,0.02678,296.60263
90.60000,4.53007,24141.84511,0.00000,0.02693,296.67945
90.90000,4.54496,24147.59248,0.00000,0.02707,296.75008
91.20000,4.55996,24148.28688,0.00000,0.02721,296.75861
91.50000,4.57509,24157.82064,0.00000,0.02736,296.87577
91.80000,4.58986,24160.16906,0.00000,0.02750,296.90463
92.10000,4.60511,24168.83409,0.00000,0.02765,297.01112
92.40000,4.61987,24173.47580,0.00000,0.02780,297.06816
92.70000,4.63500,24179.36027,0.00000,0.02794,297.14047
93.00000,4.65007,24184.17335,0.00000,0.02809,297.19962
93.30000,4.66502,24188.95811,0.00000,0.02823,297.25842
93.60000,4.68002,24195.80072,0.00000,0.02838,297.34251
93.90000,4.69497,24198.80629,0.00000,0.02853,297.37945
94.20000,4.71004,24206.44760,0.00000,0.02868,297.47335
94.50000,4.72492,24206.68304,0.00000,0.02883,297.47624
94.80000,4.73999,24215.40171,0.00000,0.02897,297.58339
95.10000,4.75488,24218.07647,0.00000,0.02911,297.61626
95.40000,4.77001,24223.08028,0.00000,0.02925,297.67775
95.70000,4.78495,24231.56649,0.00000,0.02940,297.78204
96.00000,4.79996,24232.80627,0.00000,0.02954,297.79727
96.30000,4.81509,24242.05840,0.00000,0.02969,297.91097
96.60000,4.82991,24243.16853,0.00000,0.02983,297.92461
96.90000,4.84510,24250.24211,0.00000,0.02998,298.01154
97.20000,4.85999,24254.65435,0.00000,0.03012,298.06576
97.50000,4.87506,24259.92638,0.00000,0.03026,298.13055
97.80000,4.88994,24265.03748,0.00000,0.03040,298.19336
98.10000,4.90501,24269.79542,0.00000,0.03055,298.25183
98.40000,4.92002,24274.42223,0.00000,0.03070,298.30869
98.70000,4.93496,24279.45286,0.00000,0.03083,298.37051
99.00000,4.95003,24285.31200,0.00000,0.03098,298.44252
99.30000,4.96498,24286.48174,0.00000,0.03112,298.45689
99.60000,4.98005,24294.59691,0.00000,0.03126,298.55662
99.90000,4.99487,24296.73672,0.00000,0.03140,298.58291
100.20000,5.01006,24303.02054,0.00000,0.03155,298.66014
100.50000,5.02501,24310.02110,0.00000,0.03169,298.74617
100.80000,5.03996,24310.50241,0.00000,0.03183,298.75208
101.10000,5.05508,24319.52357,0.00000,0.03197,298.86294
101.40000,5.06991,24320.85425,0.00000,0.03211,298.87929
101.70000,5.08516,24327.72815,0.00000,0.03225,298.96377
102.00000,5.09992,24329.86647,0.00000,0.03239,298.99005
102.30000,5.11505,24336.12198,0.00000,0.03254,299.06692
102.60000,5.13000,24342.72766,0.00000,0.03268,299.14810
102.90000,5.14495,24345.10291,0.00000,0.03282,299.17729
103.20000,5.16001,24352.75912,0.00000,0.03296,299.27137
103.50000,5.17496,24353.68747,0.00000,0.03310,299.28278
103.80000,5.19003,24359.83121,0.00000,0.03324,299.35828
104.10000,5.20497,24360.70889,0.00000,0.03338,299.36907
104.40000,5.21998,24368.30699,0.00000,0.03351,299.46244
104.70000,5.23487,24374.55505,0.00000,0.03365,299.53922
105.00000,5.25000,24377.83629,0.00000,0.03379,299.57955
105.30001,5.26500,24385.31369,0.00000,0.03393,299.67144
105.60001,5.27995,24385.91570,0.00000,0.03407,299.67884
105.90001,5.29514,24394.47939,0.00000,0.03421,299.78407
106.20001,5.30990,24396.95895,0.00000,0.03434,299.81455
106.50001,5.32509,24401.85994,0.00000,0.03448,299.87477
106.80001,5.33992,24406.69686,0.00000,0.03461,299.93422
107.10001,5.35505,24412.77802,0.00000,0.03476,300.00895
107.40001,5.36999,24413.50818,0.00000,0.03489,300.01792
107.70001,5.38494,24418.72805,0.00000,0.03503,300.08207
108.00001,5.40007,24425.49020,0.00000,0.03517,300.16517
108.30001,5.41490,24426.45729,0.00000,0.03531,300.17705
108.60001,5.43002,24434.28040,0.00000,0.03544,300.27319
108.90001,5.44497,24435.54848,0.00000,0.03557,300.28877
109.20001,5.46004,24441.78313,0.00000,0.03571,300.36539
109.50001,5.47498,24447.09241,0.00000,0.03584,300.43064
109.80001,5.49011,24450.35279,0.00000,0.03598,300.47070
110.10001,5.50506,24457.96728,0.00000,0.03612,300.56428
110.40001,5.52001,24457.23563,0.00000,0.03626,300.55529
110.70001,5.53513,24464.50889,0.00000,0.03639,300.64467
111.00001,5.54990,24465.61903,0.00000,0.03653,300.65831
111.30001,5.56509,24470.54535,0.00000,0.03666,300.71885
111.60001,5.57991,24474.81304,0.00000,0.03680,300.77130
111.90001,5.59504,24479.29084,0.00000,0.03693,300.82632
112.20001,5.60999,24483.57940,0.00000,0.03707,300.87903
112.50001,5.62500,24486.11557,0.00000,0.03720,300.91019
112.80001,5.64006,24491.21177,0.00000,0.03733,300.97282
113.10001,5.65495,24493.32029,0.00000,0.03746,300.99873
113.40001,5.67008,24501.38032,0.00000,0.03759,301.09778
113.70001,5.68484,24502.72441,0.00000,0.03773,301.11430
114.00001,5.69997,24508.54033,0.00000,0.03787,301.18577
114.30001,5.71486,24512.89445,0.00000,0.03800,301.23928
114.60001,5.73011,24516.98929,0.00000,0.03814,301.28960
114.90001,5.74499,24521.30467,0.00000,0.03827,301.34263
115.20001,5.75994,24520.97237,0.00000,0.03840,301.33855
115.50001,5.77513,24530.26175,0.00000,0.03854,301.45271
115.80001,5.78995,24529.80429,0.00000,0.03866,301.44708
116.10001,5.80514,24536.81231,0.00000,0.03879,301.53321
116.40001,5.81991,24537.88221,0.00000,0.03892,301.54635
116.70001,5.83504,24543.58190,0.00000,0.03905,301.61640
117.00001,5.85004,24547.27590,0.00000,0.03918,301.66179
117.30001,5.86493,24549.62879,0.00000,0.03932,301.69071
117.60001,5.88000,24555.83662,0.00000,0.03944,301.76700
117.90001,5.89500,24556.90652,0.00000,0.03957,301.78014
118.20001,5.91007,24562.23667,0.00000,0.03970,301.84565
118.50001,5.92490,24565.11408,0.00000,0.03982,301.88101
118.80001,5.94003,24570.81228,0.00000,0.03996,301.95103
119.10001,5.95497,24574.17548,0.00000,0.04009,301.99236
119.40001,5.97010,24577.68917,0.00000,0.04021,302.03554
119.70001,5.98499,24582.80474,0.00000,0.04034,302.09841
120.00001,5.99994,24582.05670,0.00000,0.04047,302.08921
120.30001,6.01506,24588.22727,0.00000,0.04060,302.16504
120.60001,6.02983,24589.49685,0.00000,0.04072,302.18065
120.90001,6.04502,24595.07287,0.00000,0.04084,302.24917
121.20001,6.05996,24597.80127,0.00000,0.04097,302.28270
121.50001,6.07503,24601.68004,0.00000,0.04109,302.33037
121.80001,6.09004,24605.54540,0.00000,0.04122,302.37787
122.10001,6.10493,24609.70879,0.00000,0.04134,302.42903
122.40001,6.12005,24615.24159,0.00000,0.04147,302.49702
122.70001,6.13500,24617.00886,0.00000,0.04159,302.51874
123.00001,6.15007,24622.79201,0.00000,0.04172,302.58981
123.30001,6.16495,24621.51796,0.00000,0.04184,302.57415
123.60001,6.18008,24625.96148,0.00000,0.04197,302.62876
123.90001,6.19491,24630.51230,0.00000,0.04209,302.68469
124.20001,6.21010,24633.96639,0.00000,0.04222,302.72713
124.50001,6.22504,24641.06381,0.00000,0.04234,302.81435
124.80001,6.23993,24641.93404,0.00000,0.04246,302.82505
125.10001,6.25512,24646.70986,0.00000,0.04259,302.88374
125.40001,6.26988,24646.73519,0.00000,0.04270,302.88405
125.70001,6.28501,24651.32922,0.00000,0.04283,302.94051
126.00001,6.29996,24655.82788,0.00000,0.04295,302.99579
126.30001,6.31491,24659.30134,0.00000,0.04307,303.03847
126.60001,6.33003,24664.93845,0.00000,0.04319,303.10775
126.90001,6.34492,24666.42559,0.00000,0.04332,303.12602
127.20001,6.36005,24671.95392,0.00000,0.04344,303.19396
127.50001,6.37499,24672.96720,0.00000,0.04356,303.20641
127.80001,6.39012,24680.07207,0.00000,0.04369,303.29373
128.10001,6.40495,24679.71295,0.00000,0.04381,303.28931
128.40001,6.42008,24686.14578,0.00000,0.04393,303.36837
128.70001,6.43496,24688.09783,0.00000,0.04406,303.39236
129.00001,6.45009,24689.62371,0.00000,0.04418,303.41111
129.30001,6.46504,24696.74200,0.00000,0.04430,303.49858
129.60001,6.47987,24695.39940,0.00000,0.04442,303.48208
129.90001,6.49511,24702.81273,0.00000,0.04455,303.57319
130.20001,6.50982,24702.89618,0.00000,0.04467,303.57421
130.50001,6.52495,24707.17877,0.00000,0.04478,303.62684
130.80001,6.53995,24712.73243,0.00000,0.04491,303.69509
131.10001,6.55502,24715.96003,0.00000,0.04503,303.73475
131.40001,6.57003,24720.41398,0.00000,0.04516,303.78949
131.70001,6.58492,24721.47346,0.00000,0.04528,303.80251
132.00001,6.60010,24727.20146,0.00000,0.04541,303.87290
132.30001,6.61499,24727.05543,0.00000,0.04553,303.87111
132.60001,6.63000,24731.13090,0.00000,0.04565,303.92119
132.90001,6.64488,24734.48068,0.00000,0.04577,303.96235
133.20001,6.66013,24737.70678,0.00000,0.04589,304.00200
133.50001,6.67490,24742.09368,0.00000,0.04601,304.05591
133.80001,6.68997,24743.11888,0.00000,0.04613,304.06851
134.10001,6.70509,24751.21021,0.00000,0.04626,304.16794
134.40001,6.71992,24750.34744,0.00000,0.04638,304.15734
134.70001,6.73517,24755.95772,0.00000,0.04650,304.22629
135.00001,6.74987,24758.14223,0.00000,0.04662,304.25313
135.30001,6.76500,24763.25780,0.00000,0.04675,304.31600
135.60001,6.78001,24765.68222,0.00000,0.04687,304.34579
135.90001,6.79502,24768.93961,0.00000,0.04699,304.38582
136.20001,6.81002,24770.91253,0.00000,0.04711,304.41007
136.50001,6.82503,24773.59474,0.00000,0.04723,304.44303
136.80001,6.84010,24778.94574,0.00000,0.04736,304.50879
137.10001,6.85498,24779.88154,0.00000,0.04749,304.52029
137.40001,6.87011,24785.81071,0.00000,0.04761,304.59315
137.70001,6.88494,24785.79879,0.00000,0.04773,304.59300
138.00001,6.90013,24789.75207,0.00000,0.04785,304.64159
138.30001,6.91495,24792.44471,0.00000,0.04797,304.67468
138.60001,6.93002,24794.39080,0.00000,0.04809,304.69859
138.90001,6.94509,24801.06205,0.00000,0.04822,304.78057
139.20001,6.95980,24799.30967,0.00000,0.04834,304.75904
139.50001,6.97510,24805.55028,0.00000,0.04846,304.83573
139.80001,6.98999,24808.77638,0.00000,0.04859,304.87538
140.10001,7.00500,24811.02049,0.00000,0.04871,304.90295
140.40001,7.02000,24816.06454,0.00000,0.04883,304.96494
140.70001,7.03501,24819.05222,0.00000,0.04895,305.00166
141.00001,7.05002,24821.26504,0.00000,0.04908,305.02885
141.30001,7.06503,24822.50035,0.00000,0.04920,305.04403
141.60001,7.08003,24828.39078,0.00000,0.04933,305.11642
141.90001,7.09498,24826.70546,0.00000,0.04945,305.09571
142.20001,7.11005,24833.37522,0.00000,0.04957,305.17767
142.50001,7.12487,24833.32902,0.00000,0.04969,305.17710
142.80001,7.14006,24836.26008,0.00000,0.04982,305.21312
143.10001,7.15501,24840.44433,0.00000,0.04994,305.26454
143.40001,7.16990,24839.53238,0.00000,0.05006,305.25334
143.70001,7.18502,24848.51032,0.00000,0.05018,305.36367
144.00001,7.19985,24848.51629,0.00000,0.05031,305.36374
144.30001,7.21510,24853.07008,0.00000,0.05043,305.41970
144.60001,7.22992,24854.21896,0.00000,0.05056,305.43382
144.90001,7.24499,24857.06210,0.00000,0.05068,305.46876
145.20001,7.26006,24860.28075,0.00000,0.05080,305.50831
145.50001,7.27501,24861.47583,0.00000,0.05092,305.52300
145.80001,7.28995,24864.29214,0.00000,0.05104,305.55761
146.10001,7.30508,24866.54222,0.00000,0.05117,305.58526
146.40001,7.32009,24871.28824,0.00000,0.05129,305.64358
146.70001,7.33491,24866.04303,0.00000,0.05141,305.57913
147.00001,7.35010,24874.55904,0.00000,0.05153,305.68378
147.30001,7.36493,24873.59643,0.00000,0.05165,305.67195
147.60001,7.38012,24878.90422,0.00000,0.05178,305.73718
147.90001,7.39500,24883.00502,0.00000,0.05190,305.78757
148.20001,7.40995,24880.89651,0.00000,0.05202,305.76166
148.50001,7.42514,24888.36795,0.00000,0.05214,305.85348
148.80001,7.43991,24887.52306,0.00000,0.05225,305.84309
149.10001,7.45503,24890.85048,0.00000,0.05237,305.88399
149.40001,7.46992,24892.77869,0.00000,0.05250,305.90768
149.70001,7.48505,24896.05397,0.00000,0.05262,305.94793
150.00001,7.50005,24897.49193,0.00000,0.05273,305.96560
150.30001,7.51500,24899.69283,0.00000,0.05285,305.99265
150.60001,7.53001,24904.34349,0.00000,0.05297,306.04980
150.90001,7.54507,24905.49535,0.00000,0.05309,306.06396
151.20001,7.56008,24909.92248,0.00000,0.05321,306.11836
151.50001,7.57485,24908.30421,0.00000,0.05333,306.09847
151.80001,7.59004,24913.66118,0.00000,0.05345,306.16431
152.10001,7.60492,24915.54469,0.00000,0.05358,306.18745
152.40001,7.62005,24916.08113,0.00000,0.05369,306.19405
152.70001,7.63494,24922.89245,0.00000,0.05381,306.27775
153.00001,7.64995,24922.73450,0.00000,0.05392,306.27581
153.30001,7.66513,24928.46847,0.00000,0.05404,306.34627
153.60001,7.67990,24927.73980,0.00000,0.05415,306.33732
153.90001,7.69509,24930.72599,0.00000,0.05428,306.37402
154.20001,7.70997,24931.78397,0.00000,0.05439,306.38702
154.50001,7.72498,24935.91309,0.00000,0.05451,306.43776
154.80001,7.73999,24937.26462,0.00000,0.05464,306.45437
155.10001,7.75506,24939.69053,0.00000,0.05475,306.48418
155.40001,7.76994,24941.45334,0.00000,0.05487,306.50584
155.70001,7.78495,24941.28048,0.00000,0.05499,306.50372
156.00001,7.80008,24947.72375,0.00000,0.05510,306.58290
156.30001,7.81485,24946.24406,0.00000,0.05522,306.56472
156.60001,7.83003,24952.91382,0.00000,0.05534,306.64668
156.90001,7.84492,24955.04022,0.00000,0.05545,306.67281
157.20001,7.86005,24955.30993,0.00000,0.05557,306.67613
157.50001,7.87499,24959.90992,0.00000,0.05569,306.73266
157.80001,7.88994,24959.44351,0.00000,0.05581,306.72693
158.10001,7.90507,24965.06870,0.00000,0.05592,306.79605
158.40001,7.91995,24965.99853,0.00000,0.05604,306.80748
158.70001,7.93508,24967.59146,0.00000,0.05616,306.82706
159.00001,7.94997,24969.54203,0.00000,0.05628,306.85103
159.30001,7.96504,24973.12874,0.00000,0.05639,306.89510
159.60001,7.97998,24973.42229,0.00000,0.05651,306.89871
159.90001,7.99505,24977.93585,0.00000,0.05663,306.95418
160.20001,8.00994,24980.22616,0.00000,0.05675,306.98232
160.50001,8.02501,24981.39292,0.00000,0.05686,306.99666
160.80001,8.04007,24984.65329,0.00000,0.05698,307.03673
161.10001,8.05484,24982.62227,0.00000,0.05709,307.01177
161.40001,8.07003,24989.17878,0.00000,0.05720,307.09234
161.70001,8.08491,24993.85178,0.00000,0.05732,307.14977
162.00001,8.10004,24993.38388,0.00000,0.05744,307.14402
162.30001,8.11505,24998.17312,0.00000,0.05756,307.20287
162.60001,8.12994,24996.80966,0.00000,0.05768,307.18612
162.90001,8.14518,25002.55406,0.00000,0.05780,307.25671
163.20001,8.15995,25001.37389,0.00000,0.05792,307.24221
163.50001,8.17502,25005.77569,0.00000,0.05803,307.29630
163.80001,8.19002,25007.12872,0.00000,0.05815,307.31293
164.10001,8.20503,25010.04040,0.00000,0.05826,307.34871
164.40001,8.21998,25009.20594,0.00000,0.05838,307.33846
164.70001,8.23493,25011.06262,0.00000,0.05849,307.36127
165.00001,8.24999,25016.73698,0.00000,0.05861,307.43101
165.30001,8.26500,25015.57469,0.00000,0.05873,307.41672
165.60001,8.28007,25022.10438,0.00000,0.05885,307.49697
165.90001,8.29483,25021.42191,0.00000,0.05897,307.48858
166.20001,8.31008,25026.10385,0.00000,0.05909,307.54612
166.50001,8.32497,25027.80855,0.00000,0.05920,307.56706
166.80001,8.34004,25026.13664,0.00000,0.05931,307.54652
167.10001,8.35504,25031.04210,0.00000,0.05943,307.60680
167.40001,8.36999,25032.37128,0.00000,0.05955,307.62314
167.70001,8.38506,25034.28757,0.00000,0.05967,307.64669
168.00001,8.39994,25034.31439,0.00000,0.05979,307.64702
168.30001,8.41507,25038.02776,0.00000,0.05990,307.69265
168.60001,8.42996,25036.88633,0.00000,0.06002,307.67862
168.90001,8.44503,25041.91101,0.00000,0.06014,307.74037
169.20001,8.45997,25042.22989,0.00000,0.06025,307.74429
169.50001,8.47504,25043.55907,0.00000,0.06037,307.76062
169.80001,8.49005,25049.22748,0.00000,0.06049,307.83028
170.10001,8.50500,25046.17870,0.00000,0.06060,307.79282
170.40001,8.52012,25053.32530,0.00000,0.06072,307.88064
170.70001,8.53483,25050.37189,0.00000,0.06085,307.84435
171.00001,8.55008,25055.63796,0.00000,0.06096,307.90906
171.30001,8.56490,25055.45318,0.00000,0.06108,307.90679
171.60001,8.58003,25055.83763,0.00000,0.06120,307.91151
171.90001,8.59510,25060.65965,0.00000,0.06131,307.97077
172.20001,8.60999,25058.44533,0.00000,0.06143,307.94356
172.50001,8.62511,25064.65316,0.00000,0.06155,308.01985
172.80001,8.63994,25062.59978,0.00000,0.06167,307.99461
173.10001,8.65507,25065.63962,0.00000,0.06179,308.03197
173.40001,8.66995,25065.86909,0.00000,0.06190,308.03479
173.70001,8.68502,25068.56918,0.00000,0.06202,308.06797
174.00001,8.69997,25070.59574,0.00000,0.06214,308.09288
174.30001,8.71498,25072.43454,0.00000,0.06225,308.11547
174.60001,8.72998,25077.49498,0.00000,0.06237,308.17766
174.90001,8.74505,25075.36709,0.00000,0.06248,308.15151
175.20001,8.76006,25078.01056,0.00000,0.06260,308.18400
175.50001,8.77489,25077.89135,0.00000,0.06272,308.18253
175.80001,8.79007,25081.70009,0.00000,0.06284,308.22934
176.10001,8.80496,25084.42402,0.00000,0.06296,308.26281
176.40001,8.82003,25084.45978,0.00000,0.06308,308.26325
176.70001,8.83503,25087.80062,0.00000,0.06320,308.30431
177.00001,8.84998,25085.95288,0.00000,0.06331,308.28160
177.30001,8.86511,25088.68277,0.00000,0.06342,308.31515
177.60001,8.87987,25088.40561,0.00000,0.06354,308.31174
177.90001,8.89500,25093.73724,0.00000,0.06365,308.37726
178.20001,8.90995,25094.32733,0.00000,0.06377,308.38451
178.50001,8.92502,25097.49830,0.00000,0.06389,308.42348
178.80001,8.93996,25098.60098,0.00000,0.06401,308.43703
179.10001,8.95497,25098.18077,0.00000,0.06413,308.43187
179.40001,8.97004,25103.58095,0.00000,0.06425,308.49823
179.70001,8.98499,25102.17726,0.00000,0.06436,308.48098
180.00001,9.00005,25106.42111,0.00000,0.06448,308.53314
180.30001,9.01488,25105.25584,0.00000,0.06459,308.51882
180.60001,9.03013,25106.90689,0.00000,0.06471,308.53911
180.90001,9.04495,25108.51622,0.00000,0.06483,308.55888
181.20001,9.05996,25108.35528,0.00000,0.06495,308.55690
181.50001,9.07509,25113.12366,0.00000,0.06507,308.61550
181.80001,9.08998,25113.92236,0.00000,0.06518,308.62532
182.10001,9.10510,25115.43036,0.00000,0.06530,308.64385
182.40001,9.11993,25114.65251,0.00000,0.06541,308.63429
182.70001,9.13506,25119.11690,0.00000,0.06553,308.68915
183.00001,9.14994,25119.20631,0.00000,0.06565,308.69025
183.30001,9.16495,25121.66798,0.00000,0.06577,308.72050
183.60001,9.17996,25122.78557,0.00000,0.06589,308.73424
183.90001,9.19503,25122.08223,0.00000,0.06601,308.72560
184.20001,9.21003,25125.07737,0.00000,0.06613,308.76240
184.50001,9.22492,25123.47102,0.00000,0.06624,308.74266
184.80001,9.24017,25129.56262,0.00000,0.06635,308.81752
185.10001,9.25487,25127.78640,0.00000,0.06647,308.79569
185.40001,9.27006,25130.42986,0.00000,0.06658,308.82818
185.70001,9.28501,25131.94382,0.00000,0.06670,308.84678
186.00001,9.30002,25129.10068,0.00000,0.06682,308.81185
186.30001,9.31508,25135.16247,0.00000,0.06693,308.88634
186.60001,9.32985,25133.30877,0.00000,0.06705,308.86356
186.90001,9.34504,25137.63011,0.00000,0.06717,308.91666
187.20001,9.35993,25137.34102,0.00000,0.06729,308.91311
187.50001,9.37499,25140.52391,0.00000,0.06741,308.95223
187.80001,9.39000,25140.02025,0.00000,0.06752,308.94604
188.10001,9.40501,25141.37328,0.00000,0.06763,308.96266
188.40001,9.42001,25144.30583,0.00000,0.06775,308.99870
188.70001,9.43502,25144.05847,0.00000,0.06787,308.99566
189.00001,9.45009,25148.33212,0.00000,0.06798,309.04818
189.30001,9.46498,25143.09287,0.00000,0.06810,308.98380
189.60001,9.48010,25147.19963,0.00000,0.06822,309.03426
189.90001,9.49487,25146.60954,0.00000,0.06833,309.02701
190.20001,9.51012,25149.05334,0.00000,0.06845,309.05704
190.50001,9.52494,25150.85042,0.00000,0.06856,309.07913
190.80001,9.53995,25150.29311,0.00000,0.06868,309.07228
191.10001,9.55508,25155.83038,0.00000,0.06879,309.14033
191.40001,9.56997,25155.44295,0.00000,0.06891,309.13557
191.70001,9.58509,25156.96287,0.00000,0.06903,309.15424
192.00001,9.59992,25157.57978,0.00000,0.06914,309.16183
192.30001,9.61499,25161.23950,0.00000,0.06926,309.20680
192.60001,9.62999,25160.59577,0.00000,0.06937,309.19889
192.90001,9.64506,25160.05039,0.00000,0.06948,309.19219
193.20001,9.66001,25161.63588,0.00000,0.06959,309.21167
193.50001,9.67508,25160.02953,0.00000,0.06971,309.19193
193.80001,9.69008,25166.43703,0.00000,0.06983,309.27067
194.10001,9.70491,25162.37795,0.00000,0.06995,309.22079
194.40001,9.72010,25167.40561,0.00000,0.07006,309.28257
194.70001,9.73493,25165.66515,0.00000,0.07018,309.26119
195.00001,9.75011,25166.79168,0.00000,0.07030,309.27503
195.30001,9.76500,25168.23411,0.00000,0.07041,309.29276
195.60001,9.77995,25168.99109,0.00000,0.07052,309.30206
195.90001,9.79507,25173.23494,0.00000,0.07063,309.35421
196.20001,9.80990,25170.96102,0.00000,0.07075,309.32627
196.50001,9.82503,25171.64946,0.00000,0.07086,309.33473
196.80001,9.83997,25172.64187,0.00000,0.07098,309.34692
197.10001,9.85504,25174.40021,0.00000,0.07109,309.36853
197.40001,9.86993,25175.59230,0.00000,0.07121,309.38318
197.70001,9.88506,25177.31488,0.00000,0.07132,309.40435
198.00001,9.90000,25178.16126,0.00000,0.07144,309.41475
198.30001,9.91507,25176.49531,0.00000,0.07155,309.39428
198.60001,9.93008,25179.79443,0.00000,0.07167,309.43482
198.90001,9.94491,25176.60558,0.00000,0.07178,309.39563
199.20001,9.96009,25181.75244,0.00000,0.07189,309.45888
199.50001,9.97492,25182.83129,0.00000,0.07200,309.47214
199.80001,9.99005,25182.33061,0.00000,0.07212,309.46599
200.10001,10.00499,25185.74595,0.00000,0.07223,309.50796
200.40001,10.01994,25183.30514,0.00000,0.07234,309.47796
200.70001,10.03507,25187.48939,0.00000,0.07246,309.52938
201.00001,10.04990,25185.92179,0.00000,0.07257,309.51012
201.30001,10.06502,25187.54005,0.00000,0.07268,309.53001
201.60001,10.07997,25188.37154,0.00000,0.07279,309.54023
201.90001,10.09498,25189.72754,0.00000,0.07291,309.55689
202.20001,10.10998,25189.37588,0.00000,0.07302,309.55257
202.50001,10.12499,25190.31167,0.00000,0.07313,309.56407
202.80001,10.14000,25192.12365,0.00000,0.07324,309.58634
203.10001,10.15501,25190.10901,0.00000,0.07336,309.56158
203.40001,10.17007,25193.82238,0.00000,0.07347,309.60721
203.70001,10.18490,25189.86166,0.00000,0.07358,309.55854
204.00001,10.20015,25194.30220,0.00000,0.07369,309.61311
204.30001,10.21491,25195.77444,0.00000,0.07380,309.63120
204.60001,10.23004,25196.41519,0.00000,0.07391,309.63907
204.90001,10.24499,25199.19276,0.00000,0.07402,309.67321
205.20001,10.25988,25196.76685,0.00000,0.07414,309.64340
205.50001,10.27512,25199.90504,0.00000,0.07425,309.68196
205.80001,10.28989,25197.89040,0.00000,0.07436,309.65720
206.10001,10.30496,25200.17326,0.00000,0.07447,309.68526
206.40001,10.31996,25198.23611,0.00000,0.07458,309.66145
206.70001,10.33503,25202.96276,0.00000,0.07468,309.71954
207.00001,10.34992,25198.88282,0.00000,0.07479,309.66940
207.30001,10.36505,25199.82457,0.00000,0.07490,309.68097
207.60001,10.38005,25202.96276,0.00000,0.07501,309.71954
207.90001,10.39500,25199.19276,0.00000,0.07512,309.67321
208.20001,10.41007,25205.03104,0.00000,0.07523,309.74495
208.50001,10.42483,25201.50244,0.00000,0.07534,309.70159
208.80001,10.44008,25205.95491,0.00000,0.07545,309.75631
209.10001,10.45491,25204.35452,0.00000,0.07555,309.73664
209.40001,10.46998,25202.44718,0.00000,0.07566,309.71320
209.70001,10.48498,25205.85358,0.00000,0.07577,309.75506
210.00001,10.49993,25206.63142,0.00000,0.07587,309.76462
210.30001,10.51512,25209.82921,0.00000,0.07598,309.80392
210.60001,10.52995,25206.65526,0.00000,0.07608,309.76491
210.90001,10.54507,25205.90723,0.00000,0.07620,309.75572
211.20001,10.56002,25206.35426,0.00000,0.07630,309.76122
211.50001,10.57503,25209.38516,0.00000,0.07640,309.79846
211.80001,10.58991,25207.35562,0.00000,0.07651,309.77352
212.10001,10.60510,25209.29873,0.00000,0.07662,309.79740
212.40001,10.61999,25211.37893,0.00000,0.07672,309.82296
212.70001,10.63494,25207.78477,0.00000,0.07683,309.77879
213.00001,10.65006,25212.22234,0.00000,0.07693,309.83333
213.30001,10.66489,25210.83057,0.00000,0.07704,309.81622
213.60001,10.68014,25213.93597,0.00000,0.07714,309.85439
213.90001,10.69490,25213.48000,0.00000,0.07725,309.84878
214.20001,10.71003,25212.20446,0.00000,0.07735,309.83311
214.50001,10.72504,25214.68103,0.00000,0.07746,309.86354
214.80001,10.73993,25212.38029,0.00000,0.07756,309.83527
215.10001,10.75505,25213.53960,0.00000,0.07767,309.84952
215.40001,10.76988,25216.04598,0.00000,0.07777,309.88032
215.70001,10.78501,25215.44695,0.00000,0.07788,309.87296
216.00001,10.80001,25214.41877,0.00000,0.07798,309.86032
216.30001,10.81508,25216.43341,0.00000,0.07808,309.88508
216.60001,10.82997,25215.27708,0.00000,0.07819,309.87087
216.90001,10.84504,25216.38870,0.00000,0.07829,309.88453
217.20001,10.85998,25220.64447,0.00000,0.07840,309.93683
217.50001,10.87493,25217.47053,0.00000,0.07851,309.89782
217.80001,10.89012,25221.00806,0.00000,0.07861,309.94130
218.10001,10.90483,25217.70000,0.00000,0.07871,309.90064
218.40001,10.92007,25218.86230,0.00000,0.07881,309.91493
218.70001,10.93496,25220.26896,0.00000,0.07891,309.93221
219.00001,10.94997,25218.52851,0.00000,0.07902,309.91082
219.30001,10.96503,25221.92597,0.00000,0.07912,309.95258
219.60001,10.97998,25220.34645,0.00000,0.07923,309.93317
219.90001,10.99517,25223.46377,0.00000,0.07933,309.97147
220.20001,11.01000,25221.23158,0.00000,0.07944,309.94404
220.50001,11.02500,25222.69189,0.00000,0.07954,309.96199
220.80001,11.04001,25223.37139,0.00000,0.07965,309.97034
221.10001,11.05508,25223.52040,0.00000,0.07976,309.97217
221.40001,11.06991,25222.99886,0.00000,0.07985,309.96576
221.70001,11.08503,25222.52500,0.00000,0.07995,309.95994
222.00001,11.10004,25226.95363,0.00000,0.08006,310.01436
222.30001,11.11493,25221.86935,0.00000,0.08016,309.95188
222.60001,11.13005,25227.15628,0.00000,0.08026,310.01685
222.90001,11.14488,25225.48139,0.00000,0.08036,309.99627
223.20001,11.16013,25226.56024,0.00000,0.08047,310.00953
223.50001,11.17502,25226.33076,0.00000,0.08057,310.00671
223.80001,11.19002,25224.54560,0.00000,0.08067,309.98477
224.10001,11.20509,25226.55129,0.00000,0.08077,310.00942
224.40001,11.21998,25224.69759,0.00000,0.08087,309.98664
224.70001,11.23504,25225.24297,0.00000,0.08097,309.99334
225.00001,11.24993,25223.02568,0.00000,0.08107,309.96609
225.30001,11.26506,25225.35324,0.00000,0.08117,309.99469
225.60001,11.28000,25224.98667,0.00000,0.08127,309.99019
225.90001,11.29507,25227.29039,0.00000,0.08138,310.01850
226.20001,11.30990,25227.43046,0.00000,0.08147,310.02022
226.50001,11.32503,25225.69299,0.00000,0.08157,309.99887
226.80001,11.34009,25229.86233,0.00000,0.08167,310.05011
227.10001,11.35486,25223.73796,0.00000,0.08176,309.97484
227.40001,11.37005,25227.56159,0.00000,0.08186,310.02183
227.70001,11.38487,25225.77345,0.00000,0.08196,309.99986
228.00001,11.40006,25226.80461,0.00000,0.08205,310.01253
228.30001,11.41495,25227.23675,0.00000,0.08215,310.01784
228.60001,11.43002,25225.85690,0.00000,0.08225,310.00088
228.90001,11.44508,25226.70329,0.00000,0.08236,310.01128
229.20001,11.45997,25225.68405,0.00000,0.08245,309.99876
229.50001,11.47504,25227.66590,0.00000,0.08255,310.02311
229.80001,11.48999,25225.45457,0.00000,0.08264,309.99594
230.10001,11.50505,25229.71928,0.00000,0.08274,310.04835
230.40001,11.51994,25225.10588,0.00000,0.08284,309.99165
230.70001,11.53513,25226.35758,0.00000,0.08293,310.00704
231.00001,11.54989,25226.47977,0.00000,0.08302,310.00854
231.30001,11.56502,25224.29824,0.00000,0.08312,309.98173
231.60001,11.58003,25228.10698,0.00000,0.08321,310.02853
231.90001,11.59486,25222.88859,0.00000,0.08330,309.96441
232.20001,11.61010,25224.77508,0.00000,0.08340,309.98759
232.50001,11.62493,25221.41635,0.00000,0.08349,309.94631
232.80001,11.64006,25222.29552,0.00000,0.08359,309.95712
233.10001,11.65500,25223.26708,0.00000,0.08368,309.96906
233.40001,11.67001,25222.31638,0.00000,0.08377,309.95737
233.70001,11.68502,25222.71872,0.00000,0.08386,309.96232
234.00001,11.69997,25220.39711,0.00000,0.08396,309.93379
234.30001,11.71503,25221.29118,0.00000,0.08405,309.94478
234.60001,11.72992,25218.79077,0.00000,0.08413,309.91405
234.90001,11.74499,25220.97230,0.00000,0.08422,309.94086
235.20001,11.75994,25219.15734,0.00000,0.08431,309.91855
235.50001,11.77506,25218.82355,0.00000,0.08440,309.91445
235.80001,11.78995,25218.21558,0.00000,0.08449,309.90698
236.10001,11.80502,25214.18929,0.00000,0.08458,309.85750
236.40001,11.82002,25217.70298,0.00000,0.08466,309.90068
236.70001,11.83485,25214.92243,0.00000,0.08475,309.86651
237.00001,11.85004,25215.77477,0.00000,0.08484,309.87698
237.30001,11.86493,25212.49354,0.00000,0.08492,309.83666
237.60001,11.88005,25210.60407,0.00000,0.08500,309.81344
237.90001,11.89500,25210.80375,0.00000,0.08509,309.81590
238.20001,11.91001,25209.45668,0.00000,0.08517,309.79934
238.50001,11.92507,25211.18820,0.00000,0.08525,309.82062
238.80001,11.93996,25207.87418,0.00000,0.08534,309.77989
239.10001,11.95503,25209.00965,0.00000,0.08542,309.79385
239.40001,11.96992,25204.22041,0.00000,0.08550,309.73499
239.70001,11.98504,25206.42877,0.00000,0.08558,309.76213
240.00001,11.99987,25201.69616,0.00000,0.08566,309.70397
240.30001,12.01500,25200.84381,0.00000,0.08574,309.69350
240.60001,12.02994,25200.15240,0.00000,0.08582,309.68500
240.90001,12.04495,25193.89689,0.00000,0.08589,309.60813
241.20001,12.06008,25197.58642,0.00000,0.08597,309.65347
241.50001,12.07491,25190.60969,0.00000,0.08604,309.56773
241.80001,12.09015,25191.49780,0.00000,0.08611,309.57864
242.10001,12.10492,25189.18812,0.00000,0.08618,309.55026
242.40001,12.11999,25184.65817,0.00000,0.08625,309.49459
242.70001,12.13499,25184.51810,0.00000,0.08633,309.49287
243.00001,12.15000,25179.75569,0.00000,0.08639,309.43435
243.30001,12.16507,25179.65138,0.00000,0.08646,309.43306
243.60001,12.17996,25174.36147,0.00000,0.08653,309.36806
243.90001,12.19502,25173.67601,0.00000,0.08660,309.35963
244.20001,12.20997,25167.33706,0.00000,0.08666,309.28173
244.50001,12.22504,25164.83068,0.00000,0.08673,309.25093
244.80001,12.23993,25160.05635,0.00000,0.08678,309.19226
245.10001,12.25505,25156.59630,0.00000,0.08685,309.14974
245.40001,12.27000,25151.54183,0.00000,0.08691,309.08762
245.70001,12.28501,25144.36245,0.00000,0.08696,308.99940
246.00001,12.30007,25142.72034,0.00000,0.08702,308.97922
246.30001,12.31490,25132.50113,0.00000,0.08707,308.85363
246.60001,12.33015,25128.89802,0.00000,0.08712,308.80935
246.90001,12.34492,25120.89908,0.00000,0.08717,308.71106
247.20001,12.36004,25114.05051,0.00000,0.08721,308.62689
247.50001,12.37499,25106.79066,0.00000,0.08726,308.53768
247.80001,12.38994,25096.81880,0.00000,0.08730,308.41513
248.10001,12.40500,25087.72016,0.00000,0.08735,308.30332
248.40001,12.41995,25073.21835,0.00000,0.08740,308.12511
248.70001,12.43508,25063.81273,0.00000,0.08743,308.00952
249.00001,12.44997,25045.74955,0.00000,0.08746,307.78754
249.30001,12.46503,25031.23879,0.00000,0.08750,307.60922
249.60001,12.47992,25003.73125,0.00000,0.08752,307.27118
249.90001,12.49505,24964.96588,0.00000,0.08754,306.79479
250.20001,12.51000,24917.51611,0.00000,0.08755,306.21168
250.50001,12.52512,24836.33906,0.00000,0.08756,305.21409
250.80001,12.54013,24583.84037,0.00000,0.08752,302.11113
251.05001,12.55251,23967.72653,0.00000,0.08737,294.53970
251.07001,12.55358,22379.58014,0.00000,0.08498,275.02295
251.07601,12.55442,19076.17897,0.00000,0.07930,234.42741
251.08201,12.55555,15060.51272,0.00000,0.07417,185.07884
251.08401,12.55597,13696.84935,0.00000,0.07251,168.32076