File: scratch/college-stuff/ME Lab/ME lab Fall 2013/group1/group1.is_tens_RawData/Specimen_RawData_2.csv
Time,Extension,Load,Strain 2,Tensile strain,Tensile stress
(sec),(mm),(N),(mm/mm),(mm/mm),(MPa)
0.00000,0.00000,0.33621,0.00000,0.00000,0.00414
0.30000,0.01375,11.61230,0.00000,0.00000,0.14292
0.60000,0.02995,16.27234,0.00000,0.00000,0.20028
0.90000,0.04496,18.55479,0.00000,0.00000,0.22837
1.20000,0.06009,21.97010,0.00000,0.00000,0.27041
1.50000,0.07492,27.79404,0.00000,0.00000,0.34209
1.80000,0.09004,35.45054,0.00000,-0.00001,0.43633
2.10000,0.10499,54.92800,0.00000,-0.00001,0.67605
2.40000,0.11994,66.95533,0.00000,-0.00002,0.82409
2.70000,0.13500,89.96291,0.00000,-0.00002,1.10726
3.00000,0.15001,138.89871,0.00000,-0.00002,1.70956
3.30000,0.16502,206.19160,0.00000,-0.00003,2.53781
3.60000,0.17991,287.90710,0.00000,-0.00003,3.54356
3.90000,0.19509,389.45780,0.00000,-0.00002,4.79344
4.20000,0.20992,503.17980,0.00000,-0.00002,6.19313
4.50000,0.22505,631.46651,0.00000,0.00000,7.77209
4.80000,0.24000,782.14826,0.00000,0.00002,9.62668
5.10000,0.25500,942.14743,0.00000,0.00004,11.59595
5.40000,0.27007,1120.97431,0.00000,0.00006,13.79695
5.70000,0.28490,1308.07143,0.00000,0.00009,16.09974
6.00000,0.30008,1519.10363,0.00000,0.00012,18.69712
6.30000,0.31485,1726.53850,0.00000,0.00016,21.25023
6.60000,0.32998,1940.49180,0.00000,0.00019,23.88356
6.90000,0.34499,2159.03334,0.00000,0.00023,26.57337
7.20000,0.35993,2382.54908,0.00000,0.00026,29.32440
7.50000,0.37500,2611.73043,0.00000,0.00030,32.14517
7.80000,0.38995,2830.58323,0.00000,0.00033,34.83881
8.10000,0.40501,3053.84342,0.00000,0.00037,37.58669
8.40000,0.41984,3269.34345,0.00000,0.00040,40.23906
8.70000,0.43503,3486.16764,0.00000,0.00044,42.90773
9.00000,0.44986,3698.11058,0.00000,0.00047,45.51633
9.30000,0.46504,3907.51362,0.00000,0.00051,48.09366
9.60000,0.47999,4111.56416,0.00000,0.00054,50.60511
9.90000,0.49494,4310.74873,0.00000,0.00058,53.05667
10.20000,0.51006,4510.89367,0.00000,0.00061,55.52006
10.50000,0.52489,4702.64852,0.00000,0.00065,57.88018
10.80000,0.54002,4897.44991,0.00000,0.00068,60.27779
11.10000,0.55491,5080.58108,0.00000,0.00071,62.53177
11.40000,0.57003,5262.05860,0.00000,0.00074,64.76539
11.70000,0.58492,5431.00685,0.00000,0.00077,66.84481
12.00000,0.59993,5584.46869,0.00000,0.00080,68.73361
12.30000,0.61493,5734.48762,0.00000,0.00083,70.58005
12.60000,0.62994,5863.05261,0.00000,0.00085,72.16242
12.90000,0.64501,5993.16210,0.00000,0.00087,73.76381
13.20000,0.65984,6119.23300,0.00000,0.00090,75.31549
13.50000,0.67502,6253.39076,0.00000,0.00092,76.96670
13.80000,0.68991,6381.24272,0.00000,0.00094,78.54031
14.10000,0.70504,6513.51437,0.00000,0.00097,80.16830
14.40000,0.71999,6644.33315,0.00000,0.00099,81.77842
14.70000,0.73505,6776.03036,0.00000,0.00101,83.39935
15.00000,0.75006,6908.75128,0.00000,0.00104,85.03288
15.30000,0.76483,7039.55665,0.00000,0.00106,86.64283
15.60000,0.78001,7176.49758,0.00000,0.00108,88.32830
15.90000,0.79496,7310.45082,0.00000,0.00111,89.97699
16.20000,0.80997,7447.49084,0.00000,0.00113,91.66368
16.50000,0.82492,7581.74360,0.00000,0.00115,93.31606
16.80000,0.83998,7718.00056,0.00000,0.00118,94.99311
17.10000,0.85499,7857.31450,0.00000,0.00121,96.70779
17.40000,0.86994,7990.42135,0.00000,0.00123,98.34607
17.70000,0.88506,8133.70198,0.00000,0.00126,100.10957
18.00000,0.89989,8267.34528,0.00000,0.00129,101.75445
18.30000,0.91508,8407.21875,0.00000,0.00131,103.47601
18.60000,0.92991,8546.74354,0.00000,0.00133,105.19328
18.90000,0.94497,8685.21333,0.00000,0.00136,106.89756
19.20000,0.95998,8828.66010,0.00000,0.00138,108.66311
19.50000,0.97493,8967.47783,0.00000,0.00141,110.37167
19.80000,0.99005,9111.31799,0.00000,0.00144,112.14206
20.10000,1.00488,9248.17473,0.00000,0.00146,113.82649
20.40000,1.02001,9395.13296,0.00000,0.00149,115.63525
20.70000,1.03490,9533.51706,0.00000,0.00152,117.33848
21.00000,1.04996,9678.19169,0.00000,0.00154,119.11914
21.30000,1.06497,9823.34092,0.00000,0.00157,120.90563
21.60000,1.08004,9964.51676,0.00000,0.00159,122.64323
21.90000,1.09498,10110.94227,0.00000,0.00162,124.44543
22.20000,1.10993,10251.90949,0.00000,0.00165,126.18045
22.50000,1.12512,10400.45321,0.00000,0.00168,128.00873
22.80000,1.13989,10543.07073,0.00000,0.00170,129.76406
23.10000,1.15507,10688.72139,0.00000,0.00173,131.55673
23.40000,1.16996,10833.98536,0.00000,0.00176,133.34464
23.70000,1.18497,10978.92225,0.00000,0.00178,135.12852
24.00000,1.19998,11127.19551,0.00000,0.00181,136.95347
24.30000,1.21486,11271.82022,0.00000,0.00184,138.73351
24.60000,1.23005,11423.66379,0.00000,0.00187,140.60240
24.90000,1.24488,11568.38536,0.00000,0.00189,142.38363
25.20000,1.26000,11719.22833,0.00000,0.00192,144.24021
25.50000,1.27495,11865.91089,0.00000,0.00195,146.04558
25.80000,1.29002,12016.29862,0.00000,0.00198,147.89655
26.10000,1.30497,12165.71629,0.00000,0.00201,149.73558
26.40000,1.32003,12312.15000,0.00000,0.00204,151.53788
26.70000,1.33504,12468.22104,0.00000,0.00207,153.45881
27.00000,1.34999,12610.11213,0.00000,0.00210,155.20520
27.30000,1.36511,12764.05603,0.00000,0.00213,157.09994
27.60000,1.37988,12910.83097,0.00000,0.00215,158.90645
27.90000,1.39507,13064.71080,0.00000,0.00218,160.80040
28.20000,1.40990,13213.38713,0.00000,0.00221,162.63031
28.50000,1.42496,13364.21818,0.00000,0.00224,164.48673
28.80000,1.44003,13519.98299,0.00000,0.00227,166.40389
29.10000,1.45498,13667.27948,0.00000,0.00230,168.21681
29.40000,1.47004,13820.70184,0.00000,0.00233,170.10513
29.70000,1.48487,13971.53586,0.00000,0.00236,171.96160
30.00000,1.50006,14127.59870,0.00000,0.00239,173.88242
30.30000,1.51495,14277.56697,0.00000,0.00242,175.72823
30.60000,1.53001,14430.58401,0.00000,0.00245,177.61156
30.90000,1.54490,14582.85898,0.00000,0.00248,179.48576
31.20000,1.56003,14734.05957,0.00000,0.00251,181.34674
31.50000,1.57503,14890.03003,0.00000,0.00254,183.26642
31.80000,1.58992,15038.96564,0.00000,0.00257,185.09952
32.10000,1.60511,15197.06398,0.00000,0.00260,187.04539
32.40000,1.61994,15347.40329,0.00000,0.00264,188.89577
32.70000,1.63506,15501.48875,0.00000,0.00266,190.79225
33.00000,1.64995,15656.09276,0.00000,0.00270,192.69512
33.30000,1.66496,15810.77129,0.00000,0.00273,194.59890
33.60000,1.68003,15967.49574,0.00000,0.00276,196.52786
33.90000,1.69491,16119.19254,0.00000,0.00280,198.39495
34.20000,1.70998,16273.11856,0.00000,0.00283,200.28947
34.50000,1.72493,16428.57492,0.00000,0.00287,202.20282
34.80000,1.73999,16586.55405,0.00000,0.00290,204.14723
35.10000,1.75488,16739.10171,0.00000,0.00293,206.02478
35.40000,1.77001,16896.21508,0.00000,0.00297,207.95854
35.70000,1.78496,17050.59409,0.00000,0.00300,209.85863
36.00000,1.80008,17203.53216,0.00000,0.00304,211.74099
36.30000,1.81503,17360.18509,0.00000,0.00307,213.66908
36.60000,1.82992,17512.42429,0.00000,0.00311,215.54284
36.90000,1.84510,17671.67598,0.00000,0.00315,217.50290
37.20000,1.85987,17825.75250,0.00000,0.00318,219.39928
37.50000,1.87500,17981.34148,0.00000,0.00321,221.31427
37.80000,1.88995,18136.21670,0.00000,0.00325,223.22047
38.10000,1.90495,18290.99953,0.00000,0.00328,225.12554
38.40000,1.92002,18448.36771,0.00000,0.00332,227.06242
38.70000,1.93491,18602.10598,0.00000,0.00335,228.95463
39.00000,1.94997,18758.74102,0.00000,0.00339,230.88250
39.30000,1.96492,18909.03413,0.00000,0.00342,232.73230
39.60000,1.97999,19066.31291,0.00000,0.00346,234.66809
39.90000,1.99488,19216.14558,0.00000,0.00350,236.51223
40.20000,2.01006,19372.10411,0.00000,0.00354,238.43177
40.50000,2.02489,19524.34033,0.00000,0.00357,240.30549
40.80000,2.04002,19673.66785,0.00000,0.00361,242.14341
41.10000,2.05508,19825.24246,0.00000,0.00365,244.00899
41.40000,2.06985,19969.88654,0.00000,0.00368,245.78927
41.70000,2.08510,20123.78126,0.00000,0.00372,247.68340
42.00000,2.09987,20269.06610,0.00000,0.00376,249.47157
42.30000,2.11499,20414.22576,0.00000,0.00380,251.25819
42.60000,2.12994,20561.02902,0.00000,0.00385,253.06505
42.90000,2.14495,20701.84350,0.00000,0.00389,254.79819
43.20000,2.16001,20844.81418,0.00000,0.00393,256.55787
43.50000,2.17496,20981.85271,0.00000,0.00398,258.24454
43.80000,2.18997,21119.85087,0.00000,0.00403,259.94302
44.10000,2.20492,21251.98245,0.00000,0.00407,261.56930
44.40000,2.22004,21388.06731,0.00000,0.00412,263.24423
44.70000,2.23487,21513.86142,0.00000,0.00417,264.79250
45.00000,2.25006,21641.88623,0.00000,0.00422,266.36823
45.30000,2.26495,21767.32272,0.00000,0.00427,267.91211
45.60000,2.27995,21884.09269,0.00000,0.00432,269.34931
45.90000,2.29502,22006.24198,0.00000,0.00437,270.85272
46.20000,2.30985,22113.25765,0.00000,0.00442,272.16987
46.50000,2.32509,22225.22348,0.00000,0.00448,273.54795
46.80000,2.33986,22324.26554,0.00000,0.00453,274.76695
47.10000,2.35493,22422.14531,0.00000,0.00458,275.97166
47.40000,2.36994,22515.91831,0.00000,0.00465,277.12582
47.70000,2.38494,22601.52251,0.00000,0.00470,278.17943
48.00000,2.40007,22682.86198,0.00000,0.00477,279.18056
48.30000,2.41502,22755.18626,0.00000,0.00483,280.07072
48.60000,2.43008,22825.39457,0.00000,0.00490,280.93485
48.90000,2.44503,22885.95736,0.00000,0.00497,281.68026
49.20000,2.46004,22947.26223,0.00000,0.00505,282.43480
49.50000,2.47487,22997.09767,0.00000,0.00513,283.04817
49.80000,2.49011,23049.27111,0.00000,0.00522,283.69032
50.10000,2.50494,23094.25324,0.00000,0.00531,284.24396
50.40000,2.51995,23132.53731,0.00000,0.00540,284.71516
50.70000,2.53507,23174.69567,0.00000,0.00551,285.23404
51.00000,2.54984,23206.79724,0.00000,0.00561,285.62915
51.30000,2.56509,23240.55284,0.00000,0.00572,286.04461
51.60000,2.57992,23270.06906,0.00000,0.00584,286.40790
51.90000,2.59504,23296.96417,0.00000,0.00597,286.73892
52.20000,2.61005,23323.43757,0.00000,0.00610,287.06476
52.50000,2.62500,23346.50010,0.00000,0.00623,287.34861
52.80000,2.64006,23370.75174,0.00000,0.00637,287.64710
53.10000,2.65501,23390.03086,0.00000,0.00651,287.88439
53.40000,2.67008,23410.11763,0.00000,0.00665,288.13162
53.70000,2.68497,23426.09018,0.00000,0.00680,288.32821
54.00000,2.70009,23446.27082,0.00000,0.00696,288.57659
54.30000,2.71492,23458.76098,0.00000,0.00712,288.73032
54.60000,2.73005,23474.61432,0.00000,0.00729,288.92544
54.90000,2.74500,23491.29170,0.00000,0.00745,289.13071
55.20000,2.75994,23498.57837,0.00000,0.00762,289.22039
55.50000,2.77507,23516.60579,0.00000,0.00778,289.44227
55.80000,2.78984,23524.81633,0.00000,0.00795,289.54333
56.10000,2.80502,23538.66994,0.00000,0.00813,289.71384
56.40000,2.81991,23550.66538,0.00000,0.00831,289.86148
56.70000,2.83498,23561.37484,0.00000,0.00848,289.99329
57.00000,2.85005,23571.62982,0.00000,0.00866,290.11951
57.30000,2.86499,23581.07418,0.00000,0.00883,290.23575
57.60000,2.88012,23591.94607,0.00000,0.00901,290.36956
57.90000,2.89501,23600.11041,0.00000,0.00919,290.47005
58.20000,2.91001,23613.92826,0.00000,0.00938,290.64012
58.50000,2.92502,23619.76653,0.00000,0.00956,290.71197
58.80000,2.94009,23631.27321,0.00000,0.00974,290.85360
59.10000,2.95492,23637.34841,0.00000,0.00992,290.92837
59.40000,2.97004,23647.04758,0.00000,0.01010,291.04775
59.70000,2.98499,23658.73009,0.00000,0.01029,291.19154
60.00000,2.99988,23661.52704,0.00000,0.01047,291.22596
60.30000,3.01512,23674.02613,0.00000,0.01065,291.37980
60.60000,3.02989,23677.67841,0.00000,0.01083,291.42475
60.90000,3.04508,23688.70527,0.00000,0.01102,291.56047
61.20000,3.06003,23696.60437,0.00000,0.01120,291.65769
61.50000,3.07497,23703.46189,0.00000,0.01139,291.74210
61.80000,3.09004,23713.45609,0.00000,0.01156,291.86511
62.10000,3.10499,23719.48063,0.00000,0.01174,291.93926
62.40000,3.12005,23727.17857,0.00000,0.01192,292.03400
62.70000,3.13500,23732.84847,0.00000,0.01210,292.10379
63.00000,3.15007,23744.92437,0.00000,0.01229,292.25242
63.30000,3.16490,23746.84513,0.00000,0.01248,292.27606
63.60000,3.18002,23759.12070,0.00000,0.01266,292.42715
63.90000,3.19491,23765.20336,0.00000,0.01284,292.50201
64.20000,3.21010,23771.54380,0.00000,0.01302,292.58005
64.50000,3.22499,23781.41880,0.00000,0.01319,292.70159
64.80000,3.23987,23783.67186,0.00000,0.01337,292.72932
65.10000,3.25512,23795.64792,0.00000,0.01356,292.87672
65.40000,3.26983,23798.25264,0.00000,0.01373,292.90878
65.70000,3.28501,23808.27814,0.00000,0.01392,293.03217
66.00000,3.29996,23814.35037,0.00000,0.01409,293.10691
66.30000,3.31503,23822.93344,0.00000,0.01426,293.21255
66.60000,3.33004,23831.60293,0.00000,0.01444,293.31926
66.90000,3.34498,23836.08073,0.00000,0.01461,293.37437
67.20000,3.36005,23845.79182,0.00000,0.01479,293.49389
67.50000,3.37500,23849.80470,0.00000,0.01496,293.54328
67.80000,3.39006,23860.80772,0.00000,0.01514,293.67871
68.10000,3.40495,23862.65844,0.00000,0.01532,293.70149
68.40000,3.42008,23872.57218,0.00000,0.01550,293.82351
68.70000,3.43491,23879.20171,0.00000,0.01567,293.90510
69.00000,3.44997,23883.87173,0.00000,0.01584,293.96258
69.30000,3.46498,23893.85551,0.00000,0.01600,294.08546
69.60000,3.47993,23897.06820,0.00000,0.01617,294.12500
69.90000,3.49511,23907.41408,0.00000,0.01634,294.25234
70.20000,3.50988,23911.49700,0.00000,0.01652,294.30259
70.50000,3.52501,23919.55107,0.00000,0.01669,294.40172
70.80000,3.53996,23926.33557,0.00000,0.01686,294.48523
71.10000,3.55502,23934.47906,0.00000,0.01703,294.58546
71.40000,3.57003,23940.11915,0.00000,0.01720,294.65487
71.70000,3.58510,23946.98113,0.00000,0.01736,294.73933
72.00000,3.59999,23954.16498,0.00000,0.01754,294.82775
72.30000,3.61493,23959.49215,0.00000,0.01770,294.89332
72.60000,3.63006,23970.94816,0.00000,0.01787,295.03432
72.90000,3.64489,23971.95697,0.00000,0.01804,295.04673
73.20000,3.66007,23983.10751,0.00000,0.01821,295.18397
73.50000,3.67490,23986.53924,0.00000,0.01838,295.22621
73.80000,3.69003,23991.03642,0.00000,0.01855,295.28156
74.10000,3.70504,24004.46534,0.00000,0.01871,295.44685
74.40000,3.71992,24005.29683,0.00000,0.01888,295.45708
74.70000,3.73511,24014.02295,0.00000,0.01904,295.56448
75.00000,3.75000,24020.08623,0.00000,0.01920,295.63911
75.30000,3.76500,24023.80407,0.00000,0.01936,295.68487
75.60000,3.77995,24032.04888,0.00000,0.01954,295.78634
75.90000,3.79502,24040.12084,0.00000,0.01970,295.88569
76.20000,3.81003,24048.43867,0.00000,0.01987,295.98807
76.50000,3.82503,24052.26827,0.00000,0.02003,296.03520
76.80000,3.83998,24059.98558,0.00000,0.02019,296.13019
77.10000,3.85499,24064.05061,0.00000,0.02035,296.18022
77.40000,3.87005,24072.38334,0.00000,0.02051,296.28278
77.70000,3.88488,24075.74356,0.00000,0.02067,296.32414
78.00000,3.90001,24085.17450,0.00000,0.02084,296.44021
78.30000,3.91496,24089.87284,0.00000,0.02100,296.49804
78.60000,3.93002,24094.63078,0.00000,0.02115,296.55660
78.90000,3.94503,24103.85907,0.00000,0.02131,296.67018
79.20000,3.95986,24105.58164,0.00000,0.02147,296.69138
79.50000,3.97516,24118.44581,0.00000,0.02164,296.84972
79.80000,3.98993,24121.86861,0.00000,0.02180,296.89184
80.10000,4.00506,24129.15677,0.00000,0.02196,296.98155
80.40000,4.02007,24134.99802,0.00000,0.02211,297.05344
80.70000,4.03501,24141.10899,0.00000,0.02227,297.12866
81.00000,4.04996,24147.65954,0.00000,0.02243,297.20928
81.30000,4.06491,24151.40122,0.00000,0.02259,297.25533
81.60000,4.08003,24162.52494,0.00000,0.02275,297.39224
81.90000,4.09492,24162.86021,0.00000,0.02291,297.39637
82.20000,4.11005,24174.06142,0.00000,0.02306,297.53423
82.50000,4.12488,24176.73320,0.00000,0.02321,297.56712
82.80000,4.14006,24185.47720,0.00000,0.02299,297.67474
83.10000,4.15501,24193.39567,0.00000,0.02315,297.77220
83.40000,4.17002,24195.35518,0.00000,0.02331,297.79632
83.70000,4.18508,24204.53280,0.00000,0.02347,297.90928
84.00000,4.19991,24208.28193,0.00000,0.02363,297.95542
84.30000,4.21516,24217.32247,0.00000,0.02380,298.06669
84.60000,4.22993,24220.99113,0.00000,0.02396,298.11184
84.90000,4.24499,24229.00200,0.00000,0.02412,298.21044
85.20000,4.25994,24234.84623,0.00000,0.02427,298.28237
85.50000,4.27501,24241.64116,0.00000,0.02443,298.36600
85.80000,4.28996,24247.12479,0.00000,0.02459,298.43350
86.10000,4.30502,24252.82449,0.00000,0.02475,298.50365
86.40000,4.32003,24260.44345,0.00000,0.02492,298.59742
86.70000,4.33492,24262.26735,0.00000,0.02508,298.61987
87.00000,4.35010,24274.01841,0.00000,0.02523,298.76450
87.30000,4.36487,24274.02139,0.00000,0.02538,298.76454
87.60000,4.38006,24281.05772,0.00000,0.02554,298.85114
87.90000,4.39489,24288.33544,0.00000,0.02570,298.94072
88.20000,4.41001,24291.16666,0.00000,0.02586,298.97556
88.50000,4.42508,24301.56022,0.00000,0.02602,299.10349
88.80000,4.43985,24302.88643,0.00000,0.02617,299.11981
89.10000,4.45515,24313.72255,0.00000,0.02633,299.25318
89.40000,4.46998,24314.35287,0.00000,0.02649,299.26094
89.70000,4.48505,24321.50543,0.00000,0.02664,299.34897
90.00000,4.50000,24327.67153,0.00000,0.02680,299.42487
90.30000,4.51506,24335.09976,0.00000,0.02695,299.51629
90.60000,4.52995,24340.21682,0.00000,0.02710,299.57927
90.90000,4.54496,24342.41474,0.00000,0.02725,299.60633
91.20000,4.55996,24349.79677,0.00000,0.02741,299.69718
91.50000,4.57491,24352.80085,0.00000,0.02756,299.73416
91.80000,4.59004,24361.93973,0.00000,0.02771,299.84664
92.10000,4.60487,24365.26418,0.00000,0.02788,299.88756
92.40000,4.62011,24374.13037,0.00000,0.02803,299.99668
92.70000,4.63494,24379.53502,0.00000,0.02818,300.06320
93.00000,4.65007,24383.08299,0.00000,0.02833,300.10687
93.30000,4.66507,24391.56175,0.00000,0.02848,300.21123
93.60000,4.67990,24394.36913,0.00000,0.02863,300.24578
93.90000,4.69509,24402.65864,0.00000,0.02878,300.34781
94.20000,4.70992,24405.43622,0.00000,0.02894,300.38199
94.50000,4.72498,24412.61113,0.00000,0.02910,300.47030
94.80000,4.73999,24416.80282,0.00000,0.02925,300.52189
95.10000,4.75500,24422.93018,0.00000,0.02939,300.59731
95.40000,4.76995,24428.64627,0.00000,0.02954,300.66766
95.70000,4.78495,24432.73365,0.00000,0.02969,300.71797
96.00000,4.80002,24442.43580,0.00000,0.02984,300.83738
96.30000,4.81497,24442.81280,0.00000,0.02999,300.84202
96.60000,4.83003,24450.34236,0.00000,0.03014,300.93470
96.90000,4.84492,24455.69485,0.00000,0.03029,301.00058
97.20000,4.86011,24461.66724,0.00000,0.03044,301.07408
97.50000,4.87494,24468.61267,0.00000,0.03059,301.15957
97.80000,4.88994,24470.14302,0.00000,0.03074,301.17840
98.10000,4.90513,24478.86467,0.00000,0.03090,301.28575
98.40000,4.91996,24481.31889,0.00000,0.03105,301.31596
98.70000,4.93514,24487.93650,0.00000,0.03120,301.39741
99.00000,4.94997,24493.20853,0.00000,0.03134,301.46229
99.30000,4.96498,24498.23320,0.00000,0.03149,301.52414
99.60000,4.97993,24501.90932,0.00000,0.03163,301.56938
99.90000,4.99499,24505.80895,0.00000,0.03178,301.61738
100.20000,5.01000,24512.79610,0.00000,0.03193,301.70338
100.50000,5.02501,24515.47235,0.00000,0.03208,301.73632
100.80000,5.04002,24523.49663,0.00000,0.03223,301.83508
101.10000,5.05490,24526.24142,0.00000,0.03237,301.86886
101.40000,5.07009,24534.08986,0.00000,0.03251,301.96546
101.70000,5.08498,24536.97920,0.00000,0.03266,302.00102
102.00000,5.10010,24542.98735,0.00000,0.03280,302.07497
102.30000,5.11499,24549.51257,0.00000,0.03295,302.15528
102.60000,5.12994,24550.46326,0.00000,0.03309,302.16699
102.90000,5.14506,24561.22488,0.00000,0.03324,302.29944
103.20000,5.15983,24560.98795,0.00000,0.03339,302.29652
103.50000,5.17508,24570.87636,0.00000,0.03353,302.41823
103.80000,5.18991,24571.70188,0.00000,0.03368,302.42839
104.10000,5.20497,24576.26164,0.00000,0.03382,302.48451
104.40000,5.21998,24580.87355,0.00000,0.03397,302.54128
104.70000,5.23499,24585.51675,0.00000,0.03411,302.59842
105.00000,5.25000,24590.85882,0.00000,0.03425,302.66417
105.30001,5.26500,24592.96584,0.00000,0.03440,302.69011
105.60001,5.28007,24601.99594,0.00000,0.03454,302.80125
105.90001,5.29496,24603.23125,0.00000,0.03468,302.81645
106.20001,5.31008,24612.59216,0.00000,0.03483,302.93167
106.50001,5.32491,24615.05234,0.00000,0.03497,302.96195
106.80001,5.34010,24620.14854,0.00000,0.03513,303.02467
107.10001,5.35493,24626.18649,0.00000,0.03527,303.09899
107.40001,5.36993,24626.98072,0.00000,0.03541,303.10876
107.70001,5.38506,24635.06460,0.00000,0.03555,303.20826
108.00001,5.39989,24636.35951,0.00000,0.03569,303.22420
108.30001,5.41507,24643.91738,0.00000,0.03583,303.31722
108.60001,5.42990,24646.20769,0.00000,0.03596,303.34541
108.90001,5.44497,24650.46197,0.00000,0.03612,303.39777
109.20001,5.46004,24657.03189,0.00000,0.03626,303.47863
109.50001,5.47504,24658.63675,0.00000,0.03640,303.49838
109.80001,5.48999,24665.15899,0.00000,0.03654,303.57866
110.10001,5.50500,24669.12121,0.00000,0.03668,303.62743
110.40001,5.52006,24676.77593,0.00000,0.03683,303.72164
110.70001,5.53489,24675.42738,0.00000,0.03697,303.70504
111.00001,5.55014,24683.65133,0.00000,0.03712,303.80626
111.30001,5.56497,24687.36023,0.00000,0.03726,303.85191
111.60001,5.57997,24690.20486,0.00000,0.03740,303.88692
111.90001,5.59498,24699.65816,0.00000,0.03754,304.00328
112.20001,5.60993,24698.34685,0.00000,0.03768,303.98714
112.50001,5.62511,24704.93019,0.00000,0.03782,304.06816
112.80001,5.63988,24705.18053,0.00000,0.03796,304.07125
113.10001,5.65501,24711.39878,0.00000,0.03810,304.14778
113.40001,5.67002,24715.70522,0.00000,0.03825,304.20078
113.70001,5.68496,24719.69426,0.00000,0.03839,304.24988
114.00001,5.69997,24724.84708,0.00000,0.03853,304.31330
114.30001,5.71504,24727.68277,0.00000,0.03866,304.34820
114.60001,5.72999,24733.52253,0.00000,0.03880,304.42008
114.90001,5.74505,24736.32395,0.00000,0.03894,304.45456
115.20001,5.76012,24743.61658,0.00000,0.03909,304.54432
115.50001,5.77489,24742.27846,0.00000,0.03923,304.52785
115.80001,5.79013,24752.21604,0.00000,0.03936,304.65016
116.10001,5.80490,24752.40678,0.00000,0.03950,304.65251
116.40001,5.82003,24757.04253,0.00000,0.03964,304.70956
116.70001,5.83504,24763.53198,0.00000,0.03978,304.78943
117.00001,5.84992,24763.66758,0.00000,0.03991,304.79110
117.30001,5.86511,24770.88124,0.00000,0.04005,304.87989
117.60001,5.87988,24771.97498,0.00000,0.04019,304.89335
117.90001,5.89506,24777.34834,0.00000,0.04033,304.95949
118.20001,5.91001,24781.55494,0.00000,0.04047,305.01126
118.50001,5.92502,24784.87939,0.00000,0.04060,305.05218
118.80001,5.94003,24790.85475,0.00000,0.04074,305.12572
119.10001,5.95503,24793.19423,0.00000,0.04087,305.15452
119.40001,5.96998,24797.96112,0.00000,0.04101,305.21319
119.70001,5.98505,24798.75982,0.00000,0.04114,305.22302
120.00001,6.00011,24806.36984,0.00000,0.04128,305.31668
120.30001,6.01482,24804.67409,0.00000,0.04142,305.29581
120.60001,6.03013,24815.58174,0.00000,0.04156,305.43006
120.90001,6.04490,24816.69188,0.00000,0.04169,305.44373
121.20001,6.06002,24819.23699,0.00000,0.04183,305.47505
121.50001,6.07509,24825.68473,0.00000,0.04196,305.55441
121.80001,6.08986,24824.72360,0.00000,0.04209,305.54258
122.10001,6.10510,24832.96692,0.00000,0.04223,305.64404
122.40001,6.11987,24833.87440,0.00000,0.04236,305.65521
122.70001,6.13500,24838.02885,0.00000,0.04249,305.70634
123.00001,6.15001,24841.78543,0.00000,0.04262,305.75258
123.30001,6.16501,24846.74752,0.00000,0.04276,305.81365
123.60001,6.18002,24848.71745,0.00000,0.04289,305.83790
123.90001,6.19503,24851.60381,0.00000,0.04303,305.87342
124.20001,6.20998,24858.31678,0.00000,0.04316,305.95605
124.50001,6.22504,24859.58487,0.00000,0.04330,305.97165
124.80001,6.24011,24866.16820,0.00000,0.04344,306.05268
125.10001,6.25488,24864.21764,0.00000,0.04357,306.02867
125.40001,6.27018,24869.07691,0.00000,0.04370,306.08848
125.70001,6.28489,24872.02734,0.00000,0.04382,306.12479
126.00001,6.29996,24875.43374,0.00000,0.04395,306.16672
126.30001,6.31503,24879.97115,0.00000,0.04408,306.22257
126.60001,6.32991,24879.99052,0.00000,0.04422,306.22281
126.90001,6.34510,24886.58875,0.00000,0.04435,306.30402
127.20001,6.35993,24887.14159,0.00000,0.04449,306.31082
127.50001,6.37505,24891.86823,0.00000,0.04462,306.36900
127.80001,6.39000,24895.34914,0.00000,0.04475,306.41184
128.10001,6.40507,24900.54220,0.00000,0.04488,306.47576
128.40001,6.42002,24900.35295,0.00000,0.04501,306.47343
128.70001,6.43508,24902.10086,0.00000,0.04513,306.49494
129.00001,6.44997,24907.57555,0.00000,0.04526,306.56232
129.30001,6.46492,24907.20898,0.00000,0.04540,306.55781
129.60001,6.48004,24915.94106,0.00000,0.04552,306.66528
129.90001,6.49481,24914.80559,0.00000,0.04565,306.65131
130.20001,6.51012,24920.70198,0.00000,0.04579,306.72388
130.50001,6.52489,24922.73301,0.00000,0.04592,306.74888
130.80001,6.53995,24922.06693,0.00000,0.04604,306.74068
131.10001,6.55508,24931.70053,0.00000,0.04617,306.85925
131.40001,6.56985,24930.83626,0.00000,0.04630,306.84861
131.70001,6.58509,24936.70434,0.00000,0.04643,306.92084
132.00001,6.59998,24938.09313,0.00000,0.04656,306.93793
132.30001,6.61499,24941.96594,0.00000,0.04668,306.98560
132.60001,6.63000,24944.35608,0.00000,0.04681,307.01502
132.90001,6.64500,24948.79961,0.00000,0.04694,307.06971
133.20001,6.65995,24952.20304,0.00000,0.04707,307.11160
133.50001,6.67502,24954.30261,0.00000,0.04720,307.13744
133.80001,6.69003,24958.46450,0.00000,0.04733,307.18866
134.10001,6.70491,24956.75683,0.00000,0.04746,307.16765
134.40001,6.72010,24966.47090,0.00000,0.04759,307.28721
134.70001,6.73481,24964.61719,0.00000,0.04772,307.26439
135.00001,6.75005,24968.17410,0.00000,0.04784,307.30817
135.30001,6.76494,24973.73670,0.00000,0.04796,307.37663
135.60001,6.77989,24970.97850,0.00000,0.04809,307.34269
135.90001,6.79508,24979.04897,0.00000,0.04821,307.44202
136.20001,6.80996,24979.91621,0.00000,0.04834,307.45269
136.50001,6.82509,24984.37315,0.00000,0.04847,307.50755
136.80001,6.83998,24986.30136,0.00000,0.04860,307.53128
137.10001,6.85498,24990.10861,0.00000,0.04872,307.57814
137.40001,6.86999,24992.95324,0.00000,0.04885,307.61315
137.70001,6.88506,24993.82198,0.00000,0.04897,307.62384
138.00001,6.89995,24996.54591,0.00000,0.04910,307.65737
138.30001,6.91501,24999.04335,0.00000,0.04922,307.68811
138.60001,6.93002,25005.48363,0.00000,0.04934,307.76737
138.90001,6.94491,25004.32432,0.00000,0.04947,307.75311
139.20001,6.96009,25010.12087,0.00000,0.04959,307.82445
139.50001,6.97486,25007.42078,0.00000,0.04971,307.79122
139.80001,6.99011,25014.74619,0.00000,0.04983,307.88138
140.10001,7.00500,25017.75026,0.00000,0.04996,307.91835
140.40001,7.01994,25018.12875,0.00000,0.05008,307.92301
140.70001,7.03513,25025.91908,0.00000,0.05021,308.01889
141.00001,7.04996,25024.53029,0.00000,0.05033,308.00180
141.30001,7.06509,25028.26452,0.00000,0.05047,308.04776
141.60001,7.07991,25029.91557,0.00000,0.05059,308.06808
141.90001,7.09504,25035.80451,0.00000,0.05072,308.14056
142.20001,7.10993,25035.51245,0.00000,0.05085,308.13697
142.50001,7.12499,25039.54172,0.00000,0.05097,308.18656
142.80001,7.13994,25042.15539,0.00000,0.05109,308.21873
143.10001,7.15507,25042.84084,0.00000,0.05122,308.22717
143.40001,7.17008,25048.13075,0.00000,0.05134,308.29227
143.70001,7.18490,25046.75388,0.00000,0.05147,308.27533
144.00001,7.20009,25053.86770,0.00000,0.05160,308.36289
144.30001,7.21492,25055.14026,0.00000,0.05173,308.37855
144.60001,7.23004,25057.22344,0.00000,0.05185,308.40419
144.90001,7.24499,25062.95443,0.00000,0.05198,308.47472
145.20001,7.26000,25063.06171,0.00000,0.05210,308.47605
145.50001,7.27507,25066.90919,0.00000,0.05223,308.52340
145.80001,7.28995,25069.05496,0.00000,0.05236,308.54981
146.10001,7.30508,25072.47329,0.00000,0.05248,308.59188
146.40001,7.32003,25073.93062,0.00000,0.05262,308.60982
146.70001,7.33509,25076.71714,0.00000,0.05275,308.64412
147.00001,7.34992,25076.67243,0.00000,0.05288,308.64357
147.30001,7.36517,25084.32269,0.00000,0.05300,308.73773
147.60001,7.37994,25082.94284,0.00000,0.05313,308.72074
147.90001,7.39500,25083.25279,0.00000,0.05325,308.72456
148.20001,7.41001,25088.57846,0.00000,0.05338,308.79011
148.50001,7.42490,25087.18073,0.00000,0.05350,308.77290
148.80001,7.44008,25093.62698,0.00000,0.05363,308.85224
149.10001,7.45491,25095.56115,0.00000,0.05376,308.87605
149.40001,7.47004,25098.83940,0.00000,0.05389,308.91640
149.70001,7.48505,25101.68254,0.00000,0.05402,308.95139
150.00001,7.49999,25101.38750,0.00000,0.05414,308.94776
150.30001,7.51512,25105.33333,0.00000,0.05427,308.99632
150.60001,7.53001,25105.81911,0.00000,0.05440,309.00230
150.90001,7.54502,25109.94673,0.00000,0.05452,309.05311
151.20001,7.55996,25110.72159,0.00000,0.05465,309.06264
151.50001,7.57497,25112.30409,0.00000,0.05478,309.08212
151.80001,7.58998,25113.54089,0.00000,0.05491,309.09734
152.10001,7.60504,25115.26346,0.00000,0.05503,309.11854
152.40001,7.61993,25120.61894,0.00000,0.05516,309.18446
152.70001,7.63494,25120.01395,0.00000,0.05528,309.17701
153.00001,7.65007,25126.36185,0.00000,0.05541,309.25514
153.30001,7.66489,25124.90749,0.00000,0.05554,309.23724
153.60001,7.68008,25129.41957,0.00000,0.05568,309.29278
153.90001,7.69497,25131.10936,0.00000,0.05580,309.31358
154.20001,7.71003,25133.34453,0.00000,0.05593,309.34109
154.50001,7.72492,25135.71382,0.00000,0.05606,309.37025
154.80001,7.73993,25136.91783,0.00000,0.05619,309.38507
155.10001,7.75512,25141.12890,0.00000,0.05631,309.43690
155.40001,7.76994,25139.26029,0.00000,0.05644,309.41390
155.70001,7.78507,25144.55020,0.00000,0.05657,309.47901
156.00001,7.79996,25144.84823,0.00000,0.05670,309.48267
156.30001,7.81502,25148.65994,0.00000,0.05682,309.52959
156.60001,7.82991,25149.80137,0.00000,0.05695,309.54364
156.90001,7.84498,25150.86532,0.00000,0.05709,309.55673
157.20001,7.86005,25156.13139,0.00000,0.05721,309.62155
157.50001,7.87493,25153.05579,0.00000,0.05734,309.58369
157.80001,7.89000,25158.95665,0.00000,0.05747,309.65632
158.10001,7.90489,25158.73313,0.00000,0.05759,309.65357
158.40001,7.92013,25163.95152,0.00000,0.05773,309.71780
158.70001,7.93490,25165.14659,0.00000,0.05785,309.73251
159.00001,7.95003,25163.82933,0.00000,0.05798,309.71629
159.30001,7.96510,25170.15934,0.00000,0.05811,309.79420
159.60001,7.97998,25168.06722,0.00000,0.05824,309.76845
159.90001,7.99505,25173.34223,0.00000,0.05837,309.83338
160.20001,8.00988,25173.91741,0.00000,0.05850,309.84046
160.50001,8.02507,25176.81122,0.00000,0.05863,309.87607
160.80001,8.03995,25174.99030,0.00000,0.05876,309.85366
161.10001,8.05502,25177.29998,0.00000,0.05889,309.88209
161.40001,8.06991,25178.58446,0.00000,0.05902,309.89790
161.70001,8.08503,25182.00874,0.00000,0.05915,309.94004
162.00001,8.10004,25187.34038,0.00000,0.05927,310.00567
162.30001,8.11499,25185.47773,0.00000,0.05940,309.98274
162.60001,8.13011,25189.25965,0.00000,0.05952,310.02929
162.90001,8.14488,25188.25829,0.00000,0.05965,310.01696
163.20001,8.16013,25193.96544,0.00000,0.05979,310.08721
163.50001,8.17490,25193.50946,0.00000,0.05992,310.08160
163.80001,8.19002,25196.09034,0.00000,0.06006,310.11336
164.10001,8.20497,25196.54930,0.00000,0.06018,310.11901
164.40001,8.21986,25195.08600,0.00000,0.06031,310.10100
164.70001,8.23505,25199.84841,0.00000,0.06043,310.15962
165.00001,8.24993,25200.26863,0.00000,0.06056,310.16479
165.30001,8.26500,25204.06544,0.00000,0.06069,310.21152
165.60001,8.27995,25204.72705,0.00000,0.06082,310.21966
165.90001,8.29501,25207.79669,0.00000,0.06095,310.25744
166.20001,8.30996,25209.06031,0.00000,0.06108,310.27300
166.50001,8.32503,25209.64146,0.00000,0.06121,310.28015
166.80001,8.33998,25213.02104,0.00000,0.06134,310.32174
167.10001,8.35498,25213.54556,0.00000,0.06147,310.32820
167.40001,8.37011,25218.21856,0.00000,0.06160,310.38571
167.70001,8.38488,25216.09664,0.00000,0.06172,310.35960
168.00001,8.40018,25220.10505,0.00000,0.06186,310.40893
168.30001,8.41495,25219.62225,0.00000,0.06199,310.40299
168.60001,8.43002,25222.95415,0.00000,0.06211,310.44400
168.90001,8.44509,25224.65587,0.00000,0.06224,310.46495
169.20001,8.45997,25222.71574,0.00000,0.06237,310.44107
169.50001,8.47510,25226.06552,0.00000,0.06250,310.48230
169.80001,8.48993,25224.13731,0.00000,0.06263,310.45856
170.10001,8.50500,25230.48818,0.00000,0.06276,310.53673
170.40001,8.52000,25231.44186,0.00000,0.06289,310.54847
170.70001,8.53501,25234.64262,0.00000,0.06302,310.58786
171.00001,8.54996,25234.26712,0.00000,0.06315,310.58324
171.30001,8.56508,25235.48901,0.00000,0.06328,310.59828
171.60001,8.58003,25238.12950,0.00000,0.06341,310.63078
171.90001,8.59498,25236.29963,0.00000,0.06353,310.60826
172.20001,8.61017,25242.60879,0.00000,0.06366,310.68591
172.50001,8.62493,25239.04145,0.00000,0.06379,310.64200
172.80001,8.64012,25243.41047,0.00000,0.06392,310.69578
173.10001,8.65495,25242.05148,0.00000,0.06405,310.67905
173.40001,8.67001,25243.20483,0.00000,0.06418,310.69325
173.70001,8.68508,25248.18778,0.00000,0.06431,310.75458
174.00001,8.69991,25246.67084,0.00000,0.06443,310.73591
174.30001,8.71504,25249.83585,0.00000,0.06456,310.77486
174.60001,8.72992,25251.04880,0.00000,0.06469,310.78979
174.90001,8.74505,25254.58336,0.00000,0.06482,310.83329
175.20001,8.76000,25254.57740,0.00000,0.06495,310.83322
175.50001,8.77507,25255.57876,0.00000,0.06507,310.84554
175.80001,8.78995,25257.31325,0.00000,0.06521,310.86689
176.10001,8.80508,25258.21328,0.00000,0.06533,310.87797
176.40001,8.82003,25261.94453,0.00000,0.06546,310.92389
176.70001,8.83491,25257.79009,0.00000,0.06559,310.87276
177.00001,8.85016,25262.62105,0.00000,0.06571,310.93222
177.30001,8.86487,25260.14447,0.00000,0.06582,310.90174
177.60001,8.88005,25262.62701,0.00000,0.06587,310.93229
177.90001,8.89488,25265.04695,0.00000,0.06600,310.96208
178.20001,8.91001,25263.57472,0.00000,0.06613,310.94396
178.50001,8.92508,25268.83483,0.00000,0.06626,311.00870
178.80001,8.93990,25266.08109,0.00000,0.06639,310.97481
179.10001,8.95509,25271.43955,0.00000,0.06651,311.04076
179.40001,8.96992,25270.22660,0.00000,0.06664,311.02583
179.70001,8.98499,25274.64330,0.00000,0.06678,311.08019
180.00001,8.99999,25274.44065,0.00000,0.06691,311.07770
180.30001,9.01506,25276.65198,0.00000,0.06704,311.10491
180.60001,9.02995,25276.21388,0.00000,0.06717,311.09952
180.90001,9.04507,25278.21064,0.00000,0.06731,311.12410
181.20001,9.06002,25280.31170,0.00000,0.06744,311.14996
181.50001,9.07491,25278.58615,0.00000,0.06757,311.12872
181.80001,9.09016,25284.34098,0.00000,0.06769,311.19955
182.10001,9.10486,25280.78556,0.00000,0.06782,311.15579
182.40001,9.12011,25283.57208,0.00000,0.06795,311.19009
182.70001,9.13494,25283.71215,0.00000,0.06809,311.19181
183.00001,9.14994,25282.89855,0.00000,0.06822,311.18180
183.30001,9.16495,25287.34505,0.00000,0.06835,311.23652
183.60001,9.17990,25286.79371,0.00000,0.06848,311.22974
183.90001,9.19503,25288.68020,0.00000,0.06861,311.25296
184.20001,9.20997,25288.66231,0.00000,0.06874,311.25274
184.50001,9.22504,25292.21773,0.00000,0.06886,311.29650
184.80001,9.23993,25289.82162,0.00000,0.06900,311.26701
185.10001,9.25511,25294.51251,0.00000,0.06913,311.32474
185.40001,9.26994,25291.65149,0.00000,0.06926,311.28953
185.70001,9.28513,25292.36078,0.00000,0.06940,311.29826
186.00001,9.30002,25296.64636,0.00000,0.06953,311.35100
186.30001,9.31484,25291.20445,0.00000,0.06966,311.28402
186.60001,9.33009,25297.58215,0.00000,0.06978,311.36252
186.90001,9.34492,25296.83411,0.00000,0.06991,311.35331
187.20001,9.35998,25296.80729,0.00000,0.07004,311.35298
187.50001,9.37499,25299.30174,0.00000,0.07017,311.38369
187.80001,9.38994,25297.72222,0.00000,0.07030,311.36425
188.10001,9.40507,25301.98395,0.00000,0.07043,311.41670
188.40001,9.41995,25300.92299,0.00000,0.07056,311.40364
188.70001,9.43502,25303.18499,0.00000,0.07069,311.43148
189.00001,9.45003,25302.87504,0.00000,0.07082,311.42767
189.30001,9.46504,25305.16982,0.00000,0.07096,311.45591
189.60001,9.47992,25302.12104,0.00000,0.07109,311.41839
189.90001,9.49505,25305.96256,0.00000,0.07122,311.46567
190.20001,9.50994,25307.30963,0.00000,0.07135,311.48225
190.50001,9.52500,25306.01919,0.00000,0.07148,311.46636
190.80001,9.54007,25309.87263,0.00000,0.07161,311.51379
191.10001,9.55484,25304.77643,0.00000,0.07173,311.45107
191.40001,9.57015,25310.99021,0.00000,0.07186,311.52755
191.70001,9.58485,25309.10075,0.00000,0.07199,311.50429
192.00001,9.59998,25310.45973,0.00000,0.07212,311.52102
192.30001,9.61499,25314.17012,0.00000,0.07225,311.56669
192.60001,9.62994,25310.98127,0.00000,0.07239,311.52744
192.90001,9.64506,25314.51583,0.00000,0.07252,311.57094
193.20001,9.65995,25312.79624,0.00000,0.07265,311.54978
193.50001,9.67508,25314.62610,0.00000,0.07278,311.57230
193.80001,9.69002,25315.20724,0.00000,0.07290,311.57945
194.10001,9.70509,25318.01462,0.00000,0.07303,311.61400
194.40001,9.71998,25315.86289,0.00000,0.07316,311.58752
194.70001,9.73516,25319.26632,0.00000,0.07329,311.62941
195.00001,9.74987,25315.07611,0.00000,0.07342,311.57784
195.30001,9.76500,25315.70792,0.00000,0.07355,311.58561
195.60001,9.78007,25319.61501,0.00000,0.07368,311.63370
195.90001,9.79483,25315.76157,0.00000,0.07381,311.58627
196.20001,9.81014,25321.94257,0.00000,0.07394,311.66235
196.50001,9.82491,25320.59550,0.00000,0.07408,311.64577
196.80001,9.83997,25319.61501,0.00000,0.07421,311.63370
197.10001,9.85510,25323.87674,0.00000,0.07433,311.68616
197.40001,9.86999,25321.44189,0.00000,0.07446,311.65619
197.70001,9.88506,25325.31321,0.00000,0.07459,311.70384
198.00001,9.90000,25321.90382,0.00000,0.07472,311.66187
198.30001,9.91507,25324.89598,0.00000,0.07485,311.69870
198.60001,9.92996,25321.50447,0.00000,0.07498,311.65696
198.90001,9.94509,25325.78111,0.00000,0.07511,311.70959
199.20001,9.95991,25323.35818,0.00000,0.07525,311.67977
199.50001,9.97510,25326.24900,0.00000,0.07538,311.71535
199.80001,9.98999,25328.60339,0.00000,0.07551,311.74433
200.10001,10.00505,25324.71120,0.00000,0.07564,311.69643
200.40001,10.02012,25328.17125,0.00000,0.07577,311.73901
200.70001,10.03489,25324.89896,0.00000,0.07589,311.69874
201.00001,10.05013,25329.95939,0.00000,0.07602,311.76102
201.30001,10.06490,25328.80902,0.00000,0.07616,311.74686
201.60001,10.07997,25327.75700,0.00000,0.07629,311.73391
201.90001,10.09504,25331.21407,0.00000,0.07642,311.77646
202.20001,10.10998,25330.29020,0.00000,0.07656,311.76509
202.50001,10.12499,25330.21569,0.00000,0.07669,311.76418
202.80001,10.14000,25330.82664,0.00000,0.07682,311.77169
203.10001,10.15507,25333.07374,0.00000,0.07695,311.79935
203.40001,10.17001,25329.53024,0.00000,0.07708,311.75574
203.70001,10.18508,25332.10516,0.00000,0.07721,311.78743
204.00001,10.19991,25329.41997,0.00000,0.07735,311.75438
204.30001,10.21509,25332.69823,0.00000,0.07747,311.79473
204.60001,10.22998,25334.19728,0.00000,0.07761,311.81318
204.90001,10.24493,25332.11410,0.00000,0.07774,311.78754
205.20001,10.26006,25335.89602,0.00000,0.07787,311.83409
205.50001,10.27488,25333.48501,0.00000,0.07800,311.80441
205.80001,10.29013,25335.89900,0.00000,0.07814,311.83413
206.10001,10.30490,25334.47146,0.00000,0.07827,311.81656
206.40001,10.31996,25334.68008,0.00000,0.07840,311.81912
206.70001,10.33509,25335.66058,0.00000,0.07853,311.83119
207.00001,10.35004,25334.82611,0.00000,0.07867,311.82092
207.30001,10.36499,25334.72478,0.00000,0.07880,311.81967
207.60001,10.38005,25336.21788,0.00000,0.07893,311.83805
207.90001,10.39500,25334.64730,0.00000,0.07906,311.81872
208.20001,10.40989,25332.46279,0.00000,0.07919,311.79183
208.50001,10.42502,25335.74402,0.00000,0.07933,311.83222
208.80001,10.43990,25333.88734,0.00000,0.07946,311.80937
209.10001,10.45509,25334.95128,0.00000,0.07959,311.82246
209.40001,10.46998,25337.26692,0.00000,0.07973,311.85096
209.70001,10.48486,25334.23901,0.00000,0.07985,311.81369
210.00001,10.50011,25338.94777,0.00000,0.07999,311.87165
210.30001,10.51488,25336.38477,0.00000,0.08012,311.84010
210.60001,10.53013,25338.15205,0.00000,0.08025,311.86186
210.90001,10.54495,25337.14175,0.00000,0.08039,311.84942
211.20001,10.55996,25335.14798,0.00000,0.08052,311.82488
211.50001,10.57497,25336.53975,0.00000,0.08066,311.84201
211.80001,10.58997,25335.15096,0.00000,0.08079,311.82492
212.10001,10.60504,25336.87353,0.00000,0.08092,311.84612
212.40001,10.61993,25332.94857,0.00000,0.08105,311.79781
212.70001,10.63506,25336.82287,0.00000,0.08118,311.84550
213.00001,10.64994,25333.81581,0.00000,0.08131,311.80849
213.30001,10.66507,25337.46958,0.00000,0.08144,311.85346
213.60001,10.67990,25337.75568,0.00000,0.08157,311.85698
213.90001,10.69502,25336.28941,0.00000,0.08171,311.83893
214.20001,10.70997,25338.94777,0.00000,0.08184,311.87165
214.50001,10.72486,25334.50127,0.00000,0.08197,311.81692
214.80001,10.74011,25338.52160,0.00000,0.08211,311.86640
215.10001,10.75487,25335.18672,0.00000,0.08223,311.82536
215.40001,10.77012,25337.61263,0.00000,0.08237,311.85522
215.70001,10.78495,25336.76028,0.00000,0.08250,311.84473
216.00001,10.80001,25335.61885,0.00000,0.08263,311.83068
216.30001,10.81502,25335.96754,0.00000,0.08276,311.83497
216.60001,10.82997,25336.28345,0.00000,0.08289,311.83886
216.90001,10.84498,25337.10897,0.00000,0.08301,311.84902
217.20001,10.85992,25335.25527,0.00000,0.08315,311.82620
217.50001,10.87505,25339.66601,0.00000,0.08328,311.88049
217.80001,10.88994,25335.15692,0.00000,0.08342,311.82499
218.10001,10.90501,25336.51292,0.00000,0.08355,311.84168
218.40001,10.91989,25336.08675,0.00000,0.08368,311.83644
218.70001,10.93508,25336.86161,0.00000,0.08382,311.84597
219.00001,10.95003,25338.53948,0.00000,0.08394,311.86662
219.30001,10.96497,25332.90684,0.00000,0.08407,311.79730
219.60001,10.98016,25336.98380,0.00000,0.08421,311.84748
219.90001,10.99493,25332.32272,0.00000,0.08433,311.79011
220.20001,11.01012,25335.62481,0.00000,0.08447,311.83075
220.50001,11.02494,25334.45954,0.00000,0.08460,311.81641
220.80001,11.04001,25333.94992,0.00000,0.08473,311.81014
221.10001,11.05502,25333.29725,0.00000,0.08486,311.80210
221.40001,11.06996,25331.07102,0.00000,0.08499,311.77470
221.70001,11.08497,25332.78763,0.00000,0.08512,311.79583
222.00001,11.10004,25332.10218,0.00000,0.08525,311.78739
222.30001,11.11505,25335.32381,0.00000,0.08538,311.82705
222.60001,11.12987,25331.93529,0.00000,0.08551,311.78534
222.90001,11.14506,25334.30457,0.00000,0.08564,311.81450
223.20001,11.15995,25334.01847,0.00000,0.08578,311.81098
223.50001,11.17507,25332.37934,0.00000,0.08590,311.79081
223.80001,11.19002,25333.76217,0.00000,0.08604,311.80783
224.10001,11.20497,25329.70011,0.00000,0.08617,311.75783
224.40001,11.22016,25332.47173,0.00000,0.08629,311.79194
224.70001,11.23492,25329.07128,0.00000,0.08643,311.75009
225.00001,11.25011,25330.27530,0.00000,0.08656,311.76491
225.30001,11.26494,25328.12357,0.00000,0.08669,311.73843
225.60001,11.28000,25329.46169,0.00000,0.08682,311.75489
225.90001,11.29501,25331.05016,0.00000,0.08695,311.77445
226.20001,11.30996,25329.36037,0.00000,0.08708,311.75365
226.50001,11.32503,25330.08456,0.00000,0.08721,311.76256
226.80001,11.33991,25325.63210,0.00000,0.08734,311.70776
227.10001,11.35504,25327.92985,0.00000,0.08747,311.73604
227.40001,11.36993,25325.64700,0.00000,0.08761,311.70794
227.70001,11.38506,25327.02088,0.00000,0.08774,311.72485
228.00001,11.39994,25327.16095,0.00000,0.08787,311.72658
228.30001,11.41501,25325.10757,0.00000,0.08800,311.70130
228.60001,11.43008,25326.67518,0.00000,0.08813,311.72060
228.90001,11.44502,25322.83068,0.00000,0.08826,311.67328
229.20001,11.46015,25323.03631,0.00000,0.08838,311.67581
229.50001,11.47492,25321.29884,0.00000,0.08851,311.65443
229.80001,11.49005,25321.41805,0.00000,0.08864,311.65589
230.10001,11.50499,25320.04416,0.00000,0.08877,311.63898
230.40001,11.51994,25318.19940,0.00000,0.08890,311.61628
230.70001,11.53507,25319.53454,0.00000,0.08903,311.63271
231.00001,11.54995,25316.72716,0.00000,0.08916,311.59816
231.30001,11.56496,25318.60769,0.00000,0.08928,311.62130
231.60001,11.57997,25316.92982,0.00000,0.08941,311.60065
231.90001,11.59510,25317.87753,0.00000,0.08953,311.61232
232.20001,11.60992,25313.27605,0.00000,0.08966,311.55568
232.50001,11.62511,25314.64398,0.00000,0.08979,311.57252
232.80001,11.63994,25311.36572,0.00000,0.08991,311.53217
233.10001,11.65500,25310.29582,0.00000,0.09003,311.51900
233.40001,11.67007,25311.66673,0.00000,0.09016,311.53587
233.70001,11.68490,25305.93574,0.00000,0.09028,311.46534
234.00001,11.70015,25308.71630,0.00000,0.09040,311.49956
234.30001,11.71491,25304.28469,0.00000,0.09052,311.44502
234.60001,11.72998,25304.38602,0.00000,0.09064,311.44626
234.90001,11.74499,25304.90756,0.00000,0.09076,311.45268
235.20001,11.76000,25303.38168,0.00000,0.09088,311.43390
235.50001,11.77500,25303.63798,0.00000,0.09101,311.43706
235.80001,11.78995,25298.49708,0.00000,0.09112,311.37378
236.10001,11.80502,25299.48950,0.00000,0.09123,311.38600
236.40001,11.81996,25295.70758,0.00000,0.09135,311.33945
236.70001,11.83503,25296.58675,0.00000,0.09147,311.35027
237.00001,11.84986,25291.15379,0.00000,0.09158,311.28340
237.30001,11.86511,25292.07468,0.00000,0.09170,311.29474
237.60001,11.87999,25289.85739,0.00000,0.09181,311.26745
237.90001,11.89500,25283.81348,0.00000,0.09192,311.19306
238.20001,11.91007,25287.01127,0.00000,0.09203,311.23242
238.50001,11.92489,25281.39651,0.00000,0.09214,311.16331
238.80001,11.94014,25282.61840,0.00000,0.09224,311.17835
239.10001,11.95485,25277.63844,0.00000,0.09235,311.11705
239.40001,11.97004,25275.88308,0.00000,0.09245,311.09545
239.70001,11.98498,25273.88930,0.00000,0.09255,311.07091
240.00001,11.99999,25270.66171,0.00000,0.09266,311.03118
240.30001,12.01494,25267.99142,0.00000,0.09276,310.99832
240.60001,12.02994,25263.34226,0.00000,0.09286,310.94110
240.90001,12.04507,25262.34984,0.00000,0.09295,310.92888
241.20001,12.05996,25252.88165,0.00000,0.09304,310.81235
241.50001,12.07509,25254.08566,0.00000,0.09314,310.82717
241.80001,12.08997,25245.59796,0.00000,0.09323,310.72270
242.10001,12.10516,25244.07208,0.00000,0.09332,310.70392
242.40001,12.11993,25237.87618,0.00000,0.09341,310.62766
242.70001,12.13499,25228.90866,0.00000,0.09349,310.51729
243.00001,12.15006,25226.84932,0.00000,0.09357,310.49194
243.30001,12.16489,25216.46321,0.00000,0.09365,310.36411
243.60001,12.18008,25214.64229,0.00000,0.09372,310.34170
243.90001,12.19490,25205.24561,0.00000,0.09380,310.22604
244.20001,12.21003,25197.15130,0.00000,0.09386,310.12642
244.50001,12.22498,25189.50105,0.00000,0.09393,310.03226
244.80001,12.23998,25176.79334,0.00000,0.09399,309.87585
245.10001,12.25499,25166.91387,0.00000,0.09405,309.75426
245.40001,12.27006,25153.47302,0.00000,0.09411,309.58883
245.70001,12.28501,25139.20665,0.00000,0.09417,309.41324
246.00001,12.29995,25122.22230,0.00000,0.09421,309.20419
246.30001,12.31502,25105.73864,0.00000,0.09426,309.00131
246.60001,12.32991,25078.84800,0.00000,0.09429,308.67034
246.90001,12.34515,25054.31771,0.00000,0.09433,308.36842
247.20001,12.35998,25027.03071,0.00000,0.09436,308.03258
247.50001,12.37493,24993.13802,0.00000,0.09438,307.61542
247.80001,12.39012,24962.75306,0.00000,0.09440,307.24145
248.10001,12.40494,24915.07977,0.00000,0.09442,306.65468
248.40001,12.42013,24857.80567,0.00000,0.09442,305.94975
248.70001,12.43490,24774.46198,0.00000,0.09442,304.92396
249.00001,12.44997,24663.52880,0.00000,0.09441,303.55860
249.30001,12.46503,24473.16796,0.00000,0.09437,301.21564
249.60001,12.48004,24072.38930,0.00000,0.09427,296.28285
249.73401,12.48686,23147.70222,0.00000,0.09378,284.90181
249.74001,12.48745,20527.01712,0.00000,0.09208,252.64643
249.74601,12.48847,16748.50881,0.00000,0.09228,206.14057
249.75001,12.48925,14047.90431,0.00000,0.09214,172.90154