File: scratch/college-stuff/ME Lab/ME lab Fall 2013/group1/group1.is_tens_RawData/Specimen_RawData_1.csv
Time,Extension,Load,Strain 2,Tensile strain,Tensile stress
(sec),(mm),(N),(mm/mm),(mm/mm),(MPa)
0.00000,-0.00060,0.60324,0.00000,0.00000,0.00746
0.30000,0.01208,19.82761,0.00000,0.00000,0.24529
0.60000,0.02930,36.09752,0.00000,-0.00001,0.44656
0.90000,0.04430,51.61327,0.00000,-0.00001,0.63850
1.20000,0.05949,74.88041,0.00000,-0.00001,0.92634
1.50000,0.07432,99.86844,0.00000,0.00000,1.23547
1.80000,0.08945,120.83220,0.00000,0.00000,1.49481
2.10000,0.10439,140.89702,0.00000,-0.00001,1.74303
2.40000,0.11934,176.20217,0.00000,-0.00001,2.17979
2.70000,0.13447,222.76021,0.00000,-0.00002,2.75575
3.00000,0.14935,279.15442,0.00000,-0.00003,3.45340
3.30000,0.16448,349.08743,0.00000,-0.00003,4.31854
3.60000,0.17931,426.55375,0.00000,-0.00003,5.27687
3.90000,0.19450,518.80805,0.00000,-0.00003,6.41814
4.20000,0.20938,619.37878,0.00000,-0.00003,7.66230
4.50000,0.22445,734.83456,0.00000,-0.00003,9.09059
4.80000,0.23946,867.84009,0.00000,-0.00003,10.73600
5.10000,0.25440,1002.56251,0.00000,-0.00003,12.40264
5.40000,0.26947,1159.30289,0.00000,-0.00002,14.34167
5.70000,0.28430,1333.34789,0.00000,0.00000,16.49477
6.00000,0.29949,1539.42937,0.00000,0.00002,19.04419
6.30000,0.31425,1763.01692,0.00000,0.00004,21.81018
6.60000,0.32938,1990.25832,0.00000,0.00007,24.62137
6.90000,0.34439,2208.80229,0.00000,0.00010,27.32496
7.20000,0.35933,2428.88294,0.00000,0.00013,30.04757
7.50000,0.37446,2661.61598,0.00000,0.00016,32.92669
7.80000,0.38929,2890.63379,0.00000,0.00020,35.75986
8.10000,0.40442,3125.49807,0.00000,0.00024,38.66535
8.40000,0.41930,3357.24428,0.00000,0.00027,41.53227
8.70000,0.43437,3592.26987,0.00000,0.00031,44.43976
9.00000,0.44932,3824.96528,0.00000,0.00035,47.31842
9.30000,0.46444,4054.63837,0.00000,0.00039,50.15969
9.60000,0.47939,4283.98661,0.00000,0.00042,52.99694
9.90000,0.49434,4508.65738,0.00000,0.00046,55.77633
10.20000,0.50947,4736.35793,0.00000,0.00050,58.59320
10.50000,0.52429,4956.06437,0.00000,0.00054,61.31118
10.80000,0.53942,5181.21757,0.00000,0.00058,64.09653
11.10000,0.55431,5398.92167,0.00000,0.00062,66.78974
11.40000,0.56938,5615.42138,0.00000,0.00065,69.46804
11.70000,0.58438,5828.30757,0.00000,0.00069,72.10164
12.00000,0.59927,6033.43621,0.00000,0.00073,74.63928
12.30000,0.61434,6238.32978,0.00000,0.00076,77.17400
12.60000,0.62934,6420.34709,0.00000,0.00079,79.42573
12.90000,0.64441,6586.07855,0.00000,0.00082,81.47598
13.20000,0.65924,6743.70006,0.00000,0.00085,83.42591
13.50000,0.67443,6906.41627,0.00000,0.00088,85.43886
13.80000,0.68937,7067.63491,0.00000,0.00090,87.43329
14.10000,0.70444,7226.86499,0.00000,0.00093,89.40311
14.40000,0.71939,7385.90211,0.00000,0.00096,91.37055
14.70000,0.73439,7541.27502,0.00000,0.00098,93.29266
15.00000,0.74952,7694.44704,0.00000,0.00101,95.18754
15.30000,0.76423,7838.31775,0.00000,0.00103,96.96736
15.60000,0.77942,7979.20227,0.00000,0.00106,98.71023
15.90000,0.79436,8120.27454,0.00000,0.00108,100.45543
16.20000,0.80937,8260.67105,0.00000,0.00110,102.19227
16.50000,0.82438,8401.01838,0.00000,0.00113,103.92850
16.80000,0.83932,8539.95159,0.00000,0.00115,105.64723
17.10000,0.85439,8684.50701,0.00000,0.00118,107.43552
17.40000,0.86934,8821.06945,0.00000,0.00120,109.12492
17.70000,0.88447,8968.77348,0.00000,0.00122,110.95216
18.00000,0.89929,9106.98250,0.00000,0.00125,112.66194
18.30000,0.91448,9250.10294,0.00000,0.00127,114.43247
18.60000,0.92931,9395.15010,0.00000,0.00130,116.22684
18.90000,0.94438,9536.41832,0.00000,0.00132,117.97446
19.20000,0.95938,9683.77367,0.00000,0.00135,119.79738
19.50000,0.97427,9825.61260,0.00000,0.00137,121.55207
19.80000,0.98946,9972.64758,0.00000,0.00140,123.37103
20.10000,1.00428,10114.13187,0.00000,0.00142,125.12132
20.40000,1.01941,10262.82459,0.00000,0.00145,126.96079
20.70000,1.03430,10407.70337,0.00000,0.00147,128.75308
21.00000,1.04937,10555.24126,0.00000,0.00150,130.57826
21.30000,1.06437,10701.61909,0.00000,0.00152,132.38909
21.60000,1.07938,10845.04128,0.00000,0.00155,134.16336
21.90000,1.09445,10995.55418,0.00000,0.00157,136.02534
22.20000,1.10933,11136.87381,0.00000,0.00160,137.77360
22.50000,1.12446,11287.91720,0.00000,0.00163,139.64215
22.80000,1.13929,11433.67514,0.00000,0.00165,141.44531
23.10000,1.15448,11582.06016,0.00000,0.00168,143.28097
23.40000,1.16936,11728.60488,0.00000,0.00170,145.09387
23.70000,1.18437,11873.35998,0.00000,0.00173,146.88463
24.00000,1.19944,12025.12160,0.00000,0.00176,148.76206
24.30000,1.21426,12170.95107,0.00000,0.00178,150.56611
24.60000,1.22945,12323.31991,0.00000,0.00181,152.45105
24.90000,1.24428,12470.92932,0.00000,0.00184,154.27712
25.20000,1.25941,12622.63358,0.00000,0.00186,156.15384
25.50000,1.27435,12769.39809,0.00000,0.00189,157.96946
25.80000,1.28942,12919.67928,0.00000,0.00192,159.82858
26.10000,1.30437,13071.10190,0.00000,0.00194,161.70182
26.40000,1.31937,13219.00785,0.00000,0.00197,163.53156
26.70000,1.33444,13372.12175,0.00000,0.00200,165.42572
27.00000,1.34933,13517.69418,0.00000,0.00202,167.22659
27.30000,1.36452,13671.67234,0.00000,0.00205,169.13144
27.60000,1.37922,13818.09115,0.00000,0.00208,170.94278
27.90000,1.39447,13970.44808,0.00000,0.00211,172.82758
28.20000,1.40936,14122.08676,0.00000,0.00214,174.70349
28.50000,1.42437,14271.35915,0.00000,0.00217,176.55013
28.80000,1.43943,14425.99744,0.00000,0.00220,178.46315
29.10000,1.45432,14573.02868,0.00000,0.00223,180.28207
29.40000,1.46945,14727.56565,0.00000,0.00225,182.19383
29.70000,1.48427,14876.61898,0.00000,0.00229,184.03776
30.00000,1.49940,15029.14727,0.00000,0.00231,185.92468
30.30000,1.51435,15180.96775,0.00000,0.00235,187.80284
30.60000,1.52942,15331.01350,0.00000,0.00237,189.65905
30.90000,1.54436,15482.86676,0.00000,0.00241,191.53762
31.20000,1.55937,15630.95003,0.00000,0.00244,193.36955
31.50000,1.57444,15784.88350,0.00000,0.00247,195.27385
31.80000,1.58926,15931.81640,0.00000,0.00250,197.09155
32.10000,1.60445,16084.74851,0.00000,0.00253,198.98346
32.40000,1.61934,16233.54554,0.00000,0.00256,200.82422
32.70000,1.63447,16384.25291,0.00000,0.00260,202.68861
33.00000,1.64941,16535.80219,0.00000,0.00263,204.56342
33.30000,1.66436,16683.14487,0.00000,0.00266,206.38619
33.60000,1.67949,16837.46576,0.00000,0.00270,208.29528
33.90000,1.69431,16982.04279,0.00000,0.00272,210.08384
34.20000,1.70938,17131.04844,0.00000,0.00276,211.92718
34.50000,1.72433,17278.91415,0.00000,0.00279,213.75641
34.80000,1.73940,17429.34138,0.00000,0.00283,215.61734
35.10000,1.75434,17574.54127,0.00000,0.00286,217.41360
35.40000,1.76941,17720.66802,0.00000,0.00290,219.22132
35.70000,1.78436,17865.17203,0.00000,0.00293,221.00897
36.00000,1.79942,18004.93449,0.00000,0.00296,222.73797
36.30000,1.81449,18149.65755,0.00000,0.00301,224.52833
36.60000,1.82932,18286.46362,0.00000,0.00304,226.22075
36.90000,1.84445,18429.94839,0.00000,0.00308,227.99579
37.20000,1.85927,18565.00357,0.00000,0.00312,229.66655
37.50000,1.87440,18700.87385,0.00000,0.00316,231.34739
37.80000,1.88941,18835.19441,0.00000,0.00320,233.00906
38.10000,1.90430,18962.34602,0.00000,0.00324,234.58205
38.40000,1.91948,19096.52650,0.00000,0.00329,236.24199
38.70000,1.93431,19219.87534,0.00000,0.00333,237.76793
39.00000,1.94944,19345.14195,0.00000,0.00339,239.31759
39.30000,1.96432,19461.50661,0.00000,0.00343,240.75713
39.60000,1.97933,19578.26912,0.00000,0.00349,242.20160
39.90000,1.99434,19690.76097,0.00000,0.00354,243.59323
40.20000,2.00946,19800.37987,0.00000,0.00360,244.94931
40.50000,2.02435,19906.22729,0.00000,0.00366,246.25875
40.80000,2.03936,20003.02821,0.00000,0.00373,247.45627
41.10000,2.05449,20101.62920,0.00000,0.00379,248.67605
41.40000,2.06925,20186.11431,0.00000,0.00386,249.72121
41.70000,2.08450,20278.88596,0.00000,0.00393,250.86888
42.00000,2.09927,20355.80277,0.00000,0.00400,251.82042
42.30000,2.11440,20429.38769,0.00000,0.00408,252.73073
42.60000,2.12940,20500.54520,0.00000,0.00416,253.61102
42.90000,2.14429,20560.23777,0.00000,0.00425,254.34947
43.20000,2.15948,20620.58002,0.00000,0.00434,255.09596
43.50000,2.17430,20668.69438,0.00000,0.00443,255.69118
43.80000,2.18943,20717.35859,0.00000,0.00454,256.29320
44.10000,2.20432,20759.26065,0.00000,0.00465,256.81157
44.40000,2.21945,20799.68750,0.00000,0.00476,257.31169
44.70000,2.23433,20834.22989,0.00000,0.00487,257.73901
45.00000,2.24946,20868.32970,0.00000,0.00499,258.16086
45.30000,2.26441,20902.79758,0.00000,0.00511,258.58726
45.60000,2.27935,20927.67358,0.00000,0.00524,258.89500
45.90000,2.29448,20958.59051,0.00000,0.00537,259.27747
46.20000,2.30925,20978.94400,0.00000,0.00551,259.52926
46.50000,2.32450,21005.92405,0.00000,0.00565,259.86303
46.80000,2.33932,21025.91991,0.00000,0.00578,260.11040
47.10000,2.35433,21045.40616,0.00000,0.00592,260.35146
47.40000,2.36934,21068.48061,0.00000,0.00607,260.63691
47.70000,2.38435,21086.84480,0.00000,0.00621,260.86410
48.00000,2.39947,21105.95405,0.00000,0.00636,261.10049
48.30000,2.41436,21119.57222,0.00000,0.00650,261.26896
48.60000,2.42943,21138.00049,0.00000,0.00666,261.49694
48.90000,2.44443,21152.44269,0.00000,0.00681,261.67560
49.20000,2.45944,21169.17372,0.00000,0.00697,261.88258
49.50000,2.47427,21180.77278,0.00000,0.00712,262.02607
49.80000,2.48951,21195.89448,0.00000,0.00727,262.21314
50.10000,2.50434,21210.48421,0.00000,0.00743,262.39363
50.40000,2.51935,21219.73783,0.00000,0.00759,262.50811
50.70000,2.53448,21236.83244,0.00000,0.00775,262.71958
51.00000,2.54924,21245.77612,0.00000,0.00791,262.83023
51.30000,2.56449,21260.62363,0.00000,0.00807,263.01390
51.60000,2.57932,21271.42102,0.00000,0.00823,263.14748
51.90000,2.59445,21280.95925,0.00000,0.00839,263.26547
52.20000,2.60945,21294.69663,0.00000,0.00856,263.43542
52.50000,2.62440,21303.09194,0.00000,0.00872,263.53928
52.80000,2.63953,21315.18573,0.00000,0.00888,263.68889
53.10000,2.65435,21324.52875,0.00000,0.00904,263.80447
53.40000,2.66942,21336.58081,0.00000,0.00921,263.95356
53.70000,2.68437,21344.20872,0.00000,0.00937,264.04793
54.00000,2.69944,21356.31293,0.00000,0.00953,264.19767
54.30000,2.71432,21365.08971,0.00000,0.00969,264.30625
54.60000,2.72945,21374.58473,0.00000,0.00986,264.42371
54.90000,2.74440,21388.29976,0.00000,0.01002,264.59338
55.20000,2.75934,21391.74938,0.00000,0.01018,264.63605
55.50000,2.77453,21405.30050,0.00000,0.01035,264.80369
55.80000,2.78924,21411.12238,0.00000,0.01051,264.87571
56.10000,2.80443,21422.48899,0.00000,0.01067,265.01633
56.40000,2.81931,21431.61595,0.00000,0.01084,265.12924
56.70000,2.83438,21439.29005,0.00000,0.01100,265.22417
57.00000,2.84945,21449.20826,0.00000,0.01116,265.34687
57.30000,2.86439,21455.43396,0.00000,0.01131,265.42389
57.60000,2.87952,21466.59195,0.00000,0.01147,265.56192
57.90000,2.89435,21473.25873,0.00000,0.01163,265.64440
58.20000,2.90942,21486.17506,0.00000,0.01180,265.80419
58.50000,2.92442,21491.88817,0.00000,0.01196,265.87486
58.80000,2.93949,21502.47246,0.00000,0.01213,266.00580
59.10000,2.95432,21508.77416,0.00000,0.01228,266.08376
59.40000,2.96945,21516.52724,0.00000,0.01244,266.17967
59.70000,2.98445,21529.30647,0.00000,0.01260,266.33776
60.00000,2.99928,21532.69947,0.00000,0.01275,266.37974
60.30000,3.01447,21544.55930,0.00000,0.01292,266.52645
60.60000,3.02929,21549.42304,0.00000,0.01308,266.58662
60.90000,3.04448,21558.98809,0.00000,0.01324,266.70495
61.20000,3.05943,21568.43096,0.00000,0.01340,266.82177
61.50000,3.07438,21574.12618,0.00000,0.01355,266.89222
61.80000,3.08950,21585.30802,0.00000,0.01371,267.03055
62.10000,3.10439,21590.42805,0.00000,0.01387,267.09389
62.40000,3.11946,21598.65201,0.00000,0.01402,267.19563
62.70000,3.13434,21603.97172,0.00000,0.01417,267.26144
63.00000,3.14947,21617.33806,0.00000,0.01433,267.42680
63.30000,3.16436,21620.37492,0.00000,0.01448,267.46436
63.60000,3.17943,21632.35694,0.00000,0.01464,267.61259
63.90000,3.19431,21639.34261,0.00000,0.01480,267.69901
64.20000,3.20950,21645.46251,0.00000,0.01496,267.77472
64.50000,3.22445,21656.47149,0.00000,0.01512,267.91091
64.80000,3.23927,21658.86909,0.00000,0.01527,267.94057
65.10000,3.25452,21671.44716,0.00000,0.01542,268.09618
65.40000,3.26929,21674.32308,0.00000,0.01557,268.13175
65.70000,3.28442,21684.81350,0.00000,0.01572,268.26153
66.00000,3.29936,21692.90483,0.00000,0.01587,268.36163
66.30000,3.31443,21699.28104,0.00000,0.01603,268.44051
66.60000,3.32950,21708.88484,0.00000,0.01618,268.55932
66.90000,3.34439,21714.52940,0.00000,0.01634,268.62914
67.20000,3.35945,21724.63089,0.00000,0.01649,268.75411
67.50000,3.37440,21729.29645,0.00000,0.01664,268.81183
67.80000,3.38947,21739.60954,0.00000,0.01679,268.93941
68.10000,3.40435,21744.05754,0.00000,0.01694,268.99443
68.40000,3.41948,21752.53779,0.00000,0.01709,269.09934
68.70000,3.43431,21760.65892,0.00000,0.01724,269.19981
69.00000,3.44938,21765.28722,0.00000,0.01739,269.25707
69.30000,3.46438,21776.25746,0.00000,0.01754,269.39278
69.60000,3.47933,21779.89632,0.00000,0.01770,269.43779
69.90000,3.49446,21789.05606,0.00000,0.01784,269.55111
70.20000,3.50928,21795.23557,0.00000,0.01800,269.62756
70.50000,3.52441,21803.22409,0.00000,0.01815,269.72638
70.80000,3.53942,21811.72222,0.00000,0.01829,269.83151
71.10000,3.55443,21818.24297,0.00000,0.01844,269.91218
71.40000,3.56949,21826.40284,0.00000,0.01859,270.01312
71.70000,3.58444,21831.40814,0.00000,0.01873,270.07504
72.00000,3.59945,21839.33109,0.00000,0.01888,270.17306
72.30000,3.61427,21844.81770,0.00000,0.01904,270.24093
72.60000,3.62940,21856.67902,0.00000,0.01919,270.38767
72.90000,3.64435,21859.76505,0.00000,0.01934,270.42585
73.20000,3.65948,21868.09033,0.00000,0.01949,270.52884
73.50000,3.67436,21874.82864,0.00000,0.01963,270.61220
73.80000,3.68937,21877.35885,0.00000,0.01978,270.64350
74.10000,3.70450,21892.89480,0.00000,0.01993,270.83569
74.40000,3.71927,21895.27154,0.00000,0.02008,270.86509
74.70000,3.73451,21903.28091,0.00000,0.02022,270.96418
75.00000,3.74934,21910.08627,0.00000,0.02037,271.04837
75.30000,3.76441,21914.78312,0.00000,0.02052,271.10647
75.60000,3.77935,21923.03836,0.00000,0.02066,271.20860
75.90000,3.79436,21931.08797,0.00000,0.02081,271.30818
76.20000,3.80943,21940.84227,0.00000,0.02095,271.42885
76.50000,3.82437,21945.14126,0.00000,0.02110,271.48203
76.80000,3.83944,21952.34597,0.00000,0.02125,271.57116
77.10000,3.85433,21957.41236,0.00000,0.02140,271.63383
77.40000,3.86946,21966.15636,0.00000,0.02154,271.74201
77.70000,3.88428,21970.82341,0.00000,0.02168,271.79974
78.00000,3.89947,21980.48979,0.00000,0.02183,271.91932
78.30000,3.91436,21985.03762,0.00000,0.02198,271.97559
78.60000,3.92943,21989.63910,0.00000,0.02212,272.03251
78.90000,3.94449,21999.60649,0.00000,0.02227,272.15582
79.20000,3.95926,22000.25916,0.00000,0.02241,272.16389
79.50000,3.97451,22013.41093,0.00000,0.02256,272.32659
79.80000,3.98933,22018.26125,0.00000,0.02270,272.38659
80.10000,4.00440,22024.78796,0.00000,0.02284,272.46733
80.40000,4.01947,22031.32808,0.00000,0.02298,272.54824
80.70000,4.03442,22036.73720,0.00000,0.02313,272.61516
81.00000,4.04942,22044.86728,0.00000,0.02328,272.71573
81.30000,4.06431,22048.47634,0.00000,0.02341,272.76038
81.60000,4.07944,22058.61360,0.00000,0.02356,272.88579
81.90000,4.09432,22060.90391,0.00000,0.02370,272.91412
82.20000,4.10939,22070.15753,0.00000,0.02384,273.02860
82.50000,4.12428,22074.77391,0.00000,0.02398,273.08571
82.80000,4.13947,22082.26174,0.00000,0.02413,273.17834
83.10000,4.15441,22091.81935,0.00000,0.02427,273.29658
83.40000,4.16942,22093.28264,0.00000,0.02442,273.31468
83.70000,4.18455,22103.47652,0.00000,0.02456,273.44079
84.00000,4.19931,22105.64315,0.00000,0.02470,273.46759
84.30000,4.21456,22115.20821,0.00000,0.02484,273.58592
84.60000,4.22933,22120.46236,0.00000,0.02497,273.65092
84.90000,4.24440,22128.19606,0.00000,0.02512,273.74659
85.20000,4.25940,22134.46051,0.00000,0.02526,273.82409
85.50000,4.27441,22139.65207,0.00000,0.02541,273.88831
85.80000,4.28942,22146.61539,0.00000,0.02555,273.97445
86.10000,4.30436,22150.83688,0.00000,0.02569,274.02668
86.40000,4.31943,22158.57953,0.00000,0.02582,274.12246
86.70000,4.33432,22160.90560,0.00000,0.02597,274.15124
87.00000,4.34945,22172.83398,0.00000,0.02611,274.29880
87.30000,4.36433,22174.99167,0.00000,0.02625,274.32550
87.60000,4.37946,22181.35297,0.00000,0.02639,274.40419
87.90000,4.39435,22189.47411,0.00000,0.02653,274.50466
88.20000,4.40942,22191.01489,0.00000,0.02666,274.52372
88.50000,4.42454,22201.24006,0.00000,0.02680,274.65021
88.80000,4.43925,22203.19360,0.00000,0.02694,274.67438
89.10000,4.45456,22213.70786,0.00000,0.02708,274.80445
89.40000,4.46938,22215.57796,0.00000,0.02722,274.82759
89.70000,4.48445,22222.32819,0.00000,0.02737,274.91109
90.00000,4.49940,22229.89351,0.00000,0.02750,275.00468
90.30000,4.51441,22235.65429,0.00000,0.02764,275.07595
90.60000,4.52941,22241.76526,0.00000,0.02778,275.15155
90.90000,4.54430,22244.56221,0.00000,0.02791,275.18615
91.20000,4.55937,22252.17223,0.00000,0.02804,275.28029
91.50000,4.57437,22254.86040,0.00000,0.02818,275.31355
91.80000,4.58944,22263.67146,0.00000,0.02832,275.42255
92.10000,4.60433,22268.24164,0.00000,0.02846,275.47908
92.40000,4.61946,22274.44202,0.00000,0.02861,275.55579
92.70000,4.63440,22282.79114,0.00000,0.02874,275.65908
93.00000,4.64947,22284.27678,0.00000,0.02887,275.67745
93.30000,4.66454,22294.06536,0.00000,0.02901,275.79855
93.60000,4.67931,22297.18417,0.00000,0.02914,275.83713
93.90000,4.69455,22305.36640,0.00000,0.02928,275.93835
94.20000,4.70932,22307.86830,0.00000,0.02942,275.96930
94.50000,4.72439,22313.94351,0.00000,0.02955,276.04446
94.80000,4.73939,22319.80264,0.00000,0.02969,276.11694
95.10000,4.75440,22323.60095,0.00000,0.02982,276.16393
95.40000,4.76941,22331.88003,0.00000,0.02996,276.26635
95.70000,4.78430,22334.84089,0.00000,0.03010,276.30298
96.00000,4.79942,22343.64003,0.00000,0.03023,276.41183
96.30000,4.81437,22345.23743,0.00000,0.03037,276.43160
96.60000,4.82944,22351.71348,0.00000,0.03050,276.51171
96.90000,4.84438,22357.78421,0.00000,0.03064,276.58681
97.20000,4.85951,22363.27678,0.00000,0.03077,276.65476
97.50000,4.87440,22370.59176,0.00000,0.03090,276.74525
97.80000,4.88935,22372.14148,0.00000,0.03103,276.76442
98.10000,4.90453,22380.32371,0.00000,0.03117,276.86565
98.40000,4.91930,22382.26384,0.00000,0.03130,276.88965
98.70000,4.93449,22389.16457,0.00000,0.03144,276.97502
99.00000,4.94937,22394.94622,0.00000,0.03158,277.04654
99.30000,4.96438,22398.67449,0.00000,0.03171,277.09266
99.60000,4.97939,22404.08808,0.00000,0.03184,277.15963
99.90000,4.99434,22406.98487,0.00000,0.03197,277.19547
100.20000,5.00946,22414.72006,0.00000,0.03210,277.29116
100.50000,5.02435,22417.40823,0.00000,0.03224,277.32442
100.80000,5.03942,22424.56079,0.00000,0.03237,277.41290
101.10000,5.05430,22428.67351,0.00000,0.03250,277.46378
101.40000,5.06949,22435.59211,0.00000,0.03263,277.54937
101.70000,5.08438,22439.65268,0.00000,0.03276,277.59960
102.00000,5.09951,22444.38976,0.00000,0.03290,277.65820
102.30000,5.11445,22451.32178,0.00000,0.03303,277.74396
102.60000,5.12934,22452.51089,0.00000,0.03316,277.75867
102.90000,5.14447,22462.94171,0.00000,0.03329,277.88771
103.20000,5.15923,22463.51838,0.00000,0.03343,277.89484
103.50000,5.17448,22471.34000,0.00000,0.03356,277.99160
103.80000,5.18931,22473.29503,0.00000,0.03369,278.01579
104.10000,5.20438,22478.38080,0.00000,0.03382,278.07870
104.40000,5.21938,22483.24603,0.00000,0.03395,278.13889
104.70000,5.23433,22487.61803,0.00000,0.03408,278.19298
105.00000,5.24946,22493.35647,0.00000,0.03421,278.26397
105.30001,5.26435,22495.96715,0.00000,0.03434,278.29626
105.60001,5.27947,22503.70830,0.00000,0.03447,278.39203
105.90001,5.29436,22505.72294,0.00000,0.03460,278.41695
106.20001,5.30943,22514.43565,0.00000,0.03474,278.52474
106.50001,5.32431,22517.91358,0.00000,0.03487,278.56776
106.80001,5.33950,22522.66556,0.00000,0.03500,278.62655
107.10001,5.35439,22528.42784,0.00000,0.03512,278.69783
107.40001,5.36934,22528.04339,0.00000,0.03525,278.69308
107.70001,5.38446,22536.14962,0.00000,0.03538,278.79336
108.00001,5.39929,22538.81395,0.00000,0.03551,278.82632
108.30001,5.41448,22545.60590,0.00000,0.03565,278.91034
108.60001,5.42936,22549.11363,0.00000,0.03578,278.95374
108.90001,5.44437,22551.74965,0.00000,0.03590,278.98635
109.20001,5.45950,22559.03631,0.00000,0.03603,279.07649
109.50001,5.47445,22560.00638,0.00000,0.03616,279.08849
109.80001,5.48939,22565.80889,0.00000,0.03629,279.16027
110.10001,5.50440,22569.77558,0.00000,0.03641,279.20934
110.40001,5.51947,22576.65098,0.00000,0.03654,279.29440
110.70001,5.53429,22577.27087,0.00000,0.03668,279.30207
111.00001,5.54948,22584.12093,0.00000,0.03681,279.38681
111.30001,5.56437,22589.59562,0.00000,0.03693,279.45454
111.60001,5.57938,22591.55810,0.00000,0.03706,279.47881
111.90001,5.59438,22600.62993,0.00000,0.03719,279.59104
112.20001,5.60933,22599.51085,0.00000,0.03731,279.57720
112.50001,5.62452,22605.85874,0.00000,0.03744,279.65573
112.80001,5.63929,22606.42946,0.00000,0.03757,279.66279
113.10001,5.65441,22611.90712,0.00000,0.03770,279.73055
113.40001,5.66942,22618.30717,0.00000,0.03783,279.80972
113.70001,5.68437,22620.56470,0.00000,0.03796,279.83765
114.00001,5.69943,22626.58179,0.00000,0.03808,279.91209
114.30001,5.71438,22628.26562,0.00000,0.03821,279.93292
114.60001,5.72945,22634.69547,0.00000,0.03833,280.01246
114.90001,5.74445,22637.65782,0.00000,0.03846,280.04911
115.20001,5.75946,22645.16950,0.00000,0.03859,280.14204
115.50001,5.77429,22644.89979,0.00000,0.03872,280.13870
115.80001,5.78954,22652.54706,0.00000,0.03885,280.23330
116.10001,5.80430,22654.89548,0.00000,0.03898,280.26236
116.40001,5.81937,22657.03678,0.00000,0.03910,280.28885
116.70001,5.83444,22665.36057,0.00000,0.03923,280.39182
117.00001,5.84933,22665.31140,0.00000,0.03935,280.39121
117.30001,5.86451,22672.00053,0.00000,0.03948,280.47396
117.60001,5.87928,22674.07328,0.00000,0.03961,280.49960
117.90001,5.89441,22679.63439,0.00000,0.03974,280.56840
118.20001,5.90947,22683.90805,0.00000,0.03987,280.62127
118.50001,5.92436,22686.34886,0.00000,0.03999,280.65146
118.80001,5.93949,22692.92474,0.00000,0.04012,280.73281
119.10001,5.95444,22695.98842,0.00000,0.04024,280.77071
119.40001,5.96944,22701.07567,0.00000,0.04037,280.83365
119.70001,5.98439,22701.30217,0.00000,0.04049,280.83645
120.00001,5.99952,22709.75709,0.00000,0.04062,280.94105
120.30001,6.01423,22707.22985,0.00000,0.04075,280.90978
120.60001,6.02947,22717.04376,0.00000,0.04088,281.03119
120.90001,6.04430,22719.90478,0.00000,0.04101,281.06658
121.20001,6.05943,22720.97468,0.00000,0.04113,281.07982
121.50001,6.07449,22729.30443,0.00000,0.04126,281.18287
121.80001,6.08926,22726.93962,0.00000,0.04138,281.15361
122.10001,6.10451,22735.53461,0.00000,0.04151,281.25994
122.40001,6.11927,22737.62524,0.00000,0.04163,281.28580
122.70001,6.13434,22741.87058,0.00000,0.04176,281.33832
123.00001,6.14941,22746.05930,0.00000,0.04189,281.39014
123.30001,6.16442,22750.25100,0.00000,0.04202,281.44199
123.60001,6.17942,22752.77078,0.00000,0.04214,281.47317
123.90001,6.19443,22755.15050,0.00000,0.04227,281.50261
124.20001,6.20944,22762.54892,0.00000,0.04240,281.59413
124.50001,6.22444,22763.76486,0.00000,0.04252,281.60917
124.80001,6.23951,22770.34819,0.00000,0.04265,281.69062
125.10001,6.25428,22769.72383,0.00000,0.04278,281.68289
125.40001,6.26953,22773.77844,0.00000,0.04291,281.73305
125.70001,6.28435,22778.48870,0.00000,0.04303,281.79132
126.00001,6.29936,22780.46608,0.00000,0.04316,281.81578
126.30001,6.31443,22786.87805,0.00000,0.04328,281.89510
126.60001,6.32926,22786.29988,0.00000,0.04340,281.88795
126.90001,6.34450,22792.27376,0.00000,0.04353,281.96185
127.20001,6.35933,22794.01720,0.00000,0.04365,281.98342
127.50001,6.37440,22798.46966,0.00000,0.04378,282.03850
127.80001,6.38946,22802.53321,0.00000,0.04392,282.08877
128.10001,6.40447,22806.83964,0.00000,0.04405,282.14205
128.40001,6.41948,22808.35956,0.00000,0.04417,282.16085
128.70001,6.43443,22809.07333,0.00000,0.04430,282.16968
129.00001,6.44937,22814.66722,0.00000,0.04442,282.23888
129.30001,6.46432,22816.01429,0.00000,0.04455,282.25555
129.60001,6.47945,22822.29066,0.00000,0.04467,282.33319
129.90001,6.49427,22822.25192,0.00000,0.04480,282.33271
130.20001,6.50946,22827.90244,0.00000,0.04493,282.40262
130.50001,6.52435,22830.83946,0.00000,0.04505,282.43895
130.80001,6.53930,22829.36871,0.00000,0.04518,282.42075
131.10001,6.55448,22838.09483,0.00000,0.04531,282.52870
131.40001,6.56925,22837.43918,0.00000,0.04543,282.52059
131.70001,6.58450,22842.94516,0.00000,0.04556,282.58871
132.00001,6.59938,22845.08497,0.00000,0.04568,282.61518
132.30001,6.61439,22847.18007,0.00000,0.04581,282.64110
132.60001,6.62940,22850.47323,0.00000,0.04594,282.68184
132.90001,6.64441,22853.68890,0.00000,0.04606,282.72162
133.20001,6.65941,22857.99384,0.00000,0.04618,282.77487
133.50001,6.67436,22857.92381,0.00000,0.04631,282.77401
133.80001,6.68943,22862.87993,0.00000,0.04643,282.83532
134.10001,6.70432,22860.54939,0.00000,0.04655,282.80649
134.40001,6.71950,22869.66592,0.00000,0.04668,282.91927
134.70001,6.73427,22868.26372,0.00000,0.04680,282.90192
135.00001,6.74940,22870.66579,0.00000,0.04693,282.93164
135.30001,6.76440,22877.41750,0.00000,0.04705,283.01516
135.60001,6.77929,22874.49539,0.00000,0.04717,282.97901
135.90001,6.79448,22881.51830,0.00000,0.04730,283.06589
136.20001,6.80931,22881.94001,0.00000,0.04741,283.07111
136.50001,6.82449,22886.99895,0.00000,0.04753,283.13369
136.80001,6.83938,22889.25052,0.00000,0.04765,283.16155
137.10001,6.85439,22891.88206,0.00000,0.04776,283.19410
137.40001,6.86945,22895.72656,0.00000,0.04788,283.24166
137.70001,6.88446,22895.14244,0.00000,0.04800,283.23444
138.00001,6.89941,22900.88236,0.00000,0.04813,283.30545
138.30001,6.91436,22900.29675,0.00000,0.04824,283.29820
138.60001,6.92942,22906.02475,0.00000,0.04837,283.36906
138.90001,6.94431,22905.21711,0.00000,0.04848,283.35907
139.20001,6.95944,22909.61593,0.00000,0.04860,283.41349
139.50001,6.97426,22909.30748,0.00000,0.04871,283.40967
139.80001,6.98951,22914.24423,0.00000,0.04883,283.47074
140.10001,7.00440,22919.02602,0.00000,0.04895,283.52990
140.40001,7.01935,22918.91724,0.00000,0.04907,283.52855
140.70001,7.03453,22925.16083,0.00000,0.04918,283.60579
141.00001,7.04936,22925.41713,0.00000,0.04930,283.60896
141.30001,7.06449,22927.63740,0.00000,0.04941,283.63643
141.60001,7.07937,22929.43448,0.00000,0.04953,283.65866
141.90001,7.09444,22934.63796,0.00000,0.04965,283.72303
142.20001,7.10933,22935.88519,0.00000,0.04976,283.73846
142.50001,7.12440,22937.94304,0.00000,0.04988,283.76392
142.80001,7.13940,22942.16007,0.00000,0.05000,283.81609
143.10001,7.15441,22940.76234,0.00000,0.05011,283.79880
143.40001,7.16948,22946.89566,0.00000,0.05023,283.87467
143.70001,7.18431,22945.60224,0.00000,0.05034,283.85867
144.00001,7.19943,22951.83986,0.00000,0.05046,283.93584
144.30001,7.21432,22954.51313,0.00000,0.05057,283.96891
144.60001,7.22945,22955.78271,0.00000,0.05069,283.98461
144.90001,7.24445,22960.17408,0.00000,0.05080,284.03894
145.20001,7.25934,22959.34111,0.00000,0.05092,284.02864
145.50001,7.27447,22964.25551,0.00000,0.05104,284.08943
145.80001,7.28930,22966.12114,0.00000,0.05116,284.11251
146.10001,7.30448,22969.53499,0.00000,0.05127,284.15474
146.40001,7.31943,22971.03405,0.00000,0.05139,284.17329
146.70001,7.33450,22972.74023,0.00000,0.05150,284.19439
147.00001,7.34938,22972.79090,0.00000,0.05161,284.19502
147.30001,7.36451,22977.91094,0.00000,0.05173,284.25836
147.60001,7.37940,22978.53231,0.00000,0.05184,284.26605
147.90001,7.39435,22978.39373,0.00000,0.05195,284.26433
148.20001,7.40947,22983.46758,0.00000,0.05207,284.32710
148.50001,7.42436,22982.53626,0.00000,0.05219,284.31558
148.80001,7.43949,22988.08396,0.00000,0.05231,284.38421
149.10001,7.45431,22990.92859,0.00000,0.05242,284.41940
149.40001,7.46950,22992.10280,0.00000,0.05253,284.43393
149.70001,7.48445,22996.48225,0.00000,0.05264,284.48811
150.00001,7.49940,22994.99810,0.00000,0.05275,284.46975
150.30001,7.51452,23000.41020,0.00000,0.05287,284.53670
150.60001,7.52935,22999.48335,0.00000,0.05298,284.52523
150.90001,7.54448,23004.01479,0.00000,0.05309,284.58129
151.20001,7.55936,23004.86267,0.00000,0.05321,284.59178
151.50001,7.57437,23005.51087,0.00000,0.05332,284.59980
151.80001,7.58938,23007.98297,0.00000,0.05344,284.63038
152.10001,7.60439,23007.50315,0.00000,0.05355,284.62444
152.40001,7.61939,23012.61574,0.00000,0.05366,284.68769
152.70001,7.63434,23013.01360,0.00000,0.05377,284.69261
153.00001,7.64947,23018.95618,0.00000,0.05388,284.76613
153.30001,7.66436,23019.16629,0.00000,0.05399,284.76873
153.60001,7.67942,23021.95728,0.00000,0.05411,284.80326
153.90001,7.69431,23023.99874,0.00000,0.05422,284.82851
154.20001,7.70950,23025.28918,0.00000,0.05433,284.84447
154.50001,7.72438,23028.25302,0.00000,0.05445,284.88114
154.80001,7.73933,23028.80436,0.00000,0.05456,284.88796
155.10001,7.75452,23033.97506,0.00000,0.05467,284.95193
155.40001,7.76929,23031.63111,0.00000,0.05478,284.92293
155.70001,7.78447,23036.51124,0.00000,0.05490,284.98330
156.00001,7.79936,23036.80032,0.00000,0.05502,284.98688
156.30001,7.81443,23040.32147,0.00000,0.05513,285.03044
156.60001,7.82937,23042.66095,0.00000,0.05524,285.05938
156.90001,7.84432,23041.95911,0.00000,0.05536,285.05070
157.20001,7.85945,23048.59757,0.00000,0.05548,285.13282
157.50001,7.87434,23045.67397,0.00000,0.05559,285.09665
157.80001,7.88940,23051.72235,0.00000,0.05570,285.17148
158.10001,7.90429,23051.47201,0.00000,0.05581,285.16838
158.40001,7.91954,23056.96011,0.00000,0.05592,285.23627
158.70001,7.93436,23057.81245,0.00000,0.05604,285.24682
159.00001,7.94943,23055.31055,0.00000,0.05616,285.21587
159.30001,7.96450,23062.44820,0.00000,0.05627,285.30417
159.60001,7.97933,23060.43357,0.00000,0.05639,285.27924
159.90001,7.99451,23064.08733,0.00000,0.05651,285.32444
160.20001,8.00928,23064.41218,0.00000,0.05663,285.32846
160.50001,8.02447,23067.73216,0.00000,0.05674,285.36953
160.80001,8.03935,23067.23297,0.00000,0.05685,285.36336
161.10001,8.05436,23067.95418,0.00000,0.05697,285.37228
161.40001,8.06931,23070.34433,0.00000,0.05708,285.40185
161.70001,8.08438,23072.03412,0.00000,0.05720,285.42275
162.00001,8.09944,23078.41480,0.00000,0.05732,285.50169
162.30001,8.11433,23075.26767,0.00000,0.05743,285.46276
162.60001,8.12952,23079.08386,0.00000,0.05755,285.50997
162.90001,8.14429,23077.72934,0.00000,0.05766,285.49321
163.20001,8.15947,23083.00436,0.00000,0.05778,285.55847
163.50001,8.17430,23083.18168,0.00000,0.05789,285.56066
163.80001,8.18943,23084.54663,0.00000,0.05802,285.57755
164.10001,8.20443,23086.64024,0.00000,0.05813,285.60345
164.40001,8.21926,23083.77177,0.00000,0.05825,285.56796
164.70001,8.23451,23089.00356,0.00000,0.05836,285.63268
165.00001,8.24934,23088.79048,0.00000,0.05848,285.63005
165.30001,8.26440,23092.57984,0.00000,0.05859,285.67692
165.60001,8.27935,23093.57077,0.00000,0.05871,285.68918
165.90001,8.29436,23094.31136,0.00000,0.05882,285.69834
166.20001,8.30942,23098.28997,0.00000,0.05893,285.74756
166.50001,8.32443,23096.50183,0.00000,0.05905,285.72544
166.80001,8.33944,23100.81571,0.00000,0.05917,285.77881
167.10001,8.35439,23099.52229,0.00000,0.05929,285.76281
167.40001,8.36951,23103.55157,0.00000,0.05941,285.81265
167.70001,8.38428,23102.82588,0.00000,0.05953,285.80368
168.00001,8.39953,23107.09655,0.00000,0.05964,285.85651
168.30001,8.41435,23106.26656,0.00000,0.05976,285.84624
168.60001,8.42942,23108.17391,0.00000,0.05987,285.86984
168.90001,8.44449,23111.51326,0.00000,0.05998,285.91115
169.20001,8.45932,23108.93685,0.00000,0.06010,285.87928
169.50001,8.47450,23112.48332,0.00000,0.06022,285.92315
169.80001,8.48933,23110.49551,0.00000,0.06033,285.89856
170.10001,8.50440,23115.18937,0.00000,0.06045,285.95662
170.40001,8.51940,23117.10417,0.00000,0.06057,285.98031
170.70001,8.53441,23119.51816,0.00000,0.06068,286.01018
171.00001,8.54936,23119.36170,0.00000,0.06080,286.00824
171.30001,8.56443,23119.93092,0.00000,0.06091,286.01528
171.60001,8.57949,23123.92741,0.00000,0.06103,286.06472
171.90001,8.59438,23120.69982,0.00000,0.06115,286.02479
172.20001,8.60951,23126.65582,0.00000,0.06127,286.09848
172.50001,8.62434,23124.09729,0.00000,0.06138,286.06682
172.80001,8.63946,23126.77503,0.00000,0.06150,286.09995
173.10001,8.65435,23127.45750,0.00000,0.06161,286.10839
173.40001,8.66942,23125.39667,0.00000,0.06172,286.08290
173.70001,8.68448,23131.49273,0.00000,0.06184,286.15831
174.00001,8.69931,23129.07279,0.00000,0.06195,286.12838
174.30001,8.71450,23133.04245,0.00000,0.06207,286.17748
174.60001,8.72933,23132.67738,0.00000,0.06218,286.17297
174.90001,8.74439,23135.73658,0.00000,0.06230,286.21081
175.20001,8.75946,23137.21329,0.00000,0.06242,286.22908
175.50001,8.77441,23136.65897,0.00000,0.06254,286.22222
175.80001,8.78941,23138.44860,0.00000,0.06265,286.24436
176.10001,8.80448,23138.21316,0.00000,0.06277,286.24145
176.40001,8.81943,23141.59274,0.00000,0.06288,286.28326
176.70001,8.83432,23137.70801,0.00000,0.06299,286.23520
177.00001,8.84950,23141.72983,0.00000,0.06310,286.28496
177.30001,8.86427,23139.48423,0.00000,0.06321,286.25717
177.60001,8.87946,23141.50184,0.00000,0.06333,286.28213
177.90001,8.89434,23145.27035,0.00000,0.06344,286.32875
178.20001,8.90935,23142.82060,0.00000,0.06356,286.29845
178.50001,8.92448,23147.09872,0.00000,0.06368,286.35137
178.80001,8.93931,23144.60576,0.00000,0.06379,286.32053
179.10001,8.95449,23149.02097,0.00000,0.06390,286.37515
179.40001,8.96932,23148.76467,0.00000,0.06401,286.37198
179.70001,8.98433,23150.74056,0.00000,0.06412,286.39643
180.00001,8.99939,23152.62258,0.00000,0.06423,286.41971
180.30001,9.01446,23152.24409,0.00000,0.06434,286.41503
180.60001,9.02941,23152.74626,0.00000,0.06446,286.42124
180.90001,9.04448,23153.41979,0.00000,0.06457,286.42957
181.20001,9.05948,23156.67719,0.00000,0.06468,286.46987
181.50001,9.07431,23154.76388,0.00000,0.06480,286.44620
181.80001,9.08956,23159.97034,0.00000,0.06491,286.51061
182.10001,9.10426,23156.14522,0.00000,0.06502,286.46329
182.40001,9.11951,23157.42970,0.00000,0.06513,286.47918
182.70001,9.13434,23159.84964,0.00000,0.06524,286.50911
183.00001,9.14929,23157.58318,0.00000,0.06535,286.48108
183.30001,9.16441,23162.30237,0.00000,0.06547,286.53946
183.60001,9.17924,23161.76146,0.00000,0.06558,286.53277
183.90001,9.19443,23162.33814,0.00000,0.06569,286.53990
184.20001,9.20938,23163.05190,0.00000,0.06580,286.54873
184.50001,9.22444,23165.72368,0.00000,0.06591,286.58178
184.80001,9.23939,23164.39450,0.00000,0.06602,286.56534
185.10001,9.25452,23165.57467,0.00000,0.06613,286.57994
185.40001,9.26934,23164.81471,0.00000,0.06624,286.57054
185.70001,9.28447,23163.82378,0.00000,0.06635,286.55828
186.00001,9.29948,23168.27923,0.00000,0.06647,286.61340
186.30001,9.31425,23163.38718,0.00000,0.06658,286.55288
186.60001,9.32949,23168.54745,0.00000,0.06669,286.61671
186.90001,9.34432,23168.32393,0.00000,0.06680,286.61395
187.20001,9.35939,23167.87541,0.00000,0.06691,286.60840
187.50001,9.37439,23170.67385,0.00000,0.06702,286.64302
187.80001,9.38928,23168.11234,0.00000,0.06712,286.61133
188.10001,9.40453,23172.50222,0.00000,0.06723,286.66564
188.40001,9.41936,23171.25797,0.00000,0.06734,286.65025
188.70001,9.43442,23172.67060,0.00000,0.06746,286.66772
189.00001,9.44937,23172.59610,0.00000,0.06757,286.66680
189.30001,9.46438,23173.74796,0.00000,0.06768,286.68105
189.60001,9.47933,23172.33831,0.00000,0.06779,286.66361
189.90001,9.49445,23173.39331,0.00000,0.06790,286.67666
190.20001,9.50934,23176.09489,0.00000,0.06800,286.71008
190.50001,9.52441,23173.17575,0.00000,0.06811,286.67397
190.80001,9.53947,23177.37192,0.00000,0.06821,286.72588
191.10001,9.55424,23171.66626,0.00000,0.06832,286.65530
191.40001,9.56955,23177.29890,0.00000,0.06843,286.72498
191.70001,9.58426,23176.45848,0.00000,0.06854,286.71458
192.00001,9.59938,23176.44805,0.00000,0.06864,286.71445
192.30001,9.61445,23179.65180,0.00000,0.06875,286.75409
192.60001,9.62928,23176.46593,0.00000,0.06886,286.71467
192.90001,9.64452,23179.96323,0.00000,0.06897,286.75794
193.20001,9.65935,23176.93532,0.00000,0.06908,286.72048
193.50001,9.67448,23178.46268,0.00000,0.06918,286.73938
193.80001,9.68943,23179.48788,0.00000,0.06929,286.75206
194.10001,9.70443,23181.61130,0.00000,0.06939,286.77833
194.40001,9.71938,23179.38358,0.00000,0.06950,286.75077
194.70001,9.73451,23181.15830,0.00000,0.06960,286.77272
195.00001,9.74933,23178.80690,0.00000,0.06970,286.74363
195.30001,9.76440,23177.77276,0.00000,0.06981,286.73084
195.60001,9.77947,23181.39374,0.00000,0.06991,286.77563
195.90001,9.79418,23177.20056,0.00000,0.07001,286.72376
196.20001,9.80954,23182.26695,0.00000,0.07012,286.78644
196.50001,9.82431,23181.16874,0.00000,0.07022,286.77285
196.80001,9.83944,23178.76965,0.00000,0.07033,286.74317
197.10001,9.85450,23183.30556,0.00000,0.07043,286.79929
197.40001,9.86933,23179.60411,0.00000,0.07053,286.75350
197.70001,9.88452,23182.81233,0.00000,0.07063,286.79318
198.00001,9.89935,23179.16304,0.00000,0.07073,286.74804
198.30001,9.91453,23180.51159,0.00000,0.07084,286.76472
198.60001,9.92936,23178.24811,0.00000,0.07093,286.73672
198.90001,9.94443,23180.65912,0.00000,0.07103,286.76655
199.20001,9.95931,23178.71004,0.00000,0.07113,286.74244
199.50001,9.97444,23179.22711,0.00000,0.07122,286.74883
199.80001,9.98939,23181.40268,0.00000,0.07132,286.77575
200.10001,10.00440,23177.70123,0.00000,0.07142,286.72996
200.40001,10.01952,23180.74852,0.00000,0.07152,286.76765
200.70001,10.03423,23176.83697,0.00000,0.07162,286.71926
201.00001,10.04954,23180.17930,0.00000,0.07171,286.76061
201.30001,10.06431,23179.86637,0.00000,0.07181,286.75674
201.60001,10.07937,23176.24241,0.00000,0.07191,286.71191
201.90001,10.09444,23179.63988,0.00000,0.07201,286.75394
202.20001,10.10939,23177.59693,0.00000,0.07210,286.72866
202.50001,10.12445,23176.90551,0.00000,0.07219,286.72011
202.80001,10.13934,23175.81773,0.00000,0.07228,286.70665
203.10001,10.15447,23178.43139,0.00000,0.07238,286.73899
203.40001,10.16942,23174.63160,0.00000,0.07247,286.69198
203.70001,10.18448,23175.57186,0.00000,0.07256,286.70361
204.00001,10.19937,23173.47229,0.00000,0.07265,286.67764
204.30001,10.21450,23172.80322,0.00000,0.07274,286.66936
204.60001,10.22938,23175.86839,0.00000,0.07283,286.70728
204.90001,10.24427,23171.62007,0.00000,0.07292,286.65473
205.20001,10.25946,23174.56007,0.00000,0.07301,286.69110
205.50001,10.27429,23171.62454,0.00000,0.07310,286.65478
205.80001,10.28953,23171.49043,0.00000,0.07319,286.65312
206.10001,10.30430,23170.67832,0.00000,0.07327,286.64308
206.40001,10.31937,23169.21949,0.00000,0.07336,286.62503
206.70001,10.33449,23170.64852,0.00000,0.07344,286.64271
207.00001,10.34944,23167.18549,0.00000,0.07353,286.59987
207.30001,10.36445,23166.18562,0.00000,0.07361,286.58750
207.60001,10.37946,23166.67736,0.00000,0.07369,286.59358
207.90001,10.39440,23162.73004,0.00000,0.07377,286.54475
208.20001,10.40929,23160.21174,0.00000,0.07385,286.51359
208.50001,10.42436,23159.96587,0.00000,0.07392,286.51055
208.80001,10.43936,23159.42645,0.00000,0.07400,286.50388
209.10001,10.45449,23156.96180,0.00000,0.07408,286.47339
209.40001,10.46944,23159.13290,0.00000,0.07415,286.50025
209.70001,10.48427,23153.72974,0.00000,0.07423,286.43341
210.00001,10.49951,23156.24952,0.00000,0.07430,286.46458
210.30001,10.51428,23153.33039,0.00000,0.07438,286.42846
210.60001,10.52947,23151.29787,0.00000,0.07445,286.40332
210.90001,10.54441,23149.10740,0.00000,0.07452,286.37622
211.20001,10.55936,23144.37479,0.00000,0.07459,286.31768
211.50001,10.57443,23145.22117,0.00000,0.07466,286.32815
211.80001,10.58932,23139.78225,0.00000,0.07473,286.26086
212.10001,10.60450,23140.96391,0.00000,0.07479,286.27548
212.40001,10.61933,23134.94235,0.00000,0.07486,286.20099
212.70001,10.63446,23135.22995,0.00000,0.07492,286.20455
213.00001,10.64935,23131.29902,0.00000,0.07499,286.15592
213.30001,10.66441,23130.69105,0.00000,0.07505,286.14840
213.60001,10.67936,23128.78966,0.00000,0.07511,286.12487
213.90001,10.69437,23122.60270,0.00000,0.07517,286.04833
214.20001,10.70943,23123.61896,0.00000,0.07523,286.06091
214.50001,10.72426,23115.04185,0.00000,0.07528,285.95480
214.80001,10.73945,23114.10904,0.00000,0.07534,285.94326
215.10001,10.75428,23109.45839,0.00000,0.07539,285.88573
215.40001,10.76946,23106.59289,0.00000,0.07544,285.85028
215.70001,10.78435,23102.92125,0.00000,0.07549,285.80486
216.00001,10.79942,23096.53014,0.00000,0.07553,285.72579
216.30001,10.81448,23093.37258,0.00000,0.07559,285.68673
216.60001,10.82937,23086.44652,0.00000,0.07563,285.60105
216.90001,10.84444,23083.33069,0.00000,0.07568,285.56250
217.20001,10.85933,23076.30479,0.00000,0.07572,285.47559
217.50001,10.87445,23075.04117,0.00000,0.07576,285.45995
217.80001,10.88934,23065.71454,0.00000,0.07580,285.34457
218.10001,10.90441,23059.73768,0.00000,0.07584,285.27064
218.40001,10.91935,23053.80553,0.00000,0.07588,285.19725
218.70001,10.93448,23045.51005,0.00000,0.07592,285.09463
219.00001,10.94943,23041.68046,0.00000,0.07595,285.04725
219.30001,10.96432,23028.41842,0.00000,0.07599,284.88319
219.60001,10.97956,23024.99264,0.00000,0.07602,284.84081
219.90001,10.99433,23011.96605,0.00000,0.07605,284.67966
220.20001,11.00946,23005.43636,0.00000,0.07608,284.59888
220.50001,11.02435,22996.06204,0.00000,0.07611,284.48291
220.80001,11.03941,22985.57460,0.00000,0.07613,284.35317
221.10001,11.05448,22975.32558,0.00000,0.07615,284.22638
221.40001,11.06931,22960.98620,0.00000,0.07617,284.04899
221.70001,11.08443,22949.59426,0.00000,0.07619,283.90806
222.00001,11.09938,22937.19649,0.00000,0.07621,283.75469
222.30001,11.11445,22926.20838,0.00000,0.07623,283.61875
222.60001,11.12934,22908.05727,0.00000,0.07624,283.39421
222.90001,11.14446,22893.57185,0.00000,0.07625,283.21501
223.20001,11.15941,22876.32972,0.00000,0.07627,283.00171
223.50001,11.17448,22856.29362,0.00000,0.07628,282.75384
223.80001,11.18948,22839.85466,0.00000,0.07629,282.55048
224.10001,11.20437,22817.23171,0.00000,0.07630,282.27061
224.40001,11.21950,22798.43241,0.00000,0.07631,282.03804
224.70001,11.23433,22773.17345,0.00000,0.07631,281.72557
225.00001,11.24951,22751.51610,0.00000,0.07631,281.45764
225.30001,11.26440,22726.12453,0.00000,0.07632,281.14353
225.60001,11.27935,22699.63324,0.00000,0.07632,280.81580
225.90001,11.29447,22674.10606,0.00000,0.07632,280.50001
226.20001,11.30936,22643.36348,0.00000,0.07632,280.11969
226.50001,11.32449,22613.48665,0.00000,0.07632,279.75009
226.80001,11.33932,22580.22875,0.00000,0.07632,279.33866
227.10001,11.35438,22551.83160,0.00000,0.07631,278.98736
227.40001,11.36933,22515.80507,0.00000,0.07631,278.54168
227.70001,11.38440,22479.59822,0.00000,0.07631,278.09376
228.00001,11.39940,22443.64321,0.00000,0.07630,277.64897
228.30001,11.41441,22401.48634,0.00000,0.07630,277.12745
228.60001,11.42948,22364.09634,0.00000,0.07629,276.66490
228.90001,11.44437,22318.55243,0.00000,0.07628,276.10148
229.20001,11.45955,22275.46275,0.00000,0.07627,275.56842
229.50001,11.47432,22226.94904,0.00000,0.07626,274.96826
229.80001,11.48945,22177.85418,0.00000,0.07625,274.36091
230.10001,11.50439,22126.52415,0.00000,0.07624,273.72591
230.40001,11.51934,22072.30479,0.00000,0.07623,273.05516
230.70001,11.53453,22017.06320,0.00000,0.07622,272.37177
231.00001,11.54936,21955.98483,0.00000,0.07621,271.61617
231.30001,11.56442,21896.21776,0.00000,0.07620,270.87680
231.60001,11.57937,21827.87061,0.00000,0.07618,270.03128
231.90001,11.59450,21759.84979,0.00000,0.07617,269.18980
232.20001,11.60939,21680.50110,0.00000,0.07615,268.20818
232.50001,11.62451,21607.83410,0.00000,0.07613,267.30922
232.80001,11.63940,21522.42959,0.00000,0.07611,266.25269
233.10001,11.65447,21417.41365,0.00000,0.07609,264.95354
233.40001,11.66947,21307.13165,0.00000,0.07606,263.58925
233.70001,11.68430,21164.68102,0.00000,0.07603,261.82700
234.00001,11.69961,21024.52219,0.00000,0.07600,260.09311
234.30001,11.71438,20731.29416,0.00000,0.07593,256.46560
234.60001,11.72950,20270.91086,0.00000,0.07583,250.77023
234.67801,11.73339,19125.98014,0.00000,0.07478,236.60636
234.68401,11.73411,16660.20155,0.00000,0.07203,206.10236
234.69001,11.73500,13382.67922,0.00000,0.07072,165.55632
234.69401,11.73560,11118.73761,0.00000,0.06879,137.54924