File: scratch/college-stuff/ME Lab/ME lab Fall 2013/group1/group1.is_tens_RawData/Specimen_RawData_5.csv
Time,Extension,Load,Strain 2,Tensile strain,Tensile stress
(sec),(mm),(N),(mm/mm),(mm/mm),(MPa)
0.00000,0.00000,0.57975,0.00000,0.00000,0.00703
0.10000,0.00179,3.28529,0.00000,0.00000,0.03981
0.20000,0.00771,7.61942,0.00000,0.00001,0.09233
0.30000,0.01375,10.34246,0.00000,0.00001,0.12532
0.40000,0.01943,11.52507,0.00000,0.00000,0.13965
0.50000,0.02481,13.19001,0.00000,0.00001,0.15983
0.60000,0.02995,13.90752,0.00000,0.00001,0.16852
0.70000,0.03498,14.67452,0.00000,0.00001,0.17782
0.80000,0.04000,14.96459,0.00000,0.00001,0.18133
0.90000,0.04496,15.53532,0.00000,0.00001,0.18825
1.00000,0.05004,15.88398,0.00000,0.00001,0.19247
1.10000,0.05495,16.26241,0.00000,0.00002,0.19706
1.20000,0.06009,16.65251,0.00000,0.00001,0.20178
1.30000,0.06487,16.97961,0.00000,0.00001,0.20575
1.40000,0.07007,17.75743,0.00000,0.00002,0.21517
1.50000,0.07492,18.39805,0.00000,0.00002,0.22294
1.60000,0.08012,18.63440,0.00000,0.00002,0.22580
1.70000,0.08496,18.88761,0.00000,0.00002,0.22887
1.80000,0.09004,18.81478,0.00000,0.00002,0.22798
1.90000,0.09489,19.07106,0.00000,0.00002,0.23109
2.00000,0.10009,19.91787,0.00000,0.00002,0.24135
2.10000,0.10499,19.78467,0.00000,0.00003,0.23974
2.20000,0.11007,19.75390,0.00000,0.00003,0.23936
2.30000,0.11498,20.01695,0.00000,0.00003,0.24255
2.40000,0.12000,20.29243,0.00000,0.00003,0.24589
2.50000,0.12502,20.12784,0.00000,0.00002,0.24390
2.60000,0.13004,20.20232,0.00000,0.00003,0.24480
2.70000,0.13500,20.45948,0.00000,0.00003,0.24791
2.80000,0.13997,20.20746,0.00000,0.00003,0.24486
2.90000,0.14505,20.69728,0.00000,0.00003,0.25080
3.00000,0.15001,20.74784,0.00000,0.00003,0.25141
3.10000,0.15509,20.77168,0.00000,0.00003,0.25170
3.20000,0.15994,20.61959,0.00000,0.00003,0.24985
3.30000,0.16508,20.37360,0.00000,0.00003,0.24687
3.40000,0.16992,20.60749,0.00000,0.00003,0.24971
3.50000,0.17512,20.73605,0.00000,0.00003,0.25127
3.60000,0.17991,21.47083,0.00000,0.00003,0.26017
3.70000,0.18511,21.78859,0.00000,0.00003,0.26402
3.80000,0.18995,21.96786,0.00000,0.00003,0.26619
3.90000,0.19515,21.47584,0.00000,0.00003,0.26023
4.00000,0.20000,21.74539,0.00000,0.00003,0.26350
4.10000,0.20508,22.39777,0.00000,0.00003,0.27140
4.20000,0.20998,21.77836,0.00000,0.00003,0.26390
4.30000,0.21506,22.44254,0.00000,0.00003,0.27194
4.40000,0.21997,21.80935,0.00000,0.00002,0.26427
4.50000,0.22505,22.50452,0.00000,0.00002,0.27269
4.60000,0.22995,23.28950,0.00000,0.00002,0.28221
4.70000,0.23503,23.79758,0.00000,0.00002,0.28836
4.80000,0.24000,23.47643,0.00000,0.00002,0.28447
4.90000,0.24508,24.21554,0.00000,0.00002,0.29343
5.00000,0.25010,24.13935,0.00000,0.00003,0.29250
5.10000,0.25500,24.91572,0.00000,0.00002,0.30191
5.20000,0.26002,25.79684,0.00000,0.00002,0.31259
5.30000,0.26505,26.19597,0.00000,0.00002,0.31742
5.40000,0.27007,26.72162,0.00000,0.00002,0.32379
5.50000,0.27497,27.51927,0.00000,0.00002,0.33346
5.60000,0.28005,28.75961,0.00000,0.00002,0.34849
5.70000,0.28490,30.37932,0.00000,0.00002,0.36812
5.80000,0.29016,31.79294,0.00000,0.00002,0.38525
5.90000,0.29500,33.47901,0.00000,0.00002,0.40568
6.00000,0.30014,35.38733,0.00000,0.00002,0.42880
6.10000,0.30493,37.96970,0.00000,0.00002,0.46009
6.20000,0.31007,47.61548,0.00000,0.00002,0.57697
6.30000,0.31491,61.06129,0.00000,0.00002,0.73990
6.40000,0.32011,77.08490,0.00000,0.00003,0.93406
6.50000,0.32490,92.36561,0.00000,0.00003,1.11922
6.60000,0.33004,114.95084,0.00000,0.00004,1.39290
6.70000,0.33488,143.27581,0.00000,0.00005,1.73612
6.80000,0.34002,175.36639,0.00000,0.00007,2.12497
6.90000,0.34499,213.12258,0.00000,0.00009,2.58247
7.00000,0.35007,251.85170,0.00000,0.00011,3.05177
7.10000,0.35497,293.91877,0.00000,0.00013,3.56151
7.20000,0.35993,332.24891,0.00000,0.00015,4.02597
7.30000,0.36501,370.40000,0.00000,0.00017,4.48826
7.40000,0.36998,407.54126,0.00000,0.00019,4.93831
7.50000,0.37500,450.74532,0.00000,0.00022,5.46183
7.60000,0.37990,493.27910,0.00000,0.00024,5.97722
7.70000,0.38498,538.18547,0.00000,0.00027,6.52137
7.80000,0.38995,578.95873,0.00000,0.00029,7.01543
7.90000,0.39503,622.13726,0.00000,0.00031,7.53864
8.00000,0.39987,664.69493,0.00000,0.00034,8.05432
8.10000,0.40501,708.23748,0.00000,0.00037,8.58194
8.20000,0.40986,749.91509,0.00000,0.00039,9.08696
8.30000,0.41506,793.68632,0.00000,0.00041,9.61735
8.40000,0.41990,835.01609,0.00000,0.00043,10.11816
8.50000,0.42504,880.14537,0.00000,0.00046,10.66500
8.60000,0.42989,922.01699,0.00000,0.00048,11.17237
8.70000,0.43503,964.17777,0.00000,0.00051,11.68325
8.80000,0.43993,1004.33649,0.00000,0.00053,12.16987
8.90000,0.44501,1047.69003,0.00000,0.00056,12.69520
9.00000,0.44986,1089.49803,0.00000,0.00059,13.20180
9.10000,0.45500,1131.33518,0.00000,0.00060,13.70875
9.20000,0.45996,1173.49317,0.00000,0.00063,14.21959
9.30000,0.46504,1214.42704,0.00000,0.00065,14.71560
9.40000,0.46995,1254.85882,0.00000,0.00068,15.20553
9.50000,0.47497,1294.24045,0.00000,0.00070,15.68273
9.60000,0.47999,1334.86111,0.00000,0.00072,16.17494
9.70000,0.48501,1373.43183,0.00000,0.00074,16.64231
9.80000,0.48997,1414.25608,0.00000,0.00076,17.13699
9.90000,0.49494,1452.53418,0.00000,0.00079,17.60082
10.00000,0.49996,1492.62538,0.00000,0.00081,18.08662
10.10000,0.50492,1528.40773,0.00000,0.00083,18.52021
10.20000,0.51006,1567.89720,0.00000,0.00085,18.99871
10.30000,0.51497,1602.83912,0.00000,0.00087,19.42211
10.40000,0.52005,1641.87364,0.00000,0.00089,19.89511
10.50000,0.52489,1676.79004,0.00000,0.00091,20.31820
10.60000,0.53009,1716.06801,0.00000,0.00093,20.79415
10.70000,0.53494,1750.41705,0.00000,0.00095,21.21036
10.80000,0.54008,1787.28458,0.00000,0.00097,21.65710
10.90000,0.54486,1821.18397,0.00000,0.00099,22.06787
11.00000,0.55000,1855.72114,0.00000,0.00101,22.48637
11.10000,0.55491,1889.12619,0.00000,0.00103,22.89115
11.20000,0.56005,1924.86253,0.00000,0.00104,23.32417
11.30000,0.56489,1958.76118,0.00000,0.00106,23.73494
11.40000,0.57003,1993.69602,0.00000,0.00108,24.15825
11.50000,0.57494,2025.55582,0.00000,0.00110,24.54431
11.60000,0.58002,2058.26145,0.00000,0.00112,24.94061
11.70000,0.58498,2092.17388,0.00000,0.00114,25.35154
11.80000,0.59000,2123.30855,0.00000,0.00115,25.72881
11.90000,0.59497,2155.53213,0.00000,0.00117,26.11927
12.00000,0.59993,2185.37301,0.00000,0.00119,26.48086
12.10000,0.60495,2217.63551,0.00000,0.00121,26.87180
12.20000,0.60991,2246.61287,0.00000,0.00122,27.22293
12.30000,0.61493,2280.67264,0.00000,0.00124,27.63564
12.40000,0.61990,2309.56636,0.00000,0.00126,27.98575
12.50000,0.62504,2341.34663,0.00000,0.00127,28.37085
12.60000,0.62994,2369.98014,0.00000,0.00129,28.71781
12.70000,0.63508,2399.53622,0.00000,0.00130,29.07595
12.80000,0.63987,2426.18807,0.00000,0.00132,29.39890
12.90000,0.64501,2454.99630,0.00000,0.00134,29.74798
13.00000,0.64991,2481.61759,0.00000,0.00135,30.07055
13.10000,0.65505,2509.64146,0.00000,0.00137,30.41013
13.20000,0.65984,2536.78802,0.00000,0.00138,30.73907
13.30000,0.66498,2564.49021,0.00000,0.00140,31.07475
13.40000,0.66982,2592.01191,0.00000,0.00141,31.40824
13.50000,0.67502,2618.42068,0.00000,0.00143,31.72824
13.60000,0.67999,2643.18604,0.00000,0.00145,32.02833
13.70000,0.68507,2670.16217,0.00000,0.00146,32.35521
13.80000,0.68991,2693.67881,0.00000,0.00148,32.64017
13.90000,0.69505,2718.05320,0.00000,0.00149,32.93552
14.00000,0.70002,2742.22177,0.00000,0.00150,33.22838
14.10000,0.70504,2766.34693,0.00000,0.00152,33.52071
14.20000,0.70994,2788.66421,0.00000,0.00153,33.79114
14.30000,0.71502,2810.13083,0.00000,0.00154,34.05125
14.40000,0.71999,2831.91316,0.00000,0.00156,34.31520
14.50000,0.72501,2851.04290,0.00000,0.00157,34.54700
14.60000,0.73009,2873.04837,0.00000,0.00158,34.81365
14.70000,0.73505,2892.39660,0.00000,0.00159,35.04809
14.80000,0.74007,2913.42959,0.00000,0.00160,35.30296
14.90000,0.74504,2932.52002,0.00000,0.00161,35.53428
15.00000,0.75006,2955.98824,0.00000,0.00162,35.81866
15.10000,0.75490,2974.96244,0.00000,0.00164,36.04857
15.20000,0.76004,2998.87117,0.00000,0.00165,36.33828
15.30000,0.76483,3018.18997,0.00000,0.00166,36.57237
15.40000,0.77009,3041.61943,0.00000,0.00168,36.85628
15.50000,0.77493,3061.39961,0.00000,0.00169,37.09596
15.60000,0.78007,3085.06154,0.00000,0.00170,37.38268
15.70000,0.78486,3106.43911,0.00000,0.00171,37.64172
15.80000,0.79006,3130.23143,0.00000,0.00173,37.93002
15.90000,0.79496,3150.90008,0.00000,0.00174,38.18046
16.00000,0.80004,3174.29192,0.00000,0.00176,38.46391
16.10000,0.80489,3196.02191,0.00000,0.00176,38.72722
16.20000,0.80997,3218.92984,0.00000,0.00178,39.00480
16.30000,0.81493,3240.43334,0.00000,0.00179,39.26537
16.40000,0.82001,3261.25287,0.00000,0.00180,39.51764
16.50000,0.82498,3282.29219,0.00000,0.00182,39.77258
16.60000,0.83000,3304.69161,0.00000,0.00183,40.04401
16.70000,0.83496,3327.44941,0.00000,0.00184,40.31977
16.80000,0.83998,3348.07076,0.00000,0.00185,40.56964
16.90000,0.84500,3370.63782,0.00000,0.00186,40.84310
17.00000,0.84997,3390.33194,0.00000,0.00187,41.08174
17.10000,0.85499,3413.52783,0.00000,0.00189,41.36281
17.20000,0.85995,3433.18544,0.00000,0.00190,41.60101
17.30000,0.86509,3456.70283,0.00000,0.00191,41.88597
17.40000,0.87000,3475.45110,0.00000,0.00192,42.11315
17.50000,0.87508,3497.31520,0.00000,0.00194,42.37809
17.60000,0.87992,3516.40396,0.00000,0.00195,42.60939
17.70000,0.88506,3538.04752,0.00000,0.00196,42.87165
17.80000,0.88991,3557.27859,0.00000,0.00197,43.10468
17.90000,0.89511,3577.41527,0.00000,0.00198,43.34869
18.00000,0.89989,3595.49448,0.00000,0.00199,43.56776
18.10000,0.90509,3615.83158,0.00000,0.00201,43.81419
18.20000,0.91000,3635.62480,0.00000,0.00202,44.05403
18.30000,0.91514,3655.25745,0.00000,0.00203,44.29192
18.40000,0.91998,3675.42505,0.00000,0.00204,44.53630
18.50000,0.92500,3696.46251,0.00000,0.00205,44.79122
18.60000,0.92991,3717.02537,0.00000,0.00207,45.04039
18.70000,0.93505,3737.25221,0.00000,0.00208,45.28548
18.80000,0.93995,3757.84002,0.00000,0.00209,45.53495
18.90000,0.94497,3779.03692,0.00000,0.00210,45.79180
19.00000,0.94994,3802.06704,0.00000,0.00211,46.07086
19.10000,0.95496,3821.97164,0.00000,0.00213,46.31205
19.20000,0.95998,3845.15636,0.00000,0.00214,46.59299
19.30000,0.96500,3864.66235,0.00000,0.00215,46.82935
19.40000,0.96996,3888.58169,0.00000,0.00216,47.11919
19.50000,0.97493,3908.33579,0.00000,0.00218,47.35856
19.60000,0.98001,3931.95860,0.00000,0.00219,47.64480
19.70000,0.98491,3952.52965,0.00000,0.00220,47.89407
19.80000,0.99005,3976.12266,0.00000,0.00221,48.17995
19.90000,0.99484,3995.96691,0.00000,0.00223,48.42041
20.00000,1.00004,4019.09687,0.00000,0.00224,48.70068
20.10000,1.00488,4039.39225,0.00000,0.00226,48.94661
20.20000,1.01008,4063.64202,0.00000,0.00227,49.24045
20.30000,1.01493,4083.12716,0.00000,0.00228,49.47656
20.40000,1.02007,4106.81963,0.00000,0.00229,49.76365
20.50000,1.02491,4127.87870,0.00000,0.00230,50.01883
20.60000,1.03005,4151.58123,0.00000,0.00232,50.30604
20.70000,1.03490,4173.13650,0.00000,0.00233,50.56723
20.80000,1.03998,4196.54511,0.00000,0.00235,50.85088
20.90000,1.04488,4219.92652,0.00000,0.00236,51.13420
21.00000,1.04996,4242.16352,0.00000,0.00237,51.40365
21.10000,1.05493,4264.33571,0.00000,0.00239,51.67232
21.20000,1.06001,4286.88638,0.00000,0.00240,51.94557
21.30000,1.06497,4309.82150,0.00000,0.00241,52.22349
21.40000,1.06999,4331.78768,0.00000,0.00243,52.48966
21.50000,1.07502,4355.03051,0.00000,0.00244,52.77130
21.60000,1.07998,4376.43342,0.00000,0.00245,53.03064
21.70000,1.08506,4400.96296,0.00000,0.00247,53.32788
21.80000,1.08996,4421.68862,0.00000,0.00248,53.57902
21.90000,1.09504,4445.47907,0.00000,0.00250,53.86729
22.00000,1.09995,4466.54260,0.00000,0.00251,54.12253
22.10000,1.10509,4490.38334,0.00000,0.00252,54.41141
22.20000,1.10999,4511.02778,0.00000,0.00254,54.66157
22.30000,1.11507,4536.36944,0.00000,0.00255,54.96864
22.40000,1.11992,4558.22796,0.00000,0.00257,55.23351
22.50000,1.12512,4581.66562,0.00000,0.00258,55.51751
22.60000,1.12996,4603.43771,0.00000,0.00259,55.78133
22.70000,1.13510,4627.21176,0.00000,0.00261,56.06941
22.80000,1.13989,4649.91331,0.00000,0.00262,56.34449
22.90000,1.14503,4672.85290,0.00000,0.00264,56.62245
23.00000,1.14993,4694.96027,0.00000,0.00265,56.89034
23.10000,1.15507,4718.37111,0.00000,0.00266,57.17401
23.20000,1.15992,4740.77612,0.00000,0.00268,57.44550
23.30000,1.16506,4765.11642,0.00000,0.00269,57.74044
23.40000,1.16996,4787.74868,0.00000,0.00271,58.01468
23.50000,1.17504,4811.39384,0.00000,0.00272,58.30120
23.60000,1.18001,4833.86070,0.00000,0.00273,58.57344
23.70000,1.18503,4856.86138,0.00000,0.00274,58.85214
23.80000,1.18993,4881.32238,0.00000,0.00276,59.14854
23.90000,1.19495,4901.28770,0.00000,0.00277,59.39047
24.00000,1.20003,4924.64788,0.00000,0.00278,59.67353
24.10000,1.20500,4946.45275,0.00000,0.00280,59.93775
24.20000,1.21002,4971.52060,0.00000,0.00281,60.24151
24.30000,1.21486,4993.15970,0.00000,0.00283,60.50371
24.40000,1.22000,5019.43678,0.00000,0.00284,60.82212
24.50000,1.22497,5041.08295,0.00000,0.00285,61.08441
24.60000,1.23005,5067.26578,0.00000,0.00287,61.40168
24.70000,1.23489,5088.83782,0.00000,0.00288,61.66308
24.80000,1.24009,5114.35717,0.00000,0.00290,61.97230
24.90000,1.24488,5135.80404,0.00000,0.00291,62.23218
25.00000,1.25014,5160.67967,0.00000,0.00292,62.53361
25.10000,1.25486,5181.98982,0.00000,0.00294,62.79183
25.20000,1.26000,5207.72226,0.00000,0.00295,63.10364
25.30000,1.26491,5230.17570,0.00000,0.00297,63.37571
25.40000,1.27005,5253.24568,0.00000,0.00298,63.65526
25.50000,1.27495,5276.19831,0.00000,0.00300,63.93338
25.60000,1.28003,5300.12734,0.00000,0.00301,64.22334
25.70000,1.28494,5322.69999,0.00000,0.00303,64.49686
25.80000,1.29002,5346.65659,0.00000,0.00304,64.78715
25.90000,1.29504,5370.85570,0.00000,0.00305,65.08038
26.00000,1.30006,5393.45965,0.00000,0.00307,65.35428
26.10000,1.30497,5419.15931,0.00000,0.00309,65.66569
26.20000,1.30999,5442.07208,0.00000,0.00310,65.94333
26.30000,1.31501,5466.93020,0.00000,0.00312,66.24454
26.40000,1.32003,5489.63100,0.00000,0.00313,66.51961
26.50000,1.32505,5513.89754,0.00000,0.00314,66.81366
26.60000,1.32996,5535.98925,0.00000,0.00315,67.08135
26.70000,1.33504,5562.75807,0.00000,0.00317,67.40572
26.80000,1.34006,5584.65980,0.00000,0.00319,67.67111
26.90000,1.34514,5608.66967,0.00000,0.00320,67.96204
27.00000,1.34999,5631.95534,0.00000,0.00322,68.24420
27.10000,1.35507,5658.18734,0.00000,0.00323,68.56207
27.20000,1.35997,5681.16270,0.00000,0.00325,68.84047
27.30000,1.36511,5706.07260,0.00000,0.00326,69.14231
27.40000,1.36996,5727.10931,0.00000,0.00328,69.39722
27.50000,1.37510,5751.84040,0.00000,0.00329,69.69689
27.60000,1.37988,5774.90777,0.00000,0.00330,69.97640
27.70000,1.38508,5798.89454,0.00000,0.00333,70.26706
27.80000,1.38999,5822.32848,0.00000,0.00334,70.55102
27.90000,1.39513,5847.23391,0.00000,0.00335,70.85280
28.00000,1.39991,5870.58514,0.00000,0.00336,71.13576
28.10000,1.40499,5895.47120,0.00000,0.00338,71.43731
28.20000,1.40990,5920.02906,0.00000,0.00340,71.73489
28.30000,1.41510,5944.25872,0.00000,0.00342,72.02848
28.40000,1.41994,5969.08741,0.00000,0.00343,72.32934
28.50000,1.42496,5992.40772,0.00000,0.00344,72.61192
28.60000,1.42999,6018.30520,0.00000,0.00346,72.92573
28.70000,1.43495,6041.79129,0.00000,0.00348,73.21032
28.80000,1.44003,6067.92383,0.00000,0.00349,73.52697
28.90000,1.44499,6089.59347,0.00000,0.00351,73.78955
29.00000,1.45001,6115.65411,0.00000,0.00353,74.10534
29.10000,1.45498,6137.27123,0.00000,0.00354,74.36728
29.20000,1.46006,6161.87342,0.00000,0.00356,74.66539
29.30000,1.46496,6184.95792,0.00000,0.00357,74.94511
29.40000,1.47004,6210.88743,0.00000,0.00359,75.25931
29.50000,1.47489,6233.82740,0.00000,0.00360,75.53728
29.60000,1.48009,6261.36661,0.00000,0.00362,75.87098
29.70000,1.48493,6284.21083,0.00000,0.00363,76.14779
29.80000,1.49007,6309.74844,0.00000,0.00365,76.45724
29.90000,1.49492,6333.20585,0.00000,0.00367,76.74148
30.00000,1.50006,6357.85684,0.00000,0.00368,77.04019
30.10000,1.50490,6382.36329,0.00000,0.00370,77.33714
30.20000,1.51004,6407.71911,0.00000,0.00371,77.64438
30.30000,1.51495,6431.39407,0.00000,0.00373,77.93126
30.40000,1.52003,6456.12627,0.00000,0.00375,78.23095
30.50000,1.52493,6480.54779,0.00000,0.00376,78.52687
30.60000,1.53007,6505.22411,0.00000,0.00378,78.82588
30.70000,1.53498,6529.35803,0.00000,0.00379,79.11832
30.80000,1.54006,6553.73856,0.00000,0.00381,79.41375
30.90000,1.54496,6578.53857,0.00000,0.00382,79.71426
31.00000,1.54998,6601.46251,0.00000,0.00384,79.99203
31.10000,1.55501,6627.88674,0.00000,0.00386,80.31222
31.20000,1.55997,6650.54694,0.00000,0.00387,80.58680
31.30000,1.56505,6678.04182,0.00000,0.00389,80.91997
31.40000,1.56995,6700.65284,0.00000,0.00390,81.19395
31.50000,1.57503,6726.90049,0.00000,0.00392,81.51201
31.60000,1.58000,6749.39528,0.00000,0.00393,81.78458
31.70000,1.58514,6775.86570,0.00000,0.00395,82.10533
31.80000,1.58992,6798.49759,0.00000,0.00397,82.37957
31.90000,1.59500,6825.59311,0.00000,0.00398,82.70790
32.00000,1.59985,6849.12354,0.00000,0.00400,82.99302
32.10000,1.60511,6877.11760,0.00000,0.00402,83.33223
32.20000,1.61001,6900.85441,0.00000,0.00403,83.61986
32.30000,1.61509,6926.01278,0.00000,0.00405,83.92471
32.40000,1.61994,6950.51402,0.00000,0.00406,84.22160
32.50000,1.62508,6974.46018,0.00000,0.00408,84.51177
32.60000,1.62992,6997.89152,0.00000,0.00409,84.79569
32.70000,1.63512,7023.28905,0.00000,0.00411,85.10344
32.80000,1.63991,7048.51374,0.00000,0.00412,85.40910
32.90000,1.64505,7074.78374,0.00000,0.00414,85.72742
33.00000,1.64995,7099.50998,0.00000,0.00416,86.02703
33.10000,1.65503,7123.03370,0.00000,0.00417,86.31208
33.20000,1.65994,7148.99674,0.00000,0.00419,86.62668
33.30000,1.66502,7173.69169,0.00000,0.00420,86.92592
33.40000,1.66998,7200.60840,0.00000,0.00422,87.25208
33.50000,1.67500,7223.56215,0.00000,0.00424,87.53021
33.60000,1.68003,7250.43043,0.00000,0.00426,87.85578
33.70000,1.68499,7273.72393,0.00000,0.00427,88.13804
33.80000,1.69007,7302.41016,0.00000,0.00429,88.48564
33.90000,1.69491,7324.81778,0.00000,0.00431,88.75716
34.00000,1.69999,7351.33961,0.00000,0.00432,89.07853
34.10000,1.70490,7374.40065,0.00000,0.00434,89.35797
34.20000,1.70998,7400.00680,0.00000,0.00436,89.66825
34.30000,1.71488,7424.37020,0.00000,0.00437,89.96347
34.40000,1.72008,7450.65808,0.00000,0.00439,90.28201
34.50000,1.72493,7475.04085,0.00000,0.00441,90.57746
34.60000,1.73007,7501.05828,0.00000,0.00443,90.89272
34.70000,1.73491,7524.85469,0.00000,0.00444,91.18107
34.80000,1.73999,7551.60302,0.00000,0.00446,91.50519
34.90000,1.74490,7575.54397,0.00000,0.00448,91.79529
35.00000,1.74998,7599.83286,0.00000,0.00449,92.08961
35.10000,1.75494,7625.80559,0.00000,0.00451,92.40433
35.20000,1.75996,7651.28210,0.00000,0.00453,92.71303
35.30000,1.76487,7675.98599,0.00000,0.00454,93.01238
35.40000,1.77001,7702.38042,0.00000,0.00457,93.33221
35.50000,1.77503,7728.08790,0.00000,0.00458,93.64371
35.60000,1.78005,7751.82620,0.00000,0.00460,93.93136
35.70000,1.78496,7777.57689,0.00000,0.00461,94.24339
35.80000,1.78998,7800.54852,0.00000,0.00463,94.52174
35.90000,1.79500,7826.23366,0.00000,0.00465,94.83298
36.00000,1.80008,7849.90862,0.00000,0.00466,95.11985
36.10000,1.80504,7876.28144,0.00000,0.00468,95.43942
36.20000,1.80995,7901.18128,0.00000,0.00470,95.74114
36.30000,1.81503,7927.80742,0.00000,0.00472,96.06378
36.40000,1.81993,7951.01598,0.00000,0.00473,96.34500
36.50000,1.82513,7977.40519,0.00000,0.00475,96.66477
36.60000,1.82998,8000.26283,0.00000,0.00477,96.94174
36.70000,1.83506,8027.30322,0.00000,0.00479,97.26940
36.80000,1.83990,8050.85450,0.00000,0.00481,97.55478
36.90000,1.84510,8077.19231,0.00000,0.00482,97.87392
37.00000,1.84995,8102.36782,0.00000,0.00484,98.17898
37.10000,1.85503,8129.61459,0.00000,0.00486,98.50914
37.20000,1.85987,8153.73361,0.00000,0.00487,98.80140
37.30000,1.86501,8180.65926,0.00000,0.00489,99.12767
37.40000,1.86992,8204.95486,0.00000,0.00491,99.42206
37.50000,1.87506,8230.25256,0.00000,0.00493,99.72860
37.60000,1.87996,8255.72088,0.00000,0.00495,100.03721
37.70000,1.88504,8280.91875,0.00000,0.00496,100.34254
37.80000,1.88995,8305.58389,0.00000,0.00498,100.64142
37.90000,1.89503,8330.84881,0.00000,0.00500,100.94756
38.00000,1.89993,8356.08020,0.00000,0.00502,101.25330
38.10000,1.90495,8381.37418,0.00000,0.00503,101.55979
38.20000,1.90998,8407.98989,0.00000,0.00505,101.88230
38.30000,1.91494,8430.76482,0.00000,0.00506,102.15827
38.40000,1.92002,8458.25300,0.00000,0.00508,102.49136
38.50000,1.92492,8481.17396,0.00000,0.00510,102.76910
38.60000,1.93000,8509.48915,0.00000,0.00512,103.11220
38.70000,1.93491,8533.89204,0.00000,0.00514,103.40790
38.80000,1.94005,8560.31775,0.00000,0.00516,103.72811
38.90000,1.94489,8583.54941,0.00000,0.00517,104.00961
39.00000,1.95003,8610.69560,0.00000,0.00519,104.33855
39.10000,1.95482,8634.48456,0.00000,0.00521,104.62681
39.20000,1.96008,8662.07927,0.00000,0.00523,104.96119
39.30000,1.96492,8684.23730,0.00000,0.00524,105.22968
39.40000,1.97006,8710.73753,0.00000,0.00526,105.55079
39.50000,1.97491,8736.82648,0.00000,0.00528,105.86692
39.60000,1.97999,8763.37960,0.00000,0.00530,106.18867
39.70000,1.98489,8788.88518,0.00000,0.00532,106.49773
39.80000,1.99003,8813.82450,0.00000,0.00533,106.79993
39.90000,1.99494,8837.67456,0.00000,0.00535,107.08893
40.00000,2.00002,8864.19043,0.00000,0.00537,107.41023
40.10000,2.00492,8889.40021,0.00000,0.00539,107.71571
40.20000,2.01006,8914.81265,0.00000,0.00540,108.02364
40.30000,2.01497,8940.03361,0.00000,0.00542,108.32925
40.40000,2.01999,8964.68759,0.00000,0.00544,108.62799
40.50000,2.02495,8992.18470,0.00000,0.00546,108.96118
40.60000,2.02997,9017.81321,0.00000,0.00548,109.27173
40.70000,2.03499,9044.12419,0.00000,0.00550,109.59055
40.80000,2.04002,9068.52186,0.00000,0.00551,109.88618
40.90000,2.04504,9095.08169,0.00000,0.00553,110.20801
41.00000,2.04994,9120.30488,0.00000,0.00555,110.51365
41.10000,2.05508,9147.27151,0.00000,0.00557,110.84042
41.20000,2.05999,9171.31379,0.00000,0.00559,111.13174
41.30000,2.06507,9198.14035,0.00000,0.00561,111.45681
41.40000,2.06991,9221.18649,0.00000,0.00563,111.73607
41.50000,2.07505,9249.15150,0.00000,0.00564,112.07493
41.60000,2.07990,9272.00839,0.00000,0.00566,112.35189
41.70000,2.08510,9299.85419,0.00000,0.00568,112.68931
41.80000,2.08988,9324.20865,0.00000,0.00570,112.98442
41.90000,2.09502,9352.14758,0.00000,0.00572,113.32296
42.00000,2.09987,9377.31713,0.00000,0.00574,113.62795
42.10000,2.10507,9404.18467,0.00000,0.00576,113.95351
42.20000,2.10997,9429.67087,0.00000,0.00578,114.26234
42.30000,2.11505,9454.54240,0.00000,0.00580,114.56371
42.40000,2.11990,9480.82209,0.00000,0.00582,114.88215
42.50000,2.12504,9507.33572,0.00000,0.00583,115.20343
42.60000,2.12994,9532.35477,0.00000,0.00585,115.50659
42.70000,2.13502,9558.95558,0.00000,0.00587,115.82892
42.80000,2.13993,9585.31126,0.00000,0.00589,116.14828
42.90000,2.14495,9611.04855,0.00000,0.00591,116.46015
43.00000,2.14997,9638.52480,0.00000,0.00593,116.79309
43.10000,2.15499,9661.37573,0.00000,0.00595,117.06998
43.20000,2.16007,9688.04508,0.00000,0.00596,117.39314
43.30000,2.16498,9712.55824,0.00000,0.00598,117.69018
43.40000,2.17006,9739.27155,0.00000,0.00600,118.01387
43.50000,2.17490,9762.65520,0.00000,0.00602,118.29722
43.60000,2.18010,9789.88335,0.00000,0.00604,118.62715
43.70000,2.18495,9814.61108,0.00000,0.00605,118.92678
43.80000,2.19003,9840.91982,0.00000,0.00608,119.24557
43.90000,2.19481,9864.85481,0.00000,0.00609,119.53560
44.00000,2.20007,9892.75277,0.00000,0.00612,119.87365
44.10000,2.20492,9917.37098,0.00000,0.00613,120.17196
44.20000,2.21012,9945.17431,0.00000,0.00615,120.50886
44.30000,2.21496,9969.50567,0.00000,0.00617,120.80369
44.40000,2.22004,9996.18992,0.00000,0.00619,121.12703
44.50000,2.22495,10020.40952,0.00000,0.00621,121.42051
44.60000,2.23009,10047.02672,0.00000,0.00623,121.74304
44.70000,2.23493,10071.65536,0.00000,0.00625,122.04147
44.80000,2.24001,10098.33738,0.00000,0.00627,122.36478
44.90000,2.24492,10123.23946,0.00000,0.00628,122.66653
45.00000,2.25006,10148.17655,0.00000,0.00630,122.96870
45.10000,2.25496,10174.47114,0.00000,0.00632,123.28732
45.20000,2.26004,10199.20260,0.00000,0.00634,123.58700
45.30000,2.26501,10226.55442,0.00000,0.00636,123.91843
45.40000,2.27003,10251.66959,0.00000,0.00638,124.22276
45.50000,2.27505,10278.04464,0.00000,0.00640,124.54235
45.60000,2.28001,10301.72929,0.00000,0.00642,124.82935
45.70000,2.28498,10329.65109,0.00000,0.00644,125.16769
45.80000,2.28994,10354.16052,0.00000,0.00645,125.46468
45.90000,2.29502,10382.88996,0.00000,0.00648,125.81280
46.00000,2.29992,10406.50234,0.00000,0.00650,126.09892
46.10000,2.30506,10434.38017,0.00000,0.00651,126.43672
46.20000,2.30985,10458.92611,0.00000,0.00653,126.73415
46.30000,2.31505,10486.69815,0.00000,0.00656,127.07068
46.40000,2.31989,10511.56819,0.00000,0.00658,127.37203
46.50000,2.32509,10538.41412,0.00000,0.00660,127.69734
46.60000,2.32994,10562.02203,0.00000,0.00662,127.98340
46.70000,2.33502,10589.24049,0.00000,0.00664,128.31321
46.80000,2.33992,10614.87272,0.00000,0.00665,128.62381
46.90000,2.34500,10640.78882,0.00000,0.00668,128.93784
47.00000,2.34991,10666.24746,0.00000,0.00670,129.24633
47.10000,2.35499,10691.14730,0.00000,0.00671,129.54805
47.20000,2.35989,10717.22284,0.00000,0.00673,129.86402
47.30000,2.36491,10743.00930,0.00000,0.00676,130.17648
47.40000,2.36994,10769.31879,0.00000,0.00678,130.49528
47.50000,2.37502,10795.69384,0.00000,0.00680,130.81488
47.60000,2.37998,10823.03002,0.00000,0.00682,131.14612
47.70000,2.38494,10847.71901,0.00000,0.00683,131.44528
47.80000,2.38997,10874.78101,0.00000,0.00685,131.77320
47.90000,2.39499,10898.33826,0.00000,0.00687,132.05865
48.00000,2.40007,10926.86653,0.00000,0.00690,132.40434
48.10000,2.40497,10951.17927,0.00000,0.00691,132.69894
48.20000,2.41005,10978.36569,0.00000,0.00693,133.02837
48.30000,2.41496,11003.38101,0.00000,0.00695,133.33149
48.40000,2.42010,11030.17330,0.00000,0.00697,133.65614
48.50000,2.42494,11053.96375,0.00000,0.00699,133.94441
48.60000,2.43008,11081.25523,0.00000,0.00701,134.27511
48.70000,2.43493,11105.56722,0.00000,0.00703,134.56971
48.80000,2.44013,11131.91694,0.00000,0.00705,134.88900
48.90000,2.44497,11157.42475,0.00000,0.00707,135.19808
49.00000,2.45005,11182.88264,0.00000,0.00709,135.50657
49.10000,2.45496,11210.13463,0.00000,0.00711,135.83679
49.20000,2.46004,11237.74126,0.00000,0.00713,136.17131
49.30000,2.46494,11262.53977,0.00000,0.00715,136.47180
49.40000,2.47008,11288.70547,0.00000,0.00717,136.78886
49.50000,2.47487,11313.70962,0.00000,0.00719,137.09184
49.60000,2.48001,11340.54884,0.00000,0.00721,137.41706
49.70000,2.48497,11367.10346,0.00000,0.00723,137.73883
49.80000,2.49005,11393.14473,0.00000,0.00725,138.05438
49.90000,2.49502,11418.96173,0.00000,0.00727,138.36721
50.00000,2.49998,11445.18033,0.00000,0.00729,138.68491
50.10000,2.50494,11472.07171,0.00000,0.00731,139.01076
50.20000,2.50996,11496.77560,0.00000,0.00733,139.31011
50.30000,2.51505,11523.45240,0.00000,0.00735,139.63336
50.40000,2.51995,11547.15046,0.00000,0.00737,139.92052
50.50000,2.52497,11575.64446,0.00000,0.00739,140.26579
50.60000,2.52993,11600.53834,0.00000,0.00741,140.56743
50.70000,2.53507,11628.03769,0.00000,0.00743,140.90065
50.80000,2.53992,11652.92487,0.00000,0.00745,141.20222
50.90000,2.54506,11679.53536,0.00000,0.00747,141.52467
51.00000,2.54984,11705.69360,0.00000,0.00749,141.84163
51.10000,2.55504,11732.88077,0.00000,0.00751,142.17107
51.20000,2.55989,11757.52729,0.00000,0.00753,142.46972
51.30000,2.56509,11785.37682,0.00000,0.00755,142.80718
51.40000,2.56981,11810.07326,0.00000,0.00757,143.10644
51.50000,2.57501,11838.09787,0.00000,0.00759,143.44602
51.60000,2.57986,11864.13616,0.00000,0.00762,143.76153
51.70000,2.58506,11890.74516,0.00000,0.00764,144.08396
51.80000,2.58996,11915.83574,0.00000,0.00766,144.38799
51.90000,2.59504,11941.56334,0.00000,0.00768,144.69974
52.00000,2.59995,11967.39748,0.00000,0.00770,145.01278
52.10000,2.60503,11992.89560,0.00000,0.00772,145.32175
52.20000,2.60999,12019.54782,0.00000,0.00774,145.64471
52.30000,2.61501,12044.94387,0.00000,0.00776,145.95244
52.40000,2.62004,12072.52368,0.00000,0.00778,146.28663
52.50000,2.62500,12097.48238,0.00000,0.00780,146.58906
52.60000,2.63008,12125.37736,0.00000,0.00783,146.92708
52.70000,2.63504,12148.99346,0.00000,0.00784,147.21324
52.80000,2.64006,12176.66939,0.00000,0.00787,147.54860
52.90000,2.64491,12200.06943,0.00000,0.00788,147.83214
53.00000,2.65005,12228.17004,0.00000,0.00791,148.17265
53.10000,2.65495,12253.03635,0.00000,0.00793,148.47396
53.20000,2.66009,12280.25183,0.00000,0.00795,148.80374
53.30000,2.66494,12304.35669,0.00000,0.00796,149.09583
53.40000,2.67008,12332.11532,0.00000,0.00799,149.43219
53.50000,2.67492,12356.55770,0.00000,0.00801,149.72836
53.60000,2.68006,12384.05481,0.00000,0.00803,150.06155
53.70000,2.68497,12409.08653,0.00000,0.00805,150.36487
53.80000,2.69005,12436.00398,0.00000,0.00807,150.69104
53.90000,2.69489,12461.33745,0.00000,0.00809,150.99801
54.00000,2.70003,12488.14464,0.00000,0.00811,151.32284
54.10000,2.70500,12513.70013,0.00000,0.00813,151.63251
54.20000,2.71008,12539.41208,0.00000,0.00815,151.94407
54.30000,2.71492,12564.74853,0.00000,0.00817,152.25108
54.40000,2.72006,12591.72857,0.00000,0.00820,152.57800
54.50000,2.72491,12617.46287,0.00000,0.00821,152.88983
54.60000,2.73005,12643.80217,0.00000,0.00824,153.20900
54.70000,2.73495,12672.10245,0.00000,0.00826,153.55192
54.80000,2.73997,12696.43307,0.00000,0.00828,153.84674
54.90000,2.74500,12725.47990,0.00000,0.00830,154.19871
55.00000,2.74996,12749.23980,0.00000,0.00832,154.48662
55.10000,2.75504,12776.75331,0.00000,0.00834,154.82001
55.20000,2.75994,12800.13472,0.00000,0.00836,155.10333
55.30000,2.76502,12829.17708,0.00000,0.00838,155.45524
55.40000,2.76993,12852.95933,0.00000,0.00840,155.74342
55.50000,2.77507,12881.46079,0.00000,0.00842,156.08878
55.60000,2.77997,12905.82865,0.00000,0.00844,156.38405
55.70000,2.78505,12933.09033,0.00000,0.00846,156.71439
55.80000,2.78984,12958.18388,0.00000,0.00848,157.01846
55.90000,2.79504,12984.94488,0.00000,0.00851,157.34273
56.00000,2.79994,13009.91774,0.00000,0.00853,157.64533
56.10000,2.80502,13037.25094,0.00000,0.00855,157.97654
56.20000,2.80987,13062.70063,0.00000,0.00857,158.28492
56.30000,2.81501,13090.42424,0.00000,0.00859,158.62086
56.40000,2.81991,13115.88138,0.00000,0.00861,158.92933
56.50000,2.82505,13142.30710,0.00000,0.00864,159.24954
56.60000,2.82996,13167.39321,0.00000,0.00866,159.55352
56.70000,2.83498,13193.38828,0.00000,0.00868,159.86851
56.80000,2.84000,13220.90924,0.00000,0.00870,160.20199
56.90000,2.84496,13246.91921,0.00000,0.00872,160.51716
57.00000,2.84999,13273.59825,0.00000,0.00874,160.84044
57.10000,2.85501,13298.47723,0.00000,0.00876,161.14190
57.20000,2.85997,13325.79553,0.00000,0.00879,161.47293
57.30000,2.86499,13349.92349,0.00000,0.00881,161.76529
57.40000,2.87007,13376.23298,0.00000,0.00883,162.08409
57.50000,2.87504,13399.58757,0.00000,0.00885,162.36709
57.60000,2.88012,13426.03862,0.00000,0.00887,162.68760
57.70000,2.88496,13450.49739,0.00000,0.00889,162.98398
57.80000,2.89004,13479.10315,0.00000,0.00891,163.33060
57.90000,2.89495,13503.83610,0.00000,0.00893,163.63030
58.00000,2.90009,13530.82061,0.00000,0.00895,163.95728
58.10000,2.90487,13554.87406,0.00000,0.00897,164.24875
58.20000,2.91001,13582.77798,0.00000,0.00900,164.58687
58.30000,2.91486,13608.42139,0.00000,0.00902,164.89760
58.40000,2.92012,13635.53405,0.00000,0.00904,165.22613
58.50000,2.92496,13660.11798,0.00000,0.00906,165.52402
58.60000,2.93004,13686.97882,0.00000,0.00908,165.84950
58.70000,2.93489,13713.23317,0.00000,0.00910,166.16763
58.80000,2.94003,13739.40259,0.00000,0.00912,166.48474
58.90000,2.94493,13764.68390,0.00000,0.00914,166.79108
59.00000,2.95007,13790.97998,0.00000,0.00917,167.10972
59.10000,2.95492,13816.44607,0.00000,0.00919,167.41830
59.20000,2.96000,13842.26829,0.00000,0.00921,167.73119
59.30000,2.96496,13869.41671,0.00000,0.00923,168.06016
59.40000,2.97004,13895.04373,0.00000,0.00925,168.37069
59.50000,2.97501,13920.96877,0.00000,0.00927,168.68483
59.60000,2.97997,13945.89394,0.00000,0.00929,168.98686
59.70000,2.98499,13974.38794,0.00000,0.00931,169.33213
59.80000,2.99001,13997.79022,0.00000,0.00933,169.61570
59.90000,2.99504,14024.29193,0.00000,0.00935,169.93683
60.00000,2.99994,14048.26194,0.00000,0.00937,170.22728
60.10000,3.00502,14077.26258,0.00000,0.00940,170.57869
60.20000,3.00986,14101.16702,0.00000,0.00942,170.86835
60.30000,3.01506,14129.27359,0.00000,0.00944,171.20893
60.40000,3.01991,14153.26148,0.00000,0.00946,171.49960
60.50000,3.02505,14180.73773,0.00000,0.00948,171.83254
60.60000,3.02989,14204.79566,0.00000,0.00950,172.12405
60.70000,3.03509,14231.72802,0.00000,0.00952,172.45040
60.80000,3.03994,14256.48183,0.00000,0.00955,172.75035
60.90000,3.04508,14281.91215,0.00000,0.00957,173.05850
61.00000,3.04992,14307.94299,0.00000,0.00959,173.37392
61.10000,3.05500,14333.44781,0.00000,0.00961,173.68297
61.20000,3.05997,14359.47418,0.00000,0.00963,173.99834
61.30000,3.06505,14385.19061,0.00000,0.00965,174.30996
61.40000,3.06995,14410.11131,0.00000,0.00967,174.61193
61.50000,3.07497,14436.03486,0.00000,0.00970,174.92605
61.60000,3.07994,14461.63952,0.00000,0.00972,175.23631
61.70000,3.08502,14486.30542,0.00000,0.00974,175.53520
61.80000,3.09004,14516.05260,0.00000,0.00976,175.89565
61.90000,3.09500,14539.87956,0.00000,0.00979,176.18437
62.00000,3.09997,14567.61062,0.00000,0.00981,176.52040
62.10000,3.10499,14592.01723,0.00000,0.00983,176.81614
62.20000,3.11007,14618.08980,0.00000,0.00985,177.13207
62.30000,3.11509,14643.83751,0.00000,0.00987,177.44406
62.40000,3.12005,14669.54798,0.00000,0.00989,177.75561
62.50000,3.12496,14694.63259,0.00000,0.00992,178.05956
62.60000,3.13004,14723.04463,0.00000,0.00994,178.40384
62.70000,3.13494,14746.39177,0.00000,0.00996,178.68675
62.80000,3.14008,14773.87249,0.00000,0.00998,179.01974
62.90000,3.14493,14797.92744,0.00000,0.01000,179.31122
63.00000,3.15007,14825.75238,0.00000,0.01003,179.64838
63.10000,3.15497,14850.19475,0.00000,0.01005,179.94456
63.20000,3.16011,14876.76948,0.00000,0.01007,180.26657
63.30000,3.16490,14900.13897,0.00000,0.01009,180.54975
63.40000,3.17004,14928.56741,0.00000,0.01011,180.89423
63.50000,3.17488,14954.34344,0.00000,0.01013,181.20656
63.60000,3.18002,14980.37130,0.00000,0.01016,181.52195
63.70000,3.18493,15006.43641,0.00000,0.01018,181.83779
63.80000,3.19001,15030.43175,0.00000,0.01020,182.12855
63.90000,3.19491,15056.65928,0.00000,0.01022,182.44636
64.00000,3.20005,15084.00738,0.00000,0.01025,182.77774
64.10000,3.20502,15110.09932,0.00000,0.01026,183.09391
64.20000,3.21010,15134.89336,0.00000,0.01029,183.39434
64.30000,3.21494,15161.06874,0.00000,0.01030,183.71152
64.40000,3.21996,15185.84192,0.00000,0.01033,184.01170
64.50000,3.22499,15213.80693,0.00000,0.01035,184.35057
64.60000,3.23001,15237.26732,0.00000,0.01037,184.63484
64.70000,3.23503,15264.05960,0.00000,0.01039,184.95949
64.80000,3.23987,15287.17428,0.00000,0.01041,185.23958
64.90000,3.24495,15315.50139,0.00000,0.01044,185.58283
65.00000,3.24986,15339.47438,0.00000,0.01046,185.87332
65.10000,3.25506,15367.06090,0.00000,0.01048,186.20759
65.20000,3.25990,15390.25903,0.00000,0.01050,186.48869
65.30000,3.26510,15418.86777,0.00000,0.01052,186.83535
65.40000,3.26983,15441.69188,0.00000,0.01054,187.11192
65.50000,3.27503,15469.20389,0.00000,0.01057,187.44529
65.60000,3.27993,15495.31817,0.00000,0.01059,187.76173
65.70000,3.28501,15520.39832,0.00000,0.01061,188.06563
65.80000,3.28986,15545.39800,0.00000,0.01062,188.36856
65.90000,3.29500,15571.17254,0.00000,0.01065,188.68088
66.00000,3.29990,15596.57305,0.00000,0.01067,188.98866
66.10000,3.30504,15622.27905,0.00000,0.01069,189.30015
66.20000,3.30995,15647.44860,0.00000,0.01072,189.60514
66.30000,3.31503,15672.86998,0.00000,0.01074,189.91318
66.40000,3.31999,15699.46110,0.00000,0.01076,190.23539
66.50000,3.32501,15723.96457,0.00000,0.01078,190.53231
66.60000,3.33004,15751.13833,0.00000,0.01081,190.86158
66.70000,3.33500,15775.43169,0.00000,0.01083,191.15595
66.80000,3.33996,15803.44737,0.00000,0.01085,191.49543
66.90000,3.34498,15827.74222,0.00000,0.01087,191.78982
67.00000,3.35001,15854.73120,0.00000,0.01090,192.11685
67.10000,3.35497,15878.07238,0.00000,0.01092,192.39968
67.20000,3.36005,15905.19547,0.00000,0.01094,192.72834
67.30000,3.36495,15930.42463,0.00000,0.01096,193.03405
67.40000,3.37009,15958.51630,0.00000,0.01099,193.37445
67.50000,3.37500,15982.20915,0.00000,0.01100,193.66154
67.60000,3.38008,16009.55129,0.00000,0.01103,193.99285
67.70000,3.38486,16033.46169,0.00000,0.01105,194.28258
67.80000,3.39006,16061.87373,0.00000,0.01107,194.62686
67.90000,3.39491,16085.46078,0.00000,0.01109,194.91267
68.00000,3.40011,16112.35291,0.00000,0.01112,195.23853
68.10000,3.40495,16136.43616,0.00000,0.01114,195.53036
68.20000,3.41003,16163.03474,0.00000,0.01116,195.85266
68.30000,3.41488,16189.19224,0.00000,0.01118,196.16962
68.40000,3.42008,16214.05482,0.00000,0.01120,196.47089
68.50000,3.42498,16240.46862,0.00000,0.01123,196.79095
68.60000,3.43006,16265.13302,0.00000,0.01125,197.08982
68.70000,3.43491,16292.53477,0.00000,0.01127,197.42186
68.80000,3.43999,16317.95913,0.00000,0.01129,197.72993
68.90000,3.44495,16344.76781,0.00000,0.01132,198.05478
69.00000,3.44997,16368.67821,0.00000,0.01134,198.34451
69.10000,3.45494,16396.52252,0.00000,0.01136,198.68191
69.20000,3.45990,16421.19288,0.00000,0.01138,198.98085
69.30000,3.46498,16447.74079,0.00000,0.01141,199.30254
69.40000,3.46994,16471.37105,0.00000,0.01143,199.58887
69.50000,3.47503,16497.70290,0.00000,0.01145,199.90794
69.60000,3.47993,16520.95765,0.00000,0.01147,200.18973
69.70000,3.48501,16549.17002,0.00000,0.01149,200.53159
69.80000,3.48985,16572.39497,0.00000,0.01151,200.81301
69.90000,3.49511,16600.52687,0.00000,0.01154,201.15389
70.00000,3.49990,16624.27634,0.00000,0.01156,201.44167
70.10000,3.50498,16651.08353,0.00000,0.01158,201.76651
70.20000,3.50988,16675.63766,0.00000,0.01161,202.06404
70.30000,3.51502,16701.71618,0.00000,0.01163,202.38004
70.40000,3.51993,16726.62795,0.00000,0.01165,202.68190
70.50000,3.52501,16752.19089,0.00000,0.01167,202.99166
70.60000,3.52985,16777.84175,0.00000,0.01170,203.30248
70.70000,3.53499,16804.48353,0.00000,0.01172,203.62530
70.80000,3.53996,16829.83190,0.00000,0.01175,203.93246
70.90000,3.54504,16855.17132,0.00000,0.01176,204.23950
71.00000,3.54994,16880.75960,0.00000,0.01179,204.54956
71.10000,3.55502,16906.99160,0.00000,0.01181,204.86743
71.20000,3.55993,16933.62445,0.00000,0.01184,205.19014
71.30000,3.56507,16958.31567,0.00000,0.01185,205.48934
71.40000,3.57003,16984.95299,0.00000,0.01188,205.81211
71.50000,3.57505,17009.00942,0.00000,0.01190,206.10361
71.60000,3.58007,17036.39179,0.00000,0.01192,206.43541
71.70000,3.58504,17060.40055,0.00000,0.01194,206.72633
71.80000,3.59006,17086.39264,0.00000,0.01197,207.04129
71.90000,3.59496,17108.69968,0.00000,0.01199,207.31159
72.00000,3.59999,17136.30259,0.00000,0.01201,207.64606
72.10000,3.60489,17161.25607,0.00000,0.01204,207.94843
72.20000,3.61003,17188.90667,0.00000,0.01206,208.28348
72.30000,3.61493,17213.77522,0.00000,0.01208,208.58482
72.40000,3.62007,17241.03540,0.00000,0.01211,208.91514
72.50000,3.62480,17264.88918,0.00000,0.01212,209.20419
72.60000,3.63006,17291.79323,0.00000,0.01215,209.53019
72.70000,3.63490,17315.66042,0.00000,0.01217,209.81940
72.80000,3.64010,17343.19776,0.00000,0.01219,210.15308
72.90000,3.64489,17366.63133,0.00000,0.01221,210.43703
73.00000,3.65003,17393.90641,0.00000,0.01224,210.76753
73.10000,3.65487,17418.66469,0.00000,0.01226,211.06753
73.20000,3.66007,17444.03541,0.00000,0.01228,211.37496
73.30000,3.66498,17469.52981,0.00000,0.01230,211.68388
73.40000,3.67000,17494.20762,0.00000,0.01232,211.98291
73.50000,3.67490,17518.95696,0.00000,0.01235,212.28281
73.60000,3.67992,17542.87332,0.00000,0.01237,212.57261
73.70000,3.68495,17569.18281,0.00000,0.01239,212.89141
73.80000,3.68997,17592.68194,0.00000,0.01241,213.17615
73.90000,3.69499,17620.59778,0.00000,0.01244,213.51442
74.00000,3.69995,17644.47987,0.00000,0.01246,213.80381
74.10000,3.70504,17672.75631,0.00000,0.01248,214.14644
74.20000,3.71000,17695.25558,0.00000,0.01250,214.41907
74.30000,3.71508,17721.01671,0.00000,0.01253,214.73123
74.40000,3.71992,17745.09996,0.00000,0.01255,215.02305
74.50000,3.72501,17771.33644,0.00000,0.01257,215.34097
74.60000,3.72991,17795.73113,0.00000,0.01260,215.63657
74.70000,3.73511,17822.15685,0.00000,0.01262,215.95678
74.80000,3.73995,17845.75582,0.00000,0.01264,216.24273
74.90000,3.74509,17872.65390,0.00000,0.01266,216.56866
75.00000,3.74994,17896.97856,0.00000,0.01269,216.86341
75.10000,3.75520,17922.50425,0.00000,0.01271,217.17272
75.20000,3.75998,17946.09576,0.00000,0.01273,217.45858
75.30000,3.76500,17969.81543,0.00000,0.01276,217.74600
75.40000,3.76991,17995.32473,0.00000,0.01278,218.05511
75.50000,3.77505,18022.45826,0.00000,0.01281,218.38389
75.60000,3.77995,18046.10789,0.00000,0.01283,218.67046
75.70000,3.78503,18072.34436,0.00000,0.01285,218.98838
75.80000,3.78988,18096.63773,0.00000,0.01287,219.28275
75.90000,3.79496,18121.89370,0.00000,0.01290,219.58878
76.00000,3.79998,18147.87090,0.00000,0.01293,219.90356
76.10000,3.80506,18172.72305,0.00000,0.01295,220.20470
76.20000,3.81003,18199.53620,0.00000,0.01297,220.52960
76.30000,3.81499,18223.36316,0.00000,0.01299,220.81832
76.40000,3.81995,18250.67252,0.00000,0.01302,221.14924
76.50000,3.82497,18273.71418,0.00000,0.01304,221.42844
76.60000,3.83006,18301.59724,0.00000,0.01306,221.76631
76.70000,3.83496,18322.86119,0.00000,0.01309,222.02397
76.80000,3.83998,18349.53725,0.00000,0.01311,222.34721
76.90000,3.84488,18372.75177,0.00000,0.01313,222.62851
77.00000,3.85008,18398.81986,0.00000,0.01316,222.94439
77.10000,3.85499,18422.27429,0.00000,0.01318,223.22859
77.20000,3.86007,18448.73279,0.00000,0.01320,223.54920
77.30000,3.86491,18472.35411,0.00000,0.01322,223.83542
77.40000,3.87005,18498.48330,0.00000,0.01325,224.15204
77.50000,3.87490,18522.90481,0.00000,0.01327,224.44796
77.60000,3.88010,18548.52289,0.00000,0.01330,224.75839
77.70000,3.88488,18571.43193,0.00000,0.01331,225.03598
77.80000,3.88996,18597.07236,0.00000,0.01334,225.34667
77.90000,3.89487,18622.99591,0.00000,0.01336,225.66080
78.00000,3.90001,18648.46945,0.00000,0.01338,225.96947
78.10000,3.90491,18672.58400,0.00000,0.01340,226.26167
78.20000,3.90999,18697.57622,0.00000,0.01343,226.56451
78.30000,3.91490,18721.75187,0.00000,0.01345,226.85746
78.40000,3.92004,18746.80072,0.00000,0.01347,227.16098
78.50000,3.92500,18771.86894,0.00000,0.01349,227.46474
78.60000,3.93002,18794.65431,0.00000,0.01351,227.74084
78.70000,3.93505,18821.32143,0.00000,0.01354,228.06397
78.80000,3.93995,18843.72681,0.00000,0.01356,228.33547
78.90000,3.94503,18870.56828,0.00000,0.01359,228.66071
79.00000,3.94999,18892.70693,0.00000,0.01361,228.92897
79.10000,3.95507,18918.51872,0.00000,0.01363,229.24174
79.20000,3.95986,18941.26683,0.00000,0.01365,229.51739
79.30000,3.96506,18967.17399,0.00000,0.01368,229.83131
79.40000,3.96996,18989.69859,0.00000,0.01369,230.10425
79.50000,3.97516,19017.49671,0.00000,0.01372,230.44109
79.60000,3.97995,19039.45655,0.00000,0.01374,230.70719
79.70000,3.98503,19065.64385,0.00000,0.01376,231.02451
79.80000,3.98993,19090.53922,0.00000,0.01379,231.32617
79.90000,3.99507,19115.03524,0.00000,0.01382,231.62300
80.00000,3.99998,19138.84729,0.00000,0.01384,231.91153
80.10000,4.00500,19162.69958,0.00000,0.01386,232.20056
80.20000,4.00990,19186.54293,0.00000,0.01388,232.48948
80.30000,4.01504,19212.03882,0.00000,0.01391,232.79842
80.40000,4.02001,19236.35453,0.00000,0.01394,233.09306
80.50000,4.02515,19261.50471,0.00000,0.01396,233.39781
80.60000,4.02999,19285.85917,0.00000,0.01398,233.69292
80.70000,4.03501,19309.77553,0.00000,0.01401,233.98273
80.80000,4.03992,19335.36828,0.00000,0.01403,234.29284
80.90000,4.04506,19358.46955,0.00000,0.01405,234.57277
81.00000,4.04996,19384.48250,0.00000,0.01407,234.88798
81.10000,4.05492,19406.89683,0.00000,0.01410,235.15958
81.20000,4.05995,19435.70077,0.00000,0.01413,235.50860
81.30000,4.06491,19458.18961,0.00000,0.01414,235.78111
81.40000,4.07005,19485.04299,0.00000,0.01418,236.10650
81.50000,4.07495,19507.68381,0.00000,0.01420,236.38085
81.60000,4.07998,19533.95605,0.00000,0.01422,236.69919
81.70000,4.08488,19556.52535,0.00000,0.01424,236.97267
81.80000,4.09002,19581.59506,0.00000,0.01427,237.27645
81.90000,4.09492,19604.38937,0.00000,0.01429,237.55266
82.00000,4.10006,19629.20576,0.00000,0.01431,237.85337
82.10000,4.10485,19653.11766,0.00000,0.01434,238.14311
82.20000,4.11005,19679.99637,0.00000,0.01436,238.46881
82.30000,4.11495,19703.72349,0.00000,0.01438,238.75632
82.40000,4.12003,19727.59366,0.00000,0.01441,239.04556
82.50000,4.12488,19752.35790,0.00000,0.01443,239.34564
82.60000,4.13002,19776.51119,0.00000,0.01446,239.63831
82.70000,4.13492,19800.49461,0.00000,0.01448,239.92893
82.80000,4.14006,19823.89987,0.00000,0.01450,240.21254
82.90000,4.14497,19847.17697,0.00000,0.01453,240.49459
83.00000,4.14999,19870.30059,0.00000,0.01455,240.77479
83.10000,4.15495,19896.94089,0.00000,0.01457,241.09760
83.20000,4.15997,19919.76500,0.00000,0.01459,241.37416
83.30000,4.16506,19945.86885,0.00000,0.01462,241.69047
83.40000,4.17002,19967.84806,0.00000,0.01464,241.95680
83.50000,4.17498,19992.77323,0.00000,0.01466,242.25883
83.60000,4.17994,20015.46919,0.00000,0.01469,242.53384
83.70000,4.18508,20040.53593,0.00000,0.01471,242.83758
83.80000,4.18999,20062.70885,0.00000,0.01473,243.10626
83.90000,4.19507,20088.51618,0.00000,0.01475,243.41898
84.00000,4.19991,20111.12124,0.00000,0.01478,243.69289
84.10000,4.20505,20136.65140,0.00000,0.01480,244.00225
84.20000,4.20996,20159.34289,0.00000,0.01483,244.27721
84.30000,4.21516,20184.88199,0.00000,0.01485,244.58667
84.40000,4.21994,20206.06399,0.00000,0.01488,244.84334
84.50000,4.22502,20233.19304,0.00000,0.01490,245.17207
84.60000,4.22987,20255.70422,0.00000,0.01492,245.44485
84.70000,4.23507,20282.66788,0.00000,0.01495,245.77157
84.80000,4.23997,20305.83024,0.00000,0.01497,246.05224
84.90000,4.24499,20331.53325,0.00000,0.01500,246.36369
85.00000,4.24990,20355.53604,0.00000,0.01502,246.65454
85.10000,4.25504,20379.46135,0.00000,0.01504,246.94445
85.20000,4.25994,20402.83680,0.00000,0.01507,247.22770
85.30000,4.26508,20426.27633,0.00000,0.01509,247.51172
85.40000,4.26987,20449.63241,0.00000,0.01511,247.79474
85.50000,4.27501,20473.47575,0.00000,0.01514,248.08365
85.60000,4.27997,20497.96879,0.00000,0.01516,248.38044
85.70000,4.28499,20520.14917,0.00000,0.01518,248.64921
85.80000,4.28996,20545.13544,0.00000,0.01521,248.95198
85.90000,4.29498,20566.65123,0.00000,0.01522,249.21269
86.00000,4.30000,20592.74912,0.00000,0.01526,249.52893
86.10000,4.30502,20613.91473,0.00000,0.01528,249.78540
86.20000,4.31010,20639.00828,0.00000,0.01530,250.08947
86.30000,4.31495,20660.14409,0.00000,0.01532,250.34557
86.40000,4.32003,20686.03039,0.00000,0.01534,250.65925
86.50000,4.32487,20708.59671,0.00000,0.01537,250.93269
86.60000,4.33007,20734.98219,0.00000,0.01539,251.25241
86.70000,4.33492,20754.63980,0.00000,0.01541,251.49061
86.80000,4.34000,20778.95403,0.00000,0.01544,251.78523
86.90000,4.34484,20798.57588,0.00000,0.01546,252.02300
87.00000,4.35010,20822.52353,0.00000,0.01548,252.31318
87.04600,4.35250,20530.17616,0.00000,0.01555,248.77071
87.04800,4.35256,20052.38086,0.00000,0.01571,242.98111
87.05000,4.35273,19336.02393,0.00000,0.01600,234.30079
87.05200,4.35297,18456.39795,0.00000,0.01641,223.64208
87.05400,4.35327,17458.36884,0.00000,0.01686,211.54864
87.05600,4.35351,16365.32396,0.00000,0.01728,198.30387
87.05800,4.35399,15213.21386,0.00000,0.01760,184.34338
87.06000,4.35429,14035.20405,0.00000,0.01780,170.06906
87.06200,4.35453,12847.13298,0.00000,0.01780,155.67282
87.06400,4.35495,11661.52880,0.00000,0.01762,141.30647