File: scratch/college-stuff/ME Lab/ME lab Fall 2013/group15/group15.is_tens_RawData/Specimen_RawData_4.csv
Time,Extension,Load,Strain 2,Tensile strain,Tensile stress
(sec),(mm),(N),(mm/mm),(mm/mm),(MPa)
0.00000,0.00006,0.76979,0.00000,0.00000,0.00935
0.40000,0.01931,12.93260,0.00000,0.00000,0.15710
0.80000,0.04000,17.94348,0.00000,0.00000,0.21797
1.20000,0.06003,30.93250,0.00000,0.00000,0.37575
1.60000,0.08006,47.46101,0.00000,-0.00001,0.57653
2.00000,0.10009,67.12406,0.00000,-0.00001,0.81538
2.40000,0.12006,97.32629,0.00000,-0.00002,1.18226
2.80000,0.14009,119.66203,0.00000,-0.00004,1.45358
3.20000,0.16006,151.55823,0.00000,-0.00007,1.84103
3.60000,0.18003,218.60567,0.00000,-0.00008,2.65548
4.00000,0.19994,321.79521,0.00000,-0.00008,3.90896
4.40000,0.21979,458.32894,0.00000,-0.00008,5.56748
4.80000,0.23988,627.71617,0.00000,-0.00008,7.62509
5.20000,0.25996,827.16253,0.00000,-0.00007,10.04783
5.60000,0.27999,1060.85772,0.00000,-0.00005,12.88661
6.00000,0.30002,1325.47123,0.00000,-0.00002,16.10096
6.40000,0.32005,1604.56635,0.00000,0.00002,19.49122
6.80000,0.34002,1892.50968,0.00000,0.00005,22.98897
7.20000,0.36005,2167.48454,0.00000,0.00010,26.32919
7.60000,0.38002,2459.42567,0.00000,0.00014,29.87550
8.00000,0.39993,2751.54691,0.00000,0.00018,33.42400
8.40000,0.41996,3047.51210,0.00000,0.00023,37.01919
8.80000,0.43987,3339.80434,0.00000,0.00027,40.56976
9.20000,0.45984,3632.44303,0.00000,0.00032,44.12455
9.60000,0.47987,3923.42024,0.00000,0.00037,47.65915
10.00000,0.49990,4209.53743,0.00000,0.00041,51.13471
10.40000,0.51999,4487.58006,0.00000,0.00046,54.51219
10.80000,0.54002,4757.46654,0.00000,0.00051,57.79060
11.20000,0.56005,5023.05590,0.00000,0.00056,61.01680
11.60000,0.58008,5271.69667,0.00000,0.00060,64.03713
12.00000,0.60005,5480.00038,0.00000,0.00063,66.56747
12.40000,0.62002,5684.86825,0.00000,0.00067,69.05607
12.80000,0.63999,5894.64232,0.00000,0.00070,71.60427
13.20000,0.65990,6102.44907,0.00000,0.00074,74.12857
13.60000,0.67993,6314.15695,0.00000,0.00078,76.70026
14.00000,0.69990,6523.48846,0.00000,0.00081,79.24308
14.40000,0.71993,6733.74385,0.00000,0.00085,81.79713
14.80000,0.73989,6942.07475,0.00000,0.00088,84.32779
15.20000,0.75998,7149.99065,0.00000,0.00092,86.85342
15.60000,0.78007,7353.87057,0.00000,0.00096,89.33002
16.00000,0.80004,7555.26647,0.00000,0.00099,91.77645
16.40000,0.82007,7752.78360,0.00000,0.00102,94.17576
16.80000,0.83998,7949.37313,0.00000,0.00106,96.56380
17.20000,0.86001,8139.16698,0.00000,0.00109,98.86929
17.60000,0.87992,8319.79960,0.00000,0.00112,101.06350
18.00000,0.89989,8505.65434,0.00000,0.00115,103.32114
18.40000,0.91986,8690.94729,0.00000,0.00118,105.57196
18.80000,0.93989,8878.76749,0.00000,0.00121,107.85347
19.20000,0.95992,9069.46585,0.00000,0.00125,110.16995
19.60000,0.97995,9257.06774,0.00000,0.00128,112.44882
20.00000,0.99992,9447.64614,0.00000,0.00132,114.76384
20.40000,1.02007,9637.11366,0.00000,0.00135,117.06537
20.80000,1.04010,9829.00485,0.00000,0.00138,119.39634
21.20000,1.06007,10019.36272,0.00000,0.00141,121.70868
21.60000,1.08004,10212.69560,0.00000,0.00145,124.05716
22.00000,1.09995,10407.65643,0.00000,0.00148,126.42542
22.40000,1.11992,10600.25766,0.00000,0.00152,128.76501
22.80000,1.13989,10794.02789,0.00000,0.00155,131.11881
23.20000,1.15992,10990.81784,0.00000,0.00158,133.50928
23.60000,1.17995,11188.59947,0.00000,0.00162,135.91180
24.00000,1.19998,11389.02977,0.00000,0.00166,138.34650
24.40000,1.21988,11586.00003,0.00000,0.00169,140.73917
24.80000,1.24003,11785.20620,0.00000,0.00173,143.15899
25.20000,1.26000,11983.75076,0.00000,0.00177,145.57078
25.60000,1.28009,12182.89062,0.00000,0.00181,147.98980
26.00000,1.30006,12385.82432,0.00000,0.00184,150.45491
26.40000,1.31997,12585.06328,0.00000,0.00188,152.87513
26.80000,1.33994,12787.31227,0.00000,0.00191,155.33192
27.20000,1.35991,12990.11409,0.00000,0.00195,157.79543
27.60000,1.37994,13191.94138,0.00000,0.00199,160.24709
28.00000,1.39997,13392.91334,0.00000,0.00202,162.68837
28.40000,1.41994,13597.39453,0.00000,0.00206,165.17227
28.80000,1.43991,13801.39142,0.00000,0.00210,167.65030
29.20000,1.45994,14008.25083,0.00000,0.00214,170.16309
29.60000,1.47997,14213.91964,0.00000,0.00218,172.66142
30.00000,1.50000,14417.57083,0.00000,0.00222,175.13524
30.40000,1.52009,14623.12788,0.00000,0.00226,177.63221
30.80000,1.54000,14829.68330,0.00000,0.00230,180.14131
31.20000,1.56003,15035.78126,0.00000,0.00234,182.64486
31.60000,1.58000,15240.64988,0.00000,0.00238,185.13347
32.00000,1.59991,15446.10113,0.00000,0.00242,187.62916
32.40000,1.62000,15657.50986,0.00000,0.00246,190.19721
32.80000,1.63997,15862.76889,0.00000,0.00250,192.69056
33.20000,1.65994,16069.31090,0.00000,0.00254,195.19950
33.60000,1.67997,16277.54569,0.00000,0.00258,197.72900
34.00000,1.69987,16488.67279,0.00000,0.00262,200.29364
34.40000,1.71996,16699.18895,0.00000,0.00266,202.85085
34.80000,1.73999,16904.83987,0.00000,0.00271,205.34896
35.20000,1.76008,17112.56504,0.00000,0.00275,207.87227
35.60000,1.78005,17322.49707,0.00000,0.00279,210.42239
36.00000,1.80002,17531.51119,0.00000,0.00283,212.96136
36.40000,1.81999,17740.05741,0.00000,0.00288,215.49464
36.80000,1.84002,17948.80927,0.00000,0.00293,218.03042
37.20000,1.85993,18157.51642,0.00000,0.00298,220.56566
37.60000,1.87984,18365.02701,0.00000,0.00301,223.08636
38.00000,1.89993,18574.53734,0.00000,0.00306,225.63136
38.40000,1.91990,18782.52476,0.00000,0.00311,228.15785
38.80000,1.93993,18989.73882,0.00000,0.00316,230.67495
39.20000,1.95996,19196.28531,0.00000,0.00321,233.18394
39.60000,1.97999,19401.05557,0.00000,0.00326,235.67136
40.00000,2.00008,19602.94247,0.00000,0.00331,238.12375
40.40000,2.02011,19802.13374,0.00000,0.00337,240.54340
40.80000,2.04002,20000.89586,0.00000,0.00342,242.95783
41.20000,2.05999,20196.92361,0.00000,0.00348,245.33905
41.60000,2.07996,20388.17257,0.00000,0.00353,247.66221
42.00000,2.09993,20575.50251,0.00000,0.00358,249.93778
42.40000,2.11990,20759.91482,0.00000,0.00364,252.17790
42.80000,2.13993,20943.33023,0.00000,0.00370,254.40591
43.20000,2.15996,21124.97538,0.00000,0.00377,256.61241
43.60000,2.17992,21298.37722,0.00000,0.00383,258.71879
44.00000,2.20001,21466.29244,0.00000,0.00390,260.75851
44.40000,2.22004,21626.31452,0.00000,0.00397,262.70235
44.80000,2.24001,21775.51538,0.00000,0.00404,264.51475
45.20000,2.25998,21919.92104,0.00000,0.00412,266.26889
45.60000,2.28013,22056.89400,0.00000,0.00420,267.93275
46.00000,2.30004,22184.73703,0.00000,0.00429,269.48571
46.40000,2.31995,22299.19285,0.00000,0.00439,270.87604
46.80000,2.33992,22405.10881,0.00000,0.00449,272.16264
47.20000,2.35983,22501.27941,0.00000,0.00460,273.33086
47.60000,2.37992,22591.02464,0.00000,0.00471,274.42102
48.00000,2.39995,22671.32998,0.00000,0.00483,275.39652
48.40000,2.41998,22742.55455,0.00000,0.00496,276.26171
48.80000,2.44001,22808.46834,0.00000,0.00510,277.06239
49.20000,2.46004,22862.59681,0.00000,0.00524,277.71990
49.60000,2.48001,22915.49742,0.00000,0.00539,278.36251
50.00000,2.50004,22961.04282,0.00000,0.00555,278.91576
50.40000,2.52013,23006.05327,0.00000,0.00571,279.46252
50.80000,2.54004,23040.51071,0.00000,0.00588,279.88109
51.20000,2.56001,23077.48348,0.00000,0.00605,280.33021
51.60000,2.57992,23109.33769,0.00000,0.00624,280.71715
52.00000,2.59989,23139.18173,0.00000,0.00643,281.07968
52.40000,2.61998,23167.57143,0.00000,0.00661,281.42454
52.80000,2.63995,23194.23407,0.00000,0.00682,281.74842
53.20000,2.65997,23220.40200,0.00000,0.00702,282.06629
53.60000,2.68000,23243.73871,0.00000,0.00722,282.34977
54.00000,2.69997,23265.05333,0.00000,0.00742,282.60868
54.40000,2.72012,23282.06897,0.00000,0.00762,282.81538
54.80000,2.74009,23302.39415,0.00000,0.00784,283.06228
55.20000,2.76012,23320.65701,0.00000,0.00805,283.28412
55.60000,2.78003,23337.04978,0.00000,0.00826,283.48325
56.00000,2.79994,23354.46030,0.00000,0.00847,283.69474
56.40000,2.81991,23368.91294,0.00000,0.00869,283.87030
56.80000,2.83982,23382.60561,0.00000,0.00890,284.03663
57.20000,2.85985,23400.32309,0.00000,0.00912,284.25185
57.60000,2.87994,23414.86365,0.00000,0.00934,284.42848
58.00000,2.90003,23431.96124,0.00000,0.00956,284.63617
58.40000,2.92006,23446.10244,0.00000,0.00978,284.80795
58.80000,2.94009,23458.13364,0.00000,0.01001,284.95410
59.20000,2.96006,23469.41978,0.00000,0.01022,285.09119
59.60000,2.98009,23481.60148,0.00000,0.01044,285.23917
60.00000,3.00012,23494.18700,0.00000,0.01066,285.39205
60.40000,3.02003,23506.05726,0.00000,0.01088,285.53624
60.80000,3.04000,23516.95746,0.00000,0.01110,285.66865
61.20000,3.05991,23529.87975,0.00000,0.01133,285.82562
61.60000,3.07982,23538.83237,0.00000,0.01154,285.93437
62.00000,3.09997,23552.17487,0.00000,0.01177,286.09645
62.40000,3.12005,23564.11517,0.00000,0.01199,286.24149
62.80000,3.14002,23577.26544,0.00000,0.01221,286.40123
63.20000,3.16011,23587.13895,0.00000,0.01243,286.52117
63.60000,3.18014,23598.10174,0.00000,0.01265,286.65434
64.00000,3.20005,23608.21515,0.00000,0.01286,286.77719
64.40000,3.22002,23618.07525,0.00000,0.01309,286.89696
64.80000,3.24005,23626.46013,0.00000,0.01331,286.99882
65.20000,3.26008,23636.45732,0.00000,0.01352,287.12026
65.60000,3.27993,23644.98824,0.00000,0.01374,287.22388
66.00000,3.29990,23655.58445,0.00000,0.01396,287.35260
66.40000,3.31987,23666.46826,0.00000,0.01418,287.48481
66.80000,3.33996,23675.65930,0.00000,0.01440,287.59646
67.20000,3.35999,23684.87120,0.00000,0.01462,287.70836
67.60000,3.38008,23696.47622,0.00000,0.01483,287.84933
68.00000,3.40005,23705.34241,0.00000,0.01504,287.95703
68.40000,3.42008,23717.45408,0.00000,0.01527,288.10415
68.80000,3.44005,23724.63942,0.00000,0.01548,288.19144
69.20000,3.46002,23733.65015,0.00000,0.01569,288.30089
69.60000,3.48011,23743.56091,0.00000,0.01591,288.42128
70.00000,3.50008,23751.25289,0.00000,0.01612,288.51472
70.40000,3.51993,23760.78665,0.00000,0.01634,288.63053
70.80000,3.53996,23767.87961,0.00000,0.01656,288.71669
71.20000,3.55993,23777.75013,0.00000,0.01676,288.83659
71.60000,3.57990,23786.64613,0.00000,0.01698,288.94465
72.00000,3.59999,23797.55676,0.00000,0.01719,289.07719
72.40000,3.62001,23807.08307,0.00000,0.01741,289.19291
72.80000,3.64004,23815.82260,0.00000,0.01762,289.29907
73.20000,3.66007,23825.52922,0.00000,0.01783,289.41698
73.60000,3.68004,23834.49227,0.00000,0.01804,289.52586
74.00000,3.70001,23840.92957,0.00000,0.01826,289.60405
74.40000,3.72004,23848.90467,0.00000,0.01847,289.70093
74.80000,3.74001,23857.69337,0.00000,0.01867,289.80769
75.20000,3.75992,23866.07379,0.00000,0.01888,289.90949
75.60000,3.77989,23874.78203,0.00000,0.01909,290.01527
76.00000,3.79986,23881.38920,0.00000,0.01931,290.09553
76.40000,3.81995,23890.53553,0.00000,0.01952,290.20663
76.80000,3.83992,23899.83982,0.00000,0.01973,290.31966
77.20000,3.86007,23911.39716,0.00000,0.01994,290.46005
77.60000,3.88004,23919.45273,0.00000,0.02014,290.55790
78.00000,3.90007,23928.33233,0.00000,0.02035,290.66576
78.40000,3.92004,23936.92583,0.00000,0.02056,290.77015
78.80000,3.94001,23942.98464,0.00000,0.02077,290.84375
79.20000,3.95998,23949.56499,0.00000,0.02098,290.92368
79.60000,3.98007,23957.51625,0.00000,0.02118,291.02027
80.00000,3.99998,23966.77285,0.00000,0.02139,291.13271
80.40000,4.01989,23972.58729,0.00000,0.02159,291.20334
80.80000,4.03998,23983.76763,0.00000,0.02180,291.33916
81.20000,4.05989,23989.76982,0.00000,0.02200,291.41207
81.60000,4.07998,23998.52276,0.00000,0.02221,291.51839
82.00000,4.10006,24008.32325,0.00000,0.02242,291.63744
82.40000,4.12009,24018.04179,0.00000,0.02262,291.75550
82.80000,4.14012,24025.94686,0.00000,0.02283,291.85152
83.20000,4.16003,24030.67946,0.00000,0.02302,291.90901
83.60000,4.17994,24037.85586,0.00000,0.02322,291.99618
84.00000,4.19997,24045.75050,0.00000,0.02342,292.09208
84.40000,4.22006,24052.89859,0.00000,0.02363,292.17891
84.80000,4.23997,24058.99614,0.00000,0.02384,292.25298
85.20000,4.26000,24066.87289,0.00000,0.02404,292.34866
85.60000,4.27991,24075.47981,0.00000,0.02424,292.45322
86.00000,4.29994,24085.53809,0.00000,0.02444,292.57540
86.40000,4.31997,24092.54760,0.00000,0.02464,292.66054
86.80000,4.34006,24101.36312,0.00000,0.02484,292.76763
87.20000,4.36009,24109.82251,0.00000,0.02504,292.87039
87.60000,4.38006,24117.25968,0.00000,0.02524,292.96073
88.00000,4.39997,24125.47469,0.00000,0.02544,293.06052
88.40000,4.42000,24131.83749,0.00000,0.02564,293.13781
88.80000,4.43997,24136.32125,0.00000,0.02584,293.19228
89.20000,4.46006,24145.45268,0.00000,0.02603,293.30320
89.60000,4.48003,24153.87034,0.00000,0.02623,293.40545
90.00000,4.49994,24160.96032,0.00000,0.02643,293.49158
90.40000,4.51997,24169.51954,0.00000,0.02663,293.59555
90.80000,4.53994,24176.83601,0.00000,0.02683,293.68442
91.20000,4.55996,24185.79161,0.00000,0.02703,293.79321
91.60000,4.58005,24194.36872,0.00000,0.02722,293.89740
92.00000,4.60014,24201.27988,0.00000,0.02742,293.98135
92.40000,4.62005,24207.93772,0.00000,0.02762,294.06223
92.80000,4.64002,24215.16478,0.00000,0.02782,294.15002
93.20000,4.65999,24221.18336,0.00000,0.02801,294.22313
93.60000,4.68002,24226.01879,0.00000,0.02820,294.28186
94.00000,4.70005,24231.80044,0.00000,0.02840,294.35210
94.40000,4.71996,24239.56841,0.00000,0.02859,294.44646
94.80000,4.73993,24247.82068,0.00000,0.02879,294.54670
95.20000,4.75990,24255.69743,0.00000,0.02898,294.64238
95.60000,4.77993,24262.78591,0.00000,0.02917,294.72849
96.00000,4.79996,24269.57488,0.00000,0.02937,294.81096
96.40000,4.82005,24278.18924,0.00000,0.02956,294.91560
96.80000,4.84008,24285.15851,0.00000,0.02976,295.00026
97.20000,4.86017,24291.06981,0.00000,0.02995,295.07206
97.60000,4.88002,24295.14825,0.00000,0.03014,295.12160
98.00000,4.89999,24301.62579,0.00000,0.03033,295.20029
98.40000,4.92002,24308.30002,0.00000,0.03052,295.28136
98.80000,4.93999,24314.60917,0.00000,0.03072,295.35800
99.20000,4.96002,24321.69765,0.00000,0.03091,295.44411
99.60000,4.97993,24327.83544,0.00000,0.03110,295.51867
100.00000,4.99990,24336.84319,0.00000,0.03128,295.62809
100.40000,5.01993,24345.61551,0.00000,0.03147,295.73465
100.80000,5.03996,24350.50905,0.00000,0.03166,295.79409
101.20000,5.06004,24357.22351,0.00000,0.03185,295.87565
101.60000,5.08013,24363.73532,0.00000,0.03205,295.95475
102.00000,5.10004,24369.20106,0.00000,0.03223,296.02115
102.40000,5.12001,24376.34170,0.00000,0.03241,296.10789
102.80000,5.13998,24382.11143,0.00000,0.03259,296.17798
103.20000,5.16001,24387.98547,0.00000,0.03279,296.24933
103.60000,5.17992,24395.23041,0.00000,0.03297,296.33734
104.00000,5.19995,24401.65430,0.00000,0.03316,296.41537
104.40000,5.21992,24407.07237,0.00000,0.03335,296.48119
104.80000,5.23989,24414.29049,0.00000,0.03353,296.56887
105.20000,5.25986,24420.91256,0.00000,0.03372,296.64931
105.60001,5.27995,24428.27225,0.00000,0.03391,296.73871
106.00001,5.30004,24432.96164,0.00000,0.03409,296.79567
106.40001,5.32007,24436.62137,0.00000,0.03426,296.84013
106.80001,5.34010,24445.05394,0.00000,0.03444,296.94256
107.20001,5.36007,24450.82217,0.00000,0.03463,297.01263
107.60001,5.38004,24456.94655,0.00000,0.03482,297.08702
108.00001,5.40001,24459.62578,0.00000,0.03500,297.11957
108.40001,5.41998,24464.24663,0.00000,0.03518,297.17570
108.80001,5.43995,24471.59737,0.00000,0.03535,297.26499
109.20001,5.45998,24479.39962,0.00000,0.03553,297.35977
109.60001,5.47989,24484.98309,0.00000,0.03571,297.42759
110.00001,5.49992,24489.25525,0.00000,0.03589,297.47949
110.40001,5.51994,24495.67914,0.00000,0.03607,297.55752
110.80001,5.53997,24501.24919,0.00000,0.03625,297.62518
111.20001,5.56012,24508.21847,0.00000,0.03643,297.70984
111.60001,5.58009,24514.21618,0.00000,0.03660,297.78270
112.00001,5.60006,24519.88310,0.00000,0.03678,297.85154
112.40001,5.62003,24525.68561,0.00000,0.03695,297.92202
112.80001,5.63994,24529.87731,0.00000,0.03713,297.97294
113.20001,5.65991,24533.26285,0.00000,0.03730,298.01406
113.60001,5.68000,24538.47229,0.00000,0.03748,298.07735
114.00001,5.69991,24545.24636,0.00000,0.03765,298.15963
114.40001,5.71988,24552.94281,0.00000,0.03783,298.25312
114.80001,5.73997,24559.98361,0.00000,0.03801,298.33865
115.20001,5.76000,24564.76837,0.00000,0.03818,298.39677
115.60001,5.78015,24569.73642,0.00000,0.03835,298.45712
116.00001,5.80018,24575.61195,0.00000,0.03852,298.52849
116.40001,5.82009,24580.98233,0.00000,0.03869,298.59373
116.80001,5.84012,24586.56728,0.00000,0.03887,298.66157
117.20001,5.86003,24592.07177,0.00000,0.03905,298.72844
117.60001,5.87994,24595.70318,0.00000,0.03922,298.77255
118.00001,5.89991,24599.39122,0.00000,0.03939,298.81735
118.40001,5.91988,24603.76173,0.00000,0.03956,298.87044
118.80001,5.93997,24609.83396,0.00000,0.03973,298.94420
119.20001,5.96000,24617.14149,0.00000,0.03989,299.03297
119.60001,5.97997,24622.39116,0.00000,0.04007,299.09674
120.00001,6.00006,24629.66591,0.00000,0.04024,299.18511
120.40001,6.02008,24632.80112,0.00000,0.04041,299.22319
120.80001,6.04011,24637.39812,0.00000,0.04058,299.27903
121.20001,6.06014,24644.72502,0.00000,0.04075,299.36803
121.60001,6.08005,24649.64092,0.00000,0.04092,299.42775
122.00001,6.09996,24652.99666,0.00000,0.04110,299.46851
122.40001,6.11999,24655.58648,0.00000,0.04126,299.49997
122.80001,6.13990,24660.01660,0.00000,0.04144,299.55379
123.20001,6.15993,24664.50930,0.00000,0.04160,299.60836
123.60001,6.17996,24671.87941,0.00000,0.04177,299.69789
124.00001,6.19993,24676.06068,0.00000,0.04194,299.74868
124.40001,6.22002,24684.54391,0.00000,0.04212,299.85173
124.80001,6.23999,24688.75796,0.00000,0.04229,299.90292
125.20001,6.26002,24694.25648,0.00000,0.04245,299.96971
125.60001,6.28011,24698.64339,0.00000,0.04262,300.02300
126.00001,6.30020,24703.72319,0.00000,0.04279,300.08471
126.40001,6.32005,24706.30705,0.00000,0.04296,300.11609
126.80001,6.33996,24710.04575,0.00000,0.04313,300.16151
127.20001,6.35993,24714.00350,0.00000,0.04330,300.20958
127.60001,6.37990,24719.13099,0.00000,0.04347,300.27187
128.00001,6.39999,24723.47617,0.00000,0.04364,300.32465
128.40001,6.41996,24728.89423,0.00000,0.04380,300.39047
128.80001,6.43999,24736.13620,0.00000,0.04397,300.47844
129.20001,6.45996,24740.63337,0.00000,0.04415,300.53307
129.60001,6.47998,24746.22428,0.00000,0.04431,300.60098
130.00001,6.50007,24750.29528,0.00000,0.04449,300.65043
130.40001,6.52004,24753.20250,0.00000,0.04464,300.68575
130.80001,6.54013,24758.83216,0.00000,0.04481,300.75413
131.20001,6.56004,24763.02832,0.00000,0.04498,300.80511
131.60001,6.58001,24764.08929,0.00000,0.04515,300.81799
132.00001,6.59992,24768.39423,0.00000,0.04532,300.87029
132.40001,6.61983,24774.09840,0.00000,0.04549,300.93958
132.80001,6.63986,24777.77004,0.00000,0.04565,300.98418
133.20001,6.66001,24784.91068,0.00000,0.04582,301.07092
133.60001,6.68004,24789.12920,0.00000,0.04598,301.12216
134.00001,6.69995,24795.36980,0.00000,0.04616,301.19797
134.40001,6.72004,24800.10241,0.00000,0.04632,301.25546
134.80001,6.74001,24803.20334,0.00000,0.04649,301.29313
135.20001,6.76004,24804.44312,0.00000,0.04665,301.30819
135.60001,6.78007,24809.85671,0.00000,0.04682,301.37395
136.00001,6.80004,24813.45534,0.00000,0.04698,301.41766
136.40001,6.81995,24816.14500,0.00000,0.04714,301.45033
136.80001,6.83992,24819.11927,0.00000,0.04731,301.48646
137.20001,6.85983,24823.95023,0.00000,0.04748,301.54515
137.60001,6.87992,24830.48588,0.00000,0.04764,301.62454
138.00001,6.90001,24834.59860,0.00000,0.04781,301.67449
138.40001,6.92004,24839.18369,0.00000,0.04797,301.73019
138.80001,6.94001,24844.14428,0.00000,0.04814,301.79045
139.20001,6.95997,24848.63102,0.00000,0.04830,301.84495
139.60001,6.98000,24853.61844,0.00000,0.04847,301.90554
140.00001,7.00003,24856.82368,0.00000,0.04864,301.94447
140.40001,7.02006,24856.46605,0.00000,0.04880,301.94013
140.80001,7.04009,24862.38331,0.00000,0.04896,302.01201
141.20001,7.06000,24866.08177,0.00000,0.04913,302.05693
141.60001,7.07997,24871.20181,0.00000,0.04929,302.11913
142.00001,7.09994,24873.93916,0.00000,0.04946,302.15238
142.40001,7.11991,24874.94797,0.00000,0.04962,302.16463
142.80001,7.13994,24881.90681,0.00000,0.04979,302.24916
143.20001,7.16003,24887.98201,0.00000,0.04995,302.32296
143.60001,7.18000,24891.37948,0.00000,0.05012,302.36423
144.00001,7.20003,24894.06914,0.00000,0.05029,302.39690
144.40001,7.22000,24895.28209,0.00000,0.05045,302.41164
144.80001,7.24003,24900.00427,0.00000,0.05061,302.46900
145.20001,7.26006,24903.30935,0.00000,0.05077,302.50915
145.60001,7.28009,24905.50876,0.00000,0.05093,302.53587
146.00001,7.30000,24908.42342,0.00000,0.05109,302.57127
146.40001,7.32003,24913.85341,0.00000,0.05126,302.63723
146.80001,7.33994,24916.13328,0.00000,0.05142,302.66492
147.20001,7.35991,24917.01692,0.00000,0.05159,302.67566
147.60001,7.37994,24920.57532,0.00000,0.05175,302.71888
148.00001,7.39997,24925.82947,0.00000,0.05190,302.78271
148.40001,7.42000,24933.13849,0.00000,0.05206,302.87149
148.80001,7.44003,24935.75066,0.00000,0.05222,302.90322
149.20001,7.45999,24936.45698,0.00000,0.05238,302.91180
149.60001,7.48002,24938.52675,0.00000,0.05254,302.93695
150.00001,7.49999,24943.43221,0.00000,0.05270,302.99653
150.40001,7.52008,24947.12472,0.00000,0.05286,303.04139
150.80001,7.54005,24950.92452,0.00000,0.05302,303.08755
151.20001,7.56002,24953.44281,0.00000,0.05318,303.11814
151.60001,7.57987,24954.81968,0.00000,0.05334,303.13486
152.00001,7.59990,24959.12611,0.00000,0.05349,303.18717
152.40001,7.61987,24961.26592,0.00000,0.05365,303.21317
152.80001,7.63996,24964.31917,0.00000,0.05380,303.25026
153.20001,7.66005,24971.45683,0.00000,0.05396,303.33696
153.60001,7.68008,24974.64418,0.00000,0.05412,303.37568
154.00001,7.70005,24977.93138,0.00000,0.05428,303.41561
154.40001,7.72002,24978.14745,0.00000,0.05444,303.41823
154.80001,7.73999,24980.26043,0.00000,0.05460,303.44390
155.20001,7.76008,24984.91406,0.00000,0.05475,303.50043
155.60001,7.78011,24989.72267,0.00000,0.05490,303.55884
156.00001,7.79996,24989.56472,0.00000,0.05506,303.55692
156.40001,7.81993,24992.36763,0.00000,0.05521,303.59097
156.80001,7.83984,24994.41803,0.00000,0.05537,303.61588
157.20001,7.85987,24999.04782,0.00000,0.05553,303.67212
157.60001,7.88002,25003.05772,0.00000,0.05568,303.72083
158.00001,7.90005,25007.97510,0.00000,0.05584,303.78056
158.40001,7.92007,25010.23412,0.00000,0.05600,303.80800
158.80001,7.94004,25014.62996,0.00000,0.05615,303.86140
159.20001,7.96001,25018.54599,0.00000,0.05630,303.90897
159.60001,7.98004,25020.69175,0.00000,0.05646,303.93503
160.00001,8.00007,25022.50969,0.00000,0.05662,303.95712
160.40001,8.02004,25024.21737,0.00000,0.05677,303.97786
160.80001,8.03995,25028.86653,0.00000,0.05693,304.03433
161.20001,8.05986,25030.28810,0.00000,0.05708,304.05160
161.60001,8.07989,25032.66931,0.00000,0.05724,304.08053
162.00001,8.09986,25035.03263,0.00000,0.05740,304.10924
162.40001,8.12001,25038.70726,0.00000,0.05756,304.15387
162.80001,8.14004,25045.36211,0.00000,0.05772,304.23471
163.20001,8.16007,25047.74928,0.00000,0.05787,304.26371
163.60001,8.18004,25049.80266,0.00000,0.05803,304.28865
164.00001,8.20007,25052.93190,0.00000,0.05818,304.32667
164.40001,8.22004,25054.12400,0.00000,0.05834,304.34115
164.80001,8.24007,25056.82111,0.00000,0.05850,304.37391
165.20001,8.26010,25058.73144,0.00000,0.05866,304.39711
165.60001,8.28001,25062.30175,0.00000,0.05882,304.44048
166.00001,8.29992,25063.55047,0.00000,0.05897,304.45565
166.40001,8.31983,25063.52365,0.00000,0.05913,304.45533
166.80001,8.33986,25067.74366,0.00000,0.05929,304.50659
167.20001,8.36001,25071.63882,0.00000,0.05945,304.55390
167.60001,8.38009,25076.30587,0.00000,0.05960,304.61060
168.00001,8.40007,25079.70631,0.00000,0.05976,304.65190
168.40001,8.42009,25081.89976,0.00000,0.05992,304.67855
168.80001,8.44006,25083.28557,0.00000,0.06007,304.69538
169.20001,8.46003,25083.66704,0.00000,0.06023,304.70002
169.60001,8.48000,25087.66353,0.00000,0.06039,304.74856
170.00001,8.50003,25088.82284,0.00000,0.06055,304.76264
170.40001,8.51994,25090.70933,0.00000,0.06070,304.78556
170.80001,8.53985,25091.43054,0.00000,0.06086,304.79432
171.20001,8.55988,25095.76380,0.00000,0.06102,304.84696
171.60001,8.57991,25098.62185,0.00000,0.06118,304.88168
172.00001,8.60006,25102.35310,0.00000,0.06133,304.92700
172.40001,8.62009,25103.79553,0.00000,0.06150,304.94452
172.80001,8.64018,25108.03938,0.00000,0.06165,304.99607
173.20001,8.66009,25109.98845,0.00000,0.06181,305.01975
173.60001,8.68006,25113.26671,0.00000,0.06197,305.05957
174.00001,8.70003,25113.77037,0.00000,0.06212,305.06569
174.40001,8.72000,25112.36966,0.00000,0.06228,305.04868
174.80001,8.74003,25115.12339,0.00000,0.06244,305.08213
175.20001,8.75988,25117.24234,0.00000,0.06260,305.10787
175.60001,8.77985,25120.67556,0.00000,0.06276,305.14957
176.00001,8.79994,25126.06084,0.00000,0.06292,305.21499
176.40001,8.81997,25128.16191,0.00000,0.06308,305.24051
176.80001,8.84000,25131.06167,0.00000,0.06324,305.27573
177.20001,8.86014,25134.55153,0.00000,0.06340,305.31813
177.60001,8.88017,25136.48272,0.00000,0.06356,305.34159
178.00001,8.90014,25138.69405,0.00000,0.06372,305.36845
178.40001,8.92005,25139.38546,0.00000,0.06388,305.37685
178.80001,8.94002,25140.78915,0.00000,0.06405,305.39390
179.20001,8.95999,25142.75312,0.00000,0.06421,305.41775
179.60001,8.98002,25142.33589,0.00000,0.06437,305.41269
180.00001,8.99999,25145.51282,0.00000,0.06453,305.45128
180.40001,9.01990,25147.57812,0.00000,0.06469,305.47637
180.80001,9.03993,25152.35543,0.00000,0.06485,305.53440
181.20001,9.05990,25153.94688,0.00000,0.06502,305.55373
181.60001,9.07999,25155.37441,0.00000,0.06518,305.57107
182.00001,9.10008,25158.29206,0.00000,0.06534,305.60651
182.40001,9.12011,25161.65078,0.00000,0.06551,305.64731
182.80001,9.14008,25161.33785,0.00000,0.06567,305.64351
183.20001,9.16005,25161.45706,0.00000,0.06583,305.64496
183.60001,9.18002,25164.21080,0.00000,0.06599,305.67841
184.00001,9.19999,25161.76701,0.00000,0.06615,305.64872
184.40001,9.21996,25165.62343,0.00000,0.06631,305.69557
184.80001,9.23999,25168.18643,0.00000,0.06647,305.72670
185.20001,9.25996,25170.95804,0.00000,0.06664,305.76037
185.60001,9.27987,25173.16937,0.00000,0.06680,305.78723
186.00001,9.29996,25176.24795,0.00000,0.06697,305.82463
186.40001,9.31993,25176.28968,0.00000,0.06713,305.82514
186.80001,9.34008,25179.21925,0.00000,0.06729,305.86072
187.20001,9.36011,25180.13418,0.00000,0.06745,305.87184
187.60001,9.38007,25184.30948,0.00000,0.06761,305.92255
188.00001,9.40004,25184.61049,0.00000,0.06777,305.92621
188.40001,9.42001,25184.19027,0.00000,0.06794,305.92111
188.80001,9.43992,25184.02040,0.00000,0.06810,305.91904
189.20001,9.45995,25187.11984,0.00000,0.06827,305.95669
189.60001,9.47998,25190.73486,0.00000,0.06843,306.00061
190.00001,9.49995,25191.65576,0.00000,0.06859,306.01179
190.40001,9.51998,25192.16835,0.00000,0.06876,306.01802
190.80001,9.53989,25193.70615,0.00000,0.06892,306.03670
191.20001,9.55998,25197.15428,0.00000,0.06909,306.07858
191.60001,9.58001,25199.33283,0.00000,0.06925,306.10505
192.00001,9.60016,25199.27025,0.00000,0.06941,306.10429
192.40001,9.62013,25201.56503,0.00000,0.06957,306.13216
192.80001,9.64004,25202.03590,0.00000,0.06974,306.13788
193.20001,9.65995,25202.92699,0.00000,0.06990,306.14871
193.60001,9.67998,25203.30548,0.00000,0.07007,306.15331
194.00001,9.69995,25203.86279,0.00000,0.07023,306.16008
194.40001,9.71998,25205.47509,0.00000,0.07039,306.17966
194.80001,9.74001,25207.62682,0.00000,0.07055,306.20580
195.20001,9.75992,25208.88746,0.00000,0.07072,306.22111
195.60001,9.77995,25210.06763,0.00000,0.07088,306.23545
196.00001,9.79998,25211.64715,0.00000,0.07104,306.25463
196.40001,9.82000,25213.94491,0.00000,0.07121,306.28255
196.80001,9.84015,25215.82544,0.00000,0.07137,306.30539
197.20001,9.86006,25216.04896,0.00000,0.07153,306.30810
197.60001,9.87997,25216.20691,0.00000,0.07169,306.31002
198.00001,9.90000,25216.89534,0.00000,0.07185,306.31839
198.40001,9.91991,25218.06657,0.00000,0.07201,306.33261
198.80001,9.93994,25219.50901,0.00000,0.07218,306.35014
199.20001,9.96003,25221.36569,0.00000,0.07234,306.37269
199.60001,9.98000,25222.34619,0.00000,0.07250,306.38460
200.00001,9.99997,25225.21317,0.00000,0.07266,306.41943
200.40001,10.01988,25227.15330,0.00000,0.07282,306.44299
200.80001,10.03997,25227.67782,0.00000,0.07299,306.44936
201.20001,10.06000,25228.05333,0.00000,0.07314,306.45393
201.60001,10.08015,25230.50904,0.00000,0.07331,306.48376
202.00001,10.10006,25231.84419,0.00000,0.07347,306.49997
202.40001,10.12003,25233.14655,0.00000,0.07363,306.51580
202.80001,10.14000,25233.19721,0.00000,0.07379,306.51641
203.20001,10.15997,25231.89187,0.00000,0.07401,306.50055
203.60001,10.18000,25233.42073,0.00000,0.07418,306.51913
204.00001,10.20003,25235.78107,0.00000,0.07435,306.54780
204.40001,10.22000,25235.75127,0.00000,0.07451,306.54744
204.80001,10.23997,25238.04903,0.00000,0.07467,306.57535
205.20001,10.25994,25238.34109,0.00000,0.07483,306.57890
205.60001,10.28003,25240.95476,0.00000,0.07500,306.61064
206.00001,10.30000,25239.12191,0.00000,0.07517,306.58838
206.40001,10.32008,25241.82796,0.00000,0.07533,306.62125
206.80001,10.34011,25244.18235,0.00000,0.07549,306.64985
207.20001,10.36002,25244.85290,0.00000,0.07565,306.65800
207.60001,10.38005,25245.14496,0.00000,0.07582,306.66154
208.00001,10.39996,25244.57872,0.00000,0.07598,306.65467
208.40001,10.41993,25242.68925,0.00000,0.07614,306.63171
208.80001,10.43996,25245.69333,0.00000,0.07631,306.66821
209.20001,10.45999,25247.65730,0.00000,0.07648,306.69206
209.60001,10.47996,25248.39342,0.00000,0.07664,306.70100
210.00001,10.49999,25249.43352,0.00000,0.07680,306.71364
210.40001,10.52002,25252.07698,0.00000,0.07697,306.74575
210.80001,10.53999,25253.04258,0.00000,0.07713,306.75748
211.20001,10.56008,25254.70555,0.00000,0.07729,306.77768
211.60001,10.58011,25254.94397,0.00000,0.07746,306.78058
212.00001,10.60008,25254.70853,0.00000,0.07762,306.77772
212.40001,10.62005,25256.16586,0.00000,0.07779,306.79542
212.80001,10.63996,25254.06182,0.00000,0.07796,306.76986
213.20001,10.65999,25256.64568,0.00000,0.07812,306.80125
213.60001,10.67996,25254.02308,0.00000,0.07829,306.76939
214.00001,10.69999,25255.56386,0.00000,0.07846,306.78811
214.40001,10.71996,25257.91824,0.00000,0.07862,306.81671
214.80001,10.73999,25260.72264,0.00000,0.07878,306.85077
215.20001,10.76002,25260.83291,0.00000,0.07895,306.85211
215.60001,10.78005,25260.45144,0.00000,0.07911,306.84748
216.00001,10.80001,25261.02960,0.00000,0.07928,306.85450
216.40001,10.82010,25263.27968,0.00000,0.07944,306.88183
216.80001,10.84007,25261.06834,0.00000,0.07961,306.85497
217.20001,10.86004,25259.56929,0.00000,0.07978,306.83676
217.60001,10.87995,25259.94182,0.00000,0.07994,306.84129
218.00001,10.89992,25259.60505,0.00000,0.08011,306.83720
218.40001,10.91989,25259.70936,0.00000,0.08027,306.83846
218.80001,10.93998,25262.27832,0.00000,0.08044,306.86967
219.20001,10.96001,25263.98003,0.00000,0.08061,306.89034
219.60001,10.97998,25264.79959,0.00000,0.08077,306.90030
220.00001,11.00001,25266.89470,0.00000,0.08094,306.92575
220.40001,11.01998,25265.45525,0.00000,0.08110,306.90826
220.80001,11.04007,25265.71155,0.00000,0.08127,306.91137
221.20001,11.06010,25265.13636,0.00000,0.08143,306.90439
221.60001,11.08007,25267.51757,0.00000,0.08160,306.93331
222.00001,11.10004,25266.07215,0.00000,0.08176,306.91575
222.40001,11.11995,25264.68933,0.00000,0.08193,306.89896
222.80001,11.13986,25264.37640,0.00000,0.08210,306.89516
223.20001,11.15989,25265.33306,0.00000,0.08227,306.90678
223.60001,11.17992,25268.97490,0.00000,0.08243,306.95101
224.00001,11.19995,25269.29677,0.00000,0.08260,306.95492
224.40001,11.22004,25270.52462,0.00000,0.08277,306.96984
224.80001,11.24001,25271.03722,0.00000,0.08294,306.97607
225.20001,11.26010,25271.55876,0.00000,0.08311,306.98240
225.60001,11.28006,25268.59045,0.00000,0.08327,306.94634
226.00001,11.30009,25268.31925,0.00000,0.08344,306.94305
226.40001,11.32018,25270.84947,0.00000,0.08362,306.97379
226.80001,11.34003,25269.89281,0.00000,0.08379,306.96216
227.20001,11.35988,25267.34173,0.00000,0.08396,306.93118
227.60001,11.37985,25267.22848,0.00000,0.08413,306.92980
228.00001,11.39982,25266.31653,0.00000,0.08430,306.91872
228.40001,11.41991,25269.49048,0.00000,0.08447,306.95728
228.80001,11.44000,25272.44985,0.00000,0.08465,306.99323
229.20001,11.46003,25271.87467,0.00000,0.08481,306.98624
229.60001,11.48012,25273.19491,0.00000,0.08499,307.00228
230.00001,11.50003,25269.55307,0.00000,0.08516,306.95804
230.40001,11.52006,25271.18325,0.00000,0.08533,306.97784
230.80001,11.54015,25270.98954,0.00000,0.08551,306.97549
231.20001,11.56006,25269.54412,0.00000,0.08568,306.95793
231.60001,11.57997,25267.07649,0.00000,0.08585,306.92795
232.00001,11.59988,25270.13123,0.00000,0.08602,306.96506
232.40001,11.61985,25269.84513,0.00000,0.08620,306.96159
232.80001,11.63988,25269.46366,0.00000,0.08638,306.95695
233.20001,11.65997,25270.76900,0.00000,0.08655,306.97281
233.60001,11.68006,25271.64221,0.00000,0.08673,306.98342
234.00001,11.70009,25273.19789,0.00000,0.08690,307.00231
234.40001,11.72006,25273.76711,0.00000,0.08707,307.00923
234.80001,11.74002,25271.52896,0.00000,0.08725,306.98204
235.20001,11.76005,25271.12067,0.00000,0.08743,306.97708
235.60001,11.78008,25269.90175,0.00000,0.08761,306.96227
236.00001,11.80005,25268.81695,0.00000,0.08779,306.94910
236.40001,11.82002,25269.08815,0.00000,0.08796,306.95239
236.80001,11.83993,25268.52489,0.00000,0.08813,306.94555
237.20001,11.85990,25269.51134,0.00000,0.08831,306.95753
237.60001,11.87987,25268.22686,0.00000,0.08849,306.94193
238.00001,11.89996,25268.78715,0.00000,0.08867,306.94873
238.40001,11.92005,25268.67688,0.00000,0.08885,306.94739
238.80001,11.94008,25270.46204,0.00000,0.08903,306.96908
239.20001,11.96005,25269.09709,0.00000,0.08920,306.95250
239.60001,11.98008,25268.81695,0.00000,0.08938,306.94910
240.00001,12.00005,25266.87682,0.00000,0.08956,306.92553
240.40001,12.02002,25264.29296,0.00000,0.08974,306.89414
240.80001,12.04011,25265.69068,0.00000,0.08991,306.91112
241.20001,12.06002,25265.25259,0.00000,0.09009,306.90580
241.60001,12.07993,25265.78903,0.00000,0.09027,306.91231
242.00001,12.09990,25264.90092,0.00000,0.09045,306.90153
242.40001,12.11987,25262.85946,0.00000,0.09063,306.87673
242.80001,12.13996,25263.60154,0.00000,0.09081,306.88574
243.20001,12.15999,25263.23795,0.00000,0.09098,306.88133
243.60001,12.18002,25264.47773,0.00000,0.09116,306.89639
244.00001,12.20005,25263.27372,0.00000,0.09134,306.88176
244.40001,12.22007,25264.08136,0.00000,0.09152,306.89157
244.80001,12.23998,25262.13825,0.00000,0.09170,306.86797
245.20001,12.26001,25261.60181,0.00000,0.09188,306.86145
245.60001,12.28004,25259.64975,0.00000,0.09206,306.83774
246.00001,12.29995,25258.79443,0.00000,0.09224,306.82735
246.40001,12.31986,25259.01496,0.00000,0.09242,306.83003
246.80001,12.33983,25259.24444,0.00000,0.09260,306.83282
247.20001,12.35986,25258.64244,0.00000,0.09278,306.82550
247.60001,12.38001,25258.47256,0.00000,0.09296,306.82344
248.00001,12.39998,25256.59204,0.00000,0.09314,306.80060
248.40001,12.42007,25258.38614,0.00000,0.09332,306.82239
248.80001,12.44010,25257.35795,0.00000,0.09350,306.80990
249.20001,12.46007,25256.71124,0.00000,0.09368,306.80204
249.60001,12.48004,25255.94532,0.00000,0.09387,306.79274
250.00001,12.49995,25253.47769,0.00000,0.09405,306.76276
250.40001,12.52004,25254.85158,0.00000,0.09423,306.77945
250.80001,12.54001,25252.29156,0.00000,0.09441,306.74836
251.20001,12.55998,25250.33355,0.00000,0.09460,306.72457
251.60001,12.57995,25250.09513,0.00000,0.09478,306.72168
252.00001,12.59992,25249.90737,0.00000,0.09496,306.71939
252.40001,12.61989,25248.15202,0.00000,0.09514,306.69807
252.80001,12.64004,25247.25497,0.00000,0.09533,306.68718
253.20001,12.66007,25248.92688,0.00000,0.09551,306.70748
253.60001,12.68010,25248.61991,0.00000,0.09570,306.70376
254.00001,12.70007,25249.06695,0.00000,0.09588,306.70919
254.40001,12.71998,25245.21351,0.00000,0.09607,306.66238
254.80001,12.74000,25242.96045,0.00000,0.09625,306.63501
255.20001,12.76003,25242.30182,0.00000,0.09644,306.62701
255.60001,12.78000,25242.19155,0.00000,0.09662,306.62567
256.00001,12.79997,25241.03224,0.00000,0.09681,306.61159
256.40001,12.81994,25238.80601,0.00000,0.09700,306.58454
256.80001,12.83985,25237.28907,0.00000,0.09718,306.56612
257.20001,12.85994,25237.19668,0.00000,0.09736,306.56499
257.60001,12.87997,25236.73177,0.00000,0.09756,306.55935
258.00001,12.90006,25238.57951,0.00000,0.09774,306.58179
258.40001,12.92015,25238.32321,0.00000,0.09793,306.57868
258.80001,12.94006,25236.27579,0.00000,0.09811,306.55381
259.20001,12.96003,25235.35490,0.00000,0.09830,306.54262
259.60001,12.98000,25231.43291,0.00000,0.09849,306.49498
260.00001,13.00003,25227.17416,0.00000,0.09868,306.44325
260.40001,13.02012,25227.28443,0.00000,0.09886,306.44459
260.80001,13.04009,25228.86693,0.00000,0.09906,306.46381
261.20001,13.05988,25225.79730,0.00000,0.09925,306.42652
261.60001,13.07991,25224.62010,0.00000,0.09943,306.41222
262.00001,13.09988,25220.67428,0.00000,0.09962,306.36429
262.40001,13.11997,25222.94521,0.00000,0.09980,306.39188
262.80001,13.14006,25224.23267,0.00000,0.09999,306.40752
263.20001,13.16009,25221.92895,0.00000,0.10018,306.37953
263.60001,13.18011,25219.39278,0.00000,0.10037,306.34872
264.00001,13.20002,25216.60328,0.00000,0.10056,306.31484
264.40001,13.21999,25214.00452,0.00000,0.10075,306.28327
264.80001,13.24002,25213.29820,0.00000,0.10093,306.27469
265.20001,13.26005,25210.38949,0.00000,0.10112,306.23936
265.60001,13.27996,25207.82948,0.00000,0.10132,306.20826
266.00001,13.29993,25206.27677,0.00000,0.10150,306.18940
266.40001,13.31984,25206.50625,0.00000,0.10169,306.19219
266.80001,13.33993,25205.05190,0.00000,0.10188,306.17452
267.20001,13.36002,25203.16243,0.00000,0.10206,306.15157
267.60001,13.38011,25202.62599,0.00000,0.10225,306.14505
268.00001,13.40008,25200.13452,0.00000,0.10243,306.11479
268.40001,13.42005,25199.21362,0.00000,0.10262,306.10360
268.80001,13.44002,25196.59996,0.00000,0.10280,306.07185
269.20001,13.45999,25192.91639,0.00000,0.10299,306.02711
269.60001,13.48008,25188.69340,0.00000,0.10318,305.97581
270.00001,13.49999,25186.36286,0.00000,0.10335,305.94750
270.40001,13.51996,25183.92801,0.00000,0.10353,305.91792
270.80001,13.53993,25180.42326,0.00000,0.10371,305.87535
271.20001,13.55990,25180.34279,0.00000,0.10389,305.87437
271.60001,13.57993,25179.68118,0.00000,0.10407,305.86633
272.00001,13.59996,25174.45683,0.00000,0.10425,305.80287
272.40001,13.62011,25171.70012,0.00000,0.10442,305.76938
272.80001,13.64014,25167.21785,0.00000,0.10459,305.71494
273.20001,13.66004,25163.76674,0.00000,0.10476,305.67301
273.60001,13.68002,25160.71796,0.00000,0.10492,305.63598
274.00001,13.69998,25151.73554,0.00000,0.10509,305.52687
274.40001,13.71995,25143.05413,0.00000,0.10525,305.42141
274.80001,13.74004,25140.20503,0.00000,0.10540,305.38680
275.20001,13.75995,25134.88531,0.00000,0.10555,305.32218
275.60001,13.77992,25127.73275,0.00000,0.10570,305.23530
276.00001,13.79989,25119.69507,0.00000,0.10585,305.13766
276.40001,13.81992,25111.02855,0.00000,0.10598,305.03239
276.80001,13.83995,25098.04666,0.00000,0.10610,304.87469
277.20001,13.86004,25084.45382,0.00000,0.10622,304.70957
277.60001,13.88013,25064.26275,0.00000,0.10634,304.46430
278.00001,13.90010,25037.91153,0.00000,0.10643,304.14421
278.40001,13.92007,25003.38554,0.00000,0.10652,303.72481
278.80001,13.94004,24962.65322,0.00000,0.10658,303.23002
279.20001,13.96001,24897.15666,0.00000,0.10664,302.43441
279.60001,13.98004,24518.53752,0.00000,0.10659,297.83519
279.70201,13.98530,23121.05745,0.00000,0.10560,280.85952
279.71001,13.98638,18822.62975,0.00000,0.10132,228.64502
279.71801,13.98787,13377.33716,0.00000,0.09346,162.49916