File: scratch/college-stuff/ME Lab/ME lab Fall 2013/group15/group15.is_tens_RawData/Specimen_RawData_3.csv
Time,Extension,Load,Strain 2,Tensile strain,Tensile stress
(sec),(mm),(N),(mm/mm),(mm/mm),(MPa)
0.00000,0.00000,-0.08127,0.00000,0.00000,-0.00099
0.10000,0.00179,1.27638,0.00000,0.00000,0.01550
0.20000,0.00747,5.68423,0.00000,0.00000,0.06905
0.30000,0.01369,7.21170,0.00000,0.00000,0.08760
0.40000,0.01931,7.53538,0.00000,0.00000,0.09153
0.50000,0.02475,9.45014,0.00000,0.00000,0.11479
0.60000,0.02983,11.32126,0.00000,0.00001,0.13752
0.70000,0.03504,11.41849,0.00000,0.00001,0.13870
0.80000,0.04000,11.51848,0.00000,0.00001,0.13992
0.90000,0.04502,12.28302,0.00000,0.00001,0.14921
1.00000,0.04998,12.38181,0.00000,0.00001,0.15041
1.10000,0.05501,12.89093,0.00000,0.00000,0.15659
1.20000,0.06003,13.22044,0.00000,0.00001,0.16059
1.30000,0.06505,13.14853,0.00000,0.00001,0.15972
1.40000,0.07001,14.58959,0.00000,0.00001,0.17722
1.50000,0.07498,14.80089,0.00000,0.00001,0.17979
1.60000,0.08006,15.75532,0.00000,0.00001,0.19139
1.70000,0.08502,17.78524,0.00000,0.00001,0.21604
1.80000,0.09016,19.04928,0.00000,0.00000,0.23140
1.90000,0.09495,19.72233,0.00000,0.00001,0.23957
2.00000,0.10009,21.40895,0.00000,0.00001,0.26006
2.10000,0.10499,22.04736,0.00000,0.00001,0.26782
2.20000,0.11013,22.00303,0.00000,0.00001,0.26728
2.30000,0.11492,22.63458,0.00000,0.00001,0.27495
2.40000,0.12006,24.51407,0.00000,0.00001,0.29778
2.50000,0.12490,26.02359,0.00000,0.00001,0.31612
2.60000,0.13010,28.83103,0.00000,0.00000,0.35022
2.70000,0.13500,29.44995,0.00000,0.00000,0.35774
2.80000,0.14009,29.55119,0.00000,0.00000,0.35897
2.90000,0.14493,32.71334,0.00000,0.00000,0.39738
3.00000,0.15001,33.69427,0.00000,0.00001,0.40930
3.10000,0.15497,35.75743,0.00000,0.00000,0.43436
3.20000,0.16006,36.68802,0.00000,0.00000,0.44566
3.30000,0.16496,39.47730,0.00000,0.00000,0.47954
3.40000,0.16998,42.74608,0.00000,-0.00001,0.51925
3.50000,0.17500,48.27148,0.00000,-0.00001,0.58637
3.60000,0.18003,55.12208,0.00000,0.00000,0.66959
3.70000,0.18511,63.63188,0.00000,0.00000,0.77296
3.80000,0.18995,72.55176,0.00000,0.00000,0.88131
3.90000,0.19503,84.52944,0.00000,0.00001,1.02681
4.00000,0.19994,97.70965,0.00000,0.00000,1.18691
4.10000,0.20508,113.76096,0.00000,0.00001,1.38189
4.20000,0.20992,125.73249,0.00000,0.00001,1.52732
4.30000,0.21506,141.28489,0.00000,0.00001,1.71624
4.40000,0.21985,156.86153,0.00000,0.00002,1.90545
4.50000,0.22505,174.48794,0.00000,0.00003,2.11957
4.60000,0.22995,192.50601,0.00000,0.00004,2.33844
4.70000,0.23503,216.21496,0.00000,0.00005,2.62644
4.80000,0.23988,240.69971,0.00000,0.00006,2.92386
4.90000,0.24502,269.56559,0.00000,0.00007,3.27451
5.00000,0.24998,299.51727,0.00000,0.00008,3.63834
5.10000,0.25506,329.96393,0.00000,0.00010,4.00819
5.20000,0.25996,362.08138,0.00000,0.00011,4.39833
5.30000,0.26499,395.84381,0.00000,0.00013,4.80845
5.40000,0.27001,433.20642,0.00000,0.00015,5.26231
5.50000,0.27503,469.39780,0.00000,0.00017,5.70194
5.60000,0.28005,508.13816,0.00000,0.00019,6.17253
5.70000,0.28502,545.42837,0.00000,0.00020,6.62551
5.80000,0.28998,582.76705,0.00000,0.00022,7.07907
5.90000,0.29500,619.49668,0.00000,0.00024,7.52524
6.00000,0.30008,659.61219,0.00000,0.00026,8.01254
6.10000,0.30499,699.16523,0.00000,0.00028,8.49300
6.20000,0.31007,740.21984,0.00000,0.00030,8.99171
6.30000,0.31497,779.78824,0.00000,0.00032,9.47236
6.40000,0.32005,823.33246,0.00000,0.00034,10.00131
6.50000,0.32496,857.87335,0.00000,0.00036,10.42089
6.60000,0.33010,901.02796,0.00000,0.00039,10.94510
6.70000,0.33488,940.36702,0.00000,0.00040,11.42296
6.80000,0.34008,983.14406,0.00000,0.00043,11.94259
6.90000,0.34493,1024.73302,0.00000,0.00045,12.44779
7.00000,0.35013,1069.64549,0.00000,0.00047,12.99336
7.10000,0.35491,1111.10089,0.00000,0.00049,13.49693
7.20000,0.36005,1152.62158,0.00000,0.00052,14.00129
7.30000,0.36490,1192.67656,0.00000,0.00054,14.48786
7.40000,0.37004,1235.34258,0.00000,0.00057,15.00614
7.50000,0.37494,1278.01588,0.00000,0.00059,15.52450
7.60000,0.38002,1320.77551,0.00000,0.00062,16.04392
7.70000,0.38492,1362.70467,0.00000,0.00064,16.55325
7.80000,0.39001,1404.26531,0.00000,0.00066,17.05810
7.90000,0.39497,1446.69991,0.00000,0.00068,17.57357
8.00000,0.39999,1486.71465,0.00000,0.00070,18.05964
8.10000,0.40495,1530.19018,0.00000,0.00073,18.58775
8.20000,0.40992,1569.67379,0.00000,0.00075,19.06737
8.30000,0.41506,1612.17153,0.00000,0.00077,19.58361
8.40000,0.42002,1651.03171,0.00000,0.00079,20.05566
8.50000,0.42504,1692.13414,0.00000,0.00082,20.55494
8.60000,0.42989,1729.47906,0.00000,0.00084,21.00858
8.70000,0.43503,1771.29097,0.00000,0.00086,21.51649
8.80000,0.43987,1809.01997,0.00000,0.00088,21.97479
8.90000,0.44507,1849.14246,0.00000,0.00090,22.46218
9.00000,0.44986,1887.21046,0.00000,0.00092,22.92460
9.10000,0.45500,1926.67171,0.00000,0.00095,23.40395
9.20000,0.45984,1964.38842,0.00000,0.00096,23.86211
9.30000,0.46510,2003.92194,0.00000,0.00098,24.34234
9.40000,0.46995,2041.49093,0.00000,0.00101,24.79870
9.50000,0.47503,2080.19819,0.00000,0.00103,25.26889
9.60000,0.47987,2117.56304,0.00000,0.00105,25.72277
9.70000,0.48501,2154.75913,0.00000,0.00107,26.17461
9.80000,0.48997,2191.72463,0.00000,0.00109,26.62364
9.90000,0.49500,2228.70018,0.00000,0.00111,27.07280
10.00000,0.49996,2265.38833,0.00000,0.00113,27.51846
10.10000,0.50498,2300.89165,0.00000,0.00115,27.94973
10.20000,0.50994,2337.50381,0.00000,0.00117,28.39447
10.30000,0.51503,2371.12362,0.00000,0.00119,28.80286
10.40000,0.52005,2408.16064,0.00000,0.00121,29.25276
10.50000,0.52501,2441.71433,0.00000,0.00123,29.66035
10.60000,0.53003,2477.70343,0.00000,0.00125,30.09752
10.70000,0.53506,2510.62959,0.00000,0.00127,30.49749
10.80000,0.54008,2545.55419,0.00000,0.00129,30.92173
10.90000,0.54498,2578.29167,0.00000,0.00130,31.31940
11.00000,0.55000,2613.17510,0.00000,0.00133,31.74315
11.10000,0.55497,2646.36837,0.00000,0.00134,32.14636
11.20000,0.56011,2678.81509,0.00000,0.00136,32.54050
11.30000,0.56495,2709.40531,0.00000,0.00138,32.91209
11.40000,0.57009,2743.07635,0.00000,0.00140,33.32110
11.50000,0.57494,2773.29385,0.00000,0.00142,33.68816
11.60000,0.58008,2806.13638,0.00000,0.00144,34.08711
11.70000,0.58498,2833.45189,0.00000,0.00145,34.41892
11.80000,0.59006,2861.04418,0.00000,0.00147,34.75410
11.90000,0.59491,2888.31070,0.00000,0.00148,35.08531
12.00000,0.60005,2914.25698,0.00000,0.00149,35.40049
12.10000,0.60489,2939.22443,0.00000,0.00151,35.70378
12.20000,0.61009,2964.66686,0.00000,0.00152,36.01284
12.30000,0.61493,2988.49922,0.00000,0.00154,36.30234
12.40000,0.62002,3013.89843,0.00000,0.00155,36.61087
12.50000,0.62492,3040.16415,0.00000,0.00157,36.92993
12.60000,0.63006,3065.37002,0.00000,0.00158,37.23611
12.70000,0.63502,3090.99387,0.00000,0.00160,37.54738
12.80000,0.63999,3115.43141,0.00000,0.00161,37.84423
12.90000,0.64501,3142.37699,0.00000,0.00163,38.17154
13.00000,0.64991,3166.79999,0.00000,0.00164,38.46822
13.10000,0.65505,3196.26890,0.00000,0.00166,38.82619
13.20000,0.65990,3221.82551,0.00000,0.00167,39.13663
13.30000,0.66504,3252.10616,0.00000,0.00169,39.50446
13.40000,0.66988,3278.67121,0.00000,0.00170,39.82716
13.50000,0.67502,3306.79044,0.00000,0.00172,40.16873
13.60000,0.67993,3332.76056,0.00000,0.00173,40.48420
13.70000,0.68513,3362.13112,0.00000,0.00175,40.84097
13.80000,0.68991,3390.13077,0.00000,0.00177,41.18110
13.90000,0.69505,3418.32414,0.00000,0.00178,41.52357
14.00000,0.69990,3444.79382,0.00000,0.00180,41.84511
14.10000,0.70510,3473.23790,0.00000,0.00182,42.19063
14.20000,0.71000,3500.34498,0.00000,0.00183,42.51991
14.30000,0.71502,3528.12409,0.00000,0.00184,42.85735
14.40000,0.71993,3555.19764,0.00000,0.00186,43.18622
14.50000,0.72507,3583.33774,0.00000,0.00187,43.52805
14.60000,0.72997,3610.77413,0.00000,0.00189,43.86133
14.70000,0.73505,3639.60005,0.00000,0.00191,44.21149
14.80000,0.73995,3665.91811,0.00000,0.00192,44.53118
14.90000,0.74498,3693.23753,0.00000,0.00194,44.86304
15.00000,0.74994,3721.51583,0.00000,0.00195,45.20655
15.10000,0.75502,3747.35482,0.00000,0.00197,45.52042
15.20000,0.75998,3776.83528,0.00000,0.00198,45.87853
15.30000,0.76501,3801.89158,0.00000,0.00200,46.18290
15.40000,0.76997,3830.02572,0.00000,0.00201,46.52465
15.50000,0.77499,3855.47541,0.00000,0.00203,46.83380
15.60000,0.78007,3885.06763,0.00000,0.00205,47.19327
15.70000,0.78492,3910.50614,0.00000,0.00206,47.50228
15.80000,0.79000,3939.65505,0.00000,0.00208,47.85636
15.90000,0.79490,3963.39893,0.00000,0.00210,48.14478
16.00000,0.80010,3993.61067,0.00000,0.00212,48.51178
16.10000,0.80495,4018.88192,0.00000,0.00212,48.81875
16.20000,0.81003,4046.35742,0.00000,0.00214,49.15251
16.30000,0.81487,4074.03857,0.00000,0.00215,49.48876
16.40000,0.82007,4101.07449,0.00000,0.00217,49.81718
16.50000,0.82492,4128.05714,0.00000,0.00219,50.14494
16.60000,0.83006,4155.50806,0.00000,0.00220,50.47840
16.70000,0.83484,4181.68940,0.00000,0.00222,50.79643
16.80000,0.83998,4209.52700,0.00000,0.00223,51.13459
16.90000,0.84489,4236.89410,0.00000,0.00226,51.46702
17.00000,0.85009,4264.37929,0.00000,0.00227,51.80090
17.10000,0.85499,4290.58485,0.00000,0.00228,52.11922
17.20000,0.86001,4317.37117,0.00000,0.00230,52.44461
17.30000,0.86497,4344.25212,0.00000,0.00231,52.77114
17.40000,0.87000,4369.66158,0.00000,0.00233,53.07980
17.50000,0.87502,4397.67726,0.00000,0.00235,53.42011
17.60000,0.87992,4423.11987,0.00000,0.00236,53.72917
17.70000,0.88494,4450.45568,0.00000,0.00237,54.06123
17.80000,0.88991,4475.48367,0.00000,0.00239,54.36525
17.90000,0.89499,4503.08956,0.00000,0.00241,54.70059
18.00000,0.89995,4528.30009,0.00000,0.00242,55.00683
18.10000,0.90503,4556.52401,0.00000,0.00244,55.34968
18.20000,0.90994,4581.25286,0.00000,0.00245,55.65007
18.30000,0.91502,4608.00827,0.00000,0.00247,55.97508
18.40000,0.91992,4632.47374,0.00000,0.00248,56.27227
18.50000,0.92506,4659.15650,0.00000,0.00249,56.59639
18.60000,0.92991,4684.94706,0.00000,0.00251,56.90968
18.70000,0.93499,4711.61120,0.00000,0.00253,57.23358
18.80000,0.93983,4735.94368,0.00000,0.00254,57.52915
18.90000,0.94503,4763.31711,0.00000,0.00256,57.86167
19.00000,0.94988,4787.85411,0.00000,0.00257,58.15973
19.10000,0.95502,4813.64168,0.00000,0.00259,58.47298
19.20000,0.95992,4838.79745,0.00000,0.00260,58.77855
19.30000,0.96506,4863.04238,0.00000,0.00262,59.07306
19.40000,0.96996,4886.20251,0.00000,0.00263,59.35440
19.50000,0.97505,4911.55125,0.00000,0.00265,59.66232
19.60000,0.97995,4935.01127,0.00000,0.00266,59.94730
19.70000,0.98503,4959.68908,0.00000,0.00268,60.24707
19.80000,0.98999,4984.51442,0.00000,0.00269,60.54863
19.90000,0.99502,5007.54863,0.00000,0.00271,60.82843
20.00000,0.99998,5033.53700,0.00000,0.00272,61.14412
20.10000,1.00494,5055.10531,0.00000,0.00274,61.40612
20.20000,1.00996,5081.08325,0.00000,0.00275,61.72168
20.30000,1.01499,5103.58587,0.00000,0.00277,61.99503
20.40000,1.02007,5129.43640,0.00000,0.00278,62.30905
20.50000,1.02491,5151.61380,0.00000,0.00279,62.57844
20.60000,1.03005,5175.84234,0.00000,0.00281,62.87275
20.70000,1.03490,5196.12841,0.00000,0.00282,63.11918
20.80000,1.04010,5221.02676,0.00000,0.00284,63.42163
20.90000,1.04494,5241.30426,0.00000,0.00284,63.66794
21.00000,1.05008,5265.08354,0.00000,0.00286,63.95680
21.10000,1.05487,5286.11951,0.00000,0.00288,64.21233
21.20000,1.06007,5309.89133,0.00000,0.00289,64.50109
21.30000,1.06497,5331.69731,0.00000,0.00290,64.76598
21.40000,1.07011,5355.43784,0.00000,0.00292,65.05436
21.50000,1.07496,5378.71309,0.00000,0.00293,65.33710
21.60000,1.08004,5402.09524,0.00000,0.00294,65.62113
21.70000,1.08494,5425.92034,0.00000,0.00295,65.91054
21.80000,1.09008,5449.70185,0.00000,0.00297,66.19942
21.90000,1.09493,5474.33123,0.00000,0.00298,66.49860
22.00000,1.10001,5498.12913,0.00000,0.00300,66.78768
22.10000,1.10497,5520.85824,0.00000,0.00302,67.06378
22.20000,1.10999,5544.67291,0.00000,0.00303,67.35307
22.30000,1.11495,5569.85438,0.00000,0.00304,67.65896
22.40000,1.11992,5592.93851,0.00000,0.00306,67.93937
22.50000,1.12500,5619.15226,0.00000,0.00307,68.25779
22.60000,1.12996,5640.90349,0.00000,0.00309,68.52201
22.70000,1.13504,5665.92962,0.00000,0.00310,68.82601
22.80000,1.13995,5688.56820,0.00000,0.00312,69.10101
22.90000,1.14503,5713.93669,0.00000,0.00313,69.40917
23.00000,1.14993,5736.92992,0.00000,0.00315,69.68848
23.10000,1.15507,5762.38967,0.00000,0.00316,69.99775
23.20000,1.15992,5784.72167,0.00000,0.00318,70.26902
23.30000,1.16506,5811.56202,0.00000,0.00319,70.59506
23.40000,1.16984,5833.33708,0.00000,0.00320,70.85957
23.50000,1.17504,5859.73077,0.00000,0.00322,71.18018
23.60000,1.17995,5883.17253,0.00000,0.00324,71.46494
23.70000,1.18509,5909.18064,0.00000,0.00325,71.78087
23.80000,1.18999,5933.07763,0.00000,0.00327,72.07115
23.90000,1.19501,5957.78078,0.00000,0.00329,72.37123
24.00000,1.19998,5982.90935,0.00000,0.00331,72.67648
24.10000,1.20506,6006.78287,0.00000,0.00332,72.96648
24.20000,1.20996,6031.35116,0.00000,0.00333,73.26492
24.30000,1.21504,6056.97259,0.00000,0.00334,73.57615
24.40000,1.21988,6080.55107,0.00000,0.00337,73.86257
24.50000,1.22503,6104.44099,0.00000,0.00338,74.15276
24.60000,1.23005,6128.85952,0.00000,0.00339,74.44939
24.70000,1.23507,6152.70287,0.00000,0.00341,74.73902
24.80000,1.24003,6179.28505,0.00000,0.00342,75.06192
24.90000,1.24500,6201.68932,0.00000,0.00344,75.33407
25.00000,1.24996,6227.03731,0.00000,0.00345,75.64199
25.10000,1.25498,6251.04606,0.00000,0.00347,75.93363
25.20000,1.26006,6276.45180,0.00000,0.00349,76.24224
25.30000,1.26491,6300.04257,0.00000,0.00350,76.52881
25.40000,1.27005,6325.70982,0.00000,0.00352,76.84059
25.50000,1.27489,6349.75508,0.00000,0.00353,77.13268
25.60000,1.28009,6375.63094,0.00000,0.00355,77.44700
25.70000,1.28494,6399.90568,0.00000,0.00356,77.74188
25.80000,1.29008,6426.96992,0.00000,0.00357,78.07064
25.90000,1.29486,6449.81265,0.00000,0.00360,78.34811
26.00000,1.30006,6476.29201,0.00000,0.00360,78.66977
26.10000,1.30491,6500.07501,0.00000,0.00363,78.95867
26.20000,1.31005,6525.62231,0.00000,0.00364,79.26900
26.30000,1.31489,6550.41337,0.00000,0.00365,79.57015
26.40000,1.31997,6574.12931,0.00000,0.00368,79.85823
26.50000,1.32494,6600.91192,0.00000,0.00369,80.18357
26.60000,1.33002,6624.15177,0.00000,0.00371,80.46587
26.70000,1.33492,6650.54098,0.00000,0.00372,80.78643
26.80000,1.34000,6675.26051,0.00000,0.00374,81.08671
26.90000,1.34496,6700.78695,0.00000,0.00376,81.39679
27.00000,1.34999,6725.20623,0.00000,0.00376,81.69342
27.10000,1.35501,6751.07911,0.00000,0.00379,82.00770
27.20000,1.35997,6775.21676,0.00000,0.00380,82.30091
27.30000,1.36499,6802.24076,0.00000,0.00382,82.62918
27.40000,1.36996,6825.74809,0.00000,0.00383,82.91473
27.50000,1.37504,6851.64109,0.00000,0.00384,83.22926
27.60000,1.38000,6874.98227,0.00000,0.00386,83.51280
27.70000,1.38508,6901.90569,0.00000,0.00388,83.83985
27.80000,1.38987,6925.76617,0.00000,0.00390,84.12969
27.90000,1.39507,6952.44521,0.00000,0.00391,84.45377
28.00000,1.39997,6976.56795,0.00000,0.00392,84.74679
28.10000,1.40511,7002.26203,0.00000,0.00395,85.05891
28.20000,1.40990,7025.38937,0.00000,0.00395,85.33984
28.30000,1.41504,7052.35377,0.00000,0.00397,85.66739
28.40000,1.41994,7075.00130,0.00000,0.00399,85.94250
28.50000,1.42508,7100.98445,0.00000,0.00400,86.25812
28.60000,1.42993,7125.05877,0.00000,0.00403,86.55056
28.70000,1.43501,7151.89129,0.00000,0.00403,86.87651
28.80000,1.43991,7175.61916,0.00000,0.00406,87.16474
28.90000,1.44505,7201.74313,0.00000,0.00407,87.48208
29.00000,1.44995,7227.57876,0.00000,0.00409,87.79591
29.10000,1.45504,7254.47461,0.00000,0.00412,88.12262
29.20000,1.45994,7280.12845,0.00000,0.00412,88.43425
29.30000,1.46502,7303.64323,0.00000,0.00415,88.71989
29.40000,1.46998,7330.51822,0.00000,0.00416,89.04635
29.50000,1.47501,7353.47420,0.00000,0.00418,89.32521
29.60000,1.47997,7381.06444,0.00000,0.00420,89.66035
29.70000,1.48493,7404.46672,0.00000,0.00420,89.94463
29.80000,1.49001,7431.57491,0.00000,0.00423,90.27392
29.90000,1.49492,7455.56131,0.00000,0.00424,90.56529
30.00000,1.50006,7483.21041,0.00000,0.00426,90.90116
30.10000,1.50490,7506.28412,0.00000,0.00428,91.18144
30.20000,1.51004,7532.82905,0.00000,0.00429,91.50389
30.30000,1.51489,7556.24473,0.00000,0.00431,91.78833
30.40000,1.52009,7583.63754,0.00000,0.00432,92.12108
30.50000,1.52487,7607.86533,0.00000,0.00434,92.41538
30.60000,1.53001,7635.01525,0.00000,0.00436,92.74518
30.70000,1.53480,7658.90181,0.00000,0.00437,93.03534
30.80000,1.54000,7685.07496,0.00000,0.00440,93.35327
30.90000,1.54490,7710.37042,0.00000,0.00441,93.66055
31.00000,1.54992,7736.11292,0.00000,0.00443,93.97325
31.10000,1.55489,7762.23689,0.00000,0.00445,94.29059
31.20000,1.55997,7787.56812,0.00000,0.00446,94.59829
31.30000,1.56499,7813.03868,0.00000,0.00448,94.90769
31.40000,1.57001,7837.87966,0.00000,0.00449,95.20945
31.50000,1.57497,7864.01182,0.00000,0.00451,95.52688
31.60000,1.57994,7888.77308,0.00000,0.00453,95.82767
31.70000,1.58496,7914.63256,0.00000,0.00454,96.14179
31.80000,1.58998,7938.39842,0.00000,0.00456,96.43048
31.90000,1.59500,7964.15210,0.00000,0.00457,96.74332
32.00000,1.59991,7987.48657,0.00000,0.00460,97.02677
32.10000,1.60493,8014.31686,0.00000,0.00461,97.35269
32.20000,1.60995,8039.27928,0.00000,0.00463,97.65592
32.30000,1.61509,8067.26962,0.00000,0.00465,97.99593
32.40000,1.62000,8092.56658,0.00000,0.00465,98.30322
32.50000,1.62508,8119.83123,0.00000,0.00468,98.63441
32.60000,1.62998,8143.61200,0.00000,0.00469,98.92328
32.70000,1.63512,8169.20251,0.00000,0.00471,99.23414
32.80000,1.63997,8193.80581,0.00000,0.00473,99.53301
32.90000,1.64511,8220.45878,0.00000,0.00475,99.85677
33.00000,1.64989,8244.69849,0.00000,0.00476,100.15122
33.10000,1.65509,8272.72832,0.00000,0.00478,100.49170
33.20000,1.65994,8296.34368,0.00000,0.00480,100.77857
33.30000,1.66514,8322.95492,0.00000,0.00482,101.10182
33.40000,1.66998,8348.69221,0.00000,0.00483,101.41446
33.50000,1.67506,8375.06130,0.00000,0.00485,101.73478
33.60000,1.67997,8399.14829,0.00000,0.00486,102.02737
33.70000,1.68511,8425.91971,0.00000,0.00489,102.35257
33.80000,1.68995,8449.93889,0.00000,0.00490,102.64434
33.90000,1.69497,8477.12234,0.00000,0.00492,102.97455
34.00000,1.69993,8503.68813,0.00000,0.00494,103.29725
34.10000,1.70502,8526.66423,0.00000,0.00495,103.57635
34.20000,1.70998,8554.28651,0.00000,0.00498,103.91189
34.30000,1.71494,8578.44204,0.00000,0.00499,104.20531
34.40000,1.71996,8605.85198,0.00000,0.00501,104.53827
34.50000,1.72493,8631.03643,0.00000,0.00503,104.84420
34.60000,1.73007,8659.26445,0.00000,0.00505,105.18709
34.70000,1.73497,8683.80293,0.00000,0.00507,105.48517
34.80000,1.73999,8712.08832,0.00000,0.00508,105.82876
34.90000,1.74484,8736.59998,0.00000,0.00511,106.12651
35.00000,1.75004,8764.33551,0.00000,0.00512,106.46343
35.10000,1.75488,8786.66341,0.00000,0.00514,106.73465
35.20000,1.76008,8813.60546,0.00000,0.00516,107.06193
35.30000,1.76493,8837.94129,0.00000,0.00517,107.35754
35.40000,1.77001,8865.21414,0.00000,0.00520,107.68884
35.50000,1.77491,8890.90225,0.00000,0.00521,108.00088
35.60000,1.78005,8918.82181,0.00000,0.00524,108.34003
35.70000,1.78490,8942.77245,0.00000,0.00525,108.63096
35.80000,1.78998,8971.61812,0.00000,0.00527,108.98136
35.90000,1.79494,8998.07438,0.00000,0.00529,109.30273
36.00000,1.80002,9023.69693,0.00000,0.00531,109.61398
36.10000,1.80498,9049.63613,0.00000,0.00533,109.92907
36.20000,1.81001,9075.62077,0.00000,0.00534,110.24472
36.30000,1.81497,9102.43541,0.00000,0.00536,110.57044
36.40000,1.81999,9127.73535,0.00000,0.00538,110.87777
36.50000,1.82501,9155.07823,0.00000,0.00540,111.20992
36.60000,1.83010,9179.44610,0.00000,0.00542,111.50592
36.70000,1.83506,9206.07075,0.00000,0.00544,111.82934
36.80000,1.84002,9230.81115,0.00000,0.00545,112.12987
36.90000,1.84504,9258.99372,0.00000,0.00547,112.47221
37.00000,1.85007,9282.85196,0.00000,0.00549,112.76203
37.10000,1.85509,9310.74992,0.00000,0.00551,113.10091
37.20000,1.85999,9335.49702,0.00000,0.00553,113.40152
37.30000,1.86507,9363.31674,0.00000,0.00555,113.73946
37.40000,1.86998,9386.55362,0.00000,0.00556,114.02173
37.50000,1.87512,9412.98380,0.00000,0.00558,114.34278
37.60000,1.87990,9436.38980,0.00000,0.00560,114.62710
37.70000,1.88504,9465.33531,0.00000,0.00562,114.97872
37.80000,1.88995,9491.13071,0.00000,0.00564,115.29206
37.90000,1.89503,9517.76430,0.00000,0.00565,115.61559
38.00000,1.89993,9543.74447,0.00000,0.00567,115.93118
38.10000,1.90507,9570.82137,0.00000,0.00569,116.26009
38.20000,1.90986,9597.00420,0.00000,0.00571,116.57814
38.30000,1.91500,9624.01479,0.00000,0.00573,116.90625
38.40000,1.91990,9647.86336,0.00000,0.00575,117.19595
38.50000,1.92504,9674.20191,0.00000,0.00577,117.51589
38.60000,1.92994,9700.08522,0.00000,0.00578,117.83030
38.70000,1.93497,9726.37087,0.00000,0.00580,118.14961
38.80000,1.93999,9752.59021,0.00000,0.00582,118.46810
38.90000,1.94501,9778.49141,0.00000,0.00584,118.78273
39.00000,1.95003,9805.96393,0.00000,0.00586,119.11645
39.10000,1.95500,9829.31927,0.00000,0.00588,119.40016
39.20000,1.95996,9858.03306,0.00000,0.00590,119.74895
39.30000,1.96492,9882.67437,0.00000,0.00591,120.04828
39.40000,1.97006,9911.91640,0.00000,0.00594,120.40349
39.50000,1.97491,9935.19872,0.00000,0.00595,120.68631
39.60000,1.97999,9964.39531,0.00000,0.00598,121.04097
39.70000,1.98489,9989.31751,0.00000,0.00600,121.34371
39.80000,1.99003,10014.95346,0.00000,0.00601,121.65512
39.90000,1.99494,10040.70118,0.00000,0.00603,121.96788
40.00000,2.00014,10068.09771,0.00000,0.00606,122.30068
40.10000,2.00492,10093.70312,0.00000,0.00607,122.61172
40.20000,2.01006,10122.34911,0.00000,0.00609,122.95969
40.30000,2.01491,10146.77286,0.00000,0.00611,123.25637
40.40000,2.02011,10174.22676,0.00000,0.00613,123.58987
40.50000,2.02501,10199.86868,0.00000,0.00615,123.90135
40.60000,2.03003,10225.57393,0.00000,0.00616,124.21360
40.70000,2.03494,10250.36201,0.00000,0.00618,124.51471
40.80000,2.04002,10277.15132,0.00000,0.00620,124.84013
40.90000,2.04498,10302.98173,0.00000,0.00622,125.15390
41.00000,2.05000,10329.25993,0.00000,0.00624,125.47311
41.10000,2.05496,10357.69209,0.00000,0.00626,125.81848
41.20000,2.05999,10382.34681,0.00000,0.00627,126.11797
41.30000,2.06501,10410.23582,0.00000,0.00630,126.45675
41.40000,2.07003,10434.03596,0.00000,0.00632,126.74586
41.50000,2.07499,10462.48972,0.00000,0.00633,127.09150
41.60000,2.07996,10488.15697,0.00000,0.00635,127.40329
41.70000,2.08498,10514.53725,0.00000,0.00638,127.72374
41.80000,2.08994,10539.76342,0.00000,0.00639,128.03017
41.90000,2.09508,10567.58761,0.00000,0.00641,128.36816
42.00000,2.09993,10592.52545,0.00000,0.00643,128.67109
42.10000,2.10507,10620.37051,0.00000,0.00645,129.00933
42.20000,2.10997,10643.67816,0.00000,0.00647,129.29246
42.30000,2.11511,10671.72736,0.00000,0.00648,129.63318
42.40000,2.11996,10695.86352,0.00000,0.00651,129.92637
42.50000,2.12504,10724.01106,0.00000,0.00652,130.26829
42.60000,2.12988,10748.68590,0.00000,0.00654,130.56802
42.70000,2.13508,10777.83629,0.00000,0.00656,130.92212
42.80000,2.13993,10803.34559,0.00000,0.00658,131.23199
42.90000,2.14507,10830.05816,0.00000,0.00660,131.55648
43.00000,2.14991,10855.79917,0.00000,0.00662,131.86916
43.10000,2.15499,10882.34261,0.00000,0.00664,132.19160
43.20000,2.15996,10910.13774,0.00000,0.00666,132.52923
43.30000,2.16504,10936.59475,0.00000,0.00668,132.85062
43.40000,2.16994,10964.76838,0.00000,0.00670,133.19285
43.50000,2.17496,10991.02497,0.00000,0.00672,133.51180
43.60000,2.17992,11018.17861,0.00000,0.00674,133.84164
43.70000,2.18501,11043.07994,0.00000,0.00676,134.14413
43.80000,2.19003,11070.68211,0.00000,0.00678,134.47942
43.90000,2.19493,11095.09394,0.00000,0.00680,134.77596
44.00000,2.20001,11124.49989,0.00000,0.00682,135.13316
44.10000,2.20492,11148.75674,0.00000,0.00684,135.42782
44.20000,2.21006,11177.67319,0.00000,0.00686,135.77908
44.30000,2.21490,11202.84721,0.00000,0.00688,136.08488
44.40000,2.22004,11232.04753,0.00000,0.00691,136.43958
44.50000,2.22489,11254.98563,0.00000,0.00692,136.71822
44.60000,2.23009,11283.21066,0.00000,0.00694,137.06108
44.70000,2.23493,11307.67465,0.00000,0.00696,137.35825
44.80000,2.24007,11336.55012,0.00000,0.00699,137.70901
44.90000,2.24486,11362.68228,0.00000,0.00701,138.02645
45.00000,2.25000,11392.09196,0.00000,0.00703,138.38370
45.10000,2.25496,11417.69066,0.00000,0.00705,138.69465
45.20000,2.25998,11443.38474,0.00000,0.00707,139.00677
45.30000,2.26489,11469.96617,0.00000,0.00709,139.32966
45.40000,2.26997,11497.52438,0.00000,0.00711,139.66442
45.50000,2.27499,11525.33367,0.00000,0.00714,140.00223
45.60000,2.28007,11551.35706,0.00000,0.00715,140.31835
45.70000,2.28498,11576.44540,0.00000,0.00717,140.62310
45.80000,2.29000,11603.97679,0.00000,0.00719,140.95754
45.90000,2.29496,11630.72363,0.00000,0.00721,141.28244
46.00000,2.30004,11656.49742,0.00000,0.00723,141.59552
46.10000,2.30500,11682.19000,0.00000,0.00725,141.90762
46.20000,2.31003,11707.37743,0.00000,0.00726,142.21358
46.30000,2.31499,11735.63525,0.00000,0.00729,142.55684
46.40000,2.31995,11761.06557,0.00000,0.00731,142.86575
46.50000,2.32503,11790.66151,0.00000,0.00733,143.22526
46.60000,2.33006,11815.95698,0.00000,0.00735,143.53253
46.70000,2.33508,11842.77534,0.00000,0.00737,143.85831
46.80000,2.33992,11867.52170,0.00000,0.00739,144.15891
46.90000,2.34500,11896.18558,0.00000,0.00741,144.50710
47.00000,2.34991,11920.08927,0.00000,0.00743,144.79746
47.10000,2.35511,11949.28065,0.00000,0.00745,145.15206
47.20000,2.35989,11973.66044,0.00000,0.00747,145.44821
47.30000,2.36503,12003.48362,0.00000,0.00749,145.81048
47.40000,2.36988,12028.54291,0.00000,0.00751,146.11489
47.50000,2.37508,12056.48780,0.00000,0.00753,146.45434
47.60000,2.37992,12082.16399,0.00000,0.00755,146.76624
47.70000,2.38506,12109.22003,0.00000,0.00757,147.09490
47.80000,2.38991,12135.57571,0.00000,0.00759,147.41505
47.90000,2.39505,12161.96790,0.00000,0.00761,147.73565
48.00000,2.39995,12189.96942,0.00000,0.00763,148.07579
48.10000,2.40503,12215.92426,0.00000,0.00765,148.39107
48.20000,2.40988,12243.54729,0.00000,0.00767,148.72662
48.30000,2.41496,12269.48872,0.00000,0.00769,149.04174
48.40000,2.41998,12297.44852,0.00000,0.00771,149.38138
48.50000,2.42500,12324.08285,0.00000,0.00773,149.70491
48.60000,2.42996,12352.16483,0.00000,0.00775,150.04604
48.70000,2.43493,12377.09671,0.00000,0.00777,150.34889
48.80000,2.44001,12407.06146,0.00000,0.00779,150.71288
48.90000,2.44497,12432.75851,0.00000,0.00781,151.02504
49.00000,2.45005,12460.34428,0.00000,0.00784,151.36013
49.10000,2.45490,12483.89184,0.00000,0.00786,151.64617
49.20000,2.46004,12510.80036,0.00000,0.00788,151.97304
49.30000,2.46488,12536.19790,0.00000,0.00790,152.28155
49.40000,2.47002,12563.62498,0.00000,0.00791,152.61472
49.50000,2.47493,12588.44882,0.00000,0.00794,152.91626
49.60000,2.48007,12618.97087,0.00000,0.00796,153.28702
49.70000,2.48485,12644.44888,0.00000,0.00797,153.59651
49.80000,2.49005,12672.30362,0.00000,0.00799,153.93487
49.90000,2.49490,12697.71159,0.00000,0.00802,154.24351
50.00000,2.50004,12724.52921,0.00000,0.00804,154.56928
50.10000,2.50494,12750.56452,0.00000,0.00806,154.88554
50.20000,2.50996,12777.14670,0.00000,0.00808,155.20844
50.30000,2.51493,12804.48884,0.00000,0.00810,155.54057
50.40000,2.52007,12832.39871,0.00000,0.00813,155.87960
50.50000,2.52497,12858.45488,0.00000,0.00815,156.19612
50.60000,2.52999,12884.75990,0.00000,0.00817,156.51565
50.70000,2.53495,12912.85902,0.00000,0.00819,156.85698
50.80000,2.53998,12937.70522,0.00000,0.00821,157.15880
50.90000,2.54500,12966.51512,0.00000,0.00823,157.50876
51.00000,2.55002,12990.83382,0.00000,0.00825,157.80417
51.10000,2.55504,13020.67935,0.00000,0.00827,158.16671
51.20000,2.56001,13044.79539,0.00000,0.00829,158.45966
51.30000,2.56503,13072.82150,0.00000,0.00832,158.80010
51.40000,2.56999,13097.53954,0.00000,0.00833,159.10036
51.50000,2.57507,13125.53734,0.00000,0.00836,159.44046
51.60000,2.57992,13150.39396,0.00000,0.00838,159.74240
51.70000,2.58506,13180.36169,0.00000,0.00840,160.10643
51.80000,2.58990,13206.08109,0.00000,0.00842,160.41885
51.90000,2.59510,13234.99978,0.00000,0.00844,160.77014
52.00000,2.59989,13260.27364,0.00000,0.00847,161.07715
52.10000,2.60503,13289.08056,0.00000,0.00848,161.42708
52.20000,2.60993,13314.46618,0.00000,0.00851,161.73545
52.30000,2.61507,13341.46708,0.00000,0.00853,162.06343
52.40000,2.61998,13367.08218,0.00000,0.00855,162.37459
52.50000,2.62506,13394.41091,0.00000,0.00857,162.70656
52.60000,2.62990,13422.31333,0.00000,0.00859,163.04550
52.70000,2.63498,13448.83144,0.00000,0.00861,163.36763
52.80000,2.63989,13475.87407,0.00000,0.00863,163.69612
52.90000,2.64497,13502.58589,0.00000,0.00865,164.02060
53.00000,2.64987,13530.16496,0.00000,0.00867,164.35561
53.10000,2.65495,13556.09149,0.00000,0.00869,164.67055
53.20000,2.65997,13584.73301,0.00000,0.00871,165.01847
53.30000,2.66500,13609.52854,0.00000,0.00873,165.31967
53.40000,2.67002,13638.09705,0.00000,0.00876,165.66670
53.50000,2.67492,13664.50191,0.00000,0.00878,165.98745
53.60000,2.68000,13692.72172,0.00000,0.00880,166.33025
53.70000,2.68491,13717.70650,0.00000,0.00882,166.63375
53.80000,2.68999,13743.72691,0.00000,0.00884,166.94982
53.90000,2.69489,13769.44184,0.00000,0.00886,167.26219
54.00000,2.69997,13799.59583,0.00000,0.00888,167.62848
54.10000,2.70488,13824.42117,0.00000,0.00890,167.93005
54.20000,2.71008,13853.02544,0.00000,0.00893,168.27751
54.30000,2.71498,13877.06995,0.00000,0.00895,168.56959
54.40000,2.72012,13906.96913,0.00000,0.00897,168.93278
54.50000,2.72497,13931.94795,0.00000,0.00898,169.23621
54.60000,2.73005,13957.16220,0.00000,0.00901,169.54250
54.70000,2.73495,13983.87402,0.00000,0.00903,169.86697
54.80000,2.74009,14010.92708,0.00000,0.00905,170.19560
54.90000,2.74488,14037.16654,0.00000,0.00907,170.51434
55.00000,2.75002,14066.04797,0.00000,0.00909,170.86517
55.10000,2.75492,14092.04602,0.00000,0.00912,171.18098
55.20000,2.76006,14120.10193,0.00000,0.00914,171.52178
55.30000,2.76502,14145.91968,0.00000,0.00916,171.83540
55.40000,2.77005,14172.60170,0.00000,0.00918,172.15952
55.50000,2.77495,14200.56224,0.00000,0.00920,172.49916
55.60000,2.78003,14226.65417,0.00000,0.00922,172.81611
55.70000,2.78499,14255.75316,0.00000,0.00925,173.16958
55.80000,2.79002,14281.13282,0.00000,0.00926,173.47788
55.90000,2.79498,14310.52089,0.00000,0.00928,173.83487
56.00000,2.79994,14335.52355,0.00000,0.00931,174.13858
56.10000,2.80502,14364.23808,0.00000,0.00933,174.48739
56.20000,2.80993,14388.61042,0.00000,0.00935,174.78345
56.30000,2.81507,14418.20562,0.00000,0.00937,175.14295
56.40000,2.81991,14444.13215,0.00000,0.00939,175.45789
56.50000,2.82505,14472.46075,0.00000,0.00942,175.80201
56.60000,2.82996,14497.85233,0.00000,0.00943,176.11045
56.70000,2.83510,14526.16006,0.00000,0.00946,176.45431
56.80000,2.83982,14551.40263,0.00000,0.00948,176.76094
56.90000,2.84502,14579.28717,0.00000,0.00951,177.09966
57.00000,2.84987,14605.02297,0.00000,0.00952,177.41229
57.10000,2.85501,14633.04758,0.00000,0.00955,177.75271
57.20000,2.85991,14659.37942,0.00000,0.00957,178.07257
57.30000,2.86499,14688.27426,0.00000,0.00959,178.42357
57.40000,2.86990,14715.61193,0.00000,0.00961,178.75565
57.50000,2.87504,14742.15835,0.00000,0.00963,179.07812
57.60000,2.87994,14767.60358,0.00000,0.00966,179.38721
57.70000,2.88496,14794.66558,0.00000,0.00968,179.71594
57.80000,2.88993,14823.15361,0.00000,0.00970,180.06200
57.90000,2.89495,14848.43493,0.00000,0.00972,180.36910
58.00000,2.90003,14878.29238,0.00000,0.00974,180.73179
58.10000,2.90499,14901.79598,0.00000,0.00976,181.01729
58.20000,2.91001,14930.21995,0.00000,0.00978,181.36257
58.30000,2.91498,14955.56384,0.00000,0.00981,181.67043
58.40000,2.92000,14984.15172,0.00000,0.00983,182.01770
58.50000,2.92502,15008.38250,0.00000,0.00985,182.31203
58.60000,2.93010,15035.25525,0.00000,0.00987,182.63847
58.70000,2.93495,15061.53196,0.00000,0.00989,182.95766
58.80000,2.94009,15091.21060,0.00000,0.00992,183.31818
58.90000,2.94499,15117.22356,0.00000,0.00994,183.63417
59.00000,2.95013,15145.11853,0.00000,0.00996,183.97302
59.10000,2.95498,15169.83211,0.00000,0.00998,184.27322
59.20000,2.96006,15197.54380,0.00000,0.01000,184.60984
59.30000,2.96490,15223.26022,0.00000,0.01002,184.92223
59.40000,2.97010,15251.22225,0.00000,0.01005,185.26189
59.50000,2.97495,15277.56304,0.00000,0.01007,185.58186
59.60000,2.98003,15303.85166,0.00000,0.01010,185.90120
59.70000,2.98493,15330.72740,0.00000,0.01011,186.22767
59.80000,2.99001,15358.84142,0.00000,0.01014,186.56918
59.90000,2.99498,15385.13303,0.00000,0.01016,186.88855
60.00000,3.00006,15411.55726,0.00000,0.01018,187.20954
60.10000,3.00496,15437.52998,0.00000,0.01020,187.52504
60.20000,3.01004,15464.88106,0.00000,0.01023,187.85728
60.30000,3.01494,15493.07853,0.00000,0.01025,188.19981
60.40000,3.02003,15518.93950,0.00000,0.01027,188.51395
60.50000,3.02505,15547.26958,0.00000,0.01029,188.85808
60.60000,3.02995,15570.54222,0.00000,0.01031,189.14078
60.70000,3.03497,15599.99734,0.00000,0.01033,189.49859
60.80000,3.03994,15625.37998,0.00000,0.01036,189.80692
60.90000,3.04508,15654.40893,0.00000,0.01038,190.15954
61.00000,3.04998,15679.80200,0.00000,0.01040,190.46800
61.10000,3.05500,15709.80847,0.00000,0.01042,190.83250
61.20000,3.05991,15735.45337,0.00000,0.01045,191.14402
61.30000,3.06505,15764.31543,0.00000,0.01046,191.49461
61.40000,3.06989,15788.36292,0.00000,0.01049,191.78673
61.50000,3.07503,15816.38455,0.00000,0.01051,192.12712
61.60000,3.07982,15841.44533,0.00000,0.01053,192.43154
61.70000,3.08502,15869.05122,0.00000,0.01055,192.76688
61.80000,3.08992,15896.08490,0.00000,0.01057,193.09526
61.90000,3.09506,15923.46728,0.00000,0.01059,193.42789
62.00000,3.09997,15949.65458,0.00000,0.01062,193.74599
62.10000,3.10505,15977.14424,0.00000,0.01064,194.07992
62.20000,3.10995,16004.83358,0.00000,0.01066,194.41627
62.30000,3.11503,16029.87945,0.00000,0.01068,194.72051
62.40000,3.11999,16057.94132,0.00000,0.01070,195.06139
62.50000,3.12496,16083.20177,0.00000,0.01072,195.36824
62.60000,3.12992,16110.46642,0.00000,0.01075,195.69943
62.70000,3.13500,16137.14099,0.00000,0.01077,196.02346
62.80000,3.14002,16165.50237,0.00000,0.01079,196.36797
62.90000,3.14505,16190.52589,0.00000,0.01081,196.67194
63.00000,3.15007,16218.68908,0.00000,0.01084,197.01405
63.10000,3.15497,16243.82734,0.00000,0.01086,197.31941
63.20000,3.16011,16272.53145,0.00000,0.01088,197.66809
63.30000,3.16502,16298.10333,0.00000,0.01090,197.97872
63.40000,3.17010,16327.03543,0.00000,0.01093,198.33017
63.50000,3.17494,16352.00381,0.00000,0.01095,198.63347
63.60000,3.18008,16380.24300,0.00000,0.01097,198.97650
63.70000,3.18499,16404.62875,0.00000,0.01099,199.27272
63.80000,3.19013,16431.65946,0.00000,0.01101,199.60107
63.90000,3.19491,16455.98412,0.00000,0.01104,199.89655
64.00000,3.20011,16484.93856,0.00000,0.01106,200.24827
64.10000,3.20496,16510.90682,0.00000,0.01108,200.56372
64.20000,3.21010,16539.65712,0.00000,0.01110,200.91296
64.30000,3.21494,16566.13946,0.00000,0.01112,201.23465
64.40000,3.22002,16593.79750,0.00000,0.01115,201.57062
64.50000,3.22487,16619.49158,0.00000,0.01117,201.88274
64.60000,3.23001,16646.35837,0.00000,0.01120,202.20910
64.70000,3.23491,16673.38163,0.00000,0.01121,202.53736
64.80000,3.24005,16698.48561,0.00000,0.01124,202.84230
64.90000,3.24495,16726.56536,0.00000,0.01126,203.18340
65.00000,3.24998,16753.65120,0.00000,0.01128,203.51242
65.10000,3.25500,16782.45068,0.00000,0.01131,203.86226
65.20000,3.26002,16807.41906,0.00000,0.01133,204.16556
65.30000,3.26504,16835.38705,0.00000,0.01135,204.50529
65.40000,3.26995,16860.03357,0.00000,0.01137,204.80468
65.50000,3.27503,16889.70625,0.00000,0.01139,205.16513
65.60000,3.27993,16914.37215,0.00000,0.01142,205.46475
65.70000,3.28507,16943.56650,0.00000,0.01144,205.81939
65.80000,3.28992,16967.42475,0.00000,0.01146,206.10920
65.90000,3.29500,16996.07819,0.00000,0.01148,206.45726
66.00000,3.29990,17021.30586,0.00000,0.01151,206.76371
66.10000,3.30504,17047.66452,0.00000,0.01153,207.08390
66.20000,3.30989,17073.72218,0.00000,0.01155,207.40043
66.30000,3.31509,17101.61120,0.00000,0.01157,207.73921
66.40000,3.31987,17128.37219,0.00000,0.01159,208.06429
66.50000,3.32501,17157.58443,0.00000,0.01162,208.41914
66.60000,3.32992,17183.07585,0.00000,0.01164,208.72879
66.70000,3.33506,17210.24811,0.00000,0.01166,209.05886
66.80000,3.33996,17235.92430,0.00000,0.01168,209.37076
66.90000,3.34498,17261.92981,0.00000,0.01170,209.68666
67.00000,3.34989,17288.72955,0.00000,0.01173,210.01220
67.10000,3.35497,17313.89016,0.00000,0.01175,210.31784
67.20000,3.35993,17341.11309,0.00000,0.01177,210.64852
67.30000,3.36495,17367.15287,0.00000,0.01179,210.96484
67.40000,3.36997,17396.63333,0.00000,0.01182,211.32295
67.50000,3.37506,17422.06216,0.00000,0.01184,211.63184
67.60000,3.38008,17449.97799,0.00000,0.01186,211.97094
67.70000,3.38510,17474.88827,0.00000,0.01188,212.27354
67.80000,3.39006,17503.15577,0.00000,0.01191,212.61691
67.90000,3.39503,17529.25664,0.00000,0.01193,212.93397
68.00000,3.40005,17556.20837,0.00000,0.01195,213.26136
68.10000,3.40501,17581.50011,0.00000,0.01197,213.56859
68.20000,3.41009,17609.93451,0.00000,0.01200,213.91399
68.30000,3.41488,17634.22936,0.00000,0.01202,214.20911
68.40000,3.42008,17662.76658,0.00000,0.01204,214.55576
68.50000,3.42498,17688.02404,0.00000,0.01206,214.86257
68.60000,3.43012,17715.68358,0.00000,0.01208,215.19856
68.70000,3.43497,17740.65197,0.00000,0.01211,215.50186
68.80000,3.44005,17769.44101,0.00000,0.01213,215.85157
68.90000,3.44489,17795.17084,0.00000,0.01215,216.16412
69.00000,3.45009,17822.64262,0.00000,0.01218,216.49783
69.10000,3.45494,17847.43220,0.00000,0.01220,216.79896
69.20000,3.46002,17873.37661,0.00000,0.01222,217.11411
69.30000,3.46492,17899.97071,0.00000,0.01224,217.43716
69.40000,3.47006,17927.27113,0.00000,0.01226,217.76879
69.50000,3.47497,17954.38975,0.00000,0.01228,218.09821
69.60000,3.48011,17981.04793,0.00000,0.01231,218.42203
69.70000,3.48495,18008.25447,0.00000,0.01233,218.75252
69.80000,3.48997,18035.31647,0.00000,0.01236,219.08125
69.90000,3.49493,18062.93726,0.00000,0.01238,219.41677
70.00000,3.50002,18088.22155,0.00000,0.01240,219.72391
70.10000,3.50498,18115.39084,0.00000,0.01242,220.05394
70.20000,3.50994,18139.62609,0.00000,0.01244,220.34834
70.30000,3.51496,18169.41351,0.00000,0.01247,220.71018
70.40000,3.51993,18194.55624,0.00000,0.01250,221.01559
70.50000,3.52507,18223.16349,0.00000,0.01252,221.36310
70.60000,3.52991,18248.04842,0.00000,0.01254,221.66538
70.70000,3.53505,18275.42782,0.00000,0.01256,221.99797
70.80000,3.53996,18299.91192,0.00000,0.01258,222.29539
70.90000,3.54516,18328.94534,0.00000,0.01261,222.64807
71.00000,3.54994,18352.11366,0.00000,0.01263,222.92950
71.10000,3.55508,18380.18894,0.00000,0.01265,223.27054
71.20000,3.55993,18406.92312,0.00000,0.01268,223.59529
71.30000,3.56507,18434.15201,0.00000,0.01270,223.92605
71.40000,3.56997,18461.49266,0.00000,0.01272,224.25816
71.50000,3.57511,18487.52797,0.00000,0.01274,224.57442
71.60000,3.57990,18512.90762,0.00000,0.01276,224.88272
71.70000,3.58498,18539.38550,0.00000,0.01279,225.20435
71.80000,3.58994,18567.17765,0.00000,0.01281,225.54196
71.90000,3.59502,18593.75834,0.00000,0.01283,225.86484
72.00000,3.59999,18620.60726,0.00000,0.01285,226.19098
72.10000,3.60495,18645.82449,0.00000,0.01288,226.49731
72.20000,3.60997,18672.81049,0.00000,0.01290,226.82511
72.30000,3.61499,18697.37953,0.00000,0.01293,227.12356
72.40000,3.62001,18725.06291,0.00000,0.01295,227.45984
72.50000,3.62504,18749.98212,0.00000,0.01297,227.76255
72.60000,3.62994,18777.38833,0.00000,0.01299,228.09546
72.70000,3.63490,18804.15678,0.00000,0.01301,228.42062
72.80000,3.64004,18832.86834,0.00000,0.01304,228.76939
72.90000,3.64501,18857.32263,0.00000,0.01306,229.06645
73.00000,3.65009,18884.50682,0.00000,0.01308,229.39666
73.10000,3.65493,18909.16675,0.00000,0.01311,229.69622
73.20000,3.66007,18937.28673,0.00000,0.01313,230.03780
73.30000,3.66492,18961.68441,0.00000,0.01316,230.33417
73.40000,3.67012,18990.74018,0.00000,0.01318,230.68712
73.50000,3.67484,19015.39415,0.00000,0.01320,230.98660
73.60000,3.67998,19043.89411,0.00000,0.01322,231.33280
73.70000,3.68489,19070.59550,0.00000,0.01325,231.65715
73.80000,3.69003,19097.57406,0.00000,0.01327,231.98487
73.90000,3.69493,19121.61708,0.00000,0.01329,232.27692
74.00000,3.70001,19147.86398,0.00000,0.01332,232.59575
74.10000,3.70492,19175.08394,0.00000,0.01334,232.92640
74.20000,3.71000,19200.70350,0.00000,0.01337,233.23761
74.30000,3.71496,19227.81765,0.00000,0.01339,233.56698
74.40000,3.72004,19252.92611,0.00000,0.01341,233.87198
74.50000,3.72495,19279.79439,0.00000,0.01344,234.19836
74.60000,3.72997,19304.22485,0.00000,0.01346,234.49512
74.70000,3.73499,19332.48788,0.00000,0.01348,234.83844
74.80000,3.73995,19357.40113,0.00000,0.01350,235.14107
74.90000,3.74497,19384.76413,0.00000,0.01353,235.47346
75.00000,3.74988,19410.03799,0.00000,0.01355,235.78047
75.10000,3.75502,19439.42904,0.00000,0.01357,236.13750
75.20000,3.75992,19463.42736,0.00000,0.01359,236.42901
75.30000,3.76512,19490.59218,0.00000,0.01362,236.75899
75.40000,3.76991,19514.06151,0.00000,0.01364,237.04408
75.50000,3.77505,19542.38713,0.00000,0.01367,237.38816
75.60000,3.77989,19567.41661,0.00000,0.01369,237.69221
75.70000,3.78509,19594.79451,0.00000,0.01371,238.02477
75.80000,3.78988,19619.04317,0.00000,0.01373,238.31933
75.90000,3.79502,19647.05735,0.00000,0.01376,238.65963
76.00000,3.79986,19672.27459,0.00000,0.01378,238.96595
76.10000,3.80500,19697.24000,0.00000,0.01380,239.26922
76.20000,3.80997,19722.92215,0.00000,0.01382,239.58119
76.30000,3.81505,19747.88904,0.00000,0.01384,239.88447
76.40000,3.81995,19773.00644,0.00000,0.01387,240.18958
76.50000,3.82497,19799.08049,0.00000,0.01389,240.50631
76.60000,3.82994,19825.89811,0.00000,0.01391,240.83207
76.70000,3.83502,19852.01240,0.00000,0.01394,241.14929
76.80000,3.83992,19878.35467,0.00000,0.01396,241.46928
76.90000,3.84494,19904.03384,0.00000,0.01399,241.78121
77.00000,3.84991,19932.22684,0.00000,0.01400,242.12368
77.10000,3.85499,19956.80034,0.00000,0.01403,242.42219
77.20000,3.86007,19984.56717,0.00000,0.01406,242.75948
77.30000,3.86503,20009.05573,0.00000,0.01408,243.05695
77.40000,3.86999,20037.51248,0.00000,0.01410,243.40262
77.50000,3.87496,20062.60455,0.00000,0.01412,243.70743
77.60000,3.88004,20089.03474,0.00000,0.01415,244.02848
77.70000,3.88500,20112.24627,0.00000,0.01417,244.31044
77.80000,3.89002,20139.72998,0.00000,0.01419,244.64430
77.90000,3.89487,20163.82962,0.00000,0.01422,244.93704
78.00000,3.90007,20192.31468,0.00000,0.01424,245.28306
78.10000,3.90491,20216.53503,0.00000,0.01427,245.57727
78.20000,3.91011,20244.59839,0.00000,0.01429,245.91817
78.30000,3.91490,20269.20021,0.00000,0.01431,246.21701
78.40000,3.92004,20297.30678,0.00000,0.01434,246.55844
78.50000,3.92488,20321.30063,0.00000,0.01436,246.84990
78.60000,3.93008,20346.45379,0.00000,0.01438,247.15544
78.70000,3.93493,20372.17170,0.00000,0.01440,247.46785
78.80000,3.94001,20397.34423,0.00000,0.01442,247.77362
78.90000,3.94485,20424.27361,0.00000,0.01445,248.10075
79.00000,3.94993,20449.87977,0.00000,0.01448,248.41179
79.10000,3.95496,20477.56463,0.00000,0.01450,248.74809
79.20000,3.95998,20502.39891,0.00000,0.01452,249.04976
79.30000,3.96494,20529.06603,0.00000,0.01454,249.37370
79.40000,3.96996,20552.90341,0.00000,0.01457,249.66326
79.50000,3.97504,20580.80584,0.00000,0.01459,250.00220
79.60000,3.98001,20603.72382,0.00000,0.01461,250.28059
79.70000,3.98503,20631.50257,0.00000,0.01464,250.61803
79.80000,3.98987,20654.79457,0.00000,0.01466,250.90096
79.90000,3.99501,20682.23208,0.00000,0.01469,251.23426
80.00000,3.99998,20707.27795,0.00000,0.01471,251.53850
80.10000,4.00506,20733.85715,0.00000,0.01473,251.86136
80.20000,4.00990,20758.12221,0.00000,0.01475,252.15612
80.30000,4.01504,20785.72363,0.00000,0.01478,252.49140
80.40000,4.01989,20810.28968,0.00000,0.01480,252.78982
80.50000,4.02509,20837.02534,0.00000,0.01482,253.11458
80.60000,4.02999,20860.78823,0.00000,0.01485,253.40324
80.70000,4.03501,20887.66545,0.00000,0.01487,253.72973
80.80000,4.03992,20915.21919,0.00000,0.01489,254.06443
80.90000,4.04506,20940.73445,0.00000,0.01492,254.37437
81.00000,4.05002,20965.35861,0.00000,0.01494,254.67349
81.10000,4.05510,20990.71294,0.00000,0.01497,254.98148
81.20000,4.05995,21015.40267,0.00000,0.01499,255.28140
81.30000,4.06503,21041.75687,0.00000,0.01501,255.60153
81.40000,4.06993,21066.44660,0.00000,0.01504,255.90144
81.50000,4.07507,21092.35525,0.00000,0.01506,256.21617
81.60000,4.07998,21117.38473,0.00000,0.01508,256.52021
81.70000,4.08500,21143.17268,0.00000,0.01511,256.83346
81.80000,4.08996,21169.34359,0.00000,0.01513,257.15137
81.90000,4.09504,21192.92617,0.00000,0.01515,257.43783
82.00000,4.10006,21218.44739,0.00000,0.01518,257.74785
82.10000,4.10497,21242.40994,0.00000,0.01520,258.03893
82.20000,4.10999,21271.12448,0.00000,0.01523,258.38774
82.30000,4.11489,21295.77100,0.00000,0.01525,258.68713
82.40000,4.12003,21322.92092,0.00000,0.01528,259.01693
82.50000,4.12494,21346.60333,0.00000,0.01530,259.30460
82.60000,4.13002,21372.40171,0.00000,0.01533,259.61799
82.70000,4.13486,21397.65322,0.00000,0.01535,259.92473
82.80000,4.14006,21425.73744,0.00000,0.01537,260.26587
82.90000,4.14497,21448.95792,0.00000,0.01540,260.54794
83.00000,4.15011,21475.44920,0.00000,0.01542,260.86974
83.10000,4.15483,21498.61753,0.00000,0.01544,261.15117
83.20000,4.16003,21525.06709,0.00000,0.01546,261.47247
83.30000,4.16494,21550.00716,0.00000,0.01549,261.77542
83.40000,4.17008,21575.53434,0.00000,0.01551,262.08551
83.50000,4.17486,21599.50733,0.00000,0.01554,262.37672
83.60000,4.17994,21625.52029,0.00000,0.01556,262.69271
83.70000,4.18485,21650.73305,0.00000,0.01558,262.99897
83.80000,4.18999,21676.48077,0.00000,0.01561,263.31174
83.90000,4.19495,21702.48330,0.00000,0.01563,263.62760
84.00000,4.19997,21726.87948,0.00000,0.01565,263.92395
84.10000,4.20494,21753.29477,0.00000,0.01568,264.24483
84.20000,4.20996,21777.09639,0.00000,0.01570,264.53395
84.30000,4.21504,21804.25972,0.00000,0.01572,264.86392
84.40000,4.22006,21827.79163,0.00000,0.01575,265.14977
84.50000,4.22502,21853.59746,0.00000,0.01577,265.46324
84.60000,4.22993,21877.61515,0.00000,0.01579,265.75499
84.70000,4.23501,21905.03478,0.00000,0.01582,266.08807
84.80000,4.23997,21928.29847,0.00000,0.01584,266.37066
84.90000,4.24511,21954.37253,0.00000,0.01586,266.68739
85.00000,4.24990,21977.83589,0.00000,0.01588,266.97241
85.10000,4.25510,22004.37039,0.00000,0.01591,267.29473
85.20000,4.25994,22026.98737,0.00000,0.01593,267.56947
85.30000,4.26508,22053.05248,0.00000,0.01595,267.88609
85.40000,4.26993,22076.51585,0.00000,0.01598,268.17111
85.50000,4.27501,22102.39619,0.00000,0.01600,268.48548
85.60000,4.27985,22126.44964,0.00000,0.01602,268.77767
85.70000,4.28499,22152.86344,0.00000,0.01605,269.09853
85.80000,4.28996,22177.67388,0.00000,0.01607,269.39991
85.90000,4.29504,22202.08794,0.00000,0.01610,269.69647
86.00000,4.29994,22226.84622,0.00000,0.01612,269.99722
86.10000,4.30502,22251.83100,0.00000,0.01615,270.30072
86.20000,4.30999,22273.00256,0.00000,0.01617,270.55790
86.30000,4.31507,22292.25934,0.00000,0.01619,270.79182
86.40000,4.31997,21685.00721,0.00000,0.01616,263.41531
86.40200,4.32015,20999.38244,0.00000,0.01595,255.08679
86.40400,4.32039,20110.88729,0.00000,0.01544,244.29393
86.40600,4.32063,19084.01996,0.00000,0.01458,231.82022
86.40800,4.32099,17946.81251,0.00000,0.01337,218.00616
86.41000,4.32135,16731.96256,0.00000,0.01181,203.24896
86.41200,4.32164,15478.31148,0.00000,0.00991,188.02043
86.41400,4.32200,14208.36151,0.00000,0.00775,172.59390
86.41600,4.32236,12934.64899,0.00000,0.00544,157.12167