File: scratch/college-stuff/ME Lab/ME lab Fall 2013/group15/group15.is_tens_RawData/Specimen_RawData_2.csv
Time,Extension,Load,Strain 2,Tensile strain,Tensile stress
(sec),(mm),(N),(mm/mm),(mm/mm),(MPa)
0.00000,0.00006,-0.11813,0.00000,0.00000,-0.00143
0.10000,0.00179,2.34114,0.00000,0.00000,0.02844
0.20000,0.00747,4.04026,0.00000,0.00000,0.04908
0.30000,0.01369,4.98204,0.00000,0.00001,0.06052
0.40000,0.01931,6.57606,0.00000,0.00001,0.07988
0.50000,0.02475,6.58618,0.00000,0.00001,0.08000
0.60000,0.02983,6.89353,0.00000,0.00001,0.08374
0.70000,0.03504,7.81187,0.00000,0.00001,0.09489
0.80000,0.04000,8.76433,0.00000,0.00002,0.10646
0.90000,0.04502,9.46492,0.00000,0.00002,0.11497
1.00000,0.04998,12.05411,0.00000,0.00002,0.14643
1.10000,0.05501,14.49844,0.00000,0.00002,0.17612
1.20000,0.06009,15.91014,0.00000,0.00002,0.19327
1.30000,0.06505,17.44665,0.00000,0.00002,0.21193
1.40000,0.07001,17.81890,0.00000,0.00002,0.21645
1.50000,0.07498,18.97822,0.00000,0.00002,0.23053
1.60000,0.08006,19.11968,0.00000,0.00001,0.23225
1.70000,0.08502,19.32627,0.00000,0.00001,0.23476
1.80000,0.09010,19.87787,0.00000,0.00001,0.24146
1.90000,0.09495,20.07156,0.00000,0.00001,0.24382
2.00000,0.10009,20.26800,0.00000,0.00001,0.24620
2.10000,0.10493,20.83321,0.00000,0.00001,0.25307
2.20000,0.11013,21.16971,0.00000,0.00001,0.25716
2.30000,0.11492,22.21997,0.00000,0.00001,0.26991
2.40000,0.12006,23.92190,0.00000,0.00001,0.29059
2.50000,0.12490,24.57795,0.00000,0.00000,0.29856
2.60000,0.13010,25.84797,0.00000,0.00000,0.31398
2.70000,0.13500,27.69897,0.00000,0.00000,0.33647
2.80000,0.14009,29.39617,0.00000,0.00000,0.35709
2.90000,0.14493,31.47673,0.00000,0.00000,0.38236
3.00000,0.15001,36.12796,0.00000,0.00000,0.43886
3.10000,0.15497,39.68778,0.00000,0.00000,0.48210
3.20000,0.16006,43.52027,0.00000,0.00000,0.52866
3.30000,0.16496,49.93815,0.00000,0.00000,0.60662
3.40000,0.16998,54.46130,0.00000,0.00000,0.66156
3.50000,0.17500,61.35873,0.00000,0.00000,0.74535
3.60000,0.18003,70.90434,0.00000,0.00000,0.86130
3.70000,0.18505,82.45767,0.00000,0.00000,1.00164
3.80000,0.18995,94.54090,0.00000,0.00000,1.14842
3.90000,0.19503,108.19630,0.00000,0.00001,1.31430
4.00000,0.19994,122.62504,0.00000,0.00001,1.48957
4.10000,0.20508,138.38713,0.00000,0.00002,1.68104
4.20000,0.20992,154.33168,0.00000,0.00002,1.87472
4.30000,0.21506,171.32316,0.00000,0.00003,2.08112
4.40000,0.21985,188.07811,0.00000,0.00004,2.28465
4.50000,0.22505,206.70181,0.00000,0.00004,2.51088
4.60000,0.22995,225.79224,0.00000,0.00005,2.74278
4.70000,0.23503,245.07870,0.00000,0.00006,2.97706
4.80000,0.23988,266.78632,0.00000,0.00007,3.24075
4.90000,0.24502,287.98259,0.00000,0.00007,3.49822
5.00000,0.24998,309.68671,0.00000,0.00008,3.76187
5.10000,0.25506,332.33827,0.00000,0.00009,4.03703
5.20000,0.25996,357.08533,0.00000,0.00010,4.33764
5.30000,0.26499,381.54158,0.00000,0.00011,4.63472
5.40000,0.27001,407.82988,0.00000,0.00012,4.95405
5.50000,0.27503,434.99060,0.00000,0.00014,5.28398
5.60000,0.28005,467.19834,0.00000,0.00015,5.67522
5.70000,0.28502,502.82986,0.00000,0.00017,6.10805
5.80000,0.28998,540.08262,0.00000,0.00019,6.56057
5.90000,0.29500,576.66400,0.00000,0.00021,7.00494
6.00000,0.30008,611.41141,0.00000,0.00023,7.42703
6.10000,0.30499,648.46645,0.00000,0.00025,7.87715
6.20000,0.31007,688.12738,0.00000,0.00027,8.35892
6.30000,0.31497,725.25926,0.00000,0.00029,8.80998
6.40000,0.32005,764.56768,0.00000,0.00031,9.28747
6.50000,0.32502,802.94628,0.00000,0.00033,9.75367
6.60000,0.33010,844.95107,0.00000,0.00036,10.26391
6.70000,0.33488,881.08173,0.00000,0.00038,10.70281
6.80000,0.34008,919.86805,0.00000,0.00040,11.17396
6.90000,0.34493,955.96500,0.00000,0.00042,11.61244
7.00000,0.35007,995.61326,0.00000,0.00045,12.09406
7.10000,0.35491,1033.79609,0.00000,0.00047,12.55788
7.20000,0.36005,1074.37437,0.00000,0.00049,13.05080
7.30000,0.36490,1111.10285,0.00000,0.00051,13.49695
7.40000,0.37004,1150.15907,0.00000,0.00053,13.97138
7.50000,0.37494,1186.38827,0.00000,0.00055,14.41147
7.60000,0.38002,1223.74957,0.00000,0.00058,14.86531
7.70000,0.38492,1261.63047,0.00000,0.00060,15.32546
7.80000,0.39001,1298.48719,0.00000,0.00062,15.77317
7.90000,0.39497,1337.80986,0.00000,0.00064,16.25084
8.00000,0.39999,1373.18037,0.00000,0.00066,16.68050
8.10000,0.40495,1411.88968,0.00000,0.00069,17.15071
8.20000,0.40992,1447.46974,0.00000,0.00071,17.58292
8.30000,0.41506,1485.18067,0.00000,0.00073,18.04101
8.40000,0.42002,1520.30187,0.00000,0.00075,18.46763
8.50000,0.42504,1557.13903,0.00000,0.00077,18.91511
8.60000,0.42989,1590.67810,0.00000,0.00079,19.32252
8.70000,0.43503,1629.41180,0.00000,0.00082,19.79303
8.80000,0.43987,1664.73147,0.00000,0.00084,20.22207
8.90000,0.44507,1702.54577,0.00000,0.00086,20.68141
9.00000,0.44992,1737.28559,0.00000,0.00088,21.10341
9.10000,0.45500,1773.23036,0.00000,0.00090,21.54005
9.20000,0.45984,1806.62777,0.00000,0.00092,21.94574
9.30000,0.46510,1842.82772,0.00000,0.00094,22.38547
9.40000,0.46995,1877.06370,0.00000,0.00096,22.80134
9.50000,0.47503,1913.54677,0.00000,0.00099,23.24452
9.60000,0.47987,1947.34130,0.00000,0.00101,23.65503
9.70000,0.48501,1980.61783,0.00000,0.00103,24.05925
9.80000,0.48997,2014.98922,0.00000,0.00105,24.47677
9.90000,0.49500,2047.22416,0.00000,0.00107,24.86834
10.00000,0.49996,2080.75121,0.00000,0.00109,25.27561
10.10000,0.50498,2111.12276,0.00000,0.00111,25.64454
10.20000,0.50994,2142.71322,0.00000,0.00113,26.02828
10.30000,0.51503,2170.71678,0.00000,0.00115,26.36845
10.40000,0.52005,2202.52294,0.00000,0.00116,26.75481
10.50000,0.52501,2231.01042,0.00000,0.00118,27.10086
10.60000,0.53003,2262.92331,0.00000,0.00120,27.48852
10.70000,0.53500,2289.10465,0.00000,0.00122,27.80655
10.80000,0.54008,2315.71235,0.00000,0.00124,28.12976
10.90000,0.54504,2340.65857,0.00000,0.00125,28.43279
11.00000,0.55000,2366.74510,0.00000,0.00127,28.74967
11.10000,0.55497,2389.90970,0.00000,0.00128,29.03106
11.20000,0.56011,2413.97433,0.00000,0.00129,29.32338
11.30000,0.56495,2435.19265,0.00000,0.00131,29.58113
11.40000,0.57009,2460.44155,0.00000,0.00133,29.88784
11.50000,0.57494,2484.72281,0.00000,0.00134,30.18279
11.60000,0.58008,2509.34996,0.00000,0.00136,30.48195
11.70000,0.58492,2530.91212,0.00000,0.00137,30.74387
11.80000,0.59006,2555.59068,0.00000,0.00139,31.04365
11.90000,0.59491,2578.05847,0.00000,0.00140,31.31657
12.00000,0.59999,2602.84077,0.00000,0.00142,31.61761
12.10000,0.60489,2626.33357,0.00000,0.00143,31.90299
12.20000,0.61009,2651.66629,0.00000,0.00145,32.21071
12.30000,0.61493,2675.59811,0.00000,0.00147,32.50142
12.40000,0.62002,2702.22165,0.00000,0.00148,32.82482
12.50000,0.62492,2727.05033,0.00000,0.00149,33.12643
12.60000,0.63006,2751.86077,0.00000,0.00151,33.42781
12.70000,0.63502,2778.48020,0.00000,0.00153,33.75116
12.80000,0.63999,2802.65678,0.00000,0.00155,34.04485
12.90000,0.64495,2830.80749,0.00000,0.00156,34.38680
13.00000,0.64991,2854.04194,0.00000,0.00157,34.66904
13.10000,0.65505,2881.51279,0.00000,0.00160,35.00274
13.20000,0.65996,2906.30199,0.00000,0.00161,35.30386
13.30000,0.66504,2933.90658,0.00000,0.00163,35.63918
13.40000,0.66988,2957.03430,0.00000,0.00164,35.92012
13.50000,0.67502,2983.45536,0.00000,0.00166,36.24107
13.60000,0.67993,3006.96064,0.00000,0.00167,36.52660
13.70000,0.68513,3032.94808,0.00000,0.00169,36.84227
13.80000,0.68991,3058.08317,0.00000,0.00170,37.14760
13.90000,0.69505,3084.38148,0.00000,0.00172,37.46705
14.00000,0.69990,3109.51509,0.00000,0.00174,37.77236
14.10000,0.70510,3135.65806,0.00000,0.00175,38.08993
14.20000,0.71000,3160.12055,0.00000,0.00177,38.38708
14.30000,0.71502,3186.48219,0.00000,0.00179,38.70731
14.40000,0.71993,3211.84210,0.00000,0.00180,39.01536
14.50000,0.72507,3237.26684,0.00000,0.00182,39.32420
14.60000,0.72997,3262.26912,0.00000,0.00184,39.62792
14.70000,0.73505,3287.85069,0.00000,0.00185,39.93866
14.80000,0.73995,3313.30970,0.00000,0.00187,40.24792
14.90000,0.74498,3340.19847,0.00000,0.00188,40.57455
15.00000,0.75000,3366.60631,0.00000,0.00190,40.89534
15.10000,0.75502,3391.05874,0.00000,0.00192,41.19237
15.20000,0.75998,3417.44237,0.00000,0.00193,41.51286
15.30000,0.76501,3441.34271,0.00000,0.00195,41.80319
15.40000,0.76997,3468.57570,0.00000,0.00197,42.13399
15.50000,0.77499,3492.26557,0.00000,0.00198,42.42176
15.60000,0.78007,3521.03300,0.00000,0.00200,42.77121
15.70000,0.78498,3544.04226,0.00000,0.00201,43.05071
15.80000,0.79000,3571.06552,0.00000,0.00203,43.37897
15.90000,0.79484,3593.60948,0.00000,0.00205,43.65282
16.00000,0.80010,3621.19600,0.00000,0.00207,43.98793
16.10000,0.80495,3644.05625,0.00000,0.00208,44.26562
16.20000,0.81003,3671.58987,0.00000,0.00210,44.60008
16.30000,0.81487,3695.25291,0.00000,0.00211,44.88752
16.40000,0.82007,3722.59319,0.00000,0.00213,45.21963
16.50000,0.82492,3746.13404,0.00000,0.00214,45.50559
16.60000,0.83006,3773.57639,0.00000,0.00216,45.83894
16.70000,0.83484,3798.82455,0.00000,0.00218,46.14564
16.80000,0.83998,3824.30330,0.00000,0.00219,46.45514
16.90000,0.84489,3849.28919,0.00000,0.00221,46.75865
17.00000,0.85009,3876.04423,0.00000,0.00223,47.08366
17.10000,0.85499,3901.13480,0.00000,0.00225,47.38844
17.20000,0.86001,3927.26138,0.00000,0.00226,47.70581
17.30000,0.86491,3953.28291,0.00000,0.00228,48.02190
17.40000,0.87000,3977.32444,0.00000,0.00230,48.31394
17.50000,0.87502,4003.62015,0.00000,0.00231,48.63336
17.60000,0.87998,4026.95462,0.00000,0.00233,48.91682
17.70000,0.88494,4053.95813,0.00000,0.00235,49.24484
17.80000,0.88991,4077.73517,0.00000,0.00236,49.53367
17.90000,0.89499,4104.91675,0.00000,0.00238,49.86385
18.00000,0.89995,4130.15895,0.00000,0.00240,50.17048
18.10000,0.90503,4156.49042,0.00000,0.00242,50.49033
18.20000,0.90988,4181.27328,0.00000,0.00243,50.79138
18.30000,0.91502,4207.88191,0.00000,0.00245,51.11460
18.40000,0.91992,4231.48572,0.00000,0.00247,51.40133
18.50000,0.92506,4257.76318,0.00000,0.00249,51.72053
18.60000,0.92991,4281.79130,0.00000,0.00250,52.01241
18.70000,0.93499,4307.05063,0.00000,0.00252,52.31924
18.80000,0.93983,4331.09179,0.00000,0.00254,52.61128
18.90000,0.94503,4357.23439,0.00000,0.00256,52.92884
19.00000,0.94988,4381.24463,0.00000,0.00257,53.22050
19.10000,0.95502,4407.40138,0.00000,0.00259,53.53824
19.20000,0.95992,4432.11794,0.00000,0.00261,53.83848
19.30000,0.96506,4456.27570,0.00000,0.00263,54.13193
19.40000,0.96996,4480.53330,0.00000,0.00264,54.42659
19.50000,0.97505,4505.19137,0.00000,0.00266,54.72612
19.60000,0.97995,4528.74973,0.00000,0.00268,55.01230
19.70000,0.98503,4552.27792,0.00000,0.00269,55.29810
19.80000,0.98993,4576.37683,0.00000,0.00271,55.59084
19.90000,0.99502,4599.27022,0.00000,0.00273,55.86893
20.00000,0.99998,4622.89862,0.00000,0.00274,56.15596
20.10000,1.00494,4644.96277,0.00000,0.00276,56.42398
20.20000,1.00996,4670.18597,0.00000,0.00277,56.73037
20.30000,1.01499,4693.20901,0.00000,0.00279,57.01004
20.40000,1.02007,4718.55216,0.00000,0.00280,57.31789
20.50000,1.02497,4741.73948,0.00000,0.00282,57.59956
20.60000,1.02999,4767.23574,0.00000,0.00284,57.90927
20.70000,1.03490,4788.45015,0.00000,0.00285,58.16697
20.80000,1.04010,4813.23265,0.00000,0.00287,58.46801
20.90000,1.04494,4834.50852,0.00000,0.00289,58.72645
21.00000,1.05008,4858.78885,0.00000,0.00290,59.02140
21.10000,1.05487,4880.20033,0.00000,0.00292,59.28149
21.20000,1.06007,4904.08652,0.00000,0.00293,59.57164
21.30000,1.06497,4925.52519,0.00000,0.00295,59.83207
21.40000,1.07011,4950.12142,0.00000,0.00297,60.13084
21.50000,1.07496,4973.52108,0.00000,0.00298,60.41509
21.60000,1.08004,4996.69313,0.00000,0.00300,60.69657
21.70000,1.08494,5018.68911,0.00000,0.00301,60.96376
21.80000,1.09002,5041.71550,0.00000,0.00303,61.24347
21.90000,1.09493,5065.23848,0.00000,0.00305,61.52921
22.00000,1.09995,5086.66001,0.00000,0.00306,61.78943
22.10000,1.10491,5108.91974,0.00000,0.00308,62.05982
22.20000,1.10999,5129.98551,0.00000,0.00310,62.31572
22.30000,1.11495,5152.28584,0.00000,0.00311,62.58661
22.40000,1.11992,5173.17094,0.00000,0.00312,62.84030
22.50000,1.12500,5196.31580,0.00000,0.00314,63.12145
22.60000,1.13002,5215.40195,0.00000,0.00316,63.35330
22.70000,1.13504,5239.41368,0.00000,0.00317,63.64498
22.80000,1.13995,5258.64772,0.00000,0.00319,63.87862
22.90000,1.14503,5281.85442,0.00000,0.00320,64.16052
23.00000,1.14987,5304.14358,0.00000,0.00322,64.43127
23.10000,1.15507,5329.16449,0.00000,0.00323,64.73521
23.20000,1.15992,5350.68549,0.00000,0.00325,64.99664
23.30000,1.16512,5374.91366,0.00000,0.00327,65.29094
23.40000,1.16990,5397.75640,0.00000,0.00328,65.56842
23.50000,1.17504,5423.65760,0.00000,0.00330,65.88305
23.60000,1.17995,5445.28216,0.00000,0.00332,66.14573
23.70000,1.18515,5468.79359,0.00000,0.00334,66.43134
23.80000,1.18993,5491.23958,0.00000,0.00335,66.70399
23.90000,1.19501,5515.57653,0.00000,0.00337,66.99962
24.00000,1.19992,5539.05591,0.00000,0.00339,67.28484
24.10000,1.20506,5563.49643,0.00000,0.00340,67.58172
24.20000,1.20996,5587.21349,0.00000,0.00342,67.86982
24.30000,1.21504,5613.30728,0.00000,0.00344,68.18679
24.40000,1.21994,5636.30313,0.00000,0.00346,68.46613
24.50000,1.22503,5659.18162,0.00000,0.00347,68.74404
24.60000,1.23005,5682.98325,0.00000,0.00349,69.03317
24.70000,1.23507,5705.64717,0.00000,0.00351,69.30848
24.80000,1.24003,5730.50454,0.00000,0.00353,69.61043
24.90000,1.24500,5751.83444,0.00000,0.00354,69.86953
25.00000,1.25002,5777.18467,0.00000,0.00356,70.17747
25.10000,1.25498,5799.84561,0.00000,0.00358,70.45274
25.20000,1.26006,5825.11239,0.00000,0.00360,70.75966
25.30000,1.26491,5847.67237,0.00000,0.00362,71.03371
25.40000,1.27005,5873.82317,0.00000,0.00364,71.35137
25.50000,1.27489,5895.34864,0.00000,0.00365,71.61285
25.60000,1.28009,5921.06245,0.00000,0.00367,71.92520
25.70000,1.28488,5944.84247,0.00000,0.00369,72.21407
25.80000,1.29008,5971.22945,0.00000,0.00371,72.53460
25.90000,1.29492,5994.35568,0.00000,0.00373,72.81552
26.00000,1.30006,6019.26707,0.00000,0.00374,73.11813
26.10000,1.30491,6042.10086,0.00000,0.00377,73.39550
26.20000,1.31005,6066.69746,0.00000,0.00378,73.69428
26.30000,1.31489,6090.53522,0.00000,0.00380,73.98385
26.40000,1.31997,6114.45606,0.00000,0.00382,74.27442
26.50000,1.32494,6138.66374,0.00000,0.00384,74.56848
26.60000,1.33002,6162.89228,0.00000,0.00386,74.86279
26.70000,1.33492,6187.81187,0.00000,0.00387,75.16550
26.80000,1.34000,6212.91995,0.00000,0.00389,75.47050
26.90000,1.34496,6238.10627,0.00000,0.00391,75.77644
27.00000,1.35005,6261.57671,0.00000,0.00393,76.06155
27.10000,1.35501,6286.25378,0.00000,0.00395,76.36131
27.20000,1.35997,6308.90578,0.00000,0.00396,76.63647
27.30000,1.36499,6334.82113,0.00000,0.00398,76.95127
27.40000,1.36996,6357.20417,0.00000,0.00400,77.22317
27.50000,1.37504,6382.65535,0.00000,0.00402,77.53233
27.60000,1.38000,6406.12245,0.00000,0.00404,77.81739
27.70000,1.38508,6433.13080,0.00000,0.00406,78.14547
27.80000,1.38993,6456.28497,0.00000,0.00407,78.42674
27.90000,1.39507,6481.52605,0.00000,0.00409,78.73335
28.00000,1.39997,6503.79732,0.00000,0.00411,79.00388
28.10000,1.40517,6530.86603,0.00000,0.00413,79.33270
28.20000,1.40996,6552.49581,0.00000,0.00414,79.59544
28.30000,1.41510,6578.29195,0.00000,0.00417,79.90880
28.40000,1.41994,6600.92384,0.00000,0.00419,80.18371
28.50000,1.42508,6626.94946,0.00000,0.00421,80.49986
28.60000,1.42993,6649.95313,0.00000,0.00422,80.77929
28.70000,1.43501,6675.76492,0.00000,0.00424,81.09284
28.80000,1.43985,6698.90270,0.00000,0.00426,81.37390
28.90000,1.44505,6723.84128,0.00000,0.00428,81.67684
29.00000,1.44995,6748.02661,0.00000,0.00430,81.97062
29.10000,1.45504,6772.91304,0.00000,0.00432,82.27293
29.20000,1.45994,6798.98337,0.00000,0.00434,82.58961
29.30000,1.46502,6822.67919,0.00000,0.00436,82.87745
29.40000,1.46998,6849.80378,0.00000,0.00438,83.20695
29.50000,1.47501,6872.66216,0.00000,0.00440,83.48461
29.60000,1.47997,6898.96643,0.00000,0.00442,83.80414
29.70000,1.48493,6921.10509,0.00000,0.00444,84.07307
29.80000,1.49001,6947.08601,0.00000,0.00446,84.38867
29.90000,1.49492,6968.96538,0.00000,0.00447,84.65444
30.00000,1.50006,6996.14733,0.00000,0.00450,84.98463
30.10000,1.50490,7018.67715,0.00000,0.00452,85.25831
30.20000,1.51004,7046.02376,0.00000,0.00454,85.59050
30.30000,1.51489,7069.00433,0.00000,0.00456,85.86965
30.40000,1.52009,7094.53225,0.00000,0.00458,86.17975
30.50000,1.52487,7118.62370,0.00000,0.00460,86.47239
30.60000,1.53001,7144.77375,0.00000,0.00462,86.79005
30.70000,1.53480,7168.31833,0.00000,0.00464,87.07605
30.80000,1.54000,7193.18688,0.00000,0.00466,87.37814
30.90000,1.54490,7218.76100,0.00000,0.00468,87.68880
31.00000,1.54992,7244.30010,0.00000,0.00470,87.99903
31.10000,1.55489,7269.16492,0.00000,0.00472,88.30107
31.20000,1.55997,7294.74425,0.00000,0.00474,88.61179
31.30000,1.56499,7320.25877,0.00000,0.00476,88.92173
31.40000,1.57007,7343.78397,0.00000,0.00479,89.20749
31.50000,1.57497,7368.21592,0.00000,0.00481,89.50428
31.60000,1.58000,7391.49451,0.00000,0.00482,89.78705
31.70000,1.58496,7416.92409,0.00000,0.00485,90.09595
31.80000,1.58998,7441.17275,0.00000,0.00486,90.39051
31.90000,1.59500,7467.47181,0.00000,0.00489,90.70997
32.00000,1.59991,7490.25345,0.00000,0.00490,90.98671
32.10000,1.60493,7516.41914,0.00000,0.00492,91.30455
32.20000,1.60995,7539.73275,0.00000,0.00495,91.58775
32.30000,1.61503,7566.87969,0.00000,0.00496,91.91752
32.40000,1.62000,7590.57105,0.00000,0.00499,92.20530
32.50000,1.62508,7616.58847,0.00000,0.00501,92.52135
32.60000,1.62992,7640.36179,0.00000,0.00503,92.81013
32.70000,1.63512,7666.77186,0.00000,0.00505,93.13094
32.80000,1.63997,7690.30601,0.00000,0.00506,93.41682
32.90000,1.64511,7716.57750,0.00000,0.00510,93.73595
33.00000,1.64989,7740.19212,0.00000,0.00511,94.02280
33.10000,1.65509,7765.89438,0.00000,0.00513,94.33502
33.20000,1.65994,7788.73414,0.00000,0.00516,94.61246
33.30000,1.66514,7815.27683,0.00000,0.00517,94.93488
33.40000,1.66998,7840.17071,0.00000,0.00520,95.23728
33.50000,1.67506,7865.40434,0.00000,0.00521,95.54380
33.60000,1.67997,7888.45196,0.00000,0.00524,95.82377
33.70000,1.68511,7913.15660,0.00000,0.00526,96.12386
33.80000,1.68989,7937.23464,0.00000,0.00527,96.41635
33.90000,1.69497,7961.65094,0.00000,0.00531,96.71294
34.00000,1.69993,7987.52978,0.00000,0.00532,97.02730
34.10000,1.70502,8010.76815,0.00000,0.00534,97.30958
34.20000,1.70998,8036.96513,0.00000,0.00537,97.62781
34.30000,1.71494,8061.47009,0.00000,0.00538,97.92548
34.40000,1.71996,8089.17135,0.00000,0.00542,98.26197
34.50000,1.72499,8112.74126,0.00000,0.00543,98.54829
34.60000,1.73007,8139.86808,0.00000,0.00545,98.87780
34.70000,1.73497,8162.48730,0.00000,0.00547,99.15257
34.80000,1.73999,8188.65597,0.00000,0.00549,99.47045
34.90000,1.74484,8211.73936,0.00000,0.00552,99.75085
35.00000,1.75004,8238.40573,0.00000,0.00553,100.07478
35.10000,1.75488,8261.30509,0.00000,0.00556,100.35294
35.20000,1.76008,8286.94999,0.00000,0.00558,100.66446
35.30000,1.76493,8311.15991,0.00000,0.00560,100.95855
35.40000,1.77001,8337.31666,0.00000,0.00563,101.27628
35.50000,1.77485,8360.89924,0.00000,0.00564,101.56275
35.60000,1.78005,8387.28622,0.00000,0.00567,101.88328
35.70000,1.78490,8411.52966,0.00000,0.00569,102.17777
35.80000,1.79004,8437.71398,0.00000,0.00571,102.49584
35.90000,1.79494,8461.70112,0.00000,0.00574,102.78722
36.00000,1.80002,8488.27660,0.00000,0.00575,103.11004
36.10000,1.80498,8513.17048,0.00000,0.00578,103.41244
36.20000,1.81001,8536.91995,0.00000,0.00579,103.70093
36.30000,1.81497,8561.89206,0.00000,0.00583,104.00428
36.40000,1.81999,8585.38449,0.00000,0.00585,104.28965
36.50000,1.82501,8612.46288,0.00000,0.00587,104.61858
36.60000,1.83004,8635.72806,0.00000,0.00590,104.90119
36.70000,1.83506,8662.36612,0.00000,0.00591,105.22477
36.80000,1.84002,8687.01041,0.00000,0.00594,105.52413
36.90000,1.84504,8714.32573,0.00000,0.00596,105.85594
37.00000,1.85001,8735.65152,0.00000,0.00598,106.11499
37.10000,1.85509,8762.08022,0.00000,0.00600,106.43603
37.20000,1.85999,8784.76277,0.00000,0.00602,106.71156
37.30000,1.86507,8810.94113,0.00000,0.00605,107.02956
37.40000,1.86992,8833.51937,0.00000,0.00607,107.30383
37.50000,1.87512,8859.56362,0.00000,0.00609,107.62020
37.60000,1.87990,8881.30665,0.00000,0.00612,107.88432
37.70000,1.88504,8908.83803,0.00000,0.00614,108.21875
37.80000,1.88995,8933.11054,0.00000,0.00617,108.51360
37.90000,1.89509,8957.54993,0.00000,0.00619,108.81047
38.00000,1.89993,8982.81708,0.00000,0.00621,109.11740
38.10000,1.90507,9006.96218,0.00000,0.00624,109.41070
38.20000,1.90992,9030.80851,0.00000,0.00626,109.70037
38.30000,1.91500,9053.49776,0.00000,0.00629,109.97598
38.40000,1.91990,9066.74862,0.00000,0.00631,110.13694
38.50000,1.92504,9091.10010,0.00000,0.00634,110.43275
38.60000,1.92994,9115.31821,0.00000,0.00637,110.72694
38.70000,1.93497,9132.45976,0.00000,0.00640,110.93516
38.80000,1.93999,9146.29772,0.00000,0.00645,111.10326
38.90000,1.94507,9145.88273,0.00000,0.00654,111.09821
38.95200,1.94776,8719.24981,0.00000,0.00706,105.91576
38.95400,1.94794,8384.38869,0.00000,0.00732,101.84808
38.95600,1.94806,7985.27971,0.00000,0.00742,96.99997
38.95800,1.94824,7547.02166,0.00000,0.00725,91.67629
38.96000,1.94842,7071.50251,0.00000,0.00680,85.90000
38.96200,1.94866,6563.85794,0.00000,0.00605,79.73346
38.96400,1.94884,6040.05270,0.00000,0.00499,73.37062
38.96600,1.94902,5514.37698,0.00000,0.00362,66.98505
38.96800,1.94920,4994.35812,0.00000,0.00199,60.66820