File: scratch/college-stuff/ME Lab/ME lab Fall 2013/group2/group2.is_tens_RawData/Specimen_RawData_3.csv
Time,Extension,Load,Strain 2,Tensile strain,Tensile stress
(sec),(mm),(N),(mm/mm),(mm/mm),(MPa)
0.00000,0.00006,-0.19492,0.00000,0.00000,-0.00243
0.40000,0.01949,38.05189,0.00000,0.00001,0.47464
0.80000,0.04006,56.09132,0.00000,0.00001,0.69966
1.20000,0.06009,73.39622,0.00000,0.00001,0.91552
1.60000,0.08012,86.52864,0.00000,0.00000,1.07933
2.00000,0.10009,105.53601,0.00000,0.00000,1.31642
2.40000,0.11994,127.11057,0.00000,0.00000,1.58553
2.80000,0.13997,152.70828,0.00000,0.00000,1.90482
3.20000,0.15994,182.42438,0.00000,-0.00001,2.27549
3.60000,0.17991,214.57002,0.00000,-0.00002,2.67646
4.00000,0.20000,263.45956,0.00000,-0.00003,3.28629
4.40000,0.22003,323.53622,0.00000,-0.00003,4.03567
4.80000,0.24005,396.80256,0.00000,-0.00005,4.94956
5.20000,0.26008,486.35551,0.00000,-0.00005,6.06661
5.60000,0.28005,598.62803,0.00000,-0.00005,7.46706
6.00000,0.30014,741.58804,0.00000,-0.00004,9.25029
6.40000,0.32005,922.57410,0.00000,-0.00003,11.50784
6.80000,0.33996,1126.40569,0.00000,-0.00001,14.05035
7.20000,0.35993,1355.95743,0.00000,0.00001,16.91370
7.60000,0.37984,1603.81701,0.00000,0.00004,20.00540
8.00000,0.39987,1876.86365,0.00000,0.00007,23.41128
8.40000,0.41990,2159.83111,0.00000,0.00009,26.94091
8.80000,0.43993,2457.12232,0.00000,0.00013,30.64921
9.20000,0.45996,2760.16016,0.00000,0.00017,34.42918
9.60000,0.47999,3061.20515,0.00000,0.00023,38.18430
10.00000,0.50002,3363.54412,0.00000,0.00027,41.95557
10.40000,0.52005,3664.70106,0.00000,0.00033,45.71208
10.80000,0.54002,3960.43994,0.00000,0.00038,49.40102
11.20000,0.55999,4251.30799,0.00000,0.00043,53.02919
11.60000,0.58002,4540.14987,0.00000,0.00047,56.63210
12.00000,0.59987,4821.72146,0.00000,0.00052,60.14431
12.40000,0.61984,5100.28489,0.00000,0.00057,63.61901
12.80000,0.63987,5368.11687,0.00000,0.00062,66.95984
13.20000,0.65984,5610.13445,0.00000,0.00066,69.97868
13.60000,0.67993,5831.69051,0.00000,0.00069,72.74228
14.00000,0.70002,6043.01132,0.00000,0.00073,75.37822
14.40000,0.71999,6255.03212,0.00000,0.00077,78.02288
14.80000,0.74007,6466.64649,0.00000,0.00080,80.66248
15.20000,0.76004,6676.59044,0.00000,0.00084,83.28124
15.60000,0.78001,6884.86844,0.00000,0.00087,85.87922
16.00000,0.79998,7090.67583,0.00000,0.00090,88.44638
16.40000,0.82001,7292.66927,0.00000,0.00094,90.96597
16.80000,0.83992,7482.56594,0.00000,0.00097,93.33467
17.20000,0.85989,7664.32732,0.00000,0.00100,95.60189
17.60000,0.87986,7848.22181,0.00000,0.00103,97.89572
18.00000,0.89989,8032.95150,0.00000,0.00107,100.19997
18.40000,0.91998,8219.61239,0.00000,0.00110,102.52831
18.80000,0.93995,8407.08464,0.00000,0.00113,104.86676
19.20000,0.95998,8595.49791,0.00000,0.00116,107.21696
19.60000,0.98007,8786.20371,0.00000,0.00119,109.59575
20.00000,1.00004,8975.77703,0.00000,0.00122,111.96042
20.40000,1.02001,9164.93759,0.00000,0.00126,114.31993
20.80000,1.03998,9356.90403,0.00000,0.00129,116.71445
21.20000,1.06001,9551.07138,0.00000,0.00133,119.13642
21.60000,1.07998,9742.76662,0.00000,0.00136,121.52755
22.00000,1.09989,9937.09564,0.00000,0.00139,123.95154
22.40000,1.11992,10133.03772,0.00000,0.00143,126.39564
22.80000,1.13989,10328.79278,0.00000,0.00147,128.83742
23.20000,1.15992,10525.03660,0.00000,0.00150,131.28529
23.60000,1.18001,10721.45179,0.00000,0.00154,133.73530
24.00000,1.20003,10920.55291,0.00000,0.00157,136.21881
24.40000,1.22006,11120.79099,0.00000,0.00161,138.71650
24.80000,1.24003,11321.79573,0.00000,0.00165,141.22376
25.20000,1.26000,11521.14496,0.00000,0.00168,143.71036
25.60000,1.27997,11720.61935,0.00000,0.00172,146.19853
26.00000,1.30000,11920.82465,0.00000,0.00176,148.69582
26.40000,1.31997,12125.39673,0.00000,0.00179,151.24757
26.80000,1.34000,12329.99861,0.00000,0.00183,153.79970
27.20000,1.35991,12530.59655,0.00000,0.00187,156.30188
27.60000,1.37988,12734.38632,0.00000,0.00190,158.84387
28.00000,1.39991,12939.98659,0.00000,0.00194,161.40845
28.40000,1.41994,13147.06653,0.00000,0.00198,163.99149
28.80000,1.44003,13353.38205,0.00000,0.00202,166.56499
29.20000,1.46006,13559.20434,0.00000,0.00206,169.13234
29.60000,1.48003,13766.30813,0.00000,0.00209,171.71567
30.00000,1.50000,13973.52964,0.00000,0.00213,174.30047
30.40000,1.51997,14179.30871,0.00000,0.00217,176.86728
30.80000,1.54000,14386.26647,0.00000,0.00221,179.44880
31.20000,1.55997,14593.79196,0.00000,0.00225,182.03739
31.60000,1.57994,14802.49465,0.00000,0.00229,184.64067
32.00000,1.59985,15011.20180,0.00000,0.00233,187.24400
32.40000,1.61994,15221.27837,0.00000,0.00237,189.86442
32.80000,1.63991,15429.83353,0.00000,0.00241,192.46585
33.20000,1.66000,15639.72682,0.00000,0.00246,195.08398
33.60000,1.68008,15853.12784,0.00000,0.00250,197.74587
34.00000,1.70005,16062.33120,0.00000,0.00254,200.35539
34.40000,1.72002,16274.55354,0.00000,0.00259,203.00257
34.80000,1.73999,16484.36338,0.00000,0.00263,205.61966
35.20000,1.75996,16695.00470,0.00000,0.00267,208.24712
35.60000,1.78005,16905.12300,0.00000,0.00271,210.86805
36.00000,1.80002,17114.52901,0.00000,0.00276,213.48010
36.40000,1.81993,17325.78427,0.00000,0.00280,216.11522
36.80000,1.83990,17538.14965,0.00000,0.00285,218.76418
37.20000,1.85987,17750.87714,0.00000,0.00289,221.41767
37.60000,1.87990,17963.22018,0.00000,0.00294,224.06635
38.00000,1.89993,18173.73633,0.00000,0.00298,226.69225
38.40000,1.92002,18387.04050,0.00000,0.00302,229.35292
38.80000,1.94005,18599.11084,0.00000,0.00307,231.99821
39.20000,1.96002,18810.11128,0.00000,0.00312,234.63015
39.60000,1.97993,19016.76506,0.00000,0.00317,237.20787
40.00000,1.99996,19224.30992,0.00000,0.00321,239.79670
40.40000,2.01999,19430.64332,0.00000,0.00326,242.37043
40.80000,2.03996,19638.50409,0.00000,0.00331,244.96320
41.20000,2.05999,19842.66341,0.00000,0.00336,247.50981
41.60000,2.07990,20044.96008,0.00000,0.00342,250.03318
42.00000,2.09987,20248.17318,0.00000,0.00347,252.56798
42.40000,2.11990,20449.07212,0.00000,0.00353,255.07392
42.80000,2.13993,20644.47254,0.00000,0.00359,257.51127
43.20000,2.16007,20839.30373,0.00000,0.00365,259.94152
43.60000,2.18010,21027.63355,0.00000,0.00371,262.29067
44.00000,2.20001,21212.20678,0.00000,0.00378,264.59297
44.40000,2.21998,21390.61540,0.00000,0.00385,266.81837
44.80000,2.24001,21563.71921,0.00000,0.00392,268.97760
45.20000,2.25998,21729.93869,0.00000,0.00399,271.05096
45.60000,2.27995,21891.27803,0.00000,0.00407,273.06345
46.00000,2.29992,22043.90913,0.00000,0.00416,274.96731
46.40000,2.31995,22189.58139,0.00000,0.00425,276.78437
46.80000,2.33992,22321.65039,0.00000,0.00435,278.43175
47.20000,2.35989,22445.20485,0.00000,0.00446,279.97292
47.60000,2.37992,22556.09185,0.00000,0.00458,281.35608
48.00000,2.40007,22656.08609,0.00000,0.00471,282.60337
48.40000,2.42010,22746.31113,0.00000,0.00484,283.72880
48.80000,2.44013,22826.31844,0.00000,0.00498,284.72678
49.20000,2.46004,22898.86326,0.00000,0.00513,285.63168
49.60000,2.48001,22963.87404,0.00000,0.00529,286.44260
50.00000,2.49998,23020.98721,0.00000,0.00545,287.15501
50.40000,2.51995,23072.41559,0.00000,0.00562,287.79651
50.80000,2.53992,23121.64903,0.00000,0.00580,288.41062
51.20000,2.55995,23167.34195,0.00000,0.00598,288.98058
51.60000,2.57992,23208.60773,0.00000,0.00617,289.49531
52.00000,2.59995,23241.32770,0.00000,0.00636,289.90345
52.40000,2.62004,23277.36467,0.00000,0.00655,290.35296
52.80000,2.64012,23307.55740,0.00000,0.00674,290.72957
53.20000,2.66015,23336.83074,0.00000,0.00694,291.09472
53.60000,2.68012,23363.25645,0.00000,0.00714,291.42434
54.00000,2.70003,23387.39187,0.00000,0.00734,291.72540
54.40000,2.72006,23408.94192,0.00000,0.00755,291.99421
54.80000,2.73991,23426.21088,0.00000,0.00776,292.20961
55.20000,2.75994,23445.81187,0.00000,0.00798,292.45411
55.60000,2.77997,23466.53938,0.00000,0.00818,292.71266
56.00000,2.79994,23484.02292,0.00000,0.00840,292.93074
56.40000,2.81991,23501.81490,0.00000,0.00861,293.15267
56.80000,2.84000,23518.17489,0.00000,0.00883,293.35674
57.20000,2.85997,23532.42636,0.00000,0.00905,293.53450
57.60000,2.88012,23547.54657,0.00000,0.00927,293.72311
58.00000,2.90009,23562.72936,0.00000,0.00949,293.91249
58.40000,2.92012,23578.79281,0.00000,0.00971,294.11286
58.80000,2.94009,23590.11918,0.00000,0.00994,294.25414
59.20000,2.96000,23600.58725,0.00000,0.01015,294.38472
59.60000,2.97997,23612.83749,0.00000,0.01038,294.53752
60.00000,2.99988,23622.98220,0.00000,0.01060,294.66406
60.40000,3.01997,23636.91181,0.00000,0.01083,294.83782
60.80000,3.04000,23648.61071,0.00000,0.01106,294.98374
61.20000,3.06003,23661.50022,0.00000,0.01128,295.14452
61.60000,3.08000,23672.26332,0.00000,0.01150,295.27878
62.00000,3.10003,23684.04120,0.00000,0.01173,295.42569
62.40000,3.12005,23692.71815,0.00000,0.01196,295.53392
62.80000,3.14014,23704.33211,0.00000,0.01219,295.67879
63.20000,3.16011,23714.77932,0.00000,0.01241,295.80911
63.60000,3.18002,23725.07155,0.00000,0.01264,295.93749
64.00000,3.20005,23735.11046,0.00000,0.01287,296.06271
64.40000,3.21996,23740.75800,0.00000,0.01310,296.13315
64.80000,3.23987,23750.91612,0.00000,0.01332,296.25986
65.20000,3.25990,23761.11597,0.00000,0.01355,296.38709
65.60000,3.27999,23775.20353,0.00000,0.01378,296.56281
66.00000,3.29996,23782.69583,0.00000,0.01401,296.65627
66.40000,3.32005,23794.32917,0.00000,0.01423,296.80138
66.80000,3.33996,23802.46073,0.00000,0.01445,296.90281
67.20000,3.36005,23813.05844,0.00000,0.01468,297.03500
67.60000,3.38014,23822.06917,0.00000,0.01490,297.14740
68.00000,3.40011,23831.64316,0.00000,0.01513,297.26682
68.40000,3.42008,23839.21295,0.00000,0.01535,297.36124
68.80000,3.43999,23849.13564,0.00000,0.01557,297.48501
69.20000,3.45990,23857.33724,0.00000,0.01580,297.58732
69.60000,3.47993,23864.10385,0.00000,0.01602,297.67172
70.00000,3.49996,23873.87007,0.00000,0.01624,297.79354
70.40000,3.51993,23883.88067,0.00000,0.01646,297.91841
70.80000,3.54002,23894.88369,0.00000,0.01668,298.05566
71.20000,3.55999,23904.64842,0.00000,0.01691,298.17746
71.60000,3.58007,23914.22987,0.00000,0.01713,298.29698
72.00000,3.59999,23921.49866,0.00000,0.01735,298.38764
72.40000,3.62007,23931.64486,0.00000,0.01757,298.51420
72.80000,3.64010,23942.03097,0.00000,0.01779,298.64376
73.20000,3.66007,23948.27455,0.00000,0.01801,298.72164
73.60000,3.67992,23955.52993,0.00000,0.01823,298.81214
74.00000,3.69995,23964.29330,0.00000,0.01845,298.92145
74.40000,3.71986,23971.73792,0.00000,0.01866,299.01431
74.80000,3.73995,23979.47907,0.00000,0.01888,299.11087
75.20000,3.76004,23989.75194,0.00000,0.01910,299.23901
75.60000,3.78001,23999.66270,0.00000,0.01932,299.36263
76.00000,3.79998,24009.78506,0.00000,0.01953,299.48889
76.40000,3.82001,24019.03123,0.00000,0.01975,299.60423
76.80000,3.84004,24026.01391,0.00000,0.01997,299.69133
77.20000,3.86007,24034.80858,0.00000,0.02019,299.80103
77.60000,3.88010,24043.26797,0.00000,0.02040,299.90655
78.00000,3.90001,24051.08064,0.00000,0.02062,300.00400
78.40000,3.92004,24057.91134,0.00000,0.02083,300.08920
78.80000,3.93995,24064.25476,0.00000,0.02104,300.16833
79.20000,3.95986,24070.01108,0.00000,0.02125,300.24013
79.60000,3.97995,24081.13927,0.00000,0.02146,300.37894
80.00000,3.99998,24090.71475,0.00000,0.02168,300.49838
80.40000,4.02007,24100.38859,0.00000,0.02189,300.61905
80.80000,4.03998,24108.24448,0.00000,0.02210,300.71704
81.20000,4.06001,24119.27432,0.00000,0.02232,300.85462
81.60000,4.08003,24126.61016,0.00000,0.02252,300.94613
82.00000,4.10000,24132.45738,0.00000,0.02273,301.01906
82.40000,4.12003,24139.88411,0.00000,0.02294,301.11170
82.80000,4.14006,24149.15711,0.00000,0.02316,301.22737
83.20000,4.15997,24156.49444,0.00000,0.02337,301.31889
83.60000,4.17994,24164.80035,0.00000,0.02358,301.42250
84.00000,4.19991,24171.43285,0.00000,0.02377,301.50523
84.40000,4.21994,24179.68214,0.00000,0.02398,301.60813
84.80000,4.23997,24190.29176,0.00000,0.02419,301.74047
85.20000,4.26000,24199.43213,0.00000,0.02440,301.85448
85.60000,4.28003,24206.78884,0.00000,0.02462,301.94624
86.00000,4.30006,24217.15558,0.00000,0.02482,302.07555
86.40000,4.32003,24223.59735,0.00000,0.02503,302.15591
86.80000,4.34000,24231.03452,0.00000,0.02523,302.24868
87.20000,4.36009,24235.97276,0.00000,0.02544,302.31027
87.60000,4.38012,24244.25334,0.00000,0.02564,302.41356
88.00000,4.39997,24250.09757,0.00000,0.02585,302.48646
88.40000,4.41994,24259.50468,0.00000,0.02605,302.60380
88.80000,4.43985,24266.81221,0.00000,0.02626,302.69495
89.20000,4.45994,24272.61323,0.00000,0.02647,302.76731
89.60000,4.47997,24281.71784,0.00000,0.02667,302.88088
90.00000,4.50000,24290.58701,0.00000,0.02687,302.99151
90.40000,4.52009,24300.60655,0.00000,0.02707,303.11649
90.80000,4.54006,24306.62662,0.00000,0.02728,303.19158
91.20000,4.55996,24311.24002,0.00000,0.02748,303.24913
91.60000,4.57999,24318.28976,0.00000,0.02769,303.33706
92.00000,4.60002,24326.85047,0.00000,0.02789,303.44385
92.40000,4.62011,24333.98962,0.00000,0.02809,303.53290
92.80000,4.64002,24340.16913,0.00000,0.02828,303.60998
93.20000,4.65999,24346.36503,0.00000,0.02849,303.68726
93.60000,4.67990,24354.82591,0.00000,0.02869,303.79280
94.00000,4.69987,24361.08887,0.00000,0.02889,303.87092
94.40000,4.71996,24370.20987,0.00000,0.02909,303.98470
94.80000,4.73999,24378.01957,0.00000,0.02929,304.08211
95.20000,4.76002,24387.25829,0.00000,0.02949,304.19735
95.60000,4.77999,24394.20670,0.00000,0.02969,304.28402
96.00000,4.80002,24401.47698,0.00000,0.02988,304.37471
96.40000,4.81999,24404.59281,0.00000,0.03008,304.41358
96.80000,4.84008,24413.40536,0.00000,0.03028,304.52350
97.20000,4.86011,24420.49384,0.00000,0.03048,304.61192
97.60000,4.88008,24426.99075,0.00000,0.03067,304.69296
98.00000,4.89999,24433.74395,0.00000,0.03087,304.77720
98.40000,4.91990,24439.63736,0.00000,0.03106,304.85071
98.80000,4.93987,24445.71406,0.00000,0.03126,304.92651
99.20000,4.95990,24453.55505,0.00000,0.03147,305.02431
99.60000,4.97999,24461.59869,0.00000,0.03166,305.12465
100.00000,5.00008,24469.37561,0.00000,0.03185,305.22165
100.40000,5.02011,24475.35396,0.00000,0.03204,305.29622
100.80000,5.04002,24481.41128,0.00000,0.03223,305.37178
101.20000,5.05998,24486.47320,0.00000,0.03243,305.43492
101.60000,5.08001,24492.74510,0.00000,0.03262,305.51315
102.00000,5.10010,24499.78739,0.00000,0.03282,305.60100
102.40000,5.12007,24507.15899,0.00000,0.03301,305.69295
102.80000,5.13992,24511.76196,0.00000,0.03320,305.75036
103.20000,5.15983,24519.25278,0.00000,0.03339,305.84380
103.60000,5.17992,24525.49189,0.00000,0.03359,305.92162
104.00000,5.19989,24530.68495,0.00000,0.03378,305.98640
104.40000,5.21998,24537.38004,0.00000,0.03397,306.06991
104.80000,5.24007,24544.79039,0.00000,0.03416,306.16235
105.20000,5.26004,24550.83132,0.00000,0.03435,306.23770
105.60001,5.28007,24556.39988,0.00000,0.03454,306.30716
106.00001,5.29998,24563.30508,0.00000,0.03473,306.39329
106.40001,5.32001,24568.84235,0.00000,0.03492,306.46236
106.80001,5.34010,24575.25432,0.00000,0.03510,306.54234
107.20001,5.36001,24580.14339,0.00000,0.03529,306.60333
107.60001,5.37992,24584.03856,0.00000,0.03548,306.65191
108.00001,5.39989,24590.84243,0.00000,0.03568,306.73678
108.40001,5.41986,24595.98631,0.00000,0.03587,306.80094
108.80001,5.43989,24602.59795,0.00000,0.03605,306.88342
109.20001,5.46004,24610.56113,0.00000,0.03623,306.98275
109.60001,5.48013,24616.18036,0.00000,0.03641,307.05284
110.00001,5.50009,24622.76369,0.00000,0.03660,307.13496
110.40001,5.52006,24628.29500,0.00000,0.03679,307.20395
110.80001,5.54003,24634.55349,0.00000,0.03698,307.28202
111.20001,5.56006,24637.14629,0.00000,0.03716,307.31436
111.60001,5.57997,24642.23355,0.00000,0.03734,307.37782
112.00001,5.60000,24649.46955,0.00000,0.03753,307.46807
112.40001,5.61997,24653.98163,0.00000,0.03771,307.52436
112.80001,5.63988,24656.66533,0.00000,0.03789,307.55783
113.20001,5.65985,24661.55738,0.00000,0.03807,307.61885
113.60001,5.67988,24669.28661,0.00000,0.03825,307.71526
114.00001,5.70003,24676.12475,0.00000,0.03844,307.80056
114.40001,5.72018,24682.79749,0.00000,0.03862,307.88379
114.80001,5.74009,24686.95939,0.00000,0.03880,307.93571
115.20001,5.76006,24693.22681,0.00000,0.03898,308.01389
115.60001,5.78003,24697.36189,0.00000,0.03916,308.06547
116.00001,5.80006,24699.85485,0.00000,0.03933,308.09656
116.40001,5.82003,24704.11360,0.00000,0.03950,308.14968
116.80001,5.84000,24709.88780,0.00000,0.03968,308.22171
117.20001,5.85991,24715.42954,0.00000,0.03987,308.29083
117.60001,5.87988,24721.17692,0.00000,0.04005,308.36252
118.00001,5.89991,24726.21202,0.00000,0.04022,308.42533
118.40001,5.91994,24730.76433,0.00000,0.04039,308.48211
118.80001,5.94009,24739.00467,0.00000,0.04056,308.58490
119.20001,5.96012,24743.90864,0.00000,0.04074,308.64607
119.60001,5.98015,24748.58612,0.00000,0.04091,308.70442
120.00001,6.00011,24753.37833,0.00000,0.04109,308.76419
120.40001,6.02002,24757.52383,0.00000,0.04127,308.81590
120.80001,6.03993,24760.77676,0.00000,0.04143,308.85648
121.20001,6.05996,24765.16664,0.00000,0.04161,308.91124
121.60001,6.07999,24767.13210,0.00000,0.04179,308.93575
122.00001,6.09996,24774.99545,0.00000,0.04196,309.03384
122.40001,6.11987,24780.98869,0.00000,0.04213,309.10859
122.80001,6.13990,24787.31275,0.00000,0.04230,309.18748
123.20001,6.15993,24791.25410,0.00000,0.04247,309.23664
123.60001,6.18002,24795.19993,0.00000,0.04265,309.28586
124.00001,6.20011,24803.31212,0.00000,0.04282,309.38705
124.40001,6.22014,24807.78992,0.00000,0.04300,309.44290
124.80001,6.24011,24811.28871,0.00000,0.04317,309.48654
125.20001,6.26002,24812.28709,0.00000,0.04334,309.49900
125.60001,6.27999,24815.08404,0.00000,0.04350,309.53389
126.00001,6.29996,24819.37706,0.00000,0.04367,309.58744
126.40001,6.31999,24824.55373,0.00000,0.04385,309.65201
126.80001,6.33990,24828.00633,0.00000,0.04402,309.69507
127.20001,6.35993,24833.30816,0.00000,0.04419,309.76121
127.60001,6.37996,24839.67096,0.00000,0.04436,309.84057
128.00001,6.39993,24844.00421,0.00000,0.04453,309.89463
128.40001,6.42002,24848.13482,0.00000,0.04469,309.94615
128.80001,6.44011,24853.67060,0.00000,0.04486,310.01520
129.20001,6.46014,24858.65206,0.00000,0.04503,310.07734
129.60001,6.48004,24863.00766,0.00000,0.04520,310.13167
130.00001,6.50001,24865.29648,0.00000,0.04537,310.16022
130.40001,6.51992,24866.76872,0.00000,0.04554,310.17858
130.80001,6.53989,24869.94714,0.00000,0.04571,310.21823
131.20001,6.55992,24876.14602,0.00000,0.04588,310.29555
131.60001,6.57995,24880.77581,0.00000,0.04605,310.35330
132.00001,6.59998,24886.88678,0.00000,0.04622,310.42953
132.40001,6.61995,24890.48094,0.00000,0.04638,310.47436
132.80001,6.63986,24894.01400,0.00000,0.04655,310.51843
133.20001,6.65995,24898.81366,0.00000,0.04672,310.57830
133.60001,6.68004,24902.99195,0.00000,0.04690,310.63042
134.00001,6.70013,24907.01675,0.00000,0.04707,310.68062
134.40001,6.72010,24912.99957,0.00000,0.04723,310.75525
134.80001,6.74001,24913.54048,0.00000,0.04740,310.76199
135.20001,6.75992,24916.23610,0.00000,0.04757,310.79562
135.60001,6.77989,24916.84854,0.00000,0.04774,310.80326
136.00001,6.79998,24922.35303,0.00000,0.04790,310.87192
136.40001,6.82001,24928.33436,0.00000,0.04808,310.94653
136.80001,6.83998,24932.91348,0.00000,0.04825,311.00365
137.20001,6.85995,24935.41688,0.00000,0.04841,311.03487
137.60001,6.87998,24939.45807,0.00000,0.04857,311.08528
138.00001,6.89995,24943.66318,0.00000,0.04874,311.13773
138.40001,6.92004,24947.95769,0.00000,0.04891,311.19130
138.80001,6.94013,24951.93332,0.00000,0.04908,311.24089
139.20001,6.96003,24955.68991,0.00000,0.04925,311.28775
139.60001,6.98000,24958.02045,0.00000,0.04942,311.31682
140.00001,6.99997,24960.04552,0.00000,0.04959,311.34208
140.40001,7.01994,24964.06883,0.00000,0.04975,311.39227
140.80001,7.03997,24967.48716,0.00000,0.04992,311.43490
141.20001,7.06000,24970.61938,0.00000,0.05009,311.47397
141.60001,7.07997,24975.08228,0.00000,0.05026,311.52964
142.00001,7.09994,24980.66425,0.00000,0.05043,311.59927
142.40001,7.11991,24984.90959,0.00000,0.05059,311.65223
142.80001,7.14000,24987.41895,0.00000,0.05076,311.68353
143.20001,7.16009,24989.46488,0.00000,0.05093,311.70905
143.60001,7.18012,24994.58343,0.00000,0.05109,311.77289
144.00001,7.20003,24997.71118,0.00000,0.05126,311.81191
144.40001,7.22000,25001.11759,0.00000,0.05143,311.85440
144.80001,7.23991,25003.69847,0.00000,0.05159,311.88659
145.20001,7.26000,25006.77705,0.00000,0.05175,311.92499
145.60001,7.27997,25009.63509,0.00000,0.05191,311.96064
146.00001,7.30000,25014.28723,0.00000,0.05209,312.01867
146.40001,7.32003,25018.68904,0.00000,0.05226,312.07358
146.80001,7.33994,25021.70503,0.00000,0.05243,312.11120
147.20001,7.35997,25024.23823,0.00000,0.05260,312.14280
147.60001,7.38000,25026.83997,0.00000,0.05276,312.17525
148.00001,7.40003,25030.04074,0.00000,0.05292,312.21517
148.40001,7.42018,25034.45148,0.00000,0.05309,312.27019
148.80001,7.44008,25036.61513,0.00000,0.05326,312.29718
149.20001,7.46005,25040.43877,0.00000,0.05342,312.34488
149.60001,7.48008,25043.07926,0.00000,0.05358,312.37781
150.00001,7.49999,25042.24479,0.00000,0.05375,312.36740
150.40001,7.51996,25043.93458,0.00000,0.05391,312.38848
150.80001,7.53999,25049.05760,0.00000,0.05408,312.45238
151.20001,7.55996,25054.46076,0.00000,0.05424,312.51978
151.60001,7.57993,25056.97608,0.00000,0.05441,312.55116
152.00001,7.59996,25059.11887,0.00000,0.05457,312.57788
152.40001,7.61999,25062.08420,0.00000,0.05473,312.61487
152.80001,7.64002,25065.29689,0.00000,0.05489,312.65495
153.20001,7.66011,25068.52150,0.00000,0.05506,312.69517
153.60001,7.68008,25070.91463,0.00000,0.05523,312.72502
154.00001,7.70011,25074.49985,0.00000,0.05539,312.76974
154.40001,7.72002,25077.01218,0.00000,0.05555,312.80108
154.80001,7.73993,25076.91979,0.00000,0.05571,312.79993
155.20001,7.75996,25078.97317,0.00000,0.05587,312.82554
155.60001,7.77993,25080.35600,0.00000,0.05603,312.84279
156.00001,7.79996,25086.13467,0.00000,0.05620,312.91487
156.40001,7.81993,25089.34736,0.00000,0.05636,312.95494
156.80001,7.83996,25094.39886,0.00000,0.05653,313.01795
157.20001,7.86005,25096.94397,0.00000,0.05669,313.04970
157.60001,7.88002,25097.34631,0.00000,0.05685,313.05472
158.00001,7.90005,25100.13878,0.00000,0.05701,313.08955
158.40001,7.92013,25104.03097,0.00000,0.05718,313.13810
158.80001,7.94004,25105.46446,0.00000,0.05734,313.15598
159.20001,7.96001,25107.34797,0.00000,0.05750,313.17947
159.60001,7.97992,25108.28376,0.00000,0.05766,313.19115
160.00001,7.99989,25109.77089,0.00000,0.05782,313.20970
160.40001,8.01992,25112.52463,0.00000,0.05799,313.24405
160.80001,8.03995,25115.48400,0.00000,0.05815,313.28096
161.20001,8.05998,25119.85004,0.00000,0.05831,313.33542
161.60001,8.08001,25123.29519,0.00000,0.05847,313.37839
162.00001,8.10004,25127.44069,0.00000,0.05863,313.43010
162.40001,8.12001,25125.87905,0.00000,0.05879,313.41062
162.80001,8.14016,25130.61762,0.00000,0.05896,313.46973
163.20001,8.16007,25133.76176,0.00000,0.05911,313.50895
163.60001,8.18004,25135.22208,0.00000,0.05928,313.52717
164.00001,8.20001,25136.08038,0.00000,0.05945,313.53787
164.40001,8.21986,25134.70054,0.00000,0.05961,313.52066
164.80001,8.23989,25138.06820,0.00000,0.05977,313.56267
165.20001,8.25992,25140.19907,0.00000,0.05993,313.58925
165.60001,8.27995,25145.91217,0.00000,0.06009,313.66051
166.00001,8.29998,25149.63746,0.00000,0.06025,313.70698
166.40001,8.32007,25152.49848,0.00000,0.06041,313.74267
166.80001,8.34004,25153.28825,0.00000,0.06058,313.75252
167.20001,8.36001,25155.29692,0.00000,0.06074,313.77757
167.60001,8.38009,25158.05960,0.00000,0.06090,313.81203
168.00001,8.40012,25159.95204,0.00000,0.06106,313.83564
168.40001,8.42009,25161.56435,0.00000,0.06122,313.85575
168.80001,8.44000,25162.83989,0.00000,0.06139,313.87166
169.20001,8.45991,25163.39123,0.00000,0.06155,313.87854
169.60001,8.47982,25163.67733,0.00000,0.06171,313.88211
170.00001,8.49985,25166.73207,0.00000,0.06188,313.92021
170.40001,8.52000,25172.62995,0.00000,0.06204,313.99378
170.80001,8.54009,25177.10030,0.00000,0.06220,314.04954
171.20001,8.56006,25178.26557,0.00000,0.06237,314.06407
171.60001,8.58009,25179.69608,0.00000,0.06253,314.08192
172.00001,8.60006,25179.39806,0.00000,0.06270,314.07820
172.40001,8.62009,25182.78956,0.00000,0.06286,314.12050
172.80001,8.64012,25184.86083,0.00000,0.06302,314.14634
173.20001,8.66009,25185.26912,0.00000,0.06318,314.15143
173.60001,8.68000,25185.37939,0.00000,0.06335,314.15281
174.00001,8.69991,25186.55658,0.00000,0.06351,314.16749
174.40001,8.71982,25188.86626,0.00000,0.06368,314.19630
174.80001,8.73991,25190.67228,0.00000,0.06383,314.21883
175.20001,8.76006,25194.74924,0.00000,0.06399,314.26969
175.60001,8.78003,25196.68341,0.00000,0.06416,314.29381
176.00001,8.80006,25199.71430,0.00000,0.06432,314.33162
176.40001,8.82003,25201.01964,0.00000,0.06448,314.34790
176.80001,8.84006,25201.97034,0.00000,0.06465,314.35976
177.20001,8.86009,25202.51274,0.00000,0.06482,314.36652
177.60001,8.88005,25202.55148,0.00000,0.06498,314.36701
178.00001,8.90008,25205.51085,0.00000,0.06514,314.40392
178.40001,8.91993,25205.08766,0.00000,0.06530,314.39864
178.80001,8.93990,25207.29005,0.00000,0.06547,314.42611
179.20001,8.95987,25209.34641,0.00000,0.06566,314.45176
179.60001,8.97990,25213.33992,0.00000,0.06583,314.50158
180.00001,8.99999,25216.46917,0.00000,0.06600,314.54061
180.40001,9.02008,25218.21856,0.00000,0.06617,314.56243
180.80001,9.04005,25219.16926,0.00000,0.06634,314.57429
181.20001,9.06008,25221.39847,0.00000,0.06651,314.60210
181.60001,9.07999,25222.18823,0.00000,0.06668,314.61195
182.00001,9.10002,25222.40877,0.00000,0.06684,314.61470
182.40001,9.12011,25224.35784,0.00000,0.06701,314.63901
182.80001,9.14008,25224.50984,0.00000,0.06717,314.64091
183.20001,9.15993,25225.48437,0.00000,0.06734,314.65306
183.60001,9.17990,25228.04737,0.00000,0.06751,314.68503
184.00001,9.19987,25229.72822,0.00000,0.06768,314.70600
184.40001,9.21984,25229.03085,0.00000,0.06785,314.69730
184.80001,9.23999,25233.02734,0.00000,0.06802,314.74715
185.20001,9.26008,25236.97913,0.00000,0.06818,314.79644
185.60001,9.28011,25237.08045,0.00000,0.06834,314.79771
186.00001,9.30008,25238.46924,0.00000,0.06851,314.81503
186.40001,9.32005,25238.12056,0.00000,0.06868,314.81068
186.80001,9.34002,25238.64210,0.00000,0.06885,314.81719
187.20001,9.35998,25239.42888,0.00000,0.06902,314.82700
187.60001,9.38007,25241.00244,0.00000,0.06919,314.84663
188.00001,9.39998,25241.69385,0.00000,0.06936,314.85525
188.40001,9.41989,25244.03930,0.00000,0.06953,314.88451
188.80001,9.43986,25245.42511,0.00000,0.06969,314.90180
189.20001,9.45989,25244.76349,0.00000,0.06986,314.89354
189.60001,9.47992,25245.60988,0.00000,0.07003,314.90410
190.00001,9.50007,25249.75538,0.00000,0.07020,314.95581
190.40001,9.52004,25251.72532,0.00000,0.07037,314.98038
190.80001,9.54007,25252.86078,0.00000,0.07054,314.99455
191.20001,9.56004,25252.44951,0.00000,0.07071,314.98942
191.60001,9.58001,25253.27504,0.00000,0.07088,314.99971
192.00001,9.59998,25253.51942,0.00000,0.07105,315.00276
192.40001,9.62007,25255.43272,0.00000,0.07121,315.02663
192.80001,9.63998,25255.64134,0.00000,0.07138,315.02923
193.20001,9.65995,25255.86486,0.00000,0.07155,315.03202
193.60001,9.67998,25258.50534,0.00000,0.07172,315.06495
194.00001,9.69983,25257.42948,0.00000,0.07190,315.05153
194.40001,9.71998,25260.48720,0.00000,0.07207,315.08968
194.80001,9.74001,25259.89413,0.00000,0.07223,315.08228
195.20001,9.76010,25263.15153,0.00000,0.07240,315.12291
195.60001,9.78007,25263.49723,0.00000,0.07257,315.12722
196.00001,9.80004,25264.58502,0.00000,0.07274,315.14079
196.40001,9.81995,25263.59558,0.00000,0.07291,315.12845
196.80001,9.84003,25263.20517,0.00000,0.07308,315.12358
197.20001,9.86006,25265.52975,0.00000,0.07325,315.15257
197.60001,9.88003,25266.20924,0.00000,0.07341,315.16105
198.00001,9.90000,25265.84268,0.00000,0.07358,315.15648
198.40001,9.91991,25264.64164,0.00000,0.07375,315.14150
198.80001,9.93994,25267.04669,0.00000,0.07392,315.17150
199.20001,9.95991,25269.21630,0.00000,0.07408,315.19856
199.60001,9.98006,25271.90149,0.00000,0.07425,315.23205
200.00001,10.00009,25272.58992,0.00000,0.07442,315.24064
200.40001,10.02012,25273.33498,0.00000,0.07458,315.24993
200.80001,10.03997,25272.48561,0.00000,0.07475,315.23934
201.20001,10.06000,25273.75221,0.00000,0.07492,315.25514
201.60001,10.07991,25271.99090,0.00000,0.07509,315.23317
202.00001,10.10006,25273.89824,0.00000,0.07525,315.25696
202.40001,10.12003,25274.21415,0.00000,0.07542,315.26090
202.80001,10.13994,25275.41518,0.00000,0.07559,315.27588
203.20001,10.15997,25276.36588,0.00000,0.07576,315.28774
203.60001,10.17988,25274.86086,0.00000,0.07592,315.26897
204.00001,10.19997,25276.06189,0.00000,0.07610,315.28395
204.40001,10.22006,25279.53088,0.00000,0.07626,315.32722
204.80001,10.24009,25282.46939,0.00000,0.07643,315.36387
205.20001,10.26006,25281.37565,0.00000,0.07659,315.35023
205.60001,10.28009,25282.83000,0.00000,0.07676,315.36837
206.00001,10.30000,25282.71675,0.00000,0.07693,315.36696
206.40001,10.31996,25281.96871,0.00000,0.07710,315.35763
206.80001,10.34005,25279.82295,0.00000,0.07727,315.33086
207.20001,10.36002,25279.76334,0.00000,0.07744,315.33012
207.60001,10.38005,25283.47671,0.00000,0.07760,315.37644
208.00001,10.39990,25281.69453,0.00000,0.07777,315.35421
208.40001,10.41987,25282.55284,0.00000,0.07794,315.36491
208.80001,10.43990,25282.61542,0.00000,0.07811,315.36569
209.20001,10.46005,25285.54201,0.00000,0.07828,315.40220
209.60001,10.48008,25286.51357,0.00000,0.07844,315.41432
210.00001,10.50011,25287.74440,0.00000,0.07861,315.42967
210.40001,10.52008,25286.93676,0.00000,0.07878,315.41960
210.80001,10.53999,25286.62086,0.00000,0.07895,315.41566
211.20001,10.55996,25284.23965,0.00000,0.07912,315.38595
211.60001,10.58005,25285.74765,0.00000,0.07929,315.40476
212.00001,10.60008,25285.06815,0.00000,0.07945,315.39629
212.40001,10.61993,25283.06842,0.00000,0.07961,315.37134
212.80001,10.63990,25284.67476,0.00000,0.07978,315.39138
213.20001,10.65987,25286.43012,0.00000,0.07995,315.41328
213.60001,10.67990,25288.50138,0.00000,0.08012,315.43911
214.00001,10.69999,25288.02752,0.00000,0.08030,315.43320
214.40001,10.72008,25289.38949,0.00000,0.08046,315.45019
214.80001,10.74011,25288.20038,0.00000,0.08062,315.43536
215.20001,10.76002,25289.40439,0.00000,0.08079,315.45038
215.60001,10.77999,25288.76960,0.00000,0.08096,315.44246
216.00001,10.80001,25286.22746,0.00000,0.08112,315.41075
216.40001,10.81998,25285.14266,0.00000,0.08130,315.39722
216.80001,10.84001,25285.04729,0.00000,0.08146,315.39603
217.20001,10.85992,25286.67748,0.00000,0.08163,315.41636
217.60001,10.87995,25287.39870,0.00000,0.08179,315.42536
218.00001,10.89992,25288.77258,0.00000,0.08196,315.44250
218.40001,10.91989,25288.84113,0.00000,0.08213,315.44335
218.80001,10.93998,25288.18250,0.00000,0.08230,315.43514
219.20001,10.96013,25290.77828,0.00000,0.08246,315.46751
219.60001,10.98016,25290.32826,0.00000,0.08263,315.46190
220.00001,11.00007,25288.65039,0.00000,0.08279,315.44097
220.40001,11.01998,25287.29737,0.00000,0.08297,315.42410
220.80001,11.04001,25287.53877,0.00000,0.08314,315.42711
221.20001,11.05998,25284.09660,0.00000,0.08330,315.38417
221.60001,11.07995,25285.04133,0.00000,0.08347,315.39595
222.00001,11.09998,25286.90994,0.00000,0.08363,315.41926
222.40001,11.11989,25286.79669,0.00000,0.08380,315.41785
222.80001,11.13992,25289.84249,0.00000,0.08396,315.45584
223.20001,11.16001,25289.40141,0.00000,0.08414,315.45034
223.60001,11.17998,25287.10067,0.00000,0.08431,315.42164
224.00001,11.20019,25288.60569,0.00000,0.08448,315.44041
224.40001,11.22016,25287.97686,0.00000,0.08465,315.43257
224.80001,11.24013,25289.16597,0.00000,0.08482,315.44740
225.20001,11.26004,25286.96954,0.00000,0.08499,315.42001
225.60001,11.27995,25286.02779,0.00000,0.08516,315.40826
226.00001,11.29991,25285.16650,0.00000,0.08533,315.39752
226.40001,11.32000,25286.20064,0.00000,0.08550,315.41042
226.80001,11.33991,25286.23641,0.00000,0.08567,315.41086
227.20001,11.35988,25286.87716,0.00000,0.08584,315.41885
227.60001,11.37991,25289.60407,0.00000,0.08602,315.45287
228.00001,11.40000,25288.38515,0.00000,0.08619,315.43766
228.40001,11.42003,25288.21826,0.00000,0.08636,315.43558
228.80001,11.44012,25288.11991,0.00000,0.08654,315.43436
229.20001,11.46015,25286.98146,0.00000,0.08671,315.42015
229.60001,11.48006,25286.84139,0.00000,0.08688,315.41841
230.00001,11.50009,25287.01723,0.00000,0.08705,315.42060
230.40001,11.51994,25283.13994,0.00000,0.08723,315.37224
230.80001,11.53991,25280.64847,0.00000,0.08741,315.34116
231.20001,11.55988,25282.60052,0.00000,0.08758,315.36551
231.60001,11.57997,25285.67910,0.00000,0.08775,315.40391
232.00001,11.60000,25284.37972,0.00000,0.08792,315.38770
232.40001,11.61997,25282.79424,0.00000,0.08810,315.36792
232.80001,11.64000,25281.89421,0.00000,0.08828,315.35670
233.20001,11.65997,25282.17733,0.00000,0.08846,315.36023
233.60001,11.68012,25282.51410,0.00000,0.08863,315.36443
234.00001,11.70015,25281.21471,0.00000,0.08881,315.34822
234.40001,11.72011,25279.53684,0.00000,0.08898,315.32729
234.80001,11.74002,25279.48618,0.00000,0.08915,315.32666
235.20001,11.75994,25278.49674,0.00000,0.08933,315.31432
235.60001,11.77985,25274.96219,0.00000,0.08951,315.27023
236.00001,11.79987,25274.52111,0.00000,0.08968,315.26473
236.40001,11.81996,25276.17812,0.00000,0.08986,315.28540
236.80001,11.83993,25275.59698,0.00000,0.09003,315.27815
237.20001,11.85996,25276.98874,0.00000,0.09021,315.29551
237.60001,11.87999,25275.32279,0.00000,0.09038,315.27473
238.00001,11.89996,25272.38727,0.00000,0.09055,315.23811
238.40001,11.92011,25273.18597,0.00000,0.09073,315.24807
238.80001,11.94014,25273.19491,0.00000,0.09090,315.24819
239.20001,11.96005,25271.74652,0.00000,0.09108,315.23012
239.60001,11.98008,25271.44253,0.00000,0.09125,315.22633
240.00001,11.99999,25269.50836,0.00000,0.09143,315.20220
240.40001,12.01984,25266.39402,0.00000,0.09161,315.16335
240.80001,12.03987,25265.55955,0.00000,0.09178,315.15295
241.20001,12.05996,25263.55982,0.00000,0.09196,315.12800
241.60001,12.08005,25266.36124,0.00000,0.09212,315.16295
242.00001,12.10002,25266.31057,0.00000,0.09230,315.16231
242.40001,12.11993,25264.79363,0.00000,0.09248,315.14339
242.80001,12.14002,25261.18159,0.00000,0.09266,315.09834
243.20001,12.16005,25259.77790,0.00000,0.09283,315.08083
243.60001,12.18008,25260.53190,0.00000,0.09300,315.09023
244.00001,12.20005,25260.90443,0.00000,0.09318,315.09488
244.40001,12.22002,25258.10301,0.00000,0.09335,315.05994
244.80001,12.23998,25254.30024,0.00000,0.09353,315.01250
245.20001,12.25989,25251.22762,0.00000,0.09370,314.97417
245.60001,12.27987,25250.77164,0.00000,0.09387,314.96849
246.00001,12.29995,25251.21570,0.00000,0.09404,314.97403
246.40001,12.31998,25250.79250,0.00000,0.09422,314.96875
246.80001,12.34001,25248.94774,0.00000,0.09439,314.94574
247.20001,12.35998,25249.07589,0.00000,0.09456,314.94734
247.60001,12.38001,25247.88678,0.00000,0.09473,314.93250
248.00001,12.40004,25244.69793,0.00000,0.09490,314.89273
248.40001,12.42013,25243.21675,0.00000,0.09507,314.87425
248.80001,12.44004,25241.02926,0.00000,0.09523,314.84696
249.20001,12.46001,25240.17096,0.00000,0.09540,314.83626
249.60001,12.47992,25238.42454,0.00000,0.09557,314.81447
250.00001,12.49989,25235.84068,0.00000,0.09574,314.78224
250.40001,12.51992,25232.14221,0.00000,0.09590,314.73611
250.80001,12.54001,25230.54481,0.00000,0.09607,314.71619
251.20001,12.55998,25229.62093,0.00000,0.09623,314.70466
251.60001,12.58001,25229.85637,0.00000,0.09640,314.70760
252.00001,12.60004,25229.52259,0.00000,0.09656,314.70343
252.40001,12.62001,25227.15628,0.00000,0.09673,314.67392
252.80001,12.64004,25225.66915,0.00000,0.09689,314.65537
253.20001,12.66007,25223.76478,0.00000,0.09705,314.63161
253.60001,12.68010,25220.80839,0.00000,0.09721,314.59474
254.00001,12.70007,25219.08581,0.00000,0.09736,314.57325
254.40001,12.71998,25216.44831,0.00000,0.09752,314.54035
254.80001,12.73994,25213.20879,0.00000,0.09767,314.49994
255.20001,12.75991,25209.23018,0.00000,0.09783,314.45031
255.60001,12.77994,25204.95057,0.00000,0.09798,314.39693
256.00001,12.80003,25207.46291,0.00000,0.09813,314.42827
256.40001,12.82000,25206.34234,0.00000,0.09828,314.41429
256.80001,12.84003,25203.74656,0.00000,0.09844,314.38191
257.20001,12.86000,25200.62327,0.00000,0.09858,314.34296
257.60001,12.88003,25196.10524,0.00000,0.09873,314.28660
258.00001,12.90006,25194.64195,0.00000,0.09887,314.26835
258.40001,12.92003,25191.36071,0.00000,0.09902,314.22742
258.80001,12.94006,25187.26885,0.00000,0.09916,314.17638
259.20001,12.96003,25181.65112,0.00000,0.09929,314.10630
259.60001,12.98000,25179.70800,0.00000,0.09943,314.08207
260.00001,12.99985,25174.76380,0.00000,0.09957,314.02039
260.40001,13.01994,25171.70906,0.00000,0.09970,313.98229
260.80001,13.04003,25168.86890,0.00000,0.09983,313.94686
261.20001,13.06000,25166.63074,0.00000,0.09996,313.91895
261.60001,13.08003,25164.61015,0.00000,0.10008,313.89374
262.00001,13.10000,25159.75535,0.00000,0.10021,313.83318
262.40001,13.12003,25155.13599,0.00000,0.10032,313.77556
262.80001,13.14000,25147.41123,0.00000,0.10044,313.67921
263.20001,13.16009,25143.60249,0.00000,0.10056,313.63170
263.60001,13.18005,25139.01293,0.00000,0.10067,313.57445
264.00001,13.20002,25130.69510,0.00000,0.10078,313.47070
264.40001,13.21993,25124.49920,0.00000,0.10088,313.39341
264.80001,13.23991,25117.06054,0.00000,0.10098,313.30063
265.20001,13.25987,25111.65440,0.00000,0.10108,313.23319
265.60001,13.27996,25108.38211,0.00000,0.10118,313.19237
266.00001,13.30005,25100.91364,0.00000,0.10127,313.09922
266.40001,13.32002,25093.05477,0.00000,0.10135,313.00119
266.80001,13.34005,25084.19156,0.00000,0.10144,312.89063
267.20001,13.36002,25072.65806,0.00000,0.10152,312.74677
267.60001,13.37999,25062.36434,0.00000,0.10159,312.61837
268.00001,13.40014,25051.95439,0.00000,0.10166,312.48852
268.40001,13.42011,25039.15131,0.00000,0.10173,312.32882
268.80001,13.43996,25026.17836,0.00000,0.10179,312.16700
269.20001,13.45993,25013.29482,0.00000,0.10185,312.00629
269.60001,13.47984,24997.83188,0.00000,0.10191,311.81341
270.00001,13.49987,24981.89658,0.00000,0.10196,311.61464
270.40001,13.51996,24967.27556,0.00000,0.10201,311.43227
270.80001,13.54005,24950.08111,0.00000,0.10205,311.21779
271.20001,13.56008,24929.98838,0.00000,0.10209,310.96716
271.60001,13.58005,24906.79473,0.00000,0.10212,310.67785
272.00001,13.60002,24882.26891,0.00000,0.10215,310.37192
272.40001,13.62005,24855.98028,0.00000,0.10218,310.04401
272.80001,13.64014,24828.69923,0.00000,0.10220,309.70372
273.20001,13.66004,24795.38918,0.00000,0.10222,309.28822
273.60001,13.68002,24762.37267,0.00000,0.10223,308.87638
274.00001,13.69987,24724.41345,0.00000,0.10224,308.40290
274.40001,13.71983,24682.32810,0.00000,0.10226,307.87794
274.80001,13.73986,24636.45488,0.00000,0.10226,307.30573
275.20001,13.76001,24588.99617,0.00000,0.10226,306.71375
275.60001,13.78010,24535.68876,0.00000,0.10226,306.04882
276.00001,13.80007,24473.55092,0.00000,0.10226,305.27373
276.40001,13.82004,24396.76672,0.00000,0.10225,304.31596
276.80001,13.84007,24303.90716,0.00000,0.10223,303.15766
277.20001,13.85998,24207.11815,0.00000,0.10221,301.95035
277.60001,13.88007,24082.71730,0.00000,0.10219,300.39862
278.00001,13.90010,23897.05777,0.00000,0.10214,298.08278
278.40001,13.92001,23548.02936,0.00000,0.10205,293.72913
278.52001,13.92635,21407.31961,0.00000,0.09911,267.02673
278.52801,13.92754,16754.57656,0.00000,0.08954,208.99019
278.53401,13.92862,12781.76457,0.00000,0.08204,159.43485