File: scratch/college-stuff/ME Lab/ME lab Fall 2013/group2/group2.is_tens_RawData/Specimen_RawData_1.csv
Time,Extension,Load,Strain 2,Tensile strain,Tensile stress
(sec),(mm),(N),(mm/mm),(mm/mm),(MPa)
0.00000,0.00006,0.19432,0.00000,0.00000,0.00241
0.10000,0.00179,3.35367,0.00000,0.00000,0.04152
0.20000,0.00771,7.91442,0.00000,0.00001,0.09798
0.30000,0.01369,7.87724,0.00000,0.00001,0.09752
0.40000,0.01949,9.35750,0.00000,0.00001,0.11585
0.50000,0.02475,9.58189,0.00000,0.00001,0.11863
0.60000,0.03001,10.46262,0.00000,0.00001,0.12953
0.70000,0.03498,10.78553,0.00000,0.00001,0.13353
0.80000,0.04006,11.77210,0.00000,0.00001,0.14574
0.90000,0.04496,13.41369,0.00000,0.00001,0.16607
1.00000,0.05004,14.38810,0.00000,0.00001,0.17813
1.10000,0.05495,15.83772,0.00000,0.00001,0.19608
1.20000,0.06009,16.75196,0.00000,0.00002,0.20740
1.30000,0.06487,16.89069,0.00000,0.00001,0.20912
1.40000,0.07001,17.21562,0.00000,0.00001,0.21314
1.50000,0.07492,17.61341,0.00000,0.00001,0.21806
1.60000,0.08012,19.15601,0.00000,0.00001,0.23716
1.70000,0.08496,20.30932,0.00000,0.00001,0.25144
1.80000,0.09004,20.23083,0.00000,0.00001,0.25047
1.90000,0.09495,21.28552,0.00000,0.00001,0.26353
2.00000,0.10009,22.92778,0.00000,0.00001,0.28386
2.10000,0.10505,24.46530,0.00000,0.00001,0.30289
2.20000,0.11007,26.31976,0.00000,0.00001,0.32585
2.30000,0.11498,28.64331,0.00000,0.00000,0.35462
2.40000,0.11994,31.84415,0.00000,0.00000,0.39425
2.50000,0.12502,33.71907,0.00000,0.00000,0.41746
2.60000,0.13004,36.63292,0.00000,0.00000,0.45353
2.70000,0.13506,40.02594,0.00000,0.00000,0.49554
2.80000,0.13997,47.50202,0.00000,-0.00001,0.58810
2.90000,0.14505,51.75073,0.00000,-0.00001,0.64070
3.00000,0.14995,55.92963,0.00000,-0.00001,0.69244
3.10000,0.15515,59.50277,0.00000,-0.00001,0.73668
3.20000,0.15994,65.73644,0.00000,-0.00001,0.81385
3.30000,0.16508,75.03584,0.00000,-0.00001,0.92898
3.40000,0.16992,91.97210,0.00000,-0.00001,1.13866
3.50000,0.17512,116.31801,0.00000,-0.00001,1.44008
3.60000,0.17991,138.92677,0.00000,-0.00002,1.71999
3.70000,0.18505,166.99847,0.00000,-0.00002,2.06753
3.80000,0.18995,198.78475,0.00000,-0.00002,2.46106
3.90000,0.19509,234.19738,0.00000,-0.00001,2.89949
4.00000,0.20000,268.58265,0.00000,-0.00002,3.32519
4.10000,0.20502,305.03445,0.00000,-0.00002,3.77649
4.20000,0.20998,340.21789,0.00000,-0.00002,4.21208
4.30000,0.21500,374.89324,0.00000,-0.00002,4.64138
4.40000,0.22003,412.76799,0.00000,-0.00003,5.11029
4.50000,0.22505,450.11682,0.00000,-0.00003,5.57268
4.60000,0.23001,492.58848,0.00000,-0.00002,6.09851
4.70000,0.23497,533.39079,0.00000,-0.00003,6.60366
4.80000,0.24005,581.60410,0.00000,-0.00003,7.20057
4.90000,0.24502,627.26121,0.00000,-0.00003,7.76582
5.00000,0.25010,678.25848,0.00000,-0.00002,8.39720
5.10000,0.25500,725.99016,0.00000,-0.00002,8.98814
5.20000,0.26008,780.33279,0.00000,-0.00002,9.66093
5.30000,0.26499,831.87688,0.00000,-0.00002,10.29907
5.40000,0.27007,888.59145,0.00000,-0.00002,11.00123
5.50000,0.27497,946.39855,0.00000,-0.00001,11.71691
5.60000,0.28005,1007.19491,0.00000,-0.00001,12.46960
5.70000,0.28490,1067.96604,0.00000,0.00000,13.22198
5.80000,0.29010,1134.71635,0.00000,0.00001,14.04839
5.90000,0.29500,1196.19099,0.00000,0.00001,14.80948
6.00000,0.30008,1261.62497,0.00000,0.00002,15.61958
6.10000,0.30493,1326.34891,0.00000,0.00003,16.42090
6.20000,0.31001,1395.89449,0.00000,0.00004,17.28191
6.30000,0.31491,1466.06266,0.00000,0.00005,18.15063
6.40000,0.32005,1539.15007,0.00000,0.00006,19.05549
6.50000,0.32490,1613.13321,0.00000,0.00007,19.97144
6.60000,0.32998,1690.61776,0.00000,0.00008,20.93074
6.70000,0.33488,1769.37748,0.00000,0.00010,21.90583
6.80000,0.33996,1846.42617,0.00000,0.00011,22.85973
6.90000,0.34499,1928.53007,0.00000,0.00013,23.87622
7.00000,0.35001,2010.06550,0.00000,0.00014,24.88567
7.10000,0.35497,2092.57994,0.00000,0.00016,25.90724
7.20000,0.35993,2163.56069,0.00000,0.00017,26.78602
7.30000,0.36501,2242.51617,0.00000,0.00019,27.76353
7.40000,0.36992,2319.90442,0.00000,0.00021,28.72164
7.50000,0.37506,2402.37880,0.00000,0.00022,29.74272
7.60000,0.37984,2471.32201,0.00000,0.00024,30.59627
7.70000,0.38504,2553.50918,0.00000,0.00026,31.61379
7.80000,0.38989,2630.12405,0.00000,0.00027,32.56232
7.90000,0.39503,2709.37365,0.00000,0.00029,33.54348
8.00000,0.39987,2787.11822,0.00000,0.00030,34.50599
8.10000,0.40501,2866.05675,0.00000,0.00031,35.48330
8.20000,0.40992,2943.69049,0.00000,0.00033,36.44444
8.30000,0.41506,3023.37091,0.00000,0.00035,37.43093
8.40000,0.41984,3098.57521,0.00000,0.00037,38.36200
8.50000,0.42498,3179.90519,0.00000,0.00038,39.36890
8.60000,0.42989,3257.90234,0.00000,0.00040,40.33455
8.70000,0.43503,3335.01250,0.00000,0.00041,41.28922
8.80000,0.43993,3412.18561,0.00000,0.00043,42.24466
8.90000,0.44501,3489.34941,0.00000,0.00045,43.19999
9.00000,0.44992,3567.51047,0.00000,0.00046,44.16766
9.10000,0.45494,3643.08693,0.00000,0.00048,45.10334
9.20000,0.45996,3720.85571,0.00000,0.00050,46.06616
9.30000,0.46504,3796.16991,0.00000,0.00051,46.99859
9.40000,0.46995,3873.58814,0.00000,0.00053,47.95707
9.50000,0.47497,3945.85691,0.00000,0.00054,48.85179
9.60000,0.47999,4023.02742,0.00000,0.00056,49.80720
9.70000,0.48501,4094.69530,0.00000,0.00057,50.69449
9.80000,0.49003,4171.83042,0.00000,0.00059,51.64946
9.90000,0.49494,4242.93876,0.00000,0.00060,52.52982
10.00000,0.50002,4319.55084,0.00000,0.00062,53.47832
10.10000,0.50486,4389.02564,0.00000,0.00063,54.33845
10.20000,0.51006,4466.50758,0.00000,0.00065,55.29772
10.30000,0.51491,4536.44991,0.00000,0.00066,56.16364
10.40000,0.52005,4613.90764,0.00000,0.00068,57.12261
10.50000,0.52489,4682.61056,0.00000,0.00069,57.97319
10.60000,0.53003,4757.59842,0.00000,0.00071,58.90158
10.70000,0.53488,4827.50162,0.00000,0.00072,59.76702
10.80000,0.54002,4902.02233,0.00000,0.00074,60.68962
10.90000,0.54486,4971.55972,0.00000,0.00075,61.55053
11.00000,0.55000,5043.92907,0.00000,0.00077,62.44650
11.10000,0.55491,5113.05556,0.00000,0.00079,63.30233
11.20000,0.55999,5183.69973,0.00000,0.00080,64.17694
11.30000,0.56489,5254.29957,0.00000,0.00082,65.05100
11.40000,0.56997,5323.72072,0.00000,0.00083,65.91047
11.50000,0.57494,5394.26021,0.00000,0.00085,66.78379
11.60000,0.58002,5461.08223,0.00000,0.00086,67.61108
11.70000,0.58498,5531.13520,0.00000,0.00087,68.47837
11.80000,0.58994,5595.79097,0.00000,0.00089,69.27885
11.90000,0.59497,5667.28339,0.00000,0.00090,70.16396
12.00000,0.59987,5730.05639,0.00000,0.00092,70.94112
12.10000,0.60501,5798.74739,0.00000,0.00093,71.79155
12.20000,0.60985,5863.01722,0.00000,0.00094,72.58725
12.30000,0.61493,5931.96563,0.00000,0.00095,73.44087
12.40000,0.61984,5994.76136,0.00000,0.00097,74.21831
12.50000,0.62504,6061.80020,0.00000,0.00098,75.04829
12.60000,0.62994,6120.25633,0.00000,0.00099,75.77200
12.70000,0.63508,6181.86779,0.00000,0.00101,76.53479
12.80000,0.63987,6239.86721,0.00000,0.00102,77.25285
12.90000,0.64501,6298.67837,0.00000,0.00103,77.98096
13.00000,0.64991,6350.40402,0.00000,0.00104,78.62135
13.10000,0.65499,6403.72634,0.00000,0.00105,79.28151
13.20000,0.65984,6456.35128,0.00000,0.00106,79.93304
13.30000,0.66492,6510.74573,0.00000,0.00107,80.60647
13.40000,0.66982,6563.79461,0.00000,0.00108,81.26324
13.50000,0.67496,6619.05780,0.00000,0.00110,81.94743
13.60000,0.67993,6674.03638,0.00000,0.00110,82.62809
13.70000,0.68501,6727.82883,0.00000,0.00112,83.29407
13.80000,0.68991,6781.19212,0.00000,0.00113,83.95474
13.90000,0.69505,6836.05894,0.00000,0.00114,84.63402
14.00000,0.70002,6889.54070,0.00000,0.00115,85.29615
14.10000,0.70504,6943.75336,0.00000,0.00116,85.96733
14.20000,0.70994,6997.61137,0.00000,0.00117,86.63412
14.30000,0.71496,7050.22886,0.00000,0.00118,87.28556
14.40000,0.71999,7106.29225,0.00000,0.00119,87.97965
14.50000,0.72501,7156.10161,0.00000,0.00120,88.59632
14.60000,0.73009,7214.21391,0.00000,0.00122,89.31578
14.70000,0.73499,7265.78981,0.00000,0.00122,89.95431
14.80000,0.74007,7320.84364,0.00000,0.00123,90.63591
14.90000,0.74498,7371.89129,0.00000,0.00124,91.26791
15.00000,0.75006,7427.08370,0.00000,0.00126,91.95122
15.10000,0.75484,7476.85805,0.00000,0.00127,92.56745
15.20000,0.76004,7535.10743,0.00000,0.00128,93.28861
15.30000,0.76483,7584.27903,0.00000,0.00129,93.89738
15.40000,0.77009,7640.01384,0.00000,0.00130,94.58740
15.50000,0.77487,7691.08385,0.00000,0.00131,95.21968
15.60000,0.78001,7746.14960,0.00000,0.00132,95.90142
15.70000,0.78486,7797.76424,0.00000,0.00133,96.54044
15.80000,0.79006,7852.14454,0.00000,0.00134,97.21369
15.90000,0.79496,7904.64878,0.00000,0.00135,97.86372
16.00000,0.79998,7957.04946,0.00000,0.00136,98.51247
16.10000,0.80489,8009.26387,0.00000,0.00137,99.15891
16.20000,0.80997,8061.16760,0.00000,0.00138,99.80151
16.30000,0.81493,8113.39840,0.00000,0.00139,100.44816
16.40000,0.82001,8163.06248,0.00000,0.00140,101.06302
16.50000,0.82498,8213.36508,0.00000,0.00141,101.68580
16.60000,0.82994,8261.98459,0.00000,0.00142,102.28773
16.70000,0.83496,8312.40565,0.00000,0.00144,102.91197
16.80000,0.83992,8356.41474,0.00000,0.00144,103.45683
16.90000,0.84500,8406.65326,0.00000,0.00145,104.07881
17.00000,0.84991,8449.69451,0.00000,0.00146,104.61168
17.10000,0.85499,8500.82561,0.00000,0.00147,105.24471
17.20000,0.85989,8545.52090,0.00000,0.00148,105.79806
17.30000,0.86509,8595.77209,0.00000,0.00149,106.42020
17.40000,0.86994,8638.59504,0.00000,0.00150,106.95037
17.50000,0.87502,8688.82984,0.00000,0.00151,107.57230
17.60000,0.87986,8733.96397,0.00000,0.00152,108.13108
17.70000,0.88506,8785.76711,0.00000,0.00153,108.77243
17.80000,0.88991,8828.93428,0.00000,0.00154,109.30687
17.90000,0.89505,8877.44650,0.00000,0.00155,109.90747
18.00000,0.89989,8922.80489,0.00000,0.00156,110.46903
18.10000,0.90503,8973.12090,0.00000,0.00157,111.09197
18.20000,0.91000,9019.19529,0.00000,0.00158,111.66240
18.30000,0.91502,9066.58992,0.00000,0.00159,112.24917
18.40000,0.91992,9113.93091,0.00000,0.00160,112.83528
18.50000,0.92500,9162.89166,0.00000,0.00161,113.44144
18.60000,0.92991,9209.72675,0.00000,0.00162,114.02128
18.70000,0.93505,9255.99709,0.00000,0.00163,114.59413
18.80000,0.93995,9304.49069,0.00000,0.00164,115.19451
18.90000,0.94497,9351.36750,0.00000,0.00165,115.77487
19.00000,0.94994,9401.69394,0.00000,0.00166,116.39793
19.10000,0.95496,9446.24841,0.00000,0.00168,116.94954
19.20000,0.95998,9496.87287,0.00000,0.00168,117.57630
19.30000,0.96500,9542.67830,0.00000,0.00169,118.14339
19.40000,0.96996,9593.55310,0.00000,0.00171,118.77325
19.50000,0.97487,9640.04323,0.00000,0.00172,119.34882
19.60000,0.98007,9689.80715,0.00000,0.00173,119.96493
19.70000,0.98491,9734.59557,0.00000,0.00173,120.51943
19.80000,0.99005,9785.33179,0.00000,0.00175,121.14757
19.90000,0.99484,9829.22614,0.00000,0.00176,121.69101
20.00000,1.00004,9881.55827,0.00000,0.00177,122.33891
20.10000,1.00488,9926.42269,0.00000,0.00178,122.89435
20.20000,1.01008,9978.10364,0.00000,0.00179,123.53419
20.30000,1.01493,10022.95986,0.00000,0.00180,124.08953
20.40000,1.02001,10073.25947,0.00000,0.00181,124.71227
20.50000,1.02485,10120.52521,0.00000,0.00182,125.29744
20.60000,1.02999,10170.08722,0.00000,0.00183,125.91105
20.70000,1.03496,10219.25211,0.00000,0.00185,126.51974
20.80000,1.03992,10266.61471,0.00000,0.00185,127.10611
20.90000,1.04488,10316.73849,0.00000,0.00187,127.72667
21.00000,1.04996,10364.30076,0.00000,0.00187,128.31551
21.10000,1.05493,10415.63302,0.00000,0.00189,128.95104
21.20000,1.06001,10462.17829,0.00000,0.00190,129.52729
21.30000,1.06497,10512.08079,0.00000,0.00191,130.14511
21.40000,1.06999,10559.90756,0.00000,0.00192,130.73723
21.50000,1.07502,10610.66017,0.00000,0.00193,131.36557
21.60000,1.07998,10655.28393,0.00000,0.00194,131.91804
21.70000,1.08506,10706.88888,0.00000,0.00195,132.55694
21.80000,1.08990,10751.86953,0.00000,0.00196,133.11382
21.90000,1.09504,10805.46007,0.00000,0.00197,133.77730
22.00000,1.09989,10849.66362,0.00000,0.00198,134.32456
22.10000,1.10509,10901.15607,0.00000,0.00199,134.96207
22.20000,1.10993,10946.56363,0.00000,0.00200,135.52424
22.30000,1.11507,10999.91873,0.00000,0.00202,136.18480
22.40000,1.11992,11046.96393,0.00000,0.00202,136.76725
22.50000,1.12512,11097.09889,0.00000,0.00204,137.38794
22.60000,1.12996,11143.28206,0.00000,0.00205,137.95971
22.70000,1.13498,11193.68896,0.00000,0.00206,138.58378
22.80000,1.13989,11243.32696,0.00000,0.00207,139.19832
22.90000,1.14503,11293.19146,0.00000,0.00208,139.81567
23.00000,1.14987,11338.89481,0.00000,0.00209,140.38150
23.10000,1.15507,11390.04752,0.00000,0.00210,141.01480
23.20000,1.15992,11438.06651,0.00000,0.00211,141.60930
23.30000,1.16500,11488.82136,0.00000,0.00212,142.23767
23.40000,1.16996,11536.83141,0.00000,0.00213,142.83206
23.50000,1.17504,11585.02251,0.00000,0.00215,143.42869
23.60000,1.18001,11634.50330,0.00000,0.00215,144.04129
23.70000,1.18497,11682.56178,0.00000,0.00216,144.63628
23.80000,1.18993,11733.18177,0.00000,0.00218,145.26298
23.90000,1.19495,11780.18749,0.00000,0.00218,145.84494
24.00000,1.20003,11833.54780,0.00000,0.00220,146.50557
24.10000,1.20494,11878.93078,0.00000,0.00221,147.06743
24.20000,1.21002,11931.70398,0.00000,0.00222,147.72079
24.30000,1.21486,11977.98997,0.00000,0.00223,148.29384
24.40000,1.22006,12031.70270,0.00000,0.00224,148.95883
24.50000,1.22491,12079.08466,0.00000,0.00225,149.54544
24.60000,1.23005,12131.00180,0.00000,0.00226,150.18821
24.70000,1.23489,12178.02763,0.00000,0.00228,150.77041
24.80000,1.24003,12231.40955,0.00000,0.00229,151.43131
24.90000,1.24494,12277.65828,0.00000,0.00230,152.00389
25.00000,1.25008,12329.93677,0.00000,0.00231,152.65113
25.10000,1.25486,12375.81968,0.00000,0.00232,153.21918
25.20000,1.25994,12428.55638,0.00000,0.00233,153.87209
25.30000,1.26491,12478.16384,0.00000,0.00235,154.48626
25.40000,1.26999,12526.59410,0.00000,0.00235,155.08585
25.50000,1.27495,12575.80370,0.00000,0.00236,155.69509
25.60000,1.27997,12624.92687,0.00000,0.00238,156.30326
25.70000,1.28494,12678.76625,0.00000,0.00239,156.96982
25.80000,1.29002,12726.53788,0.00000,0.00240,157.56126
25.90000,1.29504,12777.10795,0.00000,0.00241,158.18734
26.00000,1.30000,12822.35086,0.00000,0.00242,158.74747
26.10000,1.30497,12876.45847,0.00000,0.00244,159.41735
26.20000,1.30993,12923.96784,0.00000,0.00244,160.00554
26.30000,1.31501,12978.75643,0.00000,0.00246,160.68386
26.40000,1.31997,13024.37931,0.00000,0.00247,161.24869
26.50000,1.32505,13076.17873,0.00000,0.00248,161.89000
26.60000,1.32990,13123.40498,0.00000,0.00249,162.47468
26.70000,1.33510,13176.75412,0.00000,0.00251,163.13517
26.80000,1.34000,13224.66731,0.00000,0.00252,163.72836
26.90000,1.34514,13276.02863,0.00000,0.00253,164.36424
27.00000,1.34993,13322.24607,0.00000,0.00254,164.93644
27.10000,1.35507,13374.30328,0.00000,0.00256,165.58093
27.20000,1.35991,13422.58006,0.00000,0.00257,166.17863
27.30000,1.36511,13475.49558,0.00000,0.00258,166.83375
27.40000,1.36996,13521.13634,0.00000,0.00259,167.39881
27.50000,1.37504,13572.15792,0.00000,0.00261,168.03048
27.60000,1.37988,13621.13506,0.00000,0.00262,168.63684
27.70000,1.38502,13673.47389,0.00000,0.00263,169.28483
27.80000,1.38999,13723.43451,0.00000,0.00264,169.90336
27.90000,1.39507,13774.28323,0.00000,0.00266,170.53290
28.00000,1.39991,13820.78826,0.00000,0.00267,171.10865
28.10000,1.40499,13873.34019,0.00000,0.00268,171.75928
28.20000,1.40996,13922.60194,0.00000,0.00269,172.36916
28.30000,1.41504,13972.51487,0.00000,0.00271,172.98711
28.40000,1.41994,14021.42942,0.00000,0.00272,173.59270
28.50000,1.42490,14069.45884,0.00000,0.00273,174.18733
28.60000,1.42999,14124.33386,0.00000,0.00275,174.86671
28.70000,1.43495,14169.72727,0.00000,0.00276,175.42870
28.80000,1.44003,14222.81265,0.00000,0.00278,176.08593
28.90000,1.44493,14267.74263,0.00000,0.00279,176.64219
29.00000,1.45001,14321.85471,0.00000,0.00281,177.31212
29.10000,1.45492,14368.26289,0.00000,0.00282,177.88668
29.20000,1.46006,14420.42440,0.00000,0.00283,178.53247
29.30000,1.46490,14467.51207,0.00000,0.00285,179.11544
29.40000,1.47004,14520.13701,0.00000,0.00286,179.76696
29.50000,1.47483,14567.73877,0.00000,0.00287,180.35630
29.60000,1.48003,14619.61269,0.00000,0.00289,180.99852
29.70000,1.48487,14666.30846,0.00000,0.00291,181.57664
29.80000,1.49001,14718.77843,0.00000,0.00292,182.22625
29.90000,1.49486,14765.04952,0.00000,0.00294,182.79911
30.00000,1.50000,14816.78486,0.00000,0.00295,183.43962
30.10000,1.50496,14866.15092,0.00000,0.00297,184.05080
30.20000,1.51004,14917.38409,0.00000,0.00299,184.68509
30.30000,1.51495,14966.23456,0.00000,0.00300,185.28988
30.40000,1.51997,15012.63529,0.00000,0.00301,185.86435
30.50000,1.52493,15062.65402,0.00000,0.00303,186.48361
30.60000,1.53001,15111.76527,0.00000,0.00304,187.09163
30.70000,1.53504,15162.02390,0.00000,0.00305,187.71386
30.80000,1.54006,15209.65248,0.00000,0.00307,188.30353
30.90000,1.54496,15258.75926,0.00000,0.00309,188.91149
31.00000,1.54992,15304.89475,0.00000,0.00310,189.48268
31.10000,1.55501,15359.11560,0.00000,0.00312,190.15396
31.20000,1.55997,15403.29009,0.00000,0.00314,190.70086
31.30000,1.56505,15456.03275,0.00000,0.00315,191.35384
31.40000,1.56995,15502.19059,0.00000,0.00317,191.92530
31.50000,1.57503,15553.26432,0.00000,0.00318,192.55762
31.60000,1.57994,15598.73223,0.00000,0.00320,193.12054
31.70000,1.58508,15649.93262,0.00000,0.00322,193.75443
31.80000,1.58992,15694.20248,0.00000,0.00323,194.30251
31.90000,1.59500,15747.70659,0.00000,0.00325,194.96492
32.00000,1.59991,15791.99731,0.00000,0.00327,195.51326
32.10000,1.60505,15842.97419,0.00000,0.00329,196.14438
32.20000,1.60995,15887.98016,0.00000,0.00331,196.70158
32.30000,1.61503,15937.04522,0.00000,0.00332,197.30903
32.40000,1.61994,15985.28624,0.00000,0.00334,197.90628
32.50000,1.62502,16033.22923,0.00000,0.00336,198.49984
32.60000,1.62992,16078.76122,0.00000,0.00338,199.06355
32.70000,1.63506,16127.51335,0.00000,0.00340,199.66713
32.80000,1.63991,16174.79324,0.00000,0.00342,200.25248
32.90000,1.64505,16222.88227,0.00000,0.00344,200.84785
33.00000,1.65001,16270.00570,0.00000,0.00346,201.43126
33.10000,1.65503,16315.54216,0.00000,0.00348,201.99503
33.20000,1.66000,16365.16601,0.00000,0.00350,202.60939
33.30000,1.66496,16409.65492,0.00000,0.00352,203.16019
33.40000,1.66998,16459.03736,0.00000,0.00354,203.77157
33.50000,1.67500,16501.95569,0.00000,0.00356,204.30292
33.60000,1.68008,16551.45884,0.00000,0.00359,204.91580
33.70000,1.68493,16593.29832,0.00000,0.00361,205.43379
33.80000,1.69007,16644.81014,0.00000,0.00363,206.07154
33.90000,1.69485,16685.23401,0.00000,0.00365,206.57201
34.00000,1.70005,16732.60778,0.00000,0.00368,207.15852
34.10000,1.70490,16774.93006,0.00000,0.00370,207.68249
34.20000,1.70998,16821.28608,0.00000,0.00373,208.25640
34.30000,1.71482,16865.14318,0.00000,0.00376,208.79938
34.40000,1.72002,16912.02819,0.00000,0.00379,209.37984
34.50000,1.72493,16953.46981,0.00000,0.00382,209.89291
34.60000,1.73007,16998.69782,0.00000,0.00385,210.45285
34.70000,1.73491,17040.04407,0.00000,0.00388,210.96474
34.80000,1.73999,17083.89819,0.00000,0.00391,211.50768
34.90000,1.74496,17125.89413,0.00000,0.00395,212.02761
35.00000,1.74998,17166.96322,0.00000,0.00399,212.53607
35.10000,1.75494,17207.81177,0.00000,0.00403,213.04179
35.20000,1.75996,17249.06564,0.00000,0.00406,213.55254
35.30000,1.76493,17287.99641,0.00000,0.00411,214.03452
35.40000,1.77001,17325.71125,0.00000,0.00415,214.50145
35.50000,1.77503,17364.20691,0.00000,0.00420,214.97805
35.60000,1.78005,17396.51561,0.00000,0.00425,215.37805
35.70000,1.78502,17432.31714,0.00000,0.00431,215.82129
35.80000,1.78998,17463.75859,0.00000,0.00437,216.21055
35.90000,1.79506,17495.89890,0.00000,0.00444,216.60846
36.00000,1.80002,17522.06385,0.00000,0.00451,216.93240
36.10000,1.80504,17552.59633,0.00000,0.00459,217.31041
36.20000,1.80995,17576.66320,0.00000,0.00467,217.60837
36.30000,1.81509,17605.02756,0.00000,0.00476,217.95953
36.40000,1.81999,17625.06515,0.00000,0.00486,218.20761
36.50000,1.82513,17650.69962,0.00000,0.00497,218.52498
36.60000,1.82992,17667.63330,0.00000,0.00507,218.73463
36.70000,1.83506,17691.74933,0.00000,0.00518,219.03320
36.80000,1.83990,17706.89040,0.00000,0.00530,219.22065
36.90000,1.84510,17728.06793,0.00000,0.00541,219.48284
37.00000,1.84989,17742.10632,0.00000,0.00553,219.65664
37.10000,1.85503,17762.57902,0.00000,0.00566,219.91011
37.20000,1.85987,17776.50118,0.00000,0.00579,220.08247
37.30000,1.86507,17793.90723,0.00000,0.00592,220.29796
37.40000,1.86998,17807.93518,0.00000,0.00606,220.47164
37.50000,1.87506,17822.15238,0.00000,0.00620,220.64765
37.60000,1.87996,17836.86876,0.00000,0.00634,220.82985
37.70000,1.88504,17850.04735,0.00000,0.00648,220.99301
37.80000,1.89001,17862.72228,0.00000,0.00662,221.14993
37.90000,1.89509,17873.41982,0.00000,0.00676,221.28237
38.00000,1.89993,17885.88762,0.00000,0.00690,221.43673
38.10000,1.90489,17897.41069,0.00000,0.00705,221.57939
38.20000,1.90998,17912.67842,0.00000,0.00721,221.76842
38.30000,1.91494,17918.76405,0.00000,0.00736,221.84376
38.40000,1.92002,17933.89767,0.00000,0.00751,222.03112
38.50000,1.92486,17938.90446,0.00000,0.00766,222.09311
38.60000,1.93000,17955.50734,0.00000,0.00781,222.29866
38.70000,1.93491,17962.16369,0.00000,0.00797,222.38107
38.80000,1.94011,17973.88792,0.00000,0.00814,222.52622
38.90000,1.94489,17978.98412,0.00000,0.00829,222.58931
39.00000,1.95003,17993.33543,0.00000,0.00845,222.76699
39.10000,1.95482,17998.54189,0.00000,0.00861,222.83145
39.20000,1.96008,18011.96635,0.00000,0.00877,222.99765
39.30000,1.96498,18015.74677,0.00000,0.00893,223.04446
39.40000,1.97000,18025.79314,0.00000,0.00910,223.16883
39.50000,1.97491,18034.89476,0.00000,0.00926,223.28152
39.60000,1.97999,18044.71016,0.00000,0.00943,223.40304
39.70000,1.98495,18050.70490,0.00000,0.00959,223.47726
39.80000,1.99003,18057.06471,0.00000,0.00976,223.55599
39.90000,1.99494,18064.29476,0.00000,0.00992,223.64551
40.00000,2.00002,18072.49337,0.00000,0.01009,223.74701
40.10000,2.00498,18080.48189,0.00000,0.01027,223.84591
40.20000,2.01006,18084.93286,0.00000,0.01043,223.90102
40.30000,2.01503,18090.52080,0.00000,0.01060,223.97020
40.40000,2.01999,18095.88373,0.00000,0.01076,224.03659
40.50000,2.02501,18105.63952,0.00000,0.01093,224.15738
40.60000,2.03003,18109.03549,0.00000,0.01111,224.19942
40.70000,2.03505,18116.52482,0.00000,0.01129,224.29214
40.80000,2.03996,18117.24603,0.00000,0.01147,224.30107
40.90000,2.04504,18124.56548,0.00000,0.01164,224.39169
41.00000,2.04994,18128.88235,0.00000,0.01181,224.44513
41.10000,2.05508,18135.79798,0.00000,0.01199,224.53075
41.20000,2.05999,18136.40893,0.00000,0.01216,224.53832
41.30000,2.06513,18142.48562,0.00000,0.01234,224.61355
41.40000,2.06991,18141.50959,0.00000,0.01252,224.60147
41.50000,2.07505,18150.66189,0.00000,0.01269,224.71478
41.60000,2.07990,18148.47738,0.00000,0.01287,224.68773
41.70000,2.08510,18153.57804,0.00000,0.01305,224.75088
41.80000,2.08988,18150.26999,0.00000,0.01324,224.70992
41.90000,2.09496,18151.57235,0.00000,0.01342,224.72605
42.00000,2.09987,18148.83351,0.00000,0.01361,224.69214
42.10000,2.10507,18147.17650,0.00000,0.01379,224.67163
42.20000,2.10997,18144.22607,0.00000,0.01399,224.63510
42.30000,2.11505,18133.13514,0.00000,0.01418,224.49779
42.40000,2.11996,18119.52591,0.00000,0.01439,224.32930
42.50000,2.12504,18103.00201,0.00000,0.01459,224.12472
42.60000,2.13000,18078.51195,0.00000,0.01480,223.82152
42.70000,2.13502,18048.59191,0.00000,0.01501,223.45110
42.80000,2.13999,18026.65144,0.00000,0.01522,223.17946
42.90000,2.14495,18005.85389,0.00000,0.01543,222.92198
43.00000,2.15003,17986.01151,0.00000,0.01565,222.67632
43.10000,2.15499,17944.47601,0.00000,0.01586,222.16209
43.20000,2.16013,17903.17446,0.00000,0.01609,221.65075
43.30000,2.16498,17856.80354,0.00000,0.01633,221.07665
43.40000,2.17006,17813.30556,0.00000,0.01656,220.53813
43.50000,2.17496,17747.03711,0.00000,0.01683,219.71769
43.60000,2.18016,17677.10596,0.00000,0.01713,218.85190
43.70000,2.18495,17582.06934,0.00000,0.01746,217.67530
43.80000,2.19003,17505.54740,0.00000,0.01775,216.72792
43.90000,2.19493,17399.39749,0.00000,0.01807,215.41373
44.00000,2.20007,17279.24049,0.00000,0.01844,213.92612
44.10000,2.20498,17122.34914,0.00000,0.01884,211.98372
44.19000,2.20964,16836.27218,0.00000,0.01927,208.44194
44.19600,2.21000,16292.46622,0.00000,0.02017,201.70933
44.19800,2.21018,15773.24867,0.00000,0.02120,195.28115
44.20000,2.21036,15094.30408,0.00000,0.02252,186.87545
44.20200,2.21066,14317.43503,0.00000,0.02392,177.25740
44.20400,2.21090,13469.26540,0.00000,0.02535,166.75662
44.20600,2.21113,12557.79117,0.00000,0.02681,155.47208
44.20800,2.21143,11604.72408,0.00000,0.02819,143.67261
44.21000,2.21173,10638.69819,0.00000,0.02928,131.71270
44.21200,2.21197,9677.66568,0.00000,0.02997,119.81461