File: scratch/college-stuff/ME Lab/ME lab Fall 2013/group12/group12.is_tens_RawData/Specimen_RawData_2.csv
Time,Extension,Load,Strain 2,Tensile strain,Tensile stress
(sec),(mm),(N),(mm/mm),(mm/mm),(MPa)
0.00000,0.00000,-0.14978,0.00000,0.00000,-0.00187
0.20000,0.00717,3.14263,0.00000,0.00000,0.03920
0.40000,0.01937,5.76759,0.00000,0.00001,0.07194
0.60000,0.02995,6.15799,0.00000,0.00001,0.07681
0.80000,0.04006,7.74301,0.00000,0.00001,0.09658
1.00000,0.05004,10.72013,0.00000,0.00001,0.13372
1.20000,0.06003,11.57834,0.00000,0.00002,0.14442
1.40000,0.06995,13.67703,0.00000,0.00002,0.17060
1.60000,0.07994,14.67736,0.00000,0.00001,0.18308
1.80000,0.08998,16.61290,0.00000,0.00002,0.20722
2.00000,0.09997,18.51492,0.00000,0.00002,0.23095
2.20000,0.10995,20.97021,0.00000,0.00001,0.26157
2.40000,0.11988,23.15239,0.00000,0.00001,0.28879
2.60000,0.12998,25.57745,0.00000,0.00001,0.31904
2.80000,0.13997,26.32950,0.00000,0.00001,0.32842
3.00000,0.14995,28.97134,0.00000,0.00000,0.36138
3.20000,0.16000,32.06515,0.00000,0.00000,0.39997
3.40000,0.16998,35.51717,0.00000,0.00000,0.44303
3.60000,0.18003,41.36302,0.00000,-0.00001,0.51595
3.80000,0.19007,46.34960,0.00000,-0.00001,0.57815
4.00000,0.20006,58.90432,0.00000,-0.00001,0.73475
4.20000,0.21010,74.10036,0.00000,-0.00001,0.92430
4.40000,0.22009,97.84120,0.00000,-0.00001,1.22043
4.60000,0.23013,132.73468,0.00000,-0.00001,1.65568
4.80000,0.24000,170.30743,0.00000,0.00001,2.12435
5.00000,0.25004,216.21294,0.00000,0.00002,2.69696
5.20000,0.26002,270.45070,0.00000,0.00004,3.37350
5.40000,0.27001,327.04868,0.00000,0.00006,4.07948
5.60000,0.28005,385.30729,0.00000,0.00008,4.80618
5.80000,0.28998,461.90233,0.00000,0.00011,5.76159
6.00000,0.29996,544.96475,0.00000,0.00015,6.79768
6.20000,0.30995,628.55631,0.00000,0.00019,7.84037
6.40000,0.31987,711.28914,0.00000,0.00023,8.87235
6.60000,0.32986,792.88566,0.00000,0.00026,9.89015
6.80000,0.33984,867.48889,0.00000,0.00030,10.82073
7.00000,0.34995,948.43814,0.00000,0.00034,11.83046
7.20000,0.35993,1026.73424,0.00000,0.00038,12.80709
7.40000,0.36992,1103.39820,0.00000,0.00041,13.76337
7.60000,0.37996,1175.26976,0.00000,0.00045,14.65987
7.80000,0.38995,1243.90339,0.00000,0.00048,15.51598
8.00000,0.39999,1313.78295,0.00000,0.00051,16.38763
8.20000,0.40998,1381.78561,0.00000,0.00055,17.23587
8.40000,0.42008,1447.26755,0.00000,0.00058,18.05266
8.60000,0.43007,1511.20750,0.00000,0.00060,18.85023
8.80000,0.44005,1572.07642,0.00000,0.00063,19.60948
9.00000,0.45010,1630.49418,0.00000,0.00066,20.33816
9.20000,0.46002,1687.02733,0.00000,0.00069,21.04333
9.40000,0.47012,1741.12543,0.00000,0.00071,21.71813
9.60000,0.47999,1793.31936,0.00000,0.00074,22.36918
9.80000,0.49003,1843.39117,0.00000,0.00076,22.99376
10.00000,0.49996,1890.70199,0.00000,0.00078,23.58389
10.20000,0.51000,1934.65166,0.00000,0.00080,24.13211
10.40000,0.52005,1978.32435,0.00000,0.00082,24.67686
10.60000,0.52997,2022.91235,0.00000,0.00084,25.23304
10.80000,0.53996,2068.23386,0.00000,0.00087,25.79836
11.00000,0.54988,2117.12588,0.00000,0.00089,26.40822
11.20000,0.55987,2164.74831,0.00000,0.00091,27.00224
11.40000,0.56991,2213.59823,0.00000,0.00093,27.61158
11.60000,0.57990,2261.01708,0.00000,0.00095,28.20306
11.80000,0.58994,2314.50945,0.00000,0.00098,28.87031
12.00000,0.59987,2367.34636,0.00000,0.00101,29.52937
12.20000,0.60997,2419.59263,0.00000,0.00103,30.18107
12.40000,0.61996,2472.25370,0.00000,0.00105,30.83795
12.60000,0.63000,2525.99213,0.00000,0.00108,31.50826
12.80000,0.64005,2579.18034,0.00000,0.00111,32.17171
13.00000,0.65003,2631.46274,0.00000,0.00113,32.82386
13.20000,0.66008,2684.83367,0.00000,0.00116,33.48959
13.40000,0.67006,2737.20231,0.00000,0.00118,34.14282
13.60000,0.68011,2790.35643,0.00000,0.00120,34.80584
13.80000,0.69015,2844.34631,0.00000,0.00123,35.47929
14.00000,0.70008,2898.98440,0.00000,0.00126,36.16082
14.20000,0.71012,2954.16042,0.00000,0.00128,36.84907
14.40000,0.72004,3008.36768,0.00000,0.00131,37.52523
14.60000,0.73009,3061.99268,0.00000,0.00134,38.19413
14.80000,0.74001,3116.47132,0.00000,0.00137,38.87367
15.00000,0.75000,3171.02745,0.00000,0.00139,39.55419
15.20000,0.75998,3224.75024,0.00000,0.00142,40.22430
15.40000,0.76997,3279.42781,0.00000,0.00145,40.90633
15.60000,0.77995,3334.49468,0.00000,0.00147,41.59321
15.80000,0.78994,3390.34759,0.00000,0.00150,42.28990
16.00000,0.79992,3444.77557,0.00000,0.00153,42.96882
16.20000,0.80985,3497.68959,0.00000,0.00156,43.62884
16.40000,0.81989,3553.04219,0.00000,0.00158,44.31929
16.60000,0.82994,3608.66413,0.00000,0.00161,45.01310
16.80000,0.83986,3661.30136,0.00000,0.00164,45.66968
17.00000,0.84997,3715.07667,0.00000,0.00166,46.34045
17.20000,0.86001,3769.97702,0.00000,0.00169,47.02525
17.40000,0.87006,3823.99745,0.00000,0.00172,47.69908
17.60000,0.88004,3876.90365,0.00000,0.00174,48.35902
17.80000,0.89003,3930.29898,0.00000,0.00177,49.02505
18.00000,0.90013,3982.09020,0.00000,0.00180,49.67107
18.20000,0.91012,4035.89457,0.00000,0.00182,50.34221
18.40000,0.92010,4087.63029,0.00000,0.00185,50.98754
18.60000,0.93009,4140.36624,0.00000,0.00188,51.64535
18.80000,0.94001,4194.03799,0.00000,0.00190,52.31483
19.00000,0.95006,4245.89254,0.00000,0.00193,52.96164
19.20000,0.96004,4298.53462,0.00000,0.00195,53.61828
19.40000,0.97002,4350.94163,0.00000,0.00198,54.27199
19.60000,0.98001,4404.07582,0.00000,0.00200,54.93476
19.80000,0.98999,4455.60105,0.00000,0.00203,55.57747
20.00000,0.99998,4506.64423,0.00000,0.00206,56.21416
20.20000,1.00996,4557.57305,0.00000,0.00208,56.84943
20.40000,1.01995,4608.56296,0.00000,0.00211,57.48546
20.60000,1.02987,4659.26230,0.00000,0.00213,58.11786
20.80000,1.03986,4708.93234,0.00000,0.00216,58.73742
21.00000,1.04990,4759.25989,0.00000,0.00218,59.36519
21.20000,1.05989,4811.06825,0.00000,0.00221,60.01143
21.40000,1.06999,4860.25997,0.00000,0.00223,60.62503
21.60000,1.07992,4908.39034,0.00000,0.00226,61.22539
21.80000,1.09002,4955.16099,0.00000,0.00228,61.80879
22.00000,1.09995,5003.01458,0.00000,0.00230,62.40569
22.20000,1.10999,5048.50522,0.00000,0.00233,62.97313
22.40000,1.12004,5092.81158,0.00000,0.00235,63.52579
22.60000,1.13008,5139.98084,0.00000,0.00238,64.11416
22.80000,1.14013,5186.44713,0.00000,0.00240,64.69376
23.00000,1.15005,5235.40340,0.00000,0.00243,65.30442
23.20000,1.16010,5284.51130,0.00000,0.00245,65.91698
23.40000,1.17008,5333.74250,0.00000,0.00248,66.53107
23.60000,1.18007,5384.78419,0.00000,0.00251,67.16774
23.80000,1.19005,5435.64707,0.00000,0.00253,67.80219
24.00000,1.20003,5485.72280,0.00000,0.00255,68.42681
24.20000,1.21008,5534.90594,0.00000,0.00258,69.04030
24.40000,1.22000,5586.92664,0.00000,0.00261,69.68919
24.60000,1.23005,5637.80144,0.00000,0.00263,70.32378
24.80000,1.23997,5688.56522,0.00000,0.00266,70.95699
25.00000,1.24990,5739.11183,0.00000,0.00269,71.58749
25.20000,1.25994,5789.90132,0.00000,0.00271,72.22102
25.40000,1.26987,5841.02608,0.00000,0.00274,72.85873
25.60000,1.27991,5890.82576,0.00000,0.00276,73.47991
25.80000,1.28996,5943.24507,0.00000,0.00279,74.13377
26.00000,1.29994,5995.05454,0.00000,0.00281,74.78002
26.20000,1.30993,6046.51049,0.00000,0.00285,75.42186
26.40000,1.31991,6097.79768,0.00000,0.00287,76.06160
26.60000,1.33002,6149.28342,0.00000,0.00289,76.70381
26.80000,1.34000,6202.43810,0.00000,0.00292,77.36685
27.00000,1.35005,6254.75422,0.00000,0.00295,78.01942
27.20000,1.36003,6305.45467,0.00000,0.00297,78.65183
27.40000,1.37008,6356.78470,0.00000,0.00301,79.29211
27.60000,1.38006,6408.20190,0.00000,0.00303,79.93346
27.80000,1.39005,6460.93115,0.00000,0.00306,80.59119
28.00000,1.40015,6514.30860,0.00000,0.00308,81.25700
28.20000,1.41002,6565.91952,0.00000,0.00311,81.90077
28.40000,1.42006,6619.22842,0.00000,0.00314,82.56573
28.60000,1.43005,6671.83027,0.00000,0.00317,83.22186
28.80000,1.43997,6724.45595,0.00000,0.00320,83.87830
29.00000,1.45007,6776.75754,0.00000,0.00322,84.53069
29.20000,1.46000,6830.34733,0.00000,0.00325,85.19915
29.40000,1.47004,6883.28743,0.00000,0.00328,85.85950
29.60000,1.47997,6935.23884,0.00000,0.00331,86.50752
29.80000,1.48989,6988.85247,0.00000,0.00334,87.17628
30.00000,1.49988,7042.90420,0.00000,0.00336,87.85050
30.20000,1.50992,7097.59071,0.00000,0.00339,88.53264
30.40000,1.51991,7150.66195,0.00000,0.00342,89.19463
30.60000,1.52989,7204.71740,0.00000,0.00345,89.86889
30.80000,1.53994,7257.97564,0.00000,0.00348,90.53322
31.00000,1.54992,7310.34204,0.00000,0.00350,91.18642
31.20000,1.55991,7364.27605,0.00000,0.00353,91.85917
31.40000,1.57001,7417.50002,0.00000,0.00357,92.52306
31.60000,1.58000,7471.98164,0.00000,0.00360,93.20265
31.80000,1.59004,7525.79197,0.00000,0.00363,93.87386
32.00000,1.60003,7580.30191,0.00000,0.00365,94.55379
32.20000,1.61007,7633.83061,0.00000,0.00368,95.22149
32.40000,1.62012,7688.12224,0.00000,0.00371,95.89870
32.60000,1.63004,7742.20973,0.00000,0.00374,96.57337
32.80000,1.64015,7794.91812,0.00000,0.00377,97.23083
33.00000,1.65001,7849.43476,0.00000,0.00379,97.91085
33.20000,1.66000,7903.05659,0.00000,0.00382,98.57971
33.40000,1.67004,7957.33184,0.00000,0.00385,99.25672
33.60000,1.68003,8011.92895,0.00000,0.00388,99.93774
33.80000,1.69001,8065.03072,0.00000,0.00391,100.60011
34.00000,1.69993,8121.17383,0.00000,0.00394,101.30042
34.20000,1.70998,8173.93139,0.00000,0.00397,101.95850
34.40000,1.71990,8228.26102,0.00000,0.00400,102.63619
34.60000,1.72995,8282.36714,0.00000,0.00403,103.31109
34.80000,1.73987,8334.56069,0.00000,0.00405,103.96213
35.00000,1.74986,8390.07795,0.00000,0.00408,104.65463
35.20000,1.75990,8444.96116,0.00000,0.00411,105.33922
35.40000,1.76989,8500.38305,0.00000,0.00415,106.03053
35.60000,1.77993,8555.43539,0.00000,0.00418,106.71724
35.80000,1.78998,8610.46985,0.00000,0.00420,107.40371
36.00000,1.79996,8665.45588,0.00000,0.00423,108.08959
36.20000,1.81001,8720.18337,0.00000,0.00426,108.77224
36.40000,1.81993,8775.01741,0.00000,0.00429,109.45622
36.60000,1.83004,8830.46463,0.00000,0.00433,110.14785
36.80000,1.84002,8885.66077,0.00000,0.00436,110.83634
37.00000,1.85001,8941.61686,0.00000,0.00439,111.53432
37.20000,1.86005,8997.97902,0.00000,0.00442,112.23736
37.40000,1.87010,9054.06624,0.00000,0.00445,112.93697
37.60000,1.88008,9109.51719,0.00000,0.00449,113.62864
37.80000,1.89007,9166.23697,0.00000,0.00451,114.33614
38.00000,1.89999,9218.29343,0.00000,0.00454,114.98547
38.20000,1.90998,9274.00514,0.00000,0.00457,115.68040
38.40000,1.91996,9330.56921,0.00000,0.00461,116.38596
38.60000,1.92994,9385.61708,0.00000,0.00464,117.07260
38.80000,1.93993,9440.17842,0.00000,0.00467,117.75318
39.00000,1.95003,9495.05270,0.00000,0.00470,118.43766
39.20000,1.95990,9552.02132,0.00000,0.00473,119.14827
39.40000,1.96994,9608.52876,0.00000,0.00476,119.85312
39.60000,1.97987,9662.13569,0.00000,0.00479,120.52179
39.80000,1.98985,9717.99344,0.00000,0.00483,121.21854
40.00000,2.00002,9773.63139,0.00000,0.00486,121.91255
40.20000,2.00994,9828.89161,0.00000,0.00489,122.60184
40.40000,2.01999,9886.00031,0.00000,0.00492,123.31419
40.60000,2.02991,9941.76716,0.00000,0.00495,124.00981
40.80000,2.03990,9999.31172,0.00000,0.00498,124.72760
41.00000,2.05000,10055.38031,0.00000,0.00501,125.42698
41.20000,2.05999,10112.32883,0.00000,0.00505,126.13733
41.40000,2.07003,10169.37122,0.00000,0.00508,126.84885
41.60000,2.08002,10226.15731,0.00000,0.00511,127.55718
41.80000,2.09006,10281.48234,0.00000,0.00514,128.24729
42.00000,2.10005,10337.49804,0.00000,0.00517,128.94600
42.20000,2.11009,10395.94933,0.00000,0.00521,129.67510
42.40000,2.12014,10452.34054,0.00000,0.00523,130.37851
42.60000,2.13000,10509.38591,0.00000,0.00527,131.09007
42.80000,2.13999,10564.99407,0.00000,0.00530,131.78370
43.00000,2.14997,10622.37397,0.00000,0.00533,132.49944
43.20000,2.16001,10678.12070,0.00000,0.00536,133.19480
43.40000,2.17000,10733.36899,0.00000,0.00540,133.88395
43.60000,2.17992,10789.41822,0.00000,0.00542,134.58308
43.80000,2.18997,10846.55821,0.00000,0.00545,135.29583
44.00000,2.19989,10902.63128,0.00000,0.00549,135.99526
44.20000,2.20994,10960.40756,0.00000,0.00553,136.71594
44.40000,2.21992,11017.16161,0.00000,0.00556,137.42387
44.60000,2.22991,11075.41323,0.00000,0.00559,138.15048
44.80000,2.23995,11131.39391,0.00000,0.00562,138.84876
45.00000,2.24994,11188.89228,0.00000,0.00566,139.56597
45.20000,2.25992,11246.71176,0.00000,0.00569,140.28719
45.40000,2.26991,11303.71168,0.00000,0.00573,140.99818
45.60000,2.27995,11362.13765,0.00000,0.00576,141.72697
45.80000,2.28994,11419.55182,0.00000,0.00579,142.44313
46.00000,2.29998,11478.88526,0.00000,0.00583,143.18323
46.20000,2.31003,11536.19215,0.00000,0.00586,143.89806
46.40000,2.32001,11594.44079,0.00000,0.00590,144.62463
46.60000,2.33006,11652.44579,0.00000,0.00593,145.34816
46.80000,2.34004,11707.93399,0.00000,0.00596,146.04030
47.00000,2.35009,11765.23864,0.00000,0.00600,146.75510
47.20000,2.36007,11822.23633,0.00000,0.00603,147.46606
47.40000,2.36994,11879.62964,0.00000,0.00606,148.18197
47.60000,2.38004,11937.12652,0.00000,0.00610,148.89916
47.80000,2.39003,11995.56142,0.00000,0.00613,149.62805
48.00000,2.40001,12052.72526,0.00000,0.00616,150.34109
48.20000,2.40999,12110.07535,0.00000,0.00619,151.05646
48.40000,2.41998,12167.08198,0.00000,0.00623,151.76754
48.60000,2.43002,12224.77108,0.00000,0.00626,152.48713
48.80000,2.43995,12282.66135,0.00000,0.00630,153.20923
49.00000,2.44999,12340.29680,0.00000,0.00633,153.92815
49.20000,2.45998,12399.12808,0.00000,0.00636,154.66199
49.40000,2.46996,12458.06292,0.00000,0.00640,155.39712
49.60000,2.47989,12514.52416,0.00000,0.00643,156.10140
49.80000,2.48993,12574.34934,0.00000,0.00647,156.84763
50.00000,2.49998,12632.79766,0.00000,0.00650,157.57670
50.20000,2.50990,12691.20127,0.00000,0.00653,158.30520
50.40000,2.51995,12748.84343,0.00000,0.00657,159.02421
50.60000,2.52993,12805.75395,0.00000,0.00661,159.73409
50.80000,2.53998,12866.88000,0.00000,0.00664,160.49655
51.00000,2.55002,12924.56836,0.00000,0.00668,161.21613
51.20000,2.56001,12982.32228,0.00000,0.00671,161.93653
51.40000,2.57005,13041.25488,0.00000,0.00675,162.67164
51.60000,2.58004,13097.62001,0.00000,0.00678,163.37471
51.80000,2.59008,13156.92365,0.00000,0.00681,164.11444
52.00000,2.60007,13213.38415,0.00000,0.00684,164.81871
52.20000,2.61005,13271.90697,0.00000,0.00688,165.54870
52.40000,2.62004,13329.20194,0.00000,0.00691,166.26338
52.60000,2.63002,13387.02291,0.00000,0.00695,166.98461
52.80000,2.64000,13443.88425,0.00000,0.00698,167.69388
53.00000,2.64999,13502.66635,0.00000,0.00701,168.42711
53.20000,2.66003,13562.87003,0.00000,0.00705,169.17806
53.40000,2.67002,13621.00542,0.00000,0.00709,169.90322
53.60000,2.68000,13680.57877,0.00000,0.00712,170.64632
53.80000,2.68999,13738.22242,0.00000,0.00715,171.36534
54.00000,2.69985,13796.14472,0.00000,0.00719,172.08784
54.20000,2.70996,13856.41098,0.00000,0.00723,172.83958
54.40000,2.71994,13915.06046,0.00000,0.00726,173.57115
54.60000,2.72987,13973.87683,0.00000,0.00730,174.30481
54.80000,2.73991,14033.04338,0.00000,0.00733,175.04283
55.00000,2.74990,14093.12338,0.00000,0.00737,175.79224
55.20000,2.76000,14153.47457,0.00000,0.00740,176.54504
55.40000,2.76999,14210.97219,0.00000,0.00744,177.26224
55.60000,2.78003,14270.28030,0.00000,0.00748,178.00203
55.80000,2.79008,14328.55427,0.00000,0.00751,178.72892
56.00000,2.80000,14386.12193,0.00000,0.00755,179.44699
56.20000,2.81005,14444.94873,0.00000,0.00758,180.18078
56.40000,2.82003,14503.65633,0.00000,0.00762,180.91307
56.60000,2.83002,14561.41919,0.00000,0.00765,181.63358
56.80000,2.84000,14619.47858,0.00000,0.00769,182.35780
57.00000,2.84993,14678.07293,0.00000,0.00773,183.08868
57.20000,2.86003,14735.75234,0.00000,0.00776,183.80815
57.40000,2.87002,14794.28411,0.00000,0.00780,184.53825
57.60000,2.88006,14852.53721,0.00000,0.00783,185.26488
57.80000,2.88999,14910.77989,0.00000,0.00786,185.99138
58.00000,2.90003,14971.22347,0.00000,0.00790,186.74533
58.20000,2.91001,15028.93418,0.00000,0.00793,187.46519
58.40000,2.91988,15088.52988,0.00000,0.00797,188.20856
58.60000,2.92992,15148.10622,0.00000,0.00801,188.95169
58.80000,2.93991,15206.66629,0.00000,0.00804,189.68215
59.00000,2.94995,15265.61826,0.00000,0.00808,190.41750
59.20000,2.95988,15324.43017,0.00000,0.00811,191.15109
59.40000,2.96992,15384.68897,0.00000,0.00814,191.90274
59.60000,2.97997,15443.56197,0.00000,0.00818,192.63710
59.80000,2.98989,15502.87455,0.00000,0.00822,193.37694
60.00000,3.00000,15561.70583,0.00000,0.00825,194.11078
60.20000,3.00998,15621.37306,0.00000,0.00829,194.85504
60.40000,3.02003,15680.32056,0.00000,0.00833,195.59033
60.60000,3.03001,15738.78974,0.00000,0.00836,196.31966
60.80000,3.04006,15798.46591,0.00000,0.00839,197.06403
61.00000,3.05010,15855.58057,0.00000,0.00843,197.77646
61.20000,3.06009,15914.44463,0.00000,0.00847,198.51071
61.40000,3.07007,15973.54710,0.00000,0.00851,199.24793
61.60000,3.07994,16031.25930,0.00000,0.00854,199.96781
61.80000,3.08998,16091.47936,0.00000,0.00858,200.71897
62.00000,3.10009,16152.14646,0.00000,0.00861,201.47571
62.20000,3.11001,16210.83021,0.00000,0.00865,202.20771
62.40000,3.12005,16270.17260,0.00000,0.00869,202.94792
62.60000,3.12998,16330.23769,0.00000,0.00872,203.69715
62.80000,3.14002,16389.03469,0.00000,0.00876,204.43056
63.00000,3.15001,16446.16723,0.00000,0.00880,205.14321
63.20000,3.15993,16507.05934,0.00000,0.00884,205.90276
63.40000,3.16992,16565.75054,0.00000,0.00887,206.63485
63.60000,3.17984,16626.59049,0.00000,0.00891,207.39374
63.80000,3.18989,16686.65707,0.00000,0.00895,208.14299
64.00000,3.19987,16745.19479,0.00000,0.00898,208.87317
64.20000,3.20998,16805.27627,0.00000,0.00902,209.62260
64.40000,3.21990,16863.52044,0.00000,0.00906,210.34912
64.60000,3.22989,16923.29794,0.00000,0.00909,211.09476
64.80000,3.23999,16983.41221,0.00000,0.00913,211.84460
65.00000,3.24992,17041.28534,0.00000,0.00916,212.56649
65.20000,3.26002,17101.01813,0.00000,0.00920,213.31157
65.40000,3.27001,17160.09676,0.00000,0.00924,214.04850
65.60000,3.28005,17220.10672,0.00000,0.00927,214.79704
65.80000,3.29010,17278.79643,0.00000,0.00931,215.52911
66.00000,3.30002,17337.20154,0.00000,0.00935,216.25763
66.20000,3.31013,17395.42335,0.00000,0.00938,216.98387
66.40000,3.31999,17454.71060,0.00000,0.00942,217.72340
66.60000,3.33004,17513.96805,0.00000,0.00945,218.46255
66.80000,3.34002,17572.01552,0.00000,0.00949,219.18661
67.00000,3.35001,17632.09403,0.00000,0.00953,219.93601
67.20000,3.36005,17691.00726,0.00000,0.00956,220.67087
67.40000,3.36997,17749.25292,0.00000,0.00960,221.39741
67.60000,3.38002,17810.00346,0.00000,0.00964,222.15519
67.80000,3.38994,17868.40707,0.00000,0.00968,222.88369
68.00000,3.39987,17926.66018,0.00000,0.00972,223.61032
68.20000,3.40991,17985.94743,0.00000,0.00975,224.34984
68.40000,3.41990,18045.35985,0.00000,0.00978,225.09093
68.60000,3.42994,18104.66051,0.00000,0.00982,225.83062
68.80000,3.43987,18162.89872,0.00000,0.00986,226.55707
69.00000,3.44991,18222.85354,0.00000,0.00990,227.30492
69.20000,3.45990,18282.65041,0.00000,0.00994,228.05080
69.40000,3.46988,18340.93630,0.00000,0.00997,228.77784
69.60000,3.47999,18399.78397,0.00000,0.01001,229.51188
69.80000,3.48997,18458.99671,0.00000,0.01005,230.25048
70.00000,3.50008,18516.34234,0.00000,0.01008,230.96579
70.20000,3.51000,18574.56118,0.00000,0.01012,231.69199
70.40000,3.52005,18634.34613,0.00000,0.01016,232.43772
70.60000,3.53015,18693.44562,0.00000,0.01020,233.17491
70.80000,3.54008,18752.98768,0.00000,0.01023,233.91761
71.00000,3.55012,18811.60736,0.00000,0.01027,234.64881
71.20000,3.56005,18871.30886,0.00000,0.01031,235.39350
71.40000,3.57003,18930.22060,0.00000,0.01034,236.12835
71.60000,3.58007,18987.99837,0.00000,0.01038,236.84904
71.80000,3.59000,19048.57010,0.00000,0.01042,237.60459
72.00000,3.60004,19106.61757,0.00000,0.01045,238.32865
72.20000,3.60991,19164.55328,0.00000,0.01049,239.05132
72.40000,3.61995,19223.14465,0.00000,0.01053,239.78217
72.60000,3.62988,19282.69267,0.00000,0.01056,240.52495
72.80000,3.63992,19341.57163,0.00000,0.01061,241.25938
73.00000,3.64991,19399.66530,0.00000,0.01065,241.98402
73.20000,3.65983,19458.18663,0.00000,0.01068,242.71399
73.40000,3.66994,19516.87038,0.00000,0.01072,243.44599
73.60000,3.67986,19574.03719,0.00000,0.01076,244.15907
73.80000,3.68991,19633.37660,0.00000,0.01079,244.89925
74.00000,3.69995,19692.53123,0.00000,0.01083,245.63712
74.20000,3.70994,19751.83338,0.00000,0.01087,246.37683
74.40000,3.72010,19810.35173,0.00000,0.01091,247.10677
74.60000,3.72997,19867.79571,0.00000,0.01094,247.82330
74.80000,3.74007,19927.99640,0.00000,0.01099,248.57422
75.00000,3.75006,19984.21550,0.00000,0.01102,249.27548
75.20000,3.76010,20043.92147,0.00000,0.01106,250.02023
75.40000,3.77015,20101.26263,0.00000,0.01110,250.73548
75.60000,3.78007,20158.95993,0.00000,0.01113,251.45517
75.80000,3.79012,20217.25178,0.00000,0.01117,252.18228
76.00000,3.79998,20275.85208,0.00000,0.01120,252.91324
76.20000,3.81009,20335.66087,0.00000,0.01124,253.65927
76.40000,3.82001,20392.68315,0.00000,0.01128,254.37055
76.60000,3.83006,20451.02865,0.00000,0.01131,255.09833
76.80000,3.84004,20508.79598,0.00000,0.01135,255.81889
77.00000,3.84991,20565.69755,0.00000,0.01139,256.52866
77.20000,3.86001,20623.03126,0.00000,0.01143,257.24382
77.40000,3.86987,20679.82852,0.00000,0.01146,257.95229
77.60000,3.87992,20739.84444,0.00000,0.01150,258.70090
77.80000,3.88990,20796.69088,0.00000,0.01154,259.40998
78.00000,3.89983,20854.59232,0.00000,0.01158,260.13222
78.20000,3.90999,20914.26849,0.00000,0.01162,260.87660
78.40000,3.91992,20970.95996,0.00000,0.01165,261.58375
78.60000,3.92996,21027.97031,0.00000,0.01169,262.29488
78.80000,3.93995,21086.24727,0.00000,0.01173,263.02180
79.00000,3.94999,21145.09791,0.00000,0.01177,263.75588
79.20000,3.96004,21202.60447,0.00000,0.01181,264.47320
79.40000,3.97002,21261.23160,0.00000,0.01184,265.20449
79.60000,3.98013,21320.15675,0.00000,0.01188,265.93950
79.80000,3.98999,21377.76166,0.00000,0.01192,266.65804
80.00000,4.00010,21437.20388,0.00000,0.01196,267.39950
80.20000,4.01014,21495.75651,0.00000,0.01199,268.12986
80.40000,4.02013,21554.56841,0.00000,0.01204,268.86346
80.60000,4.03011,21610.86202,0.00000,0.01207,269.56564
80.80000,4.03998,21667.38510,0.00000,0.01211,270.27069
81.00000,4.05008,21726.04352,0.00000,0.01215,271.00237
81.20000,4.06001,21782.86016,0.00000,0.01218,271.71108
81.40000,4.06999,21839.97929,0.00000,0.01223,272.42357
81.60000,4.08003,21897.66020,0.00000,0.01226,273.14305
81.80000,4.08990,21955.10417,0.00000,0.01229,273.85959
82.00000,4.10000,22013.44818,0.00000,0.01233,274.58735
82.20000,4.10981,22066.79285,0.00000,0.01237,275.25275
82.40000,4.11985,22126.26338,0.00000,0.01241,275.99456
82.60000,4.12990,22184.05902,0.00000,0.01245,276.71548
82.80000,4.13988,22242.02305,0.00000,0.01249,277.43851
83.00000,4.14993,22300.90648,0.00000,0.01252,278.17300
83.20000,4.15991,22357.96303,0.00000,0.01256,278.88470
83.40000,4.16996,22416.23253,0.00000,0.01260,279.61153
83.60000,4.17988,22474.09970,0.00000,0.01264,280.33334
83.80000,4.18999,22533.27966,0.00000,0.01268,281.07153
84.00000,4.20003,22590.84582,0.00000,0.01272,281.78959
84.20000,4.20996,22647.37934,0.00000,0.01275,282.49477
84.40000,4.22006,22705.20031,0.00000,0.01279,283.21600
84.60000,4.22999,22762.99149,0.00000,0.01284,283.93687
84.80000,4.24009,22820.84674,0.00000,0.01287,284.65853
85.00000,4.25008,22878.63046,0.00000,0.01291,285.37930
85.20000,4.26006,22935.55737,0.00000,0.01295,286.08939
85.40000,4.27011,22994.02207,0.00000,0.01299,286.81865
85.60000,4.27997,23049.79116,0.00000,0.01302,287.51430
85.80000,4.29008,23107.75667,0.00000,0.01306,288.23734
86.00000,4.30006,23162.18466,0.00000,0.01310,288.91625
86.20000,4.31005,23219.94454,0.00000,0.01313,289.63673
86.40000,4.32003,23273.64683,0.00000,0.01317,290.30659
86.60000,4.32990,23331.42459,0.00000,0.01321,291.02728
86.80000,4.34000,23388.51839,0.00000,0.01325,291.73945
87.00000,4.34986,23444.05055,0.00000,0.01329,292.43214
87.20000,4.35997,23500.61238,0.00000,0.01333,293.13767
87.40000,4.36983,23556.18477,0.00000,0.01336,293.83086
87.60000,4.37994,23617.16181,0.00000,0.01340,294.59146
87.80000,4.38992,23671.99510,0.00000,0.01344,295.27543
88.00000,4.39985,23727.32460,0.00000,0.01348,295.96559
88.20000,4.41001,23786.23188,0.00000,0.01351,296.70038
88.40000,4.41994,23841.38554,0.00000,0.01355,297.38834
88.60000,4.42998,23899.06794,0.00000,0.01359,298.10785
88.80000,4.44003,23956.34055,0.00000,0.01363,298.82225
89.00000,4.44995,24012.13050,0.00000,0.01367,299.51815
89.20000,4.46012,24068.61335,0.00000,0.01371,300.22270
89.40000,4.46998,24122.55257,0.00000,0.01374,300.89551
89.60000,4.48009,24179.31408,0.00000,0.01378,301.60353
89.80000,4.49007,24234.73746,0.00000,0.01382,302.29486
90.00000,4.50006,24291.81337,0.00000,0.01386,303.00681
90.20000,4.51010,24345.04181,0.00000,0.01390,303.67076
90.40000,4.52003,24400.88391,0.00000,0.01393,304.36731
90.60000,4.53007,24457.47703,0.00000,0.01397,305.07323
90.80000,4.54000,24511.33728,0.00000,0.01401,305.74507
91.00000,4.54998,24566.56545,0.00000,0.01405,306.43396
91.20000,4.55996,24619.92502,0.00000,0.01409,307.09955
91.40000,4.56989,24673.91193,0.00000,0.01412,307.77296
91.60000,4.57999,24729.05368,0.00000,0.01416,308.46078
91.80000,4.58980,24783.00482,0.00000,0.01420,309.13374
92.00000,4.59996,24840.15077,0.00000,0.01424,309.84656
92.20000,4.60989,24893.42541,0.00000,0.01428,310.51109
92.40000,4.61987,24948.09628,0.00000,0.01431,311.19303
92.60000,4.62998,25002.79844,0.00000,0.01435,311.87536
92.80000,4.63996,25058.96986,0.00000,0.01438,312.57602
93.00000,4.65001,25113.44254,0.00000,0.01442,313.25550
93.20000,4.65987,25166.07344,0.00000,0.01446,313.91199
93.40000,4.66998,25221.44318,0.00000,0.01450,314.60266
93.60000,4.67996,25275.92182,0.00000,0.01453,315.28220
93.80000,4.69001,25330.01304,0.00000,0.01457,315.95691
94.00000,4.70005,25384.62877,0.00000,0.01461,316.63817
94.20000,4.70998,25433.48074,0.00000,0.01464,317.24753
94.40000,4.72008,25447.58022,0.00000,0.01464,317.42340
94.43000,4.72158,24494.24863,0.00000,0.01446,305.53191
94.43400,4.72205,22552.14900,0.00000,0.01438,281.30690
94.43800,4.72265,20003.28451,0.00000,0.01441,249.51334
94.44200,4.72355,17156.38936,0.00000,0.01426,214.00225
94.44600,4.72433,14256.77985,0.00000,0.01374,177.83363