File: scratch/college-stuff/ME Lab/ME lab Fall 2013/group12/group12.is_tens_RawData/Specimen_RawData_4.csv
Time,Extension,Load,Strain 2,Tensile strain,Tensile stress
(sec),(mm),(N),(mm/mm),(mm/mm),(MPa)
0.00000,0.00000,-0.39900,0.00000,0.00000,-0.00498
0.40000,0.01937,32.33058,0.00000,0.00000,0.40328
0.80000,0.04006,63.93294,0.00000,0.00001,0.79748
1.20000,0.06003,99.74886,0.00000,0.00001,1.24423
1.60000,0.07994,134.64523,0.00000,0.00000,1.67951
2.00000,0.09991,175.84474,0.00000,0.00000,2.19342
2.40000,0.11988,218.25098,0.00000,-0.00001,2.72238
2.80000,0.13997,274.48914,0.00000,-0.00002,3.42387
3.20000,0.16000,344.36029,0.00000,-0.00002,4.29542
3.60000,0.18009,431.83211,0.00000,-0.00002,5.38651
4.00000,0.20006,534.10497,0.00000,-0.00002,6.66222
4.40000,0.22009,659.02085,0.00000,-0.00002,8.22037
4.80000,0.24000,809.80510,0.00000,-0.00001,10.10120
5.20000,0.26002,976.61316,0.00000,0.00000,12.18190
5.60000,0.28005,1166.86262,0.00000,0.00002,14.55500
6.00000,0.29996,1387.28786,0.00000,0.00004,17.30450
6.40000,0.31987,1623.04845,0.00000,0.00007,20.24529
6.80000,0.33984,1867.86372,0.00000,0.00010,23.29902
7.20000,0.35993,2116.11185,0.00000,0.00014,26.39557
7.60000,0.37990,2365.11640,0.00000,0.00019,29.50156
8.00000,0.39999,2598.53899,0.00000,0.00031,32.41318
8.40000,0.42008,2842.12325,0.00000,0.00039,35.45156
8.80000,0.44005,3085.08314,0.00000,0.00046,38.48215
9.20000,0.46002,3322.17030,0.00000,0.00053,41.43948
9.60000,0.47999,3550.01278,0.00000,0.00058,44.28150
10.00000,0.49996,3764.19909,0.00000,0.00064,46.95318
10.40000,0.52005,3968.06076,0.00000,0.00067,49.49608
10.80000,0.53996,4168.99063,0.00000,0.00070,52.00240
11.20000,0.55987,4368.36556,0.00000,0.00073,54.48932
11.60000,0.57990,4570.70768,0.00000,0.00077,57.01326
12.00000,0.59981,4773.33367,0.00000,0.00080,59.54074
12.40000,0.61990,4976.83957,0.00000,0.00083,62.07920
12.80000,0.63999,5182.09115,0.00000,0.00087,64.63943
13.20000,0.66008,5385.65703,0.00000,0.00090,67.17863
13.60000,0.68011,5590.99838,0.00000,0.00094,69.73998
14.00000,0.70008,5794.26065,0.00000,0.00097,72.27540
14.40000,0.72004,6001.54586,0.00000,0.00100,74.86099
14.80000,0.74001,6206.41671,0.00000,0.00104,77.41647
15.20000,0.75998,6408.92088,0.00000,0.00107,79.94243
15.60000,0.77989,6613.83346,0.00000,0.00111,82.49843
16.00000,0.79998,6819.78986,0.00000,0.00114,85.06746
16.40000,0.81989,7022.10814,0.00000,0.00117,87.59110
16.80000,0.83986,7218.44733,0.00000,0.00121,90.04016
17.20000,0.85995,7414.38568,0.00000,0.00124,92.48422
17.60000,0.88004,7601.39301,0.00000,0.00127,94.81687
18.00000,0.90013,7782.62317,0.00000,0.00130,97.07747
18.40000,0.92010,7964.16029,0.00000,0.00133,99.34190
18.80000,0.94001,8148.40123,0.00000,0.00136,101.64005
19.20000,0.95998,8333.71729,0.00000,0.00140,103.95161
19.60000,0.98001,8519.26282,0.00000,0.00143,106.26603
20.00000,0.99998,8705.02964,0.00000,0.00146,108.58322
20.40000,1.01995,8892.17257,0.00000,0.00149,110.91757
20.80000,1.03992,9080.75944,0.00000,0.00152,113.26993
21.20000,1.05989,9273.04998,0.00000,0.00156,115.66849
21.60000,1.07992,9465.05517,0.00000,0.00159,118.06349
22.00000,1.09995,9656.31828,0.00000,0.00162,120.44923
22.40000,1.12004,9848.58498,0.00000,0.00166,122.84749
22.80000,1.14007,10040.64828,0.00000,0.00169,125.24321
23.20000,1.16010,10235.23584,0.00000,0.00173,127.67043
23.60000,1.18012,10431.43645,0.00000,0.00176,130.11776
24.00000,1.20003,10626.50383,0.00000,0.00180,132.55095
24.40000,1.21994,10822.36767,0.00000,0.00183,134.99408
24.80000,1.23997,11018.57126,0.00000,0.00187,137.44145
25.20000,1.25994,11216.78650,0.00000,0.00190,139.91391
25.60000,1.27991,11413.24118,0.00000,0.00194,142.36441
26.00000,1.29988,11616.60030,0.00000,0.00198,144.90104
26.40000,1.31991,11818.64291,0.00000,0.00202,147.42124
26.80000,1.34000,12022.39022,0.00000,0.00205,149.96271
27.20000,1.35997,12219.24275,0.00000,0.00209,152.41817
27.60000,1.38006,12420.99628,0.00000,0.00213,154.93477
28.00000,1.40009,12625.76878,0.00000,0.00216,157.48902
28.40000,1.42006,12828.64213,0.00000,0.00220,160.01959
28.80000,1.44003,13030.18630,0.00000,0.00224,162.53357
29.20000,1.46000,13234.20405,0.00000,0.00228,165.07841
29.60000,1.47991,13437.06548,0.00000,0.00231,167.60883
30.00000,1.49988,13642.81476,0.00000,0.00235,170.17526
30.40000,1.51997,13847.72211,0.00000,0.00239,172.73120
30.80000,1.53994,14052.41340,0.00000,0.00243,175.28444
31.20000,1.55991,14258.91668,0.00000,0.00247,177.86028
31.60000,1.57994,14465.44081,0.00000,0.00250,180.43639
32.00000,1.59997,14673.36863,0.00000,0.00254,183.03000
32.40000,1.62012,14879.29970,0.00000,0.00258,185.59870
32.80000,1.64009,15086.64340,0.00000,0.00262,188.18503
33.20000,1.66000,15293.93792,0.00000,0.00266,190.77074
33.60000,1.68003,15502.66594,0.00000,0.00271,193.37434
34.00000,1.69993,15709.15133,0.00000,0.00274,195.94996
34.40000,1.71990,15915.07196,0.00000,0.00279,198.51853
34.80000,1.73981,16120.60517,0.00000,0.00283,201.08228
35.20000,1.75990,16331.41637,0.00000,0.00287,203.71185
35.60000,1.77993,16541.23515,0.00000,0.00291,206.32905
36.00000,1.79996,16749.94379,0.00000,0.00295,208.93241
36.40000,1.81993,16959.98311,0.00000,0.00300,211.55236
36.80000,1.83996,17171.74649,0.00000,0.00305,214.19381
37.20000,1.86005,17382.09575,0.00000,0.00309,216.81763
37.60000,1.88008,17590.68668,0.00000,0.00313,219.41951
38.00000,1.90005,17800.11207,0.00000,0.00318,222.03180
38.40000,1.91996,18009.26179,0.00000,0.00322,224.64066
38.80000,1.93993,18217.26859,0.00000,0.00327,227.23525
39.20000,1.95990,18425.09359,0.00000,0.00331,229.82758
39.60000,1.97987,18630.58954,0.00000,0.00336,232.39086
40.00000,1.99996,18841.08037,0.00000,0.00341,235.01644
40.40000,2.01999,19050.91703,0.00000,0.00346,237.63387
40.80000,2.03996,19257.75409,0.00000,0.00350,240.21387
41.20000,2.05999,19464.16199,0.00000,0.00355,242.78853
41.60000,2.07996,19669.69073,0.00000,0.00360,245.35221
42.00000,2.09999,19871.44649,0.00000,0.00366,247.86884
42.40000,2.12008,20074.56869,0.00000,0.00371,250.40251
42.80000,2.14005,20271.82579,0.00000,0.00376,252.86302
43.20000,2.16007,20470.10660,0.00000,0.00382,255.33630
43.60000,2.17992,20660.05319,0.00000,0.00387,257.70562
44.00000,2.19989,20851.83114,0.00000,0.00393,260.09778
44.40000,2.21986,21038.88392,0.00000,0.00399,262.43101
44.80000,2.23995,21222.22632,0.00000,0.00405,264.71795
45.20000,2.25992,21402.27258,0.00000,0.00412,266.96378
45.60000,2.28001,21578.31788,0.00000,0.00419,269.15970
46.00000,2.29998,21746.11986,0.00000,0.00426,271.25280
46.40000,2.31995,21905.63679,0.00000,0.00434,273.24255
46.80000,2.33998,22054.20285,0.00000,0.00442,275.09571
47.20000,2.36001,22194.82511,0.00000,0.00450,276.84978
47.60000,2.38004,22328.73738,0.00000,0.00459,278.52015
48.00000,2.40001,22449.05382,0.00000,0.00470,280.02093
48.40000,2.41998,22557.24818,0.00000,0.00480,281.37050
48.80000,2.43995,22657.74906,0.00000,0.00493,282.62411
49.20000,2.45998,22746.59872,0.00000,0.00505,283.73239
49.60000,2.47989,22824.70018,0.00000,0.00519,284.70660
50.00000,2.49998,22896.82478,0.00000,0.00533,285.60625
50.40000,2.52001,22960.09511,0.00000,0.00548,286.39546
50.80000,2.53998,23019.77575,0.00000,0.00563,287.13990
51.20000,2.56001,23068.05849,0.00000,0.00580,287.74216
51.60000,2.58004,23110.98874,0.00000,0.00597,288.27765
52.00000,2.60007,23151.08478,0.00000,0.00615,288.77779
52.40000,2.62004,23187.21116,0.00000,0.00633,289.22842
52.80000,2.64006,23220.43628,0.00000,0.00651,289.64286
53.20000,2.66003,23251.91051,0.00000,0.00670,290.03546
53.60000,2.68006,23278.85628,0.00000,0.00689,290.37157
54.00000,2.69985,23302.48356,0.00000,0.00708,290.66629
54.40000,2.71994,23326.72477,0.00000,0.00728,290.96866
54.80000,2.73997,23350.40569,0.00000,0.00748,291.26405
55.20000,2.76000,23371.50872,0.00000,0.00769,291.52728
55.60000,2.77997,23390.47492,0.00000,0.00789,291.76386
56.00000,2.80000,23407.99570,0.00000,0.00809,291.98240
56.40000,2.82003,23424.83699,0.00000,0.00831,292.19248
56.80000,2.84000,23439.89164,0.00000,0.00851,292.38026
57.20000,2.86003,23456.19947,0.00000,0.00872,292.58368
57.60000,2.88006,23470.20507,0.00000,0.00893,292.75838
58.00000,2.90003,23484.95275,0.00000,0.00914,292.94234
58.40000,2.91994,23498.16710,0.00000,0.00936,293.10717
58.80000,2.93991,23510.40840,0.00000,0.00957,293.25986
59.20000,2.95994,23521.17896,0.00000,0.00978,293.39421
59.60000,2.97997,23535.28887,0.00000,0.01000,293.57021
60.00000,3.00000,23548.47044,0.00000,0.01022,293.73463
60.40000,3.02003,23561.94109,0.00000,0.01043,293.90266
60.80000,3.04006,23571.87569,0.00000,0.01065,294.02658
61.20000,3.06009,23582.61794,0.00000,0.01086,294.16057
61.60000,3.07994,23591.02070,0.00000,0.01108,294.26539
62.00000,3.10009,23603.64199,0.00000,0.01130,294.42282
62.40000,3.12011,23613.79117,0.00000,0.01152,294.54942
62.80000,3.14002,23622.81829,0.00000,0.01174,294.66202
63.20000,3.15999,23633.05390,0.00000,0.01196,294.78969
63.60000,3.17984,23641.27338,0.00000,0.01218,294.89222
64.00000,3.19987,23649.22315,0.00000,0.01240,294.99138
64.40000,3.21990,23659.64204,0.00000,0.01262,295.12134
64.80000,3.24005,23672.31548,0.00000,0.01283,295.27943
65.20000,3.26008,23684.03077,0.00000,0.01305,295.42556
65.60000,3.28011,23693.20989,0.00000,0.01327,295.54006
66.00000,3.30002,23701.01810,0.00000,0.01349,295.63745
66.40000,3.31999,23709.08558,0.00000,0.01370,295.73808
66.80000,3.34008,23718.45096,0.00000,0.01392,295.85490
67.20000,3.36011,23728.32596,0.00000,0.01413,295.97808
67.60000,3.38008,23735.43829,0.00000,0.01436,296.06680
68.00000,3.39993,23743.07662,0.00000,0.01457,296.16207
68.40000,3.41990,23753.24517,0.00000,0.01479,296.28891
68.80000,3.43981,23761.39760,0.00000,0.01500,296.39060
69.20000,3.45990,23771.14743,0.00000,0.01521,296.51222
69.60000,3.48005,23782.12512,0.00000,0.01543,296.64915
70.00000,3.50008,23790.91531,0.00000,0.01564,296.75880
70.40000,3.52005,23800.54742,0.00000,0.01585,296.87894
70.80000,3.54008,23809.80104,0.00000,0.01607,296.99437
71.20000,3.56005,23817.46024,0.00000,0.01628,297.08991
71.60000,3.58007,23824.82141,0.00000,0.01650,297.18173
72.00000,3.60010,23833.81277,0.00000,0.01671,297.29388
72.40000,3.62001,23841.20971,0.00000,0.01692,297.38615
72.80000,3.63992,23849.39790,0.00000,0.01713,297.48829
73.20000,3.65983,23855.84265,0.00000,0.01734,297.56868
73.60000,3.67986,23864.65669,0.00000,0.01756,297.67862
74.00000,3.69995,23874.90571,0.00000,0.01776,297.80646
74.40000,3.72010,23886.95180,0.00000,0.01797,297.95672
74.80000,3.74013,23895.04910,0.00000,0.01818,298.05772
75.20000,3.76016,23903.09870,0.00000,0.01839,298.15813
75.60000,3.78007,23910.50458,0.00000,0.01860,298.25051
76.00000,3.79998,23918.14142,0.00000,0.01881,298.34577
76.40000,3.82007,23926.13888,0.00000,0.01902,298.44552
76.80000,3.84010,23933.16329,0.00000,0.01923,298.53314
77.20000,3.86007,23940.96702,0.00000,0.01943,298.63048
77.60000,3.87992,23949.31614,0.00000,0.01964,298.73463
78.00000,3.89983,23956.02465,0.00000,0.01984,298.81831
78.40000,3.91992,23964.54811,0.00000,0.02005,298.92463
78.80000,3.93995,23972.89425,0.00000,0.02026,299.02873
79.20000,3.96004,23983.49345,0.00000,0.02046,299.16094
79.60000,3.98013,23993.38484,0.00000,0.02067,299.28432
80.00000,4.00016,24000.68641,0.00000,0.02088,299.37540
80.40000,4.02013,24008.74346,0.00000,0.02108,299.47590
80.80000,4.04004,24013.95738,0.00000,0.02128,299.54094
81.20000,4.06001,24021.78347,0.00000,0.02148,299.63856
81.60000,4.08003,24029.93292,0.00000,0.02169,299.74021
82.00000,4.10006,24037.32091,0.00000,0.02189,299.83237
82.40000,4.11991,24043.85805,0.00000,0.02209,299.91391
82.80000,4.13988,24052.87474,0.00000,0.02229,300.02638
83.20000,4.15991,24062.44576,0.00000,0.02249,300.14576
83.60000,4.17994,24070.51176,0.00000,0.02270,300.24638
84.00000,4.20009,24079.93376,0.00000,0.02290,300.36390
84.40000,4.22006,24087.64809,0.00000,0.02310,300.46013
84.80000,4.24009,24096.29524,0.00000,0.02330,300.56799
85.20000,4.26006,24103.72794,0.00000,0.02350,300.66070
85.60000,4.27997,24110.40366,0.00000,0.02371,300.74397
86.00000,4.30006,24117.89894,0.00000,0.02390,300.83747
86.40000,4.32003,24122.67327,0.00000,0.02411,300.89702
86.80000,4.34000,24130.34141,0.00000,0.02430,300.99267
87.20000,4.35997,24140.07038,0.00000,0.02450,301.11402
87.60000,4.37994,24148.62067,0.00000,0.02471,301.22068
88.00000,4.39985,24155.65848,0.00000,0.02490,301.30846
88.40000,4.41994,24162.06300,0.00000,0.02510,301.38835
88.80000,4.44003,24172.53256,0.00000,0.02530,301.51894
89.20000,4.46012,24180.92042,0.00000,0.02550,301.62357
89.60000,4.48009,24186.04642,0.00000,0.02570,301.68751
90.00000,4.50006,24194.38064,0.00000,0.02590,301.79147
90.40000,4.52003,24200.74493,0.00000,0.02609,301.87085
90.80000,4.54000,24206.19726,0.00000,0.02629,301.93887
91.20000,4.55996,24210.90752,0.00000,0.02648,301.99762
91.60000,4.57999,24220.36529,0.00000,0.02668,302.11559
92.00000,4.59996,24227.66685,0.00000,0.02688,302.20667
92.40000,4.61987,24236.10985,0.00000,0.02708,302.31198
92.80000,4.63996,24243.16108,0.00000,0.02727,302.39994
93.20000,4.65987,24248.34222,0.00000,0.02746,302.46457
93.60000,4.68002,24258.48991,0.00000,0.02766,302.59114
94.00000,4.70005,24266.72131,0.00000,0.02786,302.69382
94.40000,4.72008,24273.87685,0.00000,0.02805,302.78307
94.80000,4.74005,24279.76280,0.00000,0.02825,302.85649
95.20000,4.76002,24285.49528,0.00000,0.02844,302.92800
95.60000,4.77993,24290.74049,0.00000,0.02863,302.99343
96.00000,4.79996,24297.49072,0.00000,0.02883,303.07762
96.40000,4.81999,24305.20952,0.00000,0.02902,303.17391
96.80000,4.83996,24313.42453,0.00000,0.02921,303.27638
97.20000,4.85999,24321.39814,0.00000,0.02940,303.37584
97.60000,4.87990,24328.90087,0.00000,0.02960,303.46942
98.00000,4.89993,24335.29496,0.00000,0.02979,303.54918
98.40000,4.92002,24340.84266,0.00000,0.02999,303.61838
98.80000,4.94005,24349.62690,0.00000,0.03018,303.72795
99.20000,4.96020,24360.19033,0.00000,0.03037,303.85972
99.60000,4.98005,24363.63697,0.00000,0.03056,303.90271
100.00000,4.99996,24369.26663,0.00000,0.03075,303.97293
100.40000,5.01999,24373.71165,0.00000,0.03094,304.02838
100.80000,5.03996,24379.86434,0.00000,0.03113,304.10512
101.20000,5.05998,24387.71725,0.00000,0.03132,304.20308
101.60000,5.08001,24393.99958,0.00000,0.03151,304.28144
102.00000,5.09992,24399.08236,0.00000,0.03170,304.34484
102.40000,5.11995,24407.28396,0.00000,0.03189,304.44714
102.80000,5.13986,24414.10422,0.00000,0.03209,304.53222
103.20000,5.15995,24422.16575,0.00000,0.03227,304.63277
103.60000,5.18010,24426.96542,0.00000,0.03246,304.69264
104.00000,5.20013,24432.98846,0.00000,0.03265,304.76777
104.40000,5.21998,24438.43484,0.00000,0.03283,304.83571
104.80000,5.24001,24446.38610,0.00000,0.03303,304.93489
105.20000,5.25998,24450.91158,0.00000,0.03321,304.99134
105.60001,5.27995,24456.26408,0.00000,0.03339,305.05810
106.00001,5.30004,24463.63568,0.00000,0.03358,305.15005
106.40001,5.31995,24468.40554,0.00000,0.03377,305.20955
106.80001,5.33998,24477.02140,0.00000,0.03396,305.31702
107.20001,5.35989,24481.00895,0.00000,0.03415,305.36676
107.60001,5.37998,24487.85007,0.00000,0.03433,305.45209
108.00001,5.40001,24494.52281,0.00000,0.03451,305.53533
108.40001,5.42016,24501.72305,0.00000,0.03469,305.62514
108.80001,5.44013,24507.23648,0.00000,0.03488,305.69391
109.20001,5.46010,24512.58302,0.00000,0.03506,305.76060
109.60001,5.48001,24518.92644,0.00000,0.03525,305.83973
110.00001,5.49998,24524.65892,0.00000,0.03543,305.91123
110.40001,5.51994,24527.82243,0.00000,0.03561,305.95069
110.80001,5.54003,24532.80240,0.00000,0.03579,306.01281
111.20001,5.56006,24540.27385,0.00000,0.03598,306.10601
111.60001,5.57997,24547.52177,0.00000,0.03616,306.19642
112.00001,5.59994,24553.10971,0.00000,0.03634,306.26612
112.40001,5.61991,24558.25806,0.00000,0.03653,306.33034
112.80001,5.64000,24563.01749,0.00000,0.03670,306.38970
113.20001,5.66003,24569.13590,0.00000,0.03689,306.46602
113.60001,5.68012,24576.93964,0.00000,0.03707,306.56336
114.00001,5.70003,24581.04938,0.00000,0.03725,306.61463
114.40001,5.72000,24585.74772,0.00000,0.03743,306.67323
114.80001,5.73997,24590.77537,0.00000,0.03760,306.73595
115.20001,5.75988,24593.24300,0.00000,0.03778,306.76673
115.60001,5.77997,24599.86508,0.00000,0.03796,306.84933
116.00001,5.79994,24603.04201,0.00000,0.03814,306.88895
116.40001,5.81997,24610.54325,0.00000,0.03832,306.98252
116.80001,5.83994,24616.38302,0.00000,0.03849,307.05537
117.20001,5.85997,24623.90214,0.00000,0.03867,307.14916
117.60001,5.88000,24627.39199,0.00000,0.03885,307.19269
118.00001,5.90009,24633.45826,0.00000,0.03902,307.26836
118.40001,5.92006,24637.08520,0.00000,0.03920,307.31360
118.80001,5.94009,24644.26160,0.00000,0.03938,307.40311
119.20001,5.96000,24649.20431,0.00000,0.03955,307.46477
119.60001,5.98003,24653.36174,0.00000,0.03973,307.51662
120.00001,5.99994,24655.03067,0.00000,0.03990,307.53744
120.40001,6.01990,24660.53367,0.00000,0.04007,307.60608
120.80001,6.03993,24665.93683,0.00000,0.04025,307.67348
121.20001,6.05996,24670.79610,0.00000,0.04043,307.73409
121.60001,6.07993,24676.50175,0.00000,0.04060,307.80526
122.00001,6.09996,24683.77948,0.00000,0.04077,307.89604
122.40001,6.11999,24689.02618,0.00000,0.04094,307.96149
122.80001,6.14002,24692.21503,0.00000,0.04111,308.00127
123.20001,6.16011,24697.85064,0.00000,0.04129,308.07156
123.60001,6.18008,24701.43437,0.00000,0.04146,308.11626
124.00001,6.20005,24707.15642,0.00000,0.04163,308.18764
124.40001,6.22002,24709.74326,0.00000,0.04180,308.21991
124.80001,6.23993,24713.70250,0.00000,0.04197,308.26929
125.20001,6.25990,24714.93632,0.00000,0.04214,308.28468
125.60001,6.27993,24720.10255,0.00000,0.04231,308.34912
126.00001,6.29996,24726.98987,0.00000,0.04248,308.43503
126.40001,6.31993,24732.17994,0.00000,0.04264,308.49977
126.80001,6.34002,24738.57552,0.00000,0.04281,308.57955
127.20001,6.35999,24741.12213,0.00000,0.04297,308.61131
127.60001,6.38008,24745.15140,0.00000,0.04314,308.66157
128.00001,6.40017,24751.84798,0.00000,0.04331,308.74510
128.40001,6.42014,24755.58668,0.00000,0.04348,308.79174
128.80001,6.44005,24758.44622,0.00000,0.04365,308.82741
129.20001,6.46002,24761.60228,0.00000,0.04381,308.86678
129.60001,6.47987,24765.38271,0.00000,0.04398,308.91393
130.00001,6.49990,24768.58944,0.00000,0.04414,308.95393
130.40001,6.51992,24773.03296,0.00000,0.04431,309.00936
130.80001,6.54001,24779.75339,0.00000,0.04447,309.09319
131.20001,6.55998,24786.21602,0.00000,0.04464,309.17380
131.60001,6.57995,24790.50010,0.00000,0.04480,309.22724
132.00001,6.60004,24794.41613,0.00000,0.04497,309.27608
132.40001,6.62007,24795.52329,0.00000,0.04513,309.28989
132.80001,6.64010,24800.89515,0.00000,0.04530,309.35690
133.20001,6.66013,24804.76648,0.00000,0.04546,309.40519
133.60001,6.68010,24810.79549,0.00000,0.04563,309.48039
134.00001,6.69995,24812.82800,0.00000,0.04579,309.50575
134.40001,6.71992,24815.09894,0.00000,0.04595,309.53407
134.80001,6.73983,24817.78413,0.00000,0.04611,309.56757
135.20001,6.75992,24823.88169,0.00000,0.04628,309.64362
135.60001,6.78001,24829.27591,0.00000,0.04645,309.71091
136.00001,6.80004,24833.54211,0.00000,0.04661,309.76413
136.40001,6.82007,24838.64874,0.00000,0.04678,309.82782
136.80001,6.84004,24841.96723,0.00000,0.04694,309.86922
137.20001,6.86007,24844.17707,0.00000,0.04710,309.89678
137.60001,6.88010,24848.40751,0.00000,0.04727,309.94955
138.00001,6.90019,24851.60679,0.00000,0.04743,309.98946
138.40001,6.92004,24853.66315,0.00000,0.04759,310.01511
138.80001,6.94001,24857.20217,0.00000,0.04775,310.05925
139.20001,6.95986,24859.69216,0.00000,0.04791,310.09031
139.60001,6.97988,24863.76017,0.00000,0.04808,310.14105
140.00001,6.99991,24868.55686,0.00000,0.04824,310.20089
140.40001,7.01994,24874.52328,0.00000,0.04840,310.27531
140.80001,7.04003,24879.60607,0.00000,0.04856,310.33871
141.20001,7.06000,24882.85303,0.00000,0.04872,310.37921
141.60001,7.08003,24887.59458,0.00000,0.04889,310.43836
142.00001,7.10006,24888.81201,0.00000,0.04905,310.45354
142.40001,7.12009,24893.17805,0.00000,0.04921,310.50800
142.80001,7.14006,24895.93774,0.00000,0.04938,310.54242
143.20001,7.16009,24898.68999,0.00000,0.04954,310.57675
143.60001,7.17988,24901.68810,0.00000,0.04970,310.61415
144.00001,7.19985,24906.56078,0.00000,0.04986,310.67493
144.40001,7.21982,24910.42167,0.00000,0.05004,310.72309
144.80001,7.23985,24913.09643,0.00000,0.05021,310.75646
145.20001,7.26006,24918.60539,0.00000,0.05038,310.82517
145.60001,7.28003,24924.20226,0.00000,0.05054,310.89499
146.00001,7.30000,24928.95573,0.00000,0.05071,310.95428
146.40001,7.32009,24931.50085,0.00000,0.05087,310.98603
146.80001,7.34000,24931.83017,0.00000,0.05103,310.99013
147.20001,7.36003,24933.74199,0.00000,0.05119,311.01398
147.60001,7.38012,24940.61440,0.00000,0.05136,311.09970
148.00001,7.40003,24941.48761,0.00000,0.05152,311.11060
148.40001,7.41994,24944.37695,0.00000,0.05169,311.14664
148.80001,7.43991,24948.26466,0.00000,0.05185,311.19513
149.20001,7.45982,24951.34920,0.00000,0.05201,311.23361
149.60001,7.47990,24955.37102,0.00000,0.05218,311.28377
150.00001,7.49999,24958.52560,0.00000,0.05235,311.32312
150.40001,7.51996,24962.76647,0.00000,0.05252,311.37602
150.80001,7.54005,24967.94760,0.00000,0.05268,311.44065
151.20001,7.56002,24971.30632,0.00000,0.05284,311.48254
151.60001,7.57999,24971.37338,0.00000,0.05301,311.48338
152.00001,7.60002,24975.74836,0.00000,0.05317,311.53795
152.40001,7.62005,24977.15503,0.00000,0.05334,311.55550
152.80001,7.64002,24981.92787,0.00000,0.05351,311.61503
153.20001,7.65993,24984.81274,0.00000,0.05367,311.65102
153.60001,7.67990,24987.58584,0.00000,0.05384,311.68561
154.00001,7.69993,24990.01622,0.00000,0.05400,311.71592
154.40001,7.71984,24990.63909,0.00000,0.05417,311.72369
154.80001,7.73993,24995.75615,0.00000,0.05434,311.78752
155.20001,7.76008,25000.54538,0.00000,0.05450,311.84726
155.60001,7.78005,25002.81334,0.00000,0.05467,311.87555
156.00001,7.80008,25006.54161,0.00000,0.05483,311.92205
156.40001,7.81999,25009.48012,0.00000,0.05500,311.95871
156.80001,7.83996,25011.81364,0.00000,0.05517,311.98782
157.20001,7.86005,25013.51535,0.00000,0.05533,312.00904
157.60001,7.88008,25015.97106,0.00000,0.05550,312.03967
158.00001,7.89999,25018.08703,0.00000,0.05566,312.06607
158.40001,7.91995,25022.65275,0.00000,0.05583,312.12302
158.80001,7.93992,25023.28157,0.00000,0.05600,312.13086
159.20001,7.95989,25024.17266,0.00000,0.05617,312.14198
159.60001,7.97998,25027.58801,0.00000,0.05633,312.18458
160.00001,8.00001,25032.73189,0.00000,0.05650,312.24874
160.40001,8.02004,25035.53629,0.00000,0.05667,312.28372
160.80001,8.04007,25036.66878,0.00000,0.05683,312.29785
161.20001,8.05998,25039.48808,0.00000,0.05699,312.33302
161.60001,8.07995,25041.49675,0.00000,0.05716,312.35807
162.00001,8.10004,25042.75441,0.00000,0.05732,312.37376
162.40001,8.12007,25046.53633,0.00000,0.05749,312.42093
162.80001,8.14010,25047.28138,0.00000,0.05766,312.43023
163.20001,8.15995,25048.80726,0.00000,0.05782,312.44926
163.60001,8.17986,25050.92025,0.00000,0.05799,312.47562
164.00001,8.19995,25053.32828,0.00000,0.05815,312.50565
164.40001,8.21998,25055.13430,0.00000,0.05831,312.52818
164.80001,8.24007,25059.71491,0.00000,0.05848,312.58532
165.20001,8.26010,25063.24053,0.00000,0.05864,312.62930
165.60001,8.28007,25067.00456,0.00000,0.05880,312.67625
166.00001,8.30004,25068.57812,0.00000,0.05897,312.69587
166.40001,8.32001,25068.96555,0.00000,0.05913,312.70071
166.80001,8.34004,25070.96827,0.00000,0.05929,312.72569
167.20001,8.36007,25073.63856,0.00000,0.05946,312.75900
167.60001,8.38004,25075.51610,0.00000,0.05962,312.78242
168.00001,8.39994,25076.73800,0.00000,0.05978,312.79766
168.40001,8.41992,25078.93741,0.00000,0.05994,312.82509
168.80001,8.43988,25080.49607,0.00000,0.06010,312.84453
169.20001,8.45997,25083.75943,0.00000,0.06026,312.88524
169.60001,8.48006,25087.94367,0.00000,0.06043,312.93743
170.00001,8.50009,25090.25931,0.00000,0.06060,312.96632
170.40001,8.52012,25093.33789,0.00000,0.06076,313.00472
170.80001,8.53997,25094.26177,0.00000,0.06092,313.01624
171.20001,8.56000,25094.19024,0.00000,0.06108,313.01535
171.60001,8.58003,25095.95454,0.00000,0.06124,313.03736
172.00001,8.60012,25097.96023,0.00000,0.06140,313.06238
172.40001,8.62003,25099.34902,0.00000,0.06156,313.07970
172.80001,8.64000,25100.79443,0.00000,0.06173,313.09773
173.20001,8.65985,25101.91798,0.00000,0.06189,313.11174
173.60001,8.67988,25104.11441,0.00000,0.06205,313.13914
174.00001,8.69997,25108.10196,0.00000,0.06221,313.18888
174.40001,8.72000,25113.43360,0.00000,0.06237,313.25538
174.80001,8.74015,25116.99796,0.00000,0.06253,313.29985
175.20001,8.76006,25115.09657,0.00000,0.06269,313.27613
175.60001,8.78003,25118.58344,0.00000,0.06285,313.31962
176.00001,8.80000,25119.82918,0.00000,0.06301,313.33516
176.40001,8.82003,25120.59510,0.00000,0.06318,313.34471
176.80001,8.84006,25119.82024,0.00000,0.06333,313.33505
177.20001,8.86003,25121.57559,0.00000,0.06350,313.35694
177.60001,8.87987,25124.54391,0.00000,0.06365,313.39397
178.00001,8.89985,25128.06058,0.00000,0.06382,313.43784
178.40001,8.91987,25130.69510,0.00000,0.06398,313.47070
178.80001,8.93996,25132.39384,0.00000,0.06414,313.49189
179.20001,8.96005,25136.49464,0.00000,0.06430,313.54304
179.60001,8.98008,25138.98909,0.00000,0.06446,313.57415
180.00001,9.00005,25139.32586,0.00000,0.06463,313.57835
180.40001,9.02002,25140.02323,0.00000,0.06479,313.58705
180.80001,9.04005,25143.21804,0.00000,0.06495,313.62690
181.20001,9.05996,25141.91866,0.00000,0.06512,313.61070
181.60001,9.08005,25143.40281,0.00000,0.06528,313.62921
182.00001,9.10002,25143.94522,0.00000,0.06544,313.63598
182.40001,9.11993,25145.06876,0.00000,0.06560,313.64999
182.80001,9.13990,25148.46325,0.00000,0.06576,313.69233
183.20001,9.15987,25152.28987,0.00000,0.06592,313.74006
183.60001,9.17990,25152.61769,0.00000,0.06609,313.74415
184.00001,9.19999,25155.63369,0.00000,0.06625,313.78177
184.40001,9.22014,25157.15659,0.00000,0.06641,313.80077
184.80001,9.24017,25158.54239,0.00000,0.06658,313.81805
185.20001,9.26002,25159.09672,0.00000,0.06674,313.82497
185.60001,9.28005,25160.42590,0.00000,0.06690,313.84155
186.00001,9.29996,25157.86886,0.00000,0.06706,313.80965
186.40001,9.31999,25159.54673,0.00000,0.06722,313.83058
186.80001,9.34002,25163.44190,0.00000,0.06738,313.87917
187.20001,9.35998,25165.02738,0.00000,0.06755,313.89895
187.60001,9.37996,25166.69929,0.00000,0.06771,313.91980
188.00001,9.39992,25168.23411,0.00000,0.06787,313.93895
188.40001,9.41995,25169.89708,0.00000,0.06803,313.95969
188.80001,9.43998,25170.93122,0.00000,0.06820,313.97259
189.20001,9.46019,25174.03662,0.00000,0.06836,314.01132
189.60001,9.48010,25172.74022,0.00000,0.06852,313.99515
190.00001,9.50007,25173.87867,0.00000,0.06868,314.00935
190.40001,9.52004,25175.41051,0.00000,0.06884,314.02846
190.80001,9.53989,25173.99788,0.00000,0.06900,314.01084
191.20001,9.55998,25175.57740,0.00000,0.06917,314.03054
191.60001,9.57995,25177.12712,0.00000,0.06933,314.04987
192.00001,9.59992,25179.51131,0.00000,0.06949,314.07961
192.40001,9.61995,25181.58853,0.00000,0.06966,314.10552
192.80001,9.63998,25184.31544,0.00000,0.06982,314.13954
193.20001,9.65995,25183.13825,0.00000,0.06998,314.12485
193.60001,9.68004,25185.61482,0.00000,0.07014,314.15575
194.00001,9.70013,25184.95321,0.00000,0.07032,314.14749
194.40001,9.72016,25188.10630,0.00000,0.07048,314.18682
194.80001,9.74013,25187.12878,0.00000,0.07064,314.17463
195.20001,9.76004,25187.41786,0.00000,0.07081,314.17824
195.60001,9.77995,25187.99603,0.00000,0.07097,314.18545
196.00001,9.79992,25188.13312,0.00000,0.07114,314.18716
196.40001,9.81995,25190.11796,0.00000,0.07131,314.21192
196.80001,9.83997,25191.30111,0.00000,0.07147,314.22667
197.20001,9.86000,25193.70615,0.00000,0.07164,314.25667
197.60001,9.87991,25193.65549,0.00000,0.07180,314.25604
198.00001,9.89994,25196.04564,0.00000,0.07196,314.28586
198.40001,9.92003,25195.91153,0.00000,0.07213,314.28418
198.80001,9.94012,25197.30926,0.00000,0.07229,314.30162
199.20001,9.96009,25198.90368,0.00000,0.07246,314.32151
199.60001,9.98006,25199.97358,0.00000,0.07262,314.33485
200.00001,10.00003,25199.62192,0.00000,0.07279,314.33047
200.40001,10.01994,25197.80099,0.00000,0.07295,314.30775
200.80001,10.03991,25198.19736,0.00000,0.07312,314.31270
201.20001,10.05994,25200.83785,0.00000,0.07329,314.34563
201.60001,10.07997,25203.20415,0.00000,0.07345,314.37515
202.00001,10.09994,25201.52628,0.00000,0.07362,314.35422
202.40001,10.11997,25203.51708,0.00000,0.07378,314.37905
202.80001,10.13994,25204.58400,0.00000,0.07395,314.39236
203.20001,10.16003,25204.85222,0.00000,0.07411,314.39571
203.60001,10.18012,25206.11286,0.00000,0.07428,314.41143
204.00001,10.20015,25207.33476,0.00000,0.07445,314.42667
204.40001,10.22006,25208.94110,0.00000,0.07462,314.44671
204.80001,10.24003,25209.59079,0.00000,0.07478,314.45481
205.20001,10.25988,25208.55367,0.00000,0.07495,314.44188
205.60001,10.27991,25205.48999,0.00000,0.07511,314.40366
206.00001,10.29988,25207.99339,0.00000,0.07528,314.43489
206.40001,10.31996,25208.44042,0.00000,0.07544,314.44046
206.80001,10.33999,25212.73792,0.00000,0.07561,314.49407
207.20001,10.35996,25210.71434,0.00000,0.07578,314.46883
207.60001,10.37999,25212.04948,0.00000,0.07594,314.48548
208.00001,10.39996,25210.72924,0.00000,0.07611,314.46901
208.40001,10.42005,25213.44423,0.00000,0.07628,314.50288
208.80001,10.44014,25215.51251,0.00000,0.07644,314.52868
209.20001,10.46011,25213.60815,0.00000,0.07661,314.50492
209.60001,10.47996,25214.01346,0.00000,0.07678,314.50998
210.00001,10.49993,25214.68997,0.00000,0.07694,314.51842
210.40001,10.51990,25213.64987,0.00000,0.07711,314.50544
210.80001,10.53993,25212.71408,0.00000,0.07728,314.49377
211.20001,10.56002,25213.38165,0.00000,0.07744,314.50210
211.60001,10.57999,25213.05978,0.00000,0.07761,314.49808
212.00001,10.60002,25216.53175,0.00000,0.07778,314.54139
212.40001,10.61999,25216.99071,0.00000,0.07794,314.54712
212.80001,10.64002,25217.13972,0.00000,0.07810,314.54898
213.20001,10.66005,25217.97419,0.00000,0.07827,314.55938
213.60001,10.68014,25219.79213,0.00000,0.07844,314.58206
214.00001,10.70005,25218.81461,0.00000,0.07861,314.56987
214.40001,10.72002,25218.13214,0.00000,0.07878,314.56135
214.80001,10.73999,25216.92812,0.00000,0.07894,314.54634
215.20001,10.75990,25216.37380,0.00000,0.07911,314.53942
215.60001,10.77987,25216.72845,0.00000,0.07928,314.54385
216.00001,10.80001,25217.02349,0.00000,0.07944,314.54753
216.40001,10.82004,25218.97852,0.00000,0.07962,314.57191
216.80001,10.83995,25218.38248,0.00000,0.07978,314.56448
217.20001,10.85998,25222.02134,0.00000,0.07995,314.60987
217.60001,10.88001,25222.56970,0.00000,0.08012,314.61671
218.00001,10.90004,25220.12889,0.00000,0.08029,314.58626
218.40001,10.92007,25221.16899,0.00000,0.08045,314.59924
218.80001,10.94010,25223.44589,0.00000,0.08063,314.62764
219.20001,10.96001,25220.62659,0.00000,0.08080,314.59247
219.60001,10.97998,25219.61331,0.00000,0.08097,314.57983
220.00001,10.99995,25217.71193,0.00000,0.08113,314.55611
220.40001,11.01986,25217.45563,0.00000,0.08130,314.55292
220.80001,11.04001,25221.60709,0.00000,0.08148,314.60470
221.20001,11.05998,25221.65477,0.00000,0.08165,314.60529
221.60001,11.08001,25222.37003,0.00000,0.08182,314.61422
222.00001,11.10004,25223.49656,0.00000,0.08199,314.62827
222.40001,11.12007,25223.27900,0.00000,0.08216,314.62555
222.80001,11.14004,25221.30013,0.00000,0.08233,314.60087
223.20001,11.16007,25222.13161,0.00000,0.08250,314.61124
223.60001,11.18010,25221.80676,0.00000,0.08268,314.60719
224.00001,11.20007,25221.37761,0.00000,0.08285,314.60184
224.40001,11.21998,25219.47920,0.00000,0.08302,314.57816
224.80001,11.23989,25218.73116,0.00000,0.08319,314.56883
225.20001,11.25992,25217.79835,0.00000,0.08336,314.55719
225.60001,11.27995,25219.63418,0.00000,0.08353,314.58009
226.00001,11.29998,25221.19880,0.00000,0.08371,314.59961
226.40001,11.32000,25223.64259,0.00000,0.08388,314.63009
226.80001,11.34003,25222.53990,0.00000,0.08405,314.61634
227.20001,11.35994,25221.93789,0.00000,0.08423,314.60883
227.60001,11.38003,25220.46566,0.00000,0.08440,314.59046
228.00001,11.40000,25221.49682,0.00000,0.08458,314.60332
228.40001,11.42009,25220.64447,0.00000,0.08475,314.59269
228.80001,11.44006,25217.76557,0.00000,0.08492,314.55678
229.20001,11.45997,25217.04137,0.00000,0.08510,314.54775
229.60001,11.47994,25218.97256,0.00000,0.08528,314.57184
230.00001,11.49985,25216.67778,0.00000,0.08545,314.54321
230.40001,11.51988,25217.59570,0.00000,0.08563,314.55466
230.80001,11.53997,25218.37950,0.00000,0.08581,314.56444
231.20001,11.56000,25220.39413,0.00000,0.08598,314.58957
231.60001,11.58003,25221.16899,0.00000,0.08616,314.59924
232.00001,11.60000,25218.31989,0.00000,0.08634,314.56370
232.40001,11.62003,25216.25161,0.00000,0.08651,314.53790
232.80001,11.64006,25216.91024,0.00000,0.08669,314.54611
233.20001,11.66009,25216.90726,0.00000,0.08687,314.54608
233.60001,11.68006,25215.69431,0.00000,0.08705,314.53095
234.00001,11.70003,25214.15651,0.00000,0.08722,314.51176
234.40001,11.71988,25212.88693,0.00000,0.08740,314.49593
234.80001,11.73979,25212.63659,0.00000,0.08758,314.49281
235.20001,11.75994,25213.43529,0.00000,0.08776,314.50277
235.60001,11.78002,25215.18469,0.00000,0.08794,314.52459
236.00001,11.79999,25213.92405,0.00000,0.08812,314.50886
236.40001,11.82002,25214.01048,0.00000,0.08829,314.50994
236.80001,11.83993,25212.46970,0.00000,0.08847,314.49072
237.20001,11.85996,25211.05111,0.00000,0.08865,314.47303
237.60001,11.87999,25209.16164,0.00000,0.08883,314.44946
238.00001,11.90014,25209.93948,0.00000,0.08901,314.45916
238.40001,11.92011,25209.87093,0.00000,0.08919,314.45831
238.80001,11.93996,25210.38055,0.00000,0.08937,314.46466
239.20001,11.95987,25209.29277,0.00000,0.08955,314.45110
239.60001,11.97990,25206.93839,0.00000,0.08973,314.42173
240.00001,11.99987,25206.25293,0.00000,0.08991,314.41318
240.40001,12.01996,25208.17220,0.00000,0.09009,314.43712
240.80001,12.04005,25208.19604,0.00000,0.09027,314.43742
241.20001,12.06008,25209.34641,0.00000,0.09046,314.45176
241.60001,12.08011,25207.09932,0.00000,0.09064,314.42374
242.00001,12.10008,25205.50191,0.00000,0.09082,314.40381
242.40001,12.11999,25202.53360,0.00000,0.09101,314.36678
242.80001,12.14014,25204.42605,0.00000,0.09119,314.39039
243.20001,12.16011,25202.05379,0.00000,0.09137,314.36080
243.60001,12.17996,25202.05677,0.00000,0.09155,314.36084
244.00001,12.19993,25202.55744,0.00000,0.09174,314.36708
244.40001,12.21984,25200.03617,0.00000,0.09193,314.33563
244.80001,12.23987,25197.93510,0.00000,0.09211,314.30942
245.20001,12.25995,25198.37320,0.00000,0.09230,314.31489
245.60001,12.28004,25199.21362,0.00000,0.09248,314.32537
246.00001,12.30013,25199.41926,0.00000,0.09267,314.32794
246.40001,12.32004,25196.93673,0.00000,0.09285,314.29697
246.80001,12.34001,25196.17975,0.00000,0.09304,314.28753
247.20001,12.36004,25195.31548,0.00000,0.09323,314.27675
247.60001,12.38007,25194.68665,0.00000,0.09342,314.26890
248.00001,12.39998,25193.10117,0.00000,0.09360,314.24913
248.40001,12.42001,25191.81669,0.00000,0.09379,314.23311
248.80001,12.43986,25190.02855,0.00000,0.09398,314.21080
249.20001,12.45983,25190.47558,0.00000,0.09417,314.21638
249.60001,12.47986,25189.60536,0.00000,0.09436,314.20552
250.00001,12.50001,25187.68311,0.00000,0.09455,314.18154
250.40001,12.52016,25188.94374,0.00000,0.09474,314.19727
250.80001,12.54007,25188.39538,0.00000,0.09493,314.19043
251.20001,12.56010,25188.73513,0.00000,0.09512,314.19467
251.60001,12.58007,25187.43873,0.00000,0.09531,314.17850
252.00001,12.60004,25184.15153,0.00000,0.09550,314.13749
252.40001,12.62007,25183.46310,0.00000,0.09570,314.12891
252.80001,12.64004,25181.95808,0.00000,0.09589,314.11013
253.20001,12.65995,25180.53055,0.00000,0.09608,314.09233
253.60001,12.67992,25180.14610,0.00000,0.09628,314.08753
254.00001,12.69989,25177.35660,0.00000,0.09647,314.05274
254.40001,12.71985,25176.59664,0.00000,0.09667,314.04326
254.80001,12.73994,25175.92311,0.00000,0.09686,314.03486
255.20001,12.76009,25177.79469,0.00000,0.09706,314.05820
255.60001,12.78012,25176.13173,0.00000,0.09726,314.03746
256.00001,12.80009,25175.07672,0.00000,0.09745,314.02430
256.40001,12.82006,25173.98894,0.00000,0.09765,314.01073
256.80001,12.83997,25170.67492,0.00000,0.09785,313.96939
257.20001,12.86000,25168.32352,0.00000,0.09804,313.94006
257.60001,12.88003,25166.42511,0.00000,0.09825,313.91638
258.00001,12.89994,25165.13467,0.00000,0.09844,313.90028
258.40001,12.91985,25165.35223,0.00000,0.09864,313.90300
258.80001,12.93982,25161.81767,0.00000,0.09884,313.85891
259.20001,12.95991,25161.41534,0.00000,0.09904,313.85389
259.60001,12.98000,25160.82823,0.00000,0.09924,313.84657
260.00001,13.00003,25162.57167,0.00000,0.09944,313.86831
260.40001,13.02012,25161.86535,0.00000,0.09964,313.85950
260.80001,13.04015,25160.98320,0.00000,0.09985,313.84850
261.20001,13.06000,25157.47249,0.00000,0.10005,313.80471
261.60001,13.07997,25154.47736,0.00000,0.10025,313.76735
262.00001,13.09994,25151.47030,0.00000,0.10046,313.72984
262.40001,13.11997,25150.89512,0.00000,0.10066,313.72267
262.80001,13.13994,25148.62418,0.00000,0.10087,313.69434
263.20001,13.15991,25147.25924,0.00000,0.10108,313.67731
263.60001,13.17994,25147.36354,0.00000,0.10128,313.67861
264.00001,13.19997,25145.88833,0.00000,0.10149,313.66021
264.40001,13.21993,25144.30881,0.00000,0.10169,313.64051
264.80001,13.24008,25144.32371,0.00000,0.10190,313.64070
265.20001,13.26005,25143.50712,0.00000,0.10211,313.63051
265.60001,13.28002,25142.18092,0.00000,0.10232,313.61397
266.00001,13.30005,25140.64014,0.00000,0.10253,313.59475
266.40001,13.31990,25134.84359,0.00000,0.10274,313.52244
266.80001,13.33999,25132.17926,0.00000,0.10295,313.48921
267.20001,13.36002,25130.37920,0.00000,0.10317,313.46676
267.60001,13.37999,25130.38814,0.00000,0.10338,313.46687
268.00001,13.39996,25127.73573,0.00000,0.10358,313.43378
268.40001,13.41993,25127.88475,0.00000,0.10380,313.43564
268.80001,13.43990,25125.67639,0.00000,0.10401,313.40810
269.20001,13.45993,25124.32933,0.00000,0.10423,313.39129
269.60001,13.48008,25125.01776,0.00000,0.10444,313.39988
270.00001,13.50005,25123.04485,0.00000,0.10465,313.37527
270.40001,13.52008,25121.51897,0.00000,0.10487,313.35624
270.80001,13.53999,25117.83242,0.00000,0.10509,313.31025
271.20001,13.55996,25114.32171,0.00000,0.10531,313.26646
271.60001,13.57993,25109.58612,0.00000,0.10552,313.20739
272.00001,13.60002,25108.69503,0.00000,0.10573,313.19628
272.40001,13.61999,25107.47313,0.00000,0.10595,313.18104
272.80001,13.63996,25106.92775,0.00000,0.10617,313.17423
273.20001,13.65993,25105.93235,0.00000,0.10639,313.16182
273.60001,13.67996,25104.47204,0.00000,0.10661,313.14360
274.00001,13.69993,25100.92854,0.00000,0.10683,313.09940
274.40001,13.72007,25102.05209,0.00000,0.10705,313.11342
274.80001,13.74016,25099.29836,0.00000,0.10727,313.07907
275.20001,13.76007,25095.70122,0.00000,0.10749,313.03420
275.60001,13.78004,25093.13524,0.00000,0.10771,313.00219
276.00001,13.79995,25090.26527,0.00000,0.10794,312.96639
276.40001,13.81998,25087.32677,0.00000,0.10816,312.92974
276.80001,13.84001,25085.17206,0.00000,0.10838,312.90286
277.20001,13.86004,25082.63290,0.00000,0.10860,312.87119
277.60001,13.87995,25081.33054,0.00000,0.10882,312.85494
278.00001,13.89992,25082.27825,0.00000,0.10905,312.86676
278.40001,13.91989,25079.79870,0.00000,0.10927,312.83584
278.80001,13.93992,25075.72472,0.00000,0.10950,312.78502
279.20001,13.96001,25073.41504,0.00000,0.10973,312.75621
279.60001,13.98010,25071.80274,0.00000,0.10995,312.73610
280.00001,14.00013,25070.45567,0.00000,0.11018,312.71929
280.40001,14.02004,25064.88860,0.00000,0.11040,312.64985
280.80001,14.04001,25062.11698,0.00000,0.11063,312.61528
281.20001,14.05998,25058.28440,0.00000,0.11085,312.56747
281.60001,14.07995,25056.43666,0.00000,0.11107,312.54443
282.00001,14.09998,25054.92568,0.00000,0.11130,312.52558
282.40001,14.12001,25051.57292,0.00000,0.11153,312.48376
282.80001,14.13992,25047.65093,0.00000,0.11175,312.43484
283.20001,14.15989,25048.09797,0.00000,0.11198,312.44041
283.60001,14.17998,25045.18330,0.00000,0.11221,312.40406
284.00001,14.20000,25041.66961,0.00000,0.11243,312.36023
284.40001,14.22009,25038.99932,0.00000,0.11265,312.32692
284.80001,14.24012,25035.56907,0.00000,0.11287,312.28413
285.20001,14.26003,25032.62758,0.00000,0.11309,312.24744
285.60001,14.28000,25028.71454,0.00000,0.11332,312.19863
286.00001,14.30003,25024.31870,0.00000,0.11353,312.14380
286.40001,14.31994,25019.71722,0.00000,0.11375,312.08640
286.80001,14.33997,25018.45956,0.00000,0.11430,312.07071
287.20001,14.35994,25015.13958,0.00000,0.11449,312.02930
287.60001,14.37997,25011.84046,0.00000,0.11470,311.98815
288.00001,14.39994,25007.45356,0.00000,0.11492,311.93343
288.40001,14.41997,25004.18127,0.00000,0.11512,311.89261
288.80001,14.44000,24998.77959,0.00000,0.11534,311.82523
289.20001,14.46009,24994.45081,0.00000,0.11554,311.77124
289.60001,14.48012,24990.65250,0.00000,0.11574,311.72386
290.00001,14.50009,24985.17931,0.00000,0.11594,311.65559
290.40001,14.52006,24980.24851,0.00000,0.11614,311.59408
290.80001,14.54003,24971.10367,0.00000,0.11633,311.48002
291.20001,14.55994,24961.05880,0.00000,0.11652,311.35472
291.60001,14.57991,24955.01786,0.00000,0.11670,311.27937
292.00001,14.60000,24948.78024,0.00000,0.11687,311.20156
292.40001,14.61997,24940.19717,0.00000,0.11703,311.09450
292.80001,14.63993,24928.66516,0.00000,0.11719,310.95065
293.20001,14.65996,24915.64453,0.00000,0.11734,310.78824
293.60001,14.67999,24901.65383,0.00000,0.11748,310.61372
294.00001,14.70008,24888.06993,0.00000,0.11761,310.44428
294.40001,14.72017,24871.60116,0.00000,0.11773,310.23886
294.80001,14.74014,24850.84087,0.00000,0.11784,309.97990
295.20001,14.76005,24828.60684,0.00000,0.11793,309.70256
295.60001,14.78002,24801.84585,0.00000,0.11803,309.36876
296.00001,14.79981,24769.74577,0.00000,0.11810,308.96835
296.40001,14.81996,24737.41174,0.00000,0.11816,308.56503
296.80001,14.83999,24694.19837,0.00000,0.11822,308.02600
297.20001,14.85996,24649.24604,0.00000,0.11826,307.46529
297.60001,14.87993,24593.48291,0.00000,0.11829,306.76972
298.00001,14.90002,24533.70988,0.00000,0.11831,306.02413
298.40001,14.92005,24462.21560,0.00000,0.11832,305.13234
298.80001,14.94014,24369.35306,0.00000,0.11832,303.97401
299.20001,14.96017,24191.86085,0.00000,0.11830,301.76004
299.60001,14.98014,23736.94479,0.00000,0.11820,296.08559
299.64601,14.98265,21554.69805,0.00000,0.11609,268.86508
299.65401,14.98397,16748.67123,0.00000,0.11094,208.91653
299.65801,14.98468,14052.36423,0.00000,0.10737,175.28383