File: scratch/college-stuff/ME Lab/ME lab Fall 2013/group12/group12.is_tens_RawData/Specimen_RawData_1.csv
Time,Extension,Load,Strain 2,Tensile strain,Tensile stress
(sec),(mm),(N),(mm/mm),(mm/mm),(MPa)
0.00000,0.00006,-0.89987,0.00000,0.00000,-0.01122
0.20000,0.00717,7.74024,0.00000,0.00000,0.09655
0.40000,0.01937,14.81148,0.00000,-0.00001,0.18475
0.60000,0.02995,19.00778,0.00000,-0.00001,0.23710
0.80000,0.04006,21.62342,0.00000,-0.00001,0.26972
1.00000,0.05004,24.40150,0.00000,-0.00001,0.30437
1.20000,0.06003,28.24869,0.00000,-0.00001,0.35236
1.40000,0.06995,30.97713,0.00000,-0.00001,0.38640
1.60000,0.07994,32.32100,0.00000,-0.00001,0.40316
1.80000,0.08998,33.64644,0.00000,-0.00002,0.41969
2.00000,0.09997,34.62759,0.00000,-0.00002,0.43193
2.20000,0.10995,36.01495,0.00000,-0.00001,0.44924
2.40000,0.11994,39.03584,0.00000,-0.00002,0.48692
2.60000,0.12992,44.30028,0.00000,-0.00002,0.55258
2.80000,0.13997,47.47693,0.00000,-0.00003,0.59221
3.00000,0.14995,51.73197,0.00000,-0.00003,0.64528
3.20000,0.16000,55.66949,0.00000,-0.00004,0.69440
3.40000,0.16998,59.54456,0.00000,-0.00005,0.74274
3.60000,0.18009,70.80263,0.00000,-0.00005,0.88317
3.80000,0.19007,78.44075,0.00000,-0.00006,0.97844
4.00000,0.20012,102.21803,0.00000,-0.00006,1.27503
4.20000,0.21010,131.08834,0.00000,-0.00005,1.63515
4.40000,0.22009,166.21916,0.00000,-0.00005,2.07335
4.60000,0.23013,206.29298,0.00000,-0.00004,2.57322
4.80000,0.24000,248.56396,0.00000,-0.00003,3.10049
5.00000,0.25004,292.68423,0.00000,-0.00002,3.65083
5.20000,0.26002,339.23541,0.00000,-0.00002,4.23149
5.40000,0.27001,390.26977,0.00000,0.00000,4.86808
5.60000,0.28005,447.40136,0.00000,0.00001,5.58071
5.80000,0.28998,504.64300,0.00000,0.00003,6.29472
6.00000,0.29996,562.25844,0.00000,0.00004,7.01340
6.20000,0.30995,622.43883,0.00000,0.00006,7.76406
6.40000,0.31987,703.99428,0.00000,0.00009,8.78136
6.60000,0.32992,788.65811,0.00000,0.00013,9.83742
6.80000,0.33984,872.30178,0.00000,0.00016,10.88076
7.00000,0.34995,961.08131,0.00000,0.00019,11.98816
7.20000,0.35993,1045.15068,0.00000,0.00023,13.03681
7.40000,0.36992,1141.53409,0.00000,0.00026,14.23906
7.60000,0.37996,1237.31401,0.00000,0.00031,15.43378
7.80000,0.38989,1334.95340,0.00000,0.00036,16.65170
8.00000,0.39999,1430.45820,0.00000,0.00040,17.84299
8.20000,0.40998,1525.47769,0.00000,0.00044,19.02823
8.40000,0.42008,1622.27415,0.00000,0.00048,20.23563
8.60000,0.43007,1719.79778,0.00000,0.00053,21.45210
8.80000,0.44005,1815.48167,0.00000,0.00057,22.64563
9.00000,0.45004,1910.46149,0.00000,0.00062,23.83037
9.20000,0.46002,2006.13216,0.00000,0.00066,25.02373
9.40000,0.47006,2100.36188,0.00000,0.00071,26.19911
9.60000,0.47999,2192.43262,0.00000,0.00075,27.34757
9.80000,0.49003,2286.22891,0.00000,0.00079,28.51755
10.00000,0.49996,2378.03515,0.00000,0.00084,29.66270
10.20000,0.50994,2468.58224,0.00000,0.00088,30.79215
10.40000,0.52005,2560.73773,0.00000,0.00093,31.94166
10.60000,0.52991,2650.29948,0.00000,0.00097,33.05882
10.80000,0.53996,2738.70118,0.00000,0.00101,34.16151
11.00000,0.54982,2826.95182,0.00000,0.00106,35.26232
11.20000,0.55987,2914.69749,0.00000,0.00110,36.35682
11.40000,0.56991,3001.02700,0.00000,0.00114,37.43367
11.60000,0.57990,3085.31616,0.00000,0.00118,38.48506
11.80000,0.58994,3168.96364,0.00000,0.00122,39.52844
12.00000,0.59987,3251.82974,0.00000,0.00126,40.56208
12.20000,0.60991,3333.24224,0.00000,0.00130,41.57759
12.40000,0.61990,3414.05347,0.00000,0.00134,42.58560
12.60000,0.63000,3493.40364,0.00000,0.00138,43.57538
12.80000,0.64005,3572.29486,0.00000,0.00142,44.55944
13.00000,0.65003,3647.92123,0.00000,0.00145,45.50278
13.20000,0.66008,3721.27257,0.00000,0.00149,46.41773
13.40000,0.67006,3794.54307,0.00000,0.00153,47.33168
13.60000,0.68011,3866.50935,0.00000,0.00156,48.22936
13.80000,0.69009,3937.92279,0.00000,0.00160,49.12015
14.00000,0.70008,4007.19978,0.00000,0.00163,49.98428
14.20000,0.71012,4075.03098,0.00000,0.00167,50.83038
14.40000,0.72004,4143.25781,0.00000,0.00170,51.68142
14.60000,0.73009,4209.23457,0.00000,0.00173,52.50439
14.80000,0.74007,4272.67179,0.00000,0.00176,53.29568
15.00000,0.75006,4329.98128,0.00000,0.00179,54.01053
15.20000,0.75998,4384.50053,0.00000,0.00182,54.69059
15.40000,0.76997,4435.71471,0.00000,0.00185,55.32941
15.60000,0.77995,4487.95594,0.00000,0.00187,55.98105
15.80000,0.78988,4543.21243,0.00000,0.00190,56.67030
16.00000,0.79992,4599.63717,0.00000,0.00193,57.37412
16.20000,0.80985,4653.76042,0.00000,0.00196,58.04923
16.40000,0.81989,4711.36831,0.00000,0.00198,58.76781
16.60000,0.82994,4768.49750,0.00000,0.00201,59.48042
16.80000,0.83986,4825.13607,0.00000,0.00204,60.18691
17.00000,0.84997,4881.08844,0.00000,0.00207,60.88483
17.20000,0.86001,4936.84784,0.00000,0.00209,61.58036
17.40000,0.87006,4994.80069,0.00000,0.00212,62.30324
17.60000,0.88004,5051.50333,0.00000,0.00215,63.01052
17.80000,0.89003,5107.05523,0.00000,0.00218,63.70346
18.00000,0.90013,5161.90380,0.00000,0.00220,64.38762
18.20000,0.91012,5218.36504,0.00000,0.00223,65.09189
18.40000,0.92010,5273.79736,0.00000,0.00226,65.78334
18.60000,0.93009,5329.81977,0.00000,0.00229,66.48214
18.80000,0.94007,5386.06532,0.00000,0.00231,67.18372
19.00000,0.95006,5441.40413,0.00000,0.00234,67.87400
19.20000,0.95998,5497.02682,0.00000,0.00237,68.56781
19.40000,0.97008,5552.48260,0.00000,0.00240,69.25955
19.60000,0.98001,5608.93752,0.00000,0.00242,69.96375
19.80000,0.98999,5664.66525,0.00000,0.00245,70.65887
20.00000,0.99998,5717.95925,0.00000,0.00248,71.32364
20.20000,1.00996,5772.77094,0.00000,0.00251,72.00734
20.40000,1.01995,5827.29355,0.00000,0.00254,72.68744
20.60000,1.02987,5884.02301,0.00000,0.00257,73.39506
20.80000,1.03992,5937.40046,0.00000,0.00259,74.06087
21.00000,1.04990,5993.26752,0.00000,0.00262,74.75773
21.20000,1.05989,6048.84587,0.00000,0.00265,75.45099
21.40000,1.06999,6103.16284,0.00000,0.00268,76.12852
21.60000,1.07992,6156.98174,0.00000,0.00271,76.79984
21.80000,1.09002,6208.75321,0.00000,0.00273,77.44562
22.00000,1.09995,6257.02590,0.00000,0.00276,78.04775
22.20000,1.10999,6305.71768,0.00000,0.00278,78.65512
22.40000,1.12004,6354.81700,0.00000,0.00281,79.26756
22.60000,1.13008,6405.39154,0.00000,0.00283,79.89841
22.80000,1.14007,6455.65465,0.00000,0.00286,80.52537
23.00000,1.15005,6508.46884,0.00000,0.00288,81.18416
23.20000,1.16010,6560.04399,0.00000,0.00291,81.82748
23.40000,1.17008,6613.52500,0.00000,0.00294,82.49459
23.60000,1.18012,6666.20508,0.00000,0.00296,83.15170
23.80000,1.19005,6718.82853,0.00000,0.00300,83.80810
24.00000,1.20003,6772.39150,0.00000,0.00302,84.47623
24.20000,1.21008,6824.93001,0.00000,0.00305,85.13157
24.40000,1.21994,6879.82291,0.00000,0.00308,85.81628
24.60000,1.23005,6932.64380,0.00000,0.00310,86.47515
24.80000,1.23997,6985.85361,0.00000,0.00313,87.13887
25.00000,1.24990,7039.25714,0.00000,0.00316,87.80501
25.20000,1.25988,7092.73145,0.00000,0.00319,88.47202
25.40000,1.26987,7146.75635,0.00000,0.00321,89.14591
25.60000,1.27991,7199.94232,0.00000,0.00324,89.80933
25.80000,1.28990,7254.92910,0.00000,0.00327,90.49522
26.00000,1.29994,7309.04043,0.00000,0.00330,91.17018
26.20000,1.30993,7362.15264,0.00000,0.00332,91.83268
26.40000,1.31991,7417.66617,0.00000,0.00335,92.52514
26.60000,1.33002,7471.73354,0.00000,0.00338,93.19955
26.80000,1.34000,7527.32754,0.00000,0.00341,93.89301
27.00000,1.35005,7582.69131,0.00000,0.00344,94.58360
27.20000,1.36003,7634.78130,0.00000,0.00346,95.23335
27.40000,1.37008,7691.12706,0.00000,0.00349,95.93618
27.60000,1.38006,7744.57157,0.00000,0.00352,96.60283
27.80000,1.39005,7799.50619,0.00000,0.00355,97.28806
28.00000,1.40009,7855.90932,0.00000,0.00358,97.99161
28.20000,1.41002,7910.35295,0.00000,0.00361,98.67072
28.40000,1.42006,7966.61824,0.00000,0.00364,99.37256
28.60000,1.43005,8019.69469,0.00000,0.00366,100.03461
28.80000,1.43997,8075.34084,0.00000,0.00369,100.72872
29.00000,1.45007,8129.92305,0.00000,0.00372,101.40956
29.20000,1.46000,8184.13794,0.00000,0.00375,102.08581
29.40000,1.47004,8238.63596,0.00000,0.00378,102.76560
29.60000,1.47991,8292.16316,0.00000,0.00381,103.43328
29.80000,1.48989,8348.86283,0.00000,0.00384,104.14053
30.00000,1.49988,8403.58958,0.00000,0.00387,104.82317
30.20000,1.50986,8459.15452,0.00000,0.00390,105.51626
30.40000,1.51997,8515.66046,0.00000,0.00393,106.22110
30.60000,1.52989,8569.81725,0.00000,0.00396,106.89663
30.80000,1.53994,8623.89281,0.00000,0.00398,107.57115
31.00000,1.54986,8677.48186,0.00000,0.00402,108.23960
31.20000,1.55997,8734.50488,0.00000,0.00404,108.95088
31.40000,1.57001,8789.77925,0.00000,0.00408,109.64035
31.60000,1.57994,8845.11098,0.00000,0.00411,110.33054
31.80000,1.59004,8901.02237,0.00000,0.00414,111.02796
32.00000,1.59997,8957.00306,0.00000,0.00416,111.72624
32.20000,1.61007,9014.11474,0.00000,0.00420,112.43863
32.40000,1.62012,9069.45467,0.00000,0.00423,113.12892
32.60000,1.63010,9125.73859,0.00000,0.00426,113.83098
32.80000,1.64015,9180.94069,0.00000,0.00429,114.51955
33.00000,1.65001,9236.39312,0.00000,0.00432,115.21124
33.20000,1.66000,9292.92515,0.00000,0.00435,115.91640
33.40000,1.67004,9350.44959,0.00000,0.00438,116.63394
33.60000,1.68003,9407.41599,0.00000,0.00441,117.34452
33.80000,1.69001,9461.99968,0.00000,0.00444,118.02537
34.00000,1.69993,9517.91406,0.00000,0.00447,118.72283
34.20000,1.70998,9575.20828,0.00000,0.00450,119.43749
34.40000,1.71990,9630.73596,0.00000,0.00453,120.13012
34.60000,1.72995,9687.15474,0.00000,0.00456,120.83387
34.80000,1.73987,9741.23403,0.00000,0.00459,121.50844
35.00000,1.74986,9800.11150,0.00000,0.00462,122.24285
35.20000,1.75990,9855.93200,0.00000,0.00465,122.93913
35.40000,1.76983,9913.29178,0.00000,0.00468,123.65462
35.60000,1.77993,9971.14331,0.00000,0.00471,124.37624
35.80000,1.78998,10028.09107,0.00000,0.00475,125.08658
36.00000,1.79996,10084.32209,0.00000,0.00477,125.78798
36.20000,1.81001,10141.83536,0.00000,0.00481,126.50538
36.40000,1.81999,10200.50645,0.00000,0.00484,127.23722
36.60000,1.83004,10257.15023,0.00000,0.00488,127.94378
36.80000,1.84002,10314.94215,0.00000,0.00491,128.66465
37.00000,1.85001,10372.64988,0.00000,0.00494,129.38448
37.20000,1.86005,10430.77707,0.00000,0.00497,130.10953
37.40000,1.87010,10488.65989,0.00000,0.00500,130.83154
37.60000,1.88008,10545.27462,0.00000,0.00503,131.53773
37.80000,1.89007,10603.47259,0.00000,0.00507,132.26367
38.00000,1.89999,10657.54890,0.00000,0.00510,132.93820
38.20000,1.90998,10714.09509,0.00000,0.00513,133.64353
38.40000,1.91996,10772.41749,0.00000,0.00516,134.37102
38.60000,1.92994,10829.22146,0.00000,0.00519,135.07957
38.80000,1.93993,10887.24285,0.00000,0.00522,135.80331
39.00000,1.95003,10942.61482,0.00000,0.00525,136.49400
39.20000,1.95990,11002.32080,0.00000,0.00529,137.23875
39.40000,1.96994,11059.93912,0.00000,0.00532,137.95746
39.60000,1.97987,11114.82382,0.00000,0.00535,138.64207
39.80000,1.98991,11173.38613,0.00000,0.00538,139.37255
40.00000,2.00002,11231.78750,0.00000,0.00542,140.10103
40.20000,2.00994,11289.61295,0.00000,0.00545,140.82232
40.40000,2.01999,11346.91983,0.00000,0.00548,141.53715
40.60000,2.02991,11404.91292,0.00000,0.00551,142.26053
40.80000,2.03996,11463.69353,0.00000,0.00555,142.99374
41.00000,2.05000,11521.56070,0.00000,0.00558,143.71555
41.20000,2.05999,11580.60730,0.00000,0.00561,144.45208
41.40000,2.07003,11638.46329,0.00000,0.00564,145.17375
41.60000,2.08002,11696.54727,0.00000,0.00568,145.89827
41.80000,2.09006,11753.02714,0.00000,0.00571,146.60277
42.00000,2.09999,11811.60808,0.00000,0.00574,147.33349
42.20000,2.11009,11871.58674,0.00000,0.00578,148.08164
42.40000,2.12014,11928.67458,0.00000,0.00581,148.79373
42.60000,2.13000,11986.37784,0.00000,0.00584,149.51350
42.80000,2.14005,12044.86415,0.00000,0.00587,150.24304
43.00000,2.14997,12102.16135,0.00000,0.00591,150.95774
43.20000,2.16001,12160.27811,0.00000,0.00594,151.68267
43.40000,2.17000,12215.67318,0.00000,0.00598,152.37364
43.60000,2.17992,12272.72153,0.00000,0.00601,153.08524
43.80000,2.19003,12331.58410,0.00000,0.00604,153.81947
44.00000,2.19989,12389.23147,0.00000,0.00607,154.53854
44.20000,2.20994,12448.35556,0.00000,0.00611,155.27604
44.40000,2.21992,12505.61327,0.00000,0.00614,155.99025
44.60000,2.22991,12564.80515,0.00000,0.00618,156.72858
44.80000,2.24001,12623.52467,0.00000,0.00621,157.46103
45.00000,2.24994,12682.90728,0.00000,0.00624,158.20174
45.20000,2.25992,12741.38391,0.00000,0.00627,158.93116
45.40000,2.26997,12799.82924,0.00000,0.00631,159.66018
45.60000,2.27995,12859.99864,0.00000,0.00634,160.41071
45.80000,2.28994,12919.81190,0.00000,0.00638,161.15680
46.00000,2.29998,12978.87415,0.00000,0.00641,161.89352
46.20000,2.31003,13038.07348,0.00000,0.00644,162.63195
46.40000,2.32001,13096.53372,0.00000,0.00648,163.36116
46.60000,2.33006,13154.48880,0.00000,0.00651,164.08407
46.80000,2.34004,13210.89566,0.00000,0.00655,164.78767
47.00000,2.35009,13269.80442,0.00000,0.00658,165.52248
47.20000,2.36007,13327.52854,0.00000,0.00661,166.24250
47.40000,2.36994,13384.50760,0.00000,0.00664,166.95324
47.60000,2.38004,13443.40295,0.00000,0.00668,167.68788
47.80000,2.39003,13504.01491,0.00000,0.00671,168.44393
48.00000,2.40001,13561.29199,0.00000,0.00674,169.15838
48.20000,2.40999,13619.07125,0.00000,0.00678,169.87910
48.40000,2.41998,13678.43151,0.00000,0.00682,170.61953
48.60000,2.43002,13736.04685,0.00000,0.00685,171.33821
48.80000,2.43995,13795.07333,0.00000,0.00689,172.07448
49.00000,2.44999,13854.32482,0.00000,0.00692,172.81356
49.20000,2.45998,13913.25295,0.00000,0.00695,173.54861
49.40000,2.46990,13970.85637,0.00000,0.00699,174.26713
49.60000,2.47989,14029.89030,0.00000,0.00702,175.00350
49.80000,2.48993,14091.69734,0.00000,0.00706,175.77445
50.00000,2.49998,14149.85806,0.00000,0.00709,176.49993
50.20000,2.50990,14208.09329,0.00000,0.00712,177.22633
50.40000,2.52001,14266.84558,0.00000,0.00716,177.95919
50.60000,2.52999,14325.34903,0.00000,0.00720,178.68894
50.80000,2.53998,14385.60635,0.00000,0.00723,179.44056
51.00000,2.55002,14442.71803,0.00000,0.00726,180.15295
51.20000,2.56001,14502.56556,0.00000,0.00730,180.89947
51.40000,2.57011,14562.03014,0.00000,0.00733,181.64121
51.60000,2.58004,14618.95555,0.00000,0.00737,182.35127
51.80000,2.59008,14678.00289,0.00000,0.00740,183.08781
52.00000,2.60007,14735.43495,0.00000,0.00744,183.80419
52.20000,2.61005,14793.63590,0.00000,0.00747,184.53017
52.40000,2.62004,14851.40920,0.00000,0.00751,185.25081
52.60000,2.63002,14908.71608,0.00000,0.00754,185.96563
52.80000,2.64000,14967.13012,0.00000,0.00757,186.69427
53.00000,2.64999,15024.94365,0.00000,0.00760,187.41541
53.20000,2.66003,15084.95063,0.00000,0.00764,188.16392
53.40000,2.67002,15144.34516,0.00000,0.00767,188.90478
53.60000,2.68000,15203.98557,0.00000,0.00771,189.64871
53.80000,2.68999,15260.64128,0.00000,0.00774,190.35541
54.00000,2.69985,15318.82435,0.00000,0.00778,191.08117
54.20000,2.70996,15379.51976,0.00000,0.00781,191.83826
54.40000,2.71994,15437.08742,0.00000,0.00785,192.55634
54.60000,2.72987,15497.05863,0.00000,0.00789,193.30439
54.80000,2.73991,15556.26392,0.00000,0.00792,194.04290
55.00000,2.74996,15615.61376,0.00000,0.00795,194.78321
55.20000,2.76000,15674.29155,0.00000,0.00799,195.51513
55.40000,2.76999,15732.82629,0.00000,0.00803,196.24527
55.60000,2.77997,15792.58293,0.00000,0.00806,196.99065
55.80000,2.79008,15849.48599,0.00000,0.00810,197.70044
56.00000,2.80000,15907.55731,0.00000,0.00813,198.42480
56.20000,2.81005,15966.33345,0.00000,0.00817,199.15795
56.40000,2.82003,16025.07979,0.00000,0.00820,199.89073
56.60000,2.83002,16082.56251,0.00000,0.00823,200.60775
56.80000,2.84000,16140.96612,0.00000,0.00827,201.33625
57.00000,2.84993,16199.25797,0.00000,0.00831,202.06336
57.20000,2.86003,16256.73771,0.00000,0.00834,202.78034
57.40000,2.87002,16315.90575,0.00000,0.00837,203.51838
57.60000,2.88006,16375.32264,0.00000,0.00841,204.25952
57.80000,2.88999,16432.60419,0.00000,0.00845,204.97403
58.00000,2.90003,16492.19692,0.00000,0.00848,205.71737
58.20000,2.91001,16551.09376,0.00000,0.00851,206.45203
58.40000,2.91988,16611.38982,0.00000,0.00855,207.20414
58.60000,2.92998,16670.37308,0.00000,0.00858,207.93987
58.80000,2.93991,16729.16561,0.00000,0.00862,208.67323
59.00000,2.94995,16788.63317,0.00000,0.00866,209.41500
59.20000,2.95994,16847.17387,0.00000,0.00869,210.14522
59.40000,2.96992,16906.93498,0.00000,0.00873,210.89065
59.60000,2.97997,16966.30418,0.00000,0.00876,211.63120
59.80000,2.98989,17025.68531,0.00000,0.00879,212.37190
60.00000,2.99994,17083.65381,0.00000,0.00883,213.09498
60.20000,3.00998,17142.98278,0.00000,0.00887,213.83502
60.40000,3.02003,17203.23712,0.00000,0.00890,214.58661
60.60000,3.03001,17260.94186,0.00000,0.00894,215.30640
60.80000,3.04006,17318.63916,0.00000,0.00897,216.02609
61.00000,3.05010,17377.18731,0.00000,0.00901,216.75640
61.20000,3.06009,17437.05869,0.00000,0.00905,217.50321
61.40000,3.07007,17494.46839,0.00000,0.00908,218.21932
61.60000,3.07994,17552.62166,0.00000,0.00912,218.94470
61.80000,3.08998,17613.08759,0.00000,0.00916,219.69893
62.00000,3.10009,17671.20212,0.00000,0.00919,220.42383
62.20000,3.10995,17731.02731,0.00000,0.00923,221.17007
62.40000,3.12005,17790.90315,0.00000,0.00926,221.91694
62.60000,3.12998,17849.65247,0.00000,0.00930,222.64975
62.80000,3.14002,17908.41073,0.00000,0.00934,223.38268
63.00000,3.15001,17967.21965,0.00000,0.00937,224.11624
63.20000,3.15993,18029.18017,0.00000,0.00941,224.88911
63.40000,3.16992,18087.17102,0.00000,0.00945,225.61247
63.60000,3.17984,18146.66241,0.00000,0.00948,226.35454
63.80000,3.18995,18206.78413,0.00000,0.00952,227.10448
64.00000,3.19987,18264.31006,0.00000,0.00955,227.82203
64.20000,3.20998,18324.67020,0.00000,0.00959,228.57494
64.40000,3.21990,18383.62962,0.00000,0.00963,229.31038
64.60000,3.22989,18443.12251,0.00000,0.00966,230.05247
64.80000,3.23999,18502.61241,0.00000,0.00970,230.79452
65.00000,3.24992,18559.39478,0.00000,0.00973,231.50281
65.20000,3.26002,18620.58938,0.00000,0.00977,232.26612
65.40000,3.27001,18679.27164,0.00000,0.00981,232.99810
65.60000,3.28005,18738.28173,0.00000,0.00984,233.73417
65.80000,3.29010,18797.30672,0.00000,0.00988,234.47043
66.00000,3.30002,18856.72957,0.00000,0.00992,235.21165
66.20000,3.31007,18915.11083,0.00000,0.00995,235.93987
66.40000,3.31999,18972.74107,0.00000,0.00998,236.65873
66.60000,3.33004,19032.68844,0.00000,0.01003,237.40649
66.80000,3.34008,19092.27371,0.00000,0.01006,238.14973
67.00000,3.35001,19151.58182,0.00000,0.01010,238.88952
67.20000,3.36005,19210.42800,0.00000,0.01014,239.62355
67.40000,3.36997,19269.19818,0.00000,0.01017,240.35662
67.60000,3.38002,19329.75948,0.00000,0.01021,241.11204
67.80000,3.38994,19386.53141,0.00000,0.01024,241.82019
68.00000,3.39987,19446.90943,0.00000,0.01028,242.57333
68.20000,3.40991,19506.06406,0.00000,0.01032,243.31120
68.40000,3.41990,19564.43042,0.00000,0.01036,244.03924
68.60000,3.42994,19623.26020,0.00000,0.01039,244.77306
68.80000,3.43987,19683.70676,0.00000,0.01043,245.52704
69.00000,3.44991,19743.69138,0.00000,0.01047,246.27527
69.20000,3.45990,19800.07291,0.00000,0.01051,246.97855
69.40000,3.46988,19859.87872,0.00000,0.01054,247.72455
69.60000,3.47999,19919.19726,0.00000,0.01057,248.46446
69.80000,3.48997,19977.72008,0.00000,0.01061,249.19445
70.00000,3.50008,20035.99703,0.00000,0.01065,249.92138
70.20000,3.51000,20094.09070,0.00000,0.01068,250.64602
70.40000,3.52005,20153.02032,0.00000,0.01072,251.38108
70.60000,3.53015,20212.01700,0.00000,0.01076,252.11699
70.80000,3.54008,20272.19385,0.00000,0.01079,252.86761
71.00000,3.55012,20331.47216,0.00000,0.01083,253.60702
71.20000,3.56005,20389.69547,0.00000,0.01087,254.33328
71.40000,3.57003,20449.04977,0.00000,0.01091,255.07364
71.60000,3.58002,20507.34609,0.00000,0.01094,255.80081
71.80000,3.59000,20567.54082,0.00000,0.01098,256.55165
72.00000,3.60004,20626.37955,0.00000,0.01102,257.28559
72.20000,3.60991,20683.35414,0.00000,0.01105,257.99626
72.40000,3.61995,20742.94686,0.00000,0.01109,258.73960
72.60000,3.62988,20801.38773,0.00000,0.01113,259.46857
72.80000,3.63992,20861.49454,0.00000,0.01116,260.21832
73.00000,3.64991,20920.79371,0.00000,0.01120,260.95800
73.20000,3.65983,20978.96188,0.00000,0.01124,261.68356
73.40000,3.66994,21037.55027,0.00000,0.01128,262.41437
73.60000,3.67986,21096.29959,0.00000,0.01131,263.14719
73.80000,3.68991,21156.38256,0.00000,0.01135,263.89664
74.00000,3.69995,21214.09476,0.00000,0.01139,264.61652
74.20000,3.70994,21274.97792,0.00000,0.01142,265.37595
74.40000,3.72010,21334.60045,0.00000,0.01146,266.11966
74.60000,3.72997,21393.24993,0.00000,0.01150,266.85123
74.80000,3.74007,21452.12442,0.00000,0.01154,267.58561
75.00000,3.75006,21508.64303,0.00000,0.01157,268.29060
75.20000,3.76016,21569.59921,0.00000,0.01160,269.05095
75.40000,3.77015,21626.21617,0.00000,0.01164,269.75717
75.60000,3.78007,21685.96387,0.00000,0.01168,270.50244
75.80000,3.79012,21745.21536,0.00000,0.01172,271.24152
76.00000,3.79998,21802.96034,0.00000,0.01175,271.96180
76.20000,3.81009,21864.25328,0.00000,0.01179,272.72635
76.40000,3.82007,21923.51669,0.00000,0.01183,273.46558
76.60000,3.83006,21983.74271,0.00000,0.01187,274.21682
76.80000,3.84004,22041.21053,0.00000,0.01191,274.93365
77.00000,3.84996,22099.58285,0.00000,0.01194,275.66176
77.20000,3.86001,22159.79397,0.00000,0.01198,276.41281
77.40000,3.86987,22217.18729,0.00000,0.01202,277.12871
77.60000,3.87992,22277.27026,0.00000,0.01206,277.87817
77.80000,3.88990,22335.90186,0.00000,0.01209,278.60951
78.00000,3.89983,22394.30994,0.00000,0.01213,279.33807
78.20000,3.90993,22453.62103,0.00000,0.01217,280.07790
78.40000,3.91986,22513.42386,0.00000,0.01221,280.82386
78.60000,3.92996,22572.42203,0.00000,0.01225,281.55978
78.80000,3.93995,22629.57990,0.00000,0.01229,282.27274
79.00000,3.94999,22689.89533,0.00000,0.01232,283.02509
79.20000,3.96004,22750.57733,0.00000,0.01236,283.78202
79.40000,3.97002,22811.59014,0.00000,0.01240,284.54307
79.60000,3.98013,22871.12772,0.00000,0.01244,285.28572
79.80000,3.98999,22928.75350,0.00000,0.01248,286.00452
80.00000,4.00010,22990.47709,0.00000,0.01252,286.77444
80.20000,4.01014,23049.31134,0.00000,0.01256,287.50831
80.40000,4.02013,23109.55822,0.00000,0.01260,288.25981
80.60000,4.03011,23167.58931,0.00000,0.01263,288.98367
80.80000,4.03998,23225.44008,0.00000,0.01266,289.70527
81.00000,4.05008,23285.43365,0.00000,0.01270,290.45361
81.20000,4.06001,23343.26059,0.00000,0.01274,291.17492
81.40000,4.06999,23403.86659,0.00000,0.01278,291.93090
81.60000,4.08003,23462.66955,0.00000,0.01282,292.66438
81.80000,4.08990,23520.29979,0.00000,0.01285,293.38324
82.00000,4.10000,23581.00414,0.00000,0.01289,294.14044
82.20000,4.10981,23638.33636,0.00000,0.01293,294.85558
82.40000,4.11991,23697.23469,0.00000,0.01296,295.59026
82.60000,4.12990,23754.84407,0.00000,0.01300,296.30886
82.80000,4.13988,23815.36514,0.00000,0.01304,297.06377
83.00000,4.14993,23875.40489,0.00000,0.01308,297.81269
83.20000,4.15991,23933.96646,0.00000,0.01312,298.54316
83.40000,4.16996,23994.42941,0.00000,0.01316,299.29735
83.60000,4.17988,24054.48854,0.00000,0.01320,300.04651
83.80000,4.18999,24114.30478,0.00000,0.01324,300.79263
84.00000,4.20003,24174.18659,0.00000,0.01328,301.53958
84.20000,4.21002,24233.65116,0.00000,0.01331,302.28131
84.40000,4.22006,24290.97742,0.00000,0.01335,302.99638
84.60000,4.22999,24348.24705,0.00000,0.01339,303.71074
84.80000,4.24009,24408.75471,0.00000,0.01343,304.46549
85.00000,4.25008,24469.18339,0.00000,0.01347,305.21925
85.20000,4.26006,24527.82243,0.00000,0.01351,305.95069
85.40000,4.27011,24585.06525,0.00000,0.01354,306.66472
85.60000,4.27997,24642.59267,0.00000,0.01358,307.38229
85.80000,4.29008,24701.58190,0.00000,0.01362,308.11810
86.00000,4.30000,24759.85736,0.00000,0.01366,308.84501
86.20000,4.31005,24820.34564,0.00000,0.01370,309.59952
86.40000,4.31997,24876.84935,0.00000,0.01374,310.30432
86.60000,4.32990,24935.12034,0.00000,0.01377,311.03117
86.80000,4.34000,24993.37941,0.00000,0.01381,311.75787
87.00000,4.34986,25051.34940,0.00000,0.01385,312.48097
87.20000,4.35997,25111.35340,0.00000,0.01389,313.22944
87.40000,4.36983,25167.22083,0.00000,0.01393,313.92631
87.60000,4.37994,25228.78051,0.00000,0.01396,314.69418
87.80000,4.38992,25286.78179,0.00000,0.01400,315.41766
88.00000,4.39985,25344.29729,0.00000,0.01404,316.13509
88.20000,4.41001,25404.81985,0.00000,0.01408,316.89003
88.40000,4.41994,25463.50956,0.00000,0.01412,317.62210
88.60000,4.42998,25523.52250,0.00000,0.01416,318.37068
88.80000,4.43997,25582.93939,0.00000,0.01420,319.11182
89.00000,4.44995,25642.03143,0.00000,0.01424,319.84891
89.20000,4.46012,25701.55263,0.00000,0.01428,320.59136
89.40000,4.46998,25757.82537,0.00000,0.01431,321.29328
89.60000,4.48009,25817.25121,0.00000,0.01435,322.03454
89.80000,4.49007,25875.21672,0.00000,0.01439,322.75758
90.00000,4.50006,25934.64255,0.00000,0.01443,323.49883
90.20000,4.51004,25990.72754,0.00000,0.01447,324.19841
90.40000,4.52003,26049.56031,0.00000,0.01450,324.93227
90.60000,4.53007,26108.02948,0.00000,0.01454,325.66159
90.80000,4.54000,26163.49757,0.00000,0.01458,326.35348
91.00000,4.54998,26220.11602,0.00000,0.01462,327.05972
91.20000,4.55996,26277.06528,0.00000,0.01466,327.77008
91.40000,4.56989,26333.81486,0.00000,0.01469,328.47795
91.60000,4.57999,26391.41381,0.00000,0.01473,329.19642
91.80000,4.58986,26447.60907,0.00000,0.01477,329.89738
92.00000,4.59996,26506.40607,0.00000,0.01481,330.63079
92.20000,4.60983,26561.54335,0.00000,0.01485,331.31855
92.40000,4.61987,26618.88003,0.00000,0.01488,332.03375
92.60000,4.62998,26676.24652,0.00000,0.01492,332.74932
92.80000,4.63996,26734.36105,0.00000,0.01496,333.47422
93.00000,4.65001,26790.21060,0.00000,0.01500,334.17086
93.20000,4.65987,26845.65485,0.00000,0.01503,334.86245
93.40000,4.66998,26905.36082,0.00000,0.01507,335.60720
93.60000,4.67996,26963.05215,0.00000,0.01511,336.32682
93.80000,4.69001,27021.25907,0.00000,0.01515,337.05287
94.00000,4.70005,27077.41857,0.00000,0.01519,337.75338
94.20000,4.70998,27133.44395,0.00000,0.01523,338.45222
94.40000,4.72008,27188.39347,0.00000,0.01527,339.13764
94.60000,4.73001,27237.72824,0.00000,0.01530,339.75303
94.80000,4.74005,27268.43655,0.00000,0.01533,340.13607
94.85000,4.74256,26230.27563,0.00000,0.01472,327.18645
94.85400,4.74304,24127.47890,0.00000,0.01300,300.95696
94.85800,4.74370,21383.81153,0.00000,0.01023,266.73350
94.86200,4.74466,18329.11521,0.00000,0.00643,228.63039
94.86600,4.74549,15216.96597,0.00000,0.00205,189.81063