File: scratch/college-stuff/ME Lab/ME lab Fall 2013/group9/group9.is_tens_RawData/Specimen_RawData_3.csv
Time,Extension,Load,Strain 2,Tensile strain,Tensile stress
(sec),(mm),(N),(mm/mm),(mm/mm),(MPa)
0.00000,0.00006,-0.08872,0.00000,0.00000,-0.00147
0.10000,0.00155,2.79770,0.00000,0.00000,0.04621
0.20000,0.00723,8.20393,0.00000,0.00000,0.13550
0.30000,0.01357,9.68456,0.00000,0.00001,0.15995
0.40000,0.01943,10.33440,0.00000,0.00000,0.17068
0.50000,0.02469,11.54166,0.00000,0.00001,0.19062
0.60000,0.02989,12.62737,0.00000,0.00001,0.20855
0.70000,0.03498,14.73588,0.00000,0.00001,0.24338
0.80000,0.04006,19.78775,0.00000,0.00000,0.32681
0.90000,0.04502,24.86598,0.00000,0.00001,0.41069
1.00000,0.05004,28.04807,0.00000,0.00001,0.46324
1.10000,0.05495,32.28925,0.00000,0.00001,0.53329
1.20000,0.06003,34.49206,0.00000,0.00001,0.56967
1.30000,0.06505,38.73978,0.00000,0.00001,0.63982
1.40000,0.06995,41.37389,0.00000,0.00001,0.68333
1.50000,0.07504,44.60820,0.00000,0.00001,0.73675
1.60000,0.07994,48.59760,0.00000,0.00000,0.80264
1.70000,0.08514,53.03712,0.00000,0.00000,0.87596
1.80000,0.08998,56.32681,0.00000,0.00000,0.93029
1.90000,0.09513,59.47517,0.00000,0.00000,0.98229
2.00000,0.09997,61.89382,0.00000,-0.00001,1.02224
2.10000,0.10511,65.95748,0.00000,-0.00001,1.08935
2.20000,0.10995,68.34538,0.00000,-0.00001,1.12879
2.30000,0.11509,74.00660,0.00000,-0.00001,1.22229
2.40000,0.11988,79.40388,0.00000,-0.00002,1.31143
2.50000,0.12502,87.93725,0.00000,-0.00002,1.45237
2.60000,0.12992,97.36525,0.00000,-0.00002,1.60808
2.70000,0.13512,107.61607,0.00000,-0.00002,1.77738
2.80000,0.13997,118.26394,0.00000,-0.00002,1.95324
2.90000,0.14505,129.36254,0.00000,-0.00002,2.13655
3.00000,0.14989,141.36643,0.00000,-0.00003,2.33480
3.10000,0.15503,154.79225,0.00000,-0.00003,2.55654
3.20000,0.16000,169.71382,0.00000,-0.00003,2.80299
3.30000,0.16496,185.80540,0.00000,-0.00003,3.06875
3.40000,0.16992,205.89808,0.00000,-0.00003,3.40060
3.50000,0.17494,224.61095,0.00000,-0.00002,3.70967
3.60000,0.18003,245.32808,0.00000,-0.00002,4.05183
3.70000,0.18499,266.04992,0.00000,-0.00002,4.39407
3.80000,0.19007,287.75171,0.00000,-0.00002,4.75250
3.90000,0.19491,309.43444,0.00000,-0.00001,5.11061
4.00000,0.20012,333.62762,0.00000,-0.00001,5.51018
4.10000,0.20496,355.20946,0.00000,0.00000,5.86662
4.20000,0.21010,380.40059,0.00000,0.00001,6.28268
4.30000,0.21494,404.49267,0.00000,0.00001,6.68058
4.40000,0.22003,436.37631,0.00000,0.00002,7.20717
4.50000,0.22493,467.56361,0.00000,0.00003,7.72226
4.60000,0.23007,501.13085,0.00000,0.00004,8.27666
4.70000,0.23497,533.34357,0.00000,0.00006,8.80868
4.80000,0.24000,571.45730,0.00000,0.00008,9.43817
4.90000,0.24490,611.45211,0.00000,0.00009,10.09872
5.00000,0.25004,652.02955,0.00000,0.00011,10.76889
5.10000,0.25500,692.62772,0.00000,0.00013,11.43941
5.20000,0.26002,732.18094,0.00000,0.00015,12.09267
5.30000,0.26493,773.10526,0.00000,0.00017,12.76857
5.40000,0.27001,813.30137,0.00000,0.00018,13.43245
5.50000,0.27497,855.11440,0.00000,0.00020,14.12303
5.60000,0.28005,893.27497,0.00000,0.00022,14.75329
5.70000,0.28496,933.86769,0.00000,0.00024,15.42372
5.80000,0.28998,975.19616,0.00000,0.00026,16.10630
5.90000,0.29500,1020.05256,0.00000,0.00028,16.84715
6.00000,0.30002,1061.66396,0.00000,0.00030,17.53440
6.10000,0.30505,1105.53103,0.00000,0.00032,18.25890
6.20000,0.30995,1147.43207,0.00000,0.00034,18.95094
6.30000,0.31503,1191.25675,0.00000,0.00037,19.67475
6.40000,0.31987,1233.79929,0.00000,0.00039,20.37738
6.50000,0.32508,1279.89491,0.00000,0.00041,21.13869
6.60000,0.32986,1321.82324,0.00000,0.00044,21.83118
6.70000,0.33506,1368.48288,0.00000,0.00046,22.60181
6.80000,0.33984,1411.37782,0.00000,0.00048,23.31026
6.90000,0.34505,1457.72370,0.00000,0.00051,24.07570
7.00000,0.34995,1499.86800,0.00000,0.00053,24.77176
7.10000,0.35503,1543.99695,0.00000,0.00056,25.50059
7.20000,0.35987,1587.89288,0.00000,0.00058,26.22557
7.30000,0.36496,1633.07544,0.00000,0.00060,26.97181
7.40000,0.36992,1678.08123,0.00000,0.00062,27.71512
7.50000,0.37506,1720.91834,0.00000,0.00065,28.42262
7.60000,0.37990,1764.54727,0.00000,0.00067,29.14319
7.70000,0.38498,1807.67607,0.00000,0.00070,29.85550
7.80000,0.38989,1852.91786,0.00000,0.00072,30.60271
7.90000,0.39497,1895.51469,0.00000,0.00075,31.30624
8.00000,0.39999,1940.84626,0.00000,0.00077,32.05494
8.10000,0.40495,1981.72741,0.00000,0.00080,32.73013
8.20000,0.40998,2026.90121,0.00000,0.00082,33.47622
8.30000,0.41494,2068.75596,0.00000,0.00084,34.16749
8.40000,0.42002,2112.26176,0.00000,0.00087,34.88603
8.50000,0.42498,2153.10808,0.00000,0.00089,35.56064
8.60000,0.43007,2198.69670,0.00000,0.00092,36.31358
8.70000,0.43491,2239.52010,0.00000,0.00094,36.98782
8.80000,0.44005,2284.21949,0.00000,0.00096,37.72607
8.90000,0.44489,2324.12498,0.00000,0.00099,38.38515
9.00000,0.45010,2367.25397,0.00000,0.00101,39.09747
9.10000,0.45488,2407.77619,0.00000,0.00103,39.76673
9.20000,0.46002,2449.78908,0.00000,0.00105,40.46061
9.30000,0.46492,2490.82912,0.00000,0.00108,41.13843
9.40000,0.47012,2532.83810,0.00000,0.00110,41.83225
9.50000,0.47491,2571.85306,0.00000,0.00112,42.47662
9.60000,0.47999,2612.74800,0.00000,0.00115,43.15204
9.70000,0.48489,2652.29288,0.00000,0.00116,43.80516
9.80000,0.49003,2691.73477,0.00000,0.00119,44.45658
9.90000,0.49494,2732.18732,0.00000,0.00121,45.12469
10.00000,0.50002,2771.05663,0.00000,0.00123,45.76666
10.10000,0.50492,2811.29330,0.00000,0.00126,46.43120
10.20000,0.51000,2848.94910,0.00000,0.00128,47.05313
10.30000,0.51503,2890.11355,0.00000,0.00130,47.73300
10.40000,0.52005,2927.73675,0.00000,0.00132,48.35438
10.50000,0.52501,2967.26488,0.00000,0.00134,49.00722
10.60000,0.52997,3004.22795,0.00000,0.00136,49.61770
10.70000,0.53500,3042.61297,0.00000,0.00138,50.25167
10.80000,0.53996,3080.05847,0.00000,0.00141,50.87012
10.90000,0.54504,3119.38226,0.00000,0.00143,51.51959
11.00000,0.54988,3155.58240,0.00000,0.00145,52.11747
11.10000,0.55503,3193.66008,0.00000,0.00147,52.74636
11.20000,0.55987,3227.85713,0.00000,0.00149,53.31115
11.30000,0.56507,3266.57444,0.00000,0.00151,53.95061
11.40000,0.56991,3301.82016,0.00000,0.00153,54.53272
11.50000,0.57506,3339.76261,0.00000,0.00156,55.15938
11.60000,0.57990,3373.43365,0.00000,0.00158,55.71549
11.70000,0.58504,3408.91592,0.00000,0.00160,56.30151
11.80000,0.58994,3443.71833,0.00000,0.00162,56.87631
11.90000,0.59503,3478.97112,0.00000,0.00163,57.45854
12.00000,0.59987,3514.28837,0.00000,0.00166,58.04184
12.10000,0.60495,3549.05277,0.00000,0.00167,58.61601
12.20000,0.60991,3583.12465,0.00000,0.00170,59.17874
12.30000,0.61499,3616.07485,0.00000,0.00171,59.72294
12.40000,0.61990,3649.86882,0.00000,0.00173,60.28108
12.50000,0.62498,3683.30739,0.00000,0.00175,60.83335
12.60000,0.63000,3717.91050,0.00000,0.00177,61.40486
12.70000,0.63502,3748.83302,0.00000,0.00179,61.91557
12.80000,0.64005,3783.17870,0.00000,0.00181,62.48282
12.90000,0.64495,3812.92179,0.00000,0.00183,62.97406
13.00000,0.65003,3846.57793,0.00000,0.00184,63.52992
13.10000,0.65493,3876.51995,0.00000,0.00186,64.02444
13.20000,0.66008,3909.21906,0.00000,0.00188,64.56450
13.30000,0.66492,3937.92056,0.00000,0.00190,65.03853
13.40000,0.67006,3970.34697,0.00000,0.00192,65.57409
13.50000,0.67490,3997.43915,0.00000,0.00194,66.02154
13.60000,0.68011,4028.51999,0.00000,0.00195,66.53487
13.70000,0.68495,4056.74651,0.00000,0.00197,67.00106
13.80000,0.69009,4086.94521,0.00000,0.00199,67.49982
13.90000,0.69493,4116.12466,0.00000,0.00200,67.98174
14.00000,0.70008,4144.50504,0.00000,0.00202,68.45047
14.10000,0.70498,4173.08882,0.00000,0.00204,68.92256
14.20000,0.71012,4200.97932,0.00000,0.00205,69.38320
14.30000,0.71490,4226.76057,0.00000,0.00207,69.80900
14.40000,0.72004,4254.25060,0.00000,0.00209,70.26303
14.50000,0.72489,4279.36949,0.00000,0.00210,70.67789
14.60000,0.73009,4306.82413,0.00000,0.00212,71.13133
14.70000,0.73499,4332.34945,0.00000,0.00213,71.55290
14.80000,0.74007,4357.72091,0.00000,0.00215,71.97194
14.90000,0.74498,4383.77559,0.00000,0.00216,72.40226
15.00000,0.75006,4405.50968,0.00000,0.00217,72.76122
15.10000,0.75502,4426.82132,0.00000,0.00219,73.11320
15.20000,0.75998,4447.44714,0.00000,0.00220,73.45385
15.30000,0.76501,4471.90031,0.00000,0.00222,73.85772
15.40000,0.76997,4492.20911,0.00000,0.00223,74.19314
15.50000,0.77499,4515.58568,0.00000,0.00224,74.57923
15.60000,0.77995,4536.95208,0.00000,0.00225,74.93211
15.70000,0.78504,4560.96642,0.00000,0.00227,75.32873
15.80000,0.78994,4581.56765,0.00000,0.00228,75.66898
15.90000,0.79502,4605.83605,0.00000,0.00229,76.06980
16.00000,0.79998,4625.68924,0.00000,0.00231,76.39769
16.10000,0.80513,4647.68298,0.00000,0.00232,76.76094
16.20000,0.80991,4666.71921,0.00000,0.00233,77.07534
16.30000,0.81511,4689.76647,0.00000,0.00235,77.45599
16.40000,0.81989,4709.18790,0.00000,0.00236,77.77675
16.50000,0.82509,4731.17791,0.00000,0.00237,78.13994
16.60000,0.82988,4751.32503,0.00000,0.00238,78.47269
16.70000,0.83502,4773.60412,0.00000,0.00240,78.84065
16.80000,0.83986,4793.50090,0.00000,0.00241,79.16926
16.90000,0.84500,4815.48049,0.00000,0.00242,79.53228
17.00000,0.84997,4835.91668,0.00000,0.00243,79.86980
17.10000,0.85505,4857.28942,0.00000,0.00245,80.22279
17.20000,0.85995,4879.25820,0.00000,0.00246,80.58563
17.30000,0.86497,4900.02073,0.00000,0.00248,80.92854
17.40000,0.87000,4924.14348,0.00000,0.00249,81.32695
17.50000,0.87502,4945.63691,0.00000,0.00250,81.68193
17.60000,0.88004,4969.40985,0.00000,0.00252,82.07457
17.70000,0.88494,4990.38361,0.00000,0.00253,82.42097
17.80000,0.89003,5013.18872,0.00000,0.00255,82.79762
17.90000,0.89499,5035.20928,0.00000,0.00256,83.16131
18.00000,0.90013,5058.01253,0.00000,0.00257,83.53793
18.10000,0.90497,5079.73917,0.00000,0.00259,83.89676
18.20000,0.91012,5105.10430,0.00000,0.00260,84.31569
18.30000,0.91496,5125.41980,0.00000,0.00261,84.65122
18.40000,0.92010,5148.74049,0.00000,0.00263,85.03638
18.50000,0.92500,5170.04356,0.00000,0.00264,85.38823
18.60000,0.93009,5194.40174,0.00000,0.00265,85.79052
18.70000,0.93493,5216.87008,0.00000,0.00267,86.16161
18.80000,0.94007,5239.79813,0.00000,0.00268,86.54029
18.90000,0.94491,5261.91145,0.00000,0.00270,86.90551
19.00000,0.95006,5286.51513,0.00000,0.00271,87.31186
19.10000,0.95490,5309.12057,0.00000,0.00273,87.68522
19.20000,0.95998,5333.19153,0.00000,0.00273,88.08277
19.30000,0.96494,5355.92884,0.00000,0.00275,88.45830
19.40000,0.97008,5379.96888,0.00000,0.00277,88.85534
19.50000,0.97493,5402.89767,0.00000,0.00278,89.23403
19.60000,0.98001,5426.54172,0.00000,0.00279,89.62454
19.70000,0.98491,5449.34534,0.00000,0.00281,90.00116
19.80000,0.98999,5471.41619,0.00000,0.00282,90.36568
19.90000,0.99502,5496.20129,0.00000,0.00284,90.77503
20.00000,0.99998,5517.83517,0.00000,0.00285,91.13234
20.10000,1.00500,5544.33092,0.00000,0.00287,91.56994
20.20000,1.00996,5565.06813,0.00000,0.00288,91.91243
20.30000,1.01505,5591.05910,0.00000,0.00289,92.34170
20.40000,1.02001,5614.11083,0.00000,0.00290,92.72242
20.50000,1.02503,5638.61951,0.00000,0.00292,93.12721
20.60000,1.02987,5660.67584,0.00000,0.00293,93.49149
20.70000,1.03508,5685.37228,0.00000,0.00295,93.89937
20.80000,1.03992,5707.36341,0.00000,0.00296,94.26258
20.90000,1.04506,5731.56439,0.00000,0.00298,94.66228
21.00000,1.04990,5755.15702,0.00000,0.00299,95.05193
21.10000,1.05499,5780.96062,0.00000,0.00301,95.47811
21.20000,1.05989,5803.93262,0.00000,0.00302,95.85751
21.30000,1.06509,5828.43944,0.00000,0.00303,96.26226
21.40000,1.06993,5852.30961,0.00000,0.00305,96.65650
21.50000,1.07502,5878.12066,0.00000,0.00307,97.08280
21.60000,1.07992,5900.93732,0.00000,0.00308,97.45964
21.70000,1.08500,5925.08987,0.00000,0.00309,97.85854
21.80000,1.09002,5949.55869,0.00000,0.00311,98.26266
21.90000,1.09504,5972.54038,0.00000,0.00312,98.64223
22.00000,1.09995,5997.66970,0.00000,0.00314,99.05726
22.10000,1.10503,6021.11071,0.00000,0.00315,99.44441
22.20000,1.10999,6044.83150,0.00000,0.00316,99.83619
22.30000,1.11501,6067.54683,0.00000,0.00318,100.21135
22.40000,1.12004,6093.09152,0.00000,0.00319,100.63325
22.50000,1.12500,6116.34888,0.00000,0.00321,101.01736
22.60000,1.13008,6142.57529,0.00000,0.00322,101.45052
22.70000,1.13498,6165.10659,0.00000,0.00324,101.82264
22.80000,1.14007,6192.34517,0.00000,0.00326,102.27252
22.90000,1.14497,6215.09589,0.00000,0.00327,102.64827
23.00000,1.15005,6241.39756,0.00000,0.00329,103.08266
23.10000,1.15495,6263.96760,0.00000,0.00330,103.45543
23.20000,1.16010,6288.96505,0.00000,0.00332,103.86829
23.30000,1.16494,6312.82851,0.00000,0.00333,104.26241
23.40000,1.17008,6338.49800,0.00000,0.00335,104.68637
23.50000,1.17492,6361.94721,0.00000,0.00336,105.07366
23.60000,1.18007,6387.28589,0.00000,0.00338,105.49215
23.70000,1.18497,6410.85356,0.00000,0.00339,105.88139
23.80000,1.19005,6436.44631,0.00000,0.00341,106.30408
23.90000,1.19489,6459.97897,0.00000,0.00342,106.69274
24.00000,1.20003,6485.77362,0.00000,0.00344,107.11877
24.10000,1.20494,6509.60431,0.00000,0.00345,107.51235
24.20000,1.21008,6535.57703,0.00000,0.00347,107.94132
24.30000,1.21498,6559.16408,0.00000,0.00348,108.33088
24.40000,1.22000,6584.45731,0.00000,0.00350,108.74862
24.50000,1.22497,6610.22738,0.00000,0.00352,109.17424
24.60000,1.23005,6634.81951,0.00000,0.00353,109.58040
24.70000,1.23501,6659.95479,0.00000,0.00355,109.99554
24.80000,1.23997,6683.56568,0.00000,0.00357,110.38549
24.90000,1.24500,6710.62991,0.00000,0.00359,110.83249
25.00000,1.24990,6733.45178,0.00000,0.00360,111.20941
25.10000,1.25510,6761.09865,0.00000,0.00362,111.66603
25.20000,1.25994,6783.14194,0.00000,0.00363,112.03009
25.30000,1.26503,6811.53238,0.00000,0.00365,112.49899
25.40000,1.26987,6832.96770,0.00000,0.00367,112.85301
25.50000,1.27507,6860.58924,0.00000,0.00368,113.30921
25.60000,1.27991,6881.63266,0.00000,0.00369,113.65676
25.70000,1.28512,6908.58215,0.00000,0.00371,114.10186
25.80000,1.28990,6932.27127,0.00000,0.00373,114.49310
25.90000,1.29504,6958.64782,0.00000,0.00375,114.92874
26.00000,1.29994,6982.93149,0.00000,0.00376,115.32981
26.10000,1.30503,7008.63078,0.00000,0.00378,115.75426
26.20000,1.30993,7033.13351,0.00000,0.00379,116.15894
26.30000,1.31501,7059.46535,0.00000,0.00381,116.59384
26.40000,1.31991,7084.93814,0.00000,0.00383,117.01454
26.50000,1.32505,7109.24864,0.00000,0.00384,117.41606
26.60000,1.32996,7133.69697,0.00000,0.00386,117.81984
26.70000,1.33504,7158.17437,0.00000,0.00387,118.22411
26.80000,1.34000,7185.25127,0.00000,0.00390,118.67131
26.90000,1.34502,7210.66520,0.00000,0.00391,119.09105
27.00000,1.35005,7235.75801,0.00000,0.00393,119.50548
27.10000,1.35507,7258.92335,0.00000,0.00394,119.88808
27.20000,1.36003,7284.94376,0.00000,0.00396,120.31783
27.30000,1.36505,7309.53962,0.00000,0.00397,120.72405
27.40000,1.37002,7334.32323,0.00000,0.00399,121.13338
27.50000,1.37498,7357.66813,0.00000,0.00401,121.51894
27.60000,1.38006,7384.41050,0.00000,0.00403,121.96062
27.70000,1.38490,7408.01692,0.00000,0.00404,122.35050
27.80000,1.39005,7436.11529,0.00000,0.00406,122.81457
27.90000,1.39495,7458.95207,0.00000,0.00407,123.19174
28.00000,1.40009,7486.73230,0.00000,0.00409,123.65056
28.10000,1.40493,7510.45346,0.00000,0.00411,124.04234
28.20000,1.41002,7538.36855,0.00000,0.00412,124.50338
28.30000,1.41486,7561.82373,0.00000,0.00414,124.89077
28.40000,1.42006,7588.78365,0.00000,0.00415,125.33604
28.50000,1.42490,7613.02710,0.00000,0.00417,125.73644
28.60000,1.43005,7639.89985,0.00000,0.00419,126.18027
28.70000,1.43489,7665.14763,0.00000,0.00420,126.59726
28.80000,1.44003,7690.14433,0.00000,0.00422,127.01010
28.90000,1.44493,7715.12985,0.00000,0.00423,127.42276
29.00000,1.45007,7740.67566,0.00000,0.00426,127.84468
29.10000,1.45498,7766.19017,0.00000,0.00427,128.26607
29.20000,1.46000,7791.17346,0.00000,0.00428,128.67870
29.30000,1.46496,7817.86963,0.00000,0.00431,129.11961
29.40000,1.47004,7842.44537,0.00000,0.00431,129.52550
29.50000,1.47501,7868.68483,0.00000,0.00434,129.95887
29.60000,1.47997,7892.59896,0.00000,0.00435,130.35384
29.70000,1.48499,7919.57006,0.00000,0.00437,130.79929
29.80000,1.48989,7943.04088,0.00000,0.00439,131.18693
29.90000,1.49504,7970.31894,0.00000,0.00440,131.63746
30.00000,1.49994,7994.35005,0.00000,0.00442,132.03435
30.10000,1.50502,8021.45302,0.00000,0.00444,132.48199
30.20000,1.50992,8046.24856,0.00000,0.00445,132.89151
30.30000,1.51507,8072.64000,0.00000,0.00448,133.32739
30.40000,1.51991,8097.02873,0.00000,0.00448,133.73019
30.50000,1.52511,8124.14289,0.00000,0.00451,134.17801
30.60000,1.52989,8147.41179,0.00000,0.00452,134.56232
30.70000,1.53504,8173.18261,0.00000,0.00454,134.98795
30.80000,1.53994,8197.66149,0.00000,0.00456,135.39224
30.90000,1.54502,8222.60380,0.00000,0.00457,135.80418
31.00000,1.54992,8246.27504,0.00000,0.00459,136.19514
31.10000,1.55501,8273.20069,0.00000,0.00461,136.63984
31.20000,1.55991,8297.64754,0.00000,0.00463,137.04360
31.30000,1.56505,8323.70371,0.00000,0.00465,137.47395
31.40000,1.57001,8349.30465,0.00000,0.00466,137.89677
31.50000,1.57503,8374.19555,0.00000,0.00468,138.30787
31.60000,1.58000,8401.46542,0.00000,0.00470,138.75825
31.70000,1.58502,8426.28628,0.00000,0.00472,139.16819
31.80000,1.58998,8453.20597,0.00000,0.00473,139.61280
31.90000,1.59500,8477.54255,0.00000,0.00475,140.01474
32.00000,1.59997,8504.31323,0.00000,0.00477,140.45688
32.10000,1.60493,8528.32794,0.00000,0.00479,140.85351
32.20000,1.61001,8554.07938,0.00000,0.00480,141.27882
32.30000,1.61503,8578.36604,0.00000,0.00482,141.67994
32.40000,1.62012,8605.19931,0.00000,0.00484,142.12312
32.50000,1.62496,8630.01198,0.00000,0.00486,142.53292
32.60000,1.63004,8658.53280,0.00000,0.00487,143.00397
32.70000,1.63494,8681.45078,0.00000,0.00489,143.38248
32.80000,1.64009,8709.31745,0.00000,0.00491,143.84273
32.90000,1.64487,8731.99552,0.00000,0.00492,144.21728
33.00000,1.65001,8760.20491,0.00000,0.00494,144.68318
33.10000,1.65485,8783.00667,0.00000,0.00496,145.05977
33.20000,1.66006,8810.01130,0.00000,0.00498,145.50578
33.30000,1.66496,8835.15850,0.00000,0.00499,145.92111
33.40000,1.67004,8861.95600,0.00000,0.00502,146.36370
33.50000,1.67488,8888.07401,0.00000,0.00503,146.79506
33.60000,1.68003,8914.32837,0.00000,0.00505,147.22868
33.70000,1.68493,8940.29811,0.00000,0.00507,147.65759
33.80000,1.69001,8964.88428,0.00000,0.00508,148.06366
33.90000,1.69497,8992.14670,0.00000,0.00511,148.51392
34.00000,1.69993,9016.04444,0.00000,0.00512,148.90862
34.10000,1.70496,9042.83300,0.00000,0.00514,149.35105
34.20000,1.70998,9066.61525,0.00000,0.00516,149.74384
34.30000,1.71500,9093.68843,0.00000,0.00517,150.19098
34.40000,1.71996,9117.49527,0.00000,0.00519,150.58417
34.50000,1.72499,9144.66903,0.00000,0.00521,151.03297
34.60000,1.72995,9168.19349,0.00000,0.00523,151.42150
34.70000,1.73503,9194.81814,0.00000,0.00524,151.86124
34.80000,1.73987,9217.94027,0.00000,0.00526,152.24312
34.90000,1.74502,9246.96550,0.00000,0.00528,152.72250
35.00000,1.74986,9270.89080,0.00000,0.00530,153.11765
35.10000,1.75500,9297.37687,0.00000,0.00532,153.55509
35.20000,1.75990,9322.23275,0.00000,0.00533,153.96561
35.30000,1.76505,9348.50648,0.00000,0.00535,154.39955
35.40000,1.76989,9373.44357,0.00000,0.00537,154.81141
35.50000,1.77503,9398.81653,0.00000,0.00539,155.23046
35.60000,1.77993,9423.81546,0.00000,0.00541,155.64335
35.70000,1.78508,9449.93347,0.00000,0.00542,156.07471
35.80000,1.78998,9476.32939,0.00000,0.00545,156.51066
35.90000,1.79500,9502.50998,0.00000,0.00546,156.94306
36.00000,1.79996,9527.76894,0.00000,0.00548,157.36024
36.10000,1.80510,9553.78711,0.00000,0.00550,157.78995
36.20000,1.81001,9579.57059,0.00000,0.00552,158.21579
36.30000,1.81503,9604.28491,0.00000,0.00554,158.62397
36.40000,1.81993,9630.95278,0.00000,0.00556,159.06442
36.50000,1.82501,9655.02486,0.00000,0.00557,159.46199
36.60000,1.83004,9682.06301,0.00000,0.00559,159.90855
36.70000,1.83500,9707.14390,0.00000,0.00561,160.32279
36.80000,1.84002,9734.84665,0.00000,0.00563,160.78032
36.90000,1.84492,9759.88433,0.00000,0.00565,161.19384
37.00000,1.85001,9786.08727,0.00000,0.00567,161.62661
37.10000,1.85497,9810.75019,0.00000,0.00569,162.03394
37.20000,1.86005,9839.40214,0.00000,0.00571,162.50716
37.30000,1.86489,9863.53830,0.00000,0.00573,162.90579
37.40000,1.87004,9890.83350,0.00000,0.00575,163.35660
37.50000,1.87488,9914.54348,0.00000,0.00576,163.74819
37.60000,1.88008,9942.76702,0.00000,0.00578,164.21433
37.70000,1.88486,9966.00389,0.00000,0.00580,164.59811
37.80000,1.89007,9992.94296,0.00000,0.00582,165.04303
37.90000,1.89491,10016.78631,0.00000,0.00584,165.43683
38.00000,1.89999,10042.43493,0.00000,0.00585,165.86044
38.10000,1.90483,10067.38245,0.00000,0.00587,166.27247
38.20000,1.90998,10094.51598,0.00000,0.00589,166.72061
38.30000,1.91488,10121.13765,0.00000,0.00591,167.16029
38.40000,1.91996,10147.56188,0.00000,0.00593,167.59671
38.50000,1.92492,10172.85660,0.00000,0.00595,168.01448
38.60000,1.92994,10198.31598,0.00000,0.00596,168.43496
38.70000,1.93491,10225.54487,0.00000,0.00599,168.88468
38.80000,1.93999,10249.73691,0.00000,0.00600,169.28423
38.90000,1.94501,10277.52608,0.00000,0.00602,169.74319
39.00000,1.95003,10300.02162,0.00000,0.00604,170.11473
39.10000,1.95500,10328.19897,0.00000,0.00606,170.58011
39.20000,1.95996,10353.22174,0.00000,0.00608,170.99338
39.30000,1.96504,10381.17334,0.00000,0.00610,171.45503
39.40000,1.96994,10404.10176,0.00000,0.00611,171.83371
39.50000,1.97503,10429.85246,0.00000,0.00613,172.25901
39.60000,1.97987,10454.14507,0.00000,0.00615,172.66023
39.70000,1.98501,10482.25835,0.00000,0.00617,173.12454
39.80000,1.98991,10506.49732,0.00000,0.00619,173.52487
39.90000,1.99512,10534.41316,0.00000,0.00620,173.98593
40.00000,2.00002,10558.16039,0.00000,0.00622,174.37814
40.10000,2.00510,10585.87357,0.00000,0.00624,174.83585
40.20000,2.00994,10610.32638,0.00000,0.00626,175.23971
40.30000,2.01503,10637.03373,0.00000,0.00628,175.68081
40.40000,2.01993,10662.33218,0.00000,0.00630,176.09864
40.50000,2.02507,10689.47911,0.00000,0.00632,176.54699
40.60000,2.02991,10714.43558,0.00000,0.00634,176.95917
40.70000,2.03499,10742.78429,0.00000,0.00635,177.42738
40.80000,2.03996,10767.19612,0.00000,0.00638,177.83056
40.90000,2.04504,10794.37658,0.00000,0.00639,178.27948
41.00000,2.05000,10819.65119,0.00000,0.00641,178.69691
41.10000,2.05502,10845.20593,0.00000,0.00643,179.11897
41.20000,2.05999,10872.01610,0.00000,0.00645,179.56177
41.30000,2.06507,10895.86467,0.00000,0.00647,179.95565
41.40000,2.07003,10924.20146,0.00000,0.00649,180.42366
41.50000,2.07499,10947.45845,0.00000,0.00650,180.80777
41.60000,2.07996,10975.95990,0.00000,0.00653,181.27850
41.70000,2.08492,10999.19602,0.00000,0.00655,181.66227
41.80000,2.09000,11026.76392,0.00000,0.00657,182.11758
41.90000,2.09496,11050.96713,0.00000,0.00658,182.51731
42.00000,2.10005,11079.11989,0.00000,0.00660,182.98228
42.10000,2.10489,11103.89903,0.00000,0.00662,183.39154
42.20000,2.11009,11132.95481,0.00000,0.00665,183.87142
42.30000,2.11493,11156.80039,0.00000,0.00667,184.26525
42.40000,2.12008,11184.15222,0.00000,0.00668,184.71699
42.50000,2.12486,11208.76968,0.00000,0.00670,185.12358
42.60000,2.13000,11235.20806,0.00000,0.00672,185.56023
42.70000,2.13484,11259.85533,0.00000,0.00674,185.96730
42.80000,2.13999,11285.92566,0.00000,0.00676,186.39788
42.90000,2.14489,11311.86113,0.00000,0.00678,186.82623
43.00000,2.14997,11338.31367,0.00000,0.00680,187.26312
43.10000,2.15487,11364.64924,0.00000,0.00682,187.69808
43.20000,2.16001,11390.85144,0.00000,0.00684,188.13083
43.30000,2.16498,11416.31529,0.00000,0.00686,188.55139
43.40000,2.17006,11440.36502,0.00000,0.00688,188.94859
43.50000,2.17496,11467.22063,0.00000,0.00689,189.39214
43.60000,2.17998,11492.64202,0.00000,0.00691,189.81200
43.70000,2.18507,11518.75779,0.00000,0.00693,190.24333
43.80000,2.19003,11544.33191,0.00000,0.00695,190.66571
43.90000,2.19499,11570.48419,0.00000,0.00697,191.09764
44.00000,2.19995,11596.41296,0.00000,0.00699,191.52588
44.10000,2.20504,11623.67910,0.00000,0.00701,191.97620
44.20000,2.20994,11647.08585,0.00000,0.00703,192.36279
44.30000,2.21514,11675.34292,0.00000,0.00705,192.82948
44.40000,2.21992,11699.45970,0.00000,0.00707,193.22779
44.50000,2.22507,11728.10420,0.00000,0.00709,193.70088
44.60000,2.22991,11754.17155,0.00000,0.00711,194.13141
44.70000,2.23511,11781.01972,0.00000,0.00713,194.57483
44.80000,2.23995,11804.70288,0.00000,0.00715,194.96598
44.90000,2.24510,11832.39520,0.00000,0.00717,195.42335
45.00000,2.24994,11856.48665,0.00000,0.00719,195.82124
45.10000,2.25508,11882.72163,0.00000,0.00720,196.25454
45.20000,2.25992,11908.09011,0.00000,0.00723,196.67352
45.30000,2.26506,11935.05451,0.00000,0.00725,197.11887
45.40000,2.26997,11962.03753,0.00000,0.00727,197.56452
45.50000,2.27505,11989.46238,0.00000,0.00728,198.01746
45.60000,2.27995,12015.10131,0.00000,0.00730,198.44092
45.70000,2.28503,12040.86542,0.00000,0.00732,198.86643
45.80000,2.28994,12065.80102,0.00000,0.00734,199.27827
45.90000,2.29502,12093.30484,0.00000,0.00736,199.73252
46.00000,2.29992,12119.31184,0.00000,0.00739,200.16205
46.10000,2.30500,12144.24074,0.00000,0.00741,200.57378
46.20000,2.31003,12171.97403,0.00000,0.00742,201.03182
46.30000,2.31493,12195.61547,0.00000,0.00744,201.42228
46.40000,2.31995,12224.74277,0.00000,0.00746,201.90334
46.50000,2.32491,12247.76804,0.00000,0.00748,202.28363
46.60000,2.33006,12276.01916,0.00000,0.00750,202.75022
46.70000,2.33496,12299.97128,0.00000,0.00752,203.14582
46.80000,2.34010,12327.56898,0.00000,0.00754,203.60162
46.90000,2.34488,12351.67757,0.00000,0.00756,203.99979
47.00000,2.35009,12380.10749,0.00000,0.00758,204.46934
47.10000,2.35487,12403.88826,0.00000,0.00760,204.86210
47.20000,2.36007,12430.49949,0.00000,0.00762,205.30161
47.30000,2.36485,12454.99253,0.00000,0.00764,205.70614
47.40000,2.37000,12481.31320,0.00000,0.00766,206.14085
47.50000,2.37484,12506.61463,0.00000,0.00768,206.55873
47.60000,2.38004,12533.69451,0.00000,0.00770,207.00598
47.70000,2.38494,12559.22318,0.00000,0.00772,207.42761
47.80000,2.39003,12588.18805,0.00000,0.00774,207.90599
47.90000,2.39493,12613.99835,0.00000,0.00776,208.33227
48.00000,2.40001,12638.78495,0.00000,0.00778,208.74165
48.10000,2.40503,12665.48932,0.00000,0.00780,209.18270
48.20000,2.40999,12689.37439,0.00000,0.00782,209.57718
48.30000,2.41496,12716.99369,0.00000,0.00784,210.03334
48.40000,2.41998,12740.29911,0.00000,0.00786,210.41825
48.50000,2.42500,12767.78281,0.00000,0.00788,210.87217
48.60000,2.43002,12793.41877,0.00000,0.00790,211.29557
48.70000,2.43511,12820.58656,0.00000,0.00792,211.74428
48.80000,2.44001,12844.80244,0.00000,0.00794,212.14422
48.90000,2.44509,12873.24876,0.00000,0.00796,212.61404
49.00000,2.44999,12897.15320,0.00000,0.00798,213.00885
49.10000,2.45514,12924.21669,0.00000,0.00800,213.45583
49.20000,2.45998,12949.31620,0.00000,0.00802,213.87037
49.30000,2.46512,12977.85640,0.00000,0.00804,214.34174
49.40000,2.46990,13002.07376,0.00000,0.00806,214.74171
49.50000,2.47511,13030.03430,0.00000,0.00808,215.20351
49.60000,2.47995,13054.10117,0.00000,0.00810,215.60099
49.70000,2.48509,13081.79200,0.00000,0.00812,216.05833
49.80000,2.48993,13107.29682,0.00000,0.00814,216.47957
49.90000,2.49508,13133.66592,0.00000,0.00816,216.91508
50.00000,2.49998,13158.92786,0.00000,0.00818,217.33231
50.10000,2.50506,13185.67097,0.00000,0.00820,217.77400
50.20000,2.50990,13212.38130,0.00000,0.00822,218.21514
50.30000,2.51505,13238.58500,0.00000,0.00824,218.64792
50.40000,2.51995,13264.20307,0.00000,0.00826,219.07103
50.50000,2.52503,13289.08801,0.00000,0.00828,219.48203
50.60000,2.52993,13314.74185,0.00000,0.00830,219.90572
50.70000,2.53495,13341.00217,0.00000,0.00832,220.33944
50.80000,2.53998,13368.68554,0.00000,0.00834,220.79666
50.90000,2.54506,13394.13226,0.00000,0.00836,221.21693
51.00000,2.55002,13420.60864,0.00000,0.00838,221.65422
51.10000,2.55498,13446.18052,0.00000,0.00840,222.07656
51.20000,2.56001,13473.83708,0.00000,0.00842,222.53333
51.30000,2.56491,13498.30478,0.00000,0.00844,222.93744
51.40000,2.57005,13526.24446,0.00000,0.00846,223.39889
51.50000,2.57489,13548.98363,0.00000,0.00848,223.77445
51.60000,2.58004,13576.92778,0.00000,0.00850,224.23598
51.70000,2.58488,13600.98124,0.00000,0.00852,224.63324
51.80000,2.59008,13629.60935,0.00000,0.00854,225.10606
51.90000,2.59492,13652.47518,0.00000,0.00856,225.48371
52.00000,2.60007,13679.21531,0.00000,0.00858,225.92535
52.10000,2.60491,13704.53686,0.00000,0.00860,226.34356
52.20000,2.61005,13730.28308,0.00000,0.00862,226.76879
52.30000,2.61495,13756.03527,0.00000,0.00864,227.19411
52.40000,2.62004,13781.95286,0.00000,0.00867,227.62216
52.50000,2.62500,13808.13271,0.00000,0.00868,228.05455
52.60000,2.63002,13834.35428,0.00000,0.00870,228.48762
52.70000,2.63492,13860.10647,0.00000,0.00873,228.91294
52.80000,2.64000,13885.31774,0.00000,0.00875,229.32933
52.90000,2.64497,13912.32908,0.00000,0.00877,229.77545
53.00000,2.64999,13937.03073,0.00000,0.00879,230.18342
53.10000,2.65501,13964.56808,0.00000,0.00881,230.63823
53.20000,2.66003,13989.11476,0.00000,0.00883,231.04364
53.30000,2.66506,14017.18557,0.00000,0.00885,231.50726
53.40000,2.67002,14041.06617,0.00000,0.00887,231.90167
53.50000,2.67504,14068.61842,0.00000,0.00889,232.35672
53.60000,2.68000,14094.37656,0.00000,0.00891,232.78214
53.70000,2.68503,14120.93192,0.00000,0.00893,233.22073
53.80000,2.68999,14144.54728,0.00000,0.00895,233.61076
53.90000,2.69507,14172.04440,0.00000,0.00897,234.06490
54.00000,2.69991,14195.94139,0.00000,0.00899,234.45958
54.10000,2.70506,14225.01802,0.00000,0.00901,234.93981
54.20000,2.70996,14249.81803,0.00000,0.00903,235.34940
54.30000,2.71510,14277.98718,0.00000,0.00906,235.81464
54.40000,2.71994,14301.40883,0.00000,0.00907,236.20148
54.50000,2.72503,14329.40811,0.00000,0.00910,236.66391
54.60000,2.72987,14354.07102,0.00000,0.00912,237.07124
54.70000,2.73501,14381.40720,0.00000,0.00914,237.52273
54.80000,2.73991,14407.58109,0.00000,0.00916,237.95501
54.90000,2.74505,14434.85171,0.00000,0.00918,238.40541
55.00000,2.74990,14461.08371,0.00000,0.00920,238.83866
55.10000,2.75504,14487.53327,0.00000,0.00922,239.27550
55.20000,2.75994,14513.96793,0.00000,0.00924,239.71209
55.30000,2.76508,14539.38633,0.00000,0.00927,240.13190
55.40000,2.76999,14565.82695,0.00000,0.00928,240.56859
55.50000,2.77501,14590.02048,0.00000,0.00930,240.96817
55.60000,2.77997,14617.96463,0.00000,0.00933,241.42970
55.70000,2.78499,14642.18646,0.00000,0.00934,241.82974
55.80000,2.79002,14669.99054,0.00000,0.00937,242.28896
55.90000,2.79498,14694.57150,0.00000,0.00938,242.69493
56.00000,2.80000,14721.28481,0.00000,0.00941,243.13613
56.10000,2.80490,14746.06842,0.00000,0.00943,243.54545
56.20000,2.81005,14772.99035,0.00000,0.00945,243.99010
56.30000,2.81489,14797.15258,0.00000,0.00947,244.38916
56.40000,2.82009,14825.33365,0.00000,0.00949,244.85460
56.50000,2.82487,14850.18581,0.00000,0.00951,245.26505
56.60000,2.83008,14877.73657,0.00000,0.00953,245.72008
56.70000,2.83492,14902.12232,0.00000,0.00955,246.12283
56.80000,2.84006,14927.80149,0.00000,0.00957,246.54695
56.90000,2.84484,14953.21691,0.00000,0.00959,246.96671
57.00000,2.84993,14979.43997,0.00000,0.00961,247.39981
57.10000,2.85489,15005.02974,0.00000,0.00963,247.82245
57.20000,2.86003,15031.67003,0.00000,0.00965,248.26244
57.30000,2.86493,15057.44010,0.00000,0.00968,248.68806
57.40000,2.87002,15084.41120,0.00000,0.00970,249.13351
57.50000,2.87498,15111.66096,0.00000,0.00972,249.58357
57.60000,2.88006,15136.99293,0.00000,0.00974,250.00195
57.70000,2.88502,15162.14013,0.00000,0.00976,250.41728
57.80000,2.88999,15187.43634,0.00000,0.00978,250.83507
57.90000,2.89501,15215.10035,0.00000,0.00980,251.29197
58.00000,2.90003,15240.43977,0.00000,0.00982,251.71047
58.10000,2.90499,15268.23342,0.00000,0.00985,252.16951
58.20000,2.91001,15292.03355,0.00000,0.00987,252.56259
58.30000,2.91498,15321.00886,0.00000,0.00989,253.04115
58.40000,2.91994,15345.26050,0.00000,0.00991,253.44169
58.50000,2.92502,15373.43115,0.00000,0.00993,253.90695
58.60000,2.92998,15397.50546,0.00000,0.00995,254.30456
58.70000,2.93507,15425.83853,0.00000,0.00997,254.77251
58.80000,2.93997,15451.07216,0.00000,0.00999,255.18927
58.90000,2.94511,15479.46930,0.00000,0.01001,255.65827
59.00000,2.94989,15502.46477,0.00000,0.01003,256.03807
59.10000,2.95516,15530.92450,0.00000,0.01006,256.50811
59.20000,2.95994,15554.30293,0.00000,0.01008,256.89422
59.30000,2.96508,15582.29923,0.00000,0.01010,257.35661
59.40000,2.96992,15606.47041,0.00000,0.01012,257.75582
59.50000,2.97507,15632.99149,0.00000,0.01014,258.19384
59.60000,2.97997,15657.96733,0.00000,0.01016,258.60634
59.70000,2.98505,15686.09923,0.00000,0.01018,259.07096
59.80000,2.98989,15711.61151,0.00000,0.01020,259.49232
59.90000,2.99498,15738.19965,0.00000,0.01023,259.93145
60.00000,2.99994,15764.15002,0.00000,0.01025,260.36005
60.10000,3.00502,15788.24967,0.00000,0.01027,260.75808
60.20000,3.00998,15815.37426,0.00000,0.01029,261.20607
60.30000,3.01494,15839.33085,0.00000,0.01031,261.60173
60.40000,3.01997,15867.74886,0.00000,0.01033,262.07108
60.50000,3.02493,15892.21209,0.00000,0.01035,262.47512
60.60000,3.03001,15919.48867,0.00000,0.01037,262.92561
60.70000,3.03491,15943.00419,0.00000,0.01039,263.31400
60.80000,3.04000,15971.71724,0.00000,0.01042,263.78822
60.90000,3.04496,15995.31472,0.00000,0.01043,264.17795
61.00000,3.05010,16023.37658,0.00000,0.01046,264.64142
61.10000,3.05494,16047.02473,0.00000,0.01048,265.03200
61.20000,3.06009,16074.37432,0.00000,0.01050,265.48370
61.30000,3.06499,16099.67351,0.00000,0.01052,265.90154
61.40000,3.07007,16125.48828,0.00000,0.01054,266.32790
61.50000,3.07491,16149.66094,0.00000,0.01056,266.72713
61.60000,3.08000,16176.69314,0.00000,0.01058,267.17359
61.70000,3.08484,16201.80309,0.00000,0.01061,267.58831
61.80000,3.08998,16228.21093,0.00000,0.01063,268.02446
61.90000,3.09494,16254.58598,0.00000,0.01065,268.46007
62.00000,3.10009,16281.24714,0.00000,0.01067,268.90040
62.10000,3.10499,16307.99621,0.00000,0.01069,269.34219
62.20000,3.11001,16334.00023,0.00000,0.01071,269.77167
62.30000,3.11497,16359.50059,0.00000,0.01073,270.19283
62.40000,3.12005,16385.20360,0.00000,0.01075,270.61734
62.50000,3.12496,16410.02595,0.00000,0.01078,271.02731
62.60000,3.12998,16434.93026,0.00000,0.01080,271.43863
62.70000,3.13494,16463.41234,0.00000,0.01082,271.90904
62.80000,3.14002,16488.24513,0.00000,0.01084,272.31917
62.90000,3.14505,16515.51425,0.00000,0.01087,272.76955
63.00000,3.15001,16539.73162,0.00000,0.01089,273.16952
63.10000,3.15503,16568.36867,0.00000,0.01091,273.64249
63.20000,3.15999,16593.30726,0.00000,0.01093,274.05437
63.30000,3.16502,16619.42154,0.00000,0.01095,274.48568
63.40000,3.16998,16642.89087,0.00000,0.01097,274.87330
63.50000,3.17500,16670.00800,0.00000,0.01099,275.32116
63.60000,3.17984,16695.22971,0.00000,0.01101,275.73772
63.70000,3.18505,16724.10220,0.00000,0.01103,276.21458
63.80000,3.18989,16748.70998,0.00000,0.01105,276.62100
63.90000,3.19509,16774.57392,0.00000,0.01108,277.04817
64.00000,3.19987,16799.16978,0.00000,0.01110,277.45439
64.10000,3.20508,16827.06773,0.00000,0.01112,277.91515
64.20000,3.20992,16852.26560,0.00000,0.01114,278.33132
64.30000,3.21506,16877.90155,0.00000,0.01116,278.75472
64.40000,3.21990,16902.02355,0.00000,0.01118,279.15312
64.50000,3.22505,16929.68756,0.00000,0.01121,279.61002
64.60000,3.22989,16953.57859,0.00000,0.01122,280.00460
64.70000,3.23503,16978.34730,0.00000,0.01124,280.41368
64.80000,3.23999,17004.11588,0.00000,0.01127,280.83927
64.90000,3.24495,17028.07546,0.00000,0.01129,281.23499
65.00000,3.24992,17054.88712,0.00000,0.01131,281.67781
65.10000,3.25494,17078.92269,0.00000,0.01133,282.07478
65.20000,3.26002,17107.89204,0.00000,0.01135,282.55324
65.30000,3.26498,17131.95741,0.00000,0.01137,282.95070
65.40000,3.27001,17159.08796,0.00000,0.01139,283.39879
65.50000,3.27491,17182.83743,0.00000,0.01141,283.79103
65.60000,3.28005,17210.50441,0.00000,0.01143,284.24798
65.70000,3.28495,17233.44624,0.00000,0.01145,284.62688
65.80000,3.29010,17260.56635,0.00000,0.01148,285.07480
65.90000,3.29488,17283.99843,0.00000,0.01150,285.46180
66.00000,3.30002,17312.37769,0.00000,0.01152,285.93051
66.10000,3.30492,17336.45648,0.00000,0.01154,286.32820
66.20000,3.31013,17363.54828,0.00000,0.01156,286.77564
66.30000,3.31497,17387.37226,0.00000,0.01158,287.16912
66.40000,3.32005,17413.65790,0.00000,0.01160,287.60325
66.50000,3.32495,17439.11058,0.00000,0.01162,288.02363
66.60000,3.33004,17464.09386,0.00000,0.01165,288.43625
66.70000,3.33494,17489.65979,0.00000,0.01167,288.85850
66.80000,3.34002,17514.53727,0.00000,0.01169,289.26937
66.90000,3.34492,17541.31168,0.00000,0.01171,289.71158
67.00000,3.35001,17567.29782,0.00000,0.01173,290.14076
67.10000,3.35497,17592.91440,0.00000,0.01175,290.56384
67.20000,3.36005,17617.83957,0.00000,0.01178,290.97551
67.30000,3.36501,17643.61858,0.00000,0.01180,291.40127
67.40000,3.37003,17668.19060,0.00000,0.01182,291.80710
67.50000,3.37500,17695.04100,0.00000,0.01185,292.25056
67.60000,3.38002,17719.62792,0.00000,0.01187,292.65664
67.70000,3.38504,17747.18016,0.00000,0.01189,293.11169
67.80000,3.39000,17770.08474,0.00000,0.01191,293.48998
67.90000,3.39503,17797.56993,0.00000,0.01193,293.94393
68.00000,3.39993,17820.52219,0.00000,0.01196,294.32301
68.10000,3.40507,17846.51875,0.00000,0.01198,294.75236
68.20000,3.40997,17870.06408,0.00000,0.01200,295.14124
68.30000,3.41506,17897.28552,0.00000,0.01202,295.59083
68.40000,3.41990,17921.16165,0.00000,0.01204,295.98516
68.50000,3.42510,17949.47684,0.00000,0.01207,296.45282
68.60000,3.42994,17973.35893,0.00000,0.01208,296.84725
68.70000,3.43509,17999.24523,0.00000,0.01211,297.27479
68.80000,3.43987,18023.66823,0.00000,0.01213,297.67816
68.90000,3.44501,18049.25948,0.00000,0.01215,298.10082
69.00000,3.44985,18073.35168,0.00000,0.01217,298.49873
69.10000,3.45500,18098.74475,0.00000,0.01219,298.91812
69.20000,3.45990,18124.04543,0.00000,0.01222,299.33598
69.30000,3.46492,18149.80954,0.00000,0.01224,299.76150
69.40000,3.46988,18175.28754,0.00000,0.01226,300.18230
69.50000,3.47497,18199.69565,0.00000,0.01228,300.58542
69.60000,3.47999,18226.77702,0.00000,0.01230,301.03269
69.70000,3.48501,18249.32098,0.00000,0.01232,301.40503
69.80000,3.48997,18275.44123,0.00000,0.01234,301.83643
69.90000,3.49493,18299.29501,0.00000,0.01236,302.23040
70.00000,3.50008,18325.21111,0.00000,0.01238,302.65843
70.10000,3.50498,18349.16472,0.00000,0.01240,303.05404
70.20000,3.51000,18375.03463,0.00000,0.01242,303.48131
70.30000,3.51490,18399.26839,0.00000,0.01245,303.88155
70.40000,3.52005,18426.72527,0.00000,0.01247,304.33503
70.50000,3.52495,18449.76097,0.00000,0.01249,304.71549
70.60000,3.53015,18476.34912,0.00000,0.01251,305.15462
70.70000,3.53493,18500.55605,0.00000,0.01253,305.55442
70.80000,3.54008,18527.45116,0.00000,0.01255,305.99862
70.90000,3.54498,18550.94880,0.00000,0.01258,306.38670
71.00000,3.55012,18576.87384,0.00000,0.01260,306.81488
71.10000,3.55496,18601.25065,0.00000,0.01262,307.21748
71.20000,3.56005,18626.69289,0.00000,0.01264,307.63769
71.30000,3.56489,18651.20828,0.00000,0.01266,308.04258
71.40000,3.57003,18677.24359,0.00000,0.01268,308.47258
71.50000,3.57499,18701.37155,0.00000,0.01270,308.87108
71.60000,3.58007,18726.13281,0.00000,0.01273,309.28003
71.70000,3.58492,18751.38134,0.00000,0.01275,309.69704
71.80000,3.59006,18777.64761,0.00000,0.01277,310.13085
71.90000,3.59496,18802.62494,0.00000,0.01279,310.54337
72.00000,3.60004,18827.40706,0.00000,0.01281,310.95267
72.10000,3.60489,18851.66615,0.00000,0.01284,311.35334
72.20000,3.60997,18875.75686,0.00000,0.01286,311.75122
72.30000,3.61493,18901.67743,0.00000,0.01288,312.17932
72.40000,3.61995,18925.04096,0.00000,0.01290,312.56519
72.50000,3.62504,18951.00027,0.00000,0.01293,312.99393
72.60000,3.62994,18975.58719,0.00000,0.01294,313.40001
72.70000,3.63496,19002.75946,0.00000,0.01297,313.84879
72.80000,3.63992,19026.15577,0.00000,0.01299,314.23520
72.90000,3.64507,19053.14028,0.00000,0.01301,314.68088
73.00000,3.64991,19074.42659,0.00000,0.01303,315.03244
73.10000,3.65505,19101.37236,0.00000,0.01306,315.47747
73.20000,3.65983,19123.01183,0.00000,0.01308,315.83487
73.30000,3.66510,19150.30777,0.00000,0.01310,316.28569
73.40000,3.66994,19172.23781,0.00000,0.01312,316.64788
73.50000,3.67508,19197.64429,0.00000,0.01314,317.06750
73.60000,3.67986,19222.31317,0.00000,0.01316,317.47493
73.70000,3.68501,19247.78074,0.00000,0.01318,317.89555
73.80000,3.68991,19272.09944,0.00000,0.01321,318.29720
73.90000,3.69505,19296.90987,0.00000,0.01323,318.70696
74.00000,3.69995,19321.59066,0.00000,0.01325,319.11459
74.10000,3.70498,19347.57084,0.00000,0.01327,319.54368
74.20000,3.70994,19372.83874,0.00000,0.01330,319.96100
74.30000,3.71502,19397.21853,0.00000,0.01332,320.36366
74.40000,3.72004,19424.15088,0.00000,0.01334,320.80847
74.50000,3.72495,19445.29712,0.00000,0.01336,321.15772
74.60000,3.72997,19472.56774,0.00000,0.01339,321.60812
74.70000,3.73499,19496.72401,0.00000,0.01341,322.00709
74.80000,3.74007,19522.48812,0.00000,0.01343,322.43260
74.90000,3.74503,19545.17066,0.00000,0.01345,322.80723
75.00000,3.75006,19572.10153,0.00000,0.01347,323.25202
75.10000,3.75496,19596.59457,0.00000,0.01350,323.65654
75.20000,3.76010,19623.78174,0.00000,0.01352,324.10557
75.30000,3.76500,19646.53432,0.00000,0.01354,324.48135
75.40000,3.77015,19672.42658,0.00000,0.01356,324.90898
75.50000,3.77493,19694.56524,0.00000,0.01358,325.27462
75.60000,3.78007,19721.27110,0.00000,0.01360,325.71570
75.70000,3.78491,19743.77185,0.00000,0.01363,326.08732
75.80000,3.79012,19770.72805,0.00000,0.01365,326.53252
75.90000,3.79484,19793.39421,0.00000,0.01367,326.90688
76.00000,3.79998,19820.17905,0.00000,0.01369,327.34926
76.10000,3.80488,19844.68848,0.00000,0.01371,327.75405
76.20000,3.81009,19871.07545,0.00000,0.01373,328.18986
76.30000,3.81499,19896.41190,0.00000,0.01376,328.60831
76.40000,3.82007,19920.74251,0.00000,0.01378,329.01016
76.50000,3.82491,19944.63205,0.00000,0.01380,329.40472
76.60000,3.83006,19971.06522,0.00000,0.01383,329.84129
76.70000,3.83496,19994.43471,0.00000,0.01385,330.22725
76.80000,3.84004,20018.58205,0.00000,0.01387,330.62607
76.90000,3.84494,20044.58159,0.00000,0.01389,331.05548
77.00000,3.84996,20066.71429,0.00000,0.01391,331.42102
77.10000,3.85499,20092.56333,0.00000,0.01394,331.84794
77.20000,3.86007,20114.44569,0.00000,0.01396,332.20935
77.30000,3.86503,20140.34241,0.00000,0.01398,332.63706
77.40000,3.86993,20162.67329,0.00000,0.01400,333.00588
77.50000,3.87502,20189.46558,0.00000,0.01403,333.44838
77.60000,3.87992,20213.75000,0.00000,0.01405,333.84946
77.70000,3.88506,20240.84032,0.00000,0.01407,334.29688
77.80000,3.88990,20262.42465,0.00000,0.01409,334.65337
77.90000,3.89505,20288.72967,0.00000,0.01411,335.08782
78.00000,3.89989,20310.60457,0.00000,0.01413,335.44910
78.10000,3.90503,20336.24798,0.00000,0.01416,335.87263
78.20000,3.90993,20360.13007,0.00000,0.01418,336.26706
78.30000,3.91508,20385.04928,0.00000,0.01420,336.67863
78.40000,3.91992,20408.97310,0.00000,0.01422,337.07375
78.50000,3.92500,20435.05311,0.00000,0.01424,337.50449
78.60000,3.92996,20459.44333,0.00000,0.01427,337.90732
78.70000,3.93505,20483.51467,0.00000,0.01429,338.30488
78.80000,3.93995,20507.62773,0.00000,0.01431,338.70313
78.90000,3.94497,20531.21775,0.00000,0.01433,339.09274
79.00000,3.94993,20557.59132,0.00000,0.01435,339.52833
79.10000,3.95507,20581.27820,0.00000,0.01438,339.91954
79.20000,3.96004,20605.91280,0.00000,0.01440,340.32640
79.30000,3.96500,20628.79652,0.00000,0.01442,340.70435
79.40000,3.97002,20656.37559,0.00000,0.01444,341.15984
79.50000,3.97504,20678.59173,0.00000,0.01447,341.52676
79.60000,3.98013,20704.80585,0.00000,0.01449,341.95972
79.70000,3.98503,20728.07699,0.00000,0.01451,342.34406
79.80000,3.99005,20753.34191,0.00000,0.01453,342.76133
79.90000,3.99495,20776.87234,0.00000,0.01455,343.14996
80.00000,4.00010,20803.58863,0.00000,0.01457,343.59121
80.10000,4.00500,20825.66619,0.00000,0.01460,343.95584
80.20000,4.01014,20852.55086,0.00000,0.01462,344.39987
80.30000,4.01492,20874.61799,0.00000,0.01464,344.76433
80.40000,4.02013,20901.09140,0.00000,0.01467,345.20156
80.50000,4.02497,20922.33300,0.00000,0.01469,345.55238
80.60000,4.03011,20947.76332,0.00000,0.01471,345.97239
80.70000,4.03489,20969.17182,0.00000,0.01473,346.32597
80.80000,4.04004,20995.35018,0.00000,0.01475,346.75833
80.90000,4.04488,21020.03992,0.00000,0.01478,347.16611
81.00000,4.05008,21045.24523,0.00000,0.01480,347.58240
81.10000,4.05492,21069.79340,0.00000,0.01482,347.98783
81.20000,4.06001,21093.86474,0.00000,0.01485,348.38540
81.30000,4.06491,21119.33976,0.00000,0.01487,348.80614
81.40000,4.06999,21142.19218,0.00000,0.01490,349.18357
81.50000,4.07495,21166.70907,0.00000,0.01492,349.58849
81.60000,4.08003,21189.17108,0.00000,0.01494,349.95947
81.70000,4.08494,21213.67753,0.00000,0.01496,350.36422
81.80000,4.08996,21236.44054,0.00000,0.01499,350.74017
81.90000,4.09498,21262.90947,0.00000,0.01501,351.17733
82.00000,4.10006,21284.06018,0.00000,0.01503,351.52666
82.10000,4.10509,21309.35788,0.00000,0.01505,351.94447
82.20000,4.10987,21329.75608,0.00000,0.01507,352.28137
82.30000,4.11495,21357.00136,0.00000,0.01510,352.73135
82.40000,4.11991,21377.91812,0.00000,0.01512,353.07681
82.50000,4.12506,21403.53918,0.00000,0.01514,353.49997
82.60000,4.12990,21425.32766,0.00000,0.01517,353.85982
82.70000,4.13504,21450.27816,0.00000,0.01518,354.27190
82.80000,4.13988,21472.83852,0.00000,0.01521,354.64451
82.90000,4.14503,21498.05576,0.00000,0.01523,355.06100
83.00000,4.14993,21520.76662,0.00000,0.01525,355.43609
83.10000,4.15501,21544.30896,0.00000,0.01527,355.82491
83.20000,4.15991,21568.22532,0.00000,0.01529,356.21992
83.30000,4.16500,21592.76754,0.00000,0.01531,356.62525
83.40000,4.16996,21616.89401,0.00000,0.01534,357.02373
83.50000,4.17504,21641.14416,0.00000,0.01536,357.42424
83.60000,4.17994,21665.16036,0.00000,0.01538,357.82089
83.70000,4.18497,21687.19023,0.00000,0.01540,358.18473
83.80000,4.18999,21707.83728,0.00000,0.01542,358.52574
83.88400,4.19423,21304.88753,0.00000,0.01547,351.87064
83.88600,4.19441,20737.49751,0.00000,0.01557,342.49965
83.88800,4.19459,19940.30178,0.00000,0.01581,329.33320
83.89000,4.19477,18989.10850,0.00000,0.01617,313.62333
83.89200,4.19519,17920.82787,0.00000,0.01652,295.97965
83.89400,4.19549,16761.07943,0.00000,0.01675,276.82529
83.89600,4.19579,15548.56002,0.00000,0.01679,256.79937
83.89800,4.19621,14314.10164,0.00000,0.01667,236.41111
83.90000,4.19656,13072.74401,0.00000,0.01646,215.90890
83.90200,4.19692,11839.14244,0.00000,0.01619,195.53479