File: scratch/college-stuff/ME Lab/ME lab Fall 2013/group9/group9.is_tens_RawData/Specimen_RawData_1.csv
Time,Extension,Load,Strain 2,Tensile strain,Tensile stress
(sec),(mm),(N),(mm/mm),(mm/mm),(MPa)
0.00000,-0.12006,-0.13976,0.00000,0.00000,-0.00169
0.40000,-0.10069,48.57606,0.00000,0.00000,0.58891
0.80000,-0.08000,68.60580,0.00000,0.00000,0.83174
1.20000,-0.05997,80.26247,0.00000,0.00000,0.97306
1.60000,-0.03994,91.08649,0.00000,-0.00001,1.10428
2.00000,-0.01991,104.44775,0.00000,-0.00002,1.26626
2.40000,-0.00006,119.39526,0.00000,-0.00003,1.44748
2.80000,0.01997,137.69014,0.00000,-0.00004,1.66927
3.20000,0.04006,160.51342,0.00000,-0.00005,1.94597
3.60000,0.05997,192.96248,0.00000,-0.00006,2.33936
4.00000,0.07994,231.79133,0.00000,-0.00006,2.81010
4.40000,0.09991,274.09117,0.00000,-0.00006,3.32292
4.80000,0.11988,315.49050,0.00000,-0.00007,3.82482
5.20000,0.13997,369.61795,0.00000,-0.00008,4.48103
5.60000,0.16000,434.94701,0.00000,-0.00009,5.27304
6.00000,0.18003,510.37874,0.00000,-0.00010,6.18753
6.40000,0.20006,598.21308,0.00000,-0.00011,7.25239
6.80000,0.22009,707.76809,0.00000,-0.00011,8.58057
7.20000,0.24000,846.78847,0.00000,-0.00011,10.26597
7.60000,0.26002,1014.29746,0.00000,-0.00010,12.29675
8.00000,0.28005,1201.50335,0.00000,-0.00009,14.56633
8.40000,0.30002,1398.22317,0.00000,-0.00007,16.95124
8.80000,0.31987,1620.38077,0.00000,-0.00005,19.64455
9.20000,0.33984,1880.69940,0.00000,-0.00003,22.80050
9.60000,0.35987,2164.89285,0.00000,0.00001,26.24590
10.00000,0.37990,2444.90709,0.00000,0.00005,29.64063
10.40000,0.39999,2727.69090,0.00000,0.00008,33.06893
10.80000,0.42002,3015.86259,0.00000,0.00013,36.56256
11.20000,0.43999,3310.11266,0.00000,0.00017,40.12987
11.60000,0.46002,3605.35085,0.00000,0.00021,43.70917
12.00000,0.47999,3902.48932,0.00000,0.00026,47.31150
12.40000,0.49996,4197.90111,0.00000,0.00030,50.89290
12.80000,0.52005,4495.67065,0.00000,0.00036,54.50289
13.20000,0.53996,4789.88029,0.00000,0.00041,58.06971
13.60000,0.55981,5081.97136,0.00000,0.00046,61.61085
14.00000,0.57990,5372.25343,0.00000,0.00051,65.13007
14.40000,0.59981,5659.29636,0.00000,0.00055,68.61001
14.80000,0.61990,5941.13171,0.00000,0.00060,72.02681
15.20000,0.63999,6222.60533,0.00000,0.00065,75.43924
15.60000,0.66002,6491.84436,0.00000,0.00070,78.70333
16.00000,0.68011,6757.40913,0.00000,0.00075,81.92288
16.40000,0.70002,7012.89997,0.00000,0.00079,85.02031
16.80000,0.72004,7229.40937,0.00000,0.00083,87.64514
17.20000,0.74001,7424.67046,0.00000,0.00086,90.01237
17.60000,0.75998,7604.91937,0.00000,0.00089,92.19760
18.00000,0.77995,7787.73278,0.00000,0.00092,94.41393
18.40000,0.79992,7973.37517,0.00000,0.00095,96.66455
18.80000,0.81989,8159.28131,0.00000,0.00098,98.91836
19.20000,0.83986,8343.68244,0.00000,0.00101,101.15394
19.60000,0.85995,8531.62482,0.00000,0.00105,103.43244
20.00000,0.87998,8720.27129,0.00000,0.00107,105.71948
20.40000,0.90007,8906.05748,0.00000,0.00111,107.97184
20.80000,0.92010,9094.95577,0.00000,0.00114,110.26194
21.20000,0.94007,9283.01066,0.00000,0.00117,112.54180
21.60000,0.95998,9472.75385,0.00000,0.00120,114.84214
22.00000,0.98001,9665.32156,0.00000,0.00124,117.17672
22.40000,0.99998,9853.50534,0.00000,0.00127,119.45815
22.80000,1.02001,10044.67607,0.00000,0.00130,121.77579
23.20000,1.03986,10238.20192,0.00000,0.00134,124.12198
23.60000,1.05989,10433.00852,0.00000,0.00137,126.48371
24.00000,1.07992,10627.98649,0.00000,0.00140,128.84751
24.40000,1.09995,10822.10019,0.00000,0.00144,131.20083
24.80000,1.12004,11017.08114,0.00000,0.00147,133.56466
25.20000,1.14007,11213.03886,0.00000,0.00151,135.94034
25.60000,1.16010,11409.14783,0.00000,0.00155,138.31785
26.00000,1.18007,11606.23506,0.00000,0.00158,140.70722
26.40000,1.20003,11805.36523,0.00000,0.00162,143.12136
26.80000,1.21994,12001.99947,0.00000,0.00165,145.50524
27.20000,1.23997,12200.30636,0.00000,0.00169,147.90939
27.60000,1.25994,12398.49925,0.00000,0.00173,150.31217
28.00000,1.27991,12592.83274,0.00000,0.00176,152.66815
28.40000,1.29988,12796.22018,0.00000,0.00181,155.13391
28.80000,1.31991,12998.38424,0.00000,0.00184,157.58482
29.20000,1.34000,13200.09232,0.00000,0.00188,160.03022
29.60000,1.35997,13396.19458,0.00000,0.00192,162.40764
30.00000,1.38006,13597.26340,0.00000,0.00196,164.84529
30.40000,1.40009,13800.38112,0.00000,0.00200,167.30777
30.80000,1.42006,14001.25474,0.00000,0.00204,169.74304
31.20000,1.44003,14201.35796,0.00000,0.00208,172.16898
31.60000,1.46000,14402.12578,0.00000,0.00212,174.60297
32.00000,1.47991,14602.67454,0.00000,0.00216,177.03430
32.40000,1.49988,14805.75800,0.00000,0.00220,179.49637
32.80000,1.51991,15005.78374,0.00000,0.00224,181.92136
33.20000,1.53988,15207.24446,0.00000,0.00228,184.36376
33.60000,1.55991,15409.44874,0.00000,0.00232,186.81516
34.00000,1.57994,15612.23865,0.00000,0.00237,189.27367
34.40000,1.59997,15814.27902,0.00000,0.00241,191.72309
34.80000,1.62006,16016.57867,0.00000,0.00245,194.17565
35.20000,1.64009,16217.39268,0.00000,0.00250,196.61020
35.60000,1.66000,16417.60617,0.00000,0.00254,199.03748
36.00000,1.68003,16619.84771,0.00000,0.00258,201.48933
36.40000,1.69993,16816.92600,0.00000,0.00263,203.87860
36.80000,1.71990,17014.45729,0.00000,0.00268,206.27335
37.20000,1.73987,17209.71763,0.00000,0.00273,208.64057
37.60000,1.75990,17407.30256,0.00000,0.00277,211.03598
38.00000,1.77993,17602.26041,0.00000,0.00282,213.39953
38.40000,1.79996,17796.41807,0.00000,0.00287,215.75339
38.80000,1.81993,17989.00366,0.00000,0.00292,218.08818
39.20000,1.83996,18180.89783,0.00000,0.00298,220.41459
39.60000,1.86005,18369.38262,0.00000,0.00303,222.69967
40.00000,1.88008,18552.26457,0.00000,0.00309,224.91683
40.40000,1.89999,18731.33481,0.00000,0.00314,227.08777
40.80000,1.91996,18910.62260,0.00000,0.00321,229.26135
41.20000,1.93993,19083.70107,0.00000,0.00327,231.35965
41.60000,1.95990,19250.92936,0.00000,0.00334,233.38703
42.00000,1.97987,19410.52228,0.00000,0.00341,235.32184
42.40000,1.99996,19569.35823,0.00000,0.00348,237.24748
42.80000,2.01999,19723.45412,0.00000,0.00356,239.11565
43.20000,2.03996,19868.44242,0.00000,0.00365,240.87340
43.60000,2.05999,20007.14242,0.00000,0.00374,242.55492
44.00000,2.07996,20136.78551,0.00000,0.00383,244.12664
44.40000,2.09999,20259.54723,0.00000,0.00392,245.61493
44.80000,2.12008,20372.75732,0.00000,0.00402,246.98742
45.20000,2.14005,20476.56327,0.00000,0.00412,248.24590
45.60000,2.16007,20573.83955,0.00000,0.00423,249.42522
46.00000,2.17998,20658.90133,0.00000,0.00435,250.45646
46.40000,2.19995,20740.69679,0.00000,0.00448,251.44810
46.80000,2.21992,20813.97474,0.00000,0.00461,252.33648
47.20000,2.24001,20882.72572,0.00000,0.00475,253.16998
47.60000,2.25992,20946.09439,0.00000,0.00491,253.93822
48.00000,2.27995,21004.94355,0.00000,0.00506,254.65168
48.40000,2.29992,21060.06444,0.00000,0.00522,255.31993
48.80000,2.31995,21110.46612,0.00000,0.00538,255.93097
49.20000,2.34004,21155.06828,0.00000,0.00554,256.47170
49.60000,2.36007,21195.46384,0.00000,0.00572,256.96143
50.00000,2.38004,21235.03834,0.00000,0.00590,257.44121
50.40000,2.40001,21270.03521,0.00000,0.00608,257.86549
50.80000,2.41998,21303.15006,0.00000,0.00626,258.26696
51.20000,2.44001,21334.91486,0.00000,0.00644,258.65206
51.60000,2.45998,21364.09581,0.00000,0.00664,259.00583
52.00000,2.47995,21390.19668,0.00000,0.00684,259.32226
52.40000,2.49998,21417.09179,0.00000,0.00703,259.64832
52.80000,2.51995,21442.47890,0.00000,0.00723,259.95610
53.20000,2.53998,21469.31738,0.00000,0.00742,260.28147
53.60000,2.56001,21490.06575,0.00000,0.00763,260.53302
54.00000,2.58004,21510.01692,0.00000,0.00783,260.77489
54.40000,2.60007,21529.55234,0.00000,0.00804,261.01173
54.80000,2.62004,21547.71984,0.00000,0.00824,261.23198
55.20000,2.64006,21566.06615,0.00000,0.00844,261.45440
55.60000,2.66003,21583.51541,0.00000,0.00865,261.66594
56.00000,2.68006,21600.40289,0.00000,0.00887,261.87068
56.40000,2.69991,21614.43383,0.00000,0.00907,262.04078
56.80000,2.71994,21630.44065,0.00000,0.00928,262.23484
57.20000,2.73991,21647.55762,0.00000,0.00949,262.44235
57.60000,2.75994,21663.93846,0.00000,0.00970,262.64095
58.00000,2.77997,21677.83380,0.00000,0.00992,262.80941
58.40000,2.80000,21693.46660,0.00000,0.01013,262.99893
58.80000,2.82003,21707.89838,0.00000,0.01034,263.17389
59.20000,2.84006,21718.77325,0.00000,0.01054,263.30573
59.60000,2.86003,21732.26774,0.00000,0.01076,263.46933
60.00000,2.88006,21745.30625,0.00000,0.01097,263.62740
60.40000,2.90003,21758.46696,0.00000,0.01118,263.78695
60.80000,2.91994,21770.37299,0.00000,0.01139,263.93130
61.20000,2.93991,21781.96907,0.00000,0.01160,264.07188
61.60000,2.95994,21792.21511,0.00000,0.01182,264.19610
62.00000,2.97997,21805.03309,0.00000,0.01203,264.35150
62.40000,2.99994,21817.80934,0.00000,0.01224,264.50639
62.80000,3.02003,21832.16810,0.00000,0.01245,264.68046
63.20000,3.04006,21843.08022,0.00000,0.01266,264.81276
63.60000,3.06009,21855.75366,0.00000,0.01287,264.96640
64.00000,3.07994,21863.90609,0.00000,0.01309,265.06524
64.40000,3.10009,21878.15756,0.00000,0.01330,265.23801
64.80000,3.12005,21888.30376,0.00000,0.01351,265.36102
65.20000,3.14002,21898.47231,0.00000,0.01372,265.48430
65.60000,3.15999,21909.74206,0.00000,0.01393,265.62093
66.00000,3.17984,21919.71391,0.00000,0.01414,265.74182
66.40000,3.19987,21929.26407,0.00000,0.01435,265.85760
66.80000,3.21990,21939.58312,0.00000,0.01456,265.98270
67.20000,3.23999,21952.18205,0.00000,0.01477,266.13544
67.60000,3.26002,21964.83463,0.00000,0.01497,266.28884
68.00000,3.28005,21974.71857,0.00000,0.01518,266.40866
68.40000,3.30002,21984.95716,0.00000,0.01538,266.53279
68.80000,3.32005,21992.88458,0.00000,0.01559,266.62890
69.20000,3.34008,22003.95763,0.00000,0.01579,266.76314
69.60000,3.36005,22013.84008,0.00000,0.01601,266.88295
70.00000,3.38008,22022.83740,0.00000,0.01621,266.99203
70.40000,3.39993,22031.49199,0.00000,0.01642,267.09695
70.80000,3.41990,22041.87363,0.00000,0.01661,267.22281
71.20000,3.43987,22052.49965,0.00000,0.01681,267.35164
71.60000,3.45990,22061.55360,0.00000,0.01702,267.46140
72.00000,3.47999,22074.83798,0.00000,0.01722,267.62245
72.40000,3.50008,22084.04541,0.00000,0.01743,267.73408
72.80000,3.52005,22094.83236,0.00000,0.01763,267.86485
73.20000,3.54014,22105.72511,0.00000,0.01783,267.99691
73.60000,3.56005,22113.75237,0.00000,0.01803,268.09423
74.00000,3.58007,22122.84803,0.00000,0.01824,268.20450
74.40000,3.60004,22132.21639,0.00000,0.01844,268.31807
74.80000,3.62001,22141.91705,0.00000,0.01864,268.43568
75.20000,3.63998,22151.10064,0.00000,0.01884,268.54702
75.60000,3.65989,22158.14143,0.00000,0.01904,268.63237
76.00000,3.67986,22169.43353,0.00000,0.01925,268.76927
76.40000,3.69995,22178.93898,0.00000,0.01944,268.88451
76.80000,3.72004,22189.90475,0.00000,0.01964,269.01745
77.20000,3.74007,22199.49961,0.00000,0.01984,269.13378
77.60000,3.76010,22209.67561,0.00000,0.02003,269.25715
78.00000,3.78007,22217.67753,0.00000,0.02024,269.35416
78.40000,3.79998,22226.58396,0.00000,0.02044,269.46213
78.80000,3.82007,22235.26388,0.00000,0.02063,269.56736
79.20000,3.84004,22244.22395,0.00000,0.02083,269.67599
79.60000,3.86007,22251.61493,0.00000,0.02103,269.76559
80.00000,3.87992,22261.77454,0.00000,0.02122,269.88876
80.40000,3.89989,22269.10591,0.00000,0.02142,269.97764
80.80000,3.91992,22278.77527,0.00000,0.02162,270.09487
81.20000,3.93995,22287.86796,0.00000,0.02181,270.20510
81.60000,3.96004,22299.82018,0.00000,0.02200,270.35001
82.00000,3.98013,22309.30477,0.00000,0.02220,270.46499
82.40000,4.00010,22318.51816,0.00000,0.02240,270.57669
82.80000,4.02013,22327.75092,0.00000,0.02259,270.68862
83.20000,4.04004,22334.15991,0.00000,0.02279,270.76632
83.60000,4.06001,22342.51052,0.00000,0.02298,270.86756
84.00000,4.08003,22349.85530,0.00000,0.02317,270.95660
84.40000,4.10006,22358.45029,0.00000,0.02337,271.06080
84.80000,4.11991,22365.20499,0.00000,0.02356,271.14269
85.20000,4.13988,22375.94575,0.00000,0.02375,271.27291
85.60000,4.15991,22385.82522,0.00000,0.02395,271.39268
86.00000,4.17994,22394.23096,0.00000,0.02414,271.49459
86.40000,4.20003,22402.84085,0.00000,0.02434,271.59897
86.80000,4.22006,22411.82625,0.00000,0.02453,271.70790
87.20000,4.24009,22420.81612,0.00000,0.02472,271.81689
87.60000,4.26006,22428.79272,0.00000,0.02491,271.91359
88.00000,4.27997,22436.80507,0.00000,0.02510,272.01073
88.40000,4.30006,22445.10502,0.00000,0.02529,272.11135
88.80000,4.32003,22450.28168,0.00000,0.02548,272.17411
89.20000,4.34000,22458.57120,0.00000,0.02568,272.27461
89.60000,4.35997,22468.14519,0.00000,0.02587,272.39068
90.00000,4.37994,22476.64183,0.00000,0.02606,272.49369
90.40000,4.39985,22485.07738,0.00000,0.02624,272.59596
90.80000,4.41994,22492.79171,0.00000,0.02644,272.68948
91.20000,4.43997,22502.77996,0.00000,0.02663,272.81057
91.60000,4.46012,22512.31968,0.00000,0.02682,272.92623
92.00000,4.48009,22517.81523,0.00000,0.02701,272.99285
92.40000,4.50006,22527.62914,0.00000,0.02720,273.11183
92.80000,4.52003,22534.83087,0.00000,0.02738,273.19914
93.20000,4.54006,22541.24135,0.00000,0.02757,273.27685
93.60000,4.55996,22545.81004,0.00000,0.02776,273.33224
94.00000,4.57999,22554.54808,0.00000,0.02794,273.43818
94.40000,4.59996,22562.85250,0.00000,0.02813,273.53886
94.80000,4.61987,22571.79916,0.00000,0.02832,273.64732
95.20000,4.63996,22579.63717,0.00000,0.02851,273.74234
95.60000,4.65993,22585.89268,0.00000,0.02870,273.81818
96.00000,4.68002,22594.71565,0.00000,0.02888,273.92515
96.40000,4.70005,22602.10216,0.00000,0.02906,274.01470
96.80000,4.72008,22610.31568,0.00000,0.02925,274.11427
97.20000,4.73999,22616.15843,0.00000,0.02943,274.18511
97.60000,4.76002,22624.54629,0.00000,0.02962,274.28680
98.00000,4.77993,22630.53656,0.00000,0.02980,274.35942
98.40000,4.79996,22636.84571,0.00000,0.02999,274.43591
98.80000,4.81999,22643.55272,0.00000,0.03017,274.51722
99.20000,4.83996,22650.84982,0.00000,0.03035,274.60568
99.60000,4.85993,22658.38981,0.00000,0.03054,274.69709
100.00000,4.87990,22667.62555,0.00000,0.03072,274.80906
100.40000,4.89993,22675.46803,0.00000,0.03091,274.90414
100.80000,4.92002,22680.34667,0.00000,0.03109,274.96329
101.20000,4.94005,22688.50803,0.00000,0.03127,275.06223
101.60000,4.96014,22699.58705,0.00000,0.03146,275.19655
102.00000,4.98005,22703.02773,0.00000,0.03164,275.23826
102.40000,5.00002,22710.13111,0.00000,0.03182,275.32438
102.80000,5.02005,22716.47751,0.00000,0.03200,275.40132
103.20000,5.04002,22722.36347,0.00000,0.03217,275.47267
103.60000,5.06004,22730.01969,0.00000,0.03235,275.56549
104.00000,5.08001,22735.85200,0.00000,0.03253,275.63620
104.40000,5.09992,22740.91095,0.00000,0.03272,275.69753
104.80000,5.11995,22749.71008,0.00000,0.03290,275.80421
105.20000,5.13986,22756.37388,0.00000,0.03308,275.88500
105.60001,5.15995,22765.37567,0.00000,0.03325,275.99413
106.00001,5.18010,22770.10679,0.00000,0.03343,276.05149
106.40001,5.20013,22776.92109,0.00000,0.03360,276.13410
106.80001,5.21998,22781.69245,0.00000,0.03378,276.19194
107.20001,5.24001,22790.02517,0.00000,0.03396,276.29296
107.60001,5.25998,22795.65185,0.00000,0.03413,276.36118
108.00001,5.28001,22799.92849,0.00000,0.03431,276.41303
108.40001,5.30010,22806.15419,0.00000,0.03448,276.48850
108.80001,5.31995,22811.36811,0.00000,0.03466,276.55171
109.20001,5.33992,22818.48043,0.00000,0.03484,276.63794
109.60001,5.35989,22822.94333,0.00000,0.03501,276.69204
110.00001,5.37998,22831.87211,0.00000,0.03518,276.80029
110.40001,5.40001,22837.68505,0.00000,0.03535,276.87076
110.80001,5.42010,22844.22666,0.00000,0.03553,276.95007
111.20001,5.44007,22850.56561,0.00000,0.03570,277.02692
111.60001,5.46004,22855.69012,0.00000,0.03588,277.08905
112.00001,5.48001,22862.08123,0.00000,0.03605,277.16653
112.40001,5.50004,22869.21442,0.00000,0.03622,277.25301
112.80001,5.52001,22872.54184,0.00000,0.03639,277.29335
113.20001,5.54003,22875.86778,0.00000,0.03656,277.33367
113.60001,5.56000,22883.22747,0.00000,0.03674,277.42289
114.00001,5.57991,22890.08349,0.00000,0.03691,277.50601
114.40001,5.59994,22897.74418,0.00000,0.03708,277.59889
114.80001,5.61991,22902.65113,0.00000,0.03725,277.65838
115.20001,5.64000,22908.79935,0.00000,0.03742,277.73291
115.60001,5.66009,22915.39162,0.00000,0.03760,277.81283
116.00001,5.68012,22921.84830,0.00000,0.03777,277.89111
116.40001,5.70003,22926.74780,0.00000,0.03794,277.95051
116.80001,5.72000,22932.52498,0.00000,0.03812,278.02055
117.20001,5.73997,22938.04437,0.00000,0.03829,278.08746
117.60001,5.75994,22942.10941,0.00000,0.03846,278.13674
118.00001,5.78003,22948.07583,0.00000,0.03863,278.20908
118.40001,5.79994,22950.61052,0.00000,0.03881,278.23981
118.80001,5.81991,22957.25942,0.00000,0.03899,278.32041
119.20001,5.83994,22963.86808,0.00000,0.03916,278.40053
119.60001,5.85991,22972.31406,0.00000,0.03933,278.50293
120.00001,5.87994,22975.71599,0.00000,0.03951,278.54417
120.40001,5.90009,22981.54533,0.00000,0.03968,278.61484
120.80001,5.92006,22985.42708,0.00000,0.03987,278.66190
121.20001,5.94003,22992.33377,0.00000,0.04004,278.74564
121.60001,5.96000,22996.48225,0.00000,0.04022,278.79593
122.00001,5.97997,23001.98674,0.00000,0.04040,278.86266
122.40001,6.00000,23004.60339,0.00000,0.04058,278.89439
122.80001,6.01996,23009.71895,0.00000,0.04076,278.95640
123.20001,6.03987,23013.04936,0.00000,0.04094,278.99678
123.60001,6.05996,23019.25570,0.00000,0.04112,279.07202
124.00001,6.07993,23025.40392,0.00000,0.04130,279.14656
124.40001,6.09996,23032.67568,0.00000,0.04146,279.23472
124.80001,6.11999,23037.81807,0.00000,0.04163,279.29706
125.20001,6.14002,23040.54797,0.00000,0.04181,279.33016
125.60001,6.16017,23046.29982,0.00000,0.04198,279.39989
126.00001,6.18008,23049.35306,0.00000,0.04215,279.43690
126.40001,6.20005,23055.37462,0.00000,0.04233,279.50991
126.80001,6.22008,23059.75109,0.00000,0.04249,279.56296
127.20001,6.23999,23062.93249,0.00000,0.04266,279.60153
127.60001,6.25990,23064.58503,0.00000,0.04282,279.62157
128.00001,6.27993,23068.68732,0.00000,0.04299,279.67130
128.40001,6.29990,23076.90531,0.00000,0.04316,279.77093
128.80001,6.31987,23082.33529,0.00000,0.04332,279.83676
129.20001,6.33996,23088.58633,0.00000,0.04349,279.91255
129.60001,6.35999,23092.35334,0.00000,0.04365,279.95821
130.00001,6.38014,23097.30053,0.00000,0.04382,280.01819
130.40001,6.40017,23101.87519,0.00000,0.04399,280.07365
130.80001,6.42008,23105.96108,0.00000,0.04416,280.12319
131.20001,6.44005,23110.11255,0.00000,0.04432,280.17352
131.60001,6.46002,23112.77986,0.00000,0.04448,280.20585
132.00001,6.47987,23116.43958,0.00000,0.04464,280.25022
132.40001,6.49990,23120.58359,0.00000,0.04480,280.30046
132.80001,6.51992,23124.26120,0.00000,0.04497,280.34505
133.20001,6.53995,23130.52267,0.00000,0.04513,280.42096
133.60001,6.55998,23136.31177,0.00000,0.04530,280.49114
134.00001,6.57995,23141.80434,0.00000,0.04546,280.55773
134.40001,6.60004,23146.53546,0.00000,0.04562,280.61509
134.80001,6.62007,23148.31614,0.00000,0.04578,280.63668
135.20001,6.64010,23154.23638,0.00000,0.04594,280.70845
135.60001,6.66013,23157.16743,0.00000,0.04611,280.74398
136.00001,6.68010,23164.15459,0.00000,0.04628,280.82869
136.40001,6.69995,23165.53444,0.00000,0.04644,280.84542
136.80001,6.71992,23169.46089,0.00000,0.04660,280.89302
137.20001,6.73983,23171.26840,0.00000,0.04676,280.91493
137.60001,6.75986,23176.82505,0.00000,0.04693,280.98230
138.00001,6.78001,23182.60223,0.00000,0.04709,281.05234
138.40001,6.79998,23186.79094,0.00000,0.04725,281.10312
138.80001,6.82007,23192.88403,0.00000,0.04742,281.17699
139.20001,6.84004,23195.77336,0.00000,0.04758,281.21202
139.60001,6.86007,23199.89353,0.00000,0.04774,281.26197
140.00001,6.88010,23202.94827,0.00000,0.04790,281.29900
140.40001,6.90013,23206.07752,0.00000,0.04807,281.33694
140.80001,6.92004,23208.84764,0.00000,0.04824,281.37052
141.20001,6.94007,23212.74281,0.00000,0.04840,281.41775
141.60001,6.95992,23214.67847,0.00000,0.04856,281.44121
142.00001,6.97988,23218.00888,0.00000,0.04871,281.48159
142.40001,6.99991,23223.92166,0.00000,0.04888,281.55327
142.80001,7.02000,23229.59304,0.00000,0.04905,281.62203
143.20001,7.03997,23234.66241,0.00000,0.04921,281.68349
143.60001,7.06000,23237.64712,0.00000,0.04938,281.71967
144.00001,7.08003,23241.64212,0.00000,0.04954,281.76810
144.40001,7.10006,23244.44205,0.00000,0.04970,281.80205
144.80001,7.12009,23247.96766,0.00000,0.04986,281.84479
145.20001,7.14006,23250.44870,0.00000,0.05003,281.87487
145.60001,7.16009,23253.67630,0.00000,0.05019,281.91400
146.00001,7.17988,23255.82653,0.00000,0.05035,281.94007
146.40001,7.19985,23261.11645,0.00000,0.05052,282.00420
146.80001,7.21988,23263.67646,0.00000,0.05068,282.03524
147.20001,7.23985,23266.27225,0.00000,0.05084,282.06671
147.60001,7.26000,23271.50851,0.00000,0.05100,282.13019
148.00001,7.28003,23276.42292,0.00000,0.05117,282.18977
148.40001,7.30000,23281.59362,0.00000,0.05134,282.25245
148.80001,7.32003,23283.55312,0.00000,0.05149,282.27621
149.20001,7.34006,23284.18344,0.00000,0.05165,282.28385
149.60001,7.36009,23287.42892,0.00000,0.05182,282.32320
150.00001,7.38012,23293.26123,0.00000,0.05198,282.39390
150.40001,7.40003,23294.54273,0.00000,0.05214,282.40944
150.80001,7.42000,23297.00291,0.00000,0.05231,282.43927
151.20001,7.43991,23299.83860,0.00000,0.05247,282.47364
151.60001,7.45988,23302.03950,0.00000,0.05263,282.50033
152.00001,7.47990,23305.27455,0.00000,0.05279,282.53955
152.40001,7.49999,23309.08626,0.00000,0.05295,282.58576
152.80001,7.52002,23312.63870,0.00000,0.05311,282.62883
153.20001,7.54005,23317.85411,0.00000,0.05327,282.69205
153.60001,7.56002,23319.75251,0.00000,0.05343,282.71507
154.00001,7.57999,23322.55542,0.00000,0.05359,282.74905
154.40001,7.60008,23324.85020,0.00000,0.05375,282.77687
154.80001,7.62005,23326.65920,0.00000,0.05390,282.79880
155.20001,7.64002,23331.45738,0.00000,0.05406,282.85697
155.60001,7.65993,23333.89968,0.00000,0.05423,282.88658
156.00001,7.67996,23336.83074,0.00000,0.05438,282.92212
156.40001,7.69993,23338.84090,0.00000,0.05455,282.94649
156.80001,7.71990,23340.66331,0.00000,0.05470,282.96858
157.20001,7.73993,23344.58977,0.00000,0.05486,283.01618
157.60001,7.76002,23348.59669,0.00000,0.05502,283.06476
158.00001,7.77999,23352.19830,0.00000,0.05518,283.10842
158.40001,7.80008,23357.07247,0.00000,0.05534,283.16751
158.80001,7.81999,23359.86495,0.00000,0.05550,283.20137
159.20001,7.84002,23361.44894,0.00000,0.05566,283.22057
159.60001,7.86005,23363.80333,0.00000,0.05582,283.24912
160.00001,7.88008,23365.77028,0.00000,0.05597,283.27296
160.40001,7.89999,23368.34371,0.00000,0.05613,283.30416
160.80001,7.91995,23372.13010,0.00000,0.05630,283.35006
161.20001,7.93992,23374.29076,0.00000,0.05646,283.37626
161.60001,7.95989,23374.55601,0.00000,0.05662,283.37948
162.00001,7.97998,23376.66750,0.00000,0.05677,283.40507
162.40001,7.99995,23381.95294,0.00000,0.05693,283.46915
162.80001,8.01998,23386.26385,0.00000,0.05709,283.52141
163.20001,8.04007,23387.75545,0.00000,0.05725,283.53950
163.60001,8.06004,23390.15454,0.00000,0.05741,283.56858
164.00001,8.08001,23393.42684,0.00000,0.05757,283.60825
164.40001,8.10004,23394.99742,0.00000,0.05773,283.62729
164.80001,8.12007,23397.69453,0.00000,0.05789,283.65999
165.20001,8.14004,23398.19074,0.00000,0.05805,283.66601
165.60001,8.16001,23399.81049,0.00000,0.05820,283.68565
166.00001,8.17986,23401.77447,0.00000,0.05836,283.70946
166.40001,8.19995,23405.38502,0.00000,0.05852,283.75323
166.80001,8.21998,23406.15243,0.00000,0.05868,283.76253
167.20001,8.24001,23410.46482,0.00000,0.05884,283.81481
167.60001,8.26004,23414.72358,0.00000,0.05900,283.86644
168.00001,8.28007,23417.49072,0.00000,0.05915,283.89999
168.40001,8.30004,23419.38615,0.00000,0.05932,283.92297
168.80001,8.32001,23419.56049,0.00000,0.05948,283.92508
169.20001,8.34004,23420.74960,0.00000,0.05963,283.93950
169.60001,8.36007,23424.20071,0.00000,0.05980,283.98134
170.00001,8.38004,23426.13786,0.00000,0.05995,284.00482
170.40001,8.39994,23427.29568,0.00000,0.06010,284.01886
170.80001,8.41992,23428.18528,0.00000,0.06027,284.02965
171.20001,8.43988,23430.50838,0.00000,0.06043,284.05781
171.60001,8.45991,23432.97303,0.00000,0.06059,284.08769
172.00001,8.48000,23436.90544,0.00000,0.06075,284.13536
172.40001,8.50009,23439.81862,0.00000,0.06091,284.17068
172.80001,8.52006,23443.04323,0.00000,0.06106,284.20977
173.20001,8.54003,23444.57507,0.00000,0.06122,284.22835
173.60001,8.56000,23444.76879,0.00000,0.06138,284.23069
174.00001,8.58003,23445.32907,0.00000,0.06154,284.23749
174.40001,8.60006,23446.75362,0.00000,0.06169,284.25476
174.80001,8.62003,23448.48365,0.00000,0.06185,284.27573
175.20001,8.63994,23449.67574,0.00000,0.06202,284.29018
175.60001,8.65985,23451.48623,0.00000,0.06217,284.31213
176.00001,8.67994,23453.84508,0.00000,0.06233,284.34073
176.40001,8.69997,23456.70909,0.00000,0.06249,284.37545
176.80001,8.72000,23460.62064,0.00000,0.06265,284.42287
177.20001,8.74015,23464.23268,0.00000,0.06281,284.46666
177.60001,8.76006,23463.31328,0.00000,0.06297,284.45552
178.00001,8.78003,23466.99983,0.00000,0.06312,284.50021
178.40001,8.80006,23467.90433,0.00000,0.06329,284.51118
178.80001,8.82003,23469.53899,0.00000,0.06345,284.53099
179.20001,8.84012,23467.62866,0.00000,0.06361,284.50783
179.60001,8.86003,23468.87738,0.00000,0.06377,284.52297
180.00001,8.87987,23469.79082,0.00000,0.06393,284.53405
180.40001,8.89985,23475.18951,0.00000,0.06409,284.59950
180.80001,8.91987,23476.95976,0.00000,0.06425,284.62096
181.20001,8.93996,23478.52439,0.00000,0.06441,284.63993
181.60001,8.95999,23482.12600,0.00000,0.06457,284.68359
182.00001,8.98008,23485.25971,0.00000,0.06474,284.72158
182.40001,9.00005,23484.84993,0.00000,0.06490,284.71661
182.80001,9.02002,23485.91983,0.00000,0.06506,284.72959
183.20001,9.04005,23487.88381,0.00000,0.06522,284.75340
183.60001,9.06002,23488.11626,0.00000,0.06539,284.75621
184.00001,9.08005,23489.00437,0.00000,0.06555,284.76698
184.40001,9.10002,23490.24415,0.00000,0.06571,284.78201
184.80001,9.11993,23491.33492,0.00000,0.06588,284.79523
185.20001,9.13990,23494.34346,0.00000,0.06603,284.83171
185.60001,9.15987,23497.07335,0.00000,0.06620,284.86480
186.00001,9.17996,23498.83318,0.00000,0.06636,284.88614
186.40001,9.20005,23499.43966,0.00000,0.06652,284.89349
186.80001,9.22014,23500.66155,0.00000,0.06668,284.90831
187.20001,9.24017,23503.13663,0.00000,0.06684,284.93831
187.60001,9.26008,23503.52705,0.00000,0.06700,284.94304
188.00001,9.28005,23505.31369,0.00000,0.06716,284.96471
188.40001,9.30002,23501.77318,0.00000,0.06732,284.92178
188.80001,9.31999,23502.91610,0.00000,0.06748,284.93564
189.20001,9.34002,23506.37466,0.00000,0.06764,284.97757
189.60001,9.35993,23507.33429,0.00000,0.06780,284.98920
190.00001,9.37996,23509.49049,0.00000,0.06796,285.01534
190.40001,9.39992,23511.36506,0.00000,0.06812,285.03807
190.80001,9.41995,23512.57652,0.00000,0.06828,285.05276
191.20001,9.43998,23513.99511,0.00000,0.06843,285.06995
191.60001,9.46013,23515.81901,0.00000,0.06860,285.09207
192.00001,9.48004,23515.28406,0.00000,0.06876,285.08558
192.40001,9.50007,23517.22568,0.00000,0.06892,285.10912
192.80001,9.52004,23518.34923,0.00000,0.06908,285.12274
193.20001,9.53995,23518.65619,0.00000,0.06924,285.12646
193.60001,9.56004,23519.14346,0.00000,0.06940,285.13237
194.00001,9.57995,23518.51612,0.00000,0.06956,285.12476
194.40001,9.59992,23521.75266,0.00000,0.06972,285.16400
194.80001,9.61995,23523.43500,0.00000,0.06988,285.18440
195.20001,9.63998,23525.76405,0.00000,0.07005,285.21263
195.60001,9.65995,23525.45112,0.00000,0.07020,285.20884
196.00001,9.68004,23527.79359,0.00000,0.07037,285.23724
196.40001,9.70007,23527.35996,0.00000,0.07053,285.23198
196.80001,9.72016,23530.42960,0.00000,0.07069,285.26920
197.20001,9.74007,23529.41483,0.00000,0.07085,285.25689
197.60001,9.76004,23529.68752,0.00000,0.07102,285.26020
198.00001,9.78001,23530.89005,0.00000,0.07117,285.27478
198.40001,9.79998,23529.99896,0.00000,0.07133,285.26397
198.80001,9.81995,23531.65448,0.00000,0.07150,285.28405
199.20001,9.83997,23533.48732,0.00000,0.07166,285.30627
199.60001,9.85994,23535.68673,0.00000,0.07182,285.33293
200.00001,9.87991,23536.01158,0.00000,0.07199,285.33687
200.40001,9.89994,23537.33480,0.00000,0.07215,285.35291
200.80001,9.92003,23537.72223,0.00000,0.07231,285.35761
201.20001,9.94012,23538.17075,0.00000,0.07247,285.36304
201.60001,9.96009,23539.37626,0.00000,0.07263,285.37766
202.00001,9.98006,23541.00943,0.00000,0.07280,285.39746
202.40001,10.00009,23540.75462,0.00000,0.07296,285.39437
202.80001,10.02000,23539.40159,0.00000,0.07312,285.37797
203.20001,10.03991,23539.40904,0.00000,0.07328,285.37806
203.60001,10.05994,23541.33278,0.00000,0.07344,285.40138
204.00001,10.07997,23541.67402,0.00000,0.07360,285.40552
204.40001,10.09994,23541.55928,0.00000,0.07376,285.40413
204.80001,10.11997,23543.49196,0.00000,0.07392,285.42756
205.20001,10.13994,23543.92707,0.00000,0.07408,285.43283
205.60001,10.16003,23545.38143,0.00000,0.07424,285.45046
206.00001,10.18012,23544.96568,0.00000,0.07440,285.44542
206.40001,10.20015,23545.44997,0.00000,0.07456,285.45129
206.80001,10.22006,23547.95039,0.00000,0.07472,285.48161
207.20001,10.24003,23549.27808,0.00000,0.07489,285.49770
207.60001,10.25994,23547.52123,0.00000,0.07504,285.47640
208.00001,10.27997,23545.31437,0.00000,0.07521,285.44965
208.40001,10.29994,23545.47083,0.00000,0.07537,285.45155
208.80001,10.31991,23546.83131,0.00000,0.07553,285.46804
209.20001,10.33999,23549.23934,0.00000,0.07569,285.49723
209.60001,10.35990,23547.90717,0.00000,0.07585,285.48108
210.00001,10.37999,23549.61783,0.00000,0.07601,285.50182
210.40001,10.39996,23549.07990,0.00000,0.07616,285.49530
210.80001,10.42005,23550.24666,0.00000,0.07632,285.50945
211.20001,10.44014,23552.47140,0.00000,0.07648,285.53642
211.60001,10.46011,23551.69505,0.00000,0.07664,285.52701
212.00001,10.47996,23550.89784,0.00000,0.07680,285.51734
212.40001,10.49999,23551.50729,0.00000,0.07696,285.52473
212.80001,10.51996,23550.79502,0.00000,0.07712,285.51609
213.20001,10.53993,23548.76697,0.00000,0.07728,285.49151
213.60001,10.56002,23549.04860,0.00000,0.07744,285.49492
214.00001,10.57999,23549.47776,0.00000,0.07759,285.50012
214.40001,10.60002,23551.71293,0.00000,0.07775,285.52722
214.80001,10.61993,23552.50716,0.00000,0.07791,285.53685
215.20001,10.64002,23553.36249,0.00000,0.07806,285.54722
215.60001,10.66005,23553.80058,0.00000,0.07823,285.55253
216.00001,10.68014,23554.57246,0.00000,0.07838,285.56189
216.40001,10.70005,23554.11500,0.00000,0.07854,285.55634
216.80001,10.72002,23552.71578,0.00000,0.07870,285.53938
217.20001,10.73993,23550.83227,0.00000,0.07885,285.51655
217.60001,10.75990,23550.36438,0.00000,0.07901,285.51087
218.00001,10.77992,23550.22430,0.00000,0.07917,285.50918
218.40001,10.80001,23549.73555,0.00000,0.07933,285.50325
218.80001,10.81998,23550.40610,0.00000,0.07948,285.51138
219.20001,10.83995,23551.21821,0.00000,0.07963,285.52122
219.60001,10.85992,23554.15374,0.00000,0.07979,285.55681
220.00001,10.88001,23554.88092,0.00000,0.07995,285.56563
220.40001,10.90010,23551.90068,0.00000,0.08010,285.52950
220.80001,10.92007,23551.73677,0.00000,0.08026,285.52751
221.20001,10.94010,23553.40719,0.00000,0.08042,285.54776
221.60001,10.96001,23551.22864,0.00000,0.08056,285.52135
222.00001,10.97998,23549.82048,0.00000,0.08072,285.50428
222.40001,11.00001,23548.40487,0.00000,0.08087,285.48712
222.80001,11.01986,23546.50050,0.00000,0.08103,285.46403
223.20001,11.04001,23549.68637,0.00000,0.08118,285.50265
223.60001,11.05998,23549.19016,0.00000,0.08133,285.49664
224.00001,11.07995,23550.30179,0.00000,0.08149,285.51011
224.40001,11.09998,23552.05715,0.00000,0.08164,285.53140
224.80001,11.12007,23552.62786,0.00000,0.08179,285.53831
225.20001,11.14004,23550.47315,0.00000,0.08195,285.51219
225.60001,11.16013,23550.94701,0.00000,0.08209,285.51794
226.00001,11.18010,23548.97708,0.00000,0.08225,285.49405
226.40001,11.20001,23548.88171,0.00000,0.08240,285.49290
226.80001,11.21998,23547.45716,0.00000,0.08255,285.47563
227.20001,11.23995,23546.26060,0.00000,0.08271,285.46112
227.60001,11.25992,23544.23851,0.00000,0.08285,285.43661
228.00001,11.27995,23544.89416,0.00000,0.08300,285.44456
228.40001,11.29998,23546.28593,0.00000,0.08315,285.46143
228.80001,11.32000,23548.00999,0.00000,0.08331,285.48233
229.20001,11.34003,23548.17837,0.00000,0.08346,285.48437
229.60001,11.36000,23546.55117,0.00000,0.08360,285.46464
230.00001,11.38003,23544.46948,0.00000,0.08375,285.43941
230.40001,11.40006,23544.55441,0.00000,0.08390,285.44044
230.80001,11.42003,23542.80353,0.00000,0.08405,285.41921
231.20001,11.44006,23540.54749,0.00000,0.08420,285.39186
231.60001,11.46003,23539.79498,0.00000,0.08434,285.38274
232.00001,11.48000,23540.94684,0.00000,0.08449,285.39670
232.40001,11.49985,23537.60302,0.00000,0.08463,285.35616
232.80001,11.51988,23536.27533,0.00000,0.08478,285.34007
233.20001,11.54003,23537.71478,0.00000,0.08492,285.35752
233.60001,11.56000,23539.24662,0.00000,0.08506,285.37609
234.00001,11.58003,23539.20639,0.00000,0.08521,285.37560
234.40001,11.60000,23536.27533,0.00000,0.08535,285.34007
234.80001,11.62003,23533.05370,0.00000,0.08550,285.30101
235.20001,11.64006,23532.03446,0.00000,0.08564,285.28865
235.60001,11.66003,23530.51901,0.00000,0.08578,285.27028
236.00001,11.68006,23529.68156,0.00000,0.08591,285.26013
236.40001,11.70003,23527.21095,0.00000,0.08605,285.23017
236.80001,11.71994,23525.88177,0.00000,0.08619,285.21406
237.20001,11.73985,23524.28138,0.00000,0.08632,285.19466
237.60001,11.75994,23523.68981,0.00000,0.08646,285.18749
238.00001,11.77996,23523.51248,0.00000,0.08659,285.18534
238.40001,11.79999,23521.38907,0.00000,0.08673,285.15959
238.80001,11.81996,23520.65295,0.00000,0.08686,285.15067
239.20001,11.83999,23519.17177,0.00000,0.08699,285.13271
239.60001,11.86002,23516.38675,0.00000,0.08712,285.09895
240.00001,11.88005,23512.61377,0.00000,0.08724,285.05321
240.40001,11.90008,23512.27552,0.00000,0.08737,285.04911
240.80001,11.92011,23510.25939,0.00000,0.08749,285.02466
241.20001,11.93996,23508.77374,0.00000,0.08762,285.00665
241.60001,11.95987,23504.81600,0.00000,0.08774,284.95867
242.00001,11.97990,23502.94292,0.00000,0.08786,284.93596
242.40001,11.99987,23500.36651,0.00000,0.08798,284.90473
242.80001,12.01990,23498.19839,0.00000,0.08809,284.87844
243.20001,12.03999,23496.37896,0.00000,0.08821,284.85639
243.60001,12.06008,23495.98855,0.00000,0.08832,284.85165
244.00001,12.08011,23491.66423,0.00000,0.08843,284.79923
244.40001,12.10008,23488.33084,0.00000,0.08854,284.75881
244.80001,12.11999,23483.85602,0.00000,0.08864,284.70456
245.20001,12.14014,23480.92049,0.00000,0.08875,284.66898
245.60001,12.16005,23477.62287,0.00000,0.08885,284.62900
246.00001,12.17996,23473.79774,0.00000,0.08895,284.58262
246.40001,12.19993,23470.84135,0.00000,0.08905,284.54678
246.80001,12.21984,23465.95377,0.00000,0.08914,284.48753
247.20001,12.23993,23460.89333,0.00000,0.08924,284.42618
247.60001,12.25995,23457.23957,0.00000,0.08933,284.38188
248.00001,12.28004,23453.36080,0.00000,0.08941,284.33486
248.40001,12.30007,23450.28520,0.00000,0.08950,284.29757
248.80001,12.32004,23442.84952,0.00000,0.08958,284.20743
249.20001,12.34007,23437.70862,0.00000,0.08966,284.14510
249.60001,12.36004,23430.69315,0.00000,0.08974,284.06005
250.00001,12.38007,23424.02786,0.00000,0.08981,283.97924
250.40001,12.40004,23416.92448,0.00000,0.08989,283.89313
250.80001,12.42001,23409.30700,0.00000,0.08995,283.80078
251.20001,12.43986,23402.12613,0.00000,0.09002,283.71372
251.60001,12.45983,23394.50866,0.00000,0.09008,283.62137
252.00001,12.47992,23387.28309,0.00000,0.09014,283.53377
252.40001,12.50001,23376.00887,0.00000,0.09019,283.39709
252.80001,12.52010,23368.66558,0.00000,0.09025,283.30806
253.20001,12.54007,23358.33758,0.00000,0.09030,283.18285
253.60001,12.56004,23350.03763,0.00000,0.09035,283.08223
254.00001,12.58007,23338.17631,0.00000,0.09039,282.93843
254.40001,12.60004,23324.67586,0.00000,0.09044,282.77476
254.80001,12.62007,23311.37806,0.00000,0.09048,282.61354
255.20001,12.64004,23296.41134,0.00000,0.09051,282.43209
255.60001,12.65995,23280.93052,0.00000,0.09055,282.24441
256.00001,12.67986,23265.32900,0.00000,0.09058,282.05527
256.40001,12.69989,23248.16585,0.00000,0.09061,281.84719
256.80001,12.71992,23230.77619,0.00000,0.09063,281.63637
257.20001,12.73994,23212.14676,0.00000,0.09066,281.41052
257.60001,12.76009,23194.03738,0.00000,0.09068,281.19097
258.00001,12.78006,23172.68103,0.00000,0.09070,280.93206
258.40001,12.80009,23150.10130,0.00000,0.09072,280.65832
258.80001,12.82006,23127.44856,0.00000,0.09073,280.38369
259.20001,12.83997,23098.62226,0.00000,0.09074,280.03422
259.60001,12.86006,23070.80775,0.00000,0.09076,279.69701
260.00001,12.88003,23039.87592,0.00000,0.09076,279.32201
260.40001,12.89994,23009.77558,0.00000,0.09077,278.95709
260.80001,12.91985,22978.38777,0.00000,0.09077,278.57656
261.20001,12.93982,22942.12133,0.00000,0.09077,278.13689
261.60001,12.95991,22907.06486,0.00000,0.09078,277.71189
262.00001,12.98000,22867.63638,0.00000,0.09078,277.23388
262.40001,13.00003,22828.33010,0.00000,0.09077,276.75735
262.80001,13.02006,22786.47870,0.00000,0.09077,276.24997
263.20001,13.04009,22741.35500,0.00000,0.09077,275.70292
263.60001,13.06000,22692.67142,0.00000,0.09076,275.11270
264.00001,13.07997,22640.87051,0.00000,0.09076,274.48470
264.40001,13.10000,22585.08950,0.00000,0.09074,273.80844
264.80001,13.11997,22528.93597,0.00000,0.09073,273.12767
265.20001,13.14000,22469.65617,0.00000,0.09072,272.40900
265.60001,13.15991,22409.33478,0.00000,0.09071,271.67770
266.00001,13.17994,22344.11836,0.00000,0.09070,270.88705
266.40001,13.19997,22274.52397,0.00000,0.09068,270.04333
266.80001,13.21993,22201.05678,0.00000,0.09067,269.15266
267.20001,13.24008,22121.61869,0.00000,0.09065,268.18959
267.60001,13.25999,22038.90234,0.00000,0.09064,267.18679
268.00001,13.28008,21953.81969,0.00000,0.09061,266.15530
268.40001,13.30005,21859.47001,0.00000,0.09059,265.01146
268.80001,13.31996,21756.75631,0.00000,0.09057,263.76622
269.20001,13.34005,21650.68239,0.00000,0.09054,262.48024
269.60001,13.36002,21530.03663,0.00000,0.09051,261.01760
270.00001,13.37999,21374.71735,0.00000,0.09048,259.13460
270.40001,13.39996,21213.69243,0.00000,0.09044,257.18243
270.80001,13.41999,20982.74231,0.00000,0.09038,254.38252
271.07801,13.43416,19622.92492,0.00000,0.08920,237.89689
271.08601,13.43512,15947.33596,0.00000,0.08653,193.33619
271.09401,13.43643,11320.56415,0.00000,0.08381,137.24391