File: scratch/college-stuff/ME Lab/ME lab Fall 2013/group9/group9.is_tens_RawData/Specimen_RawData_2.csv
Time,Extension,Load,Strain 2,Tensile strain,Tensile stress
(sec),(mm),(N),(mm/mm),(mm/mm),(MPa)
0.00000,0.00006,-0.04983,0.00000,0.00000,-0.00057
0.30000,0.01351,42.07772,0.00000,0.00001,0.48439
0.60000,0.02995,86.85704,0.00000,0.00001,0.99987
0.90000,0.04502,137.46854,0.00000,0.00001,1.58250
1.20000,0.06003,179.21078,0.00000,0.00001,2.06302
1.50000,0.07504,227.20650,0.00000,0.00000,2.61554
1.80000,0.08998,283.93809,0.00000,0.00000,3.26862
2.10000,0.10511,351.89316,0.00000,0.00000,4.05090
2.40000,0.11988,432.75538,0.00000,0.00000,4.98176
2.70000,0.13512,533.48993,0.00000,0.00001,6.14139
3.00000,0.14989,652.62448,0.00000,0.00002,7.51283
3.30000,0.16496,780.74611,0.00000,0.00003,8.98773
3.60000,0.18003,920.50247,0.00000,0.00005,10.59657
3.90000,0.19491,1063.56582,0.00000,0.00007,12.24347
4.20000,0.21010,1213.43900,0.00000,0.00009,13.96877
4.50000,0.22493,1371.13184,0.00000,0.00011,15.78408
4.80000,0.24000,1533.98803,0.00000,0.00014,17.65884
5.10000,0.25494,1709.67281,0.00000,0.00016,19.68127
5.40000,0.27001,1900.02583,0.00000,0.00019,21.87256
5.70000,0.28496,2089.89698,0.00000,0.00022,24.05831
6.00000,0.29996,2280.76633,0.00000,0.00024,26.25554
6.30000,0.31503,2480.28561,0.00000,0.00027,28.55235
6.60000,0.32986,2688.23337,0.00000,0.00030,30.94619
6.90000,0.34505,2910.57099,0.00000,0.00033,33.50568
7.20000,0.35987,3131.06664,0.00000,0.00037,36.04396
7.50000,0.37506,3354.31248,0.00000,0.00040,38.61390
7.80000,0.38989,3578.72546,0.00000,0.00044,41.19728
8.10000,0.40495,3800.54414,0.00000,0.00047,43.75080
8.40000,0.42002,4025.25924,0.00000,0.00050,46.33765
8.70000,0.43491,4245.06143,0.00000,0.00054,48.86795
9.00000,0.45004,4468.81428,0.00000,0.00057,51.44373
9.30000,0.46492,4684.07758,0.00000,0.00061,53.92178
9.60000,0.47999,4901.58983,0.00000,0.00064,56.42572
9.90000,0.49494,5112.80484,0.00000,0.00067,58.85717
10.20000,0.51000,5326.11385,0.00000,0.00071,61.31273
10.50000,0.52501,5540.87684,0.00000,0.00074,63.78502
10.80000,0.53996,5746.14033,0.00000,0.00077,66.14795
11.10000,0.55503,5955.87082,0.00000,0.00081,68.56231
11.40000,0.56991,6156.24860,0.00000,0.00084,70.86900
11.70000,0.58504,6357.01045,0.00000,0.00087,73.18012
12.00000,0.59981,6550.77472,0.00000,0.00090,75.41068
12.30000,0.61499,6743.14424,0.00000,0.00093,77.62518
12.60000,0.62994,6934.31571,0.00000,0.00096,79.82589
12.90000,0.64495,7114.64211,0.00000,0.00099,81.90176
13.20000,0.66002,7296.63149,0.00000,0.00101,83.99677
13.50000,0.67490,7467.07618,0.00000,0.00104,85.95888
13.80000,0.69009,7635.51220,0.00000,0.00106,87.89787
14.10000,0.70498,7781.14051,0.00000,0.00109,89.57430
14.40000,0.72004,7918.31166,0.00000,0.00110,91.15338
14.70000,0.73499,8054.15064,0.00000,0.00113,92.71712
15.00000,0.75006,8190.33459,0.00000,0.00115,94.28483
15.30000,0.76495,8331.71681,0.00000,0.00117,95.91238
15.60000,0.77995,8466.44416,0.00000,0.00119,97.46333
15.90000,0.79502,8611.77668,0.00000,0.00121,99.13635
16.20000,0.80985,8744.95432,0.00000,0.00124,100.66946
16.50000,0.82509,8887.76854,0.00000,0.00126,102.31349
16.80000,0.83986,9025.04772,0.00000,0.00128,103.89381
17.10000,0.85505,9168.74781,0.00000,0.00131,105.54805
17.40000,0.87000,9308.17276,0.00000,0.00133,107.15307
17.70000,0.88494,9448.03953,0.00000,0.00135,108.76318
18.00000,0.90007,9590.47452,0.00000,0.00137,110.40285
18.30000,0.91496,9727.68366,0.00000,0.00140,111.98236
18.60000,0.93003,9872.31135,0.00000,0.00142,113.64727
18.90000,0.94491,10013.04984,0.00000,0.00145,115.26742
19.20000,0.95998,10157.90924,0.00000,0.00147,116.93500
19.50000,0.97493,10300.89483,0.00000,0.00149,118.58101
19.80000,0.98999,10444.03389,0.00000,0.00152,120.22878
20.10000,1.00500,10590.21652,0.00000,0.00154,121.91160
20.40000,1.02001,10730.29414,0.00000,0.00157,123.52413
20.70000,1.03508,10877.87002,0.00000,0.00159,125.22298
21.00000,1.04990,11020.32289,0.00000,0.00161,126.86286
21.30000,1.06503,11166.49657,0.00000,0.00164,128.54557
21.60000,1.07992,11310.81879,0.00000,0.00166,130.20697
21.90000,1.09498,11453.81480,0.00000,0.00169,131.85310
22.20000,1.10999,11600.46309,0.00000,0.00172,133.54127
22.50000,1.12500,11745.25917,0.00000,0.00175,135.20812
22.80000,1.14007,11893.50858,0.00000,0.00177,136.91473
23.10000,1.15489,12036.87862,0.00000,0.00180,138.56516
23.40000,1.17008,12186.02583,0.00000,0.00182,140.28210
23.70000,1.18491,12330.24523,0.00000,0.00185,141.94232
24.00000,1.20003,12479.82383,0.00000,0.00188,143.66422
24.30000,1.21492,12627.24400,0.00000,0.00191,145.36128
24.60000,1.23005,12776.77417,0.00000,0.00194,147.08263
24.90000,1.24500,12927.46812,0.00000,0.00196,148.81738
25.20000,1.25994,13070.62954,0.00000,0.00199,150.46541
25.50000,1.27501,13221.54552,0.00000,0.00202,152.20272
25.80000,1.28990,13367.46514,0.00000,0.00204,153.88250
26.10000,1.30503,13516.47228,0.00000,0.00207,155.59783
26.40000,1.31991,13667.09918,0.00000,0.00210,157.33180
26.70000,1.33498,13814.13043,0.00000,0.00213,159.02439
27.00000,1.35005,13964.94061,0.00000,0.00215,160.76047
27.30000,1.36499,14110.73804,0.00000,0.00218,162.43885
27.60000,1.38006,14260.72568,0.00000,0.00221,164.16547
27.90000,1.39495,14408.01173,0.00000,0.00224,165.86098
28.20000,1.41002,14561.91689,0.00000,0.00227,167.63269
28.50000,1.42490,14707.39394,0.00000,0.00229,169.30739
28.80000,1.44003,14858.00892,0.00000,0.00233,171.04122
29.10000,1.45492,15007.93695,0.00000,0.00235,172.76715
29.40000,1.47004,15155.59703,0.00000,0.00238,174.46697
29.70000,1.48493,15308.45910,0.00000,0.00241,176.22668
30.00000,1.49988,15455.77198,0.00000,0.00244,177.92250
30.30000,1.51513,15610.13460,0.00000,0.00247,179.69948
30.60000,1.52989,15754.86064,0.00000,0.00250,181.36553
30.90000,1.54502,15905.21634,0.00000,0.00253,183.09638
31.20000,1.55991,16054.34567,0.00000,0.00256,184.81311
31.50000,1.57497,16203.83561,0.00000,0.00259,186.53400
31.80000,1.58998,16353.88434,0.00000,0.00262,188.26132
32.10000,1.60493,16502.14344,0.00000,0.00265,189.96804
32.40000,1.62006,16651.22509,0.00000,0.00268,191.68422
32.70000,1.63494,16795.77380,0.00000,0.00272,193.34823
33.00000,1.65001,16948.58521,0.00000,0.00275,195.10735
33.30000,1.66490,17095.96515,0.00000,0.00278,196.80395
33.60000,1.68003,17244.77708,0.00000,0.00282,198.51703
33.90000,1.69491,17390.18559,0.00000,0.00285,200.19093
34.20000,1.70998,17533.51539,0.00000,0.00288,201.84090
34.50000,1.72499,17682.70880,0.00000,0.00291,203.55837
34.80000,1.73987,17819.62514,0.00000,0.00295,205.13452
35.10000,1.75500,17967.12428,0.00000,0.00298,206.83248
35.40000,1.76983,18107.61094,0.00000,0.00302,208.44973
35.70000,1.78508,18250.12267,0.00000,0.00305,210.09028
36.00000,1.79996,18389.59306,0.00000,0.00308,211.69583
36.30000,1.81503,18528.14257,0.00000,0.00312,213.29077
36.60000,1.83004,18667.84990,0.00000,0.00316,214.89904
36.90000,1.84492,18802.17493,0.00000,0.00319,216.44535
37.20000,1.86005,18940.45770,0.00000,0.00323,218.03723
37.50000,1.87488,19069.45556,0.00000,0.00326,219.52221
37.80000,1.89007,19203.51833,0.00000,0.00330,221.06551
38.10000,1.90483,19327.99816,0.00000,0.00334,222.49848
38.40000,1.91996,19457.55631,0.00000,0.00338,223.98992
38.70000,1.93491,19582.75735,0.00000,0.00341,225.43120
39.00000,1.95003,19698.98641,0.00000,0.00345,226.76919
39.30000,1.96504,19822.80314,0.00000,0.00349,228.19454
39.60000,1.97987,19931.59205,0.00000,0.00353,229.44689
39.90000,1.99512,20048.53785,0.00000,0.00357,230.79313
40.20000,2.00994,20157.56816,0.00000,0.00360,232.04826
40.50000,2.02507,20261.98506,0.00000,0.00364,233.25028
40.80000,2.03996,20363.91050,0.00000,0.00368,234.42361
41.10000,2.05502,20462.14640,0.00000,0.00372,235.55448
41.40000,2.07003,20557.98471,0.00000,0.00376,236.65774
41.70000,2.08492,20645.90305,0.00000,0.00381,237.66983
42.00000,2.09999,20737.92815,0.00000,0.00385,238.72920
42.30000,2.11499,20820.26452,0.00000,0.00389,239.67703
42.60000,2.13006,20901.55333,0.00000,0.00393,240.61281
42.90000,2.14489,20979.08556,0.00000,0.00397,241.50534
43.20000,2.16007,21053.42895,0.00000,0.00402,242.36116
43.50000,2.17496,21122.65825,0.00000,0.00406,243.15810
43.80000,2.19003,21191.18869,0.00000,0.00410,243.94701
44.10000,2.20504,21257.73877,0.00000,0.00414,244.71311
44.40000,2.21992,21316.78760,0.00000,0.00418,245.39287
44.70000,2.23511,21381.16062,0.00000,0.00422,246.13391
45.00000,2.24994,21436.44840,0.00000,0.00426,246.77037
45.30000,2.26506,21494.33047,0.00000,0.00431,247.43669
45.60000,2.27995,21546.51135,0.00000,0.00435,248.03738
45.90000,2.29502,21600.18981,0.00000,0.00440,248.65531
46.20000,2.31003,21648.87339,0.00000,0.00444,249.21575
46.50000,2.32491,21693.40700,0.00000,0.00449,249.72840
46.80000,2.34004,21741.83130,0.00000,0.00454,250.28585
47.10000,2.35493,21782.74244,0.00000,0.00459,250.75681
47.40000,2.37000,21828.97180,0.00000,0.00464,251.28899
47.70000,2.38494,21869.21835,0.00000,0.00469,251.75229
48.00000,2.40001,21908.28025,0.00000,0.00475,252.20196
48.30000,2.41496,21948.19152,0.00000,0.00481,252.66141
48.60000,2.43008,21983.85298,0.00000,0.00487,253.07194
48.90000,2.44509,22023.46325,0.00000,0.00494,253.52792
49.20000,2.45998,22055.49181,0.00000,0.00501,253.89662
49.50000,2.47511,22091.17711,0.00000,0.00508,254.30742
49.80000,2.48993,22123.06112,0.00000,0.00515,254.67446
50.10000,2.50506,22153.21809,0.00000,0.00523,255.02162
50.40000,2.51995,22184.18568,0.00000,0.00531,255.37811
50.70000,2.53501,22215.23076,0.00000,0.00540,255.73549
51.00000,2.54996,22242.60122,0.00000,0.00549,256.05057
51.30000,2.56497,22270.77633,0.00000,0.00558,256.37492
51.60000,2.58004,22297.48219,0.00000,0.00567,256.68235
51.90000,2.59492,22319.89801,0.00000,0.00577,256.94039
52.20000,2.61005,22347.86153,0.00000,0.00589,257.26230
52.50000,2.62494,22369.35645,0.00000,0.00600,257.50974
52.80000,2.64006,22394.67502,0.00000,0.00612,257.80120
53.10000,2.65495,22418.24120,0.00000,0.00624,258.07249
53.40000,2.67002,22436.78570,0.00000,0.00637,258.28597
53.70000,2.68503,22458.83346,0.00000,0.00650,258.53978
54.00000,2.69991,22475.89380,0.00000,0.00664,258.73617
54.30000,2.71516,22499.08745,0.00000,0.00679,259.00317
54.60000,2.72987,22513.63248,0.00000,0.00694,259.17061
54.90000,2.74500,22533.03677,0.00000,0.00710,259.39399
55.20000,2.76000,22549.94363,0.00000,0.00726,259.58861
55.50000,2.77501,22564.12953,0.00000,0.00742,259.75192
55.80000,2.79002,22582.53545,0.00000,0.00758,259.96380
56.10000,2.80496,22595.93904,0.00000,0.00775,260.11810
56.40000,2.82003,22613.96945,0.00000,0.00792,260.32566
56.70000,2.83492,22624.44198,0.00000,0.00811,260.44622
57.00000,2.84993,22639.85872,0.00000,0.00829,260.62369
57.30000,2.86493,22653.51564,0.00000,0.00847,260.78090
57.60000,2.88006,22666.85218,0.00000,0.00866,260.93443
57.90000,2.89495,22680.48674,0.00000,0.00884,261.09139
58.20000,2.91001,22690.32598,0.00000,0.00903,261.20466
58.50000,2.92508,22705.62947,0.00000,0.00922,261.38082
58.80000,2.93997,22712.75818,0.00000,0.00942,261.46289
59.10000,2.95516,22727.06032,0.00000,0.00962,261.62753
59.40000,2.96992,22734.68524,0.00000,0.00981,261.71531
59.70000,2.98505,22747.47193,0.00000,0.01001,261.86250
60.00000,2.99994,22757.25156,0.00000,0.01021,261.97508
60.30000,3.01494,22766.23845,0.00000,0.01040,262.07854
60.60000,3.03001,22778.96702,0.00000,0.01060,262.22507
60.90000,3.04496,22786.04358,0.00000,0.01079,262.30653
61.20000,3.06015,22800.42171,0.00000,0.01099,262.47205
61.50000,3.07491,22806.14525,0.00000,0.01119,262.53793
61.80000,3.08998,22818.70097,0.00000,0.01139,262.68247
62.10000,3.10493,22827.08436,0.00000,0.01159,262.77898
62.40000,3.12011,22836.94595,0.00000,0.01178,262.89250
62.70000,3.13494,22847.32312,0.00000,0.01197,263.01196
63.00000,3.15001,22852.35226,0.00000,0.01217,263.06986
63.30000,3.16502,22864.40581,0.00000,0.01237,263.20861
63.60000,3.17984,22872.20806,0.00000,0.01257,263.29843
63.90000,3.19509,22881.24561,0.00000,0.01276,263.40247
64.20000,3.20992,22889.74971,0.00000,0.01295,263.50036
64.50000,3.22505,22899.09124,0.00000,0.01314,263.60790
64.80000,3.24005,22905.95025,0.00000,0.01333,263.68686
65.10000,3.25494,22913.29056,0.00000,0.01352,263.77136
65.40000,3.27001,22923.35033,0.00000,0.01371,263.88717
65.70000,3.28495,22928.90549,0.00000,0.01389,263.95112
66.00000,3.30002,22940.04858,0.00000,0.01409,264.07939
66.30000,3.31497,22944.24325,0.00000,0.01427,264.12768
66.60000,3.33004,22954.74261,0.00000,0.01445,264.24855
66.90000,3.34486,22961.15309,0.00000,0.01464,264.32234
67.20000,3.36011,22971.11154,0.00000,0.01482,264.43698
67.50000,3.37500,22980.30257,0.00000,0.01500,264.54278
67.80000,3.39000,22984.37059,0.00000,0.01518,264.58961
68.10000,3.40507,22994.51530,0.00000,0.01536,264.70640
68.40000,3.41990,23000.64564,0.00000,0.01555,264.77697
68.70000,3.43509,23010.04678,0.00000,0.01573,264.88519
69.00000,3.44985,23016.15477,0.00000,0.01591,264.95550
69.30000,3.46492,23023.50551,0.00000,0.01608,265.04012
69.60000,3.47999,23032.31210,0.00000,0.01626,265.14150
69.90000,3.49499,23037.15348,0.00000,0.01643,265.19724
70.20000,3.51000,23046.64105,0.00000,0.01661,265.30645
70.50000,3.52495,23052.55681,0.00000,0.01678,265.37455
70.80000,3.54014,23063.27820,0.00000,0.01696,265.49798
71.10000,3.55496,23067.03329,0.00000,0.01713,265.54120
71.40000,3.57009,23076.76971,0.00000,0.01730,265.65329
71.70000,3.58492,23082.01194,0.00000,0.01748,265.71363
72.00000,3.60010,23090.44749,0.00000,0.01765,265.81074
72.30000,3.61493,23098.34510,0.00000,0.01782,265.90166
72.60000,3.62994,23101.87966,0.00000,0.01799,265.94235
72.90000,3.64507,23112.17785,0.00000,0.01815,266.06090
73.20000,3.65989,23113.91681,0.00000,0.01832,266.08091
73.50000,3.67508,23121.97834,0.00000,0.01849,266.17372
73.80000,3.68991,23130.43177,0.00000,0.01866,266.27103
74.10000,3.70498,23139.12064,0.00000,0.01882,266.37105
74.40000,3.72010,23147.31628,0.00000,0.01899,266.46540
74.70000,3.73505,23153.27525,0.00000,0.01915,266.53400
75.00000,3.75006,23159.62315,0.00000,0.01932,266.60707
75.30000,3.76506,23164.42430,0.00000,0.01949,266.66234
75.60000,3.78007,23174.46619,0.00000,0.01966,266.77794
75.90000,3.79484,23177.32126,0.00000,0.01981,266.81081
76.20000,3.81009,23188.94714,0.00000,0.01997,266.94464
76.50000,3.82491,23192.43401,0.00000,0.02014,266.98478
76.80000,3.84010,23199.64021,0.00000,0.02030,267.06774
77.10000,3.85499,23206.93135,0.00000,0.02046,267.15167
77.40000,3.86993,23211.55369,0.00000,0.02063,267.20488
77.70000,3.88512,23222.58949,0.00000,0.02079,267.33192
78.00000,3.89989,23224.21223,0.00000,0.02095,267.35060
78.30000,3.91508,23233.22892,0.00000,0.02110,267.45440
78.60000,3.92996,23238.08819,0.00000,0.02126,267.51034
78.90000,3.94497,23244.68344,0.00000,0.02142,267.58626
79.20000,3.96004,23252.94167,0.00000,0.02158,267.68133
79.50000,3.97504,23258.35526,0.00000,0.02173,267.74365
79.80000,3.98999,23266.31993,0.00000,0.02189,267.83534
80.10000,4.00506,23271.14493,0.00000,0.02205,267.89088
80.40000,4.02013,23280.61908,0.00000,0.02220,267.99994
80.70000,4.03495,23281.37904,0.00000,0.02236,268.00869
81.00000,4.05008,23291.69810,0.00000,0.02251,268.12748
81.30000,4.06491,23296.86135,0.00000,0.02267,268.18692
81.60000,4.08003,23301.94712,0.00000,0.02282,268.24547
81.90000,4.09498,23310.10848,0.00000,0.02297,268.33942
82.20000,4.10987,23310.84311,0.00000,0.02312,268.34787
82.50000,4.12506,23319.80318,0.00000,0.02328,268.45102
82.80000,4.13988,23325.86199,0.00000,0.02343,268.52077
83.10000,4.15501,23333.73576,0.00000,0.02359,268.61141
83.40000,4.16996,23339.43397,0.00000,0.02374,268.67700
83.70000,4.18497,23345.44808,0.00000,0.02390,268.74624
84.00000,4.20003,23352.08058,0.00000,0.02404,268.82259
84.30000,4.21504,23355.88634,0.00000,0.02419,268.86640
84.60000,4.22999,23363.21175,0.00000,0.02434,268.95073
84.90000,4.24505,23369.50153,0.00000,0.02449,269.02313
85.20000,4.26006,23376.55872,0.00000,0.02464,269.10437
85.50000,4.27483,23379.36312,0.00000,0.02480,269.13666
85.80000,4.29008,23389.03546,0.00000,0.02496,269.24800
86.10000,4.30496,23394.16146,0.00000,0.02510,269.30701
86.40000,4.32003,23397.26090,0.00000,0.02525,269.34269
86.70000,4.33504,23408.24157,0.00000,0.02540,269.46910
87.00000,4.34986,23411.04001,0.00000,0.02554,269.50131
87.30000,4.36517,23419.93749,0.00000,0.02570,269.60374
87.60000,4.37994,23424.29310,0.00000,0.02585,269.65388
87.90000,4.39501,23429.68285,0.00000,0.02600,269.71592
88.20000,4.41001,23437.05446,0.00000,0.02614,269.80078
88.50000,4.42502,23442.83015,0.00000,0.02629,269.86727
88.80000,4.44003,23449.73832,0.00000,0.02644,269.94680
89.10000,4.45503,23453.25798,0.00000,0.02660,269.98731
89.40000,4.47004,23461.75462,0.00000,0.02675,270.08512
89.70000,4.48499,23463.99873,0.00000,0.02690,270.11096
90.00000,4.50006,23474.06894,0.00000,0.02704,270.22688
90.30000,4.51488,23476.55892,0.00000,0.02719,270.25555
90.60000,4.53007,23484.17938,0.00000,0.02733,270.34327
90.90000,4.54490,23489.62426,0.00000,0.02748,270.40595
91.20000,4.55996,23491.68509,0.00000,0.02763,270.42968
91.50000,4.57503,23501.91474,0.00000,0.02778,270.54744
91.80000,4.58986,23504.29147,0.00000,0.02793,270.57480
92.10000,4.60511,23512.63016,0.00000,0.02808,270.67079
92.40000,4.61987,23517.24207,0.00000,0.02822,270.72388
92.70000,4.63506,23523.67043,0.00000,0.02837,270.79788
93.00000,4.65001,23528.07969,0.00000,0.02852,270.84864
93.30000,4.66502,23534.14148,0.00000,0.02866,270.91842
93.60000,4.68002,23539.89482,0.00000,0.02881,270.98465
93.90000,4.69503,23544.40391,0.00000,0.02896,271.03656
94.20000,4.70998,23552.73664,0.00000,0.02910,271.13248
94.50000,4.72492,23552.34772,0.00000,0.02925,271.12801
94.80000,4.73999,23562.06924,0.00000,0.02940,271.23992
95.10000,4.75488,23563.77691,0.00000,0.02954,271.25958
95.40000,4.77001,23571.22302,0.00000,0.02969,271.34529
95.70000,4.78489,23578.87030,0.00000,0.02984,271.43333
96.00000,4.79996,23581.13080,0.00000,0.02999,271.45935
96.30000,4.81503,23589.72430,0.00000,0.03013,271.55828
96.60000,4.82991,23591.35151,0.00000,0.03027,271.57701
96.90000,4.84516,23599.40857,0.00000,0.03042,271.66976
97.20000,4.85999,23602.73302,0.00000,0.03056,271.70803
97.50000,4.87506,23610.61722,0.00000,0.03071,271.79879
97.80000,4.89000,23615.09502,0.00000,0.03086,271.85034
98.10000,4.90507,23622.73633,0.00000,0.03101,271.93830
98.40000,4.92002,23625.08625,0.00000,0.03115,271.96535
98.70000,4.93502,23630.33742,0.00000,0.03130,272.02580
99.00000,4.95003,23637.05486,0.00000,0.03144,272.10313
99.30000,4.96498,23638.88174,0.00000,0.03159,272.12416
99.60000,4.98005,23647.41266,0.00000,0.03173,272.22237
99.90000,4.99487,23650.12169,0.00000,0.03187,272.25355
100.20000,5.01012,23657.91053,0.00000,0.03202,272.34322
100.50000,5.02501,23663.69963,0.00000,0.03217,272.40986
100.80000,5.04002,23665.90947,0.00000,0.03231,272.43530
101.10000,5.05508,23675.00514,0.00000,0.03245,272.54000
101.40000,5.06997,23677.13153,0.00000,0.03260,272.56448
101.70000,5.08510,23683.59268,0.00000,0.03274,272.63886
102.00000,5.09992,23685.62520,0.00000,0.03288,272.66226
102.30000,5.11499,23692.50059,0.00000,0.03303,272.74141
102.60000,5.13000,23697.73984,0.00000,0.03318,272.80172
102.90000,5.14501,23703.11916,0.00000,0.03332,272.86365
103.20000,5.15995,23709.79488,0.00000,0.03346,272.94049
103.50000,5.17496,23712.04197,0.00000,0.03360,272.96636
103.80000,5.19003,23718.38689,0.00000,0.03375,273.03940
104.10000,5.20497,23718.67597,0.00000,0.03389,273.04273
104.40000,5.21998,23726.74495,0.00000,0.03403,273.13562
104.70000,5.23487,23732.18387,0.00000,0.03417,273.19823
105.00000,5.25006,23736.71681,0.00000,0.03432,273.25041
105.30001,5.26500,23744.26574,0.00000,0.03446,273.33731
105.60001,5.28001,23746.49346,0.00000,0.03460,273.36296
105.90001,5.29514,23755.16891,0.00000,0.03474,273.46283
106.20001,5.30996,23757.37280,0.00000,0.03489,273.48820
106.50001,5.32509,23763.30048,0.00000,0.03503,273.55644
106.80001,5.33992,23766.94679,0.00000,0.03517,273.59841
107.10001,5.35505,23772.75825,0.00000,0.03532,273.66531
107.40001,5.36999,23773.96822,0.00000,0.03545,273.67924
107.70001,5.38500,23780.99412,0.00000,0.03559,273.76012
108.00001,5.40001,23786.47029,0.00000,0.03574,273.82316
108.30001,5.41495,23788.04535,0.00000,0.03588,273.84129
108.60001,5.43002,23797.84435,0.00000,0.03602,273.95410
108.90001,5.44491,23799.01409,0.00000,0.03617,273.96756
109.20001,5.46004,23806.50192,0.00000,0.03631,274.05376
109.50001,5.47492,23810.47159,0.00000,0.03645,274.09946
109.80001,5.49005,23814.91363,0.00000,0.03658,274.15059
110.10001,5.50500,23822.54452,0.00000,0.03673,274.23844
110.40001,5.52001,23822.94834,0.00000,0.03686,274.24309
110.70001,5.53507,23829.24110,0.00000,0.03701,274.31553
111.00001,5.54996,23832.30925,0.00000,0.03714,274.35085
111.30001,5.56509,23837.27580,0.00000,0.03729,274.40802
111.60001,5.57997,23841.52710,0.00000,0.03743,274.45696
111.90001,5.59504,23846.54731,0.00000,0.03757,274.51475
112.20001,5.60999,23850.77775,0.00000,0.03771,274.56345
112.50001,5.62506,23854.04557,0.00000,0.03784,274.60107
112.80001,5.64000,23859.08812,0.00000,0.03799,274.65912
113.10001,5.65495,23861.84633,0.00000,0.03812,274.69087
113.40001,5.67008,23870.03601,0.00000,0.03826,274.78515
113.70001,5.68484,23869.85570,0.00000,0.03840,274.78307
114.00001,5.69997,23877.56556,0.00000,0.03854,274.87182
114.30001,5.71486,23880.65010,0.00000,0.03868,274.90733
114.60001,5.73011,23886.24400,0.00000,0.03882,274.97173
114.90001,5.74499,23890.32096,0.00000,0.03896,275.01866
115.20001,5.75994,23891.70825,0.00000,0.03910,275.03463
115.50001,5.77507,23900.99764,0.00000,0.03924,275.14157
115.80001,5.78995,23900.95443,0.00000,0.03937,275.14107
116.10001,5.80508,23907.49604,0.00000,0.03951,275.21637
116.40001,5.81991,23908.26195,0.00000,0.03964,275.22519
116.70001,5.83504,23915.49051,0.00000,0.03977,275.30840
117.00001,5.84998,23916.81224,0.00000,0.03991,275.32362
117.30001,5.86493,23922.03063,0.00000,0.04005,275.38369
117.60001,5.87994,23927.48445,0.00000,0.04019,275.44648
117.90001,5.89500,23929.23534,0.00000,0.04033,275.46663
118.20001,5.91007,23936.20163,0.00000,0.04047,275.54683
118.50001,5.92490,23937.62320,0.00000,0.04060,275.56319
118.80001,5.94003,23944.04411,0.00000,0.04074,275.63711
119.10001,5.95491,23948.12852,0.00000,0.04087,275.68412
119.40001,5.97010,23951.84934,0.00000,0.04101,275.72696
119.70001,5.98493,23956.39271,0.00000,0.04114,275.77926
120.00001,6.00000,23957.57437,0.00000,0.04128,275.79286
120.30001,6.01506,23963.39029,0.00000,0.04142,275.85981
120.60001,6.02989,23965.99650,0.00000,0.04155,275.88982
120.90001,6.04502,23972.11343,0.00000,0.04169,275.96023
121.20001,6.05996,23973.05816,0.00000,0.04182,275.97111
121.50001,6.07503,23980.03340,0.00000,0.04196,276.05140
121.80001,6.08998,23982.32669,0.00000,0.04210,276.07780
122.10001,6.10499,23985.59451,0.00000,0.04223,276.11542
122.40001,6.11999,23993.09576,0.00000,0.04236,276.20177
122.70001,6.13500,23994.24762,0.00000,0.04250,276.21503
123.00001,6.15007,24000.13953,0.00000,0.04263,276.28286
123.30001,6.16495,23998.91317,0.00000,0.04276,276.26874
123.60001,6.18008,24005.12844,0.00000,0.04290,276.34029
123.90001,6.19491,24007.51859,0.00000,0.04303,276.36781
124.20001,6.21010,24013.18997,0.00000,0.04317,276.43309
124.50001,6.22504,24019.60343,0.00000,0.04330,276.50692
124.80001,6.23999,24018.88222,0.00000,0.04344,276.49862
125.10001,6.25512,24024.59830,0.00000,0.04357,276.56442
125.40001,6.26994,24025.03192,0.00000,0.04370,276.56941
125.70001,6.28501,24029.85394,0.00000,0.04383,276.62492
126.00001,6.29990,24034.56569,0.00000,0.04395,276.67916
126.30001,6.31497,24039.52330,0.00000,0.04409,276.73624
126.60001,6.32997,24043.89679,0.00000,0.04422,276.78658
126.90001,6.34498,24045.37648,0.00000,0.04435,276.80362
127.20001,6.35999,24050.84521,0.00000,0.04448,276.86657
127.50001,6.37505,24051.72586,0.00000,0.04462,276.87671
127.80001,6.39012,24059.30310,0.00000,0.04475,276.96393
128.10001,6.40495,24058.11995,0.00000,0.04488,276.95031
128.40001,6.42008,24065.40960,0.00000,0.04501,277.03423
128.70001,6.43496,24067.31993,0.00000,0.04514,277.05622
129.00001,6.45009,24070.27185,0.00000,0.04527,277.09020
129.30001,6.46498,24075.41573,0.00000,0.04541,277.14942
129.60001,6.47993,24076.50799,0.00000,0.04553,277.16199
129.90001,6.49511,24083.23437,0.00000,0.04567,277.23942
130.20001,6.50988,24082.98850,0.00000,0.04579,277.23659
130.50001,6.52501,24088.19795,0.00000,0.04592,277.29656
130.80001,6.53995,24091.03960,0.00000,0.04605,277.32928
131.10001,6.55502,24095.24024,0.00000,0.04618,277.37763
131.40001,6.57003,24100.23510,0.00000,0.04631,277.43513
131.70001,6.58498,24102.17226,0.00000,0.04644,277.45743
132.00001,6.60004,24107.99712,0.00000,0.04657,277.52449
132.30001,6.61505,24107.40256,0.00000,0.04670,277.51764
132.60001,6.63006,24112.81466,0.00000,0.04683,277.57995
132.90001,6.64488,24115.04537,0.00000,0.04696,277.60562
133.20001,6.66013,24120.45747,0.00000,0.04709,277.66793
133.50001,6.67490,24122.43783,0.00000,0.04722,277.69072
133.80001,6.69003,24124.28707,0.00000,0.04735,277.71201
134.10001,6.70503,24129.75878,0.00000,0.04748,277.77500
134.40001,6.71992,24131.42323,0.00000,0.04761,277.79416
134.70001,6.73511,24135.68795,0.00000,0.04774,277.84326
135.00001,6.74993,24137.95143,0.00000,0.04786,277.86931
135.30001,6.76500,24142.24893,0.00000,0.04799,277.91878
135.60001,6.78001,24144.10710,0.00000,0.04812,277.94017
135.90001,6.79502,24147.82643,0.00000,0.04826,277.98299
136.20001,6.80996,24149.19883,0.00000,0.04838,277.99879
136.50001,6.82509,24153.22959,0.00000,0.04851,278.04519
136.80001,6.84004,24156.95488,0.00000,0.04865,278.08807
137.10001,6.85498,24157.66865,0.00000,0.04877,278.09629
137.40001,6.87011,24163.84667,0.00000,0.04890,278.16741
137.70001,6.88494,24162.14645,0.00000,0.04902,278.14784
138.00001,6.90013,24167.34099,0.00000,0.04915,278.20764
138.30001,6.91495,24169.63577,0.00000,0.04928,278.23405
138.60001,6.93002,24172.30010,0.00000,0.04941,278.26472
138.90001,6.94509,24178.05791,0.00000,0.04954,278.33101
139.20001,6.95986,24176.45305,0.00000,0.04966,278.31253
139.50001,6.97510,24183.11834,0.00000,0.04979,278.38926
139.80001,6.98993,24183.98559,0.00000,0.04992,278.39924
140.10001,7.00500,24188.92682,0.00000,0.05005,278.45613
140.40001,7.02000,24192.44349,0.00000,0.05017,278.49661
140.70001,7.03501,24196.18815,0.00000,0.05030,278.53972
141.00001,7.04996,24197.39813,0.00000,0.05043,278.55365
141.30001,7.06509,24199.52899,0.00000,0.05056,278.57818
141.60001,7.08003,24205.14524,0.00000,0.05069,278.64283
141.90001,7.09498,24202.51071,0.00000,0.05081,278.61250
142.20001,7.11005,24209.90467,0.00000,0.05093,278.69762
142.50001,7.12487,24209.13130,0.00000,0.05106,278.68872
142.80001,7.14006,24212.45128,0.00000,0.05119,278.72693
143.10001,7.15495,24214.60003,0.00000,0.05131,278.75167
143.40001,7.16996,24216.33005,0.00000,0.05144,278.77159
143.70001,7.18502,24223.60033,0.00000,0.05157,278.85528
144.00001,7.19985,24224.46012,0.00000,0.05170,278.86518
144.30001,7.21510,24230.35949,0.00000,0.05183,278.93309
144.60001,7.22992,24229.77090,0.00000,0.05195,278.92631
144.90001,7.24499,24233.61093,0.00000,0.05208,278.97052
145.20001,7.26000,24235.43185,0.00000,0.05220,278.99148
145.50001,7.27507,24239.54159,0.00000,0.05232,279.03879
145.80001,7.28989,24241.11664,0.00000,0.05245,279.05692
146.10001,7.30508,24242.85859,0.00000,0.05258,279.07697
146.40001,7.32003,24247.93988,0.00000,0.05271,279.13547
146.70001,7.33491,24245.09227,0.00000,0.05283,279.10269
147.00001,7.35010,24254.05681,0.00000,0.05296,279.20588
147.30001,7.36487,24252.58011,0.00000,0.05308,279.18889
147.60001,7.38012,24259.15301,0.00000,0.05321,279.26455
147.90001,7.39494,24260.89048,0.00000,0.05333,279.28455
148.20001,7.40995,24261.35242,0.00000,0.05346,279.28987
148.50001,7.42514,24267.70926,0.00000,0.05358,279.36305
148.80001,7.43991,24266.62743,0.00000,0.05371,279.35059
149.10001,7.45503,24270.78485,0.00000,0.05384,279.39845
149.40001,7.46992,24272.33756,0.00000,0.05396,279.41633
149.70001,7.48505,24277.35329,0.00000,0.05409,279.47407
150.00001,7.49999,24277.26388,0.00000,0.05421,279.47304
150.30001,7.51506,24281.01003,0.00000,0.05434,279.51616
150.60001,7.53001,24283.06937,0.00000,0.05447,279.53987
150.90001,7.54507,24284.72489,0.00000,0.05459,279.55893
151.20001,7.56002,24288.73181,0.00000,0.05471,279.60505
151.50001,7.57485,24286.81701,0.00000,0.05484,279.58301
151.80001,7.59004,24293.16789,0.00000,0.05496,279.65612
152.10001,7.60492,24294.38829,0.00000,0.05509,279.67017
152.40001,7.62005,24296.67413,0.00000,0.05521,279.69648
152.70001,7.63494,24301.55128,0.00000,0.05534,279.75263
153.00001,7.65001,24302.70314,0.00000,0.05546,279.76589
153.30001,7.66507,24307.09451,0.00000,0.05559,279.81644
153.60001,7.67990,24306.88441,0.00000,0.05572,279.81402
153.90001,7.69509,24310.33403,0.00000,0.05584,279.85373
154.20001,7.70997,24310.48155,0.00000,0.05597,279.85543
154.50001,7.72498,24315.72974,0.00000,0.05609,279.91585
154.80001,7.73993,24314.34691,0.00000,0.05622,279.89993
155.10001,7.75506,24319.93335,0.00000,0.05634,279.96424
155.40001,7.76994,24321.03604,0.00000,0.05647,279.97693
155.70001,7.78501,24321.77514,0.00000,0.05659,279.98544
156.00001,7.80008,24327.89654,0.00000,0.05672,280.05591
156.30001,7.81490,24325.85806,0.00000,0.05685,280.03244
156.60001,7.83009,24332.44884,0.00000,0.05697,280.10831
156.90001,7.84486,24333.35632,0.00000,0.05710,280.11876
157.20001,7.86005,24335.33520,0.00000,0.05722,280.14154
157.50001,7.87499,24337.77303,0.00000,0.05735,280.16960
157.80001,7.89000,24338.76991,0.00000,0.05747,280.18108
158.10001,7.90507,24343.04953,0.00000,0.05760,280.23034
158.40001,7.92001,24344.33848,0.00000,0.05773,280.24518
158.70001,7.93508,24345.11334,0.00000,0.05785,280.25410
159.00001,7.94997,24346.05062,0.00000,0.05797,280.26489
159.30001,7.96504,24349.87128,0.00000,0.05810,280.30887
159.60001,7.97998,24348.77604,0.00000,0.05823,280.29627
159.90001,7.99505,24354.36696,0.00000,0.05835,280.36063
160.20001,8.00994,24355.41451,0.00000,0.05848,280.37269
160.50001,8.02501,24355.54117,0.00000,0.05860,280.37414
160.80001,8.04007,24359.99960,0.00000,0.05873,280.42547
161.10001,8.05484,24356.91357,0.00000,0.05885,280.38994
161.40001,8.07009,24363.75022,0.00000,0.05898,280.46864
161.70001,8.08491,24365.91536,0.00000,0.05910,280.49357
162.00001,8.09998,24367.82420,0.00000,0.05923,280.51554
162.30001,8.11499,24370.45425,0.00000,0.05935,280.54582
162.60001,8.13000,24369.94463,0.00000,0.05947,280.53995
162.90001,8.14512,24374.40306,0.00000,0.05960,280.59128
163.20001,8.16001,24372.58214,0.00000,0.05972,280.57032
163.50001,8.17508,24377.52187,0.00000,0.05985,280.62718
163.80001,8.19002,24377.34306,0.00000,0.05998,280.62512
164.10001,8.20503,24380.39780,0.00000,0.06010,280.66029
164.40001,8.21998,24379.19229,0.00000,0.06022,280.64641
164.70001,8.23499,24381.37829,0.00000,0.06034,280.67157
165.00001,8.24999,24387.02285,0.00000,0.06046,280.73655
165.30001,8.26500,24385.20640,0.00000,0.06059,280.71564
165.60001,8.28007,24392.07286,0.00000,0.06071,280.79469
165.90001,8.29490,24389.96136,0.00000,0.06083,280.77038
166.20001,8.31014,24394.69546,0.00000,0.06096,280.82488
166.50001,8.32497,24395.96653,0.00000,0.06109,280.83951
166.80001,8.34004,24396.71010,0.00000,0.06120,280.84807
167.10001,8.35498,24400.42347,0.00000,0.06133,280.89082
167.40001,8.36999,24401.28773,0.00000,0.06145,280.90077
167.70001,8.38506,24403.10419,0.00000,0.06158,280.92168
168.00001,8.39994,24402.79424,0.00000,0.06170,280.91811
168.30001,8.41507,24406.47483,0.00000,0.06182,280.96048
168.60001,8.42996,24404.54364,0.00000,0.06194,280.93825
168.90001,8.44503,24409.49380,0.00000,0.06207,280.99523
169.20001,8.45991,24409.39397,0.00000,0.06219,280.99408
169.50001,8.47504,24412.07021,0.00000,0.06231,281.02489
169.80001,8.48999,24416.70299,0.00000,0.06243,281.07822
170.10001,8.50500,24413.65272,0.00000,0.06256,281.04311
170.40001,8.52006,24419.95144,0.00000,0.06268,281.11562
170.70001,8.53477,24416.79835,0.00000,0.06281,281.07932
171.00001,8.55008,24422.45036,0.00000,0.06293,281.14438
171.30001,8.56490,24421.08393,0.00000,0.06305,281.12865
171.60001,8.58003,24422.99575,0.00000,0.06318,281.15066
171.90001,8.59504,24425.79716,0.00000,0.06330,281.18291
172.20001,8.60999,24424.56782,0.00000,0.06342,281.16876
172.50001,8.62505,24430.33010,0.00000,0.06354,281.23509
172.80001,8.64000,24427.92505,0.00000,0.06366,281.20741
173.10001,8.65507,24430.75329,0.00000,0.06379,281.23997
173.40001,8.66995,24430.21089,0.00000,0.06391,281.23372
173.70001,8.68508,24433.96896,0.00000,0.06403,281.27698
174.00001,8.69997,24434.27891,0.00000,0.06415,281.28055
174.30001,8.71498,24435.01949,0.00000,0.06427,281.28908
174.60001,8.72998,24440.39136,0.00000,0.06439,281.35092
174.90001,8.74505,24438.50040,0.00000,0.06452,281.32915
175.20001,8.76006,24441.13642,0.00000,0.06464,281.35949
175.50001,8.77483,24441.13046,0.00000,0.06476,281.35942
175.80001,8.79013,24445.39070,0.00000,0.06488,281.40847
176.10001,8.80496,24445.83029,0.00000,0.06500,281.41353
176.40001,8.82003,24446.75565,0.00000,0.06512,281.42418
176.70001,8.83503,24448.19212,0.00000,0.06525,281.44072
177.00001,8.84998,24447.46047,0.00000,0.06537,281.43229
177.30001,8.86505,24449.47511,0.00000,0.06549,281.45549
177.60001,8.87987,24448.78072,0.00000,0.06561,281.44749
177.90001,8.89500,24454.81122,0.00000,0.06573,281.51691
178.20001,8.90995,24453.21828,0.00000,0.06585,281.49858
178.50001,8.92502,24457.55005,0.00000,0.06597,281.54844
178.80001,8.93996,24457.32653,0.00000,0.06609,281.54587
179.10001,8.95497,24457.56346,0.00000,0.06621,281.54860
179.40001,8.96998,24463.00089,0.00000,0.06633,281.61119
179.70001,8.98499,24459.73307,0.00000,0.06645,281.57357
180.00001,9.00005,24463.77873,0.00000,0.06657,281.62014
180.30001,9.01488,24461.65681,0.00000,0.06669,281.59572
180.60001,9.03013,24464.80840,0.00000,0.06682,281.63200
180.90001,9.04495,24464.17511,0.00000,0.06694,281.62471
181.20001,9.06002,24465.38806,0.00000,0.06705,281.63867
181.50001,9.07503,24469.50525,0.00000,0.06717,281.68607
181.80001,9.08998,24469.12676,0.00000,0.06729,281.68171
182.10001,9.10504,24470.30395,0.00000,0.06741,281.69526
182.40001,9.11993,24469.05226,0.00000,0.06753,281.68085
182.70001,9.13506,24473.50472,0.00000,0.06765,281.73211
183.00001,9.14994,24472.35435,0.00000,0.06777,281.71886
183.30001,9.16501,24476.40300,0.00000,0.06789,281.76547
183.60001,9.17990,24476.05431,0.00000,0.06801,281.76146
183.90001,9.19503,24476.54605,0.00000,0.06813,281.76712
184.20001,9.21003,24479.04497,0.00000,0.06825,281.79589
184.50001,9.22498,24476.49091,0.00000,0.06837,281.76648
184.80001,9.24017,24482.79262,0.00000,0.06848,281.83903
185.10001,9.25494,24480.49039,0.00000,0.06860,281.81252
185.40001,9.27006,24482.55271,0.00000,0.06872,281.83627
185.70001,9.28501,24482.86563,0.00000,0.06883,281.83987
186.00001,9.30002,24481.67503,0.00000,0.06895,281.82616
186.30001,9.31502,24485.62682,0.00000,0.06907,281.87165
186.60001,9.32991,24485.28409,0.00000,0.06919,281.86771
186.90001,9.34504,24488.41035,0.00000,0.06931,281.90370
187.20001,9.35993,24487.84560,0.00000,0.06942,281.89720
187.50001,9.37505,24491.12833,0.00000,0.06954,281.93499
187.80001,9.38994,24489.04514,0.00000,0.06966,281.91100
188.10001,9.40501,24490.91524,0.00000,0.06977,281.93253
188.40001,9.41995,24492.16098,0.00000,0.06989,281.94687
188.70001,9.43502,24492.51860,0.00000,0.07001,281.95099
189.00001,9.45003,24496.58960,0.00000,0.07013,281.99785
189.30001,9.46498,24493.07889,0.00000,0.07024,281.95744
189.60001,9.48010,24495.90713,0.00000,0.07036,281.99000
189.90001,9.49487,24495.05776,0.00000,0.07047,281.98022
190.20001,9.51012,24498.22575,0.00000,0.07059,282.01669
190.50001,9.52488,24497.84428,0.00000,0.07071,282.01230
190.80001,9.53995,24499.10194,0.00000,0.07082,282.02678
191.10001,9.55502,24501.55765,0.00000,0.07094,282.05504
191.40001,9.56997,24501.29390,0.00000,0.07106,282.05201
191.70001,9.58509,24502.32506,0.00000,0.07117,282.06388
192.00001,9.59992,24502.08813,0.00000,0.07129,282.06115
192.30001,9.61505,24505.99670,0.00000,0.07141,282.10615
192.60001,9.62994,24504.25178,0.00000,0.07152,282.08606
192.90001,9.64506,24504.53043,0.00000,0.07163,282.08927
193.20001,9.65995,24504.74799,0.00000,0.07175,282.09177
193.50001,9.67508,24504.21751,0.00000,0.07186,282.08566
193.80001,9.69008,24509.27049,0.00000,0.07198,282.14383
194.10001,9.70491,24505.82534,0.00000,0.07209,282.10417
194.40001,9.72016,24509.23026,0.00000,0.07221,282.14337
194.70001,9.73493,24506.33347,0.00000,0.07232,282.11002
195.00001,9.75011,24507.46596,0.00000,0.07244,282.12306
195.30001,9.76494,24508.13055,0.00000,0.07255,282.13071
195.60001,9.78001,24510.59818,0.00000,0.07266,282.15912
195.90001,9.79507,24513.90773,0.00000,0.07278,282.19722
196.20001,9.80996,24510.87236,0.00000,0.07289,282.16227
196.50001,9.82497,24510.63693,0.00000,0.07300,282.15956
196.80001,9.83997,24511.55633,0.00000,0.07311,282.17015
197.10001,9.85504,24513.69315,0.00000,0.07323,282.19475
197.40001,9.86993,24512.99876,0.00000,0.07334,282.18675
197.70001,9.88506,24515.69438,0.00000,0.07346,282.21778
198.00001,9.89994,24515.83594,0.00000,0.07357,282.21941
198.30001,9.91507,24514.33688,0.00000,0.07368,282.20216
198.60001,9.93008,24516.57504,0.00000,0.07379,282.22792
198.90001,9.94497,24513.32808,0.00000,0.07390,282.19054
199.20001,9.96009,24518.69994,0.00000,0.07401,282.25238
199.50001,9.97486,24517.11297,0.00000,0.07412,282.23411
199.80001,9.99005,24517.79842,0.00000,0.07423,282.24200
200.10001,10.00499,24519.26321,0.00000,0.07434,282.25887
200.40001,10.02000,24518.29016,0.00000,0.07446,282.24766
200.70001,10.03507,24522.06165,0.00000,0.07457,282.29108
201.00001,10.04990,24520.23029,0.00000,0.07467,282.27000
201.30001,10.06502,24522.62193,0.00000,0.07479,282.29753
201.60001,10.07997,24522.59362,0.00000,0.07490,282.29721
201.90001,10.09504,24523.94366,0.00000,0.07501,282.31275
202.20001,10.10998,24522.52358,0.00000,0.07512,282.29640
202.50001,10.12505,24523.98539,0.00000,0.07523,282.31323
202.80001,10.13994,24524.88542,0.00000,0.07534,282.32359
203.10001,10.15507,24524.26851,0.00000,0.07546,282.31649
203.40001,10.17001,24526.96860,0.00000,0.07556,282.34757
203.70001,10.18490,24523.81104,0.00000,0.07567,282.31122
204.00001,10.20015,24528.12791,0.00000,0.07578,282.36091
204.30001,10.21485,24527.96996,0.00000,0.07589,282.35910
204.60001,10.23004,24530.56425,0.00000,0.07600,282.38896
204.90001,10.24499,24531.23927,0.00000,0.07612,282.39673
205.20001,10.25994,24529.90711,0.00000,0.07622,282.38140
205.50001,10.27506,24531.00234,0.00000,0.07633,282.39400
205.80001,10.28995,24529.15311,0.00000,0.07645,282.37272
206.10001,10.30496,24531.81893,0.00000,0.07656,282.40340
206.40001,10.31991,24529.13225,0.00000,0.07667,282.37248
206.70001,10.33503,24534.29401,0.00000,0.07678,282.43190
207.00001,10.34992,24529.30212,0.00000,0.07689,282.37443
207.30001,10.36511,24531.52388,0.00000,0.07699,282.40001
207.60001,10.37999,24532.66084,0.00000,0.07710,282.41310
207.90001,10.39506,24530.71177,0.00000,0.07722,282.39066
208.20001,10.41007,24535.55465,0.00000,0.07732,282.44641
208.50001,10.42483,24530.89356,0.00000,0.07743,282.39275
208.80001,10.44014,24535.42352,0.00000,0.07755,282.44490
209.10001,10.45491,24533.19430,0.00000,0.07765,282.41924
209.40001,10.47004,24532.96036,0.00000,0.07776,282.41654
209.70001,10.48498,24533.28073,0.00000,0.07787,282.42023
210.00001,10.49999,24534.84833,0.00000,0.07798,282.43828
210.30001,10.51506,24536.48001,0.00000,0.07808,282.45706
210.60001,10.52995,24533.31798,0.00000,0.07820,282.42066
210.90001,10.54507,24533.55193,0.00000,0.07830,282.42335
211.20001,10.56002,24531.05003,0.00000,0.07841,282.39455
211.50001,10.57503,24532.87244,0.00000,0.07851,282.41553
211.80001,10.58991,24531.69525,0.00000,0.07862,282.40198
212.10001,10.60510,24533.50872,0.00000,0.07872,282.42286
212.40001,10.61993,24533.65177,0.00000,0.07883,282.42450
212.70001,10.63500,24530.41673,0.00000,0.07893,282.38726
213.00001,10.65006,24535.12996,0.00000,0.07904,282.44152
213.30001,10.66489,24532.20189,0.00000,0.07914,282.40781
213.60001,10.68014,24534.80065,0.00000,0.07925,282.43773
213.90001,10.69490,24533.52511,0.00000,0.07936,282.42305
214.20001,10.71003,24531.26162,0.00000,0.07946,282.39699
214.50001,10.72504,24532.71896,0.00000,0.07957,282.41377
214.80001,10.73999,24529.60461,0.00000,0.07966,282.37791
215.10001,10.75505,24531.23480,0.00000,0.07977,282.39668
215.40001,10.77000,24530.15745,0.00000,0.07987,282.38428
215.70001,10.78501,24530.00993,0.00000,0.07997,282.38258
216.00001,10.80001,24527.30387,0.00000,0.08007,282.35143
216.30001,10.81508,24528.67776,0.00000,0.08017,282.36724
216.60001,10.82997,24526.49176,0.00000,0.08027,282.34208
216.90001,10.84510,24526.35467,0.00000,0.08037,282.34050
217.20001,10.85992,24529.30510,0.00000,0.08047,282.37447
217.50001,10.87493,24524.43540,0.00000,0.08056,282.31841
217.80001,10.89006,24527.79114,0.00000,0.08066,282.35704
218.10001,10.90489,24522.47888,0.00000,0.08076,282.29588
218.40001,10.92007,24522.73667,0.00000,0.08086,282.29885
218.70001,10.93496,24523.31185,0.00000,0.08095,282.30547
219.00001,10.95003,24521.13777,0.00000,0.08104,282.28045
219.30001,10.96503,24521.40152,0.00000,0.08113,282.28348
219.60001,10.97998,24518.53901,0.00000,0.08122,282.25053
219.90001,10.99511,24519.21701,0.00000,0.08132,282.25833
220.20001,11.01005,24515.70332,0.00000,0.08141,282.21789
220.50001,11.02506,24515.20115,0.00000,0.08149,282.21211
220.80001,11.04001,24513.84217,0.00000,0.08158,282.19646
221.10001,11.05508,24513.37427,0.00000,0.08168,282.19107
221.40001,11.06991,24510.95283,0.00000,0.08176,282.16320
221.70001,11.08509,24510.25695,0.00000,0.08184,282.15519
222.00001,11.10004,24511.03926,0.00000,0.08193,282.16419
222.30001,11.11493,24503.81070,0.00000,0.08201,282.08098
222.60001,11.13005,24506.80584,0.00000,0.08209,282.11546
222.90001,11.14488,24502.71249,0.00000,0.08217,282.06834
223.20001,11.16013,24501.97041,0.00000,0.08226,282.05980
223.50001,11.17495,24499.09300,0.00000,0.08234,282.02667
223.80001,11.19002,24496.40036,0.00000,0.08241,281.99568
224.10001,11.20503,24494.60775,0.00000,0.08249,281.97504
224.40001,11.21998,24491.46509,0.00000,0.08256,281.93886
224.70001,11.23504,24488.66665,0.00000,0.08264,281.90665
225.00001,11.24999,24485.11273,0.00000,0.08271,281.86574
225.30001,11.26506,24485.47482,0.00000,0.08278,281.86990
225.60001,11.27995,24479.51287,0.00000,0.08286,281.80127
225.90001,11.29507,24479.61867,0.00000,0.08292,281.80249
226.20001,11.30990,24475.69668,0.00000,0.08299,281.75734
226.50001,11.32509,24471.94755,0.00000,0.08306,281.71418
226.80001,11.34003,24470.32928,0.00000,0.08312,281.69555
227.10001,11.35492,24460.34104,0.00000,0.08318,281.58057
227.40001,11.37005,24460.12646,0.00000,0.08324,281.57810
227.70001,11.38482,24453.01563,0.00000,0.08330,281.49624
228.00001,11.40006,24450.42729,0.00000,0.08336,281.46645
228.30001,11.41495,24445.16122,0.00000,0.08341,281.40583
228.60001,11.43002,24438.98171,0.00000,0.08347,281.33469
228.90001,11.44508,24433.72905,0.00000,0.08352,281.27422
229.20001,11.46003,24426.18310,0.00000,0.08357,281.18735
229.50001,11.47504,24422.08230,0.00000,0.08362,281.14015
229.80001,11.48999,24412.18495,0.00000,0.08367,281.02621
230.10001,11.50505,24409.44463,0.00000,0.08371,280.99467
230.40001,11.51988,24395.94418,0.00000,0.08376,280.83925
230.70001,11.53513,24390.82563,0.00000,0.08380,280.78033
231.00001,11.54989,24380.07444,0.00000,0.08384,280.65656
231.30001,11.56502,24367.68413,0.00000,0.08387,280.51393
231.60001,11.58003,24361.42713,0.00000,0.08391,280.44190
231.90001,11.59492,24344.19543,0.00000,0.08394,280.24354
232.20001,11.61010,24335.54828,0.00000,0.08397,280.14399
232.50001,11.62493,24317.36887,0.00000,0.08400,279.93472
232.80001,11.64006,24305.94862,0.00000,0.08403,279.80325
233.10001,11.65494,24289.67953,0.00000,0.08405,279.61596
233.40001,11.67001,24275.69628,0.00000,0.08407,279.45499
233.70001,11.68502,24256.88505,0.00000,0.08409,279.23844
234.00001,11.70003,24234.64656,0.00000,0.08411,278.98244
234.30001,11.71503,24214.86229,0.00000,0.08413,278.75469
234.60001,11.72992,24191.59710,0.00000,0.08414,278.48687
234.90001,11.74505,24172.16897,0.00000,0.08416,278.26322
235.20001,11.75994,24144.13989,0.00000,0.08417,277.94055
235.50001,11.77506,24119.23558,0.00000,0.08418,277.65386
235.80001,11.78989,24091.55518,0.00000,0.08418,277.33521
236.10001,11.80502,24059.94236,0.00000,0.08419,276.97129
236.40001,11.82002,24031.50052,0.00000,0.08420,276.64388
236.70001,11.83491,23993.47574,0.00000,0.08420,276.20615
237.00001,11.85010,23958.68450,0.00000,0.08420,275.80564
237.30001,11.86493,23917.91642,0.00000,0.08420,275.33633
237.60001,11.88005,23874.24856,0.00000,0.08419,274.83364
237.90001,11.89500,23830.18732,0.00000,0.08419,274.32642
238.20001,11.91001,23783.46771,0.00000,0.08419,273.78860
238.50001,11.92501,23730.33464,0.00000,0.08418,273.17694
238.80001,11.93996,23670.56161,0.00000,0.08417,272.48885
239.10001,11.95503,23598.93918,0.00000,0.08416,271.66435
239.40001,11.96998,23505.39565,0.00000,0.08414,270.58751
239.70001,11.98510,23387.85380,0.00000,0.08412,269.23440
240.00001,11.99987,23256.81001,0.00000,0.08409,267.72586
240.30001,12.01506,23077.59672,0.00000,0.08406,265.66281
240.60001,12.02994,22707.81696,0.00000,0.08398,261.40601
240.84801,12.04244,21814.50129,0.00000,0.08388,251.12241
240.85401,12.04286,19632.75671,0.00000,0.08423,226.00678
240.86001,12.04382,16182.86520,0.00000,0.08323,186.29260
240.86601,12.04495,12388.23384,0.00000,0.07642,142.60987