File: scratch/college-stuff/ME Lab/ME lab Fall 2013/group6/group6.is_tens_RawData/Specimen_RawData_5.csv
Time,Extension,Load,Strain 2,Tensile strain,Tensile stress
(sec),(mm),(N),(mm/mm),(mm/mm),(MPa)
0.00000,0.00000,0.25393,0.00000,0.00000,0.00305
0.20000,0.00753,7.20885,0.00000,0.00001,0.08671
0.40000,0.01949,8.30989,0.00000,0.00001,0.09995
0.60000,0.03001,10.87211,0.00000,0.00001,0.13077
0.80000,0.04012,11.50623,0.00000,0.00001,0.13840
1.00000,0.05004,13.43147,0.00000,0.00002,0.16155
1.20000,0.06009,14.77688,0.00000,0.00001,0.17773
1.40000,0.07001,16.19783,0.00000,0.00002,0.19483
1.60000,0.08012,16.72140,0.00000,0.00002,0.20112
1.80000,0.09004,18.40785,0.00000,0.00002,0.22141
2.00000,0.10003,19.46113,0.00000,0.00002,0.23408
2.20000,0.11001,21.11494,0.00000,0.00002,0.25397
2.40000,0.11988,23.35249,0.00000,0.00001,0.28088
2.60000,0.12998,25.20067,0.00000,0.00001,0.30311
2.80000,0.13991,25.91930,0.00000,0.00001,0.31175
3.00000,0.14995,29.54913,0.00000,0.00001,0.35541
3.20000,0.15994,30.46361,0.00000,0.00001,0.36641
3.40000,0.16992,32.41250,0.00000,0.00001,0.38985
3.60000,0.17997,37.93947,0.00000,0.00000,0.45633
3.80000,0.18995,40.50005,0.00000,0.00000,0.48713
4.00000,0.20006,47.18752,0.00000,-0.00001,0.56757
4.20000,0.21004,63.10371,0.00000,-0.00001,0.75900
4.40000,0.22009,78.90343,0.00000,-0.00001,0.94904
4.60000,0.23007,104.29200,0.00000,-0.00002,1.25441
4.80000,0.24011,134.97289,0.00000,-0.00002,1.62344
5.00000,0.25016,170.05677,0.00000,-0.00001,2.04542
5.20000,0.26008,216.55408,0.00000,0.00000,2.60469
5.40000,0.27013,266.34508,0.00000,0.00001,3.20357
5.60000,0.28005,312.48443,0.00000,0.00004,3.75852
5.80000,0.29004,365.90912,0.00000,0.00006,4.40111
6.00000,0.30008,421.10207,0.00000,0.00008,5.06496
6.20000,0.31001,476.90966,0.00000,0.00011,5.73621
6.40000,0.32005,539.03637,0.00000,0.00013,6.48346
6.60000,0.32998,599.80345,0.00000,0.00016,7.21436
6.80000,0.33990,657.87700,0.00000,0.00018,7.91286
7.00000,0.34995,711.58400,0.00000,0.00021,8.55884
7.20000,0.35987,764.28684,0.00000,0.00023,9.19275
7.40000,0.36992,814.25486,0.00000,0.00025,9.79376
7.60000,0.37984,863.60434,0.00000,0.00027,10.38733
7.80000,0.38989,908.06531,0.00000,0.00029,10.92210
8.00000,0.39993,949.88672,0.00000,0.00031,11.42512
8.20000,0.40992,989.78607,0.00000,0.00033,11.90502
8.40000,0.41996,1027.14244,0.00000,0.00035,12.35434
8.60000,0.42995,1063.76233,0.00000,0.00036,12.79480
8.80000,0.44005,1096.44439,0.00000,0.00037,13.18790
9.00000,0.45004,1127.40658,0.00000,0.00039,13.56031
9.20000,0.46008,1153.69111,0.00000,0.00040,13.87645
9.40000,0.47006,1180.61071,0.00000,0.00041,14.20024
9.60000,0.48005,1202.62830,0.00000,0.00042,14.46506
9.80000,0.49015,1224.26143,0.00000,0.00043,14.72526
10.00000,0.50008,1244.58484,0.00000,0.00044,14.96971
10.20000,0.51012,1263.01451,0.00000,0.00044,15.19138
10.40000,0.52005,1279.73342,0.00000,0.00045,15.39247
10.60000,0.53003,1294.18960,0.00000,0.00046,15.56635
10.80000,0.54008,1307.83878,0.00000,0.00046,15.73052
11.00000,0.55000,1319.20474,0.00000,0.00047,15.86723
11.20000,0.55999,1330.42149,0.00000,0.00047,16.00214
11.40000,0.56997,1343.82704,0.00000,0.00048,16.16338
11.60000,0.57996,1355.49605,0.00000,0.00049,16.30374
11.80000,0.58994,1366.28002,0.00000,0.00049,16.43345
12.00000,0.59981,1376.65775,0.00000,0.00049,16.55827
12.20000,0.60991,1391.01371,0.00000,0.00049,16.73094
12.40000,0.61984,1403.51076,0.00000,0.00051,16.88125
12.60000,0.62994,1417.02099,0.00000,0.00051,17.04375
12.80000,0.63999,1427.64812,0.00000,0.00051,17.17157
13.00000,0.64997,1435.14862,0.00000,0.00052,17.26179
13.20000,0.65996,1442.51380,0.00000,0.00052,17.35038
13.40000,0.66994,1446.41297,0.00000,0.00052,17.39728
13.60000,0.68005,1449.32363,0.00000,0.00052,17.43228
13.80000,0.69009,1459.16799,0.00000,0.00052,17.55069
14.00000,0.70008,1467.47101,0.00000,0.00053,17.65056
14.20000,0.71006,1481.33598,0.00000,0.00053,17.81733
14.40000,0.72004,1500.77287,0.00000,0.00054,18.05111
14.60000,0.73015,1523.56485,0.00000,0.00055,18.32525
14.80000,0.74013,1549.87909,0.00000,0.00057,18.64175
15.00000,0.75012,1578.11493,0.00000,0.00058,18.98137
15.20000,0.76004,1608.78021,0.00000,0.00059,19.35021
15.40000,0.77003,1641.96193,0.00000,0.00061,19.74931
15.60000,0.78001,1677.47568,0.00000,0.00063,20.17647
15.80000,0.79000,1712.26226,0.00000,0.00064,20.59488
16.00000,0.79998,1747.90323,0.00000,0.00066,21.02356
16.20000,0.80997,1785.94347,0.00000,0.00068,21.48111
16.40000,0.81995,1822.27381,0.00000,0.00070,21.91808
16.60000,0.82994,1861.55029,0.00000,0.00072,22.39050
16.80000,0.83986,1901.42170,0.00000,0.00074,22.87006
17.00000,0.84991,1940.68756,0.00000,0.00075,23.34235
17.20000,0.85989,1981.81011,0.00000,0.00078,23.83697
17.40000,0.87000,2022.05554,0.00000,0.00079,24.32103
17.60000,0.87992,2062.48816,0.00000,0.00081,24.80735
17.80000,0.88997,2106.10218,0.00000,0.00083,25.33194
18.00000,0.89995,2148.08676,0.00000,0.00085,25.83692
18.20000,0.91000,2191.55494,0.00000,0.00088,26.35975
18.40000,0.92004,2235.46661,0.00000,0.00090,26.88791
18.60000,0.93003,2281.63674,0.00000,0.00092,27.44324
18.80000,0.94007,2326.37040,0.00000,0.00094,27.98129
19.00000,0.95006,2370.27165,0.00000,0.00096,28.50933
19.20000,0.96004,2413.92776,0.00000,0.00098,29.03442
19.40000,0.97008,2458.88438,0.00000,0.00101,29.57516
19.60000,0.98007,2506.89797,0.00000,0.00103,30.15266
19.80000,0.99005,2552.80677,0.00000,0.00105,30.70484
20.00000,0.99998,2598.48069,0.00000,0.00107,31.25420
20.20000,1.01008,2645.07905,0.00000,0.00109,31.81468
20.40000,1.02001,2690.89360,0.00000,0.00111,32.36573
20.60000,1.02999,2736.55988,0.00000,0.00114,32.91500
20.80000,1.03998,2781.83203,0.00000,0.00116,33.45953
21.00000,1.04990,2829.81433,0.00000,0.00118,34.03666
21.20000,1.05995,2874.69141,0.00000,0.00120,34.57643
21.40000,1.06987,2921.87557,0.00000,0.00123,35.14396
21.60000,1.07986,2970.30825,0.00000,0.00125,35.72650
21.80000,1.08996,3020.79897,0.00000,0.00127,36.33379
22.00000,1.09989,3071.79186,0.00000,0.00130,36.94713
22.20000,1.10993,3123.05037,0.00000,0.00132,37.56366
22.40000,1.11992,3176.13333,0.00000,0.00135,38.20214
22.60000,1.12996,3227.43841,0.00000,0.00138,38.81923
22.80000,1.13995,3279.46879,0.00000,0.00140,39.44504
23.00000,1.14993,3332.93416,0.00000,0.00143,40.08812
23.20000,1.16004,3384.57897,0.00000,0.00145,40.70930
23.40000,1.17002,3436.87944,0.00000,0.00148,41.33836
23.60000,1.18007,3488.31825,0.00000,0.00151,41.95706
23.80000,1.19005,3541.66366,0.00000,0.00153,42.59869
24.00000,1.20009,3593.06931,0.00000,0.00156,43.21699
24.20000,1.21008,3645.22822,0.00000,0.00159,43.84435
24.40000,1.22000,3696.71658,0.00000,0.00161,44.46365
24.60000,1.23011,3750.20690,0.00000,0.00164,45.10702
24.80000,1.23997,3802.50514,0.00000,0.00167,45.73606
25.00000,1.25002,3854.40737,0.00000,0.00169,46.36033
25.20000,1.25994,3906.39417,0.00000,0.00172,46.98562
25.40000,1.26993,3959.33948,0.00000,0.00175,47.62244
25.60000,1.27997,4011.41867,0.00000,0.00177,48.24885
25.80000,1.28996,4061.57449,0.00000,0.00180,48.85211
26.00000,1.29994,4112.79351,0.00000,0.00183,49.46817
26.20000,1.30987,4166.90223,0.00000,0.00186,50.11898
26.40000,1.31991,4219.53686,0.00000,0.00188,50.75207
26.60000,1.32990,4270.67019,0.00000,0.00191,51.36709
26.80000,1.33994,4322.41820,0.00000,0.00193,51.98951
27.00000,1.34999,4373.01099,0.00000,0.00196,52.59803
27.20000,1.35991,4424.75639,0.00000,0.00199,53.22042
27.40000,1.36996,4474.33963,0.00000,0.00201,53.81680
27.60000,1.37994,4525.19618,0.00000,0.00204,54.42850
27.80000,1.38999,4578.34788,0.00000,0.00206,55.06780
28.00000,1.40003,4627.10857,0.00000,0.00209,55.65429
28.20000,1.40996,4678.06421,0.00000,0.00212,56.26718
28.40000,1.42006,4728.91033,0.00000,0.00215,56.87875
28.60000,1.43005,4781.26146,0.00000,0.00217,57.50842
28.80000,1.44009,4829.99422,0.00000,0.00220,58.09457
29.00000,1.45007,4875.02255,0.00000,0.00222,58.63617
29.20000,1.46006,4920.09297,0.00000,0.00224,59.17827
29.40000,1.47004,4967.71857,0.00000,0.00227,59.75110
29.60000,1.47997,5017.67695,0.00000,0.00229,60.35200
29.80000,1.49001,5065.42586,0.00000,0.00232,60.92631
30.00000,1.50000,5114.91746,0.00000,0.00235,61.52159
30.20000,1.50998,5163.70051,0.00000,0.00237,62.10835
30.40000,1.51997,5212.76966,0.00000,0.00239,62.69855
30.60000,1.52995,5262.04109,0.00000,0.00242,63.29118
30.80000,1.54000,5311.24920,0.00000,0.00245,63.88305
31.00000,1.54986,5361.04217,0.00000,0.00247,64.48195
31.20000,1.55991,5411.47776,0.00000,0.00250,65.08858
31.40000,1.56989,5460.70114,0.00000,0.00252,65.68064
31.60000,1.57988,5509.96028,0.00000,0.00255,66.27312
31.80000,1.58992,5560.66744,0.00000,0.00258,66.88302
32.00000,1.59991,5613.69844,0.00000,0.00261,67.52087
32.20000,1.61001,5664.78819,0.00000,0.00263,68.13537
32.40000,1.62000,5715.39029,0.00000,0.00266,68.74400
32.60000,1.62998,5764.75859,0.00000,0.00268,69.33780
32.80000,1.64003,5816.82734,0.00000,0.00271,69.96408
33.00000,1.65007,5868.40250,0.00000,0.00274,70.58442
33.20000,1.66006,5919.56936,0.00000,0.00276,71.19985
33.40000,1.67004,5972.71249,0.00000,0.00280,71.83904
33.60000,1.68008,6023.23972,0.00000,0.00282,72.44678
33.80000,1.69007,6075.57446,0.00000,0.00285,73.07626
34.00000,1.69999,6125.41959,0.00000,0.00287,73.67579
34.20000,1.70998,6177.43507,0.00000,0.00290,74.30142
34.40000,1.71996,6230.96079,0.00000,0.00293,74.94522
34.60000,1.73007,6282.31615,0.00000,0.00296,75.56292
34.80000,1.73999,6333.65288,0.00000,0.00298,76.18039
35.00000,1.74998,6384.38761,0.00000,0.00301,76.79062
35.20000,1.75996,6438.41848,0.00000,0.00304,77.44050
35.40000,1.76995,6491.16188,0.00000,0.00306,78.07489
35.60000,1.78005,6544.02301,0.00000,0.00309,78.71070
35.80000,1.78992,6596.31640,0.00000,0.00312,79.33967
36.00000,1.79996,6648.95475,0.00000,0.00315,79.97280
36.20000,1.80995,6701.89634,0.00000,0.00317,80.60958
36.40000,1.81993,6753.28225,0.00000,0.00320,81.22764
36.60000,1.82998,6807.72066,0.00000,0.00324,81.88242
36.80000,1.83996,6862.94064,0.00000,0.00326,82.54660
37.00000,1.84995,6915.62891,0.00000,0.00329,83.18033
37.20000,1.85993,6969.30662,0.00000,0.00332,83.82595
37.40000,1.86998,7024.70094,0.00000,0.00335,84.49223
37.60000,1.88002,7077.98228,0.00000,0.00338,85.13309
37.80000,1.89007,7131.37239,0.00000,0.00341,85.77526
38.00000,1.90005,7183.00343,0.00000,0.00344,86.39627
38.20000,1.91004,7238.23905,0.00000,0.00346,87.06064
38.40000,1.92008,7291.16946,0.00000,0.00350,87.69728
38.60000,1.93000,7345.13626,0.00000,0.00353,88.34639
38.80000,1.94005,7399.13136,0.00000,0.00356,88.99583
39.00000,1.95003,7453.18681,0.00000,0.00359,89.64601
39.20000,1.95996,7507.58275,0.00000,0.00361,90.30027
39.40000,1.97000,7558.10887,0.00000,0.00365,90.90799
39.60000,1.97999,7613.19026,0.00000,0.00368,91.57051
39.80000,1.99003,7665.88002,0.00000,0.00372,92.20425
40.00000,2.00002,7718.88569,0.00000,0.00375,92.84180
40.20000,2.01000,7772.60959,0.00000,0.00377,93.48798
40.40000,2.01999,7825.29116,0.00000,0.00380,94.12163
40.60000,2.02991,7882.02435,0.00000,0.00383,94.80401
40.80000,2.03996,7935.27961,0.00000,0.00386,95.44456
41.00000,2.04994,7988.70325,0.00000,0.00389,96.08713
41.20000,2.05999,8042.50762,0.00000,0.00392,96.73428
41.40000,2.06991,8097.48322,0.00000,0.00395,97.39552
41.60000,2.07996,8152.51917,0.00000,0.00398,98.05749
41.80000,2.09000,8206.11939,0.00000,0.00401,98.70218
42.00000,2.09993,8261.57331,0.00000,0.00404,99.36918
42.20000,2.11003,8317.79242,0.00000,0.00407,100.04537
42.40000,2.12002,8372.48042,0.00000,0.00410,100.70315
42.60000,2.13006,8428.57435,0.00000,0.00413,101.37785
42.80000,2.14005,8483.32047,0.00000,0.00416,102.03633
43.00000,2.15003,8537.82967,0.00000,0.00419,102.69195
43.20000,2.16013,8591.58114,0.00000,0.00422,103.33847
43.40000,2.17006,8646.33396,0.00000,0.00425,103.99703
43.60000,2.18010,8702.58361,0.00000,0.00428,104.67359
43.80000,2.19003,8756.91399,0.00000,0.00431,105.32707
44.00000,2.20001,8810.75785,0.00000,0.00434,105.97470
44.20000,2.21006,8865.47342,0.00000,0.00437,106.63281
44.40000,2.21998,8922.00023,0.00000,0.00440,107.31271
44.60000,2.23003,8977.57038,0.00000,0.00443,107.98110
44.80000,2.24001,9032.49234,0.00000,0.00446,108.64170
45.00000,2.25000,9086.95161,0.00000,0.00449,109.29673
45.20000,2.25992,9142.65215,0.00000,0.00452,109.96668
45.40000,2.26991,9198.14259,0.00000,0.00456,110.63412
45.60000,2.27995,9253.59353,0.00000,0.00459,111.30107
45.80000,2.28988,9311.04720,0.00000,0.00462,111.99212
46.00000,2.29986,9367.15007,0.00000,0.00466,112.66692
46.20000,2.30991,9422.46020,0.00000,0.00469,113.33218
46.40000,2.31989,9479.09281,0.00000,0.00472,114.01335
46.60000,2.33000,9536.66866,0.00000,0.00475,114.70587
46.80000,2.33992,9594.36595,0.00000,0.00479,115.39984
47.00000,2.35003,9649.69695,0.00000,0.00482,116.06536
47.20000,2.36001,9705.54054,0.00000,0.00486,116.73704
47.40000,2.37000,9760.93784,0.00000,0.00489,117.40335
47.60000,2.38004,9817.09436,0.00000,0.00492,118.07879
47.80000,2.39003,9874.53684,0.00000,0.00495,118.76970
48.00000,2.40007,9931.56806,0.00000,0.00498,119.45567
48.20000,2.40999,9988.04122,0.00000,0.00501,120.13492
48.40000,2.42004,10043.13827,0.00000,0.00505,120.79762
48.60000,2.43002,10098.23456,0.00000,0.00508,121.46031
48.80000,2.44001,10155.97060,0.00000,0.00511,122.15475
49.00000,2.45005,10211.14364,0.00000,0.00514,122.81837
49.20000,2.46004,10267.53709,0.00000,0.00518,123.49666
49.40000,2.47002,10324.07507,0.00000,0.00520,124.17669
49.60000,2.47995,10381.55332,0.00000,0.00524,124.86803
49.80000,2.48993,10438.38710,0.00000,0.00527,125.55162
50.00000,2.49992,10494.92657,0.00000,0.00531,126.23167
50.20000,2.50990,10552.45399,0.00000,0.00534,126.92361
50.40000,2.51995,10608.90108,0.00000,0.00537,127.60254
50.60000,2.52987,10666.92844,0.00000,0.00540,128.30049
50.80000,2.53992,10723.26973,0.00000,0.00544,128.97816
51.00000,2.54990,10782.25523,0.00000,0.00547,129.68763
51.20000,2.55995,10840.19467,0.00000,0.00551,130.38452
51.40000,2.56993,10896.43613,0.00000,0.00554,131.06098
51.60000,2.57992,10956.08100,0.00000,0.00557,131.77838
51.80000,2.59002,11013.96829,0.00000,0.00560,132.47464
52.00000,2.60001,11069.33951,0.00000,0.00564,133.14064
52.20000,2.61011,11127.20147,0.00000,0.00567,133.83660
52.40000,2.62010,11183.93689,0.00000,0.00571,134.51900
52.60000,2.63008,11242.02982,0.00000,0.00574,135.21774
52.80000,2.64012,11297.99411,0.00000,0.00577,135.89087
53.00000,2.64999,11355.20115,0.00000,0.00581,136.57895
53.20000,2.66009,11414.41613,0.00000,0.00584,137.29118
53.40000,2.66996,11471.74835,0.00000,0.00588,137.98076
53.60000,2.68000,11527.94659,0.00000,0.00591,138.65671
53.80000,2.69005,11586.45228,0.00000,0.00595,139.36041
54.00000,2.70003,11644.38426,0.00000,0.00598,140.05721
54.20000,2.71002,11701.66954,0.00000,0.00601,140.74623
54.40000,2.71994,11759.17387,0.00000,0.00605,141.43788
54.60000,2.72993,11818.82322,0.00000,0.00608,142.15534
54.80000,2.73985,11875.35301,0.00000,0.00612,142.83527
55.00000,2.74984,11933.91755,0.00000,0.00615,143.53968
55.20000,2.75994,11993.72411,0.00000,0.00619,144.25902
55.40000,2.76993,12053.42859,0.00000,0.00622,144.97714
55.60000,2.77991,12111.04766,0.00000,0.00626,145.67018
55.80000,2.78990,12169.19944,0.00000,0.00630,146.36962
56.00000,2.79994,12228.56715,0.00000,0.00633,147.08369
56.20000,2.80993,12286.85230,0.00000,0.00637,147.78473
56.40000,2.81997,12346.39809,0.00000,0.00640,148.50094
56.60000,2.83002,12406.16441,0.00000,0.00644,149.21980
56.80000,2.84000,12464.58143,0.00000,0.00647,149.92244
57.00000,2.84999,12522.12375,0.00000,0.00650,150.61455
57.20000,2.86003,12579.93132,0.00000,0.00654,151.30985
57.40000,2.87007,12639.32735,0.00000,0.00657,152.02426
57.60000,2.88012,12697.82335,0.00000,0.00661,152.72784
57.80000,2.88999,12754.74131,0.00000,0.00665,153.41244
58.00000,2.90003,12812.50268,0.00000,0.00668,154.10719
58.20000,2.91001,12873.01630,0.00000,0.00672,154.83504
58.40000,2.92006,12932.58518,0.00000,0.00676,155.55153
58.60000,2.93004,12991.02008,0.00000,0.00679,156.25438
58.80000,2.94003,13050.97193,0.00000,0.00683,156.97547
59.00000,2.95001,13108.23411,0.00000,0.00687,157.66421
59.20000,2.95994,13166.04316,0.00000,0.00690,158.35953
59.40000,2.96992,13225.96967,0.00000,0.00694,159.08032
59.60000,2.97991,13285.91406,0.00000,0.00697,159.80132
59.80000,2.98989,13344.00922,0.00000,0.00701,160.50009
60.00000,2.99988,13402.36068,0.00000,0.00704,161.20193
60.20000,3.00986,13464.31375,0.00000,0.00708,161.94709
60.40000,3.01991,13523.03326,0.00000,0.00711,162.65336
60.60000,3.02989,13582.02100,0.00000,0.00715,163.36286
60.80000,3.04000,13641.51090,0.00000,0.00719,164.07840
61.00000,3.04998,13700.15591,0.00000,0.00722,164.78377
61.20000,3.06003,13759.10193,0.00000,0.00725,165.49277
61.40000,3.07007,13817.77376,0.00000,0.00729,166.19847
61.60000,3.08006,13878.17115,0.00000,0.00733,166.92492
61.80000,3.09010,13936.32144,0.00000,0.00736,167.62434
62.00000,3.10009,13994.87108,0.00000,0.00740,168.32857
62.20000,3.11007,14054.93468,0.00000,0.00744,169.05101
62.40000,3.12011,14114.46780,0.00000,0.00747,169.76707
62.60000,3.13010,14174.30639,0.00000,0.00751,170.48680
62.80000,3.14008,14232.58930,0.00000,0.00755,171.18782
63.00000,3.15001,14292.26846,0.00000,0.00758,171.90563
63.20000,3.16005,14351.57955,0.00000,0.00762,172.61902
63.40000,3.16998,14410.57920,0.00000,0.00765,173.32866
63.60000,3.17996,14471.28505,0.00000,0.00770,174.05882
63.80000,3.18995,14529.63799,0.00000,0.00773,174.76068
64.00000,3.19993,14590.86984,0.00000,0.00777,175.49717
64.20000,3.20998,14649.84119,0.00000,0.00780,176.20647
64.40000,3.21984,14709.49203,0.00000,0.00784,176.92394
64.60000,3.22989,14770.27386,0.00000,0.00788,177.65502
64.80000,3.23987,14828.14252,0.00000,0.00792,178.35106
65.00000,3.24986,14888.94373,0.00000,0.00795,179.08237
65.20000,3.25996,14948.99839,0.00000,0.00799,179.80470
65.40000,3.26989,15007.89225,0.00000,0.00803,180.51306
65.60000,3.28005,15069.62180,0.00000,0.00807,181.25554
65.80000,3.28998,15130.01770,0.00000,0.00810,181.98197
66.00000,3.30002,15189.39137,0.00000,0.00814,182.69611
66.20000,3.31007,15248.25096,0.00000,0.00818,183.40407
66.40000,3.32011,15308.89422,0.00000,0.00821,184.13348
66.60000,3.33010,15367.67632,0.00000,0.00825,184.84050
66.80000,3.34008,15426.91588,0.00000,0.00829,185.55303
67.00000,3.35007,15488.44874,0.00000,0.00833,186.29314
67.20000,3.36011,15547.94312,0.00000,0.00836,187.00873
67.40000,3.37009,15608.68621,0.00000,0.00840,187.73934
67.60000,3.38008,15668.21933,0.00000,0.00844,188.45540
67.80000,3.39000,15729.65831,0.00000,0.00847,189.19438
68.00000,3.40005,15788.64604,0.00000,0.00851,189.90387
68.20000,3.40997,15846.42380,0.00000,0.00855,190.59882
68.40000,3.41996,15907.28313,0.00000,0.00858,191.33083
68.60000,3.43000,15968.43451,0.00000,0.00862,192.06635
68.80000,3.43987,16029.11204,0.00000,0.00866,192.79617
69.00000,3.44985,16088.82099,0.00000,0.00870,193.51434
69.20000,3.45984,16149.03659,0.00000,0.00873,194.23861
69.40000,3.46988,16209.55169,0.00000,0.00877,194.96647
69.60000,3.47993,16270.20985,0.00000,0.00881,195.69606
69.80000,3.48991,16331.45213,0.00000,0.00885,196.43268
70.00000,3.50002,16391.95681,0.00000,0.00889,197.16042
70.20000,3.50988,16450.99819,0.00000,0.00893,197.87056
70.40000,3.51993,16509.97996,0.00000,0.00897,198.57999
70.60000,3.52997,16572.66915,0.00000,0.00901,199.33401
70.80000,3.54002,16632.81918,0.00000,0.00904,200.05748
71.00000,3.55006,16692.25395,0.00000,0.00908,200.77236
71.20000,3.56005,16752.44719,0.00000,0.00912,201.49635
71.40000,3.57009,16813.08448,0.00000,0.00916,202.22569
71.60000,3.58007,16873.22706,0.00000,0.00920,202.94908
71.80000,3.59012,16934.87465,0.00000,0.00923,203.69057
72.00000,3.60004,16992.64050,0.00000,0.00927,204.38537
72.20000,3.61003,17053.62201,0.00000,0.00931,205.11885
72.40000,3.62001,17114.00300,0.00000,0.00935,205.84510
72.60000,3.63000,17176.60129,0.00000,0.00938,206.59803
72.80000,3.64004,17237.36823,0.00000,0.00942,207.32892
73.00000,3.64997,17296.42898,0.00000,0.00945,208.03930
73.20000,3.65995,17357.41198,0.00000,0.00950,208.77280
73.40000,3.66994,17417.74976,0.00000,0.00953,209.49853
73.60000,3.67992,17478.16056,0.00000,0.00957,210.22514
73.80000,3.68991,17536.81898,0.00000,0.00961,210.93068
74.00000,3.69989,17599.23100,0.00000,0.00965,211.68136
74.20000,3.70994,17659.93088,0.00000,0.00969,212.41146
74.40000,3.71992,17720.51752,0.00000,0.00973,213.14018
74.60000,3.72991,17781.77917,0.00000,0.00977,213.87703
74.80000,3.73995,17841.74591,0.00000,0.00981,214.59830
75.00000,3.75000,17903.07611,0.00000,0.00985,215.33598
75.20000,3.76004,17963.04435,0.00000,0.00989,216.05727
75.40000,3.76991,18021.84582,0.00000,0.00993,216.76452
75.60000,3.78001,18083.01210,0.00000,0.00997,217.50022
75.80000,3.79000,18142.40962,0.00000,0.01002,218.21465
76.00000,3.79998,18204.54448,0.00000,0.01006,218.96200
76.20000,3.81009,18265.19221,0.00000,0.01009,219.69146
76.40000,3.82001,18325.25432,0.00000,0.01013,220.41388
76.60000,3.83012,18386.60836,0.00000,0.01018,221.15184
76.80000,3.84004,18446.23685,0.00000,0.01021,221.86905
77.00000,3.85002,18506.44052,0.00000,0.01025,222.59317
77.20000,3.86007,18567.20150,0.00000,0.01029,223.32399
77.40000,3.86999,18627.96098,0.00000,0.01033,224.05480
77.60000,3.88004,18687.92921,0.00000,0.01037,224.77609
77.80000,3.88996,18747.37293,0.00000,0.01041,225.49107
78.00000,3.89995,18810.03082,0.00000,0.01045,226.24471
78.20000,3.90993,18870.51910,0.00000,0.01049,226.97226
78.40000,3.91992,18930.07904,0.00000,0.01052,227.68864
78.60000,3.92990,18989.24261,0.00000,0.01056,228.40025
78.80000,3.93989,19049.84415,0.00000,0.01060,229.12916
79.00000,3.94993,19109.65443,0.00000,0.01064,229.84855
79.20000,3.95986,19167.78237,0.00000,0.01068,230.54771
79.40000,3.96990,19229.36291,0.00000,0.01071,231.28839
79.60000,3.98001,19290.42637,0.00000,0.01076,232.02285
79.80000,3.98993,19351.16053,0.00000,0.01079,232.75336
80.00000,3.99998,19412.72169,0.00000,0.01083,233.49381
80.20000,4.00996,19474.17706,0.00000,0.01087,234.23298
80.40000,4.02001,19533.84876,0.00000,0.01091,234.95071
80.60000,4.03011,19593.98091,0.00000,0.01096,235.67397
80.80000,4.04004,19655.80732,0.00000,0.01099,236.41761
81.00000,4.05008,19715.61313,0.00000,0.01104,237.13695
81.20000,4.06001,19775.23714,0.00000,0.01108,237.85410
81.40000,4.07005,19835.65986,0.00000,0.01111,238.58085
81.60000,4.08003,19896.73078,0.00000,0.01115,239.31541
81.80000,4.09002,19958.26960,0.00000,0.01119,240.05559
82.00000,4.10000,20017.47340,0.00000,0.01123,240.76768
82.20000,4.10993,20077.97360,0.00000,0.01127,241.49537
82.40000,4.11997,20136.42937,0.00000,0.01131,242.19847
82.60000,4.12996,20197.16948,0.00000,0.01135,242.92905
82.80000,4.14000,20258.57270,0.00000,0.01139,243.66760
83.00000,4.14987,20317.01356,0.00000,0.01143,244.37052
83.20000,4.15985,20376.74040,0.00000,0.01146,245.08890
83.40000,4.16996,20437.24209,0.00000,0.01150,245.81661
83.60000,4.17982,20498.63189,0.00000,0.01155,246.55500
83.80000,4.18993,20558.73275,0.00000,0.01158,247.27788
84.00000,4.19991,20618.77251,0.00000,0.01162,248.00003
84.20000,4.20996,20679.98946,0.00000,0.01166,248.73634
84.40000,4.21994,20738.67619,0.00000,0.01171,249.44222
84.60000,4.22993,20801.06735,0.00000,0.01174,250.19265
84.80000,4.24003,20862.55550,0.00000,0.01179,250.93223
85.00000,4.24996,20923.43122,0.00000,0.01183,251.66443
85.20000,4.26000,20983.76304,0.00000,0.01187,252.39010
85.40000,4.26999,21044.44653,0.00000,0.01191,253.11999
85.60000,4.28003,21106.07326,0.00000,0.01195,253.86123
85.80000,4.29008,21165.60042,0.00000,0.01199,254.57721
86.00000,4.30006,21226.09168,0.00000,0.01203,255.30479
86.20000,4.31010,21286.45778,0.00000,0.01207,256.03087
86.40000,4.32003,21346.26210,0.00000,0.01211,256.75019
86.60000,4.33001,21406.99327,0.00000,0.01216,257.48066
86.80000,4.33994,21465.62785,0.00000,0.01219,258.18591
87.00000,4.34998,21528.00113,0.00000,0.01223,258.93612
87.20000,4.36009,21586.63273,0.00000,0.01227,259.64134
87.40000,4.36995,21646.73805,0.00000,0.01231,260.36428
87.60000,4.38006,21707.45730,0.00000,0.01235,261.09460
87.80000,4.38986,21765.23358,0.00000,0.01238,261.78953
88.00000,4.39985,21826.28810,0.00000,0.01243,262.52388
88.20000,4.40995,21887.82096,0.00000,0.01247,263.26399
88.40000,4.41994,21949.57137,0.00000,0.01251,264.00672
88.60000,4.42998,22009.93150,0.00000,0.01255,264.73272
88.80000,4.43985,22068.59291,0.00000,0.01259,265.43829
89.00000,4.44989,22131.37299,0.00000,0.01263,266.19341
89.20000,4.45994,22191.58411,0.00000,0.01268,266.91762
89.40000,4.46998,22252.60735,0.00000,0.01272,267.65160
89.60000,4.48003,22313.10010,0.00000,0.01276,268.37920
89.80000,4.48995,22372.94912,0.00000,0.01280,269.09905
90.00000,4.50000,22432.56867,0.00000,0.01284,269.81615
90.20000,4.50998,22491.62495,0.00000,0.01288,270.52647
90.40000,4.52009,22554.23665,0.00000,0.01293,271.27956
90.60000,4.53007,22612.96362,0.00000,0.01296,271.98592
90.80000,4.54006,22670.38673,0.00000,0.01301,272.67660
91.00000,4.55010,22731.12535,0.00000,0.01305,273.40715
91.20000,4.55996,22789.97749,0.00000,0.01309,274.11502
91.40000,4.57007,22848.95331,0.00000,0.01313,274.82437
91.60000,4.57999,22906.92031,0.00000,0.01317,275.52159
91.80000,4.58992,22965.75755,0.00000,0.01321,276.22928
92.00000,4.60002,23026.27414,0.00000,0.01325,276.95717
92.20000,4.60995,23084.36930,0.00000,0.01329,277.65593
92.40000,4.61999,23143.62526,0.00000,0.01333,278.36865
92.60000,4.62992,23202.35968,0.00000,0.01337,279.07510
92.80000,4.63996,23261.79892,0.00000,0.01341,279.79003
93.00000,4.65001,23321.91020,0.00000,0.01345,280.51304
93.20000,4.65993,23380.63717,0.00000,0.01349,281.21940
93.40000,4.66998,23438.21526,0.00000,0.01353,281.91194
93.60000,4.67990,23497.88398,0.00000,0.01357,282.62963
93.80000,4.69001,23559.45706,0.00000,0.01361,283.37022
94.00000,4.69987,23617.92773,0.00000,0.01365,284.07350
94.20000,4.70992,23677.45489,0.00000,0.01369,284.78949
94.40000,4.72002,23735.65435,0.00000,0.01373,285.48950
94.60000,4.72995,23794.49159,0.00000,0.01377,286.19719
94.80000,4.73999,23853.39141,0.00000,0.01381,286.90563
95.00000,4.74998,23911.38822,0.00000,0.01385,287.60321
95.20000,4.76008,23971.63659,0.00000,0.01389,288.32787
95.40000,4.77001,24028.21034,0.00000,0.01393,289.00833
95.60000,4.77999,24086.71379,0.00000,0.01398,289.71200
95.80000,4.79009,24146.55387,0.00000,0.01402,290.43175
96.00000,4.80002,24205.20633,0.00000,0.01406,291.13722
96.20000,4.81000,24262.09599,0.00000,0.01410,291.82148
96.40000,4.81999,24317.67285,0.00000,0.01414,292.48995
96.60000,4.83003,24377.04504,0.00000,0.01418,293.20407
96.80000,4.84008,24435.80180,0.00000,0.01422,293.91079
97.00000,4.85000,24493.64066,0.00000,0.01426,294.60647
97.20000,4.86005,24552.45107,0.00000,0.01430,295.31383
97.40000,4.86997,24610.49259,0.00000,0.01434,296.01195
97.60000,4.87996,24669.24936,0.00000,0.01439,296.71867
97.80000,4.88994,24726.53985,0.00000,0.01443,297.40775
98.00000,4.89993,24787.23526,0.00000,0.01447,298.13779
98.20000,4.90997,24844.72692,0.00000,0.01451,298.82929
98.40000,4.91990,24901.88032,0.00000,0.01455,299.51672
98.60000,4.92994,24960.08426,0.00000,0.01459,300.21679
98.80000,4.93993,25018.62943,0.00000,0.01463,300.92097
99.00000,4.94997,25079.53346,0.00000,0.01467,301.65351
99.20000,4.95996,25136.03568,0.00000,0.01471,302.33312
99.40000,4.96994,25194.34094,0.00000,0.01475,303.03440
99.60000,4.98011,25254.79198,0.00000,0.01480,303.76150
99.80000,4.99003,25309.80706,0.00000,0.01483,304.42322
100.00000,5.00008,25367.71595,0.00000,0.01487,305.11974
100.20000,5.01006,25424.64435,0.00000,0.01491,305.80446
100.40000,5.02005,25481.86183,0.00000,0.01495,306.49267
100.60000,5.03009,25539.54720,0.00000,0.01500,307.18650
100.80000,5.04002,25597.67962,0.00000,0.01504,307.88571
101.00000,5.05006,25656.39615,0.00000,0.01508,308.59195
101.20000,5.05993,25711.02381,0.00000,0.01512,309.24900
101.40000,5.07003,25768.39924,0.00000,0.01516,309.93911
101.60000,5.08001,25826.38264,0.00000,0.01520,310.63652
101.80000,5.09006,25884.55677,0.00000,0.01524,311.33623
102.00000,5.10004,25940.86826,0.00000,0.01528,312.01354
102.20000,5.10985,25996.92047,0.00000,0.01532,312.68773
102.40000,5.11995,26057.50263,0.00000,0.01536,313.41641
102.60000,5.12988,26114.02869,0.00000,0.01540,314.09629
102.80000,5.13986,26172.16110,0.00000,0.01544,314.79550
103.00000,5.14991,26229.36368,0.00000,0.01548,315.48353
103.20000,5.15983,26286.34572,0.00000,0.01552,316.16890
103.40000,5.16994,26344.43045,0.00000,0.01558,316.86754
103.60000,5.17992,26400.22337,0.00000,0.01562,317.53861
103.80000,5.18997,26458.41539,0.00000,0.01566,318.23853
104.00000,5.20001,26513.98182,0.00000,0.01570,318.90688
104.20000,5.20994,26568.79425,0.00000,0.01574,319.56616
104.40000,5.22004,26624.48883,0.00000,0.01578,320.23605
104.60000,5.23003,26681.87916,0.00000,0.01583,320.92633
104.80000,5.24007,26737.85090,0.00000,0.01587,321.59955
105.00000,5.25000,26791.65900,0.00000,0.01591,322.24675
105.20000,5.25998,26847.51749,0.00000,0.01595,322.91861
105.40001,5.27008,26902.79782,0.00000,0.01599,323.58351
105.60001,5.28001,26958.75764,0.00000,0.01603,324.25659
105.80001,5.29011,27014.05883,0.00000,0.01607,324.92174
106.00001,5.29998,27070.00077,0.00000,0.01611,325.59461
106.20001,5.31002,27127.59674,0.00000,0.01615,326.28736
106.40001,5.32001,27181.54192,0.00000,0.01619,326.93621
106.60001,5.32993,27238.24382,0.00000,0.01623,327.61821
106.80001,5.34004,27294.43908,0.00000,0.01628,328.29412
107.00001,5.34990,27348.47665,0.00000,0.01631,328.94408
107.20001,5.35995,27402.42779,0.00000,0.01635,329.59300
107.40001,5.36987,27453.77421,0.00000,0.01639,330.21059
107.60001,5.37986,27508.38995,0.00000,0.01643,330.86750
107.80001,5.38990,27562.72554,0.00000,0.01647,331.52104
108.00001,5.39989,27616.28628,0.00000,0.01651,332.16526
108.20001,5.40993,27667.70422,0.00000,0.01654,332.78371
108.40001,5.41992,27714.01107,0.00000,0.01657,333.34068
108.46201,5.42303,26521.53373,0.00000,0.01628,318.99771
108.46601,5.42356,24315.52559,0.00000,0.01585,292.46412
108.47001,5.42428,21494.10248,0.00000,0.01586,258.52840
108.47401,5.42524,18381.39594,0.00000,0.01562,221.08915
108.47801,5.42614,15219.75994,0.00000,0.01402,183.06138