File: scratch/college-stuff/ME Lab/ME lab Fall 2013/group6/group6.is_tens_RawData/Specimen_RawData_3.csv
Time,Extension,Load,Strain 2,Tensile strain,Tensile stress
(sec),(mm),(N),(mm/mm),(mm/mm),(MPa)
0.00000,0.00000,-0.38787,0.00000,0.00000,-0.00476
0.30000,0.01363,7.91543,0.00000,0.00000,0.09708
0.60000,0.03001,9.94978,0.00000,0.00000,0.12203
0.90000,0.04496,13.70435,0.00000,0.00000,0.16808
1.20000,0.06009,16.72397,0.00000,0.00000,0.20512
1.50000,0.07498,23.32399,0.00000,0.00000,0.28606
1.80000,0.09004,28.96325,0.00000,0.00000,0.35523
2.10000,0.10511,35.01042,0.00000,-0.00001,0.42940
2.40000,0.11988,39.86744,0.00000,-0.00002,0.48897
2.70000,0.13506,50.91782,0.00000,-0.00002,0.62450
3.00000,0.14995,61.38844,0.00000,-0.00003,0.75292
3.30000,0.16508,75.88403,0.00000,-0.00004,0.93070
3.60000,0.17997,98.35385,0.00000,-0.00006,1.20629
3.90000,0.19503,144.01354,0.00000,-0.00007,1.76630
4.20000,0.21004,205.19535,0.00000,-0.00009,2.51668
4.50000,0.22505,275.25707,0.00000,-0.00010,3.37598
4.80000,0.24005,372.05520,0.00000,-0.00011,4.56319
5.10000,0.25494,501.45215,0.00000,-0.00011,6.15022
5.40000,0.27013,672.07599,0.00000,-0.00009,8.24289
5.70000,0.28490,867.68502,0.00000,-0.00007,10.64200
6.00000,0.30008,1087.80842,0.00000,-0.00004,13.34178
6.30000,0.31491,1312.41232,0.00000,-0.00001,16.09650
6.60000,0.32992,1531.34819,0.00000,0.00003,18.78171
6.90000,0.34505,1755.97668,0.00000,0.00006,21.53674
7.20000,0.35987,1978.57842,0.00000,0.00009,24.26691
7.50000,0.37506,2206.90258,0.00000,0.00013,27.06727
7.80000,0.38989,2431.40459,0.00000,0.00017,29.82074
8.10000,0.40495,2658.28036,0.00000,0.00020,32.60334
8.40000,0.41996,2882.11145,0.00000,0.00024,35.34858
8.70000,0.43497,3102.03396,0.00000,0.00027,38.04589
9.00000,0.44998,3323.30093,0.00000,0.00031,40.75969
9.30000,0.46498,3533.43636,0.00000,0.00035,43.33697
9.60000,0.48005,3745.40500,0.00000,0.00038,45.93673
9.90000,0.49488,3948.12599,0.00000,0.00042,48.42306
10.20000,0.51006,4154.06823,0.00000,0.00046,50.94891
10.50000,0.52489,4350.43797,0.00000,0.00048,53.35735
10.80000,0.54002,4547.15639,0.00000,0.00052,55.77006
11.10000,0.55497,4735.64453,0.00000,0.00055,58.08184
11.40000,0.56997,4914.37055,0.00000,0.00058,60.27388
11.70000,0.58510,5071.06185,0.00000,0.00061,62.19567
12.00000,0.59981,5218.62209,0.00000,0.00064,64.00547
12.30000,0.61499,5376.37398,0.00000,0.00066,65.94027
12.60000,0.62994,5526.61493,0.00000,0.00069,67.78295
12.90000,0.64501,5680.46086,0.00000,0.00072,69.66984
13.20000,0.65996,5832.22024,0.00000,0.00074,71.53114
13.50000,0.67502,5982.53384,0.00000,0.00077,73.37471
13.80000,0.69003,6133.85104,0.00000,0.00079,75.23059
14.10000,0.70504,6280.90873,0.00000,0.00082,77.03423
14.40000,0.72004,6426.26509,0.00000,0.00085,78.81700
14.70000,0.73493,6563.90414,0.00000,0.00087,80.50512
15.00000,0.75012,6697.77170,0.00000,0.00090,82.14698
15.30000,0.76489,6830.31604,0.00000,0.00091,83.77261
15.60000,0.77995,6964.68279,0.00000,0.00094,85.42059
15.90000,0.79502,7101.68257,0.00000,0.00097,87.10087
16.20000,0.80991,7235.54194,0.00000,0.00099,88.74263
16.50000,0.82504,7372.70638,0.00000,0.00101,90.42493
16.80000,0.83986,7508.49694,0.00000,0.00104,92.09038
17.10000,0.85505,7649.04693,0.00000,0.00106,93.81420
17.40000,0.87000,7784.76223,0.00000,0.00109,95.47872
17.70000,0.88500,7925.46198,0.00000,0.00111,97.20438
18.00000,0.89995,8064.88171,0.00000,0.00114,98.91434
18.30000,0.91502,8202.80164,0.00000,0.00116,100.60590
18.60000,0.92997,8345.15914,0.00000,0.00119,102.35189
18.90000,0.94491,8482.92112,0.00000,0.00121,104.04152
19.20000,0.96004,8626.80078,0.00000,0.00124,105.80618
19.50000,0.97487,8767.79631,0.00000,0.00126,107.53546
19.80000,0.99005,8912.36439,0.00000,0.00129,109.30856
20.10000,1.00494,9054.42536,0.00000,0.00131,111.05092
20.40000,1.02001,9197.28726,0.00000,0.00134,112.80309
20.70000,1.03496,9344.16279,0.00000,0.00138,114.60449
21.00000,1.04990,9486.21631,0.00000,0.00140,116.34675
21.30000,1.06503,9635.71966,0.00000,0.00143,118.18039
21.60000,1.07992,9777.84917,0.00000,0.00146,119.92358
21.90000,1.09504,9927.61925,0.00000,0.00148,121.76048
22.20000,1.10987,10068.43224,0.00000,0.00151,123.48753
22.50000,1.12500,10218.33420,0.00000,0.00154,125.32605
22.80000,1.13995,10364.31417,0.00000,0.00157,127.11647
23.10000,1.15501,10511.31263,0.00000,0.00159,128.91938
23.40000,1.17002,10660.42408,0.00000,0.00162,130.74820
23.70000,1.18491,10804.41773,0.00000,0.00165,132.51426
24.00000,1.20009,10957.04511,0.00000,0.00168,134.38621
24.30000,1.21486,11102.76878,0.00000,0.00170,136.17348
24.60000,1.23005,11256.03840,0.00000,0.00174,138.05331
24.90000,1.24488,11406.16164,0.00000,0.00176,139.89454
25.20000,1.25994,11554.58689,0.00000,0.00179,141.71495
25.50000,1.27501,11706.77468,0.00000,0.00182,143.58151
25.80000,1.28996,11855.22228,0.00000,0.00184,145.40219
26.10000,1.30503,12009.18779,0.00000,0.00188,147.29055
26.40000,1.31991,12157.86338,0.00000,0.00190,149.11403
26.70000,1.33504,12313.56785,0.00000,0.00193,151.02372
27.00000,1.34993,12462.44162,0.00000,0.00196,152.84963
27.30000,1.36505,12618.50595,0.00000,0.00199,154.76373
27.60000,1.37988,12767.46392,0.00000,0.00202,156.59067
27.90000,1.39507,12921.99939,0.00000,0.00205,158.48602
28.20000,1.40996,13076.51699,0.00000,0.00208,160.38115
28.50000,1.42484,13227.16624,0.00000,0.00211,162.22884
28.80000,1.44009,13383.23653,0.00000,0.00214,164.14301
29.10000,1.45492,13535.49212,0.00000,0.00217,166.01040
29.40000,1.47004,13690.18257,0.00000,0.00219,167.90765
29.70000,1.48493,13845.14421,0.00000,0.00222,169.80823
30.00000,1.49994,13998.68280,0.00000,0.00226,171.69135
30.30000,1.51501,14157.32801,0.00000,0.00229,173.63711
30.60000,1.52995,14308.86686,0.00000,0.00231,175.49571
30.90000,1.54502,14466.23951,0.00000,0.00235,177.42585
31.20000,1.55991,14617.83201,0.00000,0.00238,179.28511
31.50000,1.57497,14775.88415,0.00000,0.00241,181.22359
31.80000,1.58992,14930.34065,0.00000,0.00244,183.11797
32.10000,1.60505,15088.69678,0.00000,0.00247,185.06018
32.40000,1.61994,15244.72386,0.00000,0.00250,186.97383
32.70000,1.63506,15398.62603,0.00000,0.00254,188.86141
33.00000,1.65001,15559.66586,0.00000,0.00258,190.83653
33.30000,1.66490,15712.46684,0.00000,0.00261,192.71061
33.60000,1.68008,15873.27123,0.00000,0.00264,194.68285
33.90000,1.69485,16028.24032,0.00000,0.00267,196.58352
34.20000,1.70998,16184.48496,0.00000,0.00271,198.49983
34.50000,1.72493,16345.51883,0.00000,0.00274,200.47488
34.80000,1.73993,16500.88429,0.00000,0.00278,202.38041
35.10000,1.75500,16659.81859,0.00000,0.00281,204.32971
35.40000,1.76995,16816.55794,0.00000,0.00285,206.25209
35.70000,1.78508,16975.25382,0.00000,0.00288,208.19847
36.00000,1.79996,17128.47799,0.00000,0.00291,210.07773
36.30000,1.81509,17289.88141,0.00000,0.00295,212.05732
36.60000,1.82998,17446.31827,0.00000,0.00298,213.97599
36.90000,1.84504,17605.82179,0.00000,0.00301,215.93227
37.20000,1.85993,17765.37001,0.00000,0.00305,217.88910
37.50000,1.87500,17918.50924,0.00000,0.00308,219.76733
37.80000,1.89001,18080.34629,0.00000,0.00312,221.75223
38.10000,1.90477,18233.16067,0.00000,0.00315,223.62647
38.40000,1.92008,18395.92457,0.00000,0.00319,225.62274
38.70000,1.93485,18551.23788,0.00000,0.00323,227.52763
39.00000,1.94997,18708.87578,0.00000,0.00326,229.46103
39.30000,1.96498,18867.09780,0.00000,0.00330,231.40160
39.60000,1.97999,19022.34852,0.00000,0.00333,233.30572
39.90000,1.99506,19177.87045,0.00000,0.00337,235.21317
40.20000,2.01000,19333.46838,0.00000,0.00340,237.12155
40.50000,2.02501,19489.39264,0.00000,0.00344,239.03393
40.80000,2.03996,19642.61979,0.00000,0.00348,240.91324
41.10000,2.05508,19796.22245,0.00000,0.00352,242.79715
41.40000,2.06985,19945.99998,0.00000,0.00357,244.63414
41.70000,2.08504,20100.35664,0.00000,0.00360,246.52730
42.00000,2.09993,20253.06821,0.00000,0.00364,248.40028
42.30000,2.11499,20400.48391,0.00000,0.00369,250.20830
42.60000,2.13006,20554.11935,0.00000,0.00373,252.09262
42.90000,2.14483,20697.17646,0.00000,0.00377,253.84719
43.20000,2.16013,20846.54421,0.00000,0.00382,255.67915
43.50000,2.17490,20987.89811,0.00000,0.00386,257.41284
43.80000,2.18997,21131.46931,0.00000,0.00391,259.17371
44.10000,2.20498,21272.07518,0.00000,0.00395,260.89822
44.40000,2.21998,21407.91863,0.00000,0.00400,262.56431
44.70000,2.23499,21543.32548,0.00000,0.00405,264.22505
45.00000,2.25000,21672.47832,0.00000,0.00410,265.80909
45.30000,2.26506,21805.49353,0.00000,0.00415,267.44050
45.60000,2.27995,21926.95439,0.00000,0.00421,268.93019
45.90000,2.29508,22051.70542,0.00000,0.00426,270.46024
46.20000,2.30985,22165.86322,0.00000,0.00432,271.86037
46.50000,2.32503,22278.38486,0.00000,0.00438,273.24043
46.80000,2.33992,22385.25450,0.00000,0.00444,274.55116
47.10000,2.35493,22481.61733,0.00000,0.00451,275.73304
47.40000,2.37000,22579.56415,0.00000,0.00458,276.93434
47.70000,2.38482,22662.09573,0.00000,0.00466,277.94657
48.00000,2.40007,22744.66306,0.00000,0.00475,278.95924
48.30000,2.41490,22813.08919,0.00000,0.00484,279.79848
48.60000,2.42996,22876.43850,0.00000,0.00493,280.57545
48.90000,2.44503,22935.48584,0.00000,0.00504,281.29965
49.20000,2.46004,22987.53113,0.00000,0.00514,281.93798
49.50000,2.47499,23032.40597,0.00000,0.00527,282.48836
49.80000,2.48999,23071.22052,0.00000,0.00538,282.96441
50.10000,2.50500,23110.19301,0.00000,0.00550,283.44240
50.40000,2.51995,23138.29809,0.00000,0.00563,283.78711
50.70000,2.53507,23171.57239,0.00000,0.00576,284.19521
51.00000,2.54990,23195.01489,0.00000,0.00590,284.48273
51.30000,2.56509,23220.67320,0.00000,0.00605,284.79742
51.60000,2.57998,23243.74318,0.00000,0.00619,285.08037
51.90000,2.59498,23259.09138,0.00000,0.00633,285.26862
52.20000,2.61011,23283.47266,0.00000,0.00648,285.56765
52.50000,2.62494,23296.91648,0.00000,0.00663,285.73253
52.80000,2.64012,23314.87983,0.00000,0.00679,285.95285
53.10000,2.65495,23329.44423,0.00000,0.00695,286.13148
53.40000,2.66996,23344.57189,0.00000,0.00711,286.31702
53.70000,2.68497,23358.42848,0.00000,0.00726,286.48697
54.00000,2.70003,23371.29861,0.00000,0.00742,286.64482
54.30000,2.71498,23382.61306,0.00000,0.00758,286.78359
54.60000,2.72999,23393.53561,0.00000,0.00774,286.91755
54.90000,2.74505,23408.52469,0.00000,0.00791,287.10139
55.20000,2.75994,23414.46728,0.00000,0.00808,287.17427
55.50000,2.77507,23427.28376,0.00000,0.00825,287.33147
55.80000,2.78984,23435.16350,0.00000,0.00841,287.42811
56.10000,2.80502,23447.10827,0.00000,0.00858,287.57461
56.40000,2.81997,23457.93694,0.00000,0.00874,287.70742
56.70000,2.83492,23463.41610,0.00000,0.00892,287.77462
57.00000,2.85005,23474.42508,0.00000,0.00909,287.90965
57.30000,2.86487,23480.90559,0.00000,0.00926,287.98913
57.60000,2.88012,23491.84304,0.00000,0.00943,288.12327
57.90000,2.89495,23499.37111,0.00000,0.00960,288.21560
58.20000,2.90995,23510.07164,0.00000,0.00977,288.34684
58.50000,2.92502,23518.98402,0.00000,0.00995,288.45615
58.80000,2.94003,23525.61355,0.00000,0.01012,288.53746
59.10000,2.95498,23534.19513,0.00000,0.01029,288.64272
59.40000,2.96998,23540.22861,0.00000,0.01046,288.71671
59.70000,2.98505,23552.67555,0.00000,0.01064,288.86937
60.00000,2.99988,23555.89718,0.00000,0.01082,288.90889
60.30000,3.01500,23567.82407,0.00000,0.01099,289.05517
60.60000,3.02989,23572.76380,0.00000,0.01117,289.11575
60.90000,3.04508,23581.26789,0.00000,0.01134,289.22005
61.20000,3.06009,23591.29786,0.00000,0.01151,289.34307
61.50000,3.07491,23595.27200,0.00000,0.01168,289.39181
61.80000,3.09016,23606.87107,0.00000,0.01185,289.53407
62.10000,3.10493,23612.33383,0.00000,0.01202,289.60107
62.40000,3.12011,23619.66968,0.00000,0.01221,289.69105
62.70000,3.13500,23624.46785,0.00000,0.01238,289.74989
63.00000,3.15001,23635.06258,0.00000,0.01255,289.87984
63.30000,3.16496,23641.20334,0.00000,0.01272,289.95515
63.60000,3.18002,23648.33802,0.00000,0.01289,290.04266
63.90000,3.19497,23656.80486,0.00000,0.01307,290.14650
64.20000,3.21004,23662.57906,0.00000,0.01324,290.21732
64.50000,3.22510,23672.26630,0.00000,0.01341,290.33613
64.80000,3.23987,23674.23773,0.00000,0.01358,290.36031
65.10000,3.25506,23685.84573,0.00000,0.01375,290.50268
65.40000,3.26995,23690.33396,0.00000,0.01393,290.55773
65.70000,3.28507,23697.61020,0.00000,0.01411,290.64697
66.00000,3.30002,23704.77915,0.00000,0.01427,290.73490
66.30000,3.31497,23709.01853,0.00000,0.01444,290.78689
66.60000,3.33016,23720.33000,0.00000,0.01461,290.92563
66.90000,3.34492,23724.89274,0.00000,0.01478,290.98159
67.20000,3.36005,23734.50398,0.00000,0.01495,291.09947
67.50000,3.37500,23739.84903,0.00000,0.01512,291.16502
67.80000,3.39006,23747.51121,0.00000,0.01529,291.25900
68.10000,3.40501,23753.87251,0.00000,0.01546,291.33702
68.40000,3.42002,23759.41128,0.00000,0.01562,291.40495
68.70000,3.43497,23768.21041,0.00000,0.01579,291.51287
69.00000,3.44991,23772.43936,0.00000,0.01596,291.56474
69.30000,3.46504,23782.98491,0.00000,0.01613,291.69408
69.60000,3.47993,23786.33469,0.00000,0.01630,291.73516
69.90000,3.49505,23794.69424,0.00000,0.01647,291.83769
70.20000,3.50988,23801.46384,0.00000,0.01663,291.92072
70.50000,3.52501,23807.19483,0.00000,0.01680,291.99101
70.80000,3.54008,23817.80744,0.00000,0.01696,292.12117
71.10000,3.55496,23820.05453,0.00000,0.01713,292.14873
71.40000,3.57015,23830.03831,0.00000,0.01730,292.27118
71.70000,3.58498,23834.06907,0.00000,0.01747,292.32062
72.00000,3.59999,23841.70741,0.00000,0.01763,292.41430
72.30000,3.61493,23848.01060,0.00000,0.01779,292.49161
72.60000,3.63000,23856.99749,0.00000,0.01796,292.60183
72.90000,3.64501,23862.36042,0.00000,0.01813,292.66760
73.20000,3.66001,23866.64450,0.00000,0.01830,292.72015
73.50000,3.67502,23875.78785,0.00000,0.01846,292.83229
73.80000,3.68991,23877.53427,0.00000,0.01862,292.85371
74.10000,3.70509,23891.45792,0.00000,0.01879,293.02448
74.40000,3.71992,23893.37867,0.00000,0.01895,293.04804
74.70000,3.73511,23901.79485,0.00000,0.01911,293.15126
75.00000,3.75000,23909.62988,0.00000,0.01928,293.24736
75.30000,3.76500,23912.02301,0.00000,0.01944,293.27671
75.60000,3.78001,23922.57601,0.00000,0.01960,293.40614
75.90000,3.79490,23925.69929,0.00000,0.01976,293.44444
76.20000,3.81009,23937.34306,0.00000,0.01993,293.58725
76.50000,3.82491,23940.27859,0.00000,0.02010,293.62326
76.80000,3.84004,23946.69354,0.00000,0.02026,293.70193
77.10000,3.85499,23953.14723,0.00000,0.02043,293.78109
77.40000,3.86999,23960.08968,0.00000,0.02059,293.86624
77.70000,3.88500,23967.88299,0.00000,0.02076,293.96182
78.00000,3.90001,23973.34874,0.00000,0.02091,294.02886
78.30000,3.91502,23980.10790,0.00000,0.02107,294.11176
78.60000,3.92996,23981.79471,0.00000,0.02123,294.13244
78.90000,3.94503,23991.34338,0.00000,0.02139,294.24956
79.20000,3.95986,23994.59630,0.00000,0.02155,294.28945
79.50000,3.97510,24005.97334,0.00000,0.02171,294.42899
79.80000,3.98993,24011.89059,0.00000,0.02187,294.50156
80.10000,4.00506,24015.76787,0.00000,0.02203,294.54912
80.40000,4.02007,24024.16617,0.00000,0.02220,294.65212
80.70000,4.03495,24027.42356,0.00000,0.02235,294.69207
81.00000,4.05008,24036.68761,0.00000,0.02251,294.80570
81.30000,4.06485,24040.07316,0.00000,0.02267,294.84722
81.60000,4.08003,24049.21800,0.00000,0.02282,294.95938
81.90000,4.09492,24053.67047,0.00000,0.02298,295.01399
82.20000,4.10993,24059.89617,0.00000,0.02314,295.09034
82.50000,4.12494,24065.19204,0.00000,0.02330,295.15530
82.80000,4.14000,24070.81425,0.00000,0.02347,295.22425
83.10000,4.15501,24080.21092,0.00000,0.02362,295.33950
83.40000,4.16996,24081.24506,0.00000,0.02378,295.35219
83.70000,4.18503,24089.33789,0.00000,0.02393,295.45144
84.00000,4.19991,24094.26123,0.00000,0.02408,295.51183
84.30000,4.21510,24103.62959,0.00000,0.02424,295.62673
84.60000,4.22993,24109.76738,0.00000,0.02440,295.70201
84.90000,4.24499,24114.29137,0.00000,0.02456,295.75749
85.20000,4.26000,24122.21283,0.00000,0.02472,295.85465
85.50000,4.27489,24125.83232,0.00000,0.02488,295.89904
85.80000,4.29008,24134.24104,0.00000,0.02504,296.00217
86.10000,4.30496,24137.63255,0.00000,0.02519,296.04377
86.40000,4.32003,24145.28430,0.00000,0.02534,296.13761
86.70000,4.33492,24149.13476,0.00000,0.02550,296.18484
87.00000,4.34998,24158.67448,0.00000,0.02565,296.30184
87.30000,4.36499,24162.80210,0.00000,0.02581,296.35247
87.60000,4.38006,24166.84330,0.00000,0.02597,296.40203
87.90000,4.39501,24175.44276,0.00000,0.02612,296.50750
88.20000,4.40995,24178.58988,0.00000,0.02628,296.54610
88.50000,4.42508,24186.87791,0.00000,0.02644,296.64775
88.80000,4.43991,24190.57935,0.00000,0.02659,296.69315
89.10000,4.45509,24199.68843,0.00000,0.02675,296.80487
89.40000,4.46998,24203.21852,0.00000,0.02690,296.84817
89.70000,4.48505,24207.16435,0.00000,0.02705,296.89656
90.00000,4.50006,24215.90239,0.00000,0.02720,297.00373
90.30000,4.51494,24220.57539,0.00000,0.02736,297.06105
90.60000,4.53007,24227.66834,0.00000,0.02752,297.14804
90.90000,4.54490,24228.75315,0.00000,0.02767,297.16135
91.20000,4.55996,24236.84150,0.00000,0.02782,297.26055
91.50000,4.57497,24241.14048,0.00000,0.02798,297.31327
91.80000,4.58998,24245.47970,0.00000,0.02812,297.36649
92.10000,4.60499,24252.44153,0.00000,0.02828,297.45188
92.40000,4.61999,24257.20543,0.00000,0.02843,297.51031
92.70000,4.63506,24265.56498,0.00000,0.02858,297.61284
93.00000,4.65001,24267.77929,0.00000,0.02873,297.63999
93.30000,4.66514,24276.39812,0.00000,0.02889,297.74570
93.60000,4.67990,24279.70320,0.00000,0.02903,297.78624
93.90000,4.69515,24286.73357,0.00000,0.02919,297.87247
94.20000,4.70992,24292.32001,0.00000,0.02934,297.94098
94.50000,4.72492,24294.05451,0.00000,0.02949,297.96226
94.80000,4.73999,24302.87600,0.00000,0.02965,298.07045
95.10000,4.75488,24305.15289,0.00000,0.02980,298.09837
95.40000,4.77007,24311.93143,0.00000,0.02995,298.18151
95.70000,4.78489,24316.35857,0.00000,0.03009,298.23581
96.00000,4.80002,24323.98647,0.00000,0.03025,298.32937
96.30000,4.81503,24327.73560,0.00000,0.03040,298.37535
96.60000,4.83003,24332.55762,0.00000,0.03054,298.43449
96.90000,4.84504,24339.46133,0.00000,0.03070,298.51916
97.20000,4.86005,24343.14191,0.00000,0.03085,298.56430
97.50000,4.87512,24351.62067,0.00000,0.03100,298.66829
97.80000,4.88994,24352.13476,0.00000,0.03114,298.67460
98.10000,4.90513,24359.97427,0.00000,0.03129,298.77075
98.40000,4.91990,24363.44028,0.00000,0.03144,298.81326
98.70000,4.93508,24369.21149,0.00000,0.03159,298.88404
99.00000,4.94997,24376.93626,0.00000,0.03175,298.97879
99.30000,4.96498,24379.77493,0.00000,0.03189,299.01360
99.60000,4.98011,24389.08666,0.00000,0.03204,299.12781
99.90000,4.99487,24387.94822,0.00000,0.03218,299.11384
100.20000,5.01006,24396.54768,0.00000,0.03233,299.21932
100.50000,5.02495,24399.46085,0.00000,0.03248,299.25505
100.80000,5.04002,24405.59417,0.00000,0.03263,299.33027
101.10000,5.05496,24410.63076,0.00000,0.03279,299.39204
101.40000,5.07003,24416.35430,0.00000,0.03294,299.46224
101.70000,5.08504,24421.94372,0.00000,0.03308,299.53079
102.00000,5.10004,24424.29215,0.00000,0.03323,299.55960
102.30000,5.11505,24433.05403,0.00000,0.03337,299.66706
102.60000,5.12994,24433.05701,0.00000,0.03352,299.66710
102.90000,5.14506,24442.85750,0.00000,0.03367,299.78730
103.20000,5.15989,24445.65147,0.00000,0.03382,299.82156
103.50000,5.17508,24451.62535,0.00000,0.03396,299.89483
103.80000,5.18997,24455.85132,0.00000,0.03411,299.94666
104.10000,5.20491,24458.19527,0.00000,0.03425,299.97541
104.40000,5.22004,24464.71751,0.00000,0.03440,300.05541
104.70000,5.23487,24468.18054,0.00000,0.03454,300.09788
105.00000,5.25006,24473.19180,0.00000,0.03469,300.15934
105.30001,5.26494,24477.38498,0.00000,0.03483,300.21077
105.60001,5.28001,24483.67625,0.00000,0.03498,300.28793
105.90001,5.29502,24487.69659,0.00000,0.03512,300.33724
106.20001,5.31008,24493.71517,0.00000,0.03526,300.41106
106.50001,5.32497,24498.83372,0.00000,0.03541,300.47384
106.80001,5.34004,24500.57864,0.00000,0.03555,300.49524
107.10001,5.35505,24509.70858,0.00000,0.03570,300.60721
107.40001,5.36987,24508.07244,0.00000,0.03585,300.58715
107.70001,5.38506,24515.56027,0.00000,0.03599,300.67898
108.00001,5.39989,24518.93389,0.00000,0.03613,300.72036
108.30001,5.41507,24524.06585,0.00000,0.03627,300.78330
108.60001,5.43002,24529.44219,0.00000,0.03642,300.84924
108.90001,5.44491,24530.39736,0.00000,0.03656,300.86096
109.20001,5.46016,24538.77032,0.00000,0.03670,300.96365
109.50001,5.47498,24539.24865,0.00000,0.03685,300.96952
109.80001,5.48999,24545.31193,0.00000,0.03699,301.04388
110.10001,5.50494,24550.82834,0.00000,0.03714,301.11154
110.40001,5.52001,24556.35369,0.00000,0.03728,301.17931
110.70001,5.53489,24556.70983,0.00000,0.03742,301.18368
111.00001,5.55008,24562.11150,0.00000,0.03756,301.24993
111.30001,5.56503,24568.64715,0.00000,0.03770,301.33008
111.60001,5.57997,24568.69036,0.00000,0.03784,301.33061
111.90001,5.59504,24578.91703,0.00000,0.03799,301.45604
112.20001,5.60987,24576.97690,0.00000,0.03812,301.43225
112.50001,5.62511,24584.94008,0.00000,0.03826,301.52991
112.80001,5.63988,24585.73878,0.00000,0.03840,301.53971
113.10001,5.65501,24590.42519,0.00000,0.03854,301.59719
113.40001,5.67002,24597.23502,0.00000,0.03868,301.68071
113.70001,5.68484,24597.67014,0.00000,0.03883,301.68605
114.00001,5.70009,24604.52318,0.00000,0.03897,301.77010
114.30001,5.71492,24606.75389,0.00000,0.03910,301.79746
114.60001,5.73005,24610.89641,0.00000,0.03924,301.84826
114.90001,5.74499,24615.93598,0.00000,0.03938,301.91007
115.20001,5.76006,24622.10357,0.00000,0.03951,301.98572
115.50001,5.77495,24623.48342,0.00000,0.03965,302.00264
115.80001,5.79013,24628.65412,0.00000,0.03979,302.06606
116.10001,5.80496,24633.51041,0.00000,0.03993,302.12562
116.40001,5.81997,24632.82049,0.00000,0.04007,302.11716
116.70001,5.83510,24641.93106,0.00000,0.04021,302.22890
117.00001,5.84986,24641.51531,0.00000,0.04035,302.22380
117.30001,5.86505,24648.06736,0.00000,0.04048,302.30416
117.60001,5.87988,24651.65108,0.00000,0.04062,302.34811
117.90001,5.89500,24653.26637,0.00000,0.04075,302.36792
118.20001,5.91007,24658.55032,0.00000,0.04088,302.43273
118.50001,5.92490,24659.52784,0.00000,0.04102,302.44472
118.80001,5.94015,24668.26141,0.00000,0.04115,302.55184
119.10001,5.95497,24670.13597,0.00000,0.04129,302.57483
119.40001,5.97004,24674.49903,0.00000,0.04143,302.62834
119.70001,5.98499,24677.04564,0.00000,0.04156,302.65957
120.00001,6.00006,24683.67517,0.00000,0.04170,302.74088
120.30001,6.01494,24683.02697,0.00000,0.04183,302.73293
120.60001,6.03001,24688.58212,0.00000,0.04197,302.80107
120.90001,6.04496,24694.35632,0.00000,0.04211,302.87189
121.20001,6.05996,24693.82286,0.00000,0.04224,302.86534
121.50001,6.07509,24701.94846,0.00000,0.04237,302.96500
121.80001,6.08986,24700.73253,0.00000,0.04251,302.95009
122.10001,6.10510,24708.90135,0.00000,0.04264,303.05028
122.40001,6.11993,24712.23474,0.00000,0.04278,303.09116
122.70001,6.13500,24713.34040,0.00000,0.04291,303.10472
123.00001,6.15007,24720.27987,0.00000,0.04306,303.18983
123.30001,6.16495,24721.93688,0.00000,0.04319,303.21016
123.60001,6.18014,24726.41468,0.00000,0.04332,303.26508
123.90001,6.19497,24727.66489,0.00000,0.04346,303.28041
124.20001,6.21004,24733.66261,0.00000,0.04359,303.35397
124.50001,6.22504,24736.42081,0.00000,0.04372,303.38780
124.80001,6.24011,24740.93437,0.00000,0.04386,303.44316
125.10001,6.25494,24741.98043,0.00000,0.04399,303.45599
125.40001,6.27012,24744.36760,0.00000,0.04413,303.48527
125.70001,6.28495,24748.42221,0.00000,0.04428,303.53499
126.00001,6.29990,24751.08653,0.00000,0.04441,303.56767
126.30001,6.31503,24757.43443,0.00000,0.04454,303.64553
126.60001,6.32991,24757.21389,0.00000,0.04468,303.64282
126.90001,6.34510,24762.76755,0.00000,0.04481,303.71094
127.20001,6.35993,24765.86252,0.00000,0.04494,303.74890
127.50001,6.37505,24768.71312,0.00000,0.04507,303.78386
127.80001,6.39012,24775.00737,0.00000,0.04521,303.86106
128.10001,6.40501,24776.40957,0.00000,0.04534,303.87825
128.40001,6.42014,24780.83819,0.00000,0.04547,303.93257
128.70001,6.43496,24780.74878,0.00000,0.04561,303.93147
129.00001,6.45003,24786.21751,0.00000,0.04573,303.99855
129.30001,6.46492,24786.78375,0.00000,0.04587,304.00549
129.60001,6.47998,24794.04509,0.00000,0.04600,304.09455
129.90001,6.49493,24795.94648,0.00000,0.04614,304.11787
130.20001,6.51006,24799.36481,0.00000,0.04627,304.15980
130.50001,6.52495,24804.20917,0.00000,0.04640,304.21921
130.80001,6.53989,24802.23775,0.00000,0.04653,304.19503
131.10001,6.55508,24810.56303,0.00000,0.04666,304.29714
131.40001,6.56991,24812.95317,0.00000,0.04679,304.32645
131.70001,6.58509,24817.76029,0.00000,0.04693,304.38541
132.00001,6.59998,24821.97136,0.00000,0.04706,304.43706
132.30001,6.61499,24822.10547,0.00000,0.04720,304.43871
132.60001,6.63006,24826.68161,0.00000,0.04733,304.49483
132.90001,6.64488,24828.52787,0.00000,0.04746,304.51748
133.20001,6.66007,24834.01000,0.00000,0.04759,304.58471
133.50001,6.67496,24833.25601,0.00000,0.04773,304.57547
133.80001,6.69003,24838.40883,0.00000,0.04785,304.63866
134.10001,6.70491,24837.90070,0.00000,0.04799,304.63243
134.40001,6.72010,24846.41522,0.00000,0.04812,304.73686
134.70001,6.73493,24847.37337,0.00000,0.04825,304.74861
135.00001,6.74999,24847.20200,0.00000,0.04839,304.74651
135.30001,6.76506,24854.21896,0.00000,0.04852,304.83257
135.60001,6.77983,24850.03024,0.00000,0.04865,304.78120
135.90001,6.79508,24857.84888,0.00000,0.04878,304.87709
136.20001,6.80990,24859.89928,0.00000,0.04891,304.90224
136.50001,6.82509,24864.89415,0.00000,0.04904,304.96350
136.80001,6.83998,24866.93114,0.00000,0.04918,304.98849
137.10001,6.85498,24867.14423,0.00000,0.04931,304.99110
137.40001,6.87011,24874.25506,0.00000,0.04945,305.07831
137.70001,6.88500,24872.14208,0.00000,0.04958,305.05240
138.00001,6.90007,24877.67339,0.00000,0.04971,305.12024
138.30001,6.91495,24878.68369,0.00000,0.04984,305.13263
138.60001,6.93002,24883.60852,0.00000,0.04997,305.19303
138.90001,6.94491,24882.79045,0.00000,0.05010,305.18300
139.20001,6.96003,24886.64389,0.00000,0.05023,305.23026
139.50001,6.97492,24887.88515,0.00000,0.05036,305.24548
139.80001,6.99005,24891.11274,0.00000,0.05049,305.28507
140.10001,7.00506,24896.93314,0.00000,0.05062,305.35645
140.40001,7.01988,24895.73210,0.00000,0.05075,305.34172
140.70001,7.03513,24902.12768,0.00000,0.05088,305.42016
141.00001,7.04990,24903.78320,0.00000,0.05101,305.44047
141.30001,7.06509,24905.84403,0.00000,0.05114,305.46574
141.60001,7.07997,24908.38021,0.00000,0.05127,305.49685
141.90001,7.09498,24910.80761,0.00000,0.05140,305.52662
142.20001,7.11005,24914.70277,0.00000,0.05153,305.57440
142.50001,7.12493,24914.29895,0.00000,0.05166,305.56944
142.80001,7.14000,24918.94513,0.00000,0.05179,305.62643
143.10001,7.15495,24919.02113,0.00000,0.05191,305.62736
143.40001,7.17002,24924.29763,0.00000,0.05204,305.69207
143.70001,7.18490,24924.06964,0.00000,0.05218,305.68928
144.00001,7.19997,24927.78301,0.00000,0.05231,305.73482
144.30001,7.21498,24932.67655,0.00000,0.05244,305.79484
144.60001,7.22998,24931.54556,0.00000,0.05257,305.78097
144.90001,7.24505,24938.22426,0.00000,0.05270,305.86288
145.20001,7.25988,24935.50479,0.00000,0.05283,305.82953
145.50001,7.27513,24941.46675,0.00000,0.05296,305.90265
145.80001,7.28989,24944.20856,0.00000,0.05309,305.93628
146.10001,7.30508,24945.88345,0.00000,0.05321,305.95682
146.40001,7.32003,24949.27943,0.00000,0.05334,305.99847
146.70001,7.33503,24948.97991,0.00000,0.05347,305.99480
147.00001,7.35004,24952.14045,0.00000,0.05360,306.03356
147.30001,7.36499,24954.81223,0.00000,0.05373,306.06633
147.60001,7.38006,24955.94472,0.00000,0.05386,306.08022
147.90001,7.39494,24957.16065,0.00000,0.05399,306.09513
148.20001,7.41001,24960.49106,0.00000,0.05411,306.13598
148.50001,7.42496,24961.70104,0.00000,0.05424,306.15082
148.80001,7.44003,24964.80495,0.00000,0.05437,306.18889
149.10001,7.45497,24969.90860,0.00000,0.05449,306.25149
149.40001,7.47004,24970.30348,0.00000,0.05462,306.25633
149.70001,7.48517,24975.60829,0.00000,0.05475,306.32139
150.00001,7.49993,24972.34493,0.00000,0.05487,306.28137
150.30001,7.51518,24979.39616,0.00000,0.05500,306.36785
150.60001,7.52995,24979.51835,0.00000,0.05512,306.36935
150.90001,7.54507,24982.85919,0.00000,0.05526,306.41032
151.20001,7.55996,24985.34024,0.00000,0.05538,306.44075
151.50001,7.57491,24985.28510,0.00000,0.05552,306.44008
151.80001,7.59004,24989.25924,0.00000,0.05564,306.48882
152.10001,7.60492,24988.13123,0.00000,0.05577,306.47498
152.40001,7.62005,24992.49279,0.00000,0.05589,306.52848
152.70001,7.63494,24994.75479,0.00000,0.05602,306.55622
153.00001,7.65001,24999.54402,0.00000,0.05614,306.61496
153.30001,7.66501,25001.35601,0.00000,0.05627,306.63718
153.60001,7.68008,25003.29614,0.00000,0.05640,306.66098
153.90001,7.69503,25007.11977,0.00000,0.05653,306.70787
154.20001,7.71009,25006.45220,0.00000,0.05666,306.69969
154.50001,7.72504,25011.33382,0.00000,0.05679,306.75956
154.80001,7.73987,25010.32650,0.00000,0.05691,306.74720
155.10001,7.75518,25016.28101,0.00000,0.05704,306.82023
155.40001,7.76988,25013.77165,0.00000,0.05716,306.78946
155.70001,7.78501,25017.19296,0.00000,0.05729,306.83142
156.00001,7.80002,25020.21492,0.00000,0.05742,306.86848
156.30001,7.81496,25020.16425,0.00000,0.05755,306.86786
156.60001,7.83009,25025.44224,0.00000,0.05768,306.93260
156.90001,7.84492,25023.87464,0.00000,0.05780,306.91337
157.20001,7.86011,25028.10061,0.00000,0.05793,306.96520
157.50001,7.87499,25027.15290,0.00000,0.05805,306.95358
157.80001,7.89000,25031.68881,0.00000,0.05818,307.00921
158.10001,7.90495,25033.61702,0.00000,0.05831,307.03286
158.40001,7.92007,25035.58397,0.00000,0.05845,307.05698
158.70001,7.93496,25039.20496,0.00000,0.05858,307.10139
159.00001,7.95003,25035.84325,0.00000,0.05870,307.06016
159.30001,7.96510,25043.24019,0.00000,0.05884,307.15088
159.60001,7.97992,25039.94703,0.00000,0.05896,307.11049
159.90001,7.99511,25045.16542,0.00000,0.05908,307.17450
160.20001,8.00988,25045.71080,0.00000,0.05921,307.18119
160.50001,8.02501,25048.67613,0.00000,0.05934,307.21756
160.80001,8.04001,25050.18413,0.00000,0.05947,307.23605
161.10001,8.05496,25049.01290,0.00000,0.05959,307.22169
161.40001,8.07003,25053.52497,0.00000,0.05972,307.27703
161.70001,8.08491,25053.37894,0.00000,0.05985,307.27523
162.00001,8.10004,25058.62415,0.00000,0.05997,307.33957
162.30001,8.11499,25057.43802,0.00000,0.06010,307.32502
162.60001,8.13000,25060.27818,0.00000,0.06023,307.35985
162.90001,8.14494,25060.48679,0.00000,0.06035,307.36241
163.20001,8.16013,25064.51309,0.00000,0.06048,307.41179
163.50001,8.17490,25066.05089,0.00000,0.06061,307.43065
163.80001,8.18996,25065.70816,0.00000,0.06074,307.42645
164.10001,8.20509,25069.61524,0.00000,0.06087,307.47437
164.40001,8.21986,25067.89565,0.00000,0.06099,307.45328
164.70001,8.23511,25071.35570,0.00000,0.06112,307.49572
165.00001,8.24993,25073.02761,0.00000,0.06124,307.51622
165.30001,8.26500,25074.75317,0.00000,0.06137,307.53739
165.60001,8.28001,25077.63803,0.00000,0.06150,307.57277
165.90001,8.29490,25077.71552,0.00000,0.06162,307.57372
166.20001,8.31008,25081.75373,0.00000,0.06175,307.62325
166.50001,8.32497,25080.70469,0.00000,0.06188,307.61038
166.80001,8.33998,25084.31971,0.00000,0.06201,307.65472
167.10001,8.35498,25084.55515,0.00000,0.06214,307.65760
167.40001,8.36999,25087.64863,0.00000,0.06227,307.69555
167.70001,8.38488,25088.26554,0.00000,0.06239,307.70311
168.00001,8.40012,25090.36064,0.00000,0.06252,307.72881
168.30001,8.41495,25091.72857,0.00000,0.06265,307.74559
168.60001,8.42996,25090.88814,0.00000,0.06278,307.73528
168.90001,8.44515,25095.89195,0.00000,0.06291,307.79665
169.20001,8.45985,25093.56737,0.00000,0.06303,307.76814
169.50001,8.47510,25096.87245,0.00000,0.06316,307.80867
169.80001,8.48993,25098.54138,0.00000,0.06329,307.82914
170.10001,8.50494,25098.62483,0.00000,0.06341,307.83017
170.40001,8.52000,25102.77331,0.00000,0.06355,307.88105
170.70001,8.53489,25103.74486,0.00000,0.06368,307.89296
171.00001,8.55002,25106.09031,0.00000,0.06381,307.92173
171.30001,8.56496,25106.42707,0.00000,0.06394,307.92586
171.60001,8.58009,25107.66685,0.00000,0.06406,307.94107
171.90001,8.59498,25106.62973,0.00000,0.06419,307.92835
172.20001,8.61011,25112.08653,0.00000,0.06431,307.99527
172.50001,8.62499,25110.64112,0.00000,0.06444,307.97754
172.80001,8.64012,25112.18190,0.00000,0.06457,307.99644
173.10001,8.65501,25115.18002,0.00000,0.06470,308.03321
173.40001,8.66989,25112.06865,0.00000,0.06484,307.99505
173.70001,8.68514,25117.88011,0.00000,0.06497,308.06633
174.00001,8.69985,25115.82077,0.00000,0.06509,308.04107
174.30001,8.71509,25120.04673,0.00000,0.06522,308.09290
174.60001,8.72992,25121.14942,0.00000,0.06535,308.10643
174.90001,8.74499,25121.34612,0.00000,0.06548,308.10884
175.20001,8.76012,25124.63629,0.00000,0.06561,308.14919
175.50001,8.77500,25124.60351,0.00000,0.06574,308.14879
175.80001,8.79013,25126.45125,0.00000,0.06587,308.17145
176.10001,8.80502,25125.74196,0.00000,0.06600,308.16275
176.40001,8.82009,25130.66232,0.00000,0.06613,308.22310
176.70001,8.83491,25127.40791,0.00000,0.06625,308.18319
177.00001,8.85010,25130.96333,0.00000,0.06640,308.22679
177.30001,8.86493,25129.87554,0.00000,0.06653,308.21345
177.60001,8.88005,25129.66096,0.00000,0.06666,308.21082
177.90001,8.89500,25134.50980,0.00000,0.06679,308.27029
178.20001,8.90989,25131.35076,0.00000,0.06692,308.23154
178.50001,8.92514,25137.24566,0.00000,0.06705,308.30384
178.80001,8.93984,25135.85687,0.00000,0.06717,308.28681
179.10001,8.95503,25139.16492,0.00000,0.06730,308.32738
179.40001,8.96998,25141.41500,0.00000,0.06743,308.35498
179.70001,8.98499,25141.12294,0.00000,0.06756,308.35140
180.00001,9.00005,25144.00184,0.00000,0.06769,308.38671
180.30001,9.01500,25142.32695,0.00000,0.06782,308.36617
180.60001,9.03007,25145.02406,0.00000,0.06795,308.39925
180.90001,9.04501,25144.07039,0.00000,0.06808,308.38755
181.20001,9.06008,25147.41123,0.00000,0.06821,308.42852
181.50001,9.07491,25146.21019,0.00000,0.06834,308.41379
181.80001,9.09009,25151.81303,0.00000,0.06847,308.48251
182.10001,9.10492,25151.05009,0.00000,0.06859,308.47315
182.40001,9.12005,25150.09940,0.00000,0.06872,308.46149
182.70001,9.13500,25153.74422,0.00000,0.06885,308.50620
183.00001,9.14983,25150.71630,0.00000,0.06899,308.46906
183.30001,9.16507,25155.88999,0.00000,0.06912,308.53251
183.60001,9.17990,25155.62177,0.00000,0.06925,308.52922
183.90001,9.19503,25156.08966,0.00000,0.06938,308.53496
184.20001,9.20997,25158.03277,0.00000,0.06951,308.55879
184.50001,9.22504,25158.50365,0.00000,0.06964,308.56457
184.80001,9.24005,25160.79247,0.00000,0.06977,308.59264
185.10001,9.25505,25159.20699,0.00000,0.06990,308.57320
185.40001,9.27000,25161.67164,0.00000,0.07003,308.60342
185.70001,9.28501,25159.06394,0.00000,0.07016,308.57144
186.00001,9.30008,25163.16473,0.00000,0.07029,308.62174
186.30001,9.31484,25159.35004,0.00000,0.07042,308.57495
186.60001,9.33003,25162.46736,0.00000,0.07055,308.61318
186.90001,9.34498,25165.71283,0.00000,0.07067,308.65299
187.20001,9.36005,25164.13033,0.00000,0.07081,308.63358
187.50001,9.37505,25167.00625,0.00000,0.07094,308.66885
187.80001,9.38988,25163.46574,0.00000,0.07107,308.62543
188.10001,9.40513,25168.55896,0.00000,0.07120,308.68790
188.40001,9.41989,25169.94774,0.00000,0.07133,308.70493
188.70001,9.43502,25170.03119,0.00000,0.07145,308.70595
189.00001,9.44997,25172.00708,0.00000,0.07159,308.73019
189.30001,9.46498,25171.13090,0.00000,0.07171,308.71944
189.60001,9.47998,25171.76867,0.00000,0.07185,308.72726
189.90001,9.49499,25171.77165,0.00000,0.07197,308.72730
190.20001,9.51000,25174.60883,0.00000,0.07211,308.76210
190.50001,9.52494,25173.62833,0.00000,0.07224,308.75007
190.80001,9.54001,25176.39995,0.00000,0.07237,308.78406
191.10001,9.55484,25172.52862,0.00000,0.07249,308.73658
191.40001,9.57009,25176.30458,0.00000,0.07262,308.78290
191.70001,9.58497,25177.82748,0.00000,0.07275,308.80157
192.00001,9.59998,25176.71287,0.00000,0.07289,308.78790
192.30001,9.61505,25181.99980,0.00000,0.07302,308.85275
192.60001,9.62981,25177.44601,0.00000,0.07316,308.79689
192.90001,9.64512,25182.20246,0.00000,0.07329,308.85523
193.20001,9.65995,25180.78685,0.00000,0.07342,308.83787
193.50001,9.67502,25180.94182,0.00000,0.07355,308.83977
193.80001,9.69002,25184.14557,0.00000,0.07368,308.87906
194.10001,9.70503,25183.96676,0.00000,0.07381,308.87687
194.40001,9.72004,25185.37939,0.00000,0.07394,308.89420
194.70001,9.73504,25186.02014,0.00000,0.07407,308.90205
195.00001,9.74999,25184.71777,0.00000,0.07420,308.88608
195.30001,9.76494,25183.39455,0.00000,0.07433,308.86985
195.60001,9.78007,25187.59966,0.00000,0.07446,308.92143
195.90001,9.79483,25184.90851,0.00000,0.07459,308.88842
196.20001,9.81008,25189.04209,0.00000,0.07472,308.93912
196.50001,9.82491,25189.66794,0.00000,0.07486,308.94679
196.80001,9.83997,25187.53111,0.00000,0.07499,308.92059
197.10001,9.85510,25192.13259,0.00000,0.07512,308.97702
197.40001,9.86987,25188.92288,0.00000,0.07525,308.93766
197.70001,9.88512,25193.28892,0.00000,0.07538,308.99121
198.00001,9.89994,25191.83457,0.00000,0.07551,308.97337
198.30001,9.91507,25192.25776,0.00000,0.07564,308.97856
198.60001,9.93002,25191.59317,0.00000,0.07577,308.97041
198.90001,9.94503,25190.26101,0.00000,0.07591,308.95407
199.20001,9.95997,25193.00282,0.00000,0.07604,308.98770
199.50001,9.97492,25191.73324,0.00000,0.07617,308.97213
199.80001,9.99005,25194.33796,0.00000,0.07630,309.00407
200.10001,10.00499,25192.49916,0.00000,0.07644,308.98152
200.40001,10.02006,25195.08898,0.00000,0.07656,309.01328
200.70001,10.03489,25193.56608,0.00000,0.07669,308.99460
201.00001,10.05008,25195.68801,0.00000,0.07682,309.02063
201.30001,10.06496,25199.13912,0.00000,0.07695,309.06296
201.60001,10.07991,25195.02938,0.00000,0.07709,309.01255
201.90001,10.09510,25198.39406,0.00000,0.07722,309.05382
202.20001,10.10992,25196.96653,0.00000,0.07735,309.03631
202.50001,10.12511,25197.86358,0.00000,0.07748,309.04731
202.80001,10.13988,25197.20197,0.00000,0.07762,309.03920
203.10001,10.15501,25198.96328,0.00000,0.07775,309.06080
203.40001,10.17001,25198.13180,0.00000,0.07788,309.05060
203.70001,10.18496,25196.56122,0.00000,0.07801,309.03134
204.00001,10.20003,25198.21525,0.00000,0.07814,309.05163
204.30001,10.21498,25197.26753,0.00000,0.07827,309.04000
204.60001,10.22998,25201.66934,0.00000,0.07841,309.09399
204.90001,10.24493,25198.79937,0.00000,0.07854,309.05879
205.20001,10.26000,25201.59781,0.00000,0.07867,309.09311
205.50001,10.27494,25200.30439,0.00000,0.07880,309.07725
205.80001,10.29007,25200.39678,0.00000,0.07893,309.07838
206.10001,10.30496,25202.70646,0.00000,0.07908,309.10671
206.40001,10.31991,25198.25697,0.00000,0.07921,309.05214
206.70001,10.33521,25205.23965,0.00000,0.07934,309.13778
207.00001,10.34992,25200.51301,0.00000,0.07947,309.07981
207.30001,10.36511,25200.09577,0.00000,0.07960,309.07469
207.60001,10.37999,25202.14915,0.00000,0.07973,309.09987
207.90001,10.39500,25199.39840,0.00000,0.07986,309.06614
208.20001,10.40995,25201.35045,0.00000,0.07999,309.09008
208.50001,10.42490,25200.04809,0.00000,0.08013,309.07411
208.80001,10.44002,25202.13425,0.00000,0.08026,309.09969
209.10001,10.45497,25200.20306,0.00000,0.08039,309.07601
209.40001,10.47004,25203.71377,0.00000,0.08052,309.11906
209.70001,10.48492,25201.04349,0.00000,0.08065,309.08631
210.00001,10.50005,25205.02806,0.00000,0.08078,309.13518
210.30001,10.51494,25204.51546,0.00000,0.08092,309.12890
210.60001,10.53013,25203.79424,0.00000,0.08105,309.12005
210.90001,10.54507,25205.99365,0.00000,0.08118,309.14703
211.20001,10.56002,25200.54281,0.00000,0.08131,309.08017
211.50001,10.57509,25204.73897,0.00000,0.08144,309.13164
211.80001,10.58985,25201.79749,0.00000,0.08157,309.09556
212.10001,10.60510,25205.03104,0.00000,0.08171,309.13522
212.40001,10.61993,25201.55311,0.00000,0.08183,309.09256
212.70001,10.63500,25202.81076,0.00000,0.08197,309.10799
213.00001,10.65000,25203.59159,0.00000,0.08210,309.11757
213.30001,10.66495,25203.02534,0.00000,0.08223,309.11062
213.60001,10.68002,25206.10690,0.00000,0.08236,309.14842
213.90001,10.69497,25203.43363,0.00000,0.08250,309.11563
214.20001,10.71003,25207.12614,0.00000,0.08263,309.16092
214.50001,10.72492,25203.32336,0.00000,0.08276,309.11428
214.80001,10.74005,25204.97143,0.00000,0.08289,309.13449
215.10001,10.75487,25205.12342,0.00000,0.08302,309.13635
215.40001,10.77006,25205.50489,0.00000,0.08316,309.14103
215.70001,10.78501,25207.74901,0.00000,0.08330,309.16856
216.00001,10.79996,25202.75414,0.00000,0.08343,309.10729
216.30001,10.81514,25205.67179,0.00000,0.08356,309.14308
216.60001,10.82991,25202.70050,0.00000,0.08369,309.10664
216.90001,10.84504,25204.52142,0.00000,0.08383,309.12897
217.20001,10.85992,25204.25022,0.00000,0.08396,309.12564
217.50001,10.87505,25206.06220,0.00000,0.08409,309.14787
217.80001,10.89000,25205.46615,0.00000,0.08422,309.14056
218.10001,10.90501,25203.91941,0.00000,0.08436,309.12159
218.40001,10.92001,25204.97739,0.00000,0.08449,309.13456
218.70001,10.93502,25204.26214,0.00000,0.08463,309.12579
219.00001,10.95003,25205.71053,0.00000,0.08476,309.14355
219.30001,10.96491,25202.42631,0.00000,0.08490,309.10327
219.60001,10.98010,25204.78070,0.00000,0.08503,309.13215
219.90001,10.99499,25202.49188,0.00000,0.08517,309.10408
220.20001,11.01005,25203.38595,0.00000,0.08530,309.11504
220.50001,11.02494,25204.90289,0.00000,0.08543,309.13365
220.80001,11.04001,25201.99716,0.00000,0.08557,309.09801
221.10001,11.05514,25203.27866,0.00000,0.08570,309.11373
221.40001,11.06991,25199.78881,0.00000,0.08583,309.07093
221.70001,11.08503,25199.75007,0.00000,0.08597,309.07045
222.00001,11.09998,25200.56367,0.00000,0.08610,309.08043
222.30001,11.11505,25201.51436,0.00000,0.08623,309.09209
222.60001,11.12999,25202.55148,0.00000,0.08636,309.10481
222.90001,11.14500,25201.15077,0.00000,0.08650,309.08763
223.20001,11.16007,25203.30846,0.00000,0.08663,309.11409
223.50001,11.17502,25199.12720,0.00000,0.08676,309.06281
223.80001,11.19002,25201.40111,0.00000,0.08690,309.09070
224.10001,11.20491,25198.79341,0.00000,0.08703,309.05872
224.40001,11.22010,25200.50406,0.00000,0.08716,309.07970
224.70001,11.23486,25198.73977,0.00000,0.08730,309.05806
225.00001,11.25005,25196.74003,0.00000,0.08743,309.03353
225.30001,11.26500,25198.00663,0.00000,0.08757,309.04907
225.60001,11.27989,25194.29028,0.00000,0.08770,309.00349
225.90001,11.29513,25199.24939,0.00000,0.08783,309.06431
226.20001,11.30984,25196.58506,0.00000,0.08796,309.03163
226.50001,11.32503,25197.45827,0.00000,0.08809,309.04234
226.80001,11.33991,25196.24531,0.00000,0.08823,309.02746
227.10001,11.35492,25195.17839,0.00000,0.08837,309.01438
227.40001,11.36993,25195.84596,0.00000,0.08850,309.02257
227.70001,11.38494,25194.47207,0.00000,0.08863,309.00572
228.00001,11.40000,25195.37508,0.00000,0.08877,309.01679
228.30001,11.41495,25193.03560,0.00000,0.08890,308.98810
228.60001,11.43008,25193.52436,0.00000,0.08904,308.99409
228.90001,11.44496,25192.54088,0.00000,0.08916,308.98203
229.20001,11.46009,25192.23690,0.00000,0.08929,308.97830
229.50001,11.47492,25191.95974,0.00000,0.08943,308.97490
229.80001,11.49005,25189.74841,0.00000,0.08956,308.94778
230.10001,11.50505,25191.42926,0.00000,0.08969,308.96840
230.40001,11.51988,25187.02745,0.00000,0.08983,308.91441
230.70001,11.53513,25189.87954,0.00000,0.08996,308.94939
231.00001,11.54989,25188.09438,0.00000,0.09008,308.92750
231.30001,11.56496,25187.96623,0.00000,0.09021,308.92592
231.60001,11.57997,25188.97951,0.00000,0.09035,308.93835
231.90001,11.59504,25187.39104,0.00000,0.09048,308.91887
232.20001,11.60998,25186.24365,0.00000,0.09061,308.90480
232.50001,11.62505,25183.43031,0.00000,0.09074,308.87029
232.80001,11.64006,25184.61347,0.00000,0.09087,308.88480
233.10001,11.65500,25182.37531,0.00000,0.09100,308.85735
233.40001,11.67007,25183.68363,0.00000,0.09113,308.87340
233.70001,11.68490,25178.82884,0.00000,0.09126,308.81385
234.00001,11.70015,25180.42624,0.00000,0.09139,308.83345
234.30001,11.71491,25178.37286,0.00000,0.09152,308.80826
234.60001,11.72998,25176.60260,0.00000,0.09164,308.78655
234.90001,11.74505,25180.16696,0.00000,0.09178,308.83027
235.20001,11.75988,25176.53704,0.00000,0.09190,308.78575
235.50001,11.77512,25178.46823,0.00000,0.09203,308.80943
235.80001,11.78989,25175.04990,0.00000,0.09216,308.76751
236.10001,11.80502,25174.49260,0.00000,0.09228,308.76067
236.40001,11.81996,25175.12739,0.00000,0.09241,308.76846
236.70001,11.83497,25174.26312,0.00000,0.09254,308.75786
237.00001,11.84998,25173.02930,0.00000,0.09266,308.74272
237.30001,11.86504,25170.78817,0.00000,0.09279,308.71524
237.60001,11.88005,25171.84615,0.00000,0.09292,308.72821
237.90001,11.89500,25165.00652,0.00000,0.09303,308.64433
238.20001,11.91013,25168.63644,0.00000,0.09316,308.68885
238.50001,11.92489,25163.88297,0.00000,0.09329,308.63055
238.80001,11.94008,25165.40289,0.00000,0.09341,308.64919
239.10001,11.95491,25165.17043,0.00000,0.09353,308.64634
239.40001,11.96998,25162.37497,0.00000,0.09365,308.61205
239.70001,11.98504,25164.30020,0.00000,0.09378,308.63566
240.00001,11.99987,25158.64372,0.00000,0.09390,308.56629
240.30001,12.01506,25160.56895,0.00000,0.09402,308.58990
240.60001,12.02988,25158.27417,0.00000,0.09414,308.56176
240.90001,12.04501,25156.76022,0.00000,0.09426,308.54319
241.20001,12.06002,25154.87671,0.00000,0.09437,308.52009
241.50001,12.07503,25153.24354,0.00000,0.09449,308.50006
241.80001,12.09003,25153.02598,0.00000,0.09461,308.49739
242.10001,12.10510,25151.47030,0.00000,0.09473,308.47831
242.40001,12.11999,25149.44673,0.00000,0.09484,308.45349
242.70001,12.13499,25144.34159,0.00000,0.09495,308.39087
243.00001,12.15012,25144.79160,0.00000,0.09506,308.39639
243.30001,12.16489,25140.00535,0.00000,0.09518,308.33769
243.60001,12.18008,25141.44480,0.00000,0.09529,308.35535
243.90001,12.19496,25140.89942,0.00000,0.09540,308.34866
244.20001,12.20997,25135.49328,0.00000,0.09551,308.28235
244.50001,12.22510,25136.93869,0.00000,0.09562,308.30008
244.80001,12.23993,25130.95438,0.00000,0.09572,308.22668
245.10001,12.25511,25131.12128,0.00000,0.09583,308.22873
245.40001,12.27000,25127.64931,0.00000,0.09593,308.18615
245.70001,12.28495,25123.29519,0.00000,0.09603,308.13274
246.00001,12.29995,25121.34612,0.00000,0.09614,308.10884
246.30001,12.31496,25117.14399,0.00000,0.09623,308.05730
246.60001,12.32997,25114.05945,0.00000,0.09633,308.01947
246.90001,12.34503,25109.11524,0.00000,0.09643,307.95883
247.20001,12.36004,25109.20763,0.00000,0.09653,307.95996
247.50001,12.37493,25101.15206,0.00000,0.09662,307.86116
247.80001,12.39006,25101.31001,0.00000,0.09671,307.86310
248.10001,12.40488,25094.75350,0.00000,0.09680,307.78269
248.40001,12.42013,25090.17587,0.00000,0.09689,307.72654
248.70001,12.43496,25088.12249,0.00000,0.09697,307.70136
249.00001,12.44991,25079.82850,0.00000,0.09705,307.59963
249.30001,12.46509,25078.71985,0.00000,0.09713,307.58604
249.60001,12.47986,25070.64044,0.00000,0.09721,307.48694
249.90001,12.49505,25065.09125,0.00000,0.09728,307.41888
250.20001,12.50993,25056.94330,0.00000,0.09735,307.31895
250.50001,12.52506,25050.60434,0.00000,0.09742,307.24120
250.80001,12.54001,25041.07654,0.00000,0.09749,307.12435
251.10001,12.55502,25033.51867,0.00000,0.09756,307.03165
251.40001,12.57002,25026.24094,0.00000,0.09762,306.94239
251.70001,12.58503,25013.82530,0.00000,0.09768,306.79012
252.00001,12.60010,25005.91576,0.00000,0.09773,306.69311
252.30001,12.61487,24988.37411,0.00000,0.09778,306.47796
252.60001,12.63011,24978.03271,0.00000,0.09783,306.35113
252.90001,12.64488,24958.64332,0.00000,0.09787,306.11332
253.20001,12.66007,24939.16303,0.00000,0.09791,305.87440
253.50001,12.67495,24916.05580,0.00000,0.09795,305.59099
253.80001,12.68996,24885.99718,0.00000,0.09798,305.22233
254.10001,12.70515,24852.49043,0.00000,0.09801,304.81137
254.40001,12.71985,24806.41454,0.00000,0.09802,304.24626
254.70001,12.73510,24756.78325,0.00000,0.09803,303.63754
255.00001,12.74999,24697.58391,0.00000,0.09804,302.91147
255.30001,12.76500,24635.86926,0.00000,0.09804,302.15455
255.60001,12.78000,24565.59241,0.00000,0.09804,301.29262
255.90001,12.79507,24499.48639,0.00000,0.09804,300.48184
256.20001,12.80996,24420.62497,0.00000,0.09803,299.51462
256.50001,12.82502,24298.11060,0.00000,0.09801,298.01200
256.80001,12.84009,24081.93052,0.00000,0.09796,295.36059
257.10001,12.85492,23715.72554,0.00000,0.09787,290.86915
257.27001,12.86359,22848.87433,0.00000,0.09688,280.23738
257.27601,12.86419,20294.40552,0.00000,0.08936,248.90727
257.28201,12.86520,16580.24341,0.00000,0.07861,203.35373
257.28601,12.86592,13914.63131,0.00000,0.07095,170.66048