File: scratch/college-stuff/ME Lab/ME lab Fall 2013/group17/group17.is_tens_RawData/Specimen_RawData_4.csv
Time,Extension,Load,Strain 2,Tensile strain,Tensile stress
(sec),(mm),(N),(mm/mm),(mm/mm),(MPa)
0.00000,0.00000,-0.63361,0.00000,0.00000,-0.00790
0.10000,0.00179,2.64950,0.00000,0.00000,0.03305
0.20000,0.00765,7.29733,0.00000,0.00001,0.09102
0.30000,0.01363,10.63614,0.00000,0.00001,0.13267
0.40000,0.01943,13.89895,0.00000,0.00001,0.17337
0.50000,0.02469,16.22581,0.00000,0.00001,0.20239
0.60000,0.03001,20.03296,0.00000,0.00001,0.24988
0.70000,0.03498,22.78622,0.00000,0.00001,0.28423
0.80000,0.04006,26.42391,0.00000,0.00001,0.32960
0.90000,0.04490,28.76163,0.00000,0.00002,0.35876
1.00000,0.05010,32.45651,0.00000,0.00002,0.40485
1.10000,0.05495,40.79823,0.00000,0.00001,0.50890
1.20000,0.06009,47.81744,0.00000,0.00002,0.59646
1.30000,0.06487,52.44304,0.00000,0.00002,0.65415
1.40000,0.07007,56.24669,0.00000,0.00002,0.70160
1.50000,0.07492,62.27983,0.00000,0.00003,0.77685
1.60000,0.08012,72.09632,0.00000,0.00003,0.89930
1.70000,0.08496,81.74282,0.00000,0.00004,1.01963
1.80000,0.09004,90.31218,0.00000,0.00004,1.12652
1.90000,0.09495,100.01562,0.00000,0.00005,1.24756
2.00000,0.10009,111.57593,0.00000,0.00004,1.39176
2.10000,0.10499,123.81945,0.00000,0.00005,1.54448
2.20000,0.11001,138.40897,0.00000,0.00005,1.72646
2.30000,0.11498,155.90907,0.00000,0.00006,1.94475
2.40000,0.12000,174.63363,0.00000,0.00006,2.17831
2.50000,0.12502,194.92122,0.00000,0.00007,2.43137
2.60000,0.12998,218.17677,0.00000,0.00007,2.72145
2.70000,0.13500,245.95954,0.00000,0.00008,3.06801
2.80000,0.13991,273.81917,0.00000,0.00010,3.41552
2.90000,0.14505,304.42150,0.00000,0.00011,3.79724
3.00000,0.14995,334.75661,0.00000,0.00013,4.17563
3.10000,0.15503,370.21153,0.00000,0.00015,4.61788
3.20000,0.15988,404.64522,0.00000,0.00016,5.04739
3.30000,0.16508,443.59518,0.00000,0.00018,5.53324
3.40000,0.16992,477.52983,0.00000,0.00020,5.95652
3.50000,0.17506,515.89953,0.00000,0.00022,6.43513
3.60000,0.17991,555.76744,0.00000,0.00024,6.93243
3.70000,0.18499,595.16835,0.00000,0.00026,7.42390
3.80000,0.18989,634.03528,0.00000,0.00028,7.90871
3.90000,0.19509,671.98314,0.00000,0.00029,8.38206
4.00000,0.20000,710.59172,0.00000,0.00031,8.86365
4.10000,0.20502,751.84545,0.00000,0.00033,9.37823
4.20000,0.20992,794.11445,0.00000,0.00035,9.90548
4.30000,0.21500,837.70920,0.00000,0.00037,10.44926
4.40000,0.21997,880.04190,0.00000,0.00039,10.97731
4.50000,0.22505,923.18356,0.00000,0.00042,11.51544
4.60000,0.22995,968.82172,0.00000,0.00044,12.08471
4.70000,0.23497,1014.00334,0.00000,0.00046,12.64829
4.80000,0.23994,1062.19612,0.00000,0.00048,13.24943
4.90000,0.24502,1106.27441,0.00000,0.00050,13.79924
5.00000,0.25004,1152.50219,0.00000,0.00053,14.37587
5.10000,0.25500,1196.83268,0.00000,0.00055,14.92883
5.20000,0.26008,1244.02102,0.00000,0.00058,15.51744
5.30000,0.26499,1287.53018,0.00000,0.00060,16.06016
5.40000,0.27007,1336.23695,0.00000,0.00063,16.66771
5.50000,0.27491,1379.65996,0.00000,0.00065,17.20935
5.60000,0.28005,1429.92334,0.00000,0.00067,17.83632
5.70000,0.28490,1474.62506,0.00000,0.00070,18.39391
5.80000,0.29010,1521.82449,0.00000,0.00072,18.98266
5.90000,0.29494,1565.84755,0.00000,0.00075,19.53178
6.00000,0.30002,1613.80563,0.00000,0.00077,20.13000
6.10000,0.30487,1661.52418,0.00000,0.00080,20.72522
6.20000,0.31007,1709.87602,0.00000,0.00082,21.32834
6.30000,0.31497,1754.80582,0.00000,0.00084,21.88878
6.40000,0.32005,1801.12403,0.00000,0.00087,22.46653
6.50000,0.32490,1848.54008,0.00000,0.00090,23.05798
6.60000,0.32998,1895.39529,0.00000,0.00092,23.64244
6.70000,0.33488,1942.83985,0.00000,0.00095,24.23424
6.80000,0.33996,1988.50464,0.00000,0.00097,24.80385
6.90000,0.34493,2035.66067,0.00000,0.00099,25.39205
7.00000,0.34995,2082.03252,0.00000,0.00102,25.97048
7.10000,0.35491,2128.72233,0.00000,0.00105,26.55287
7.20000,0.35993,2172.71168,0.00000,0.00108,27.10158
7.30000,0.36501,2221.46604,0.00000,0.00110,27.70972
7.40000,0.36998,2267.72223,0.00000,0.00112,28.28670
7.50000,0.37500,2315.71943,0.00000,0.00115,28.88540
7.60000,0.37990,2358.38089,0.00000,0.00117,29.41754
7.70000,0.38504,2404.97850,0.00000,0.00120,29.99878
7.80000,0.38995,2449.82373,0.00000,0.00122,30.55817
7.90000,0.39503,2497.97516,0.00000,0.00125,31.15879
8.00000,0.39987,2541.91104,0.00000,0.00127,31.70683
8.10000,0.40507,2589.41483,0.00000,0.00130,32.29937
8.20000,0.40992,2633.85028,0.00000,0.00132,32.85364
8.30000,0.41512,2680.25808,0.00000,0.00135,33.43252
8.40000,0.41996,2724.89581,0.00000,0.00137,33.98931
8.50000,0.42504,2771.28611,0.00000,0.00140,34.56797
8.60000,0.42995,2816.00822,0.00000,0.00142,35.12581
8.70000,0.43503,2861.86561,0.00000,0.00145,35.69782
8.80000,0.43993,2907.04481,0.00000,0.00147,36.26137
8.90000,0.44501,2953.16763,0.00000,0.00150,36.83669
9.00000,0.44992,2996.72149,0.00000,0.00152,37.37996
9.10000,0.45500,3040.99992,0.00000,0.00154,37.93227
9.20000,0.45996,3087.39617,0.00000,0.00157,38.51100
9.30000,0.46504,3131.52187,0.00000,0.00160,39.06141
9.40000,0.46995,3177.42191,0.00000,0.00162,39.63395
9.50000,0.47497,3218.77226,0.00000,0.00164,40.14974
9.60000,0.47999,3264.07775,0.00000,0.00167,40.71486
9.70000,0.48501,3307.88232,0.00000,0.00169,41.26126
9.80000,0.48997,3353.89189,0.00000,0.00172,41.83517
9.90000,0.49494,3394.95465,0.00000,0.00174,42.34737
10.00000,0.50002,3440.60063,0.00000,0.00176,42.91674
10.10000,0.50486,3481.55126,0.00000,0.00178,43.42754
10.20000,0.51006,3527.68898,0.00000,0.00181,44.00305
10.30000,0.51485,3569.44464,0.00000,0.00183,44.52389
10.40000,0.52005,3614.12950,0.00000,0.00186,45.08127
10.50000,0.52489,3655.29209,0.00000,0.00188,45.59472
10.60000,0.53009,3699.63385,0.00000,0.00191,46.14782
10.70000,0.53494,3741.32730,0.00000,0.00193,46.66789
10.80000,0.54002,3785.46566,0.00000,0.00195,47.21845
10.90000,0.54486,3825.78932,0.00000,0.00197,47.72144
11.00000,0.55000,3868.30308,0.00000,0.00200,48.25174
11.10000,0.55491,3911.36333,0.00000,0.00202,48.78885
11.20000,0.55999,3952.24430,0.00000,0.00204,49.29879
11.30000,0.56489,3995.01771,0.00000,0.00207,49.83233
11.40000,0.56997,4034.33070,0.00000,0.00209,50.32270
11.50000,0.57488,4077.10411,0.00000,0.00212,50.85624
11.60000,0.58002,4117.32122,0.00000,0.00214,51.35789
11.70000,0.58498,4161.22302,0.00000,0.00217,51.90551
11.80000,0.59000,4201.47814,0.00000,0.00219,52.40763
11.90000,0.59497,4242.52227,0.00000,0.00221,52.91960
12.00000,0.59993,4280.94342,0.00000,0.00223,53.39885
12.10000,0.60501,4323.56596,0.00000,0.00225,53.93051
12.20000,0.60991,4362.75490,0.00000,0.00228,54.41934
12.30000,0.61493,4404.67298,0.00000,0.00230,54.94221
12.40000,0.61990,4442.85274,0.00000,0.00233,55.41845
12.50000,0.62504,4484.88928,0.00000,0.00235,55.94280
12.60000,0.62994,4521.75215,0.00000,0.00237,56.40261
12.70000,0.63508,4563.04736,0.00000,0.00239,56.91771
12.80000,0.63993,4601.41785,0.00000,0.00242,57.39633
12.90000,0.64513,4639.97722,0.00000,0.00244,57.87730
13.00000,0.64997,4678.25122,0.00000,0.00246,58.35472
13.10000,0.65511,4717.80300,0.00000,0.00248,58.84807
13.20000,0.65990,4757.45648,0.00000,0.00251,59.34270
13.30000,0.66504,4796.94754,0.00000,0.00253,59.83529
13.40000,0.66994,4832.55610,0.00000,0.00255,60.27946
13.50000,0.67502,4871.94471,0.00000,0.00257,60.77078
13.60000,0.67993,4908.99645,0.00000,0.00259,61.23295
13.70000,0.68501,4949.53133,0.00000,0.00261,61.73856
13.80000,0.68997,4988.30006,0.00000,0.00263,62.22215
13.90000,0.69505,5026.94584,0.00000,0.00266,62.70420
14.00000,0.70002,5064.54110,0.00000,0.00268,63.17315
14.10000,0.70504,5100.50319,0.00000,0.00270,63.62173
14.20000,0.70994,5139.63699,0.00000,0.00272,64.10987
14.30000,0.71502,5174.89053,0.00000,0.00274,64.54961
14.40000,0.72004,5213.61232,0.00000,0.00277,65.03261
14.50000,0.72501,5246.92275,0.00000,0.00278,65.44811
14.60000,0.73003,5287.05344,0.00000,0.00281,65.94869
14.70000,0.73493,5322.45338,0.00000,0.00282,66.39025
14.80000,0.74001,5360.44315,0.00000,0.00285,66.86412
14.90000,0.74498,5395.09989,0.00000,0.00287,67.29642
15.00000,0.75006,5432.03838,0.00000,0.00289,67.75717
15.10000,0.75490,5464.86527,0.00000,0.00291,68.16664
15.20000,0.76004,5503.28009,0.00000,0.00293,68.64582
15.30000,0.76489,5537.10125,0.00000,0.00295,69.06769
15.40000,0.77009,5575.68036,0.00000,0.00297,69.54891
15.50000,0.77487,5609.27764,0.00000,0.00299,69.96799
15.60000,0.78001,5645.83130,0.00000,0.00302,70.42394
15.70000,0.78486,5680.64339,0.00000,0.00303,70.85818
15.80000,0.79006,5716.04371,0.00000,0.00306,71.29975
15.90000,0.79496,5749.98409,0.00000,0.00308,71.72311
16.00000,0.80004,5785.12996,0.00000,0.00310,72.16150
16.10000,0.80495,5818.64454,0.00000,0.00312,72.57955
16.20000,0.81003,5854.12644,0.00000,0.00314,73.02214
16.30000,0.81499,5887.81349,0.00000,0.00316,73.44234
16.40000,0.82001,5918.98561,0.00000,0.00317,73.83117
16.50000,0.82504,5953.41660,0.00000,0.00320,74.26065
16.60000,0.83000,5985.34457,0.00000,0.00322,74.65890
16.70000,0.83502,6020.91029,0.00000,0.00324,75.10254
16.80000,0.84004,6051.36193,0.00000,0.00325,75.48238
16.90000,0.84506,6083.85615,0.00000,0.00327,75.88770
17.00000,0.84997,6114.24968,0.00000,0.00329,76.26682
17.10000,0.85505,6148.83304,0.00000,0.00331,76.69820
17.20000,0.86001,6181.11007,0.00000,0.00333,77.10081
17.30000,0.86509,6214.56914,0.00000,0.00335,77.51816
17.40000,0.86994,6244.47279,0.00000,0.00337,77.89117
17.50000,0.87502,6276.64253,0.00000,0.00339,78.29244
17.60000,0.87992,6306.24443,0.00000,0.00340,78.66169
17.70000,0.88506,6338.64850,0.00000,0.00343,79.06588
17.80000,0.88997,6368.06190,0.00000,0.00344,79.43277
17.90000,0.89505,6400.36836,0.00000,0.00346,79.83575
18.00000,0.89989,6429.83094,0.00000,0.00348,80.20326
18.10000,0.90503,6459.38292,0.00000,0.00349,80.57188
18.20000,0.90994,6485.86154,0.00000,0.00351,80.90216
18.30000,0.91508,6513.55833,0.00000,0.00353,81.24764
18.40000,0.91992,6540.42289,0.00000,0.00354,81.58274
18.50000,0.92506,6568.86548,0.00000,0.00357,81.93752
18.60000,0.92991,6595.77921,0.00000,0.00357,82.27323
18.70000,0.93505,6624.77389,0.00000,0.00360,82.63490
18.80000,0.93995,6653.26342,0.00000,0.00361,82.99027
18.90000,0.94497,6680.25538,0.00000,0.00363,83.32696
19.00000,0.94994,6710.54274,0.00000,0.00365,83.70475
19.10000,0.95484,6736.64212,0.00000,0.00366,84.03030
19.20000,0.95998,6768.50826,0.00000,0.00369,84.42779
19.30000,0.96494,6796.49338,0.00000,0.00370,84.77686
19.40000,0.97002,6827.87225,0.00000,0.00372,85.16827
19.50000,0.97493,6855.01173,0.00000,0.00374,85.50680
19.60000,0.98007,6884.62481,0.00000,0.00375,85.87618
19.70000,0.98497,6912.28956,0.00000,0.00377,86.22126
19.80000,0.99005,6942.11721,0.00000,0.00378,86.59332
19.90000,0.99484,6969.82965,0.00000,0.00381,86.93899
20.00000,1.00004,7001.03268,0.00000,0.00382,87.32821
20.10000,1.00488,7029.05804,0.00000,0.00384,87.67779
20.20000,1.01008,7059.55327,0.00000,0.00386,88.05817
20.30000,1.01493,7087.07720,0.00000,0.00387,88.40150
20.40000,1.02001,7117.74677,0.00000,0.00390,88.78406
20.50000,1.02491,7146.88748,0.00000,0.00391,89.14755
20.60000,1.03005,7176.55942,0.00000,0.00393,89.51766
20.70000,1.03496,7206.11587,0.00000,0.00395,89.88634
20.80000,1.04004,7237.23844,0.00000,0.00397,90.27455
20.90000,1.04500,7267.46172,0.00000,0.00399,90.65154
21.00000,1.05002,7295.94454,0.00000,0.00400,91.00683
21.10000,1.05499,7325.41382,0.00000,0.00403,91.37442
21.20000,1.06001,7353.57404,0.00000,0.00404,91.72568
21.30000,1.06497,7384.40678,0.00000,0.00406,92.11027
21.40000,1.06999,7412.65863,0.00000,0.00409,92.46267
21.50000,1.07502,7443.97938,0.00000,0.00409,92.85336
21.60000,1.08004,7472.10458,0.00000,0.00412,93.20418
21.70000,1.08506,7501.02103,0.00000,0.00413,93.56487
21.80000,1.08996,7528.93984,0.00000,0.00415,93.91312
21.90000,1.09504,7559.60867,0.00000,0.00418,94.29567
22.00000,1.09995,7586.74666,0.00000,0.00419,94.63418
22.10000,1.10509,7617.75523,0.00000,0.00422,95.02097
22.20000,1.10993,7645.67554,0.00000,0.00423,95.36924
22.30000,1.11501,7676.70125,0.00000,0.00425,95.75624
22.40000,1.11986,7704.85625,0.00000,0.00426,96.10744
22.50000,1.12512,7735.62416,0.00000,0.00428,96.49122
22.60000,1.12996,7764.04962,0.00000,0.00431,96.84579
22.70000,1.13510,7794.44128,0.00000,0.00432,97.22489
22.80000,1.13989,7823.93217,0.00000,0.00434,97.59274
22.90000,1.14503,7854.37673,0.00000,0.00436,97.97250
23.00000,1.14993,7881.93494,0.00000,0.00438,98.31625
23.10000,1.15507,7911.80506,0.00000,0.00440,98.68884
23.20000,1.15992,7939.80658,0.00000,0.00441,99.03812
23.30000,1.16500,7969.15665,0.00000,0.00444,99.40422
23.40000,1.16996,7998.30705,0.00000,0.00445,99.76783
23.50000,1.17504,8027.42839,0.00000,0.00447,100.13108
23.60000,1.18001,8057.16589,0.00000,0.00449,100.50201
23.70000,1.18503,8085.34846,0.00000,0.00450,100.85355
23.80000,1.18999,8116.52988,0.00000,0.00453,101.24250
23.90000,1.19495,8143.06885,0.00000,0.00454,101.57353
24.00000,1.20003,8173.18335,0.00000,0.00456,101.94917
24.10000,1.20494,8199.30211,0.00000,0.00458,102.27496
24.20000,1.21002,8231.98929,0.00000,0.00460,102.68269
24.30000,1.21486,8258.64002,0.00000,0.00462,103.01512
24.40000,1.22006,8289.63295,0.00000,0.00463,103.40172
24.50000,1.22491,8316.43119,0.00000,0.00466,103.73599
24.60000,1.23005,8346.06513,0.00000,0.00467,104.10563
24.70000,1.23489,8374.20747,0.00000,0.00469,104.45667
24.80000,1.24009,8404.45682,0.00000,0.00471,104.83399
24.90000,1.24494,8431.83771,0.00000,0.00472,105.17553
25.00000,1.25008,8460.87113,0.00000,0.00475,105.53768
25.10000,1.25492,8487.92866,0.00000,0.00476,105.87518
25.20000,1.26000,8515.17245,0.00000,0.00478,106.21501
25.30000,1.26497,8542.42072,0.00000,0.00480,106.55490
25.40000,1.27005,8568.33458,0.00000,0.00482,106.87813
25.50000,1.27495,8596.70267,0.00000,0.00484,107.23199
25.60000,1.28003,8624.26013,0.00000,0.00485,107.57573
25.70000,1.28494,8651.52553,0.00000,0.00487,107.91583
25.80000,1.29002,8678.24927,0.00000,0.00489,108.24917
25.90000,1.29504,8706.30145,0.00000,0.00490,108.59908
26.00000,1.30000,8732.16018,0.00000,0.00492,108.92163
26.10000,1.30497,8758.19027,0.00000,0.00493,109.24632
26.20000,1.30999,8781.62608,0.00000,0.00495,109.53865
26.30000,1.31501,8805.89187,0.00000,0.00497,109.84133
26.40000,1.32009,8829.39547,0.00000,0.00498,110.13451
26.50000,1.32505,8856.08494,0.00000,0.00500,110.46742
26.60000,1.32996,8880.38725,0.00000,0.00501,110.77056
26.70000,1.33504,8906.48663,0.00000,0.00504,111.09611
26.80000,1.33994,8929.45901,0.00000,0.00505,111.38266
26.90000,1.34514,8957.03211,0.00000,0.00507,111.72660
27.00000,1.34999,8979.91136,0.00000,0.00508,112.01199
27.10000,1.35507,9006.67161,0.00000,0.00510,112.34578
27.20000,1.35991,9029.62089,0.00000,0.00512,112.63204
27.30000,1.36511,9056.32973,0.00000,0.00513,112.96520
27.40000,1.36996,9080.18202,0.00000,0.00515,113.26272
27.50000,1.37504,9106.45276,0.00000,0.00516,113.59042
27.60000,1.37988,9131.26841,0.00000,0.00519,113.89996
27.70000,1.38502,9156.91480,0.00000,0.00520,114.21986
27.80000,1.38993,9180.54581,0.00000,0.00522,114.51462
27.90000,1.39501,9206.36505,0.00000,0.00524,114.83668
28.00000,1.39991,9232.47933,0.00000,0.00525,115.16242
28.10000,1.40505,9259.08759,0.00000,0.00527,115.49432
28.20000,1.40996,9284.63042,0.00000,0.00529,115.81294
28.30000,1.41510,9309.80965,0.00000,0.00530,116.12701
28.40000,1.42000,9335.00379,0.00000,0.00532,116.44127
28.50000,1.42496,9358.94400,0.00000,0.00533,116.73990
28.60000,1.42999,9385.71393,0.00000,0.00536,117.07381
28.70000,1.43495,9407.99192,0.00000,0.00537,117.35170
28.80000,1.44003,9434.73279,0.00000,0.00539,117.68526
28.90000,1.44493,9458.09036,0.00000,0.00541,117.97661
29.00000,1.45001,9485.80131,0.00000,0.00542,118.32226
29.10000,1.45492,9510.12075,0.00000,0.00544,118.62562
29.20000,1.46006,9538.12599,0.00000,0.00546,118.97494
29.30000,1.46496,9561.51709,0.00000,0.00548,119.26671
29.40000,1.47004,9588.46509,0.00000,0.00549,119.60285
29.50000,1.47489,9611.65875,0.00000,0.00551,119.89216
29.60000,1.48009,9638.66785,0.00000,0.00553,120.22906
29.70000,1.48493,9664.29859,0.00000,0.00554,120.54877
29.80000,1.49007,9690.93069,0.00000,0.00556,120.88097
29.90000,1.49486,9714.37097,0.00000,0.00558,121.17336
30.00000,1.50000,9740.95911,0.00000,0.00560,121.50501
30.10000,1.50496,9765.26737,0.00000,0.00562,121.80822
30.20000,1.51004,9791.32652,0.00000,0.00563,122.13327
30.30000,1.51495,9816.54078,0.00000,0.00565,122.44778
30.40000,1.52003,9843.45749,0.00000,0.00566,122.78353
30.50000,1.52499,9868.18299,0.00000,0.00568,123.09195
30.60000,1.53001,9894.04097,0.00000,0.00570,123.41449
30.70000,1.53504,9920.29682,0.00000,0.00572,123.74200
30.80000,1.54006,9943.21033,0.00000,0.00573,124.02781
30.90000,1.54496,9971.21483,0.00000,0.00575,124.37713
31.00000,1.54998,9994.55079,0.00000,0.00577,124.66821
31.10000,1.55501,10021.81694,0.00000,0.00579,125.00832
31.20000,1.56003,10046.23398,0.00000,0.00580,125.31289
31.30000,1.56505,10073.76835,0.00000,0.00582,125.65634
31.40000,1.56995,10099.25231,0.00000,0.00584,125.97422
31.50000,1.57503,10127.18156,0.00000,0.00586,126.32260
31.60000,1.57994,10150.94668,0.00000,0.00587,126.61903
31.70000,1.58508,10178.36481,0.00000,0.00589,126.96104
31.80000,1.58992,10202.42572,0.00000,0.00591,127.26116
31.90000,1.59506,10229.53838,0.00000,0.00593,127.59936
32.00000,1.59991,10252.79164,0.00000,0.00594,127.88941
32.10000,1.60511,10280.31930,0.00000,0.00596,128.23278
32.20000,1.60995,10305.34953,0.00000,0.00598,128.54500
32.30000,1.61503,10332.03304,0.00000,0.00599,128.87784
32.40000,1.61994,10358.11380,0.00000,0.00602,129.20316
32.50000,1.62508,10383.33252,0.00000,0.00603,129.51773
32.60000,1.62998,10408.19660,0.00000,0.00605,129.82787
32.70000,1.63506,10434.14250,0.00000,0.00607,130.15151
32.80000,1.63991,10460.22102,0.00000,0.00609,130.47680
32.90000,1.64499,10485.36822,0.00000,0.00610,130.79048
33.00000,1.64995,10512.38626,0.00000,0.00612,131.12749
33.10000,1.65497,10537.52899,0.00000,0.00614,131.44111
33.20000,1.65994,10564.13576,0.00000,0.00616,131.77300
33.30000,1.66496,10590.07719,0.00000,0.00617,132.09658
33.40000,1.66992,10615.98137,0.00000,0.00620,132.41970
33.50000,1.67494,10640.82533,0.00000,0.00621,132.72959
33.60000,1.68003,10667.63178,0.00000,0.00623,133.06397
33.70000,1.68499,10692.40272,0.00000,0.00625,133.37295
33.80000,1.69001,10720.37667,0.00000,0.00627,133.72189
33.90000,1.69491,10743.91603,0.00000,0.00628,134.01551
34.00000,1.70005,10771.31629,0.00000,0.00630,134.35729
34.10000,1.70496,10793.91390,0.00000,0.00632,134.63916
34.20000,1.71004,10820.88128,0.00000,0.00634,134.97554
34.30000,1.71488,10845.46596,0.00000,0.00635,135.28220
34.40000,1.72002,10871.56087,0.00000,0.00637,135.60770
34.50000,1.72493,10895.72459,0.00000,0.00639,135.90911
34.60000,1.73007,10922.55265,0.00000,0.00641,136.24375
34.70000,1.73491,10948.96346,0.00000,0.00642,136.57319
34.80000,1.74005,10976.00833,0.00000,0.00644,136.91054
34.90000,1.74496,11001.36861,0.00000,0.00646,137.22687
35.00000,1.75004,11025.83855,0.00000,0.00648,137.53210
35.10000,1.75494,11051.16606,0.00000,0.00650,137.84803
35.20000,1.76002,11078.21092,0.00000,0.00652,138.18537
35.30000,1.76493,11103.91170,0.00000,0.00654,138.50596
35.40000,1.77001,11129.33010,0.00000,0.00655,138.82302
35.50000,1.77503,11156.31983,0.00000,0.00657,139.15968
35.60000,1.78005,11181.83509,0.00000,0.00659,139.47794
35.70000,1.78502,11208.34872,0.00000,0.00661,139.80866
35.80000,1.79004,11233.61290,0.00000,0.00663,140.12380
35.90000,1.79506,11258.89197,0.00000,0.00665,140.43912
36.00000,1.80002,11282.40302,0.00000,0.00666,140.73239
36.10000,1.80504,11310.73609,0.00000,0.00669,141.08580
36.20000,1.80995,11335.58825,0.00000,0.00670,141.39580
36.30000,1.81503,11363.73505,0.00000,0.00672,141.74689
36.40000,1.81993,11387.96583,0.00000,0.00674,142.04914
36.50000,1.82507,11415.57768,0.00000,0.00676,142.39356
36.60000,1.82986,11439.98653,0.00000,0.00677,142.69803
36.70000,1.83506,11468.10800,0.00000,0.00679,143.04880
36.80000,1.83990,11492.21733,0.00000,0.00681,143.34953
36.90000,1.84510,11519.92902,0.00000,0.00683,143.69520
37.00000,1.84995,11544.75585,0.00000,0.00685,144.00488
37.10000,1.85503,11572.59047,0.00000,0.00687,144.35208
37.20000,1.85987,11597.60058,0.00000,0.00689,144.66404
37.30000,1.86501,11623.23281,0.00000,0.00691,144.98377
37.40000,1.86992,11648.99841,0.00000,0.00693,145.30516
37.50000,1.87500,11674.38850,0.00000,0.00694,145.62187
37.60000,1.87990,11699.96485,0.00000,0.00696,145.94090
37.70000,1.88498,11725.32067,0.00000,0.00698,146.25717
37.80000,1.88995,11752.52572,0.00000,0.00700,146.59652
37.90000,1.89497,11776.59780,0.00000,0.00702,146.89679
38.00000,1.89993,11804.15303,0.00000,0.00703,147.24050
38.10000,1.90489,11828.51270,0.00000,0.00705,147.54435
38.20000,1.90998,11856.63417,0.00000,0.00707,147.89513
38.30000,1.91494,11881.24269,0.00000,0.00709,148.20209
38.40000,1.92002,11907.89491,0.00000,0.00711,148.53454
38.50000,1.92492,11932.59656,0.00000,0.00713,148.84265
38.60000,1.93000,11961.53983,0.00000,0.00715,149.20368
38.70000,1.93491,11986.86063,0.00000,0.00717,149.51952
38.80000,1.94011,12013.02111,0.00000,0.00719,149.84584
38.90000,1.94495,12037.96566,0.00000,0.00721,150.15699
39.00000,1.95009,12066.12289,0.00000,0.00723,150.50821
39.10000,1.95500,12091.23731,0.00000,0.00725,150.82148
39.20000,1.96014,12116.87922,0.00000,0.00727,151.14133
39.30000,1.96498,12141.27243,0.00000,0.00728,151.44560
39.40000,1.97000,12166.76533,0.00000,0.00730,151.76359
39.50000,1.97491,12193.04651,0.00000,0.00732,152.09141
39.60000,1.98005,12218.97304,0.00000,0.00734,152.41481
39.70000,1.98495,12244.26106,0.00000,0.00736,152.73024
39.80000,1.99009,12270.48635,0.00000,0.00738,153.05736
39.90000,1.99494,12296.42257,0.00000,0.00740,153.38088
40.00000,2.00002,12323.39367,0.00000,0.00742,153.71731
40.10000,2.00498,12348.91042,0.00000,0.00743,154.03559
40.20000,2.01006,12376.00222,0.00000,0.00746,154.37353
40.30000,2.01503,12402.72671,0.00000,0.00747,154.70688
40.40000,2.01999,12426.55665,0.00000,0.00749,155.00412
40.50000,2.02495,12453.53073,0.00000,0.00751,155.34059
40.60000,2.02997,12477.04551,0.00000,0.00753,155.63390
40.70000,2.03499,12505.54472,0.00000,0.00755,155.98939
40.80000,2.03996,12529.09154,0.00000,0.00757,156.28311
40.90000,2.04498,12556.61547,0.00000,0.00759,156.62643
41.00000,2.04988,12582.33041,0.00000,0.00761,156.94719
41.10000,2.05502,12610.55768,0.00000,0.00763,157.29928
41.20000,2.05993,12634.34738,0.00000,0.00764,157.59603
41.30000,2.06507,12662.27663,0.00000,0.00766,157.94441
41.40000,2.06991,12686.11103,0.00000,0.00768,158.24171
41.50000,2.07505,12712.61126,0.00000,0.00770,158.57226
41.60000,2.07990,12736.71091,0.00000,0.00772,158.87287
41.70000,2.08510,12764.66697,0.00000,0.00774,159.22158
41.80000,2.08988,12788.83219,0.00000,0.00776,159.52301
41.90000,2.09496,12815.86438,0.00000,0.00777,159.86020
42.00000,2.09987,12842.26030,0.00000,0.00780,160.18945
42.10000,2.10501,12869.28505,0.00000,0.00781,160.52655
42.20000,2.10991,12895.47384,0.00000,0.00783,160.85322
42.30000,2.11499,12921.86081,0.00000,0.00785,161.18236
42.40000,2.11996,12946.27041,0.00000,0.00787,161.48684
42.50000,2.12504,12973.56635,0.00000,0.00789,161.82731
42.60000,2.13000,13000.25880,0.00000,0.00791,162.16027
42.70000,2.13502,13023.98741,0.00000,0.00793,162.45625
42.80000,2.14005,13051.11945,0.00000,0.00795,162.79468
42.90000,2.14495,13074.48596,0.00000,0.00796,163.08615
43.00000,2.15003,13101.16947,0.00000,0.00798,163.41899
43.10000,2.15499,13124.38101,0.00000,0.00800,163.70852
43.20000,2.16007,13152.21041,0.00000,0.00802,164.05565
43.30000,2.16492,13176.81521,0.00000,0.00804,164.36256
43.40000,2.17006,13205.79797,0.00000,0.00806,164.72408
43.50000,2.17496,13231.11057,0.00000,0.00808,165.03982
43.60000,2.18016,13258.49593,0.00000,0.00810,165.38142
43.70000,2.18495,13281.89075,0.00000,0.00812,165.67324
43.80000,2.19009,13308.71284,0.00000,0.00814,166.00780
43.90000,2.19493,13334.12975,0.00000,0.00816,166.32484
44.00000,2.20007,13360.15016,0.00000,0.00818,166.64941
44.10000,2.20498,13384.41521,0.00000,0.00820,166.95209
44.20000,2.21006,13412.52476,0.00000,0.00822,167.30271
44.30000,2.21490,13438.91770,0.00000,0.00824,167.63193
44.40000,2.22004,13465.00814,0.00000,0.00826,167.95737
44.50000,2.22501,13491.21928,0.00000,0.00828,168.28432
44.60000,2.23009,13516.27707,0.00000,0.00830,168.59688
44.70000,2.23499,13542.13804,0.00000,0.00832,168.91946
44.80000,2.24001,13567.81572,0.00000,0.00834,169.23975
44.90000,2.24492,13593.27286,0.00000,0.00835,169.55730
45.00000,2.25000,13619.29774,0.00000,0.00838,169.88192
45.10000,2.25496,13645.54167,0.00000,0.00840,170.20928
45.20000,2.25998,13670.04514,0.00000,0.00841,170.51493
45.30000,2.26501,13697.91627,0.00000,0.00844,170.86258
45.40000,2.26991,13721.55696,0.00000,0.00845,171.15746
45.50000,2.27499,13750.35793,0.00000,0.00847,171.51672
45.60000,2.27995,13774.64980,0.00000,0.00850,171.81972
45.70000,2.28503,13802.96350,0.00000,0.00852,172.17290
45.80000,2.28994,13828.90046,0.00000,0.00854,172.49643
45.90000,2.29508,13856.66579,0.00000,0.00856,172.84276
46.00000,2.29992,13880.12171,0.00000,0.00858,173.13534
46.10000,2.30506,13907.50259,0.00000,0.00860,173.47688
46.20000,2.30985,13931.71996,0.00000,0.00862,173.77896
46.30000,2.31505,13958.07266,0.00000,0.00864,174.10767
46.40000,2.31989,13983.53577,0.00000,0.00865,174.42529
46.50000,2.32503,14009.84079,0.00000,0.00867,174.75341
46.60000,2.32988,14036.09663,0.00000,0.00870,175.08091
46.70000,2.33502,14063.12883,0.00000,0.00871,175.41810
46.80000,2.33992,14089.09410,0.00000,0.00873,175.74198
46.90000,2.34506,14115.24266,0.00000,0.00875,176.06815
47.00000,2.34997,14139.33337,0.00000,0.00877,176.36865
47.10000,2.35499,14164.69812,0.00000,0.00879,176.68504
47.20000,2.35995,14192.34723,0.00000,0.00881,177.02992
47.30000,2.36497,14216.52138,0.00000,0.00883,177.33146
47.40000,2.37000,14243.94399,0.00000,0.00885,177.67352
47.50000,2.37502,14267.54147,0.00000,0.00887,177.96787
47.60000,2.37998,14296.65387,0.00000,0.00889,178.33100
47.70000,2.38500,14320.73116,0.00000,0.00891,178.63133
47.80000,2.39003,14347.78571,0.00000,0.00893,178.96880
47.90000,2.39499,14372.21915,0.00000,0.00895,179.27358
48.00000,2.40007,14399.01590,0.00000,0.00897,179.60783
48.10000,2.40491,14422.80710,0.00000,0.00899,179.90459
48.20000,2.41005,14451.09993,0.00000,0.00901,180.25750
48.30000,2.41496,14475.01183,0.00000,0.00902,180.55577
48.40000,2.42016,14502.41208,0.00000,0.00904,180.89755
48.50000,2.42494,14526.87532,0.00000,0.00906,181.20270
48.60000,2.43008,14553.62141,0.00000,0.00908,181.53632
48.70000,2.43487,14579.30207,0.00000,0.00910,181.85665
48.80000,2.44013,14606.09138,0.00000,0.00912,182.19081
48.90000,2.44497,14631.97321,0.00000,0.00914,182.51365
49.00000,2.45005,14659.49416,0.00000,0.00916,182.85693
49.10000,2.45490,14685.11522,0.00000,0.00918,183.17652
49.20000,2.46004,14711.63929,0.00000,0.00920,183.50737
49.30000,2.46488,14736.86248,0.00000,0.00922,183.82200
49.40000,2.47008,14763.20624,0.00000,0.00924,184.15060
49.50000,2.47493,14789.29818,0.00000,0.00926,184.47606
49.60000,2.48001,14814.63909,0.00000,0.00928,184.79215
49.70000,2.48497,14841.08865,0.00000,0.00930,185.12207
49.80000,2.49005,14867.96588,0.00000,0.00932,185.45733
49.90000,2.49496,14893.86410,0.00000,0.00935,185.78038
50.00000,2.49998,14917.91606,0.00000,0.00936,186.08039
50.10000,2.50500,14945.05703,0.00000,0.00938,186.41894
50.20000,2.50996,14969.49345,0.00000,0.00940,186.72375
50.30000,2.51505,14996.24550,0.00000,0.00942,187.05744
50.40000,2.51995,15020.36154,0.00000,0.00944,187.35826
50.50000,2.52503,15049.21764,0.00000,0.00946,187.71820
50.60000,2.52987,15073.38583,0.00000,0.00948,188.01966
50.70000,2.53507,15102.23001,0.00000,0.00950,188.37945
50.80000,2.53992,15124.87531,0.00000,0.00952,188.66192
50.90000,2.54500,15152.94611,0.00000,0.00954,189.01207
51.00000,2.54984,15177.22756,0.00000,0.00956,189.31494
51.10000,2.55510,15205.32668,0.00000,0.00958,189.66544
51.20000,2.55995,15228.77812,0.00000,0.00960,189.95797
51.30000,2.56509,15255.37074,0.00000,0.00962,190.28967
51.40000,2.56987,15280.38085,0.00000,0.00965,190.60164
51.50000,2.57501,15307.69467,0.00000,0.00966,190.94234
51.60000,2.57998,15333.11754,0.00000,0.00968,191.25946
51.70000,2.58506,15357.70148,0.00000,0.00970,191.56611
51.80000,2.58996,15382.07978,0.00000,0.00972,191.87019
51.90000,2.59498,15408.93018,0.00000,0.00975,192.20511
52.00000,2.59995,15435.19646,0.00000,0.00976,192.53275
52.10000,2.60503,15460.54482,0.00000,0.00979,192.84893
52.20000,2.61005,15488.46066,0.00000,0.00981,193.19715
52.30000,2.61507,15511.64538,0.00000,0.00982,193.48634
52.40000,2.62004,15539.75195,0.00000,0.00985,193.83693
52.50000,2.62500,15564.25542,0.00000,0.00986,194.14258
52.60000,2.63008,15590.63643,0.00000,0.00989,194.47165
52.70000,2.63504,15615.40663,0.00000,0.00990,194.78062
52.80000,2.64006,15642.08865,0.00000,0.00993,195.11344
52.90000,2.64497,15668.29532,0.00000,0.00995,195.44034
53.00000,2.65005,15696.74313,0.00000,0.00997,195.79518
53.10000,2.65495,15719.86377,0.00000,0.00999,196.08358
53.20000,2.66009,15748.84653,0.00000,0.01001,196.44510
53.30000,2.66494,15771.82412,0.00000,0.01003,196.73171
53.40000,2.67008,15798.68644,0.00000,0.01005,197.06678
53.50000,2.67498,15822.49850,0.00000,0.01006,197.36381
53.60000,2.68012,15849.84809,0.00000,0.01009,197.70496
53.70000,2.68497,15873.50070,0.00000,0.01011,197.99999
53.80000,2.69005,15901.24071,0.00000,0.01013,198.34601
53.90000,2.69489,15926.71275,0.00000,0.01015,198.66374
54.00000,2.70003,15952.89260,0.00000,0.01017,198.99029
54.10000,2.70500,15979.12759,0.00000,0.01019,199.31754
54.20000,2.71002,16003.92163,0.00000,0.01021,199.62681
54.30000,2.71492,16029.57398,0.00000,0.01023,199.94679
54.40000,2.72006,16057.42574,0.00000,0.01025,200.29420
54.50000,2.72503,16083.83656,0.00000,0.01027,200.62364
54.60000,2.73005,16106.90504,0.00000,0.01029,200.91139
54.70000,2.73495,16133.74799,0.00000,0.01031,201.24621
54.80000,2.73991,16157.99367,0.00000,0.01033,201.54865
54.90000,2.74500,16185.63533,0.00000,0.01036,201.89344
55.00000,2.74996,16208.70680,0.00000,0.01037,202.18122
55.10000,2.75504,16235.98039,0.00000,0.01039,202.52142
55.20000,2.75988,16260.91748,0.00000,0.01041,202.83248
55.30000,2.76497,16288.55616,0.00000,0.01043,203.17723
55.40000,2.76987,16313.75104,0.00000,0.01046,203.49150
55.50000,2.77507,16340.40475,0.00000,0.01048,203.82397
55.60000,2.77991,16363.53582,0.00000,0.01049,204.11250
55.70000,2.78505,16390.00624,0.00000,0.01051,204.44268
55.80000,2.78984,16413.61117,0.00000,0.01053,204.73712
55.90000,2.79504,16439.80891,0.00000,0.01055,205.06390
56.00000,2.79994,16465.49255,0.00000,0.01058,205.38427
56.10000,2.80502,16491.38778,0.00000,0.01060,205.70728
56.20000,2.80987,16517.92973,0.00000,0.01061,206.03835
56.30000,2.81501,16545.32254,0.00000,0.01063,206.38004
56.40000,2.81991,16570.19556,0.00000,0.01065,206.69029
56.50000,2.82505,16595.37107,0.00000,0.01067,207.00432
56.60000,2.82996,16621.33038,0.00000,0.01069,207.32813
56.70000,2.83504,16646.88736,0.00000,0.01071,207.64692
56.80000,2.84000,16673.86591,0.00000,0.01074,207.98344
56.90000,2.84496,16697.16686,0.00000,0.01075,208.27409
57.00000,2.84993,16723.32585,0.00000,0.01077,208.60038
57.10000,2.85501,16747.76971,0.00000,0.01079,208.90529
57.20000,2.85997,16775.33388,0.00000,0.01082,209.24911
57.30000,2.86499,16799.05802,0.00000,0.01084,209.54504
57.40000,2.87002,16826.45530,0.00000,0.01085,209.88678
57.50000,2.87498,16850.10642,0.00000,0.01088,210.18180
57.60000,2.88000,16877.38746,0.00000,0.01090,210.52209
57.70000,2.88490,16901.93713,0.00000,0.01092,210.82831
57.80000,2.89004,16930.16589,0.00000,0.01094,211.18043
57.90000,2.89495,16953.56816,0.00000,0.01096,211.47234
58.00000,2.90009,16980.04752,0.00000,0.01098,211.80263
58.10000,2.90493,17003.85362,0.00000,0.01100,212.09958
58.20000,2.91007,17031.86035,0.00000,0.01102,212.44892
58.30000,2.91486,17055.51147,0.00000,0.01104,212.74394
58.40000,2.92006,17083.02796,0.00000,0.01106,213.08717
58.50000,2.92490,17108.47169,0.00000,0.01108,213.40455
58.60000,2.92998,17135.22077,0.00000,0.01111,213.73820
58.70000,2.93489,17160.38138,0.00000,0.01112,214.05205
58.80000,2.94009,17186.88458,0.00000,0.01114,214.38264
58.90000,2.94499,17212.37004,0.00000,0.01117,214.70053
59.00000,2.95007,17235.81254,0.00000,0.01118,214.99295
59.10000,2.95492,17262.09074,0.00000,0.01121,215.32073
59.20000,2.96000,17286.48841,0.00000,0.01123,215.62506
59.30000,2.96496,17312.96033,0.00000,0.01125,215.95526
59.40000,2.96998,17337.01676,0.00000,0.01127,216.25533
59.50000,2.97495,17364.81339,0.00000,0.01129,216.60205
59.60000,2.97991,17389.46587,0.00000,0.01131,216.90956
59.70000,2.98493,17415.55482,0.00000,0.01133,217.23498
59.80000,2.98989,17439.03309,0.00000,0.01135,217.52784
59.90000,2.99504,17466.68369,0.00000,0.01138,217.87275
60.00000,2.99994,17490.94427,0.00000,0.01140,218.17536
60.10000,3.00502,17518.25809,0.00000,0.01142,218.51606
60.20000,3.00986,17541.27592,0.00000,0.01144,218.80318
60.30000,3.01506,17568.05331,0.00000,0.01146,219.13719
60.40000,3.01997,17591.93093,0.00000,0.01148,219.43503
60.50000,3.02499,17618.38943,0.00000,0.01150,219.76506
60.60000,3.02989,17642.78412,0.00000,0.01152,220.06935
60.70000,3.03503,17668.60634,0.00000,0.01154,220.39145
60.80000,3.03994,17693.58367,0.00000,0.01156,220.70301
60.90000,3.04508,17720.23588,0.00000,0.01158,221.03546
61.00000,3.04992,17745.67813,0.00000,0.01160,221.35282
61.10000,3.05506,17773.21696,0.00000,0.01163,221.69632
61.20000,3.05997,17797.51182,0.00000,0.01165,221.99937
61.30000,3.06505,17821.88416,0.00000,0.01167,222.30338
61.40000,3.06995,17847.09990,0.00000,0.01169,222.61791
61.50000,3.07503,17872.95938,0.00000,0.01171,222.94047
61.60000,3.07994,17899.02151,0.00000,0.01173,223.26556
61.70000,3.08508,17924.18957,0.00000,0.01175,223.57950
61.80000,3.08998,17950.88798,0.00000,0.01177,223.91252
61.90000,3.09500,17975.54195,0.00000,0.01179,224.22005
62.00000,3.10003,18003.91972,0.00000,0.01181,224.57402
62.10000,3.10505,18026.86751,0.00000,0.01183,224.86026
62.20000,3.11007,18052.55115,0.00000,0.01185,225.18063
62.30000,3.11497,18076.40344,0.00000,0.01188,225.47816
62.40000,3.11999,18102.87982,0.00000,0.01189,225.80841
62.50000,3.12496,18127.80201,0.00000,0.01192,226.11928
62.60000,3.13010,18154.47211,0.00000,0.01194,226.45196
62.70000,3.13494,18177.21128,0.00000,0.01196,226.73560
62.80000,3.14008,18204.73522,0.00000,0.01198,227.07892
62.90000,3.14487,18228.38038,0.00000,0.01200,227.37386
63.00000,3.15007,18256.15317,0.00000,0.01202,227.72029
63.10000,3.15497,18279.99502,0.00000,0.01204,228.01768
63.20000,3.16011,18305.85599,0.00000,0.01206,228.34026
63.30000,3.16490,18330.23876,0.00000,0.01208,228.64440
63.40000,3.16998,18356.02969,0.00000,0.01210,228.96611
63.50000,3.17488,18381.82062,0.00000,0.01212,229.28781
63.60000,3.18008,18408.81258,0.00000,0.01215,229.62450
63.70000,3.18493,18432.61570,0.00000,0.01217,229.92141
63.80000,3.19001,18456.64233,0.00000,0.01218,230.22111
63.90000,3.19491,18482.03987,0.00000,0.01221,230.53791
64.00000,3.19993,18507.20495,0.00000,0.01223,230.85181
64.10000,3.20496,18532.59355,0.00000,0.01225,231.16850
64.20000,3.20998,18556.06288,0.00000,0.01227,231.46125
64.30000,3.21500,18582.86113,0.00000,0.01229,231.79552
64.40000,3.21996,18606.00263,0.00000,0.01231,232.08417
64.50000,3.22505,18633.38500,0.00000,0.01234,232.42573
64.60000,3.22995,18657.02718,0.00000,0.01235,232.72064
64.70000,3.23509,18683.02375,0.00000,0.01238,233.04491
64.80000,3.23993,18706.13992,0.00000,0.01240,233.33325
64.90000,3.24501,18731.71180,0.00000,0.01242,233.65222
65.00000,3.24986,18755.92321,0.00000,0.01243,233.95423
65.10000,3.25506,18785.68232,0.00000,0.01246,234.32543
65.20000,3.25990,18808.65097,0.00000,0.01248,234.61193
65.30000,3.26504,18834.30332,0.00000,0.01250,234.93191
65.40000,3.26995,18859.42221,0.00000,0.01252,235.24523
65.50000,3.27509,18884.79292,0.00000,0.01254,235.56170
65.60000,3.27999,18908.71525,0.00000,0.01256,235.86010
65.70000,3.28501,18934.28713,0.00000,0.01258,236.17907
65.80000,3.28992,18959.48201,0.00000,0.01261,236.49334
65.90000,3.29506,18986.21470,0.00000,0.01263,236.82680
66.00000,3.29996,19010.04910,0.00000,0.01265,237.12410
66.10000,3.30504,19035.37661,0.00000,0.01267,237.44002
66.20000,3.30989,19060.91720,0.00000,0.01269,237.75861
66.30000,3.31503,19085.83492,0.00000,0.01271,238.06942
66.40000,3.31999,19110.95083,0.00000,0.01274,238.38271
66.50000,3.32507,19136.15912,0.00000,0.01276,238.69714
66.60000,3.33004,19160.90995,0.00000,0.01278,239.00588
66.70000,3.33500,19185.12881,0.00000,0.01280,239.30797
66.80000,3.33996,19211.61711,0.00000,0.01282,239.63838
66.90000,3.34492,19235.47834,0.00000,0.01284,239.93601
67.00000,3.35001,19263.03506,0.00000,0.01287,240.27975
67.10000,3.35491,19285.56412,0.00000,0.01288,240.56077
67.20000,3.35999,19312.69914,0.00000,0.01291,240.89924
67.30000,3.36483,19335.93750,0.00000,0.01293,241.18910
67.40000,3.37003,19364.00384,0.00000,0.01295,241.53919
67.50000,3.37488,19387.36737,0.00000,0.01297,241.83062
67.60000,3.38008,19413.71113,0.00000,0.01299,242.15922
67.70000,3.38492,19437.24304,0.00000,0.01301,242.45275
67.80000,3.39006,19462.02666,0.00000,0.01303,242.76189
67.90000,3.39491,19485.65990,0.00000,0.01305,243.05668
68.00000,3.40011,19509.89217,0.00000,0.01308,243.35895
68.10000,3.40489,19534.70409,0.00000,0.01310,243.66844
68.20000,3.40997,19559.15987,0.00000,0.01312,243.97349
68.30000,3.41488,19585.75249,0.00000,0.01314,244.30520
68.40000,3.42002,19610.85051,0.00000,0.01316,244.61826
68.50000,3.42492,19635.88893,0.00000,0.01318,244.93058
68.60000,3.43000,19660.13014,0.00000,0.01320,245.23296
68.70000,3.43497,19686.51116,0.00000,0.01323,245.56203
68.80000,3.43999,19709.13559,0.00000,0.01325,245.84423
68.90000,3.44501,19733.91175,0.00000,0.01327,246.15328
69.00000,3.44997,19755.96845,0.00000,0.01329,246.42841
69.10000,3.45494,19782.07380,0.00000,0.01331,246.75404
69.20000,3.45990,19806.58174,0.00000,0.01333,247.05974
69.30000,3.46498,19832.71539,0.00000,0.01335,247.38572
69.40000,3.46994,19856.35906,0.00000,0.01338,247.68064
69.50000,3.47508,19881.44368,0.00000,0.01340,247.99354
69.60000,3.47993,19905.38388,0.00000,0.01342,248.29216
69.70000,3.48507,19932.80649,0.00000,0.01345,248.63422
69.80000,3.48997,19955.31172,0.00000,0.01346,248.91494
69.90000,3.49517,19980.22944,0.00000,0.01348,249.22576
70.00000,3.49996,20005.06818,0.00000,0.01351,249.53558
70.10000,3.50504,20030.24518,0.00000,0.01353,249.84963
70.20000,3.50994,20054.67266,0.00000,0.01355,250.15433
70.30000,3.51508,20080.69158,0.00000,0.01357,250.47888
70.40000,3.51993,20102.84215,0.00000,0.01359,250.75518
70.50000,3.52501,20128.83574,0.00000,0.01361,251.07941
70.60000,3.52991,20153.47034,0.00000,0.01364,251.38670
70.70000,3.53499,20179.22997,0.00000,0.01366,251.70801
70.80000,3.53996,20204.42337,0.00000,0.01368,252.02227
70.90000,3.54510,20229.84922,0.00000,0.01370,252.33942
71.00000,3.54994,20254.22454,0.00000,0.01372,252.64347
71.10000,3.55502,20278.91874,0.00000,0.01374,252.95149
71.20000,3.55993,20303.92289,0.00000,0.01377,253.26338
71.30000,3.56507,20326.56670,0.00000,0.01379,253.54583
71.40000,3.56997,20351.81373,0.00000,0.01381,253.86076
71.50000,3.57499,20374.43668,0.00000,0.01383,254.14295
71.60000,3.57996,20401.07399,0.00000,0.01385,254.47521
71.70000,3.58492,20424.19612,0.00000,0.01387,254.76363
71.80000,3.59006,20451.98530,0.00000,0.01390,255.11026
71.90000,3.59490,20474.97779,0.00000,0.01392,255.39706
72.00000,3.59999,20501.10102,0.00000,0.01394,255.72291
72.10000,3.60483,20523.68373,0.00000,0.01396,256.00460
72.20000,3.61003,20550.58330,0.00000,0.01398,256.34013
72.30000,3.61487,20570.98001,0.00000,0.01401,256.59455
72.40000,3.62007,20596.88419,0.00000,0.01403,256.91767
72.50000,3.62486,20620.17024,0.00000,0.01405,257.20813
72.60000,3.63006,20646.23386,0.00000,0.01407,257.53324
72.70000,3.63490,20670.40354,0.00000,0.01409,257.83472
72.80000,3.64004,20695.09178,0.00000,0.01411,258.14268
72.90000,3.64489,20719.44475,0.00000,0.01413,258.44645
73.00000,3.65003,20745.18204,0.00000,0.01416,258.76748
73.10000,3.65493,20768.70054,0.00000,0.01418,259.06084
73.20000,3.66007,20792.80317,0.00000,0.01420,259.36149
73.30000,3.66504,20817.75665,0.00000,0.01422,259.67275
73.40000,3.67000,20841.71772,0.00000,0.01424,259.97163
73.50000,3.67502,20867.88416,0.00000,0.01427,260.29802
73.60000,3.68004,20889.71138,0.00000,0.01429,260.57029
73.70000,3.68507,20915.68857,0.00000,0.01431,260.89432
73.80000,3.68997,20938.08800,0.00000,0.01433,261.17372
73.90000,3.69499,20963.55706,0.00000,0.01436,261.49141
74.00000,3.69995,20985.87304,0.00000,0.01438,261.76977
74.10000,3.70509,21009.53907,0.00000,0.01440,262.06497
74.20000,3.71006,20998.24846,0.00000,0.01442,261.92414
74.20400,3.71024,20603.84154,0.00000,0.01436,257.00445
74.20600,3.71042,20044.56669,0.00000,0.01424,250.02827
74.20800,3.71066,19264.52368,0.00000,0.01406,240.29832
74.21000,3.71084,18336.25436,0.00000,0.01379,228.71944
74.21200,3.71119,17299.71021,0.00000,0.01343,215.78998
74.21400,3.71155,16180.62556,0.00000,0.01297,201.83095
74.21600,3.71185,15006.97732,0.00000,0.01244,187.19131
74.21800,3.71221,13803.14231,0.00000,0.01187,172.17513
74.22000,3.71257,12591.01331,0.00000,0.01127,157.05549