File: scratch/college-stuff/ME Lab/ME lab Fall 2013/group17/group17.is_tens_RawData/Specimen_RawData_2.csv
Time,Extension,Load,Strain 2,Tensile strain,Tensile stress
(sec),(mm),(N),(mm/mm),(mm/mm),(MPa)
0.00000,0.00000,-0.03477,0.00000,0.00000,-0.00043
0.30000,0.01357,31.18294,0.00000,0.00001,0.38896
0.60000,0.03001,66.31638,0.00000,0.00001,0.82721
0.90000,0.04490,94.54248,0.00000,0.00002,1.17929
1.20000,0.06009,137.25645,0.00000,0.00004,1.71208
1.50000,0.07492,178.53177,0.00000,0.00004,2.22694
1.80000,0.09004,215.30672,0.00000,0.00005,2.68565
2.10000,0.10499,254.21532,0.00000,0.00006,3.17098
2.40000,0.12000,301.87950,0.00000,0.00007,3.76553
2.70000,0.13500,358.45765,0.00000,0.00008,4.47126
3.00000,0.14995,421.48395,0.00000,0.00010,5.25743
3.30000,0.16508,498.28715,0.00000,0.00011,6.21544
3.60000,0.17991,585.94323,0.00000,0.00011,7.30883
3.90000,0.19503,690.70375,0.00000,0.00013,8.61557
4.20000,0.20992,814.50911,0.00000,0.00014,10.15988
4.50000,0.22505,963.65493,0.00000,0.00016,12.02026
4.80000,0.23994,1133.98889,0.00000,0.00018,14.14494
5.10000,0.25500,1316.80630,0.00000,0.00021,16.42534
5.40000,0.27007,1508.41195,0.00000,0.00024,18.81535
5.70000,0.28490,1703.04812,0.00000,0.00028,21.24317
6.00000,0.30002,1904.71075,0.00000,0.00031,23.75863
6.30000,0.31497,2105.44579,0.00000,0.00034,26.26253
6.60000,0.32998,2317.13075,0.00000,0.00038,28.90300
6.90000,0.34493,2534.51131,0.00000,0.00041,31.61453
7.20000,0.35993,2752.27651,0.00000,0.00044,34.33085
7.50000,0.37500,2976.65969,0.00000,0.00048,37.12972
7.80000,0.38995,3194.21850,0.00000,0.00052,39.84346
8.10000,0.40507,3419.08820,0.00000,0.00056,42.64840
8.40000,0.41990,3641.46717,0.00000,0.00059,45.42227
8.70000,0.43503,3866.45496,0.00000,0.00063,48.22868
9.00000,0.44992,4089.20571,0.00000,0.00067,51.00719
9.30000,0.46504,4311.29970,0.00000,0.00071,53.77751
9.60000,0.47999,4533.73045,0.00000,0.00075,56.55202
9.90000,0.49488,4753.18991,0.00000,0.00079,59.28948
10.20000,0.51006,4977.62896,0.00000,0.00082,62.08904
10.50000,0.52489,5191.17117,0.00000,0.00086,64.75269
10.80000,0.54002,5404.49545,0.00000,0.00088,67.41361
11.10000,0.55491,5613.01857,0.00000,0.00091,70.01465
11.40000,0.56997,5819.69805,0.00000,0.00094,72.59269
11.70000,0.58492,6020.98964,0.00000,0.00096,75.10353
12.00000,0.59993,6211.75505,0.00000,0.00098,77.48306
12.30000,0.61493,6408.82626,0.00000,0.00102,79.94125
12.60000,0.62994,6581.34148,0.00000,0.00105,82.09314
12.90000,0.64513,6750.01144,0.00000,0.00108,84.19707
13.20000,0.65990,6916.97299,0.00000,0.00111,86.27968
13.50000,0.67502,7089.12313,0.00000,0.00114,88.42702
13.80000,0.68997,7260.17579,0.00000,0.00117,90.56066
14.10000,0.70504,7432.93315,0.00000,0.00121,92.71557
14.40000,0.71999,7607.57029,0.00000,0.00124,94.89393
14.70000,0.73493,7776.95999,0.00000,0.00127,97.00683
15.00000,0.75006,7952.29301,0.00000,0.00130,99.19387
15.30000,0.76489,8122.24969,0.00000,0.00133,101.31384
15.60000,0.78001,8298.05583,0.00000,0.00136,103.50678
15.90000,0.79496,8466.86140,0.00000,0.00139,105.61240
16.20000,0.81003,8641.40466,0.00000,0.00142,107.78958
16.50000,0.82498,8809.52999,0.00000,0.00145,109.88671
16.80000,0.84004,8975.22941,0.00000,0.00149,111.95359
17.10000,0.85505,9140.98844,0.00000,0.00153,114.02120
17.40000,0.86994,9293.89670,0.00000,0.00155,115.92852
17.70000,0.88506,9442.56783,0.00000,0.00158,117.78299
18.00000,0.89989,9579.10195,0.00000,0.00160,119.48606
18.30000,0.91508,9722.56064,0.00000,0.00162,121.27551
18.60000,0.92991,9864.36754,0.00000,0.00165,123.04436
18.90000,0.94497,10006.65426,0.00000,0.00168,124.81919
19.20000,0.95992,10151.32815,0.00000,0.00170,126.62379
19.50000,0.97493,10292.78859,0.00000,0.00173,128.38832
19.80000,0.99005,10439.93980,0.00000,0.00175,130.22382
20.10000,1.00488,10581.46134,0.00000,0.00178,131.98911
20.40000,1.02001,10728.87480,0.00000,0.00181,133.82789
20.70000,1.03496,10873.77518,0.00000,0.00183,135.63532
21.00000,1.05002,11020.26626,0.00000,0.00186,137.46259
21.30000,1.06497,11165.70309,0.00000,0.00188,139.27672
21.60000,1.08004,11307.96671,0.00000,0.00191,141.05126
21.90000,1.09504,11456.28467,0.00000,0.00193,142.90132
22.20000,1.10987,11597.40090,0.00000,0.00196,144.66155
22.50000,1.12512,11748.07325,0.00000,0.00199,146.54098
22.80000,1.13989,11894.28344,0.00000,0.00202,148.36475
23.10000,1.15507,12041.68350,0.00000,0.00204,150.20336
23.40000,1.16996,12189.35475,0.00000,0.00207,152.04536
23.70000,1.18503,12336.10883,0.00000,0.00210,153.87591
24.00000,1.20003,12487.93229,0.00000,0.00213,155.76970
24.30000,1.21492,12631.12426,0.00000,0.00216,157.55582
24.60000,1.23005,12783.08332,0.00000,0.00219,159.45130
24.90000,1.24494,12929.86125,0.00000,0.00221,161.28215
25.20000,1.26000,13079.25284,0.00000,0.00224,163.14561
25.50000,1.27495,13226.06653,0.00000,0.00227,164.97691
25.80000,1.29002,13376.31345,0.00000,0.00230,166.85103
26.10000,1.30497,13527.19218,0.00000,0.00233,168.73303
26.40000,1.32009,13673.81811,0.00000,0.00236,170.56199
26.70000,1.33504,13826.62803,0.00000,0.00239,172.46808
27.00000,1.34993,13974.75749,0.00000,0.00242,174.31579
27.30000,1.36511,14127.29323,0.00000,0.00245,176.21846
27.60000,1.37988,14276.41362,0.00000,0.00247,178.07853
27.90000,1.39501,14425.88866,0.00000,0.00250,179.94303
28.20000,1.40996,14580.46287,0.00000,0.00254,181.87113
28.50000,1.42496,14728.95592,0.00000,0.00256,183.72337
28.80000,1.43997,14881.88505,0.00000,0.00259,185.63095
29.10000,1.45492,15030.89517,0.00000,0.00262,187.48965
29.40000,1.47004,15186.93715,0.00000,0.00265,189.43606
29.70000,1.48493,15336.55524,0.00000,0.00268,191.30234
30.00000,1.50000,15486.90647,0.00000,0.00271,193.17776
30.30000,1.51495,15638.63754,0.00000,0.00274,195.07040
30.60000,1.53001,15789.31808,0.00000,0.00277,196.94993
30.90000,1.54490,15942.61229,0.00000,0.00280,198.86206
31.20000,1.55997,16091.09044,0.00000,0.00283,200.71412
31.50000,1.57503,16249.51065,0.00000,0.00286,202.69019
31.80000,1.58986,16396.02631,0.00000,0.00289,204.51777
32.10000,1.60511,16551.98485,0.00000,0.00292,206.46314
32.40000,1.61994,16701.75791,0.00000,0.00296,208.33135
32.70000,1.63500,16853.70505,0.00000,0.00299,210.22668
33.00000,1.64995,17007.35539,0.00000,0.00302,212.14326
33.30000,1.66496,17156.74102,0.00000,0.00305,214.00664
33.60000,1.68003,17310.15444,0.00000,0.00308,215.92026
33.90000,1.69491,17459.03641,0.00000,0.00312,217.77736
34.20000,1.70998,17610.96418,0.00000,0.00315,219.67245
34.50000,1.72493,17757.35915,0.00000,0.00318,221.49852
34.80000,1.74005,17912.43851,0.00000,0.00322,223.43292
35.10000,1.75494,18059.17323,0.00000,0.00325,225.26323
35.40000,1.77001,18209.01483,0.00000,0.00329,227.13230
35.70000,1.78502,18359.41672,0.00000,0.00332,229.00836
36.00000,1.80002,18503.50201,0.00000,0.00336,230.80562
36.30000,1.81503,18657.51743,0.00000,0.00340,232.72675
36.60000,1.82980,18799.78478,0.00000,0.00343,234.50134
36.90000,1.84510,18951.09862,0.00000,0.00348,236.38877
37.20000,1.85981,19093.22143,0.00000,0.00351,238.16156
37.50000,1.87500,19237.08618,0.00000,0.00355,239.95607
37.80000,1.88995,19379.58747,0.00000,0.00359,241.73358
38.10000,1.90489,19520.51371,0.00000,0.00363,243.49144
38.40000,1.92002,19662.21482,0.00000,0.00367,245.25896
38.70000,1.93497,19801.55557,0.00000,0.00370,246.99705
39.00000,1.95009,19939.20654,0.00000,0.00375,248.71405
39.30000,1.96498,20070.92685,0.00000,0.00379,250.35708
39.60000,1.98005,20206.80159,0.00000,0.00384,252.05193
39.90000,1.99494,20336.32398,0.00000,0.00388,253.66754
40.20000,2.01006,20467.36330,0.00000,0.00393,255.30208
40.50000,2.02495,20594.67733,0.00000,0.00397,256.89014
40.80000,2.03996,20715.06828,0.00000,0.00402,258.39185
41.10000,2.05508,20838.78070,0.00000,0.00407,259.93500
41.40000,2.06991,20954.88757,0.00000,0.00412,261.38327
41.70000,2.08510,21070.97954,0.00000,0.00418,262.83136
42.00000,2.09987,21182.83808,0.00000,0.00423,264.22664
42.30000,2.11499,21289.11614,0.00000,0.00429,265.55231
42.60000,2.13000,21392.69561,0.00000,0.00435,266.84432
42.90000,2.14495,21487.31947,0.00000,0.00441,268.02462
43.20000,2.16001,21585.13516,0.00000,0.00448,269.24474
43.50000,2.17496,21671.63193,0.00000,0.00455,270.32366
43.80000,2.19003,21760.54567,0.00000,0.00462,271.43274
44.10000,2.20498,21837.46248,0.00000,0.00469,272.39217
44.40000,2.22004,21916.57126,0.00000,0.00477,273.37894
44.70000,2.23493,21985.54128,0.00000,0.00486,274.23925
45.00000,2.25006,22051.52214,0.00000,0.00495,275.06227
45.30000,2.26495,22113.97439,0.00000,0.00505,275.84128
45.60000,2.28001,22166.79305,0.00000,0.00515,276.50012
45.90000,2.29508,22222.03910,0.00000,0.00526,277.18923
46.20000,2.30985,22265.50430,0.00000,0.00538,277.73140
46.50000,2.32503,22310.64141,0.00000,0.00550,278.29442
46.80000,2.33992,22352.36019,0.00000,0.00562,278.81481
47.10000,2.35493,22388.63558,0.00000,0.00574,279.26729
47.40000,2.37000,22425.70519,0.00000,0.00587,279.72969
47.70000,2.38500,22456.78455,0.00000,0.00600,280.11736
48.00000,2.40007,22488.45100,0.00000,0.00614,280.51235
48.30000,2.41502,22513.94540,0.00000,0.00628,280.83036
48.60000,2.43008,22543.64192,0.00000,0.00643,281.20078
48.90000,2.44497,22565.78654,0.00000,0.00658,281.47701
49.20000,2.46004,22592.19736,0.00000,0.00673,281.80645
49.50000,2.47493,22611.43774,0.00000,0.00688,282.04644
49.80000,2.49005,22632.29489,0.00000,0.00703,282.30661
50.10000,2.50500,22653.32788,0.00000,0.00718,282.56897
50.40000,2.51995,22667.30666,0.00000,0.00734,282.74333
50.70000,2.53507,22689.74185,0.00000,0.00750,283.02318
51.00000,2.54984,22702.47489,0.00000,0.00766,283.18201
51.30000,2.56509,22717.40884,0.00000,0.00782,283.36829
51.60000,2.57998,22733.69282,0.00000,0.00799,283.57141
51.90000,2.59498,22747.22606,0.00000,0.00815,283.74022
52.20000,2.61011,22763.35806,0.00000,0.00832,283.94144
52.50000,2.62500,22774.54734,0.00000,0.00848,284.08101
52.80000,2.64000,22787.99564,0.00000,0.00865,284.24876
53.10000,2.65501,22798.78855,0.00000,0.00882,284.38339
53.40000,2.67008,22813.85660,0.00000,0.00898,284.57134
53.70000,2.68497,22821.24907,0.00000,0.00915,284.66355
54.00000,2.70009,22834.71227,0.00000,0.00931,284.83148
54.30000,2.71492,22845.50220,0.00000,0.00948,284.96607
54.60000,2.73011,22855.87788,0.00000,0.00966,285.09550
54.90000,2.74500,22868.35462,0.00000,0.00982,285.25113
55.20000,2.75988,22873.92020,0.00000,0.00999,285.32055
55.50000,2.77513,22887.36701,0.00000,0.01016,285.48828
55.80000,2.78984,22892.61818,0.00000,0.01033,285.55378
56.10000,2.80502,22904.15764,0.00000,0.01050,285.69772
56.40000,2.81997,22913.39338,0.00000,0.01067,285.81292
56.70000,2.83498,22922.58739,0.00000,0.01084,285.92761
57.00000,2.84999,22931.10043,0.00000,0.01101,286.03379
57.30000,2.86499,22939.58068,0.00000,0.01118,286.13957
57.60000,2.88000,22949.84758,0.00000,0.01136,286.26764
57.90000,2.89501,22955.92278,0.00000,0.01153,286.34342
58.20000,2.91007,22968.37717,0.00000,0.01170,286.49877
58.50000,2.92490,22972.42880,0.00000,0.01188,286.54931
58.80000,2.94009,22983.80733,0.00000,0.01205,286.69124
59.10000,2.95498,22990.53073,0.00000,0.01222,286.77510
59.40000,2.96998,22995.29761,0.00000,0.01239,286.83457
59.70000,2.98493,23007.38245,0.00000,0.01256,286.98531
60.00000,2.99994,23012.57700,0.00000,0.01274,287.05010
60.30000,3.01512,23023.19258,0.00000,0.01291,287.18252
60.60000,3.02989,23028.38564,0.00000,0.01308,287.24729
60.90000,3.04502,23037.26375,0.00000,0.01325,287.35803
61.20000,3.06003,23044.58469,0.00000,0.01343,287.44935
61.50000,3.07503,23053.98881,0.00000,0.01360,287.56666
61.80000,3.08998,23061.05793,0.00000,0.01378,287.65483
62.10000,3.10505,23068.54874,0.00000,0.01394,287.74827
62.40000,3.11999,23075.23042,0.00000,0.01411,287.83162
62.70000,3.13494,23080.02710,0.00000,0.01428,287.89145
63.00000,3.15007,23092.94492,0.00000,0.01445,288.05258
63.30000,3.16490,23095.02363,0.00000,0.01463,288.07851
63.60000,3.18008,23106.28146,0.00000,0.01480,288.21894
63.90000,3.19491,23109.95162,0.00000,0.01497,288.26472
64.20000,3.20998,23116.47087,0.00000,0.01514,288.34603
64.50000,3.22505,23127.18779,0.00000,0.01530,288.47971
64.80000,3.23993,23129.73738,0.00000,0.01547,288.51152
65.10000,3.25512,23140.82980,0.00000,0.01565,288.64988
65.40000,3.26995,23146.34621,0.00000,0.01582,288.71869
65.70000,3.28507,23153.81318,0.00000,0.01599,288.81183
66.00000,3.29996,23160.16853,0.00000,0.01615,288.89110
66.30000,3.31503,23168.88869,0.00000,0.01632,288.99987
66.60000,3.33004,23176.38844,0.00000,0.01649,289.09342
66.90000,3.34498,23182.39361,0.00000,0.01666,289.16833
67.20000,3.35999,23191.36113,0.00000,0.01683,289.28019
67.50000,3.37494,23196.34408,0.00000,0.01699,289.34234
67.80000,3.39006,23204.29236,0.00000,0.01716,289.44149
68.10000,3.40489,23208.80890,0.00000,0.01732,289.49782
68.40000,3.42002,23217.49181,0.00000,0.01749,289.60613
68.70000,3.43497,23225.63976,0.00000,0.01766,289.70777
69.00000,3.44997,23228.09398,0.00000,0.01783,289.73838
69.30000,3.46504,23238.17462,0.00000,0.01799,289.86412
69.60000,3.47993,23241.90438,0.00000,0.01815,289.91064
69.90000,3.49517,23251.60950,0.00000,0.01832,290.03170
70.20000,3.50994,23257.69067,0.00000,0.01848,290.10756
70.50000,3.52501,23265.21277,0.00000,0.01865,290.20138
70.80000,3.54002,23272.31169,0.00000,0.01881,290.28993
71.10000,3.55502,23278.99188,0.00000,0.01898,290.37326
71.40000,3.56997,23284.58875,0.00000,0.01915,290.44307
71.70000,3.58492,23288.62399,0.00000,0.01931,290.49341
72.00000,3.59999,23298.09070,0.00000,0.01947,290.61149
72.30000,3.61487,23300.58217,0.00000,0.01963,290.64257
72.60000,3.63006,23311.73122,0.00000,0.01980,290.78164
72.90000,3.64489,23315.08398,0.00000,0.01996,290.82346
73.20000,3.66007,23322.84451,0.00000,0.02012,290.92026
73.50000,3.67502,23330.36661,0.00000,0.02029,291.01409
73.80000,3.68997,23333.78643,0.00000,0.02045,291.05675
74.10000,3.70509,23345.30354,0.00000,0.02061,291.20041
74.40000,3.71992,23349.17635,0.00000,0.02078,291.24871
74.70000,3.73517,23357.43159,0.00000,0.02094,291.35169
75.00000,3.74994,23361.73803,0.00000,0.02110,291.40540
75.30000,3.76506,23368.97254,0.00000,0.02126,291.49564
75.60000,3.77995,23374.38166,0.00000,0.02142,291.56311
75.90000,3.79496,23381.80989,0.00000,0.02158,291.65577
76.20000,3.80997,23388.32021,0.00000,0.02174,291.73698
76.50000,3.82503,23395.59495,0.00000,0.02191,291.82772
76.80000,3.84004,23402.83990,0.00000,0.02207,291.91809
77.10000,3.85499,23406.04812,0.00000,0.02223,291.95811
77.40000,3.87005,23415.00074,0.00000,0.02239,292.06978
77.70000,3.88488,23419.66182,0.00000,0.02254,292.12792
78.00000,3.90007,23426.68027,0.00000,0.02270,292.21547
78.30000,3.91496,23434.66133,0.00000,0.02286,292.31502
78.60000,3.93002,23437.78461,0.00000,0.02302,292.35398
78.90000,3.94509,23447.46739,0.00000,0.02318,292.47476
79.20000,3.95992,23451.98840,0.00000,0.02334,292.53115
79.50000,3.97516,23460.80542,0.00000,0.02350,292.64113
79.80000,3.98999,23464.06579,0.00000,0.02365,292.68180
80.10000,4.00506,23471.29434,0.00000,0.02381,292.77197
80.40000,4.02001,23477.89705,0.00000,0.02398,292.85433
80.70000,4.03507,23482.95301,0.00000,0.02414,292.91739
81.00000,4.05002,23490.70609,0.00000,0.02429,293.01410
81.30000,4.06497,23493.95156,0.00000,0.02444,293.05458
81.60000,4.07998,23502.70152,0.00000,0.02460,293.16373
81.90000,4.09498,23506.29270,0.00000,0.02476,293.20852
82.20000,4.11005,23513.43781,0.00000,0.02491,293.29765
82.50000,4.12488,23518.68749,0.00000,0.02507,293.36313
82.80000,4.14006,23526.07399,0.00000,0.02523,293.45527
83.10000,4.15501,23534.28751,0.00000,0.02538,293.55772
83.40000,4.17002,23537.17089,0.00000,0.02553,293.59369
83.70000,4.18508,23545.32927,0.00000,0.02569,293.69545
84.00000,4.19991,23548.69843,0.00000,0.02585,293.73748
84.30000,4.21510,23556.26225,0.00000,0.02601,293.83182
84.60000,4.22987,23560.26322,0.00000,0.02616,293.88173
84.90000,4.24499,23569.10408,0.00000,0.02632,293.99201
85.20000,4.26000,23573.34942,0.00000,0.02647,294.04496
85.50000,4.27501,23577.83169,0.00000,0.02662,294.10087
85.80000,4.28996,23584.39416,0.00000,0.02678,294.18273
86.10000,4.30496,23589.66172,0.00000,0.02693,294.24844
86.40000,4.32009,23599.80047,0.00000,0.02709,294.37490
86.70000,4.33498,23602.74941,0.00000,0.02725,294.41169
87.00000,4.35004,23609.70974,0.00000,0.02740,294.49851
87.30000,4.36493,23614.39317,0.00000,0.02755,294.55693
87.60000,4.38012,23621.26410,0.00000,0.02771,294.64263
87.90000,4.39495,23626.37222,0.00000,0.02786,294.70635
88.20000,4.40995,23630.34040,0.00000,0.02802,294.75585
88.50000,4.42508,23640.80399,0.00000,0.02818,294.88637
88.80000,4.43991,23642.20023,0.00000,0.02834,294.90378
89.10000,4.45509,23650.18725,0.00000,0.02849,295.00341
89.40000,4.46998,23653.86933,0.00000,0.02864,295.04934
89.70000,4.48499,23660.50333,0.00000,0.02879,295.13209
90.00000,4.49994,23666.58002,0.00000,0.02894,295.20789
90.30000,4.51494,23671.12041,0.00000,0.02910,295.26452
90.60000,4.53001,23677.29992,0.00000,0.02925,295.34160
90.90000,4.54496,23681.48565,0.00000,0.02940,295.39381
91.20000,4.55996,23688.44301,0.00000,0.02954,295.48060
91.50000,4.57491,23693.44980,0.00000,0.02969,295.54305
91.80000,4.59010,23702.02839,0.00000,0.02985,295.65006
92.10000,4.60493,23706.21562,0.00000,0.03000,295.70228
92.40000,4.62017,23711.80058,0.00000,0.03016,295.77195
92.70000,4.63500,23717.51815,0.00000,0.03031,295.84327
93.00000,4.64995,23719.43891,0.00000,0.03046,295.86723
93.30000,4.66507,23729.64472,0.00000,0.03061,295.99453
93.60000,4.67984,23731.71300,0.00000,0.03075,296.02033
93.90000,4.69503,23739.47054,0.00000,0.03090,296.11709
94.20000,4.70992,23743.73227,0.00000,0.03105,296.17025
94.50000,4.72492,23748.23391,0.00000,0.03120,296.22641
94.80000,4.73993,23752.92033,0.00000,0.03136,296.28486
95.10000,4.75494,23759.42320,0.00000,0.03151,296.36598
95.40000,4.77001,23766.53403,0.00000,0.03165,296.45467
95.70000,4.78501,23769.59920,0.00000,0.03180,296.49291
96.00000,4.80008,23777.95279,0.00000,0.03195,296.59711
96.30000,4.81497,23780.32058,0.00000,0.03210,296.62664
96.60000,4.83009,23787.31221,0.00000,0.03225,296.71385
96.90000,4.84492,23791.73189,0.00000,0.03240,296.76898
97.20000,4.86011,23798.20496,0.00000,0.03255,296.84972
97.50000,4.87494,23802.38771,0.00000,0.03269,296.90190
97.80000,4.88988,23804.70186,0.00000,0.03284,296.93076
98.10000,4.90507,23812.38043,0.00000,0.03299,297.02654
98.40000,4.91990,23817.36785,0.00000,0.03314,297.08876
98.70000,4.93502,23823.30149,0.00000,0.03329,297.16277
99.00000,4.94991,23827.61091,0.00000,0.03344,297.21652
99.30000,4.96498,23834.27024,0.00000,0.03358,297.29959
99.60000,4.97999,23838.06109,0.00000,0.03373,297.34688
99.90000,4.99499,23842.34518,0.00000,0.03387,297.40031
100.20000,5.01006,23848.60367,0.00000,0.03401,297.47838
100.50000,5.02507,23852.49883,0.00000,0.03416,297.52697
100.80000,5.04007,23859.79146,0.00000,0.03431,297.61793
101.10000,5.05490,23860.13269,0.00000,0.03446,297.62219
101.40000,5.07009,23869.64858,0.00000,0.03461,297.74089
101.70000,5.08492,23872.49470,0.00000,0.03475,297.77639
102.00000,5.10004,23876.11121,0.00000,0.03489,297.82150
102.30000,5.11499,23883.37553,0.00000,0.03504,297.91211
102.60000,5.12994,23885.24264,0.00000,0.03518,297.93540
102.90000,5.14512,23892.73345,0.00000,0.03533,298.02884
103.20000,5.15989,23894.46646,0.00000,0.03547,298.05045
103.50000,5.17502,23898.49126,0.00000,0.03561,298.10066
103.80000,5.18997,23904.72442,0.00000,0.03576,298.17841
104.10000,5.20497,23909.54047,0.00000,0.03590,298.23848
104.40000,5.22004,23915.35044,0.00000,0.03604,298.31095
104.70000,5.23505,23920.19778,0.00000,0.03618,298.37142
105.00000,5.25006,23925.95708,0.00000,0.03633,298.44326
105.30001,5.26506,23926.29683,0.00000,0.03647,298.44749
105.60001,5.28007,23935.00507,0.00000,0.03661,298.55612
105.90001,5.29490,23935.91404,0.00000,0.03675,298.56746
106.20001,5.31008,23943.81315,0.00000,0.03689,298.66599
106.50001,5.32491,23946.40893,0.00000,0.03703,298.69836
106.80001,5.33998,23947.80368,0.00000,0.03717,298.71576
107.10001,5.35505,23956.50446,0.00000,0.03731,298.82429
107.40001,5.36993,23957.44920,0.00000,0.03745,298.83608
107.70001,5.38512,23965.37066,0.00000,0.03760,298.93489
108.00001,5.39989,23967.96346,0.00000,0.03773,298.96723
108.30001,5.41502,23973.32489,0.00000,0.03787,299.03410
108.60001,5.43002,23978.60289,0.00000,0.03801,299.09994
108.90001,5.44497,23983.26695,0.00000,0.03815,299.15812
109.20001,5.46004,23988.72674,0.00000,0.03829,299.22622
109.50001,5.47504,23991.14817,0.00000,0.03843,299.25642
109.80001,5.48999,23998.11000,0.00000,0.03857,299.34326
110.10001,5.50500,24000.05460,0.00000,0.03871,299.36752
110.40001,5.52012,24007.84940,0.00000,0.03884,299.46475
110.70001,5.53495,24007.45451,0.00000,0.03898,299.45982
111.00001,5.55014,24013.70406,0.00000,0.03912,299.53778
111.30001,5.56491,24017.04788,0.00000,0.03925,299.57949
111.60001,5.58003,24020.92665,0.00000,0.03939,299.62787
111.90001,5.59504,24027.41909,0.00000,0.03953,299.70885
112.20001,5.60993,24027.95553,0.00000,0.03967,299.71555
112.50001,5.62517,24036.16309,0.00000,0.03980,299.81792
112.80001,5.63994,24037.25088,0.00000,0.03993,299.83149
113.10001,5.65501,24043.08617,0.00000,0.04007,299.90428
113.40001,5.66996,24048.05273,0.00000,0.04021,299.96623
113.70001,5.68496,24052.60652,0.00000,0.04034,300.02303
114.00001,5.69997,24055.12333,0.00000,0.04048,300.05443
114.30001,5.71504,24059.16303,0.00000,0.04062,300.10482
114.60001,5.73005,24065.82385,0.00000,0.04075,300.18790
114.90001,5.74499,24066.37669,0.00000,0.04089,300.19480
115.20001,5.76006,24074.41884,0.00000,0.04102,300.29511
115.50001,5.77489,24075.32632,0.00000,0.04116,300.30643
115.80001,5.79013,24080.48362,0.00000,0.04129,300.37076
116.10001,5.80490,24082.53700,0.00000,0.04143,300.39637
116.40001,5.81997,24083.73207,0.00000,0.04156,300.41128
116.70001,5.83498,24091.39425,0.00000,0.04170,300.50686
117.00001,5.84986,24094.25676,0.00000,0.04182,300.54256
117.30001,5.86511,24099.68227,0.00000,0.04196,300.61024
117.60001,5.87988,24102.63717,0.00000,0.04209,300.64710
117.90001,5.89500,24108.19978,0.00000,0.04222,300.71648
118.20001,5.91001,24111.30220,0.00000,0.04236,300.75518
118.50001,5.92502,24117.25372,0.00000,0.04250,300.82942
118.80001,5.93991,24119.03441,0.00000,0.04263,300.85163
119.10001,5.95503,24122.63602,0.00000,0.04279,300.89655
119.40001,5.96998,24126.61016,0.00000,0.04291,300.94613
119.70001,5.98493,24126.92159,0.00000,0.04304,300.95001
120.00001,6.00006,24135.10978,0.00000,0.04318,301.05215
120.30001,6.01488,24136.00087,0.00000,0.04330,301.06326
120.60001,6.03007,24141.26843,0.00000,0.04344,301.12897
120.90001,6.04490,24145.13379,0.00000,0.04358,301.17718
121.20001,6.05996,24147.04859,0.00000,0.04371,301.20107
121.50001,6.07509,24153.35178,0.00000,0.04384,301.27969
121.80001,6.08992,24154.82402,0.00000,0.04397,301.29805
122.10001,6.10510,24160.93349,0.00000,0.04411,301.37426
122.40001,6.11993,24162.27907,0.00000,0.04424,301.39105
122.70001,6.13500,24167.60623,0.00000,0.04437,301.45750
123.00001,6.15001,24167.70756,0.00000,0.04450,301.45876
123.30001,6.16507,24174.20149,0.00000,0.04464,301.53976
123.60001,6.17996,24175.99708,0.00000,0.04477,301.56216
123.90001,6.19503,24180.36610,0.00000,0.04490,301.61666
124.20001,6.21004,24185.22239,0.00000,0.04503,301.67723
124.50001,6.22492,24185.35948,0.00000,0.04516,301.67894
124.80001,6.24011,24192.06351,0.00000,0.04530,301.76257
125.10001,6.25488,24192.26617,0.00000,0.04543,301.76509
125.40001,6.27006,24196.65307,0.00000,0.04556,301.81981
125.70001,6.28495,24201.29329,0.00000,0.04569,301.87769
126.00001,6.29996,24202.12477,0.00000,0.04582,301.88807
126.30001,6.31509,24209.38313,0.00000,0.04595,301.97860
126.60001,6.32991,24210.86729,0.00000,0.04608,301.99712
126.90001,6.34516,24216.44181,0.00000,0.04620,302.06665
127.20001,6.35993,24216.35836,0.00000,0.04633,302.06561
127.50001,6.37499,24222.33820,0.00000,0.04646,302.14020
127.80001,6.39000,24225.32141,0.00000,0.04659,302.17741
128.10001,6.40501,24228.56241,0.00000,0.04673,302.21784
128.40001,6.41990,24231.93157,0.00000,0.04686,302.25986
128.70001,6.43502,24232.63639,0.00000,0.04699,302.26866
129.00001,6.45003,24239.54308,0.00000,0.04712,302.35481
129.30001,6.46486,24239.03793,0.00000,0.04725,302.34851
129.60001,6.48004,24246.58686,0.00000,0.04737,302.44267
129.90001,6.49487,24247.93392,0.00000,0.04750,302.45947
130.20001,6.51012,24252.14052,0.00000,0.04763,302.51194
130.50001,6.52501,24257.04598,0.00000,0.04776,302.57313
130.80001,6.54001,24257.80296,0.00000,0.04789,302.58257
131.10001,6.55514,24263.70233,0.00000,0.04802,302.65616
131.40001,6.56997,24265.20884,0.00000,0.04815,302.67495
131.70001,6.58509,24269.00715,0.00000,0.04827,302.72233
132.00001,6.59998,24269.72836,0.00000,0.04841,302.73133
132.30001,6.61505,24274.54889,0.00000,0.04853,302.79146
132.60001,6.62994,24274.94973,0.00000,0.04866,302.79646
132.90001,6.64500,24280.29180,0.00000,0.04879,302.86309
133.20001,6.65995,24285.02738,0.00000,0.04892,302.92216
133.50001,6.67502,24284.19441,0.00000,0.04904,302.91177
133.80001,6.69009,24291.51535,0.00000,0.04917,303.00309
134.10001,6.70485,24289.41578,0.00000,0.04929,302.97690
134.40001,6.72010,24297.67996,0.00000,0.04942,303.07999
134.70001,6.73487,24300.00752,0.00000,0.04955,303.10902
135.00001,6.75005,24303.01309,0.00000,0.04968,303.14651
135.30001,6.76500,24307.03491,0.00000,0.04982,303.19668
135.60001,6.78001,24306.00077,0.00000,0.04995,303.18378
135.90001,6.79514,24312.16687,0.00000,0.05007,303.26069
136.20001,6.80990,24312.31737,0.00000,0.05019,303.26257
136.50001,6.82509,24318.18247,0.00000,0.05032,303.33573
136.80001,6.83998,24319.18234,0.00000,0.05044,303.34820
137.10001,6.85504,24323.61245,0.00000,0.05057,303.40346
137.40001,6.86993,24324.40072,0.00000,0.05070,303.41329
137.70001,6.88506,24328.54176,0.00000,0.05083,303.46494
138.00001,6.89995,24331.60394,0.00000,0.05095,303.50314
138.30001,6.91495,24333.94492,0.00000,0.05108,303.53234
138.60001,6.93002,24340.31069,0.00000,0.05121,303.61174
138.90001,6.94491,24339.71167,0.00000,0.05134,303.60427
139.20001,6.96009,24345.71981,0.00000,0.05147,303.67922
139.50001,6.97492,24347.48560,0.00000,0.05159,303.70124
139.80001,6.99005,24350.01880,0.00000,0.05172,303.73284
140.10001,7.00506,24354.16728,0.00000,0.05185,303.78459
140.40001,7.02000,24355.31169,0.00000,0.05198,303.79886
140.70001,7.03507,24360.14414,0.00000,0.05210,303.85914
141.00001,7.04996,24359.36034,0.00000,0.05223,303.84936
141.30001,7.06509,24364.52061,0.00000,0.05236,303.91373
141.60001,7.07997,24366.19550,0.00000,0.05249,303.93462
141.90001,7.09498,24370.71204,0.00000,0.05261,303.99096
142.20001,7.10999,24372.42270,0.00000,0.05274,304.01230
142.50001,7.12499,24374.49098,0.00000,0.05287,304.03810
142.80001,7.13994,24379.62741,0.00000,0.05300,304.10217
143.10001,7.15495,24379.49479,0.00000,0.05313,304.10051
143.40001,7.17008,24385.85013,0.00000,0.05326,304.17979
143.70001,7.18484,24386.49982,0.00000,0.05338,304.18789
144.00001,7.20003,24392.79258,0.00000,0.05351,304.26638
144.30001,7.21492,24394.79381,0.00000,0.05364,304.29135
144.60001,7.23004,24396.25561,0.00000,0.05377,304.30958
144.90001,7.24499,24398.66513,0.00000,0.05390,304.33964
145.20001,7.26000,24398.90355,0.00000,0.05404,304.34261
145.50001,7.27507,24403.39327,0.00000,0.05416,304.39861
145.80001,7.28989,24405.98160,0.00000,0.05429,304.43090
146.10001,7.30502,24410.11220,0.00000,0.05442,304.48242
146.40001,7.31997,24409.51467,0.00000,0.05455,304.47497
146.70001,7.33503,24414.88653,0.00000,0.05468,304.54198
147.00001,7.34992,24416.00263,0.00000,0.05481,304.55590
147.30001,7.36499,24419.38370,0.00000,0.05494,304.59807
147.60001,7.38000,24424.02989,0.00000,0.05508,304.65603
147.90001,7.39500,24422.89293,0.00000,0.05521,304.64184
148.20001,7.41007,24427.62554,0.00000,0.05534,304.70088
148.50001,7.42490,24426.13691,0.00000,0.05546,304.68231
148.80001,7.44014,24434.45027,0.00000,0.05560,304.78601
149.10001,7.45497,24434.55905,0.00000,0.05573,304.78736
149.40001,7.47004,24437.79111,0.00000,0.05585,304.82768
149.70001,7.48505,24440.32431,0.00000,0.05599,304.85928
150.00001,7.49999,24440.82052,0.00000,0.05613,304.86547
150.30001,7.51506,24444.27013,0.00000,0.05625,304.90850
150.60001,7.52989,24444.31931,0.00000,0.05639,304.90911
150.90001,7.54502,24449.84615,0.00000,0.05652,304.97805
151.20001,7.55996,24450.93840,0.00000,0.05665,304.99167
151.50001,7.57497,24452.55965,0.00000,0.05678,305.01190
151.80001,7.58992,24455.59353,0.00000,0.05691,305.04974
152.10001,7.60504,24458.91500,0.00000,0.05704,305.09117
152.40001,7.61999,24463.10222,0.00000,0.05717,305.14340
152.70001,7.63500,24462.85635,0.00000,0.05730,305.14033
153.00001,7.65013,24468.66930,0.00000,0.05743,305.21284
153.30001,7.66489,24467.21941,0.00000,0.05757,305.19476
153.60001,7.68020,24473.02639,0.00000,0.05770,305.26719
153.90001,7.69491,24472.86099,0.00000,0.05783,305.26513
154.20001,7.71003,24475.29137,0.00000,0.05796,305.29544
154.50001,7.72498,24478.85275,0.00000,0.05811,305.33987
154.80001,7.73993,24477.89907,0.00000,0.05823,305.32797
155.10001,7.75506,24482.38134,0.00000,0.05836,305.38388
155.40001,7.76994,24482.23680,0.00000,0.05849,305.38208
155.70001,7.78501,24487.38217,0.00000,0.05862,305.44626
156.00001,7.79996,24488.64281,0.00000,0.05875,305.46198
156.30001,7.81502,24492.64675,0.00000,0.05888,305.51193
156.60001,7.82997,24494.99816,0.00000,0.05903,305.54126
156.90001,7.84504,24494.64947,0.00000,0.05915,305.53691
157.20001,7.86005,24499.73971,0.00000,0.05929,305.60040
157.50001,7.87505,24497.81299,0.00000,0.05943,305.57637
157.80001,7.89012,24503.99101,0.00000,0.05956,305.65343
158.10001,7.90489,24502.27290,0.00000,0.05968,305.63200
158.40001,7.92013,24506.66577,0.00000,0.05982,305.68679
158.70001,7.93496,24509.29582,0.00000,0.05995,305.71960
159.00001,7.95003,24508.02475,0.00000,0.06008,305.70375
159.30001,7.96504,24512.55918,0.00000,0.06022,305.76031
159.60001,7.97992,24511.76196,0.00000,0.06035,305.75036
159.90001,7.99505,24516.79707,0.00000,0.06048,305.81317
160.20001,8.00988,24516.02370,0.00000,0.06061,305.80352
160.50001,8.02501,24520.59984,0.00000,0.06074,305.86060
160.80001,8.04001,24521.48348,0.00000,0.06088,305.87163
161.10001,8.05502,24524.31470,0.00000,0.06101,305.90694
161.40001,8.06997,24525.12980,0.00000,0.06115,305.91711
161.70001,8.08503,24527.69130,0.00000,0.06128,305.94906
162.00001,8.10004,24531.33613,0.00000,0.06141,305.99452
162.30001,8.11499,24529.96373,0.00000,0.06154,305.97740
162.60001,8.13011,24533.54597,0.00000,0.06167,306.02209
162.90001,8.14488,24531.60733,0.00000,0.06180,305.99791
163.20001,8.16013,24536.74078,0.00000,0.06193,306.06194
163.50001,8.17490,24537.02986,0.00000,0.06207,306.06554
163.80001,8.18990,24537.54693,0.00000,0.06221,306.07199
164.10001,8.20509,24543.69664,0.00000,0.06234,306.14870
164.40001,8.21998,24541.58366,0.00000,0.06247,306.12235
164.70001,8.23505,24545.63379,0.00000,0.06260,306.17287
165.00001,8.24993,24546.88847,0.00000,0.06273,306.18852
165.30001,8.26506,24551.08613,0.00000,0.06285,306.24088
165.60001,8.28001,24551.35137,0.00000,0.06299,306.24419
165.90001,8.29501,24553.21848,0.00000,0.06312,306.26748
166.20001,8.30996,24554.07828,0.00000,0.06325,306.27820
166.50001,8.32509,24554.64751,0.00000,0.06338,306.28530
166.80001,8.33998,24558.08520,0.00000,0.06352,306.32818
167.10001,8.35492,24557.07788,0.00000,0.06365,306.31562
167.40001,8.37011,24562.11001,0.00000,0.06377,306.37838
167.70001,8.38488,24559.42035,0.00000,0.06390,306.34484
168.00001,8.40012,24563.16352,0.00000,0.06403,306.39153
168.30001,8.41495,24564.43757,0.00000,0.06416,306.40742
168.60001,8.42996,24566.11395,0.00000,0.06429,306.42833
168.90001,8.44509,24570.22965,0.00000,0.06442,306.47967
169.20001,8.45991,24568.68738,0.00000,0.06455,306.46043
169.50001,8.47504,24571.65718,0.00000,0.06468,306.49747
169.80001,8.48993,24571.40237,0.00000,0.06480,306.49429
170.10001,8.50500,24575.70881,0.00000,0.06493,306.54801
170.40001,8.51988,24574.89818,0.00000,0.06506,306.53790
170.70001,8.53501,24578.11087,0.00000,0.06519,306.57797
171.00001,8.54996,24578.56536,0.00000,0.06532,306.58364
171.30001,8.56508,24577.67278,0.00000,0.06545,306.57251
171.60001,8.58003,24582.04925,0.00000,0.06558,306.62710
171.90001,8.59492,24578.46105,0.00000,0.06570,306.58234
172.20001,8.61011,24586.05915,0.00000,0.06583,306.67712
172.50001,8.62487,24582.50970,0.00000,0.06595,306.63284
172.80001,8.64006,24586.92193,0.00000,0.06608,306.68788
173.10001,8.65501,24587.29744,0.00000,0.06621,306.69256
173.40001,8.66995,24586.83103,0.00000,0.06633,306.68675
173.70001,8.68502,24591.01230,0.00000,0.06646,306.73890
174.00001,8.69991,24590.65616,0.00000,0.06658,306.73446
174.30001,8.71504,24593.49483,0.00000,0.06671,306.76987
174.60001,8.72998,24593.79137,0.00000,0.06683,306.77357
174.90001,8.74505,24596.15171,0.00000,0.06695,306.80301
175.20001,8.76000,24594.18476,0.00000,0.06708,306.77847
175.50001,8.77507,24597.17244,0.00000,0.06720,306.81574
175.80001,8.78995,24598.48970,0.00000,0.06733,306.83217
176.10001,8.80508,24597.84299,0.00000,0.06745,306.82410
176.40001,8.82003,24600.86942,0.00000,0.06757,306.86185
176.70001,8.83485,24597.11581,0.00000,0.06769,306.81503
177.00001,8.85010,24602.70077,0.00000,0.06782,306.88470
177.30001,8.86487,24602.67246,0.00000,0.06793,306.88435
177.60001,8.88005,24604.72286,0.00000,0.06805,306.90992
177.90001,8.89494,24606.45884,0.00000,0.06817,306.93158
178.20001,8.90995,24605.53199,0.00000,0.06830,306.92001
178.50001,8.92508,24608.77299,0.00000,0.06842,306.96044
178.80001,8.93996,24608.86240,0.00000,0.06853,306.96156
179.10001,8.95503,24610.52686,0.00000,0.06866,306.98232
179.40001,8.96998,24611.16016,0.00000,0.06877,306.99022
179.70001,8.98505,24614.17019,0.00000,0.06889,307.02776
180.00001,8.99993,24611.83667,0.00000,0.06901,306.99866
180.30001,9.01506,24615.25202,0.00000,0.06913,307.04126
180.60001,9.02995,24616.44709,0.00000,0.06925,307.05616
180.90001,9.04501,24614.60680,0.00000,0.06937,307.03321
181.20001,9.06002,24619.42732,0.00000,0.06949,307.09334
181.50001,9.07485,24617.61236,0.00000,0.06961,307.07070
181.80001,9.09009,24622.37626,0.00000,0.06973,307.13012
182.10001,9.10492,24621.59246,0.00000,0.06984,307.12035
182.40001,9.11999,24621.45686,0.00000,0.06996,307.11865
182.70001,9.13500,24624.02284,0.00000,0.07008,307.15066
183.00001,9.14994,24622.93655,0.00000,0.07019,307.13711
183.30001,9.16507,24627.24596,0.00000,0.07031,307.19087
183.60001,9.17996,24624.36855,0.00000,0.07043,307.15497
183.90001,9.19509,24628.07000,0.00000,0.07055,307.20114
184.20001,9.21003,24627.29365,0.00000,0.07066,307.19146
184.50001,9.22504,24630.12934,0.00000,0.07078,307.22683
184.80001,9.23993,24630.10252,0.00000,0.07090,307.22650
185.10001,9.25511,24631.66565,0.00000,0.07101,307.24600
185.40001,9.26994,24632.48670,0.00000,0.07112,307.25624
185.70001,9.28501,24629.43047,0.00000,0.07124,307.21811
186.00001,9.30008,24634.85450,0.00000,0.07136,307.28577
186.30001,9.31484,24631.61051,0.00000,0.07147,307.24531
186.60001,9.33009,24638.07017,0.00000,0.07159,307.32588
186.90001,9.34486,24637.82132,0.00000,0.07170,307.32278
187.20001,9.36005,24638.82118,0.00000,0.07182,307.33525
187.50001,9.37505,24639.51558,0.00000,0.07193,307.34391
187.80001,9.39000,24638.85248,0.00000,0.07205,307.33564
188.10001,9.40513,24642.67015,0.00000,0.07216,307.38326
188.40001,9.41995,24641.91169,0.00000,0.07227,307.37380
188.70001,9.43502,24643.90993,0.00000,0.07238,307.39873
189.00001,9.44997,24641.19643,0.00000,0.07250,307.36488
189.30001,9.46504,24644.28991,0.00000,0.07262,307.40347
189.60001,9.47980,24641.79397,0.00000,0.07277,307.37233
189.90001,9.49505,24645.60419,0.00000,0.07290,307.41986
190.20001,9.50994,24649.68711,0.00000,0.07300,307.47079
190.50001,9.52500,24646.94530,0.00000,0.07312,307.43659
190.80001,9.54007,24651.48568,0.00000,0.07323,307.49322
191.10001,9.55490,24648.60231,0.00000,0.07334,307.45726
191.40001,9.57015,24652.48555,0.00000,0.07346,307.50569
191.70001,9.58491,24653.33939,0.00000,0.07357,307.51635
192.00001,9.60004,24652.92662,0.00000,0.07368,307.51120
192.30001,9.61505,24654.91146,0.00000,0.07380,307.53595
192.60001,9.62999,24653.12481,0.00000,0.07390,307.51367
192.90001,9.64506,24655.91282,0.00000,0.07402,307.54845
193.20001,9.66001,24653.66721,0.00000,0.07413,307.52043
193.50001,9.67502,24658.32978,0.00000,0.07424,307.57859
193.80001,9.69002,24657.68158,0.00000,0.07435,307.57051
194.10001,9.70509,24661.32492,0.00000,0.07447,307.61595
194.40001,9.71992,24658.14203,0.00000,0.07458,307.57625
194.70001,9.73510,24660.10451,0.00000,0.07470,307.60073
195.00001,9.74999,24662.36800,0.00000,0.07481,307.62896
195.30001,9.76494,24658.73957,0.00000,0.07493,307.58371
195.60001,9.78007,24665.50320,0.00000,0.07504,307.66807
195.90001,9.79489,24663.02514,0.00000,0.07514,307.63716
196.20001,9.81014,24666.37492,0.00000,0.07526,307.67895
196.50001,9.82491,24663.57797,0.00000,0.07537,307.64406
196.80001,9.83997,24664.78348,0.00000,0.07548,307.65909
197.10001,9.85510,24669.92438,0.00000,0.07559,307.72322
197.40001,9.86999,24666.96203,0.00000,0.07570,307.68627
197.70001,9.88500,24668.61010,0.00000,0.07582,307.70683
198.00001,9.90006,24667.83077,0.00000,0.07593,307.69711
198.30001,9.91507,24669.05564,0.00000,0.07604,307.71238
198.60001,9.92996,24668.81871,0.00000,0.07615,307.70943
198.90001,9.94503,24670.63665,0.00000,0.07627,307.73210
199.20001,9.95991,24669.44605,0.00000,0.07638,307.71725
199.50001,9.97504,24670.97193,0.00000,0.07649,307.73629
199.80001,9.98999,24673.23393,0.00000,0.07660,307.76450
200.10001,10.00493,24669.87073,0.00000,0.07672,307.72255
200.40001,10.02012,24674.22634,0.00000,0.07683,307.77688
200.70001,10.03489,24673.25628,0.00000,0.07694,307.76478
201.00001,10.05008,24675.36926,0.00000,0.07705,307.79114
201.30001,10.06496,24675.12786,0.00000,0.07716,307.78813
201.60001,10.07997,24673.99985,0.00000,0.07728,307.77406
201.90001,10.09498,24673.82848,0.00000,0.07739,307.77192
202.20001,10.10998,24673.43658,0.00000,0.07750,307.76703
202.50001,10.12505,24675.59576,0.00000,0.07763,307.79396
202.80001,10.13994,24673.92683,0.00000,0.07774,307.77315
203.10001,10.15507,24678.57450,0.00000,0.07785,307.83112
203.40001,10.16995,24676.76550,0.00000,0.07796,307.80855
203.70001,10.18508,24679.76213,0.00000,0.07807,307.84593
204.00001,10.19991,24678.25562,0.00000,0.07818,307.82714
204.30001,10.21503,24678.42549,0.00000,0.07829,307.82926
204.60001,10.22998,24682.04498,0.00000,0.07840,307.87441
204.90001,10.24487,24676.65374,0.00000,0.07851,307.80716
205.20001,10.26012,24679.99905,0.00000,0.07862,307.84889
205.50001,10.27488,24676.91600,0.00000,0.07873,307.81043
205.80001,10.29007,24679.29572,0.00000,0.07885,307.84011
206.10001,10.30502,24682.08224,0.00000,0.07896,307.87487
206.40001,10.31996,24679.14671,0.00000,0.07907,307.83826
206.70001,10.33503,24679.65782,0.00000,0.07918,307.84463
207.00001,10.34998,24678.88594,0.00000,0.07929,307.83500
207.30001,10.36499,24679.46112,0.00000,0.07939,307.84218
207.60001,10.37993,24679.18992,0.00000,0.07950,307.83879
207.90001,10.39506,24684.11922,0.00000,0.07961,307.90028
208.20001,10.40989,24680.67259,0.00000,0.07972,307.85729
208.50001,10.42496,24681.38933,0.00000,0.07983,307.86623
208.80001,10.43984,24680.86034,0.00000,0.07994,307.85963
209.10001,10.45509,24682.32512,0.00000,0.08005,307.87790
209.40001,10.47004,24684.04770,0.00000,0.08016,307.89939
209.70001,10.48492,24679.70848,0.00000,0.08026,307.84526
210.00001,10.50017,24683.81524,0.00000,0.08037,307.89649
210.30001,10.51494,24680.61298,0.00000,0.08048,307.85655
210.60001,10.53007,24682.33556,0.00000,0.08059,307.87803
210.90001,10.54495,24679.69954,0.00000,0.08070,307.84515
211.20001,10.56002,24680.72772,0.00000,0.08080,307.85798
211.50001,10.57503,24682.09267,0.00000,0.08091,307.87500
211.80001,10.58991,24680.56083,0.00000,0.08101,307.85590
212.10001,10.60504,24682.59484,0.00000,0.08111,307.88127
212.40001,10.61999,24680.09293,0.00000,0.08122,307.85006
212.70001,10.63506,24682.87349,0.00000,0.08133,307.88474
213.00001,10.64994,24681.46831,0.00000,0.08143,307.86721
213.30001,10.66501,24682.72597,0.00000,0.08154,307.88290
213.60001,10.67996,24684.39192,0.00000,0.08165,307.90368
213.90001,10.69508,24681.48470,0.00000,0.08175,307.86742
214.20001,10.71003,24682.49053,0.00000,0.08186,307.87997
214.50001,10.72498,24678.60430,0.00000,0.08196,307.83149
214.80001,10.74011,24682.04200,0.00000,0.08206,307.87437
215.10001,10.75487,24679.00366,0.00000,0.08216,307.83647
215.40001,10.77000,24681.66500,0.00000,0.08226,307.86967
215.70001,10.78495,24680.79329,0.00000,0.08236,307.85879
216.00001,10.80001,24680.42374,0.00000,0.08246,307.85419
216.30001,10.81508,24682.15674,0.00000,0.08256,307.87580
216.60001,10.82997,24679.98117,0.00000,0.08267,307.84866
216.90001,10.84504,24683.02548,0.00000,0.08277,307.88664
217.20001,10.85992,24679.01856,0.00000,0.08287,307.83666
217.50001,10.87505,24681.85425,0.00000,0.08298,307.87203
217.80001,10.88994,24677.15889,0.00000,0.08308,307.81346
218.10001,10.90507,24679.52222,0.00000,0.08317,307.84294
218.40001,10.91995,24679.72487,0.00000,0.08327,307.84547
218.70001,10.93502,24676.03236,0.00000,0.08337,307.79941
219.00001,10.95009,24680.48632,0.00000,0.08347,307.85497
219.30001,10.96491,24673.12217,0.00000,0.08356,307.76311
219.60001,10.98016,24676.35274,0.00000,0.08366,307.80341
219.90001,10.99493,24674.05200,0.00000,0.08376,307.77471
220.20001,11.01005,24673.75547,0.00000,0.08385,307.77101
220.50001,11.02494,24674.71212,0.00000,0.08395,307.78294
220.80001,11.03995,24673.65861,0.00000,0.08405,307.76980
221.10001,11.05502,24674.33512,0.00000,0.08414,307.77824
221.40001,11.06996,24670.41761,0.00000,0.08424,307.72937
221.70001,11.08503,24672.60361,0.00000,0.08433,307.75664
222.00001,11.09998,24670.27903,0.00000,0.08442,307.72764
222.30001,11.11505,24672.09846,0.00000,0.08451,307.75034
222.60001,11.12993,24669.96312,0.00000,0.08460,307.72370
222.90001,11.14506,24667.96041,0.00000,0.08469,307.69872
223.20001,11.16001,24665.95620,0.00000,0.08478,307.67372
223.50001,11.17507,24663.03110,0.00000,0.08487,307.63724
223.80001,11.19002,24663.95497,0.00000,0.08496,307.64876
224.10001,11.20491,24661.81368,0.00000,0.08505,307.62205
224.40001,11.22016,24664.13975,0.00000,0.08513,307.65106
224.70001,11.23492,24660.36975,0.00000,0.08522,307.60404
225.00001,11.25005,24660.27141,0.00000,0.08530,307.60281
225.30001,11.26500,24659.67089,0.00000,0.08538,307.59532
225.60001,11.28000,24658.20909,0.00000,0.08546,307.57709
225.90001,11.29501,24657.99302,0.00000,0.08555,307.57439
226.20001,11.30996,24653.55396,0.00000,0.08563,307.51902
226.50001,11.32503,24654.54638,0.00000,0.08571,307.53140
226.80001,11.33997,24649.05977,0.00000,0.08580,307.46296
227.10001,11.35498,24648.32217,0.00000,0.08588,307.45376
227.40001,11.36981,24644.03808,0.00000,0.08595,307.40032
227.70001,11.38506,24645.52224,0.00000,0.08603,307.41884
228.00001,11.39994,24641.59876,0.00000,0.08610,307.36990
228.30001,11.41501,24637.56204,0.00000,0.08618,307.31954
228.60001,11.43008,24637.02112,0.00000,0.08625,307.31280
228.90001,11.44496,24631.15603,0.00000,0.08632,307.23964
229.20001,11.46015,24631.70886,0.00000,0.08639,307.24653
229.50001,11.47492,24627.44415,0.00000,0.08646,307.19334
229.80001,11.48999,24624.07351,0.00000,0.08652,307.15129
230.10001,11.50499,24621.11413,0.00000,0.08659,307.11438
230.40001,11.52000,24616.34427,0.00000,0.08666,307.05488
230.70001,11.53495,24612.58024,0.00000,0.08672,307.00793
231.00001,11.55001,24607.22774,0.00000,0.08678,306.94117
231.30001,11.56502,24602.48768,0.00000,0.08684,306.88204
231.60001,11.57997,24594.93130,0.00000,0.08690,306.78779
231.90001,11.59504,24593.01353,0.00000,0.08696,306.76386
232.20001,11.60998,24584.12200,0.00000,0.08701,306.65295
232.50001,11.62517,24581.18647,0.00000,0.08707,306.61634
232.80001,11.63994,24574.38558,0.00000,0.08712,306.53151
233.10001,11.65500,24565.39422,0.00000,0.08717,306.41935
233.40001,11.67007,24561.86265,0.00000,0.08722,306.37530
233.70001,11.68490,24549.40379,0.00000,0.08726,306.21989
234.00001,11.70015,24544.24351,0.00000,0.08730,306.15552
234.30001,11.71491,24534.55627,0.00000,0.08735,306.03469
234.60001,11.72998,24525.07466,0.00000,0.08739,305.91642
234.90001,11.74499,24516.90882,0.00000,0.08743,305.81456
235.20001,11.76000,24504.10873,0.00000,0.08746,305.65490
235.50001,11.77500,24492.59609,0.00000,0.08749,305.51129
235.80001,11.79001,24478.73503,0.00000,0.08752,305.33840
236.10001,11.80508,24467.32223,0.00000,0.08755,305.19604
236.40001,11.81996,24448.21000,0.00000,0.08758,304.95764
236.70001,11.83503,24433.96747,0.00000,0.08760,304.77998
237.00001,11.84992,24415.58540,0.00000,0.08763,304.55069
237.30001,11.86511,24399.80954,0.00000,0.08765,304.35391
237.60001,11.87999,24382.52866,0.00000,0.08767,304.13836
237.90001,11.89494,24358.37686,0.00000,0.08768,303.83710
238.20001,11.91007,24340.73985,0.00000,0.08770,303.61710
238.50001,11.92489,24313.94905,0.00000,0.08771,303.28292
238.80001,11.94014,24290.67343,0.00000,0.08772,302.99259
239.10001,11.95491,24260.66399,0.00000,0.08773,302.61826
239.40001,11.96992,24230.50553,0.00000,0.08774,302.24208
239.70001,11.98504,24202.28869,0.00000,0.08775,301.89011
240.00001,11.99999,24166.15039,0.00000,0.08775,301.43934
240.30001,12.01500,24132.12061,0.00000,0.08775,301.01486
240.60001,12.03000,24092.91565,0.00000,0.08775,300.52583
240.90001,12.04507,24053.11018,0.00000,0.08775,300.02932
241.20001,12.05996,24007.57819,0.00000,0.08775,299.46137
241.50001,12.07509,23962.83746,0.00000,0.08775,298.90329
241.80001,12.08991,23911.21984,0.00000,0.08774,298.25943
242.10001,12.10516,23856.01550,0.00000,0.08774,297.57083
242.40001,12.11999,23793.94770,0.00000,0.08773,296.79662
242.70001,12.13493,23712.72594,0.00000,0.08771,295.78349
243.00001,12.15012,23620.74554,0.00000,0.08770,294.63616
243.30001,12.16495,23470.16186,0.00000,0.08767,292.75784
243.60001,12.18014,23138.52161,0.00000,0.08761,288.62109
243.87001,12.19353,22610.29333,0.00000,0.08753,282.03217
243.87801,12.19425,20416.40133,0.00000,0.08905,254.66640
243.88401,12.19520,16966.12984,0.00000,0.09158,211.62903
243.89001,12.19622,13080.18118,0.00000,0.09198,163.15719