File: scratch/college-stuff/ME Lab/ME lab Fall 2013/group17/group17.is_tens_RawData/Specimen_RawData_1.csv
Time,Extension,Load,Strain 2,Tensile strain,Tensile stress
(sec),(mm),(N),(mm/mm),(mm/mm),(MPa)
0.00000,0.00000,0.16931,0.00000,0.00000,0.00210
0.30000,0.01357,15.66828,0.00000,0.00000,0.19429
0.60000,0.03001,21.11162,0.00000,0.00000,0.26179
0.90000,0.04490,28.06672,0.00000,0.00000,0.34803
1.20000,0.06009,40.68197,0.00000,0.00000,0.50446
1.50000,0.07492,54.79895,0.00000,0.00000,0.67951
1.80000,0.09004,73.77490,0.00000,0.00000,0.91481
2.10000,0.10499,92.32682,0.00000,0.00000,1.14486
2.40000,0.12000,110.70061,0.00000,0.00000,1.37269
2.70000,0.13500,132.98673,0.00000,0.00000,1.64904
3.00000,0.14995,166.04587,0.00000,-0.00001,2.05898
3.30000,0.16508,215.01188,0.00000,-0.00001,2.66616
3.60000,0.17991,281.70929,0.00000,-0.00001,3.49321
3.90000,0.19503,362.07316,0.00000,-0.00001,4.48973
4.20000,0.20992,459.68266,0.00000,0.00000,5.70009
4.50000,0.22505,570.18511,0.00000,0.00000,7.07033
4.80000,0.23994,699.42456,0.00000,0.00001,8.67290
5.10000,0.25500,839.14483,0.00000,0.00003,10.40544
5.40000,0.27007,983.99892,0.00000,0.00004,12.20164
5.70000,0.28490,1137.41746,0.00000,0.00006,14.10404
6.00000,0.30002,1314.19711,0.00000,0.00008,16.29612
6.30000,0.31497,1519.72435,0.00000,0.00011,18.84467
6.60000,0.32998,1737.07884,0.00000,0.00015,21.53987
6.90000,0.34493,1947.40929,0.00000,0.00018,24.14798
7.20000,0.35993,2154.77627,0.00000,0.00021,26.71935
7.50000,0.37500,2363.83714,0.00000,0.00025,29.31171
7.80000,0.38995,2572.66182,0.00000,0.00028,31.90115
8.10000,0.40507,2791.72882,0.00000,0.00032,34.61759
8.40000,0.41990,3009.28578,0.00000,0.00035,37.31531
8.70000,0.43503,3231.83909,0.00000,0.00039,40.07498
9.00000,0.44992,3450.83177,0.00000,0.00043,42.79051
9.30000,0.46498,3667.09232,0.00000,0.00047,45.47215
9.60000,0.47999,3885.45059,0.00000,0.00051,48.17980
9.90000,0.49494,4098.52453,0.00000,0.00055,50.82193
10.20000,0.51006,4316.63319,0.00000,0.00059,53.52649
10.50000,0.52489,4526.83531,0.00000,0.00062,56.13301
10.80000,0.54002,4739.16642,0.00000,0.00066,58.76593
11.10000,0.55491,4943.02213,0.00000,0.00070,61.29375
11.40000,0.56991,5144.80472,0.00000,0.00073,63.79586
11.70000,0.58492,5346.65883,0.00000,0.00077,66.29887
12.00000,0.59993,5538.50085,0.00000,0.00081,68.67772
12.30000,0.61493,5738.08663,0.00000,0.00084,71.15259
12.60000,0.62988,5924.15705,0.00000,0.00087,73.45988
12.90000,0.64513,6107.66076,0.00000,0.00091,75.73533
13.20000,0.65990,6261.06709,0.00000,0.00093,77.63758
13.50000,0.67508,6414.32554,0.00000,0.00096,79.53799
13.80000,0.68997,6567.35376,0.00000,0.00099,81.43555
14.10000,0.70504,6719.21149,0.00000,0.00102,83.31860
14.40000,0.71999,6872.19426,0.00000,0.00104,85.21559
14.70000,0.73493,7017.50964,0.00000,0.00106,87.01751
15.00000,0.75006,7166.35212,0.00000,0.00109,88.86316
15.30000,0.76489,7311.75169,0.00000,0.00112,90.66613
15.60000,0.78001,7459.96460,0.00000,0.00114,92.50398
15.90000,0.79496,7593.01186,0.00000,0.00117,94.15377
16.20000,0.81003,7729.05275,0.00000,0.00119,95.84068
16.50000,0.82498,7863.56777,0.00000,0.00121,97.50868
16.80000,0.84004,7996.00184,0.00000,0.00124,99.15087
17.10000,0.85505,8136.38195,0.00000,0.00127,100.89159
17.40000,0.86994,8267.71110,0.00000,0.00129,102.52008
17.70000,0.88506,8409.53588,0.00000,0.00132,104.27871
18.00000,0.89989,8544.65216,0.00000,0.00134,105.95416
18.30000,0.91508,8684.87284,0.00000,0.00137,107.69291
18.60000,0.92991,8821.14395,0.00000,0.00139,109.38268
18.90000,0.94497,8961.70810,0.00000,0.00142,111.12568
19.20000,0.95992,9103.64836,0.00000,0.00144,112.88575
19.50000,0.97493,9241.37160,0.00000,0.00147,114.59352
19.80000,0.99005,9384.25735,0.00000,0.00149,116.36531
20.10000,1.00488,9522.78450,0.00000,0.00152,118.08306
20.40000,1.02001,9666.24692,0.00000,0.00155,119.86200
20.70000,1.03496,9808.24530,0.00000,0.00157,121.62279
21.00000,1.05002,9952.66438,0.00000,0.00160,123.41359
21.30000,1.06497,10094.73130,0.00000,0.00163,125.17523
21.60000,1.08004,10234.87076,0.00000,0.00165,126.91297
21.90000,1.09504,10380.30386,0.00000,0.00168,128.71634
22.20000,1.10987,10519.60811,0.00000,0.00171,130.44372
22.50000,1.12506,10668.63537,0.00000,0.00173,132.29167
22.80000,1.13989,10813.10436,0.00000,0.00176,134.08309
23.10000,1.15507,10959.58650,0.00000,0.00179,135.89948
23.40000,1.16996,11104.54798,0.00000,0.00182,137.69701
23.70000,1.18503,11250.07868,0.00000,0.00184,139.50160
24.00000,1.20003,11400.26599,0.00000,0.00187,141.36393
24.30000,1.21486,11543.78131,0.00000,0.00190,143.14353
24.60000,1.23005,11693.74213,0.00000,0.00192,145.00305
24.90000,1.24494,11840.93878,0.00000,0.00195,146.82830
25.20000,1.26000,11987.67051,0.00000,0.00198,148.64778
25.50000,1.27495,12134.68164,0.00000,0.00201,150.47073
25.80000,1.29002,12282.81856,0.00000,0.00203,152.30763
26.10000,1.30497,12435.71788,0.00000,0.00206,154.20359
26.40000,1.32003,12581.36183,0.00000,0.00209,156.00959
26.70000,1.33504,12733.13612,0.00000,0.00212,157.89160
27.00000,1.34993,12879.07660,0.00000,0.00215,159.70127
27.30000,1.36511,13032.67777,0.00000,0.00217,161.60593
27.60000,1.37988,13181.21403,0.00000,0.00220,163.44779
27.90000,1.39501,13331.27171,0.00000,0.00223,165.30851
28.20000,1.40996,13485.23945,0.00000,0.00226,167.21772
28.50000,1.42496,13632.57468,0.00000,0.00229,169.04468
28.80000,1.44003,13786.05962,0.00000,0.00232,170.94791
29.10000,1.45486,13934.19951,0.00000,0.00235,172.78485
29.40000,1.47004,14090.80476,0.00000,0.00238,174.72676
29.70000,1.48493,14241.35268,0.00000,0.00241,176.59356
30.00000,1.50000,14391.60258,0.00000,0.00244,178.45667
30.30000,1.51495,14541.04781,0.00000,0.00247,180.30980
30.60000,1.53001,14693.03966,0.00000,0.00250,182.19451
30.90000,1.54490,14846.28767,0.00000,0.00253,184.09479
31.20000,1.55997,14996.26637,0.00000,0.00257,185.95454
31.50000,1.57503,15155.53594,0.00000,0.00260,187.92949
31.80000,1.58986,15302.51503,0.00000,0.00263,189.75204
32.10000,1.60511,15459.06663,0.00000,0.00266,191.69328
32.40000,1.61988,15608.94996,0.00000,0.00269,193.55185
32.70000,1.63500,15763.71938,0.00000,0.00272,195.47100
33.00000,1.64995,15917.60367,0.00000,0.00276,197.37917
33.30000,1.66496,16068.73274,0.00000,0.00279,199.25318
33.60000,1.68003,16222.05377,0.00000,0.00283,201.15437
33.90000,1.69491,16373.76547,0.00000,0.00286,203.03560
34.20000,1.70998,16528.28455,0.00000,0.00289,204.95165
34.50000,1.72493,16678.41971,0.00000,0.00292,206.81333
34.80000,1.73999,16834.06383,0.00000,0.00296,208.74333
35.10000,1.75494,16984.28839,0.00000,0.00299,210.60612
35.40000,1.77007,17138.59737,0.00000,0.00302,212.51956
35.70000,1.78502,17292.40865,0.00000,0.00306,214.42683
36.00000,1.80002,17441.61546,0.00000,0.00309,216.27700
36.30000,1.81503,17599.28167,0.00000,0.00313,218.23207
36.60000,1.82980,17749.02791,0.00000,0.00316,220.08893
36.90000,1.84510,17904.77484,0.00000,0.00320,222.02020
37.20000,1.85981,18054.15899,0.00000,0.00323,223.87257
37.50000,1.87500,18204.49233,0.00000,0.00327,225.73672
37.80000,1.88995,18356.08631,0.00000,0.00330,227.61649
38.10000,1.90483,18502.45893,0.00000,0.00334,229.43152
38.40000,1.92002,18657.10616,0.00000,0.00338,231.34915
38.70000,1.93497,18805.67074,0.00000,0.00342,233.19136
39.00000,1.95009,18954.57953,0.00000,0.00345,235.03784
39.30000,1.96498,19099.49929,0.00000,0.00349,236.83485
39.60000,1.98005,19248.79551,0.00000,0.00353,238.68613
39.90000,1.99494,19391.84815,0.00000,0.00357,240.45999
40.20000,2.01006,19537.15384,0.00000,0.00361,242.26179
40.50000,2.02489,19685.18347,0.00000,0.00365,244.09737
40.80000,2.03990,19821.12080,0.00000,0.00369,245.78300
41.10000,2.05508,19966.91674,0.00000,0.00374,247.59088
41.40000,2.06991,20103.06567,0.00000,0.00378,249.27913
41.70000,2.08510,20244.30633,0.00000,0.00382,251.03052
42.00000,2.09987,20377.65533,0.00000,0.00387,252.68406
42.30000,2.11499,20512.23069,0.00000,0.00391,254.35280
42.60000,2.13000,20642.82447,0.00000,0.00396,255.97217
42.90000,2.14495,20767.83627,0.00000,0.00401,257.52232
43.20000,2.16001,20895.85215,0.00000,0.00406,259.10973
43.50000,2.17496,21017.24744,0.00000,0.00410,260.61504
43.80000,2.19003,21141.67660,0.00000,0.00416,262.15796
44.10000,2.20498,21256.15925,0.00000,0.00421,263.57756
44.40000,2.22004,21373.41499,0.00000,0.00426,265.03153
44.70000,2.23493,21482.91618,0.00000,0.00432,266.38935
45.00000,2.25006,21588.73677,0.00000,0.00438,267.70154
45.30000,2.26495,21696.92665,0.00000,0.00444,269.04310
45.60000,2.27995,21789.84433,0.00000,0.00450,270.19528
45.90000,2.29508,21889.85944,0.00000,0.00457,271.43547
46.20000,2.30985,21974.14488,0.00000,0.00464,272.48062
46.50000,2.32503,22058.88778,0.00000,0.00471,273.53143
46.80000,2.33992,22139.77873,0.00000,0.00478,274.53449
47.10000,2.35499,22211.87353,0.00000,0.00487,275.42847
47.40000,2.37000,22282.29046,0.00000,0.00495,276.30164
47.70000,2.38500,22342.96352,0.00000,0.00504,277.05399
48.00000,2.40007,22400.83367,0.00000,0.00513,277.77158
48.30000,2.41502,22449.21625,0.00000,0.00522,278.37153
48.60000,2.43008,22500.47773,0.00000,0.00533,279.00717
48.90000,2.44497,22539.81680,0.00000,0.00544,279.49498
49.20000,2.46004,22580.22279,0.00000,0.00555,279.99602
49.50000,2.47487,22612.23346,0.00000,0.00568,280.39295
49.80000,2.49005,22644.56153,0.00000,0.00581,280.79382
50.10000,2.50500,22675.40544,0.00000,0.00594,281.17629
50.40000,2.51995,22698.57377,0.00000,0.00607,281.46358
50.70000,2.53513,22729.54881,0.00000,0.00621,281.84767
51.00000,2.54984,22748.02029,0.00000,0.00635,282.07672
51.30000,2.56509,22768.75228,0.00000,0.00650,282.33379
51.60000,2.57998,22789.75397,0.00000,0.00665,282.59422
51.90000,2.59498,22807.15406,0.00000,0.00681,282.80998
52.20000,2.61011,22826.74611,0.00000,0.00696,283.05292
52.50000,2.62500,22840.31212,0.00000,0.00711,283.22114
52.80000,2.64000,22855.55154,0.00000,0.00727,283.41011
53.10000,2.65495,22868.83891,0.00000,0.00743,283.57487
53.40000,2.67008,22885.08862,0.00000,0.00759,283.77637
53.70000,2.68497,22895.73848,0.00000,0.00775,283.90843
54.00000,2.70003,22911.39513,0.00000,0.00792,284.10257
54.30000,2.71492,22923.29520,0.00000,0.00809,284.25013
54.60000,2.73011,22935.00602,0.00000,0.00825,284.39535
54.90000,2.74500,22947.56323,0.00000,0.00842,284.55106
55.20000,2.75994,22954.22554,0.00000,0.00858,284.63367
55.50000,2.77513,22969.42621,0.00000,0.00875,284.82216
55.80000,2.78984,22975.51334,0.00000,0.00892,284.89764
56.10000,2.80502,22987.91260,0.00000,0.00909,285.05139
56.40000,2.81997,22997.51341,0.00000,0.00926,285.17044
56.70000,2.83498,23008.14837,0.00000,0.00942,285.30232
57.00000,2.84993,23015.83439,0.00000,0.00959,285.39763
57.30000,2.86499,23026.14599,0.00000,0.00976,285.52549
57.60000,2.88000,23035.53075,0.00000,0.00994,285.64186
57.90000,2.89495,23042.40912,0.00000,0.01010,285.72715
58.20000,2.91007,23055.40293,0.00000,0.01027,285.88828
58.50000,2.92490,23059.99845,0.00000,0.01044,285.94526
58.80000,2.94009,23071.08939,0.00000,0.01061,286.08279
59.10000,2.95492,23077.59374,0.00000,0.01078,286.16344
59.40000,2.96998,23083.76729,0.00000,0.01095,286.24000
59.70000,2.98493,23095.05939,0.00000,0.01113,286.38002
60.00000,2.99994,23100.29417,0.00000,0.01130,286.44493
60.30000,3.01512,23111.90367,0.00000,0.01147,286.58889
60.60000,3.02989,23116.49323,0.00000,0.01163,286.64580
60.90000,3.04508,23126.32203,0.00000,0.01180,286.76768
61.20000,3.05997,23133.87990,0.00000,0.01197,286.86140
61.50000,3.07503,23142.99345,0.00000,0.01214,286.97440
61.80000,3.08998,23149.57678,0.00000,0.01232,287.05604
62.10000,3.10505,23157.03034,0.00000,0.01248,287.14846
62.40000,3.11999,23163.93256,0.00000,0.01265,287.23405
62.70000,3.13494,23169.13456,0.00000,0.01282,287.29856
63.00000,3.15007,23181.33563,0.00000,0.01299,287.44985
63.30000,3.16490,23184.26222,0.00000,0.01316,287.48614
63.60000,3.18008,23197.08467,0.00000,0.01333,287.64514
63.90000,3.19491,23200.16474,0.00000,0.01349,287.68333
64.20000,3.20998,23205.91509,0.00000,0.01366,287.75464
64.50000,3.22505,23217.48734,0.00000,0.01383,287.89813
64.80000,3.23993,23219.98924,0.00000,0.01400,287.92916
65.10000,3.25512,23230.63463,0.00000,0.01417,288.06116
65.40000,3.26995,23236.03630,0.00000,0.01433,288.12814
65.70000,3.28501,23242.54066,0.00000,0.01449,288.20880
66.00000,3.29996,23249.75878,0.00000,0.01466,288.29830
66.30000,3.31503,23257.92909,0.00000,0.01482,288.39961
66.60000,3.33004,23265.29324,0.00000,0.01499,288.49093
66.90000,3.34498,23270.43712,0.00000,0.01516,288.55471
67.20000,3.35999,23279.39868,0.00000,0.01533,288.66584
67.50000,3.37494,23284.70498,0.00000,0.01549,288.73164
67.80000,3.39006,23292.98109,0.00000,0.01566,288.83426
68.10000,3.40489,23297.88506,0.00000,0.01582,288.89507
68.40000,3.42002,23305.83334,0.00000,0.01598,288.99363
68.70000,3.43497,23313.90977,0.00000,0.01614,289.09378
69.00000,3.44997,23316.74695,0.00000,0.01630,289.12896
69.30000,3.46504,23327.50708,0.00000,0.01647,289.26238
69.60000,3.47993,23331.69430,0.00000,0.01663,289.31431
69.90000,3.49517,23340.81382,0.00000,0.01679,289.42739
70.20000,3.50994,23346.43900,0.00000,0.01696,289.49714
70.50000,3.52507,23354.57057,0.00000,0.01712,289.59797
70.80000,3.54002,23360.46100,0.00000,0.01728,289.67101
71.10000,3.55502,23367.54948,0.00000,0.01745,289.75891
71.40000,3.56997,23373.17914,0.00000,0.01760,289.82872
71.70000,3.58498,23377.77168,0.00000,0.01776,289.88567
72.00000,3.59999,23388.48859,0.00000,0.01792,290.01856
72.30000,3.61493,23389.55402,0.00000,0.01809,290.03177
72.60000,3.63006,23400.60920,0.00000,0.01825,290.16885
72.90000,3.64489,23404.36727,0.00000,0.01841,290.21545
73.20000,3.66007,23412.03243,0.00000,0.01857,290.31050
73.50000,3.67502,23419.78699,0.00000,0.01873,290.40666
73.80000,3.68997,23422.56308,0.00000,0.01889,290.44108
74.10000,3.70509,23433.02369,0.00000,0.01905,290.57080
74.40000,3.71998,23437.45381,0.00000,0.01921,290.62573
74.70000,3.73511,23444.62425,0.00000,0.01937,290.71464
75.00000,3.74994,23449.14973,0.00000,0.01953,290.77076
75.30000,3.76506,23456.30527,0.00000,0.01968,290.85949
75.60000,3.77995,23461.74121,0.00000,0.01984,290.92689
75.90000,3.79496,23469.00702,0.00000,0.02000,291.01699
76.20000,3.80997,23475.91370,0.00000,0.02016,291.10263
76.50000,3.82503,23482.23329,0.00000,0.02032,291.18100
76.80000,3.84010,23489.00586,0.00000,0.02048,291.26498
77.10000,3.85493,23491.21869,0.00000,0.02063,291.29242
77.40000,3.87005,23500.30243,0.00000,0.02079,291.40506
77.70000,3.88488,23504.98736,0.00000,0.02095,291.46315
78.00000,3.90007,23512.35151,0.00000,0.02110,291.55446
78.30000,3.91496,23520.11353,0.00000,0.02126,291.65071
78.60000,3.93002,23522.91346,0.00000,0.02142,291.68543
78.90000,3.94509,23532.81826,0.00000,0.02157,291.80825
79.20000,3.95992,23537.00101,0.00000,0.02173,291.86012
79.50000,3.97510,23546.50199,0.00000,0.02188,291.97793
79.80000,3.98999,23550.13341,0.00000,0.02204,292.02296
80.10000,4.00506,23556.45448,0.00000,0.02219,292.10134
80.40000,4.02001,23562.54905,0.00000,0.02235,292.17692
80.70000,4.03507,23568.58701,0.00000,0.02250,292.25179
81.00000,4.05002,23576.44588,0.00000,0.02266,292.34924
81.30000,4.06497,23580.34551,0.00000,0.02281,292.39759
81.60000,4.07998,23589.15806,0.00000,0.02296,292.50687
81.90000,4.09498,23590.92683,0.00000,0.02311,292.52880
82.20000,4.11005,23599.01369,0.00000,0.02327,292.62908
82.50000,4.12488,23604.60460,0.00000,0.02343,292.69841
82.80000,4.14006,23611.30416,0.00000,0.02358,292.78148
83.10000,4.15501,23619.97515,0.00000,0.02374,292.88900
83.40000,4.17002,23622.90472,0.00000,0.02389,292.92533
83.70000,4.18508,23631.59060,0.00000,0.02404,293.03304
84.00000,4.19991,23634.28473,0.00000,0.02419,293.06644
84.30000,4.21510,23641.69955,0.00000,0.02434,293.15839
84.60000,4.22987,23646.11924,0.00000,0.02449,293.21319
84.90000,4.24499,23653.34332,0.00000,0.02465,293.30277
85.20000,4.26000,23657.90606,0.00000,0.02480,293.35935
85.50000,4.27501,23662.63866,0.00000,0.02495,293.41803
85.80000,4.29002,23669.18921,0.00000,0.02510,293.49926
86.10000,4.30496,23674.15875,0.00000,0.02525,293.56088
86.40000,4.32003,23684.31836,0.00000,0.02541,293.68686
86.70000,4.33498,23686.33598,0.00000,0.02556,293.71188
87.00000,4.35004,23694.48543,0.00000,0.02571,293.81294
87.30000,4.36493,23698.08853,0.00000,0.02586,293.85761
87.60000,4.38012,23705.27238,0.00000,0.02601,293.94669
87.90000,4.39495,23710.15549,0.00000,0.02616,294.00725
88.20000,4.40995,23712.67676,0.00000,0.02632,294.03851
88.50000,4.42508,23723.90032,0.00000,0.02647,294.17768
88.80000,4.43991,23725.22503,0.00000,0.02662,294.19411
89.10000,4.45509,23733.66058,0.00000,0.02677,294.29871
89.40000,4.46998,23737.45888,0.00000,0.02692,294.34581
89.70000,4.48499,23743.72780,0.00000,0.02706,294.42354
90.00000,4.50000,23749.85069,0.00000,0.02721,294.49947
90.30000,4.51494,23754.44770,0.00000,0.02736,294.55647
90.60000,4.53001,23760.74791,0.00000,0.02751,294.63459
90.90000,4.54496,23764.27054,0.00000,0.02766,294.67827
91.20000,4.56003,23772.52430,0.00000,0.02781,294.78062
91.50000,4.57491,23775.81298,0.00000,0.02796,294.82140
91.80000,4.59010,23784.59573,0.00000,0.02810,294.93031
92.10000,4.60493,23789.37900,0.00000,0.02826,294.98962
92.40000,4.62017,23794.83879,0.00000,0.02840,295.05732
92.70000,4.63500,23800.58169,0.00000,0.02855,295.12854
93.00000,4.65001,23802.19549,0.00000,0.02870,295.14855
93.30000,4.66507,23811.54895,0.00000,0.02885,295.26453
93.60000,4.67984,23814.95684,0.00000,0.02899,295.30679
93.90000,4.69503,23821.87545,0.00000,0.02914,295.39258
94.20000,4.70992,23826.60657,0.00000,0.02929,295.45125
94.50000,4.72492,23830.23798,0.00000,0.02944,295.49627
94.80000,4.73993,23834.83052,0.00000,0.02958,295.55322
95.10000,4.75494,23841.74466,0.00000,0.02973,295.63896
95.40000,4.77001,23848.78099,0.00000,0.02988,295.72621
95.70000,4.78495,23851.44383,0.00000,0.03002,295.75923
96.00000,4.80008,23860.16697,0.00000,0.03016,295.86740
96.30000,4.81497,23861.30244,0.00000,0.03031,295.88148
96.60000,4.83009,23869.39377,0.00000,0.03046,295.98181
96.90000,4.84492,23872.25330,0.00000,0.03061,296.01727
97.20000,4.86011,23879.91548,0.00000,0.03076,296.11228
97.50000,4.87494,23883.44258,0.00000,0.03091,296.15601
97.80000,4.88988,23886.92051,0.00000,0.03105,296.19914
98.10000,4.90507,23894.49924,0.00000,0.03119,296.29312
98.40000,4.91990,23898.54491,0.00000,0.03133,296.34328
98.70000,4.93508,23905.09844,0.00000,0.03148,296.42455
99.00000,4.94997,23908.41693,0.00000,0.03162,296.46570
99.30000,4.96504,23916.13871,0.00000,0.03177,296.56145
99.60000,4.97999,23919.10702,0.00000,0.03191,296.59826
99.90000,4.99499,23923.22719,0.00000,0.03206,296.64935
100.20000,5.01000,23928.47836,0.00000,0.03220,296.71446
100.50000,5.02507,23933.75188,0.00000,0.03235,296.77985
100.80000,5.04007,23940.73457,0.00000,0.03249,296.86644
101.10000,5.05490,23941.70463,0.00000,0.03263,296.87847
101.40000,5.07009,23950.86735,0.00000,0.03278,296.99209
101.70000,5.08492,23953.19790,0.00000,0.03292,297.02098
102.00000,5.10004,23957.73083,0.00000,0.03306,297.07719
102.30000,5.11499,23965.22760,0.00000,0.03320,297.17015
102.60000,5.12994,23966.83842,0.00000,0.03334,297.19013
102.90000,5.14512,23973.38748,0.00000,0.03348,297.27134
103.20000,5.15989,23975.18903,0.00000,0.03363,297.29368
103.50000,5.17502,23979.61617,0.00000,0.03377,297.34857
103.80000,5.18997,23986.01025,0.00000,0.03391,297.42786
104.10000,5.20497,23990.68326,0.00000,0.03405,297.48581
104.40000,5.21998,23995.96274,0.00000,0.03419,297.55127
104.70000,5.23505,24000.05311,0.00000,0.03432,297.60199
105.00000,5.25006,24007.83747,0.00000,0.03447,297.69852
105.30001,5.26500,24007.44110,0.00000,0.03460,297.69360
105.60001,5.28007,24015.91986,0.00000,0.03475,297.79874
105.90001,5.29496,24017.44723,0.00000,0.03489,297.81768
106.20001,5.31008,24024.88887,0.00000,0.03503,297.90996
106.50001,5.32485,24027.63963,0.00000,0.03516,297.94407
106.80001,5.33998,24029.85543,0.00000,0.03530,297.97154
107.10001,5.35505,24037.04971,0.00000,0.03544,298.06075
107.40001,5.36993,24037.50420,0.00000,0.03557,298.06639
107.70001,5.38512,24045.41373,0.00000,0.03572,298.16447
108.00001,5.39989,24048.07359,0.00000,0.03586,298.19745
108.30001,5.41502,24053.76285,0.00000,0.03599,298.26800
108.60001,5.43002,24058.98571,0.00000,0.03614,298.33276
108.90001,5.44503,24062.68716,0.00000,0.03627,298.37866
109.20001,5.46004,24066.94740,0.00000,0.03640,298.43148
109.50001,5.47504,24069.96787,0.00000,0.03653,298.46894
109.80001,5.48999,24077.40653,0.00000,0.03667,298.56118
110.10001,5.50500,24079.70279,0.00000,0.03682,298.58965
110.40001,5.52012,24087.45885,0.00000,0.03696,298.68583
110.70001,5.53495,24086.28017,0.00000,0.03709,298.67121
111.00001,5.55008,24094.46388,0.00000,0.03722,298.77269
111.30001,5.56491,24097.85241,0.00000,0.03736,298.81471
111.60001,5.58003,24101.35269,0.00000,0.03750,298.85811
111.90001,5.59504,24107.42640,0.00000,0.03763,298.93343
112.20001,5.60993,24108.61105,0.00000,0.03777,298.94812
112.50001,5.62517,24115.76062,0.00000,0.03791,299.03677
112.80001,5.63988,24116.41181,0.00000,0.03804,299.04485
113.10001,5.65501,24123.31700,0.00000,0.03817,299.13047
113.40001,5.66996,24127.51913,0.00000,0.03831,299.18258
113.70001,5.68496,24132.48718,0.00000,0.03844,299.24418
114.00001,5.69997,24135.32883,0.00000,0.03858,299.27942
114.30001,5.71504,24138.37314,0.00000,0.03871,299.31717
114.60001,5.73005,24145.02501,0.00000,0.03886,299.39965
114.90001,5.74499,24146.39890,0.00000,0.03899,299.41669
115.20001,5.76006,24154.24883,0.00000,0.03912,299.51403
115.50001,5.77489,24155.69574,0.00000,0.03925,299.53197
115.80001,5.79013,24161.33583,0.00000,0.03939,299.60191
116.10001,5.80490,24163.19996,0.00000,0.03952,299.62502
116.40001,5.81997,24164.69604,0.00000,0.03965,299.64357
116.70001,5.83498,24171.98718,0.00000,0.03978,299.73398
117.00001,5.84986,24173.83343,0.00000,0.03992,299.75688
117.30001,5.86511,24179.88032,0.00000,0.04006,299.83186
117.60001,5.87988,24182.46716,0.00000,0.04019,299.86394
117.90001,5.89500,24187.20573,0.00000,0.04032,299.92269
118.20001,5.91001,24191.02788,0.00000,0.04046,299.97009
118.50001,5.92502,24196.18666,0.00000,0.04059,300.03406
118.80001,5.93997,24198.47548,0.00000,0.04072,300.06244
119.10001,5.95503,24202.13073,0.00000,0.04086,300.10777
119.40001,5.97004,24206.16001,0.00000,0.04099,300.15773
119.70001,5.98493,24206.11829,0.00000,0.04112,300.15721
120.00001,6.00006,24214.47337,0.00000,0.04125,300.26081
120.30001,6.01488,24215.23780,0.00000,0.04138,300.27029
120.60001,6.03007,24220.61563,0.00000,0.04152,300.33698
120.90001,6.04490,24224.74623,0.00000,0.04165,300.38820
121.20001,6.05996,24225.95024,0.00000,0.04178,300.40313
121.50001,6.07509,24232.37413,0.00000,0.04191,300.48279
121.80001,6.08992,24234.32767,0.00000,0.04205,300.50701
122.10001,6.10510,24239.27039,0.00000,0.04218,300.56830
122.40001,6.11993,24241.08684,0.00000,0.04231,300.59082
122.70001,6.13500,24246.15324,0.00000,0.04244,300.65365
123.00001,6.14995,24245.77922,0.00000,0.04256,300.64901
123.30001,6.16507,24253.19999,0.00000,0.04269,300.74103
123.60001,6.17996,24254.86743,0.00000,0.04282,300.76170
123.90001,6.19503,24259.31990,0.00000,0.04296,300.81691
124.20001,6.20998,24263.94075,0.00000,0.04309,300.87421
124.50001,6.22492,24263.81707,0.00000,0.04322,300.87268
124.80001,6.24005,24269.64492,0.00000,0.04335,300.94495
125.10001,6.25488,24270.00850,0.00000,0.04348,300.94945
125.40001,6.27006,24274.71727,0.00000,0.04360,301.00784
125.70001,6.28495,24278.88960,0.00000,0.04373,301.05958
126.00001,6.29996,24280.59131,0.00000,0.04385,301.08068
126.30001,6.31509,24287.48757,0.00000,0.04399,301.16620
126.60001,6.32991,24287.41008,0.00000,0.04412,301.16523
126.90001,6.34516,24293.15150,0.00000,0.04424,301.23643
127.20001,6.35999,24294.32720,0.00000,0.04437,301.25101
127.50001,6.37499,24299.16561,0.00000,0.04450,301.31100
127.80001,6.39000,24302.32167,0.00000,0.04463,301.35014
128.10001,6.40501,24305.69232,0.00000,0.04476,301.39193
128.40001,6.41990,24307.64586,0.00000,0.04489,301.41616
128.70001,6.43502,24309.06296,0.00000,0.04502,301.43373
129.00001,6.45003,24316.19465,0.00000,0.04514,301.52216
129.30001,6.46486,24314.32456,0.00000,0.04527,301.49898
129.60001,6.48004,24322.92253,0.00000,0.04540,301.60559
129.90001,6.49487,24324.26363,0.00000,0.04552,301.62222
130.20001,6.51012,24328.14538,0.00000,0.04565,301.67035
130.50001,6.52507,24332.74835,0.00000,0.04578,301.72743
130.80001,6.54001,24333.55004,0.00000,0.04590,301.73737
131.10001,6.55514,24339.62077,0.00000,0.04603,301.81265
131.40001,6.56997,24340.53570,0.00000,0.04616,301.82399
131.70001,6.58509,24344.06579,0.00000,0.04629,301.86777
132.00001,6.59998,24345.99698,0.00000,0.04641,301.89171
132.30001,6.61505,24349.86979,0.00000,0.04654,301.93974
132.60001,6.62988,24349.87724,0.00000,0.04666,301.93983
132.90001,6.64500,24355.84962,0.00000,0.04678,302.01389
133.20001,6.65995,24360.37809,0.00000,0.04691,302.07004
133.50001,6.67502,24359.33203,0.00000,0.04703,302.05707
133.80001,6.69009,24366.43392,0.00000,0.04717,302.14513
134.10001,6.70485,24364.38650,0.00000,0.04729,302.11975
134.40001,6.72010,24372.60598,0.00000,0.04742,302.22167
134.70001,6.73493,24375.19431,0.00000,0.04754,302.25376
135.00001,6.75005,24379.33236,0.00000,0.04767,302.30508
135.30001,6.76500,24382.83712,0.00000,0.04780,302.34853
135.60001,6.78001,24383.01742,0.00000,0.04792,302.35077
135.90001,6.79514,24387.68446,0.00000,0.04804,302.40864
136.20001,6.80996,24389.26250,0.00000,0.04817,302.42821
136.50001,6.82509,24394.94282,0.00000,0.04829,302.49865
136.80001,6.84004,24397.28677,0.00000,0.04842,302.52771
137.10001,6.85504,24400.44582,0.00000,0.04854,302.56688
137.40001,6.86993,24401.07167,0.00000,0.04867,302.57464
137.70001,6.88506,24405.37065,0.00000,0.04879,302.62795
138.00001,6.89995,24408.60718,0.00000,0.04892,302.66809
138.30001,6.91495,24409.92445,0.00000,0.04904,302.68442
138.60001,6.93002,24416.96376,0.00000,0.04917,302.77171
138.90001,6.94491,24416.71193,0.00000,0.04929,302.76858
139.20001,6.96009,24422.45036,0.00000,0.04942,302.83974
139.50001,6.97492,24424.04181,0.00000,0.04955,302.85948
139.80001,6.99005,24426.94604,0.00000,0.04967,302.89549
140.10001,7.00506,24431.29122,0.00000,0.04980,302.94937
140.40001,7.02000,24432.96164,0.00000,0.04992,302.97008
140.70001,7.03507,24437.04158,0.00000,0.05005,303.02067
141.00001,7.04996,24438.13235,0.00000,0.05018,303.03420
141.30001,7.06509,24441.37782,0.00000,0.05031,303.07444
141.60001,7.07991,24443.89462,0.00000,0.05043,303.10565
141.90001,7.09498,24447.15053,0.00000,0.05056,303.14602
142.20001,7.10999,24448.57508,0.00000,0.05068,303.16369
142.50001,7.12499,24451.60747,0.00000,0.05081,303.20129
142.80001,7.13994,24455.94072,0.00000,0.05093,303.25502
143.10001,7.15495,24456.78115,0.00000,0.05106,303.26544
143.40001,7.17008,24462.82804,0.00000,0.05119,303.34043
143.70001,7.18484,24463.20653,0.00000,0.05132,303.34512
144.00001,7.20003,24468.84662,0.00000,0.05145,303.41506
144.30001,7.21492,24471.35150,0.00000,0.05158,303.44612
144.60001,7.23004,24472.75072,0.00000,0.05170,303.46347
144.90001,7.24499,24475.60281,0.00000,0.05183,303.49883
145.20001,7.25994,24475.79801,0.00000,0.05196,303.50126
145.50001,7.27507,24481.23842,0.00000,0.05208,303.56872
145.80001,7.28989,24483.35886,0.00000,0.05221,303.59501
146.10001,7.30502,24487.96779,0.00000,0.05234,303.65216
146.40001,7.31997,24488.15852,0.00000,0.05247,303.65453
146.70001,7.33503,24492.41281,0.00000,0.05260,303.70728
147.00001,7.34992,24493.32029,0.00000,0.05273,303.71853
147.30001,7.36505,24497.05154,0.00000,0.05286,303.76480
147.60001,7.38000,24501.66941,0.00000,0.05299,303.82206
147.90001,7.39500,24500.31340,0.00000,0.05312,303.80525
148.20001,7.41007,24505.71060,0.00000,0.05325,303.87217
148.50001,7.42484,24503.26085,0.00000,0.05338,303.84180
148.80001,7.44014,24511.50417,0.00000,0.05351,303.94401
149.10001,7.45497,24512.23731,0.00000,0.05364,303.95310
149.40001,7.47004,24515.23393,0.00000,0.05377,303.99026
149.70001,7.48505,24518.07410,0.00000,0.05390,304.02548
150.00001,7.49999,24518.09794,0.00000,0.05403,304.02578
150.30001,7.51506,24521.46113,0.00000,0.05416,304.06748
150.60001,7.52989,24521.68316,0.00000,0.05429,304.07023
150.90001,7.54502,24526.70336,0.00000,0.05443,304.13248
151.20001,7.55996,24528.01764,0.00000,0.05455,304.14878
151.50001,7.57497,24529.95330,0.00000,0.05469,304.17278
151.80001,7.58992,24531.85469,0.00000,0.05481,304.19636
152.10001,7.60504,24535.27153,0.00000,0.05494,304.23873
152.40001,7.61999,24540.21424,0.00000,0.05507,304.30002
152.70001,7.63500,24539.29931,0.00000,0.05520,304.28867
153.00001,7.65013,24544.11685,0.00000,0.05534,304.34841
153.30001,7.66489,24542.81449,0.00000,0.05547,304.33226
153.60001,7.68020,24548.67363,0.00000,0.05560,304.40492
153.90001,7.69491,24548.28471,0.00000,0.05573,304.40009
154.20001,7.71003,24550.13692,0.00000,0.05586,304.42306
154.50001,7.72498,24554.56257,0.00000,0.05599,304.47794
154.80001,7.73993,24553.90990,0.00000,0.05612,304.46985
155.10001,7.75506,24558.09265,0.00000,0.05625,304.52171
155.40001,7.76988,24557.20603,0.00000,0.05638,304.51072
155.70001,7.78501,24562.46316,0.00000,0.05651,304.57591
156.00001,7.79996,24565.02169,0.00000,0.05664,304.60763
156.30001,7.81502,24567.68900,0.00000,0.05677,304.64071
156.60001,7.82997,24570.59473,0.00000,0.05690,304.67674
156.90001,7.84504,24570.35035,0.00000,0.05703,304.67371
157.20001,7.86005,24574.38558,0.00000,0.05716,304.72375
157.50001,7.87499,24572.65258,0.00000,0.05729,304.70226
157.80001,7.89012,24579.17929,0.00000,0.05743,304.78319
158.10001,7.90489,24577.12889,0.00000,0.05756,304.75776
158.40001,7.92013,24582.48883,0.00000,0.05769,304.82423
158.70001,7.93496,24584.38277,0.00000,0.05781,304.84771
159.00001,7.95003,24583.36502,0.00000,0.05794,304.83509
159.30001,7.96504,24587.82494,0.00000,0.05807,304.89040
159.60001,7.97992,24586.26628,0.00000,0.05820,304.87107
159.90001,7.99505,24591.57705,0.00000,0.05833,304.93692
160.20001,8.00988,24591.46678,0.00000,0.05846,304.93555
160.50001,8.02501,24595.50798,0.00000,0.05860,304.98567
160.80001,8.04001,24596.31711,0.00000,0.05872,304.99570
161.10001,8.05502,24598.90097,0.00000,0.05885,305.02774
161.40001,8.06997,24599.13343,0.00000,0.05898,305.03062
161.70001,8.08509,24602.99283,0.00000,0.05910,305.07848
162.00001,8.10004,24605.72720,0.00000,0.05923,305.11238
162.30001,8.11499,24604.31308,0.00000,0.05936,305.09485
162.60001,8.13011,24609.69836,0.00000,0.05949,305.16163
162.90001,8.14488,24607.72097,0.00000,0.05962,305.13711
163.20001,8.16013,24612.16748,0.00000,0.05975,305.19224
163.50001,8.17490,24611.86647,0.00000,0.05988,305.18851
163.80001,8.18996,24612.77694,0.00000,0.06001,305.19980
164.10001,8.20503,24617.83886,0.00000,0.06013,305.26257
164.40001,8.21998,24617.19662,0.00000,0.06026,305.25461
164.70001,8.23505,24620.16940,0.00000,0.06039,305.29147
165.00001,8.24987,24621.10072,0.00000,0.06052,305.30302
165.30001,8.26506,24626.52773,0.00000,0.06064,305.37031
165.60001,8.28001,24626.00619,0.00000,0.06077,305.36384
165.90001,8.29501,24627.99698,0.00000,0.06090,305.38853
166.20001,8.30996,24629.56905,0.00000,0.06102,305.40802
166.50001,8.32509,24630.12785,0.00000,0.06115,305.41495
166.80001,8.33998,24633.19749,0.00000,0.06128,305.45302
167.10001,8.35492,24631.92493,0.00000,0.06141,305.43724
167.40001,8.37011,24637.40855,0.00000,0.06153,305.50523
167.70001,8.38488,24635.89907,0.00000,0.06166,305.48652
168.00001,8.40012,24638.72135,0.00000,0.06178,305.52151
168.30001,8.41495,24639.65714,0.00000,0.06191,305.53312
168.60001,8.42996,24641.67625,0.00000,0.06204,305.55815
168.90001,8.44509,24646.17640,0.00000,0.06216,305.61396
169.20001,8.45991,24644.65052,0.00000,0.06229,305.59504
169.50001,8.47504,24647.79019,0.00000,0.06241,305.63397
169.80001,8.48993,24647.24034,0.00000,0.06254,305.62715
170.10001,8.50500,24651.29048,0.00000,0.06267,305.67737
170.40001,8.51994,24650.49177,0.00000,0.06280,305.66747
170.70001,8.53501,24654.90997,0.00000,0.06292,305.72225
171.00001,8.54996,24655.44194,0.00000,0.06305,305.72885
171.30001,8.56508,24653.18143,0.00000,0.06317,305.70082
171.60001,8.58003,24658.20611,0.00000,0.06329,305.76313
171.90001,8.59492,24654.85930,0.00000,0.06341,305.72163
172.20001,8.61011,24661.46052,0.00000,0.06355,305.80348
172.50001,8.62487,24659.30730,0.00000,0.06367,305.77678
172.80001,8.64006,24664.56145,0.00000,0.06380,305.84193
173.10001,8.65495,24664.45416,0.00000,0.06392,305.84060
173.40001,8.66995,24663.60033,0.00000,0.06404,305.83001
173.70001,8.68502,24668.69205,0.00000,0.06416,305.89315
174.00001,8.69997,24669.03776,0.00000,0.06429,305.89744
174.30001,8.71504,24670.84229,0.00000,0.06441,305.91981
174.60001,8.72998,24670.65454,0.00000,0.06453,305.91749
174.90001,8.74505,24674.07882,0.00000,0.06466,305.95995
175.20001,8.76000,24672.19830,0.00000,0.06478,305.93663
175.50001,8.77507,24675.78948,0.00000,0.06490,305.98116
175.80001,8.78995,24676.97114,0.00000,0.06503,305.99581
176.10001,8.80508,24676.78040,0.00000,0.06514,305.99345
176.40001,8.82003,24679.48198,0.00000,0.06527,306.02695
176.70001,8.83491,24676.38552,0.00000,0.06539,305.98855
177.00001,8.85010,24681.70673,0.00000,0.06551,306.05453
177.30001,8.86487,24683.23559,0.00000,0.06563,306.07349
177.60001,8.88005,24684.78382,0.00000,0.06576,306.09269
177.90001,8.89494,24687.23506,0.00000,0.06588,306.12309
178.20001,8.90989,24686.09810,0.00000,0.06600,306.10899
178.50001,8.92508,24690.81134,0.00000,0.06612,306.16743
178.80001,8.93996,24688.85183,0.00000,0.06624,306.14313
179.10001,8.95503,24691.96022,0.00000,0.06636,306.18168
179.40001,8.96998,24693.13741,0.00000,0.06649,306.19628
179.70001,8.98505,24696.69133,0.00000,0.06662,306.24034
180.00001,8.99993,24693.59338,0.00000,0.06674,306.20193
180.30001,9.01506,24697.83276,0.00000,0.06686,306.25450
180.60001,9.03001,24699.53895,0.00000,0.06699,306.27566
180.90001,9.04501,24697.74634,0.00000,0.06711,306.25343
181.20001,9.06002,24702.58325,0.00000,0.06722,306.31340
181.50001,9.07485,24700.24973,0.00000,0.06734,306.28447
181.80001,9.09009,24705.49643,0.00000,0.06747,306.34953
182.10001,9.10486,24704.58150,0.00000,0.06759,306.33818
182.40001,9.11999,24704.54574,0.00000,0.06771,306.33774
182.70001,9.13500,24708.29487,0.00000,0.06783,306.38423
183.00001,9.14994,24707.57365,0.00000,0.06796,306.37529
183.30001,9.16507,24710.80273,0.00000,0.06808,306.41533
183.60001,9.17996,24708.56011,0.00000,0.06821,306.38752
183.90001,9.19509,24710.90853,0.00000,0.06833,306.41664
184.20001,9.21003,24711.95012,0.00000,0.06845,306.42955
184.50001,9.22504,24714.45650,0.00000,0.06858,306.46063
184.80001,9.23993,24714.77687,0.00000,0.06870,306.46461
185.10001,9.25511,24716.07774,0.00000,0.06882,306.48074
185.40001,9.26994,24716.58140,0.00000,0.06895,306.48698
185.70001,9.28501,24714.65468,0.00000,0.06907,306.46309
186.00001,9.30008,24718.70333,0.00000,0.06919,306.51329
186.30001,9.31490,24716.25060,0.00000,0.06931,306.48288
186.60001,9.33009,24721.94582,0.00000,0.06944,306.55350
186.90001,9.34492,24722.24087,0.00000,0.06956,306.55716
187.20001,9.36005,24722.89652,0.00000,0.06969,306.56529
187.50001,9.37505,24723.80251,0.00000,0.06981,306.57652
187.80001,9.39000,24722.94271,0.00000,0.06993,306.56586
188.10001,9.40513,24726.94963,0.00000,0.07006,306.61555
188.40001,9.41995,24725.92145,0.00000,0.07017,306.60280
188.70001,9.43502,24728.09106,0.00000,0.07029,306.62970
189.00001,9.44997,24725.20620,0.00000,0.07041,306.59393
189.30001,9.46504,24728.60664,0.00000,0.07053,306.63610
189.60001,9.47980,24724.84708,0.00000,0.07066,306.58948
189.90001,9.49505,24729.87026,0.00000,0.07078,306.65177
190.20001,9.50994,24732.78195,0.00000,0.07090,306.68787
190.50001,9.52500,24730.90887,0.00000,0.07103,306.66464
190.80001,9.54007,24734.97987,0.00000,0.07115,306.71512
191.10001,9.55490,24732.34683,0.00000,0.07127,306.68247
191.40001,9.57015,24735.39561,0.00000,0.07139,306.72028
191.70001,9.58491,24736.32842,0.00000,0.07151,306.73185
192.00001,9.59998,24735.81582,0.00000,0.07163,306.72549
192.30001,9.61499,24738.79755,0.00000,0.07175,306.76246
192.60001,9.62999,24736.11534,0.00000,0.07187,306.72920
192.90001,9.64506,24738.62618,0.00000,0.07199,306.76034
193.20001,9.66001,24736.60409,0.00000,0.07211,306.73526
193.50001,9.67502,24741.10425,0.00000,0.07223,306.79107
193.80001,9.69002,24739.87639,0.00000,0.07235,306.77584
194.10001,9.70509,24743.24405,0.00000,0.07248,306.81760
194.40001,9.71992,24740.72427,0.00000,0.07259,306.78636
194.70001,9.73510,24741.76288,0.00000,0.07272,306.79923
195.00001,9.74999,24745.17524,0.00000,0.07284,306.84155
195.30001,9.76494,24741.78523,0.00000,0.07296,306.79951
195.60001,9.78007,24747.63691,0.00000,0.07308,306.87207
195.90001,9.79489,24744.45701,0.00000,0.07320,306.83264
196.20001,9.81014,24747.25842,0.00000,0.07331,306.86738
196.50001,9.82491,24745.83536,0.00000,0.07343,306.84973
196.80001,9.83997,24747.40893,0.00000,0.07355,306.86925
197.10001,9.85510,24751.35475,0.00000,0.07368,306.91817
197.40001,9.86999,24748.51161,0.00000,0.07379,306.88292
197.70001,9.88500,24750.61119,0.00000,0.07392,306.90895
198.00001,9.90000,24749.71414,0.00000,0.07403,306.89783
198.30001,9.91507,24751.83159,0.00000,0.07415,306.92409
198.60001,9.92996,24750.89431,0.00000,0.07427,306.91246
198.90001,9.94503,24753.21591,0.00000,0.07439,306.94125
199.20001,9.95991,24752.92087,0.00000,0.07450,306.93759
199.50001,9.97504,24754.02206,0.00000,0.07462,306.95125
199.80001,9.98999,24757.16472,0.00000,0.07474,306.99022
200.10001,10.00493,24752.93279,0.00000,0.07486,306.93774
200.40001,10.02006,24757.85613,0.00000,0.07498,306.99879
200.70001,10.03489,24756.69682,0.00000,0.07511,306.98442
201.00001,10.05008,24758.42834,0.00000,0.07523,307.00589
201.30001,10.06490,24758.18992,0.00000,0.07534,307.00293
201.60001,10.07997,24758.39257,0.00000,0.07546,307.00544
201.90001,10.09504,24758.03047,0.00000,0.07558,307.00095
202.20001,10.10998,24757.71010,0.00000,0.07569,306.99698
202.50001,10.12505,24759.57274,0.00000,0.07581,307.02008
202.80001,10.13994,24757.65198,0.00000,0.07593,306.99626
203.10001,10.15501,24762.41738,0.00000,0.07605,307.05535
203.40001,10.16995,24760.63818,0.00000,0.07617,307.03329
203.70001,10.18508,24763.12220,0.00000,0.07629,307.06409
204.00001,10.19991,24762.86888,0.00000,0.07641,307.06095
204.30001,10.21503,24762.67368,0.00000,0.07653,307.05853
204.60001,10.22998,24767.57318,0.00000,0.07665,307.11928
204.90001,10.24487,24760.59645,0.00000,0.07677,307.03277
205.20001,10.26012,24765.67328,0.00000,0.07689,307.09572
205.50001,10.27488,24762.35628,0.00000,0.07700,307.05459
205.80001,10.29013,24765.41251,0.00000,0.07712,307.09249
206.10001,10.30502,24768.44043,0.00000,0.07725,307.13004
206.40001,10.31996,24766.36916,0.00000,0.07736,307.10435
206.70001,10.33503,24766.73871,0.00000,0.07748,307.10894
207.00001,10.34998,24765.61219,0.00000,0.07759,307.09497
207.30001,10.36499,24765.78504,0.00000,0.07771,307.09711
207.60001,10.37993,24765.71351,0.00000,0.07783,307.09622
207.90001,10.39506,24770.96766,0.00000,0.07795,307.16138
208.20001,10.40989,24767.84289,0.00000,0.07807,307.12263
208.50001,10.42496,24769.67573,0.00000,0.07819,307.14536
208.80001,10.43990,24769.51331,0.00000,0.07831,307.14334
209.10001,10.45509,24770.49828,0.00000,0.07843,307.15555
209.40001,10.47004,24772.79305,0.00000,0.07855,307.18401
209.70001,10.48492,24769.00816,0.00000,0.07866,307.13708
210.00001,10.50017,24773.10002,0.00000,0.07878,307.18782
210.30001,10.51494,24770.86037,0.00000,0.07890,307.16004
210.60001,10.53007,24771.73358,0.00000,0.07902,307.17087
210.90001,10.54495,24770.10638,0.00000,0.07914,307.15070
211.20001,10.56002,24771.29847,0.00000,0.07926,307.16548
211.50001,10.57503,24773.91362,0.00000,0.07938,307.19791
211.80001,10.58997,24773.18645,0.00000,0.07950,307.18889
212.10001,10.60504,24775.53785,0.00000,0.07961,307.21805
212.40001,10.61999,24772.66788,0.00000,0.07973,307.18246
212.70001,10.63506,24776.13539,0.00000,0.07984,307.22546
213.00001,10.64994,24774.07306,0.00000,0.07997,307.19988
213.30001,10.66501,24775.67345,0.00000,0.08009,307.21973
213.60001,10.67990,24776.61073,0.00000,0.08021,307.23135
213.90001,10.69508,24774.63037,0.00000,0.08033,307.20679
214.20001,10.71003,24777.64338,0.00000,0.08045,307.24415
214.50001,10.72498,24775.10870,0.00000,0.08057,307.21272
214.80001,10.74011,24776.27248,0.00000,0.08068,307.22716
215.10001,10.75487,24774.89710,0.00000,0.08080,307.21010
215.40001,10.77000,24776.61967,0.00000,0.08092,307.23146
215.70001,10.78495,24777.61060,0.00000,0.08105,307.24375
216.00001,10.80001,24776.18605,0.00000,0.08116,307.22608
216.30001,10.81502,24778.97853,0.00000,0.08128,307.26071
216.60001,10.82997,24777.04883,0.00000,0.08140,307.23678
216.90001,10.84504,24780.25407,0.00000,0.08152,307.27653
217.20001,10.85992,24777.09800,0.00000,0.08164,307.23739
217.50001,10.87505,24780.09909,0.00000,0.08176,307.27461
217.80001,10.88994,24775.84332,0.00000,0.08187,307.22183
218.10001,10.90507,24778.76991,0.00000,0.08199,307.25812
218.40001,10.91995,24779.27953,0.00000,0.08212,307.26444
218.70001,10.93502,24775.72858,0.00000,0.08224,307.22041
219.00001,10.95009,24782.26572,0.00000,0.08236,307.30147
219.30001,10.96497,24775.21002,0.00000,0.08248,307.21398
219.60001,10.98016,24777.62401,0.00000,0.08259,307.24391
219.90001,10.99499,24776.61520,0.00000,0.08271,307.23140
220.20001,11.01005,24776.64202,0.00000,0.08283,307.23174
220.50001,11.02494,24777.78941,0.00000,0.08295,307.24597
220.80001,11.03995,24777.22615,0.00000,0.08306,307.23898
221.10001,11.05502,24779.20502,0.00000,0.08319,307.26352
221.40001,11.06996,24775.30986,0.00000,0.08331,307.21522
221.70001,11.08503,24777.78047,0.00000,0.08343,307.24585
222.00001,11.09992,24775.22641,0.00000,0.08355,307.21418
222.30001,11.11505,24778.86826,0.00000,0.08367,307.25934
222.60001,11.12993,24777.33344,0.00000,0.08378,307.24031
222.90001,11.14506,24776.84170,0.00000,0.08390,307.23421
223.20001,11.16001,24775.81799,0.00000,0.08401,307.22152
223.50001,11.17507,24773.42933,0.00000,0.08413,307.19190
223.80001,11.19002,24774.56927,0.00000,0.08425,307.20604
224.10001,11.20491,24771.91240,0.00000,0.08437,307.17309
224.40001,11.22016,24775.78521,0.00000,0.08449,307.22111
224.70001,11.23492,24772.60828,0.00000,0.08461,307.18172
225.00001,11.25005,24773.84061,0.00000,0.08472,307.19700
225.30001,11.26500,24774.51414,0.00000,0.08484,307.20535
225.60001,11.28000,24774.52606,0.00000,0.08495,307.20550
225.90001,11.29501,24775.57510,0.00000,0.08507,307.21851
226.20001,11.30990,24771.87365,0.00000,0.08519,307.17261
226.50001,11.32503,24774.94329,0.00000,0.08530,307.21067
226.80001,11.33997,24771.18820,0.00000,0.08542,307.16411
227.10001,11.35498,24771.42513,0.00000,0.08553,307.16705
227.40001,11.36981,24769.06329,0.00000,0.08565,307.13776
227.70001,11.38506,24772.10313,0.00000,0.08576,307.17545
228.00001,11.39994,24771.10177,0.00000,0.08587,307.16304
228.30001,11.41501,24767.25131,0.00000,0.08599,307.11529
228.60001,11.43008,24770.35671,0.00000,0.08610,307.15380
228.90001,11.44496,24767.40777,0.00000,0.08621,307.11723
229.20001,11.46015,24769.55503,0.00000,0.08632,307.14386
229.50001,11.47492,24767.23641,0.00000,0.08643,307.11511
229.80001,11.48999,24767.56722,0.00000,0.08655,307.11921
230.10001,11.50499,24766.81620,0.00000,0.08666,307.10990
230.40001,11.52000,24764.78368,0.00000,0.08677,307.08469
230.70001,11.53495,24763.03875,0.00000,0.08687,307.06306
231.00001,11.54995,24763.13114,0.00000,0.08698,307.06420
231.30001,11.56502,24763.38148,0.00000,0.08709,307.06731
231.60001,11.57991,24760.91534,0.00000,0.08721,307.03673
231.90001,11.59510,24763.77338,0.00000,0.08731,307.07217
232.20001,11.60998,24759.22555,0.00000,0.08742,307.01577
232.50001,11.62517,24760.02276,0.00000,0.08753,307.02566
232.80001,11.63994,24758.79639,0.00000,0.08764,307.01045
233.10001,11.65500,24756.35856,0.00000,0.08774,306.98022
233.40001,11.67007,24757.81143,0.00000,0.08785,306.99824
233.70001,11.68484,24753.30085,0.00000,0.08795,306.94231
234.00001,11.70015,24755.43916,0.00000,0.08806,306.96882
234.30001,11.71491,24753.09074,0.00000,0.08816,306.93970
234.60001,11.72998,24752.65563,0.00000,0.08826,306.93430
234.90001,11.74499,24753.58248,0.00000,0.08836,306.94580
235.20001,11.76000,24749.94659,0.00000,0.08846,306.90071
235.50001,11.77500,24749.64708,0.00000,0.08857,306.89700
235.80001,11.79001,24746.34647,0.00000,0.08866,306.85607
236.10001,11.80508,24746.64599,0.00000,0.08876,306.85978
236.40001,11.81996,24742.10262,0.00000,0.08885,306.80345
236.70001,11.83503,24741.85526,0.00000,0.08896,306.80038
237.00001,11.84992,24738.22087,0.00000,0.08905,306.75531
237.30001,11.86511,24737.84387,0.00000,0.08914,306.75064
237.60001,11.87999,24738.64853,0.00000,0.08924,306.76062
237.90001,11.89494,24733.23643,0.00000,0.08933,306.69351
238.20001,11.91007,24735.98868,0.00000,0.08942,306.72763
238.50001,11.92483,24730.58105,0.00000,0.08951,306.66058
238.80001,11.94014,24731.50045,0.00000,0.08961,306.67198
239.10001,11.95491,24727.18358,0.00000,0.08970,306.61845
239.40001,11.96992,24723.22732,0.00000,0.08978,306.56939
239.70001,11.98504,24724.27487,0.00000,0.08986,306.58238
240.00001,11.99999,24718.40978,0.00000,0.08995,306.50965
240.30001,12.01500,24718.86426,0.00000,0.09003,306.51529
240.60001,12.03000,24713.68611,0.00000,0.09011,306.45108
240.90001,12.04507,24711.01880,0.00000,0.09019,306.41801
241.20001,12.05996,24705.37275,0.00000,0.09027,306.34799
241.50001,12.07509,24705.88684,0.00000,0.09035,306.35437
241.80001,12.08991,24701.74581,0.00000,0.09043,306.30302
242.10001,12.10510,24698.30811,0.00000,0.09050,306.26039
242.40001,12.11999,24695.28764,0.00000,0.09058,306.22294
242.70001,12.13493,24685.44394,0.00000,0.09065,306.10088
243.00001,12.15012,24685.57060,0.00000,0.09072,306.10245
243.30001,12.16489,24678.46125,0.00000,0.09078,306.01429
243.60001,12.18008,24673.98793,0.00000,0.09084,305.95882
243.90001,12.19496,24668.95729,0.00000,0.09091,305.89644
244.20001,12.20997,24661.76748,0.00000,0.09096,305.80729
244.50001,12.22504,24655.14839,0.00000,0.09103,305.72521
244.80001,12.24004,24645.93351,0.00000,0.09108,305.61094
245.10001,12.25505,24641.29329,0.00000,0.09114,305.55341
245.40001,12.27006,24630.19043,0.00000,0.09119,305.41573
245.70001,12.28513,24625.14937,0.00000,0.09123,305.35322
246.00001,12.29989,24610.06641,0.00000,0.09128,305.16619
246.30001,12.31502,24601.75753,0.00000,0.09133,305.06316
246.60001,12.32991,24590.13611,0.00000,0.09137,304.91905
246.90001,12.34510,24578.09150,0.00000,0.09141,304.76970
247.20001,12.35998,24566.83218,0.00000,0.09145,304.63008
247.50001,12.37499,24546.67240,0.00000,0.09148,304.38010
247.80001,12.39012,24531.36742,0.00000,0.09152,304.19032
248.10001,12.40488,24507.22158,0.00000,0.09154,303.89091
248.40001,12.42013,24485.75348,0.00000,0.09157,303.62470
248.70001,12.43496,24461.08907,0.00000,0.09159,303.31886
249.00001,12.44997,24432.23596,0.00000,0.09161,302.96108
249.30001,12.46497,24387.70533,0.00000,0.09162,302.40890
249.60001,12.48004,24329.58037,0.00000,0.09163,301.68815
249.90001,12.49505,24218.37151,0.00000,0.09163,300.30915
250.11001,12.50563,23460.87843,0.00000,0.09124,290.91620
250.11601,12.50617,21241.86307,0.00000,0.08586,263.40028
250.12201,12.50706,17586.11947,0.00000,0.07353,218.06886
250.12801,12.50814,13510.63699,0.00000,0.05936,167.53265