File: scratch/college-stuff/ME Lab/ME lab Fall 2013/group10/group10.is_tens_RawData/Specimen_RawData_2.csv
Time,Extension,Load,Strain 2,Tensile strain,Tensile stress
(sec),(mm),(N),(mm/mm),(mm/mm),(MPa)
0.00000,0.00000,0.18129,0.00000,0.00000,0.00223
0.30000,0.01357,18.04890,0.00000,0.00000,0.22198
0.60000,0.02995,44.78554,0.00000,0.00001,0.55080
0.90000,0.04502,64.23551,0.00000,0.00001,0.79001
1.20000,0.06003,87.33081,0.00000,0.00000,1.07406
1.50000,0.07504,114.32917,0.00000,0.00000,1.40610
1.80000,0.08998,141.27630,0.00000,0.00000,1.73752
2.10000,0.10511,172.13813,0.00000,0.00000,2.11708
2.40000,0.11988,209.31549,0.00000,0.00000,2.57431
2.70000,0.13512,251.71437,0.00000,-0.00001,3.09576
3.00000,0.14995,296.47534,0.00000,-0.00001,3.64627
3.30000,0.16496,351.81448,0.00000,-0.00001,4.32687
3.60000,0.18003,417.79708,0.00000,-0.00001,5.13837
3.90000,0.19491,489.23772,0.00000,0.00000,6.01700
4.20000,0.21010,581.13271,0.00000,0.00000,7.14719
4.50000,0.22493,692.92542,0.00000,0.00001,8.52209
4.80000,0.24000,816.96343,0.00000,0.00002,10.04760
5.10000,0.25494,950.14349,0.00000,0.00004,11.68555
5.40000,0.27001,1098.73414,0.00000,0.00006,13.51302
5.70000,0.28496,1265.62845,0.00000,0.00008,15.56561
6.00000,0.30002,1430.37997,0.00000,0.00010,17.59184
6.30000,0.31503,1611.66582,0.00000,0.00013,19.82142
6.60000,0.32992,1782.26121,0.00000,0.00016,21.91952
6.90000,0.34505,1965.27820,0.00000,0.00019,24.17040
7.20000,0.35987,2144.41083,0.00000,0.00022,26.37350
7.50000,0.37506,2323.43022,0.00000,0.00024,28.57521
7.80000,0.38989,2500.78645,0.00000,0.00027,30.75646
8.10000,0.40495,2672.42212,0.00000,0.00031,32.86736
8.40000,0.42002,2845.40318,0.00000,0.00034,34.99481
8.70000,0.43485,3012.02070,0.00000,0.00036,37.04399
9.00000,0.45004,3179.34081,0.00000,0.00039,39.10181
9.30000,0.46492,3336.63784,0.00000,0.00042,41.03636
9.60000,0.47999,3496.31868,0.00000,0.00044,43.00023
9.90000,0.49494,3644.02607,0.00000,0.00047,44.81684
10.20000,0.51000,3787.60286,0.00000,0.00049,46.58265
10.50000,0.52501,3924.91408,0.00000,0.00051,48.27140
10.80000,0.53996,4054.34817,0.00000,0.00053,49.86328
11.10000,0.55503,4182.11333,0.00000,0.00055,51.43462
11.40000,0.56991,4300.53845,0.00000,0.00058,52.89110
11.70000,0.58504,4404.23414,0.00000,0.00071,54.16643
12.00000,0.59987,4510.90671,0.00000,0.00072,55.47836
12.30000,0.61499,4625.55736,0.00000,0.00075,56.88842
12.60000,0.62994,4743.83309,0.00000,0.00077,58.34306
12.90000,0.64495,4857.40080,0.00000,0.00079,59.73979
13.20000,0.66002,4978.33602,0.00000,0.00081,61.22714
13.50000,0.67490,5092.37424,0.00000,0.00082,62.62967
13.80000,0.69009,5215.32707,0.00000,0.00085,64.14183
14.10000,0.70498,5333.67172,0.00000,0.00087,65.59731
14.40000,0.72004,5455.29500,0.00000,0.00089,67.09312
14.70000,0.73499,5576.27939,0.00000,0.00091,68.58108
15.00000,0.75006,5697.10508,0.00000,0.00093,70.06708
15.30000,0.76495,5822.35493,0.00000,0.00096,71.60749
15.60000,0.77995,5942.78239,0.00000,0.00097,73.08859
15.90000,0.79502,6071.72847,0.00000,0.00100,74.67446
16.20000,0.80985,6193.08874,0.00000,0.00102,76.16704
16.50000,0.82509,6322.20581,0.00000,0.00104,77.75501
16.80000,0.83986,6445.69919,0.00000,0.00106,79.27382
17.10000,0.85505,6575.01966,0.00000,0.00108,80.86430
17.40000,0.87000,6703.04522,0.00000,0.00111,82.43885
17.70000,0.88494,6829.11351,0.00000,0.00113,83.98933
18.00000,0.90007,6961.22870,0.00000,0.00115,85.61418
18.30000,0.91496,7086.09894,0.00000,0.00117,87.14992
18.60000,0.93009,7219.38983,0.00000,0.00120,88.78923
18.90000,0.94491,7347.99579,0.00000,0.00122,90.37091
19.20000,0.95998,7482.36775,0.00000,0.00124,92.02352
19.50000,0.97493,7613.59558,0.00000,0.00127,93.63745
19.80000,0.99005,7746.78737,0.00000,0.00129,95.27554
20.10000,1.00500,7881.12655,0.00000,0.00132,96.92774
20.40000,1.02001,8011.84028,0.00000,0.00134,98.53535
20.70000,1.03502,8149.33851,0.00000,0.00136,100.22640
21.00000,1.04990,8282.99299,0.00000,0.00139,101.87018
21.30000,1.06503,8421.44266,0.00000,0.00141,103.57293
21.60000,1.07992,8556.31009,0.00000,0.00144,105.23163
21.90000,1.09504,8692.80621,0.00000,0.00146,106.91036
22.20000,1.10999,8829.89392,0.00000,0.00149,108.59636
22.50000,1.12500,8967.29156,0.00000,0.00151,110.28617
22.80000,1.14007,9106.19423,0.00000,0.00154,111.99450
23.10000,1.15489,9244.44348,0.00000,0.00156,113.69479
23.40000,1.17008,9386.54169,0.00000,0.00159,115.44241
23.70000,1.18491,9522.37323,0.00000,0.00161,117.11297
24.00000,1.20003,9666.32962,0.00000,0.00164,118.88344
24.30000,1.21492,9806.08538,0.00000,0.00166,120.60226
24.60000,1.23005,9947.28208,0.00000,0.00169,122.33880
24.90000,1.24500,10094.12780,0.00000,0.00172,124.14481
25.20000,1.25994,10230.01373,0.00000,0.00175,125.81603
25.50000,1.27507,10375.19425,0.00000,0.00177,127.60157
25.80000,1.28990,10516.02662,0.00000,0.00180,129.33363
26.10000,1.30503,10658.93620,0.00000,0.00182,131.09123
26.40000,1.31985,10803.30163,0.00000,0.00186,132.86674
26.70000,1.33504,10947.28932,0.00000,0.00188,134.63760
27.00000,1.35005,11092.04888,0.00000,0.00191,136.41796
27.30000,1.36499,11234.04726,0.00000,0.00194,138.16436
27.60000,1.38006,11379.76721,0.00000,0.00196,139.95653
27.90000,1.39495,11522.85337,0.00000,0.00199,141.71630
28.20000,1.41002,11672.42378,0.00000,0.00202,143.55583
28.50000,1.42490,11815.38999,0.00000,0.00205,145.31413
28.80000,1.44003,11963.22143,0.00000,0.00207,147.13226
29.10000,1.45492,12108.33713,0.00000,0.00210,148.91700
29.40000,1.47004,12254.45569,0.00000,0.00213,150.71407
29.70000,1.48493,12404.07526,0.00000,0.00216,152.55420
30.00000,1.49994,12549.91740,0.00000,0.00219,154.34787
30.30000,1.51507,12699.26429,0.00000,0.00222,156.18465
30.60000,1.52989,12843.39875,0.00000,0.00224,157.95732
30.90000,1.54502,12990.79657,0.00000,0.00227,159.77012
31.20000,1.55991,13137.86656,0.00000,0.00230,161.57889
31.50000,1.57497,13285.14516,0.00000,0.00233,163.39023
31.80000,1.58998,13436.49179,0.00000,0.00236,165.25160
32.10000,1.60493,13583.86129,0.00000,0.00239,167.06405
32.40000,1.62012,13734.82347,0.00000,0.00242,168.92069
32.70000,1.63488,13878.31420,0.00000,0.00244,170.68545
33.00000,1.65001,14033.53065,0.00000,0.00248,172.59441
33.30000,1.66496,14180.40991,0.00000,0.00250,174.40084
33.60000,1.68003,14332.65507,0.00000,0.00254,176.27326
33.90000,1.69491,14481.89616,0.00000,0.00257,178.10873
34.20000,1.70998,14629.41617,0.00000,0.00260,179.92304
34.50000,1.72499,14781.88336,0.00000,0.00263,181.79819
34.80000,1.73987,14925.53949,0.00000,0.00266,183.56497
35.10000,1.75500,15080.41918,0.00000,0.00269,185.46979
35.40000,1.76989,15228.24764,0.00000,0.00272,187.28790
35.70000,1.78508,15379.46463,0.00000,0.00276,189.14767
36.00000,1.79990,15528.71466,0.00000,0.00279,190.98325
36.30000,1.81503,15680.65435,0.00000,0.00283,192.85192
36.60000,1.83004,15832.26919,0.00000,0.00286,194.71658
36.90000,1.84492,15982.03927,0.00000,0.00289,196.55856
37.20000,1.86005,16134.94158,0.00000,0.00293,198.43907
37.50000,1.87488,16283.23346,0.00000,0.00296,200.26287
37.80000,1.89007,16436.42932,0.00000,0.00299,202.14698
38.10000,1.90483,16580.09440,0.00000,0.00303,203.91387
38.40000,1.91996,16735.84133,0.00000,0.00307,205.82936
38.70000,1.93491,16885.87070,0.00000,0.00310,207.67453
39.00000,1.95003,17031.07208,0.00000,0.00314,209.46032
39.30000,1.96498,17184.13383,0.00000,0.00318,211.34278
39.60000,1.97987,17326.58148,0.00000,0.00321,213.09471
39.90000,1.99512,17479.86674,0.00000,0.00325,214.97992
40.20000,2.00994,17624.61662,0.00000,0.00329,216.76016
40.50000,2.02507,17771.90268,0.00000,0.00333,218.57159
40.80000,2.03990,17916.83286,0.00000,0.00336,220.35404
41.10000,2.05502,18060.28634,0.00000,0.00340,222.11834
41.40000,2.07003,18204.21070,0.00000,0.00344,223.88842
41.70000,2.08498,18343.07015,0.00000,0.00348,225.59621
42.00000,2.09999,18486.84698,0.00000,0.00352,227.36448
42.30000,2.11493,18623.47871,0.00000,0.00356,229.04488
42.60000,2.13000,18763.18157,0.00000,0.00361,230.76304
42.90000,2.14489,18895.13433,0.00000,0.00365,232.38589
43.20000,2.16001,19030.12395,0.00000,0.00370,234.04609
43.50000,2.17490,19158.23817,0.00000,0.00374,235.62173
43.80000,2.19003,19285.43597,0.00000,0.00379,237.18610
44.10000,2.20504,19412.74554,0.00000,0.00385,238.75185
44.40000,2.21992,19531.17847,0.00000,0.00389,240.20842
44.70000,2.23511,19652.71533,0.00000,0.00395,241.70317
45.00000,2.24988,19763.19402,0.00000,0.00401,243.06191
45.30000,2.26506,19876.78856,0.00000,0.00407,244.45898
45.60000,2.27995,19982.15020,0.00000,0.00414,245.75479
45.90000,2.29502,20082.86715,0.00000,0.00420,246.99348
46.20000,2.31003,20180.33266,0.00000,0.00427,248.19218
46.50000,2.32491,20266.21550,0.00000,0.00434,249.24843
46.80000,2.34004,20352.46193,0.00000,0.00442,250.30915
47.10000,2.35487,20427.22851,0.00000,0.00450,251.22868
47.40000,2.37000,20502.33334,0.00000,0.00458,252.15238
47.70000,2.38494,20566.85984,0.00000,0.00468,252.94597
48.00000,2.40001,20627.47926,0.00000,0.00477,253.69151
48.30000,2.41496,20683.91889,0.00000,0.00487,254.38565
48.60000,2.43008,20732.36555,0.00000,0.00498,254.98148
48.90000,2.44509,20783.87588,0.00000,0.00509,255.61499
49.20000,2.45998,20823.08680,0.00000,0.00520,256.09723
49.50000,2.47517,20864.73554,0.00000,0.00532,256.60946
49.80000,2.48999,20899.61469,0.00000,0.00544,257.03843
50.10000,2.50506,20931.79375,0.00000,0.00557,257.43419
50.40000,2.51995,20963.54663,0.00000,0.00569,257.82471
50.70000,2.53495,20996.02520,0.00000,0.00583,258.22415
51.00000,2.55002,21021.44063,0.00000,0.00597,258.53673
51.30000,2.56497,21047.35523,0.00000,0.00610,258.85545
51.60000,2.58004,21071.68734,0.00000,0.00623,259.15470
51.90000,2.59492,21090.13647,0.00000,0.00637,259.38160
52.20000,2.61005,21114.84110,0.00000,0.00651,259.68544
52.50000,2.62494,21131.47080,0.00000,0.00665,259.88996
52.80000,2.64006,21152.43822,0.00000,0.00679,260.14783
53.10000,2.65495,21172.35214,0.00000,0.00694,260.39275
53.40000,2.67008,21186.02842,0.00000,0.00709,260.56095
53.70000,2.68509,21204.66828,0.00000,0.00724,260.79020
54.00000,2.69991,21217.92734,0.00000,0.00739,260.95327
54.30000,2.71516,21236.33325,0.00000,0.00754,261.17963
54.60000,2.72993,21248.22438,0.00000,0.00768,261.32588
54.90000,2.74500,21264.13733,0.00000,0.00784,261.52159
55.20000,2.75994,21277.64523,0.00000,0.00799,261.68772
55.50000,2.77501,21287.81527,0.00000,0.00814,261.81280
55.80000,2.79002,21303.34228,0.00000,0.00830,262.00376
56.10000,2.80496,21313.51978,0.00000,0.00845,262.12893
56.40000,2.82003,21327.55071,0.00000,0.00861,262.30149
56.70000,2.83492,21334.82099,0.00000,0.00876,262.39091
57.00000,2.84993,21349.47479,0.00000,0.00892,262.57113
57.30000,2.86493,21358.91020,0.00000,0.00908,262.68717
57.60000,2.88006,21369.89087,0.00000,0.00924,262.82222
57.90000,2.89495,21382.61944,0.00000,0.00940,262.97877
58.20000,2.91001,21391.08628,0.00000,0.00955,263.08290
58.50000,2.92502,21404.35278,0.00000,0.00971,263.24606
58.80000,2.93997,21410.92271,0.00000,0.00987,263.32686
59.10000,2.95516,21423.43968,0.00000,0.01003,263.48080
59.40000,2.96992,21429.93659,0.00000,0.01019,263.56071
59.70000,2.98505,21441.61761,0.00000,0.01035,263.70437
60.00000,2.99994,21449.81772,0.00000,0.01052,263.80522
60.30000,3.01494,21458.52298,0.00000,0.01067,263.91228
60.60000,3.03001,21469.36804,0.00000,0.01083,264.04566
60.90000,3.04496,21476.15850,0.00000,0.01099,264.12918
61.20000,3.06015,21488.66951,0.00000,0.01115,264.28305
61.50000,3.07491,21492.33222,0.00000,0.01132,264.32809
61.80000,3.08998,21504.86559,0.00000,0.01148,264.48224
62.10000,3.10493,21512.96735,0.00000,0.01164,264.58188
62.40000,3.12011,21522.20756,0.00000,0.01180,264.69552
62.70000,3.13494,21531.17657,0.00000,0.01196,264.80583
63.00000,3.15001,21536.52310,0.00000,0.01212,264.87158
63.30000,3.16502,21547.83159,0.00000,0.01229,265.01066
63.60000,3.17990,21554.82024,0.00000,0.01245,265.09662
63.90000,3.19509,21563.42268,0.00000,0.01261,265.20241
64.20000,3.20992,21571.88803,0.00000,0.01277,265.30653
64.50000,3.22505,21580.51133,0.00000,0.01293,265.41258
64.80000,3.23999,21587.69816,0.00000,0.01309,265.50097
65.10000,3.25494,21593.99539,0.00000,0.01325,265.57842
65.40000,3.27001,21604.69741,0.00000,0.01341,265.71004
65.70000,3.28495,21610.07524,0.00000,0.01357,265.77618
66.00000,3.30002,21622.24352,0.00000,0.01373,265.92584
66.30000,3.31497,21625.30720,0.00000,0.01389,265.96351
66.60000,3.33004,21635.58304,0.00000,0.01404,266.08989
66.90000,3.34486,21642.62235,0.00000,0.01421,266.17647
67.20000,3.36005,21651.56752,0.00000,0.01437,266.28648
67.50000,3.37506,21661.31437,0.00000,0.01452,266.40636
67.80000,3.39000,21664.05320,0.00000,0.01468,266.44004
68.10000,3.40507,21675.19182,0.00000,0.01484,266.57703
68.40000,3.41990,21680.73803,0.00000,0.01500,266.64524
68.70000,3.43509,21689.98122,0.00000,0.01515,266.75892
69.00000,3.44985,21695.82546,0.00000,0.01531,266.83080
69.30000,3.46492,21704.00321,0.00000,0.01548,266.93137
69.60000,3.47999,21712.94242,0.00000,0.01564,267.04132
69.90000,3.49499,21717.21458,0.00000,0.01579,267.09386
70.20000,3.51000,21726.70364,0.00000,0.01594,267.21056
70.50000,3.52495,21732.22005,0.00000,0.01610,267.27841
70.80000,3.54014,21743.37059,0.00000,0.01626,267.41554
71.10000,3.55496,21746.52815,0.00000,0.01642,267.45438
71.40000,3.57009,21757.21526,0.00000,0.01658,267.58581
71.70000,3.58492,21762.28613,0.00000,0.01674,267.64818
72.00000,3.60010,21770.83939,0.00000,0.01689,267.75337
72.30000,3.61493,21779.36882,0.00000,0.01705,267.85827
72.60000,3.62994,21784.49780,0.00000,0.01720,267.92135
72.90000,3.64507,21794.49648,0.00000,0.01736,268.04433
73.20000,3.65983,21796.80169,0.00000,0.01752,268.07268
73.50000,3.67508,21805.82434,0.00000,0.01767,268.18364
73.80000,3.68991,21813.50440,0.00000,0.01782,268.27810
74.10000,3.70498,21822.84594,0.00000,0.01797,268.39299
74.40000,3.72004,21830.65861,0.00000,0.01813,268.48907
74.70000,3.73505,21836.03346,0.00000,0.01829,268.55518
75.00000,3.75006,21843.46765,0.00000,0.01845,268.64661
75.30000,3.76506,21848.99449,0.00000,0.01860,268.71458
75.60000,3.78007,21859.20626,0.00000,0.01876,268.84017
75.90000,3.79484,21862.19692,0.00000,0.01891,268.87695
76.20000,3.81009,21873.70956,0.00000,0.01906,269.01854
76.50000,3.82491,21877.65539,0.00000,0.01921,269.06707
76.80000,3.84010,21885.19686,0.00000,0.01937,269.15982
77.10000,3.85499,21892.65937,0.00000,0.01953,269.25160
77.40000,3.86999,21897.69298,0.00000,0.01968,269.31351
77.70000,3.88512,21907.65440,0.00000,0.01984,269.43602
78.00000,3.89989,21910.95799,0.00000,0.01998,269.47665
78.30000,3.91508,21919.78246,0.00000,0.02014,269.58518
78.60000,3.92996,21924.95316,0.00000,0.02029,269.64878
78.90000,3.94497,21931.98651,0.00000,0.02044,269.73528
79.20000,3.96004,21941.25205,0.00000,0.02059,269.84923
79.50000,3.97504,21946.16646,0.00000,0.02074,269.90967
79.80000,3.98999,21954.08642,0.00000,0.02090,270.00708
80.10000,4.00506,21959.24670,0.00000,0.02105,270.07054
80.40000,4.02013,21969.64175,0.00000,0.02120,270.19839
80.70000,4.03489,21971.28832,0.00000,0.02135,270.21864
81.00000,4.05008,21982.12594,0.00000,0.02150,270.35193
81.30000,4.06491,21987.93590,0.00000,0.02166,270.42338
81.60000,4.08009,21993.59834,0.00000,0.02181,270.49302
81.90000,4.09498,22002.87730,0.00000,0.02196,270.60714
82.20000,4.10987,22004.15432,0.00000,0.02210,270.62285
82.50000,4.12506,22015.24675,0.00000,0.02225,270.75927
82.80000,4.13988,22020.32059,0.00000,0.02240,270.82167
83.10000,4.15501,22028.14519,0.00000,0.02256,270.91790
83.40000,4.16990,22035.00271,0.00000,0.02271,271.00224
83.70000,4.18497,22042.94056,0.00000,0.02286,271.09987
84.00000,4.20003,22049.26908,0.00000,0.02301,271.17770
84.30000,4.21504,22054.08812,0.00000,0.02315,271.23697
84.60000,4.22999,22061.83076,0.00000,0.02330,271.33219
84.90000,4.24499,22067.54833,0.00000,0.02345,271.40251
85.20000,4.26006,22076.30426,0.00000,0.02361,271.51020
85.50000,4.27483,22078.36062,0.00000,0.02376,271.53549
85.80000,4.29008,22088.02998,0.00000,0.02390,271.65441
86.10000,4.30490,22093.99939,0.00000,0.02405,271.72783
86.40000,4.32003,22097.92286,0.00000,0.02420,271.77608
86.70000,4.33504,22107.83809,0.00000,0.02435,271.89803
87.00000,4.34986,22110.89134,0.00000,0.02449,271.93558
87.30000,4.36517,22120.01681,0.00000,0.02465,272.04781
87.60000,4.37994,22124.95059,0.00000,0.02479,272.10849
87.90000,4.39501,22130.03784,0.00000,0.02494,272.17105
88.20000,4.41001,22137.99953,0.00000,0.02509,272.26897
88.50000,4.42496,22143.87506,0.00000,0.02524,272.34123
88.80000,4.43997,22150.46585,0.00000,0.02538,272.42229
89.10000,4.45503,22154.91533,0.00000,0.02553,272.47701
89.40000,4.47004,22163.11395,0.00000,0.02569,272.57785
89.70000,4.48499,22165.36552,0.00000,0.02583,272.60554
90.00000,4.50006,22177.18959,0.00000,0.02597,272.75096
90.30000,4.51488,22179.13270,0.00000,0.02612,272.77486
90.60000,4.53007,22187.81412,0.00000,0.02627,272.88163
90.90000,4.54490,22193.59726,0.00000,0.02641,272.95275
91.20000,4.55996,22196.50596,0.00000,0.02656,272.98853
91.50000,4.57503,22205.71637,0.00000,0.02671,273.10180
91.80000,4.58986,22208.87095,0.00000,0.02685,273.14060
92.10000,4.60511,22218.47773,0.00000,0.02700,273.25875
92.40000,4.61987,22223.34892,0.00000,0.02715,273.31866
92.70000,4.63506,22231.14371,0.00000,0.02729,273.41453
93.00000,4.65001,22235.71539,0.00000,0.02743,273.47075
93.30000,4.66502,22243.04676,0.00000,0.02758,273.56092
93.60000,4.68002,22248.59744,0.00000,0.02773,273.62918
93.90000,4.69503,22252.80404,0.00000,0.02788,273.68092
94.20000,4.70998,22261.38115,0.00000,0.02802,273.78641
94.50000,4.72492,22262.21710,0.00000,0.02817,273.79669
94.80000,4.73999,22272.73434,0.00000,0.02831,273.92604
95.10000,4.75482,22273.88769,0.00000,0.02845,273.94022
95.40000,4.77001,22282.43947,0.00000,0.02859,274.04540
95.70000,4.78489,22290.33411,0.00000,0.02874,274.14249
96.00000,4.79996,22293.00290,0.00000,0.02888,274.17531
96.30000,4.81503,22301.95254,0.00000,0.02903,274.28538
96.60000,4.82991,22304.01635,0.00000,0.02917,274.31077
96.90000,4.84516,22311.88416,0.00000,0.02932,274.40753
97.20000,4.85999,22315.90599,0.00000,0.02946,274.45699
97.50000,4.87506,22324.48310,0.00000,0.02960,274.56248
97.80000,4.88994,22328.46022,0.00000,0.02975,274.61139
98.10000,4.90507,22336.07769,0.00000,0.02990,274.70508
98.40000,4.92002,22339.31571,0.00000,0.03004,274.74490
98.70000,4.93502,22345.48628,0.00000,0.03018,274.82079
99.00000,4.95003,22352.29462,0.00000,0.03032,274.90453
99.30000,4.96498,22354.64007,0.00000,0.03046,274.93337
99.60000,4.98005,22363.34085,0.00000,0.03060,275.04038
99.90000,4.99487,22365.52089,0.00000,0.03075,275.06719
100.20000,5.01006,22373.26205,0.00000,0.03089,275.16240
100.50000,5.02495,22378.79336,0.00000,0.03104,275.23043
100.80000,5.04002,22382.14761,0.00000,0.03118,275.27168
101.10000,5.05508,22391.69627,0.00000,0.03132,275.38912
101.40000,5.06997,22394.39040,0.00000,0.03145,275.42225
101.70000,5.08516,22400.37769,0.00000,0.03159,275.49589
102.00000,5.09992,22402.69780,0.00000,0.03173,275.52442
102.30000,5.11505,22411.02904,0.00000,0.03187,275.62688
102.60000,5.13000,22416.06861,0.00000,0.03202,275.68886
102.90000,5.14501,22421.21547,0.00000,0.03216,275.75216
103.20000,5.15995,22428.24286,0.00000,0.03230,275.83859
103.50000,5.17502,22431.77593,0.00000,0.03244,275.88204
103.80000,5.19003,22437.80345,0.00000,0.03258,275.95618
104.10000,5.20497,22437.86603,0.00000,0.03271,275.95695
104.40000,5.21998,22446.86782,0.00000,0.03285,276.06766
104.70000,5.23487,22452.33953,0.00000,0.03300,276.13495
105.00000,5.25006,22458.08691,0.00000,0.03313,276.20564
105.30001,5.26494,22464.58083,0.00000,0.03327,276.28550
105.60001,5.28001,22467.30924,0.00000,0.03341,276.31906
105.90001,5.29508,22475.14129,0.00000,0.03355,276.41538
106.20001,5.30996,22478.29735,0.00000,0.03369,276.45420
106.50001,5.32509,22484.78830,0.00000,0.03383,276.53403
106.80001,5.33992,22487.89668,0.00000,0.03397,276.57226
107.10001,5.35505,22494.44127,0.00000,0.03411,276.65275
107.40001,5.36993,22495.81963,0.00000,0.03425,276.66970
107.70001,5.38500,22503.08841,0.00000,0.03438,276.75910
108.00001,5.40001,22508.43197,0.00000,0.03452,276.82482
108.30001,5.41495,22510.79530,0.00000,0.03465,276.85388
108.60001,5.43002,22520.08021,0.00000,0.03479,276.96807
108.90001,5.44497,22521.64483,0.00000,0.03493,276.98732
109.20001,5.46010,22527.98527,0.00000,0.03507,277.06530
109.50001,5.47492,22532.89819,0.00000,0.03521,277.12572
109.80001,5.49005,22537.85282,0.00000,0.03535,277.18665
110.10001,5.50500,22545.23933,0.00000,0.03548,277.27750
110.40001,5.52001,22546.00674,0.00000,0.03562,277.28694
110.70001,5.53513,22552.74206,0.00000,0.03576,277.36977
111.00001,5.54996,22555.98158,0.00000,0.03589,277.40961
111.30001,5.56509,22561.20145,0.00000,0.03603,277.47381
111.60001,5.57997,22565.70011,0.00000,0.03617,277.52914
111.90001,5.59504,22571.40875,0.00000,0.03631,277.59935
112.20001,5.60993,22574.55140,0.00000,0.03644,277.63800
112.50001,5.62506,22578.77588,0.00000,0.03657,277.68996
112.80001,5.64000,22584.26845,0.00000,0.03671,277.75751
113.10001,5.65501,22587.12202,0.00000,0.03685,277.79260
113.40001,5.67008,22595.04646,0.00000,0.03698,277.89006
113.70001,5.68484,22595.36535,0.00000,0.03712,277.89398
114.00001,5.70003,22603.15567,0.00000,0.03726,277.98980
114.30001,5.71486,22606.98229,0.00000,0.03739,278.03686
114.60001,5.73011,22612.24240,0.00000,0.03752,278.10155
114.90001,5.74499,22616.67401,0.00000,0.03765,278.15605
115.20001,5.75994,22618.25353,0.00000,0.03779,278.17548
115.50001,5.77507,22627.83349,0.00000,0.03792,278.29330
115.80001,5.78995,22628.41463,0.00000,0.03806,278.30045
116.10001,5.80508,22634.95028,0.00000,0.03820,278.38083
116.40001,5.81991,22635.87862,0.00000,0.03833,278.39225
116.70001,5.83504,22644.02509,0.00000,0.03846,278.49244
117.00001,5.84998,22646.77435,0.00000,0.03859,278.52625
117.30001,5.86493,22650.67250,0.00000,0.03872,278.57419
117.60001,5.87994,22656.79985,0.00000,0.03885,278.64955
117.90001,5.89500,22658.65505,0.00000,0.03899,278.67237
118.20001,5.91007,22664.96420,0.00000,0.03912,278.74996
118.50001,5.92490,22666.91178,0.00000,0.03925,278.77391
118.80001,5.94003,22673.78271,0.00000,0.03939,278.85842
119.10001,5.95491,22677.65850,0.00000,0.03952,278.90608
119.40001,5.97010,22681.99027,0.00000,0.03964,278.95936
119.70001,5.98499,22686.02699,0.00000,0.03977,279.00901
120.00001,6.00000,22687.76298,0.00000,0.03991,279.03036
120.30001,6.01506,22693.34197,0.00000,0.04004,279.09897
120.60001,6.02983,22695.55032,0.00000,0.04018,279.12613
120.90001,6.04502,22702.13217,0.00000,0.04031,279.20708
121.20001,6.05996,22703.93074,0.00000,0.04044,279.22920
121.50001,6.07497,22710.42913,0.00000,0.04057,279.30912
121.80001,6.08998,22712.06379,0.00000,0.04069,279.32923
122.10001,6.10499,22716.41046,0.00000,0.04083,279.38268
122.40001,6.11999,22723.09214,0.00000,0.04095,279.46486
122.70001,6.13500,22724.74468,0.00000,0.04109,279.48518
123.00001,6.15007,22730.93313,0.00000,0.04122,279.56129
123.30001,6.16489,22729.54285,0.00000,0.04135,279.54420
123.60001,6.18008,22736.07105,0.00000,0.04148,279.62448
123.90001,6.19491,22738.52080,0.00000,0.04161,279.65461
124.20001,6.21010,22743.62296,0.00000,0.04174,279.71736
124.50001,6.22504,22748.80856,0.00000,0.04187,279.78114
124.80001,6.23999,22751.10185,0.00000,0.04200,279.80934
125.10001,6.25512,22755.88512,0.00000,0.04212,279.86817
125.40001,6.26994,22757.45571,0.00000,0.04225,279.88749
125.70001,6.28501,22761.54011,0.00000,0.04238,279.93772
126.00001,6.29990,22765.28031,0.00000,0.04251,279.98372
126.30001,6.31497,22770.76393,0.00000,0.04264,280.05116
126.60001,6.32997,22773.65029,0.00000,0.04276,280.08666
126.90001,6.34498,22775.79606,0.00000,0.04289,280.11305
127.20001,6.35999,22781.12173,0.00000,0.04302,280.17855
127.50001,6.37505,22783.11998,0.00000,0.04315,280.20313
127.80001,6.39012,22789.76887,0.00000,0.04328,280.28490
128.10001,6.40495,22788.81073,0.00000,0.04341,280.27311
128.40001,6.42014,22796.22108,0.00000,0.04354,280.36425
128.70001,6.43496,22797.53089,0.00000,0.04366,280.38036
129.00001,6.45009,22800.11773,0.00000,0.04378,280.41218
129.30001,6.46498,22805.77123,0.00000,0.04391,280.48171
129.60001,6.47993,22806.70702,0.00000,0.04403,280.49322
129.90001,6.49511,22813.29930,0.00000,0.04416,280.57429
130.20001,6.50988,22812.78670,0.00000,0.04429,280.56799
130.50001,6.52501,22817.55656,0.00000,0.04441,280.62665
130.80001,6.53995,22821.47557,0.00000,0.04454,280.67485
131.10001,6.55502,22826.04873,0.00000,0.04467,280.73109
131.40001,6.57003,22829.85747,0.00000,0.04479,280.77794
131.70001,6.58498,22831.98535,0.00000,0.04491,280.80411
132.00001,6.60004,22838.12612,0.00000,0.04504,280.87963
132.30001,6.61505,22838.91290,0.00000,0.04516,280.88931
132.60001,6.63006,22843.10907,0.00000,0.04529,280.94091
132.90001,6.64488,22845.22802,0.00000,0.04541,280.96697
133.20001,6.66013,22850.36147,0.00000,0.04554,281.03011
133.50001,6.67484,22852.87082,0.00000,0.04566,281.06097
133.80001,6.69003,22855.53813,0.00000,0.04578,281.09378
134.10001,6.70503,22860.57174,0.00000,0.04591,281.15568
134.40001,6.71992,22862.53572,0.00000,0.04603,281.17984
134.70001,6.73511,22867.33985,0.00000,0.04616,281.23892
135.00001,6.74993,22869.05348,0.00000,0.04628,281.26000
135.30001,6.76500,22874.46409,0.00000,0.04641,281.32654
135.60001,6.77995,22875.50420,0.00000,0.04653,281.33933
135.90001,6.79502,22879.28015,0.00000,0.04665,281.38577
136.20001,6.80996,22881.23667,0.00000,0.04678,281.40983
136.50001,6.82509,22885.56397,0.00000,0.04690,281.46305
136.80001,6.84004,22889.57536,0.00000,0.04702,281.51239
137.10001,6.85504,22891.46781,0.00000,0.04715,281.53566
137.40001,6.87011,22895.86365,0.00000,0.04727,281.58973
137.70001,6.88494,22896.37774,0.00000,0.04740,281.59605
138.00001,6.90013,22900.13134,0.00000,0.04752,281.64221
138.30001,6.91495,22902.67944,0.00000,0.04765,281.67355
138.60001,6.93002,22905.76994,0.00000,0.04777,281.71156
138.90001,6.94509,22911.28039,0.00000,0.04789,281.77933
139.20001,6.95986,22910.46828,0.00000,0.04801,281.76935
139.50001,6.97510,22916.59117,0.00000,0.04813,281.84465
139.80001,6.98993,22918.04850,0.00000,0.04825,281.86257
140.10001,7.00500,22923.02251,0.00000,0.04838,281.92375
140.40001,7.01994,22925.96698,0.00000,0.04850,281.95996
140.70001,7.03501,22929.83979,0.00000,0.04863,282.00759
141.00001,7.04996,22930.89181,0.00000,0.04875,282.02053
141.30001,7.06509,22934.27885,0.00000,0.04887,282.06219
141.60001,7.08003,22938.78049,0.00000,0.04899,282.11755
141.90001,7.09498,22937.57200,0.00000,0.04911,282.10269
142.20001,7.11005,22944.19706,0.00000,0.04924,282.18417
142.50001,7.12487,22943.78132,0.00000,0.04936,282.17905
142.80001,7.14006,22948.46475,0.00000,0.04949,282.23665
143.10001,7.15495,22950.06514,0.00000,0.04961,282.25634
143.40001,7.16996,22951.62529,0.00000,0.04973,282.27552
143.70001,7.18502,22958.39638,0.00000,0.04985,282.35880
144.00001,7.19985,22959.29044,0.00000,0.04997,282.36980
144.30001,7.21510,22964.60420,0.00000,0.05009,282.43515
144.60001,7.22992,22964.59675,0.00000,0.05022,282.43506
144.90001,7.24499,22968.70947,0.00000,0.05034,282.48564
145.20001,7.26000,22970.53784,0.00000,0.05047,282.50812
145.50001,7.27507,22974.34658,0.00000,0.05059,282.55497
145.80001,7.28989,22975.73686,0.00000,0.05071,282.57207
146.10001,7.30508,22978.45185,0.00000,0.05084,282.60546
146.40001,7.32003,22983.26194,0.00000,0.05096,282.66461
146.70001,7.33491,22979.87044,0.00000,0.05108,282.62290
147.00001,7.35016,22988.10780,0.00000,0.05120,282.72421
147.30001,7.36487,22987.14966,0.00000,0.05132,282.71243
147.60001,7.38012,22993.86114,0.00000,0.05145,282.79497
147.90001,7.39494,22996.47629,0.00000,0.05157,282.82713
148.20001,7.40995,22996.28556,0.00000,0.05170,282.82479
148.50001,7.42508,23001.77515,0.00000,0.05182,282.89230
148.80001,7.43991,23000.84680,0.00000,0.05194,282.88089
149.10001,7.45503,23005.02360,0.00000,0.05206,282.93225
149.40001,7.46992,23006.96373,0.00000,0.05218,282.95612
149.70001,7.48505,23011.75594,0.00000,0.05230,283.01505
150.00001,7.49999,23011.83939,0.00000,0.05243,283.01608
150.30001,7.51506,23016.25758,0.00000,0.05255,283.07042
150.60001,7.53001,23018.22305,0.00000,0.05268,283.09459
150.90001,7.54507,23019.47176,0.00000,0.05280,283.10995
151.20001,7.56002,23023.98235,0.00000,0.05293,283.16542
151.50001,7.57485,23022.32832,0.00000,0.05304,283.14508
151.80001,7.59004,23029.52856,0.00000,0.05317,283.23363
152.10001,7.60486,23029.66863,0.00000,0.05329,283.23536
152.40001,7.61999,23032.14073,0.00000,0.05341,283.26576
152.70001,7.63488,23036.02695,0.00000,0.05353,283.31356
153.00001,7.64995,23037.46939,0.00000,0.05366,283.33130
153.30001,7.66507,23042.20051,0.00000,0.05378,283.38948
153.60001,7.67996,23042.14090,0.00000,0.05391,283.38875
153.90001,7.69509,23044.94381,0.00000,0.05403,283.42322
154.20001,7.70997,23046.33111,0.00000,0.05415,283.44028
154.50001,7.72504,23052.10829,0.00000,0.05428,283.51134
154.80001,7.73999,23050.35889,0.00000,0.05440,283.48982
155.10001,7.75506,23055.46850,0.00000,0.05453,283.55266
155.40001,7.76994,23056.61589,0.00000,0.05465,283.56677
155.70001,7.78501,23057.47420,0.00000,0.05477,283.57733
156.00001,7.80008,23063.36462,0.00000,0.05490,283.64977
156.30001,7.81490,23060.99832,0.00000,0.05502,283.62067
156.60001,7.83009,23067.72172,0.00000,0.05514,283.70336
156.90001,7.84486,23069.62907,0.00000,0.05526,283.72682
157.20001,7.86005,23070.27429,0.00000,0.05539,283.73475
157.50001,7.87499,23073.20237,0.00000,0.05551,283.77077
157.80001,7.89000,23074.13071,0.00000,0.05564,283.78218
158.10001,7.90507,23078.62341,0.00000,0.05577,283.83744
158.40001,7.92001,23080.49947,0.00000,0.05589,283.86051
158.70001,7.93508,23081.23559,0.00000,0.05602,283.86956
159.00001,7.94997,23081.32052,0.00000,0.05613,283.87061
159.30001,7.96504,23086.12317,0.00000,0.05625,283.92968
159.60001,7.97998,23084.94598,0.00000,0.05637,283.91520
159.90001,7.99505,23090.28953,0.00000,0.05650,283.98092
160.20001,8.00994,23092.19986,0.00000,0.05663,284.00441
160.50001,8.02501,23093.47242,0.00000,0.05675,284.02006
160.80001,8.04007,23096.46159,0.00000,0.05687,284.05682
161.10001,8.05484,23094.60640,0.00000,0.05700,284.03401
161.40001,8.07009,23100.65627,0.00000,0.05712,284.10841
161.70001,8.08491,23103.39659,0.00000,0.05725,284.14212
162.00001,8.10004,23104.12377,0.00000,0.05737,284.15106
162.30001,8.11499,23108.01893,0.00000,0.05749,284.19897
162.60001,8.13005,23107.71942,0.00000,0.05762,284.19528
162.90001,8.14512,23111.83363,0.00000,0.05775,284.24588
163.20001,8.16001,23110.52084,0.00000,0.05787,284.22974
163.50001,8.17508,23114.80194,0.00000,0.05799,284.28239
163.80001,8.19002,23114.56352,0.00000,0.05812,284.27946
164.10001,8.20503,23118.36332,0.00000,0.05824,284.32619
164.40001,8.21998,23117.13845,0.00000,0.05836,284.31112
164.70001,8.23499,23119.49879,0.00000,0.05848,284.34015
165.00001,8.24999,23124.19116,0.00000,0.05861,284.39786
165.30001,8.26500,23122.81728,0.00000,0.05874,284.38097
165.60001,8.28007,23128.66151,0.00000,0.05886,284.45284
165.90001,8.29483,23126.83761,0.00000,0.05898,284.43041
166.20001,8.31008,23131.30200,0.00000,0.05911,284.48532
166.50001,8.32497,23132.61181,0.00000,0.05922,284.50143
166.80001,8.34004,23133.24213,0.00000,0.05935,284.50918
167.10001,8.35498,23136.85864,0.00000,0.05947,284.55366
167.40001,8.36999,23138.15802,0.00000,0.05959,284.56964
167.70001,8.38506,23139.39333,0.00000,0.05972,284.58483
168.00001,8.39994,23139.36800,0.00000,0.05984,284.58452
168.30001,8.41507,23142.57920,0.00000,0.05997,284.62401
168.60001,8.42996,23141.59870,0.00000,0.06009,284.61195
168.90001,8.44503,23146.13461,0.00000,0.06021,284.66774
169.20001,8.45991,23145.92749,0.00000,0.06033,284.66519
169.50001,8.47504,23148.63801,0.00000,0.06045,284.69853
169.80001,8.48999,23152.57341,0.00000,0.06058,284.74693
170.10001,8.50500,23149.07908,0.00000,0.06070,284.70395
170.40001,8.52006,23155.20793,0.00000,0.06082,284.77933
170.70001,8.53477,23153.24992,0.00000,0.06094,284.75525
171.00001,8.55008,23158.41615,0.00000,0.06106,284.81879
171.30001,8.56490,23156.73232,0.00000,0.06119,284.79808
171.60001,8.58003,23158.60242,0.00000,0.06131,284.82108
171.90001,8.59504,23162.51397,0.00000,0.06143,284.86918
172.20001,8.60999,23160.61854,0.00000,0.06155,284.84587
172.50001,8.62505,23166.04704,0.00000,0.06168,284.91264
172.80001,8.64000,23164.22015,0.00000,0.06180,284.89017
173.10001,8.65507,23167.57441,0.00000,0.06192,284.93142
173.40001,8.66995,23168.03485,0.00000,0.06204,284.93708
173.70001,8.68508,23171.59027,0.00000,0.06216,284.98081
174.00001,8.69991,23171.03297,0.00000,0.06228,284.97396
174.30001,8.71498,23172.55288,0.00000,0.06240,284.99265
174.60001,8.72992,23177.54775,0.00000,0.06252,285.05408
174.90001,8.74505,23175.62252,0.00000,0.06264,285.03040
175.20001,8.76006,23178.82776,0.00000,0.06277,285.06982
175.50001,8.77483,23177.73700,0.00000,0.06289,285.05641
175.80001,8.79007,23182.49643,0.00000,0.06301,285.11494
176.10001,8.80490,23182.70057,0.00000,0.06314,285.11745
176.40001,8.82003,23183.73173,0.00000,0.06325,285.13014
176.70001,8.83503,23185.30530,0.00000,0.06338,285.14949
177.00001,8.84998,23185.02963,0.00000,0.06349,285.14610
177.30001,8.86505,23187.67458,0.00000,0.06361,285.17863
177.60001,8.87987,23187.49577,0.00000,0.06373,285.17643
177.90001,8.89500,23192.28947,0.00000,0.06386,285.23538
178.20001,8.90995,23191.20169,0.00000,0.06398,285.22201
178.50001,8.92502,23194.60958,0.00000,0.06410,285.26392
178.80001,8.93996,23194.67813,0.00000,0.06422,285.26476
179.10001,8.95503,23195.71525,0.00000,0.06434,285.27752
179.40001,8.96998,23200.13344,0.00000,0.06446,285.33186
179.70001,8.98499,23197.64942,0.00000,0.06458,285.30131
180.00001,9.00005,23201.96927,0.00000,0.06470,285.35443
180.30001,9.01488,23200.15579,0.00000,0.06482,285.33213
180.60001,9.03013,23203.14795,0.00000,0.06495,285.36893
180.90001,9.04489,23202.84247,0.00000,0.06506,285.36517
181.20001,9.06002,23204.86009,0.00000,0.06519,285.38999
181.50001,9.07503,23208.13984,0.00000,0.06531,285.43032
181.80001,9.08998,23209.08457,0.00000,0.06543,285.44194
182.10001,9.10504,23209.28127,0.00000,0.06555,285.44436
182.40001,9.11993,23208.10854,0.00000,0.06567,285.42994
182.70001,9.13506,23213.69648,0.00000,0.06579,285.49866
183.00001,9.14994,23212.01116,0.00000,0.06592,285.47794
183.30001,9.16501,23213.96172,0.00000,0.06604,285.50193
183.60001,9.17990,23214.60098,0.00000,0.06616,285.50979
183.90001,9.19503,23216.58283,0.00000,0.06628,285.53416
184.20001,9.21003,23218.55575,0.00000,0.06640,285.55843
184.50001,9.22498,23216.14474,0.00000,0.06652,285.52877
184.80001,9.24017,23222.72658,0.00000,0.06664,285.60972
185.10001,9.25494,23219.20544,0.00000,0.06676,285.56642
185.40001,9.27012,23221.88765,0.00000,0.06688,285.59940
185.70001,9.28501,23221.84294,0.00000,0.06701,285.59885
186.00001,9.30002,23220.66426,0.00000,0.06712,285.58436
186.30001,9.31502,23224.16455,0.00000,0.06724,285.62741
186.60001,9.32991,23223.88291,0.00000,0.06736,285.62394
186.90001,9.34504,23227.63950,0.00000,0.06748,285.67014
187.20001,9.35993,23226.88103,0.00000,0.06760,285.66082
187.50001,9.37499,23229.54684,0.00000,0.06772,285.69360
187.80001,9.38994,23226.39972,0.00000,0.06784,285.65490
188.10001,9.40501,23229.64817,0.00000,0.06796,285.69485
188.40001,9.41995,23231.64642,0.00000,0.06808,285.71942
188.70001,9.43508,23231.90123,0.00000,0.06820,285.72256
189.00001,9.45009,23235.75616,0.00000,0.06832,285.76997
189.30001,9.46498,23231.55701,0.00000,0.06844,285.71833
189.60001,9.48010,23234.95150,0.00000,0.06856,285.76007
189.90001,9.49487,23232.99050,0.00000,0.06867,285.73596
190.20001,9.51012,23236.61447,0.00000,0.06879,285.78053
190.50001,9.52488,23236.10187,0.00000,0.06891,285.77422
190.80001,9.54001,23238.39068,0.00000,0.06903,285.80237
191.10001,9.55502,23240.33380,0.00000,0.06915,285.82627
191.40001,9.56997,23239.77947,0.00000,0.06927,285.81945
191.70001,9.58509,23241.53781,0.00000,0.06939,285.84108
192.00001,9.59992,23240.57817,0.00000,0.06951,285.82927
192.30001,9.61505,23244.71623,0.00000,0.06963,285.88017
192.60001,9.62994,23242.18303,0.00000,0.06974,285.84901
192.90001,9.64506,23243.87431,0.00000,0.06986,285.86981
193.20001,9.65995,23245.27204,0.00000,0.06998,285.88700
193.50001,9.67508,23243.41834,0.00000,0.07010,285.86420
193.80001,9.69008,23249.00180,0.00000,0.07022,285.93287
194.10001,9.70491,23244.54635,0.00000,0.07033,285.87808
194.40001,9.72010,23249.80497,0.00000,0.07045,285.94275
194.70001,9.73493,23246.67722,0.00000,0.07057,285.90428
195.00001,9.75011,23248.44748,0.00000,0.07069,285.92606
195.30001,9.76494,23249.10313,0.00000,0.07080,285.93412
195.60001,9.78001,23250.49639,0.00000,0.07092,285.95126
195.90001,9.79501,23253.33953,0.00000,0.07104,285.98622
196.20001,9.80996,23250.91660,0.00000,0.07116,285.95642
196.50001,9.82497,23252.22641,0.00000,0.07128,285.97253
196.80001,9.83997,23252.44546,0.00000,0.07140,285.97523
197.10001,9.85504,23255.36013,0.00000,0.07152,286.01107
197.40001,9.86993,23254.23509,0.00000,0.07163,285.99724
197.70001,9.88506,23256.69080,0.00000,0.07175,286.02744
198.00001,9.89994,23256.49709,0.00000,0.07186,286.02506
198.30001,9.91507,23255.10830,0.00000,0.07198,286.00798
198.60001,9.93002,23257.54613,0.00000,0.07210,286.03796
198.90001,9.94497,23255.39142,0.00000,0.07222,286.01146
199.20001,9.96009,23259.24635,0.00000,0.07233,286.05887
199.50001,9.97486,23258.76206,0.00000,0.07245,286.05291
199.80001,9.99005,23259.09883,0.00000,0.07257,286.05705
200.10001,10.00499,23259.57566,0.00000,0.07269,286.06292
200.40001,10.02000,23259.52500,0.00000,0.07280,286.06230
200.70001,10.03507,23262.04628,0.00000,0.07292,286.09330
201.00001,10.04990,23260.63812,0.00000,0.07304,286.07599
201.30001,10.06502,23263.55129,0.00000,0.07315,286.11181
201.60001,10.07997,23263.29648,0.00000,0.07327,286.10868
201.90001,10.09504,23264.35596,0.00000,0.07339,286.12171
202.20001,10.10998,23262.98952,0.00000,0.07350,286.10490
202.50001,10.12499,23262.92694,0.00000,0.07362,286.10413
202.80001,10.13994,23264.23675,0.00000,0.07373,286.12024
203.10001,10.15507,23263.28754,0.00000,0.07385,286.10857
203.40001,10.17007,23267.18867,0.00000,0.07397,286.15655
203.70001,10.18490,23263.42613,0.00000,0.07409,286.11027
204.00001,10.20015,23267.99631,0.00000,0.07420,286.16648
204.30001,10.21485,23267.66551,0.00000,0.07432,286.16241
204.60001,10.23004,23269.38659,0.00000,0.07444,286.18358
204.90001,10.24499,23270.55782,0.00000,0.07455,286.19798
205.20001,10.25994,23269.38659,0.00000,0.07466,286.18358
205.50001,10.27506,23270.85137,0.00000,0.07478,286.20160
205.80001,10.28995,23268.78607,0.00000,0.07490,286.17619
206.10001,10.30502,23271.52938,0.00000,0.07501,286.20993
206.40001,10.31996,23268.67580,0.00000,0.07513,286.17484
206.70001,10.33509,23273.57233,0.00000,0.07526,286.23506
207.00001,10.34992,23268.64302,0.00000,0.07537,286.17444
207.30001,10.36511,23271.49957,0.00000,0.07549,286.20957
207.60001,10.37999,23272.43239,0.00000,0.07560,286.22104
207.90001,10.39506,23271.08979,0.00000,0.07571,286.20453
208.20001,10.41007,23274.74207,0.00000,0.07583,286.24945
208.50001,10.42483,23271.26563,0.00000,0.07595,286.20669
208.80001,10.44014,23275.57504,0.00000,0.07606,286.25969
209.10001,10.45491,23272.59183,0.00000,0.07618,286.22300
209.40001,10.46998,23272.27443,0.00000,0.07629,286.21910
209.70001,10.48492,23274.32632,0.00000,0.07641,286.24433
210.00001,10.49999,23275.00135,0.00000,0.07653,286.25263
210.30001,10.51506,23277.36020,0.00000,0.07665,286.28165
210.60001,10.53001,23274.40083,0.00000,0.07676,286.24525
210.90001,10.54507,23274.61690,0.00000,0.07688,286.24791
211.20001,10.56002,23273.20576,0.00000,0.07699,286.23055
211.50001,10.57509,23275.47967,0.00000,0.07710,286.25852
211.80001,10.58991,23274.46491,0.00000,0.07722,286.24604
212.10001,10.60510,23278.03224,0.00000,0.07734,286.28991
212.40001,10.61993,23278.07844,0.00000,0.07745,286.29048
212.70001,10.63500,23274.79869,0.00000,0.07757,286.25014
213.00001,10.65006,23278.70876,0.00000,0.07769,286.29823
213.30001,10.66489,23276.59875,0.00000,0.07780,286.27228
213.60001,10.68014,23279.60283,0.00000,0.07792,286.30923
213.90001,10.69485,23278.07993,0.00000,0.07803,286.29050
214.20001,10.71003,23277.87280,0.00000,0.07815,286.28795
214.50001,10.72504,23278.94568,0.00000,0.07827,286.30114
214.80001,10.73999,23276.64196,0.00000,0.07838,286.27281
215.10001,10.75505,23279.40762,0.00000,0.07850,286.30683
215.40001,10.77000,23278.29003,0.00000,0.07862,286.29308
215.70001,10.78501,23279.08725,0.00000,0.07873,286.30289
216.00001,10.80001,23276.79396,0.00000,0.07885,286.27468
216.30001,10.81508,23279.18857,0.00000,0.07896,286.30413
216.60001,10.82991,23277.12327,0.00000,0.07907,286.27873
216.90001,10.84510,23278.45842,0.00000,0.07919,286.29515
217.20001,10.85998,23280.97224,0.00000,0.07930,286.32607
217.50001,10.87493,23278.13506,0.00000,0.07942,286.29118
217.80001,10.89012,23281.53253,0.00000,0.07954,286.33296
218.10001,10.90489,23277.15009,0.00000,0.07966,286.27906
218.40001,10.92007,23277.95774,0.00000,0.07977,286.28899
218.70001,10.93496,23279.93065,0.00000,0.07988,286.31326
219.00001,10.95003,23279.26606,0.00000,0.08000,286.30509
219.30001,10.96503,23280.65485,0.00000,0.08011,286.32217
219.60001,10.97998,23277.42428,0.00000,0.08022,286.28243
219.90001,10.99511,23279.49256,0.00000,0.08034,286.30787
220.20001,11.01005,23276.90423,0.00000,0.08045,286.27604
220.50001,11.02506,23278.48375,0.00000,0.08057,286.29546
220.80001,11.04001,23278.82946,0.00000,0.08069,286.29972
221.10001,11.05508,23279.15728,0.00000,0.08080,286.30375
221.40001,11.06991,23277.73273,0.00000,0.08091,286.28623
221.70001,11.08509,23277.67611,0.00000,0.08102,286.28553
222.00001,11.10004,23279.90532,0.00000,0.08114,286.31295
222.30001,11.11493,23274.68097,0.00000,0.08125,286.24869
222.60001,11.13005,23279.32566,0.00000,0.08137,286.30582
222.90001,11.14488,23277.07410,0.00000,0.08148,286.27813
223.20001,11.16013,23278.17380,0.00000,0.08159,286.29165
223.50001,11.17502,23277.16649,0.00000,0.08170,286.27926
223.80001,11.19002,23276.03698,0.00000,0.08181,286.26537
224.10001,11.20503,23276.13682,0.00000,0.08192,286.26660
224.40001,11.21998,23275.70617,0.00000,0.08204,286.26130
224.70001,11.23504,23275.51842,0.00000,0.08215,286.25899
225.00001,11.24993,23273.20129,0.00000,0.08226,286.23050
225.30001,11.26506,23276.52723,0.00000,0.08238,286.27140
225.60001,11.27995,23273.78839,0.00000,0.08249,286.23772
225.90001,11.29507,23277.01151,0.00000,0.08260,286.27736
226.20001,11.30990,23275.44838,0.00000,0.08271,286.25813
226.50001,11.32509,23275.57057,0.00000,0.08282,286.25964
226.80001,11.34003,23276.50338,0.00000,0.08293,286.27111
227.10001,11.35492,23271.03764,0.00000,0.08304,286.20389
227.40001,11.37005,23274.56623,0.00000,0.08315,286.24728
227.70001,11.38482,23271.36397,0.00000,0.08326,286.20790
228.00001,11.40006,23273.42331,0.00000,0.08337,286.23323
228.30001,11.41489,23272.50838,0.00000,0.08348,286.22197
228.60001,11.43002,23271.98535,0.00000,0.08359,286.21554
228.90001,11.44508,23271.73054,0.00000,0.08370,286.21241
229.20001,11.46003,23270.08992,0.00000,0.08381,286.19223
229.50001,11.47504,23272.43090,0.00000,0.08392,286.22102
229.80001,11.48999,23270.00648,0.00000,0.08403,286.19120
230.10001,11.50505,23272.24016,0.00000,0.08414,286.21868
230.40001,11.51988,23267.34215,0.00000,0.08424,286.15844
230.70001,11.53513,23270.09737,0.00000,0.08435,286.19232
231.00001,11.54989,23268.55063,0.00000,0.08446,286.17330
231.30001,11.56502,23267.72511,0.00000,0.08457,286.16315
231.60001,11.58003,23269.95879,0.00000,0.08467,286.19062
231.90001,11.59492,23264.59289,0.00000,0.08478,286.12462
232.20001,11.61010,23267.29000,0.00000,0.08489,286.15779
232.50001,11.62493,23262.84051,0.00000,0.08499,286.10307
232.80001,11.64006,23264.91922,0.00000,0.08510,286.12864
233.10001,11.65500,23263.76885,0.00000,0.08520,286.11449
233.40001,11.67001,23265.37669,0.00000,0.08530,286.13426
233.70001,11.68502,23263.58110,0.00000,0.08541,286.11218
234.00001,11.70003,23261.43235,0.00000,0.08551,286.08575
234.30001,11.71503,23262.02244,0.00000,0.08562,286.09301
234.60001,11.72992,23259.12714,0.00000,0.08571,286.05740
234.90001,11.74505,23262.68703,0.00000,0.08582,286.10118
235.20001,11.75994,23258.16303,0.00000,0.08592,286.04555
235.50001,11.77506,23258.75461,0.00000,0.08602,286.05282
235.80001,11.78989,23257.77262,0.00000,0.08612,286.04074
236.10001,11.80502,23254.89819,0.00000,0.08622,286.00539
236.40001,11.82002,23257.64000,0.00000,0.08632,286.03911
236.70001,11.83485,23254.15611,0.00000,0.08642,285.99627
237.00001,11.85010,23255.76246,0.00000,0.08653,286.01602
237.30001,11.86493,23252.31731,0.00000,0.08662,285.97365
237.60001,11.88005,23250.19389,0.00000,0.08672,285.94753
237.90001,11.89494,23249.65149,0.00000,0.08682,285.94086
238.20001,11.91001,23249.99422,0.00000,0.08691,285.94508
238.50001,11.92501,23250.10449,0.00000,0.08701,285.94644
238.80001,11.93996,23248.47579,0.00000,0.08710,285.92640
239.10001,11.95503,23249.60083,0.00000,0.08720,285.94024
239.40001,11.96998,23243.42728,0.00000,0.08729,285.86431
239.70001,11.98510,23246.52672,0.00000,0.08739,285.90243
240.00001,11.99987,23240.48877,0.00000,0.08748,285.82817
240.30001,12.01500,23241.21147,0.00000,0.08757,285.83706
240.60001,12.02994,23240.46791,0.00000,0.08766,285.82792
240.90001,12.04501,23235.26442,0.00000,0.08775,285.76392
241.20001,12.06008,23239.08806,0.00000,0.08785,285.81095
241.50001,12.07491,23231.75520,0.00000,0.08793,285.72076
241.80001,12.09021,23231.86845,0.00000,0.08802,285.72216
242.10001,12.10492,23229.86871,0.00000,0.08810,285.69756
242.40001,12.11999,23227.78255,0.00000,0.08819,285.67190
242.70001,12.13499,23227.35190,0.00000,0.08827,285.66661
243.00001,12.15006,23224.71589,0.00000,0.08835,285.63419
243.30001,12.16495,23222.80407,0.00000,0.08844,285.61068
243.60001,12.17996,23218.82397,0.00000,0.08852,285.56173
243.90001,12.19502,23220.46310,0.00000,0.08859,285.58188
244.20001,12.20997,23214.16438,0.00000,0.08867,285.50442
244.50001,12.22504,23212.99314,0.00000,0.08875,285.49001
244.80001,12.23993,23208.13984,0.00000,0.08883,285.43032
245.10001,12.25505,23206.88069,0.00000,0.08891,285.41484
245.40001,12.26994,23202.87675,0.00000,0.08898,285.36559
245.70001,12.28507,23199.09185,0.00000,0.08905,285.31905
246.00001,12.30007,23199.07695,0.00000,0.08912,285.31886
246.30001,12.31490,23191.00946,0.00000,0.08919,285.21964
246.60001,12.33015,23191.15698,0.00000,0.08925,285.22146
246.90001,12.34492,23185.16374,0.00000,0.08932,285.14775
247.20001,12.36004,23182.66183,0.00000,0.08938,285.11698
247.50001,12.37493,23177.28549,0.00000,0.08944,285.05086
247.80001,12.39000,23173.72561,0.00000,0.08951,285.00707
248.10001,12.40494,23167.89925,0.00000,0.08957,284.93542
248.40001,12.42001,23160.82269,0.00000,0.08963,284.84838
248.70001,12.43508,23158.60242,0.00000,0.08968,284.82108
249.00001,12.44997,23148.94199,0.00000,0.08973,284.70227
249.30001,12.46503,23146.95716,0.00000,0.08978,284.67786
249.60001,12.47992,23138.46946,0.00000,0.08983,284.57347
249.90001,12.49505,23130.67615,0.00000,0.08988,284.47762
250.20001,12.51000,23124.65161,0.00000,0.08993,284.40353
250.50001,12.52512,23114.61270,0.00000,0.08997,284.28006
250.80001,12.54007,23108.63584,0.00000,0.09001,284.20655
251.10001,12.55490,23099.11251,0.00000,0.09006,284.08943
251.40001,12.57014,23092.45914,0.00000,0.09009,284.00760
251.70001,12.58497,23079.00786,0.00000,0.09013,283.84217
252.00001,12.60004,23069.04495,0.00000,0.09016,283.71964
252.30001,12.61504,23058.75868,0.00000,0.09019,283.59313
252.60001,12.63005,23046.41157,0.00000,0.09023,283.44127
252.90001,12.64494,23033.38498,0.00000,0.09025,283.28106
253.20001,12.65995,23018.04274,0.00000,0.09028,283.09237
253.50001,12.67501,23005.98025,0.00000,0.09030,282.94402
253.80001,12.68996,22985.76832,0.00000,0.09032,282.69544
254.10001,12.70509,22974.28399,0.00000,0.09034,282.55420
254.40001,12.71992,22953.85152,0.00000,0.09036,282.30290
254.70001,12.73504,22937.13689,0.00000,0.09038,282.09734
255.00001,12.74999,22918.90085,0.00000,0.09039,281.87306
255.30001,12.76506,22894.02634,0.00000,0.09040,281.56713
255.60001,12.78012,22876.58453,0.00000,0.09042,281.35262
255.90001,12.79495,22850.33762,0.00000,0.09043,281.02982
256.20001,12.81008,22827.86071,0.00000,0.09044,280.75338
256.50001,12.82491,22799.30860,0.00000,0.09044,280.40222
256.80001,12.83997,22773.69052,0.00000,0.09044,280.08716
257.10001,12.85498,22746.19192,0.00000,0.09045,279.74896
257.40001,12.87005,22716.83365,0.00000,0.09045,279.38789
257.70001,12.88499,22686.32799,0.00000,0.09046,279.01271
258.00001,12.89994,22651.93164,0.00000,0.09046,278.58968
258.30001,12.91501,22620.60493,0.00000,0.09045,278.20440
258.60001,12.92996,22580.81287,0.00000,0.09045,277.71501
258.90001,12.94502,22546.54914,0.00000,0.09045,277.29361
259.20001,12.95991,22508.20994,0.00000,0.09045,276.82208
259.50001,12.97510,22470.55769,0.00000,0.09045,276.35901
259.80001,12.98998,22431.51218,0.00000,0.09044,275.87880
260.10001,13.00505,22386.32292,0.00000,0.09043,275.32303
260.40001,13.02012,22343.39863,0.00000,0.09043,274.79512
260.70001,13.03489,22295.93843,0.00000,0.09042,274.21142
261.00001,13.05013,22250.50032,0.00000,0.09041,273.65259
261.30001,13.06490,22199.02575,0.00000,0.09041,273.01952
261.60001,13.07997,22149.75208,0.00000,0.09039,272.41351
261.90001,13.09498,22094.46728,0.00000,0.09039,271.73358
262.20001,13.10992,22035.06082,0.00000,0.09037,271.00296
262.50001,13.12499,21978.02961,0.00000,0.09036,270.30155
262.80001,13.14000,21910.40367,0.00000,0.09034,269.46984
263.10001,13.15500,21848.59365,0.00000,0.09033,268.70965
263.40001,13.16995,21764.49448,0.00000,0.09032,267.67534
263.70001,13.18508,21675.42577,0.00000,0.09030,266.57991
264.00001,13.19997,21588.58627,0.00000,0.09028,265.51189
264.30001,13.21509,21486.43136,0.00000,0.09026,264.25552
264.60001,13.23004,21274.53089,0.00000,0.09021,261.64942
264.90001,13.24505,20941.69557,0.00000,0.09014,257.55597
265.20001,13.26011,20388.86547,0.00000,0.09002,250.75687
265.35001,13.26765,19502.90948,0.00000,0.09015,239.86075
265.35601,13.26818,17403.61750,0.00000,0.09328,214.04215
265.36201,13.26908,14254.75478,0.00000,0.09675,175.31518
265.36601,13.26968,11969.79806,0.00000,0.09716,147.21315