File: scratch/college-stuff/ME Lab/ME lab Fall 2013/group10/group10.is_tens_RawData/Specimen_RawData_4.csv
Time,Extension,Load,Strain 2,Tensile strain,Tensile stress
(sec),(mm),(N),(mm/mm),(mm/mm),(MPa)
0.00000,0.00000,-0.33346,0.00000,0.00000,-0.00408
0.10000,0.00161,2.61239,0.00000,0.00000,0.03194
0.20000,0.00729,8.93546,0.00000,0.00000,0.10925
0.30000,0.01357,11.73737,0.00000,0.00001,0.14351
0.40000,0.01937,12.43980,0.00000,0.00000,0.15210
0.50000,0.02469,13.57273,0.00000,0.00001,0.16595
0.60000,0.02995,15.43490,0.00000,0.00000,0.18872
0.70000,0.03498,17.95353,0.00000,0.00000,0.21951
0.80000,0.04006,20.45635,0.00000,0.00001,0.25011
0.90000,0.04502,25.16810,0.00000,0.00001,0.30772
1.00000,0.05004,28.20427,0.00000,0.00001,0.34485
1.10000,0.05495,30.98581,0.00000,0.00001,0.37886
1.20000,0.06003,32.28138,0.00000,0.00001,0.39470
1.30000,0.06499,35.04972,0.00000,0.00001,0.42854
1.40000,0.06995,38.34738,0.00000,0.00000,0.46886
1.50000,0.07504,40.97485,0.00000,0.00001,0.50099
1.60000,0.07994,44.17572,0.00000,0.00000,0.54012
1.70000,0.08514,47.34212,0.00000,-0.00001,0.57884
1.80000,0.08998,49.02346,0.00000,-0.00001,0.59940
1.90000,0.09513,52.29415,0.00000,-0.00001,0.63939
2.00000,0.09991,54.98883,0.00000,-0.00001,0.67233
2.10000,0.10511,60.29864,0.00000,-0.00001,0.73726
2.20000,0.10995,67.08223,0.00000,-0.00001,0.82020
2.30000,0.11509,75.06430,0.00000,-0.00002,0.91779
2.40000,0.11988,81.17892,0.00000,-0.00002,0.99255
2.50000,0.12502,87.50464,0.00000,-0.00002,1.06990
2.60000,0.12992,94.64657,0.00000,-0.00002,1.15722
2.70000,0.13512,99.69220,0.00000,-0.00002,1.21891
2.80000,0.13997,105.72680,0.00000,-0.00002,1.29269
2.90000,0.14505,111.46773,0.00000,-0.00003,1.36289
3.00000,0.14989,118.13586,0.00000,-0.00003,1.44442
3.10000,0.15503,126.07669,0.00000,-0.00003,1.54151
3.20000,0.16000,134.19365,0.00000,-0.00004,1.64075
3.30000,0.16496,144.39962,0.00000,-0.00004,1.76554
3.40000,0.16992,157.31627,0.00000,-0.00004,1.92346
3.50000,0.17494,170.19357,0.00000,-0.00003,2.08091
3.60000,0.18003,186.56284,0.00000,-0.00003,2.28105
3.70000,0.18505,202.54841,0.00000,-0.00003,2.47651
3.80000,0.19007,221.06061,0.00000,-0.00002,2.70285
3.90000,0.19491,236.60962,0.00000,-0.00002,2.89296
4.00000,0.20006,255.22686,0.00000,-0.00001,3.12059
4.10000,0.20490,273.06997,0.00000,-0.00001,3.33875
4.20000,0.21010,292.64856,0.00000,0.00000,3.57814
4.30000,0.21494,311.84787,0.00000,0.00001,3.81288
4.40000,0.22009,332.71518,0.00000,0.00002,4.06802
4.50000,0.22493,354.08325,0.00000,0.00003,4.32928
4.60000,0.23013,373.88857,0.00000,0.00003,4.57144
4.70000,0.23497,393.61529,0.00000,0.00004,4.81263
4.80000,0.24000,415.52288,0.00000,0.00006,5.08049
4.90000,0.24490,438.26718,0.00000,0.00007,5.35858
5.00000,0.25004,462.26066,0.00000,0.00007,5.65194
5.10000,0.25500,485.75769,0.00000,0.00008,5.93923
5.20000,0.26002,509.94195,0.00000,0.00010,6.23492
5.30000,0.26499,535.02382,0.00000,0.00011,6.54159
5.40000,0.27001,558.99671,0.00000,0.00012,6.83470
5.50000,0.27497,583.08155,0.00000,0.00013,7.12918
5.60000,0.28005,607.44947,0.00000,0.00014,7.42712
5.70000,0.28496,636.33746,0.00000,0.00015,7.78033
5.80000,0.28998,664.89861,0.00000,0.00017,8.12954
5.90000,0.29500,696.07049,0.00000,0.00018,8.51067
6.00000,0.30002,725.89810,0.00000,0.00019,8.87536
6.10000,0.30511,757.25950,0.00000,0.00021,9.25881
6.20000,0.30995,784.76565,0.00000,0.00022,9.59512
6.30000,0.31503,818.69066,0.00000,0.00024,10.00991
6.40000,0.31993,850.73244,0.00000,0.00025,10.40168
6.50000,0.32508,887.75959,0.00000,0.00027,10.85440
6.60000,0.32992,920.34023,0.00000,0.00028,11.25275
6.70000,0.33506,957.34783,0.00000,0.00030,11.70524
6.80000,0.33984,992.34339,0.00000,0.00032,12.13312
6.90000,0.34505,1030.28426,0.00000,0.00035,12.59701
7.00000,0.34995,1065.75117,0.00000,0.00036,13.03065
7.10000,0.35509,1101.68150,0.00000,0.00038,13.46996
7.20000,0.35987,1136.22686,0.00000,0.00039,13.89234
7.30000,0.36501,1170.45939,0.00000,0.00041,14.31089
7.40000,0.36992,1204.13881,0.00000,0.00043,14.72268
7.50000,0.37506,1237.95774,0.00000,0.00044,15.13618
7.60000,0.37996,1272.12545,0.00000,0.00046,15.55394
7.70000,0.38492,1304.51787,0.00000,0.00048,15.94999
7.80000,0.38989,1338.00982,0.00000,0.00049,16.35949
7.90000,0.39497,1370.59549,0.00000,0.00051,16.75790
8.00000,0.39999,1403.89148,0.00000,0.00053,17.16501
8.10000,0.40495,1435.56204,0.00000,0.00054,17.55223
8.20000,0.40998,1469.28970,0.00000,0.00056,17.96461
8.30000,0.41500,1498.66845,0.00000,0.00058,18.32382
8.40000,0.42008,1529.96182,0.00000,0.00059,18.70643
8.50000,0.42498,1558.45629,0.00000,0.00061,19.05483
8.60000,0.43007,1591.08471,0.00000,0.00062,19.45377
8.70000,0.43491,1620.03785,0.00000,0.00064,19.80777
8.80000,0.44005,1650.89555,0.00000,0.00066,20.18506
8.90000,0.44489,1680.26648,0.00000,0.00067,20.54417
9.00000,0.45010,1710.78872,0.00000,0.00068,20.91736
9.10000,0.45488,1738.53468,0.00000,0.00070,21.25660
9.20000,0.46002,1766.36707,0.00000,0.00072,21.59690
9.30000,0.46492,1792.49328,0.00000,0.00073,21.91634
9.40000,0.47012,1820.53652,0.00000,0.00074,22.25921
9.50000,0.47497,1848.44602,0.00000,0.00076,22.60046
9.60000,0.47999,1875.90625,0.00000,0.00077,22.93620
9.70000,0.48489,1901.36507,0.00000,0.00078,23.24748
9.80000,0.49003,1928.12383,0.00000,0.00080,23.57465
9.90000,0.49494,1954.51565,0.00000,0.00081,23.89734
10.00000,0.50002,1980.66998,0.00000,0.00082,24.21712
10.10000,0.50492,2006.46520,0.00000,0.00083,24.53251
10.20000,0.51000,2030.97258,0.00000,0.00085,24.83216
10.30000,0.51503,2057.33106,0.00000,0.00086,25.15444
10.40000,0.52005,2081.67322,0.00000,0.00088,25.45206
10.50000,0.52501,2107.35369,0.00000,0.00089,25.76605
10.60000,0.52997,2129.91368,0.00000,0.00090,26.04188
10.70000,0.53500,2154.90609,0.00000,0.00091,26.34746
10.80000,0.53996,2176.11082,0.00000,0.00092,26.60672
10.90000,0.54504,2200.75864,0.00000,0.00093,26.90809
11.00000,0.54988,2220.68671,0.00000,0.00095,27.15174
11.10000,0.55503,2245.31423,0.00000,0.00096,27.45286
11.20000,0.55987,2265.37902,0.00000,0.00096,27.69818
11.30000,0.56513,2289.13035,0.00000,0.00098,27.98858
11.40000,0.56991,2309.76827,0.00000,0.00099,28.24092
11.50000,0.57506,2333.29963,0.00000,0.00100,28.52863
11.60000,0.57990,2353.41713,0.00000,0.00101,28.77460
11.70000,0.58504,2375.34009,0.00000,0.00103,29.04265
11.80000,0.58994,2396.88214,0.00000,0.00104,29.30604
11.90000,0.59503,2419.12715,0.00000,0.00105,29.57802
12.00000,0.59987,2441.24755,0.00000,0.00106,29.84848
12.10000,0.60495,2463.67268,0.00000,0.00108,30.12267
12.20000,0.60991,2484.30371,0.00000,0.00108,30.37492
12.30000,0.61499,2505.11002,0.00000,0.00109,30.62931
12.40000,0.61996,2528.63429,0.00000,0.00111,30.91694
12.50000,0.62498,2550.92941,0.00000,0.00112,31.18953
12.60000,0.62994,2575.96020,0.00000,0.00113,31.49558
12.70000,0.63502,2597.73266,0.00000,0.00115,31.76178
12.80000,0.64005,2621.49889,0.00000,0.00116,32.05237
12.90000,0.64495,2642.15991,0.00000,0.00117,32.30498
13.00000,0.65003,2666.45383,0.00000,0.00119,32.60202
13.10000,0.65493,2688.20357,0.00000,0.00119,32.86795
13.20000,0.66008,2711.51755,0.00000,0.00121,33.15300
13.30000,0.66498,2731.65237,0.00000,0.00122,33.39918
13.40000,0.67006,2755.21372,0.00000,0.00123,33.68726
13.50000,0.67490,2775.54393,0.00000,0.00125,33.93583
13.60000,0.68011,2797.98824,0.00000,0.00125,34.21025
13.70000,0.68501,2818.37042,0.00000,0.00127,34.45946
13.80000,0.69015,2841.92618,0.00000,0.00128,34.74747
13.90000,0.69493,2862.00121,0.00000,0.00129,34.99292
14.00000,0.70008,2884.62043,0.00000,0.00130,35.26948
14.10000,0.70498,2905.07637,0.00000,0.00131,35.51959
14.20000,0.71012,2927.34224,0.00000,0.00132,35.79183
14.30000,0.71496,2946.63906,0.00000,0.00133,36.02777
14.40000,0.72004,2969.35327,0.00000,0.00134,36.30549
14.50000,0.72489,2987.64650,0.00000,0.00136,36.52915
14.60000,0.73009,3009.12634,0.00000,0.00137,36.79178
14.70000,0.73499,3029.09389,0.00000,0.00138,37.03592
14.80000,0.74007,3050.70784,0.00000,0.00139,37.30019
14.90000,0.74498,3071.89859,0.00000,0.00141,37.55928
15.00000,0.75006,3090.98586,0.00000,0.00141,37.79266
15.10000,0.75502,3111.73182,0.00000,0.00143,38.04631
15.20000,0.76004,3130.73173,0.00000,0.00143,38.27862
15.30000,0.76495,3151.83476,0.00000,0.00145,38.53664
15.40000,0.76997,3169.36150,0.00000,0.00146,38.75094
15.50000,0.77499,3190.54537,0.00000,0.00147,39.00994
15.60000,0.77995,3209.21130,0.00000,0.00148,39.23817
15.70000,0.78504,3229.99842,0.00000,0.00149,39.49233
15.80000,0.78994,3249.61320,0.00000,0.00150,39.73215
15.90000,0.79502,3271.19604,0.00000,0.00151,39.99604
16.00000,0.79998,3289.75767,0.00000,0.00152,40.22299
16.10000,0.80513,3309.68052,0.00000,0.00153,40.46658
16.20000,0.80991,3329.05799,0.00000,0.00154,40.70350
16.30000,0.81505,3351.29239,0.00000,0.00156,40.97536
16.40000,0.81989,3371.37580,0.00000,0.00157,41.22091
16.50000,0.82504,3390.94698,0.00000,0.00158,41.46020
16.60000,0.82988,3411.35040,0.00000,0.00158,41.70967
16.70000,0.83502,3432.22357,0.00000,0.00160,41.96488
16.80000,0.83986,3452.24105,0.00000,0.00161,42.20963
16.90000,0.84500,3473.33103,0.00000,0.00162,42.46749
17.00000,0.84997,3495.14596,0.00000,0.00163,42.73421
17.10000,0.85505,3517.15721,0.00000,0.00165,43.00334
17.20000,0.86001,3538.34890,0.00000,0.00165,43.26245
17.30000,0.86497,3559.13676,0.00000,0.00167,43.51661
17.40000,0.87000,3581.63416,0.00000,0.00168,43.79168
17.50000,0.87502,3600.56795,0.00000,0.00169,44.02318
17.60000,0.88004,3623.84245,0.00000,0.00170,44.30775
17.70000,0.88500,3643.40618,0.00000,0.00171,44.54695
17.80000,0.89003,3665.55825,0.00000,0.00172,44.81780
17.90000,0.89499,3685.75491,0.00000,0.00174,45.06474
18.00000,0.90013,3708.47844,0.00000,0.00175,45.34257
18.10000,0.90497,3729.10611,0.00000,0.00176,45.59478
18.20000,0.91012,3751.42545,0.00000,0.00177,45.86768
18.30000,0.91496,3770.37823,0.00000,0.00178,46.09941
18.40000,0.92010,3793.20048,0.00000,0.00179,46.37845
18.50000,0.92500,3812.94005,0.00000,0.00180,46.61980
18.60000,0.93009,3835.98767,0.00000,0.00182,46.90160
18.70000,0.93493,3855.87178,0.00000,0.00183,47.14471
18.80000,0.94007,3878.05998,0.00000,0.00184,47.41600
18.90000,0.94491,3898.56659,0.00000,0.00185,47.66673
19.00000,0.95006,3921.26851,0.00000,0.00186,47.94430
19.10000,0.95490,3942.54662,0.00000,0.00188,48.20446
19.20000,0.96004,3965.36514,0.00000,0.00189,48.48346
19.30000,0.96494,3986.38956,0.00000,0.00190,48.74052
19.40000,0.97008,4008.28160,0.00000,0.00191,49.00819
19.50000,0.97493,4028.88656,0.00000,0.00192,49.26012
19.60000,0.98001,4051.44617,0.00000,0.00194,49.53595
19.70000,0.98491,4073.55428,0.00000,0.00195,49.80626
19.80000,0.98999,4094.71728,0.00000,0.00196,50.06501
19.90000,0.99502,4119.05721,0.00000,0.00198,50.36261
20.00000,1.00004,4139.50048,0.00000,0.00199,50.61257
20.10000,1.00500,4163.39785,0.00000,0.00200,50.90475
20.20000,1.00996,4183.04950,0.00000,0.00201,51.14503
20.30000,1.01505,4206.95916,0.00000,0.00203,51.43736
20.40000,1.02001,4226.57914,0.00000,0.00204,51.67725
20.50000,1.02503,4250.60987,0.00000,0.00205,51.97107
20.60000,1.02987,4271.22675,0.00000,0.00206,52.22315
20.70000,1.03502,4294.41519,0.00000,0.00208,52.50667
20.80000,1.03992,4315.07900,0.00000,0.00209,52.75932
20.90000,1.04506,4339.22522,0.00000,0.00210,53.05455
21.00000,1.04990,4360.58454,0.00000,0.00212,53.31570
21.10000,1.05499,4384.37350,0.00000,0.00213,53.60656
21.20000,1.05989,4406.68091,0.00000,0.00214,53.87931
21.30000,1.06509,4429.18204,0.00000,0.00215,54.15442
21.40000,1.06999,4451.35273,0.00000,0.00216,54.42550
21.50000,1.07502,4474.32026,0.00000,0.00218,54.70632
21.60000,1.07992,4497.03485,0.00000,0.00219,54.98404
21.70000,1.08500,4518.83785,0.00000,0.00220,55.25062
21.80000,1.09002,4541.91044,0.00000,0.00222,55.53272
21.90000,1.09504,4563.47615,0.00000,0.00223,55.79640
22.00000,1.09995,4586.40233,0.00000,0.00224,56.07671
22.10000,1.10497,4608.15877,0.00000,0.00226,56.34272
22.20000,1.10999,4630.61668,0.00000,0.00227,56.61731
22.30000,1.11507,4651.71821,0.00000,0.00228,56.87531
22.40000,1.12004,4675.45912,0.00000,0.00230,57.16559
22.50000,1.12500,4698.28248,0.00000,0.00231,57.44464
22.60000,1.13008,4722.18245,0.00000,0.00232,57.73686
22.70000,1.13498,4743.49037,0.00000,0.00233,57.99739
22.80000,1.14007,4767.74201,0.00000,0.00235,58.29391
22.90000,1.14497,4789.25519,0.00000,0.00236,58.55694
23.00000,1.15005,4813.68527,0.00000,0.00237,58.85564
23.10000,1.15489,4834.51970,0.00000,0.00239,59.11038
23.20000,1.16010,4858.59960,0.00000,0.00240,59.40480
23.30000,1.16500,4878.93745,0.00000,0.00242,59.65346
23.40000,1.17008,4903.62644,0.00000,0.00243,59.95533
23.50000,1.17492,4926.08249,0.00000,0.00244,60.22989
23.60000,1.18007,4949.79285,0.00000,0.00245,60.51979
23.70000,1.18491,4971.72289,0.00000,0.00247,60.78793
23.80000,1.19011,4995.71674,0.00000,0.00248,61.08129
23.90000,1.19489,5017.82745,0.00000,0.00250,61.35163
24.00000,1.20003,5042.18079,0.00000,0.00251,61.64940
24.10000,1.20494,5064.02664,0.00000,0.00252,61.91650
24.20000,1.21008,5087.14989,0.00000,0.00253,62.19922
24.30000,1.21492,5109.25315,0.00000,0.00255,62.46947
24.40000,1.22000,5132.74558,0.00000,0.00256,62.75671
24.50000,1.22497,5156.30059,0.00000,0.00258,63.04471
24.60000,1.23005,5178.84269,0.00000,0.00259,63.32032
24.70000,1.23501,5203.12153,0.00000,0.00260,63.61718
24.80000,1.23997,5225.44943,0.00000,0.00261,63.89017
24.90000,1.24500,5250.29525,0.00000,0.00263,64.19396
25.00000,1.24996,5270.77019,0.00000,0.00264,64.44430
25.10000,1.25504,5296.63526,0.00000,0.00266,64.76054
25.20000,1.25994,5317.76696,0.00000,0.00267,65.01891
25.30000,1.26503,5342.69661,0.00000,0.00268,65.32372
25.40000,1.26987,5364.24108,0.00000,0.00269,65.58714
25.50000,1.27507,5388.51693,0.00000,0.00271,65.88396
25.60000,1.27991,5409.34876,0.00000,0.00272,66.13866
25.70000,1.28512,5434.12678,0.00000,0.00274,66.44161
25.80000,1.28996,5454.71907,0.00000,0.00275,66.69339
25.90000,1.29504,5479.27059,0.00000,0.00276,66.99358
26.00000,1.29988,5501.90061,0.00000,0.00278,67.27027
26.10000,1.30503,5524.88714,0.00000,0.00279,67.55132
26.20000,1.30993,5548.85827,0.00000,0.00280,67.84441
26.30000,1.31501,5574.54824,0.00000,0.00282,68.15851
26.40000,1.31991,5598.10549,0.00000,0.00283,68.44654
26.50000,1.32499,5621.73389,0.00000,0.00285,68.73544
26.60000,1.33002,5645.41854,0.00000,0.00286,69.02502
26.70000,1.33504,5668.22030,0.00000,0.00287,69.30381
26.80000,1.34000,5693.13355,0.00000,0.00289,69.60842
26.90000,1.34502,5716.21172,0.00000,0.00290,69.89059
27.00000,1.35005,5740.08860,0.00000,0.00292,70.18253
27.10000,1.35507,5760.93085,0.00000,0.00293,70.43736
27.20000,1.35997,5786.20806,0.00000,0.00295,70.74642
27.30000,1.36499,5809.44195,0.00000,0.00296,71.03049
27.40000,1.37002,5833.38588,0.00000,0.00297,71.32325
27.50000,1.37498,5856.29456,0.00000,0.00299,71.60335
27.60000,1.38006,5881.02192,0.00000,0.00300,71.90568
27.70000,1.38490,5903.24216,0.00000,0.00301,72.17736
27.80000,1.39005,5929.09120,0.00000,0.00303,72.49341
27.90000,1.39495,5950.95903,0.00000,0.00304,72.76078
28.00000,1.40015,5976.62516,0.00000,0.00306,73.07460
28.10000,1.40493,5998.62300,0.00000,0.00307,73.34356
28.20000,1.41008,6024.55996,0.00000,0.00309,73.66068
28.30000,1.41486,6047.12293,0.00000,0.00310,73.93655
28.40000,1.42006,6072.10621,0.00000,0.00312,74.24202
28.50000,1.42490,6094.46801,0.00000,0.00313,74.51543
28.60000,1.43005,6118.79043,0.00000,0.00315,74.81281
28.70000,1.43489,6142.46279,0.00000,0.00316,75.10225
28.80000,1.44003,6166.08150,0.00000,0.00317,75.39103
28.90000,1.44493,6191.36058,0.00000,0.00319,75.70011
29.00000,1.45007,6215.92067,0.00000,0.00320,76.00040
29.10000,1.45498,6239.41347,0.00000,0.00322,76.28764
29.20000,1.46000,6262.79190,0.00000,0.00323,76.57348
29.30000,1.46496,6286.59725,0.00000,0.00325,76.86454
29.40000,1.47004,6309.60315,0.00000,0.00327,77.14583
29.50000,1.47501,6334.93736,0.00000,0.00328,77.45558
29.60000,1.47997,6356.49115,0.00000,0.00329,77.71912
29.70000,1.48499,6383.04949,0.00000,0.00331,78.04384
29.80000,1.48989,6406.05465,0.00000,0.00332,78.32512
29.90000,1.49498,6431.43132,0.00000,0.00334,78.63539
30.00000,1.49994,6454.61828,0.00000,0.00336,78.91889
30.10000,1.50508,6481.50072,0.00000,0.00337,79.24758
30.20000,1.50992,6502.81906,0.00000,0.00339,79.50823
30.30000,1.51513,6528.94676,0.00000,0.00340,79.82769
30.40000,1.51991,6550.73151,0.00000,0.00341,80.09404
30.50000,1.52511,6576.60142,0.00000,0.00343,80.41035
30.60000,1.52989,6599.62520,0.00000,0.00344,80.69185
30.70000,1.53504,6623.96550,0.00000,0.00346,80.98945
30.80000,1.53988,6647.61961,0.00000,0.00347,81.27867
30.90000,1.54502,6671.31096,0.00000,0.00349,81.56833
31.00000,1.54986,6694.43533,0.00000,0.00351,81.85107
31.10000,1.55501,6720.02062,0.00000,0.00352,82.16389
31.20000,1.55991,6743.56446,0.00000,0.00354,82.45176
31.30000,1.56505,6767.21483,0.00000,0.00355,82.74093
31.40000,1.57001,6792.63249,0.00000,0.00357,83.05170
31.50000,1.57497,6817.14863,0.00000,0.00358,83.35145
31.60000,1.57994,6842.36437,0.00000,0.00360,83.65976
31.70000,1.58502,6865.66830,0.00000,0.00361,83.94469
31.80000,1.58998,6890.99059,0.00000,0.00363,84.25430
31.90000,1.59500,6913.58820,0.00000,0.00364,84.53059
32.00000,1.59997,6940.44083,0.00000,0.00366,84.85891
32.10000,1.60493,6963.22620,0.00000,0.00367,85.13750
32.20000,1.61001,6988.70793,0.00000,0.00369,85.44906
32.30000,1.61503,7012.54308,0.00000,0.00370,85.74049
32.40000,1.62012,7038.95241,0.00000,0.00372,86.06339
32.50000,1.62496,7061.95980,0.00000,0.00373,86.34469
32.60000,1.63004,7088.54645,0.00000,0.00375,86.66976
32.70000,1.63494,7109.61521,0.00000,0.00377,86.92736
32.80000,1.64009,7135.45457,0.00000,0.00378,87.24329
32.90000,1.64487,7158.83300,0.00000,0.00380,87.52914
33.00000,1.65007,7184.32069,0.00000,0.00381,87.84077
33.10000,1.65485,7207.46368,0.00000,0.00383,88.12373
33.20000,1.66006,7233.83874,0.00000,0.00384,88.44621
33.30000,1.66496,7257.18141,0.00000,0.00386,88.73162
33.40000,1.67004,7282.88740,0.00000,0.00388,89.04592
33.50000,1.67488,7307.05857,0.00000,0.00389,89.34145
33.60000,1.68003,7331.89061,0.00000,0.00391,89.64507
33.70000,1.68493,7356.14002,0.00000,0.00392,89.94156
33.80000,1.69001,7379.94686,0.00000,0.00394,90.23264
33.90000,1.69491,7404.79827,0.00000,0.00395,90.53649
34.00000,1.69993,7429.33899,0.00000,0.00397,90.83654
34.10000,1.70496,7454.86096,0.00000,0.00399,91.14859
34.20000,1.70998,7477.04133,0.00000,0.00400,91.41978
34.30000,1.71500,7503.18095,0.00000,0.00402,91.73939
34.40000,1.71996,7525.59528,0.00000,0.00403,92.01344
34.50000,1.72499,7551.81313,0.00000,0.00405,92.33400
34.60000,1.72995,7574.23863,0.00000,0.00407,92.60819
34.70000,1.73503,7600.06383,0.00000,0.00408,92.92395
34.80000,1.73993,7622.52659,0.00000,0.00410,93.19859
34.90000,1.74502,7650.42305,0.00000,0.00411,93.53968
35.00000,1.74986,7672.69284,0.00000,0.00413,93.81196
35.10000,1.75500,7698.64991,0.00000,0.00415,94.12933
35.20000,1.75990,7721.89945,0.00000,0.00416,94.41360
35.30000,1.76505,7748.00181,0.00000,0.00418,94.73275
35.40000,1.76989,7771.08222,0.00000,0.00419,95.01494
35.50000,1.77503,7796.87911,0.00000,0.00421,95.33036
35.60000,1.77993,7821.08381,0.00000,0.00423,95.62630
35.70000,1.78508,7847.84555,0.00000,0.00424,95.95351
35.80000,1.78998,7871.48401,0.00000,0.00426,96.24253
35.90000,1.79500,7897.04621,0.00000,0.00428,96.55507
36.00000,1.79996,7920.70627,0.00000,0.00429,96.84436
36.10000,1.80504,7944.84317,0.00000,0.00432,97.13947
36.20000,1.81001,7968.58743,0.00000,0.00433,97.42979
36.30000,1.81503,7993.69812,0.00000,0.00434,97.73681
36.40000,1.81993,8018.69333,0.00000,0.00436,98.04242
36.50000,1.82501,8043.89939,0.00000,0.00438,98.35061
36.60000,1.83004,8070.14704,0.00000,0.00440,98.67153
36.70000,1.83506,8094.67807,0.00000,0.00441,98.97146
36.80000,1.84002,8121.98296,0.00000,0.00443,99.30531
36.90000,1.84492,8144.78844,0.00000,0.00444,99.58415
37.00000,1.85001,8171.13295,0.00000,0.00446,99.90626
37.10000,1.85497,8194.68200,0.00000,0.00448,100.19418
37.20000,1.86005,8221.85948,0.00000,0.00450,100.52648
37.30000,1.86489,8244.90413,0.00000,0.00451,100.80824
37.40000,1.87004,8272.42285,0.00000,0.00453,101.14470
37.50000,1.87488,8295.11285,0.00000,0.00455,101.42213
37.60000,1.88008,8321.93270,0.00000,0.00457,101.75005
37.70000,1.88486,8346.02416,0.00000,0.00458,102.04461
37.80000,1.89007,8372.36196,0.00000,0.00460,102.36663
37.90000,1.89491,8395.53550,0.00000,0.00461,102.64997
38.00000,1.89999,8420.30570,0.00000,0.00463,102.95283
38.10000,1.90489,8444.89187,0.00000,0.00464,103.25343
38.20000,1.90998,8471.21701,0.00000,0.00466,103.57530
38.30000,1.91488,8496.42977,0.00000,0.00468,103.88357
38.40000,1.91996,8521.41082,0.00000,0.00469,104.18901
38.50000,1.92492,8545.49482,0.00000,0.00472,104.48348
38.60000,1.92994,8570.37529,0.00000,0.00473,104.78769
38.70000,1.93491,8597.07296,0.00000,0.00475,105.11411
38.80000,1.93993,8621.00273,0.00000,0.00477,105.40669
38.90000,1.94501,8648.22567,0.00000,0.00478,105.73954
39.00000,1.95003,8671.68680,0.00000,0.00480,106.02640
39.10000,1.95500,8698.39936,0.00000,0.00481,106.35300
39.20000,1.95996,8722.17715,0.00000,0.00483,106.64373
39.30000,1.96504,8748.61777,0.00000,0.00485,106.96701
39.40000,1.96994,8771.28839,0.00000,0.00486,107.24420
39.50000,1.97503,8795.57580,0.00000,0.00488,107.54115
39.60000,1.97993,8819.47502,0.00000,0.00490,107.83336
39.70000,1.98501,8846.39397,0.00000,0.00492,108.16249
39.80000,1.98985,8869.31568,0.00000,0.00493,108.44275
39.90000,1.99512,8896.70029,0.00000,0.00495,108.77757
40.00000,2.00002,8920.51309,0.00000,0.00497,109.06873
40.10000,2.00510,8947.54604,0.00000,0.00498,109.39925
40.20000,2.00994,8972.12029,0.00000,0.00500,109.69971
40.30000,2.01509,8998.11536,0.00000,0.00502,110.01755
40.40000,2.01999,9023.23723,0.00000,0.00503,110.32471
40.50000,2.02507,9048.44329,0.00000,0.00506,110.63290
40.60000,2.02991,9072.84915,0.00000,0.00507,110.93130
40.70000,2.03499,9099.53043,0.00000,0.00509,111.25752
40.80000,2.03990,9123.58537,0.00000,0.00511,111.55164
40.90000,2.04504,9149.35470,0.00000,0.00512,111.86671
41.00000,2.05000,9174.80290,0.00000,0.00515,112.17786
41.10000,2.05502,9199.54106,0.00000,0.00516,112.48033
41.20000,2.05999,9225.98839,0.00000,0.00518,112.80369
41.30000,2.06507,9249.85707,0.00000,0.00519,113.09553
41.40000,2.07003,9277.22231,0.00000,0.00521,113.43012
41.50000,2.07499,9301.09248,0.00000,0.00524,113.72197
41.60000,2.07996,9328.09636,0.00000,0.00524,114.05214
41.70000,2.08498,9351.09183,0.00000,0.00526,114.33330
41.80000,2.09006,9377.10404,0.00000,0.00528,114.65134
41.90000,2.09496,9399.87898,0.00000,0.00530,114.92981
42.00000,2.10005,9426.99611,0.00000,0.00532,115.26136
42.10000,2.10489,9452.90402,0.00000,0.00533,115.57813
42.20000,2.11009,9480.16495,0.00000,0.00536,115.91144
42.30000,2.11493,9504.10962,0.00000,0.00537,116.20421
42.40000,2.12014,9531.76096,0.00000,0.00539,116.54229
42.50000,2.12486,9555.90606,0.00000,0.00541,116.83751
42.60000,2.13000,9582.92931,0.00000,0.00542,117.16791
42.70000,2.13484,9605.87487,0.00000,0.00545,117.44846
42.80000,2.13999,9632.24173,0.00000,0.00546,117.77084
42.90000,2.14489,9656.94264,0.00000,0.00548,118.07285
43.00000,2.14997,9682.70525,0.00000,0.00550,118.38785
43.10000,2.15487,9707.61180,0.00000,0.00551,118.69237
43.20000,2.16001,9733.43179,0.00000,0.00554,119.00807
43.30000,2.16498,9758.42252,0.00000,0.00555,119.31362
43.40000,2.17006,9782.39775,0.00000,0.00557,119.60676
43.50000,2.17496,9807.66565,0.00000,0.00559,119.91570
43.60000,2.17998,9831.54699,0.00000,0.00560,120.20770
43.70000,2.18501,9858.96662,0.00000,0.00563,120.54295
43.80000,2.19003,9883.23838,0.00000,0.00564,120.83971
43.90000,2.19499,9909.97031,0.00000,0.00566,121.16656
44.00000,2.19995,9934.64068,0.00000,0.00568,121.46819
44.10000,2.20504,9961.48735,0.00000,0.00569,121.79644
44.20000,2.20994,9984.99691,0.00000,0.00572,122.08389
44.30000,2.21514,10011.58804,0.00000,0.00573,122.40901
44.40000,2.21992,10035.54240,0.00000,0.00576,122.70189
44.50000,2.22507,10063.10284,0.00000,0.00578,123.03887
44.60000,2.22991,10087.53553,0.00000,0.00578,123.33760
44.70000,2.23511,10114.90375,0.00000,0.00582,123.67222
44.80000,2.23995,10138.98700,0.00000,0.00582,123.96668
44.90000,2.24510,10166.04230,0.00000,0.00585,124.29748
45.00000,2.24994,10190.48467,0.00000,0.00586,124.59633
45.10000,2.25508,10216.07593,0.00000,0.00587,124.90923
45.20000,2.25992,10240.14056,0.00000,0.00591,125.20346
45.30000,2.26506,10266.94849,0.00000,0.00591,125.53123
45.40000,2.26997,10291.88633,0.00000,0.00594,125.83614
45.50000,2.27505,10318.89096,0.00000,0.00595,126.16632
45.60000,2.27995,10344.61185,0.00000,0.00597,126.48080
45.70000,2.28503,10370.52199,0.00000,0.00600,126.79760
45.80000,2.28994,10395.89047,0.00000,0.00601,127.10777
45.90000,2.29502,10420.99223,0.00000,0.00603,127.41468
46.00000,2.29992,10447.62582,0.00000,0.00604,127.74033
46.10000,2.30500,10472.39751,0.00000,0.00606,128.04320
46.20000,2.31003,10499.60926,0.00000,0.00609,128.37591
46.30000,2.31493,10522.74257,0.00000,0.00609,128.65876
46.40000,2.31995,10551.02795,0.00000,0.00612,129.00460
46.50000,2.32491,10574.41980,0.00000,0.00614,129.29060
46.60000,2.33006,10601.27318,0.00000,0.00615,129.61893
46.70000,2.33496,10624.18148,0.00000,0.00618,129.89903
46.80000,2.34004,10651.32990,0.00000,0.00619,130.23096
46.90000,2.34488,10674.78880,0.00000,0.00621,130.51779
47.00000,2.35009,10702.33360,0.00000,0.00623,130.85457
47.10000,2.35487,10727.11498,0.00000,0.00625,131.15757
47.20000,2.36007,10752.41119,0.00000,0.00627,131.46686
47.30000,2.36485,10778.12761,0.00000,0.00628,131.78128
47.40000,2.37000,10804.03551,0.00000,0.00631,132.09805
47.50000,2.37484,10828.01446,0.00000,0.00632,132.39124
47.60000,2.38004,10854.98855,0.00000,0.00634,132.72104
47.70000,2.38494,10880.33468,0.00000,0.00636,133.03094
47.80000,2.39003,10906.04663,0.00000,0.00638,133.34532
47.90000,2.39493,10933.01550,0.00000,0.00640,133.67506
48.00000,2.40001,10957.55398,0.00000,0.00641,133.97508
48.10000,2.40503,10984.11754,0.00000,0.00643,134.29987
48.20000,2.40999,11008.07488,0.00000,0.00645,134.59279
48.30000,2.41496,11034.57808,0.00000,0.00647,134.91683
48.40000,2.41998,11057.91703,0.00000,0.00650,135.20219
48.50000,2.42500,11084.83225,0.00000,0.00651,135.53128
48.60000,2.43008,11109.23290,0.00000,0.00653,135.82962
48.70000,2.43511,11135.72195,0.00000,0.00655,136.15349
48.80000,2.44001,11160.00935,0.00000,0.00657,136.45045
48.90000,2.44509,11187.61376,0.00000,0.00659,136.78796
49.00000,2.44999,11210.76718,0.00000,0.00661,137.07105
49.10000,2.45514,11237.56990,0.00000,0.00663,137.39876
49.20000,2.45998,11261.44305,0.00000,0.00664,137.69065
49.30000,2.46512,11289.47511,0.00000,0.00666,138.03339
49.40000,2.46996,11312.01982,0.00000,0.00668,138.30904
49.50000,2.47511,11339.56611,0.00000,0.00670,138.64584
49.60000,2.47995,11363.06897,0.00000,0.00672,138.93320
49.70000,2.48509,11391.34094,0.00000,0.00674,139.27888
49.80000,2.48993,11417.24885,0.00000,0.00676,139.59565
49.90000,2.49508,11441.95274,0.00000,0.00678,139.89770
50.00000,2.49992,11466.56349,0.00000,0.00679,140.19860
50.10000,2.50506,11492.60402,0.00000,0.00681,140.51700
50.20000,2.50990,11518.78461,0.00000,0.00683,140.83710
50.30000,2.51505,11544.87953,0.00000,0.00685,141.15615
50.40000,2.51995,11569.27645,0.00000,0.00687,141.45445
50.50000,2.52503,11593.65699,0.00000,0.00688,141.75254
50.60000,2.52993,11619.03292,0.00000,0.00691,142.06281
50.70000,2.53495,11645.01533,0.00000,0.00692,142.38049
50.80000,2.53998,11672.29339,0.00000,0.00695,142.71401
50.90000,2.54506,11696.37963,0.00000,0.00696,143.00851
51.00000,2.55002,11722.13405,0.00000,0.00698,143.32340
51.10000,2.55498,11746.70458,0.00000,0.00700,143.62381
51.20000,2.55995,11773.96625,0.00000,0.00702,143.95714
51.30000,2.56491,11798.86386,0.00000,0.00704,144.26155
51.40000,2.57011,11826.00334,0.00000,0.00706,144.59338
51.50000,2.57489,11847.57724,0.00000,0.00708,144.85716
51.60000,2.58004,11875.36791,0.00000,0.00710,145.19695
51.70000,2.58488,11899.05629,0.00000,0.00712,145.48658
51.80000,2.59008,11926.03260,0.00000,0.00714,145.81641
51.90000,2.59492,11949.31418,0.00000,0.00716,146.10107
52.00000,2.60007,11977.23821,0.00000,0.00718,146.44249
52.10000,2.60491,12001.16426,0.00000,0.00719,146.73503
52.20000,2.61005,12027.47375,0.00000,0.00721,147.05670
52.30000,2.61495,12052.62616,0.00000,0.00723,147.36424
52.40000,2.62004,12078.32992,0.00000,0.00725,147.67851
52.50000,2.62500,12103.30427,0.00000,0.00727,147.98386
52.60000,2.63002,12128.92085,0.00000,0.00729,148.29707
52.70000,2.63492,12153.82963,0.00000,0.00731,148.60162
52.80000,2.64000,12179.38140,0.00000,0.00732,148.91404
52.90000,2.64497,12205.38616,0.00000,0.00735,149.23199
53.00000,2.64999,12230.37615,0.00000,0.00737,149.53754
53.10000,2.65501,12258.32477,0.00000,0.00739,149.87926
53.20000,2.66003,12282.41399,0.00000,0.00740,150.17379
53.30000,2.66506,12309.20851,0.00000,0.00743,150.50140
53.40000,2.67002,12334.03310,0.00000,0.00745,150.80492
53.50000,2.67504,12360.83731,0.00000,0.00747,151.13265
53.60000,2.68000,12386.82419,0.00000,0.00749,151.45039
53.70000,2.68503,12412.95934,0.00000,0.00751,151.76993
53.80000,2.68999,12436.31244,0.00000,0.00753,152.05547
53.90000,2.69507,12463.59050,0.00000,0.00755,152.38899
54.00000,2.69991,12485.98993,0.00000,0.00756,152.66286
54.10000,2.70506,12514.40346,0.00000,0.00759,153.01026
54.20000,2.70996,12538.33920,0.00000,0.00760,153.30292
54.30000,2.71510,12566.48600,0.00000,0.00763,153.64706
54.40000,2.71994,12590.68251,0.00000,0.00764,153.94291
54.50000,2.72503,12618.61175,0.00000,0.00766,154.28439
54.60000,2.72987,12643.68147,0.00000,0.00768,154.59091
54.70000,2.73507,12669.68101,0.00000,0.00770,154.90880
54.80000,2.73991,12695.06365,0.00000,0.00772,155.21915
54.90000,2.74500,12720.24363,0.00000,0.00774,155.52702
55.00000,2.74990,12745.49663,0.00000,0.00776,155.83578
55.10000,2.75504,12771.85977,0.00000,0.00778,156.15811
55.20000,2.75994,12798.17522,0.00000,0.00780,156.47987
55.30000,2.76508,12823.82905,0.00000,0.00782,156.79353
55.40000,2.76999,12850.08788,0.00000,0.00784,157.11459
55.50000,2.77501,12875.09352,0.00000,0.00786,157.42032
55.60000,2.77997,12901.73978,0.00000,0.00788,157.74612
55.70000,2.78499,12924.68160,0.00000,0.00789,158.02662
55.80000,2.79002,12951.58565,0.00000,0.00791,158.35557
55.90000,2.79492,12975.52884,0.00000,0.00794,158.64832
56.00000,2.80000,13003.41636,0.00000,0.00795,158.98929
56.10000,2.80490,13026.58916,0.00000,0.00797,159.27262
56.20000,2.81005,13052.95974,0.00000,0.00799,159.59505
56.30000,2.81489,13076.55126,0.00000,0.00801,159.88349
56.40000,2.82009,13103.91128,0.00000,0.00803,160.21802
56.50000,2.82487,13127.36571,0.00000,0.00805,160.50479
56.60000,2.83008,13153.49787,0.00000,0.00807,160.82430
56.70000,2.83492,13178.86412,0.00000,0.00809,161.13445
56.80000,2.84006,13204.57906,0.00000,0.00811,161.44886
56.90000,2.84484,13230.45045,0.00000,0.00813,161.76518
57.00000,2.84993,13255.52613,0.00000,0.00815,162.07177
57.10000,2.85489,13280.91621,0.00000,0.00817,162.38221
57.20000,2.86003,13306.08279,0.00000,0.00819,162.68992
57.30000,2.86493,13331.21806,0.00000,0.00820,162.99724
57.40000,2.87002,13356.43679,0.00000,0.00823,163.30558
57.50000,2.87498,13382.03847,0.00000,0.00825,163.61861
57.60000,2.88006,13407.55075,0.00000,0.00827,163.93054
57.70000,2.88502,13434.16572,0.00000,0.00829,164.25595
57.80000,2.88999,13459.81658,0.00000,0.00831,164.56958
57.90000,2.89501,13487.66237,0.00000,0.00833,164.91004
58.00000,2.90003,13510.71298,0.00000,0.00835,165.19187
58.10000,2.90499,13537.42331,0.00000,0.00837,165.51845
58.20000,2.91001,13561.92231,0.00000,0.00839,165.81800
58.30000,2.91498,13588.87702,0.00000,0.00841,166.14756
58.40000,2.91994,13613.01243,0.00000,0.00843,166.44266
58.50000,2.92502,13640.22791,0.00000,0.00845,166.77542
58.60000,2.92998,13664.21282,0.00000,0.00847,167.06868
58.70000,2.93507,13692.06011,0.00000,0.00849,167.40916
58.80000,2.93991,13715.33573,0.00000,0.00851,167.69374
58.90000,2.94511,13743.64495,0.00000,0.00853,168.03987
59.00000,2.94989,13766.88033,0.00000,0.00855,168.32396
59.10000,2.95516,13794.44301,0.00000,0.00857,168.66097
59.20000,2.95994,13817.80952,0.00000,0.00859,168.94666
59.30000,2.96508,13846.25584,0.00000,0.00861,169.29447
59.40000,2.96986,13869.59255,0.00000,0.00863,169.57980
59.50000,2.97507,13896.23582,0.00000,0.00865,169.90556
59.60000,2.97997,13920.37868,0.00000,0.00867,170.20075
59.70000,2.98505,13945.58251,0.00000,0.00869,170.50891
59.80000,2.98989,13970.42274,0.00000,0.00871,170.81262
59.90000,2.99498,13996.62942,0.00000,0.00874,171.13304
60.00000,2.99994,14021.52777,0.00000,0.00875,171.43747
60.10000,3.00502,14046.62430,0.00000,0.00877,171.74432
60.20000,3.00992,14074.16463,0.00000,0.00879,172.08105
60.30000,3.01494,14097.53710,0.00000,0.00881,172.36682
60.40000,3.01997,14125.75841,0.00000,0.00883,172.71187
60.50000,3.02499,14148.51397,0.00000,0.00885,172.99010
60.60000,3.03001,14174.77727,0.00000,0.00887,173.31121
60.70000,3.03491,14197.79807,0.00000,0.00889,173.59268
60.80000,3.04006,14226.16690,0.00000,0.00891,173.93954
60.90000,3.04496,14249.13853,0.00000,0.00893,174.22041
61.00000,3.05010,14278.36269,0.00000,0.00895,174.57772
61.10000,3.05494,14300.43727,0.00000,0.00897,174.84762
61.20000,3.06015,14328.25178,0.00000,0.00899,175.18770
61.30000,3.06493,14351.92078,0.00000,0.00901,175.47710
61.40000,3.07007,14377.41518,0.00000,0.00903,175.78881
61.50000,3.07491,14402.00061,0.00000,0.00905,176.08941
61.60000,3.08000,14427.40560,0.00000,0.00907,176.40003
61.70000,3.08484,14453.80747,0.00000,0.00909,176.72284
61.80000,3.08998,14480.37922,0.00000,0.00911,177.04772
61.90000,3.09494,14505.68140,0.00000,0.00913,177.35709
62.00000,3.10009,14531.56024,0.00000,0.00915,177.67350
62.10000,3.10499,14557.04570,0.00000,0.00917,177.98510
62.20000,3.11001,14582.29125,0.00000,0.00919,178.29377
62.30000,3.11497,14607.69475,0.00000,0.00921,178.60438
62.40000,3.12005,14633.44097,0.00000,0.00923,178.91917
62.50000,3.12490,14659.21402,0.00000,0.00925,179.23429
62.60000,3.12998,14685.35811,0.00000,0.00927,179.55395
62.70000,3.13494,14711.65717,0.00000,0.00929,179.87550
62.80000,3.14002,14735.30382,0.00000,0.00931,180.16462
62.90000,3.14505,14761.55519,0.00000,0.00933,180.48559
63.00000,3.15007,14784.78163,0.00000,0.00935,180.76957
63.10000,3.15503,14813.48127,0.00000,0.00937,181.12047
63.20000,3.15999,14836.97593,0.00000,0.00940,181.40774
63.30000,3.16502,14864.10946,0.00000,0.00942,181.73949
63.40000,3.16992,14886.99019,0.00000,0.00943,182.01925
63.50000,3.17500,14914.88814,0.00000,0.00946,182.36035
63.60000,3.17984,14938.79259,0.00000,0.00948,182.65262
63.70000,3.18505,14966.67415,0.00000,0.00950,182.99352
63.80000,3.18989,14990.58604,0.00000,0.00952,183.28589
63.90000,3.19509,15016.21306,0.00000,0.00954,183.59922
64.00000,3.19987,15041.16505,0.00000,0.00956,183.90430
64.10000,3.20508,15068.94082,0.00000,0.00958,184.24391
64.20000,3.20992,15094.32495,0.00000,0.00960,184.55427
64.30000,3.21506,15120.80580,0.00000,0.00962,184.87805
64.40000,3.21990,15145.37185,0.00000,0.00964,185.17841
64.50000,3.22505,15171.69029,0.00000,0.00966,185.50020
64.60000,3.22989,15195.94491,0.00000,0.00968,185.79675
64.70000,3.23497,15220.56907,0.00000,0.00970,186.09783
64.80000,3.23999,15247.44332,0.00000,0.00973,186.42641
64.90000,3.24501,15271.34925,0.00000,0.00974,186.71870
65.00000,3.24992,15297.72431,0.00000,0.00977,187.04118
65.10000,3.25494,15321.88654,0.00000,0.00978,187.33661
65.20000,3.26002,15349.76363,0.00000,0.00981,187.67745
65.30000,3.26498,15373.74407,0.00000,0.00983,187.97066
65.40000,3.27001,15400.94614,0.00000,0.00985,188.30325
65.50000,3.27491,15424.02059,0.00000,0.00987,188.58537
65.60000,3.28005,15452.20166,0.00000,0.00989,188.92994
65.70000,3.28495,15475.15094,0.00000,0.00991,189.21053
65.80000,3.29010,15502.99078,0.00000,0.00993,189.55092
65.90000,3.29494,15525.77168,0.00000,0.00995,189.82946
66.00000,3.30002,15553.67708,0.00000,0.00997,190.17065
66.10000,3.30492,15577.18068,0.00000,0.00999,190.45802
66.20000,3.31013,15604.10857,0.00000,0.01001,190.78726
66.30000,3.31497,15628.34680,0.00000,0.01003,191.08362
66.40000,3.32005,15654.36423,0.00000,0.01005,191.40172
66.50000,3.32495,15681.02837,0.00000,0.01007,191.72774
66.60000,3.33004,15706.77757,0.00000,0.01010,192.04257
66.70000,3.33494,15732.48804,0.00000,0.01011,192.35692
66.80000,3.34002,15757.74252,0.00000,0.01013,192.66570
66.90000,3.34486,15782.35030,0.00000,0.01016,192.96658
67.00000,3.35001,15808.45863,0.00000,0.01018,193.28580
67.10000,3.35497,15834.16313,0.00000,0.01020,193.60008
67.20000,3.36005,15859.40570,0.00000,0.01022,193.90871
67.30000,3.36495,15885.12659,0.00000,0.01024,194.22319
67.40000,3.37003,15911.21703,0.00000,0.01026,194.54219
67.50000,3.37500,15938.49212,0.00000,0.01029,194.87568
67.60000,3.38002,15962.91363,0.00000,0.01030,195.17428
67.70000,3.38504,15989.75211,0.00000,0.01033,195.50242
67.80000,3.39000,16013.00836,0.00000,0.01035,195.78677
67.90000,3.39497,16039.73359,0.00000,0.01037,196.11353
68.00000,3.39993,16063.74830,0.00000,0.01039,196.40715
68.10000,3.40507,16090.03842,0.00000,0.01041,196.72860
68.20000,3.40991,16113.82216,0.00000,0.01043,197.01939
68.30000,3.41506,16140.71727,0.00000,0.01045,197.34823
68.40000,3.41990,16165.49343,0.00000,0.01047,197.65116
68.50000,3.42510,16193.04419,0.00000,0.01049,197.98802
68.60000,3.42994,16215.82508,0.00000,0.01052,198.26656
68.70000,3.43509,16242.59204,0.00000,0.01053,198.59383
68.80000,3.43987,16268.25929,0.00000,0.01055,198.90765
68.90000,3.44501,16294.75951,0.00000,0.01058,199.23167
69.00000,3.44985,16319.52226,0.00000,0.01060,199.53443
69.10000,3.45500,16344.75142,0.00000,0.01062,199.84290
69.20000,3.45990,16369.43370,0.00000,0.01064,200.14469
69.30000,3.46492,16394.86402,0.00000,0.01066,200.45562
69.40000,3.46988,16420.76969,0.00000,0.01068,200.77236
69.50000,3.47497,16444.24200,0.00000,0.01070,201.05935
69.60000,3.47999,16471.37254,0.00000,0.01072,201.39107
69.70000,3.48507,16494.88360,0.00000,0.01075,201.67853
69.80000,3.48997,16522.68916,0.00000,0.01076,202.01850
69.90000,3.49499,16546.56827,0.00000,0.01078,202.31046
70.00000,3.50002,16573.15344,0.00000,0.01081,202.63551
70.10000,3.50498,16597.29034,0.00000,0.01083,202.93063
70.20000,3.51000,16623.08127,0.00000,0.01085,203.24597
70.30000,3.51490,16647.20029,0.00000,0.01087,203.54087
70.40000,3.52005,16674.52157,0.00000,0.01089,203.87492
70.50000,3.52495,16698.30829,0.00000,0.01091,204.16575
70.60000,3.53015,16726.17495,0.00000,0.01093,204.50647
70.70000,3.53493,16750.28950,0.00000,0.01095,204.80131
70.80000,3.54008,16777.43495,0.00000,0.01097,205.13321
70.90000,3.54498,16802.47039,0.00000,0.01100,205.43931
71.00000,3.55012,16827.96031,0.00000,0.01101,205.75097
71.10000,3.55496,16852.97638,0.00000,0.01104,206.05683
71.20000,3.56005,16879.59880,0.00000,0.01106,206.38234
71.30000,3.56489,16903.12624,0.00000,0.01108,206.67000
71.40000,3.57003,16930.21953,0.00000,0.01110,207.00127
71.50000,3.57499,16955.18345,0.00000,0.01112,207.30649
71.60000,3.58007,16980.57503,0.00000,0.01114,207.61695
71.70000,3.58492,17005.71477,0.00000,0.01116,207.92433
71.80000,3.59006,17031.64130,0.00000,0.01118,208.24132
71.90000,3.59496,17056.35786,0.00000,0.01120,208.54353
72.00000,3.60004,17081.69281,0.00000,0.01123,208.85329
72.10000,3.60489,17106.84896,0.00000,0.01125,209.16087
72.20000,3.60997,17132.98410,0.00000,0.01127,209.48041
72.30000,3.61493,17160.42161,0.00000,0.01129,209.81589
72.40000,3.62001,17183.75832,0.00000,0.01131,210.10122
72.50000,3.62504,17210.45822,0.00000,0.01134,210.42767
72.60000,3.62994,17234.21961,0.00000,0.01135,210.71819
72.70000,3.63502,17261.44552,0.00000,0.01138,211.05108
72.80000,3.63992,17284.53338,0.00000,0.01140,211.33337
72.90000,3.64507,17311.93066,0.00000,0.01142,211.66835
73.00000,3.64991,17334.20938,0.00000,0.01144,211.94074
73.10000,3.65505,17362.78832,0.00000,0.01146,212.29017
73.20000,3.65983,17385.14006,0.00000,0.01148,212.56346
73.30000,3.66510,17412.80258,0.00000,0.01151,212.90168
73.40000,3.66994,17435.53281,0.00000,0.01153,213.17960
73.50000,3.67508,17460.44308,0.00000,0.01155,213.48417
73.60000,3.67986,17485.36974,0.00000,0.01157,213.78894
73.70000,3.68495,17510.95951,0.00000,0.01159,214.10182
73.80000,3.68991,17535.91597,0.00000,0.01162,214.40695
73.90000,3.69505,17560.59080,0.00000,0.01164,214.70865
74.00000,3.69995,17586.65293,0.00000,0.01166,215.02730
74.10000,3.70498,17611.81206,0.00000,0.01168,215.33492
74.20000,3.70994,17637.03674,0.00000,0.01170,215.64333
74.30000,3.71502,17661.33308,0.00000,0.01172,215.94040
74.40000,3.72004,17687.67983,0.00000,0.01175,216.26253
74.50000,3.72495,17710.69914,0.00000,0.01177,216.54398
74.60000,3.72997,17738.37507,0.00000,0.01179,216.88237
74.70000,3.73499,17764.05722,0.00000,0.01181,217.19638
74.80000,3.74007,17790.79735,0.00000,0.01183,217.52332
74.90000,3.74503,17813.80922,0.00000,0.01185,217.80468
75.00000,3.75006,17839.76108,0.00000,0.01188,218.12199
75.10000,3.75496,17863.85924,0.00000,0.01190,218.41663
75.20000,3.76010,17890.94657,0.00000,0.01192,218.74782
75.30000,3.76500,17913.47116,0.00000,0.01194,219.02322
75.40000,3.77015,17940.59873,0.00000,0.01196,219.35490
75.50000,3.77493,17964.29604,0.00000,0.01198,219.64464
75.60000,3.78007,17991.87064,0.00000,0.01200,219.98179
75.70000,3.78491,18014.59491,0.00000,0.01202,220.25963
75.80000,3.79012,18042.07265,0.00000,0.01205,220.59560
75.90000,3.79484,18063.20995,0.00000,0.01206,220.85404
76.00000,3.79998,18090.07674,0.00000,0.01209,221.18253
76.10000,3.80494,18115.65012,0.00000,0.01211,221.49521
76.20000,3.81009,18140.72132,0.00000,0.01213,221.80175
76.30000,3.81499,18166.40794,0.00000,0.01215,222.11581
76.40000,3.82007,18190.93525,0.00000,0.01217,222.41570
76.50000,3.82491,18215.56240,0.00000,0.01219,222.71681
76.60000,3.83006,18240.89736,0.00000,0.01222,223.02657
76.70000,3.83496,18265.62583,0.00000,0.01224,223.32892
76.80000,3.84004,18289.43342,0.00000,0.01226,223.62001
76.90000,3.84494,18315.57751,0.00000,0.01228,223.93967
77.00000,3.84996,18338.81438,0.00000,0.01230,224.22378
77.10000,3.85499,18365.64094,0.00000,0.01232,224.55178
77.20000,3.86001,18388.62300,0.00000,0.01235,224.83277
77.30000,3.86503,18414.87586,0.00000,0.01237,225.15376
77.40000,3.86993,18438.71921,0.00000,0.01239,225.44529
77.50000,3.87496,18463.57584,0.00000,0.01241,225.74920
77.60000,3.87992,18488.14189,0.00000,0.01243,226.04957
77.70000,3.88506,18515.85805,0.00000,0.01245,226.38844
77.80000,3.88990,18537.57948,0.00000,0.01247,226.65403
77.90000,3.89505,18564.61167,0.00000,0.01250,226.98454
78.00000,3.89989,18588.61446,0.00000,0.01251,227.27802
78.10000,3.90503,18615.19367,0.00000,0.01254,227.60299
78.20000,3.90993,18638.36050,0.00000,0.01256,227.88625
78.30000,3.91508,18664.48522,0.00000,0.01258,228.20567
78.40000,3.91992,18688.02011,0.00000,0.01260,228.49342
78.50000,3.92506,18713.16731,0.00000,0.01263,228.80089
78.60000,3.92996,18737.85257,0.00000,0.01265,229.10271
78.70000,3.93505,18761.66910,0.00000,0.01267,229.39391
78.80000,3.93995,18787.17393,0.00000,0.01269,229.70575
78.90000,3.94497,18811.66697,0.00000,0.01272,230.00522
79.00000,3.94993,18836.91400,0.00000,0.01274,230.31391
79.10000,3.95501,18861.40108,0.00000,0.01276,230.61331
79.20000,3.96004,18887.10409,0.00000,0.01278,230.92757
79.30000,3.96500,18910.01612,0.00000,0.01280,231.20771
79.40000,3.97002,18937.81275,0.00000,0.01283,231.54757
79.50000,3.97504,18960.74563,0.00000,0.01285,231.82797
79.60000,3.98013,18987.00893,0.00000,0.01287,232.14908
79.70000,3.98503,19010.04463,0.00000,0.01289,232.43073
79.80000,3.99005,19035.32892,0.00000,0.01292,232.73988
79.90000,3.99495,19060.89038,0.00000,0.01294,233.05241
80.00000,4.00010,19086.73942,0.00000,0.01296,233.36846
80.10000,4.00500,19109.04944,0.00000,0.01298,233.64124
80.20000,4.01014,19134.55725,0.00000,0.01300,233.95311
80.30000,4.01492,19156.64524,0.00000,0.01303,234.22318
80.40000,4.02007,19183.54779,0.00000,0.01305,234.55211
80.50000,4.02497,19206.19011,0.00000,0.01307,234.82895
80.60000,4.03011,19231.95273,0.00000,0.01309,235.14394
80.70000,4.03495,19253.56835,0.00000,0.01311,235.40823
80.80000,4.04004,19279.68264,0.00000,0.01313,235.72752
80.90000,4.04488,19302.72430,0.00000,0.01316,236.00925
81.00000,4.05008,19327.68673,0.00000,0.01318,236.31446
81.10000,4.05492,19351.75657,0.00000,0.01320,236.60875
81.20000,4.06001,19377.05576,0.00000,0.01322,236.91808
81.30000,4.06491,19402.35347,0.00000,0.01324,237.22739
81.40000,4.06999,19427.07151,0.00000,0.01327,237.52961
81.50000,4.07495,19452.15613,0.00000,0.01329,237.83631
81.60000,4.08003,19475.32296,0.00000,0.01331,238.11956
81.70000,4.08494,19500.10061,0.00000,0.01333,238.42251
81.80000,4.08996,19522.75932,0.00000,0.01335,238.69956
81.90000,4.09498,19549.93159,0.00000,0.01338,239.03178
82.00000,4.10000,19572.43979,0.00000,0.01340,239.30699
82.10000,4.10503,19597.99677,0.00000,0.01342,239.61946
82.20000,4.10987,19619.48425,0.00000,0.01344,239.88219
82.30000,4.11501,19647.07673,0.00000,0.01346,240.21955
82.40000,4.11985,19668.78474,0.00000,0.01348,240.48497
82.50000,4.12506,19694.53990,0.00000,0.01351,240.79987
82.60000,4.12990,19716.24047,0.00000,0.01353,241.06520
82.70000,4.13504,19742.28919,0.00000,0.01355,241.38369
82.80000,4.13988,19764.79441,0.00000,0.01357,241.65885
82.90000,4.14503,19790.10701,0.00000,0.01359,241.96835
83.00000,4.14993,19814.89360,0.00000,0.01362,242.27140
83.10000,4.15501,19840.01547,0.00000,0.01364,242.57856
83.20000,4.15991,19864.76779,0.00000,0.01366,242.88120
83.30000,4.16500,19888.94790,0.00000,0.01369,243.17685
83.40000,4.16996,19913.20252,0.00000,0.01371,243.47340
83.50000,4.17504,19936.13243,0.00000,0.01373,243.75376
83.60000,4.17988,19957.99989,0.00000,0.01375,244.02113
83.70000,4.18497,19982.66578,0.00000,0.01377,244.32271
83.80000,4.18999,20008.02308,0.00000,0.01380,244.63275
83.90000,4.19507,20030.95746,0.00000,0.01382,244.91316
84.00000,4.20003,20056.08082,0.00000,0.01384,245.22034
84.10000,4.20500,20078.61584,0.00000,0.01387,245.49587
84.20000,4.21002,20104.29949,0.00000,0.01389,245.80989
84.30000,4.21504,20126.76597,0.00000,0.01391,246.08458
84.40000,4.22000,20152.13519,0.00000,0.01393,246.39477
84.50000,4.22502,20174.64489,0.00000,0.01396,246.66999
84.60000,4.22999,20198.94868,0.00000,0.01398,246.96714
84.70000,4.23489,20222.55659,0.00000,0.01400,247.25579
84.79800,4.23997,19649.76490,0.00000,0.01396,240.25242
84.80000,4.24015,19013.63283,0.00000,0.01375,232.47460
84.80200,4.24039,18198.50206,0.00000,0.01327,222.50822
84.80400,4.24057,17260.32197,0.00000,0.01247,211.03734
84.80600,4.24087,16221.68273,0.00000,0.01135,198.33818
84.80800,4.24123,15113.22260,0.00000,0.00989,184.78533
84.81000,4.24159,13972.12893,0.00000,0.00803,170.83348
84.81200,4.24189,12818.90124,0.00000,0.00579,156.73328
84.81400,4.24224,11663.98972,0.00000,0.00328,142.61248