File: scratch/college-stuff/ME Lab/ME lab Fall 2013/group4/group4.is_tens_RawData/Specimen_RawData_5.csv
Time,Extension,Load,Strain 2,Tensile strain,Tensile stress
(sec),(mm),(N),(mm/mm),(mm/mm),(MPa)
0.00000,0.00000,-0.41071,0.00000,0.00000,-0.00515
0.10000,0.00179,4.23877,0.00000,0.00001,0.05310
0.20000,0.00765,22.12499,0.00000,0.00001,0.27717
0.30000,0.01369,28.10851,0.00000,0.00001,0.35213
0.40000,0.01955,34.71651,0.00000,0.00001,0.43491
0.50000,0.02475,39.10536,0.00000,0.00001,0.48989
0.60000,0.03001,41.58751,0.00000,0.00001,0.52098
0.70000,0.03498,44.81957,0.00000,0.00002,0.56147
0.80000,0.04006,46.93494,0.00000,0.00002,0.58797
0.90000,0.04496,48.42932,0.00000,0.00002,0.60669
1.00000,0.05010,49.38758,0.00000,0.00001,0.61870
1.10000,0.05495,50.51118,0.00000,0.00001,0.63277
1.20000,0.06009,51.39784,0.00000,0.00002,0.64388
1.30000,0.06487,52.57273,0.00000,0.00001,0.65860
1.40000,0.07001,54.43390,0.00000,0.00001,0.68192
1.50000,0.07498,56.70351,0.00000,0.00001,0.71035
1.60000,0.08012,60.14797,0.00000,0.00001,0.75350
1.70000,0.08496,63.27967,0.00000,0.00002,0.79273
1.80000,0.09004,67.27719,0.00000,0.00001,0.84281
1.90000,0.09495,70.38405,0.00000,0.00001,0.88173
2.00000,0.10003,74.37165,0.00000,0.00001,0.93168
2.10000,0.10505,76.52057,0.00000,0.00001,0.95860
2.20000,0.11001,78.77928,0.00000,0.00001,0.98690
2.30000,0.11503,81.31758,0.00000,0.00001,1.01870
2.40000,0.11994,85.80148,0.00000,0.00001,1.07487
2.50000,0.12502,89.16028,0.00000,0.00001,1.11695
2.60000,0.12998,96.85006,0.00000,0.00001,1.21328
2.70000,0.13506,107.56906,0.00000,0.00001,1.34756
2.80000,0.13991,111.67213,0.00000,0.00001,1.39896
2.90000,0.14505,116.22087,0.00000,0.00001,1.45595
3.00000,0.14995,122.20999,0.00000,0.00002,1.53097
3.10000,0.15515,133.21372,0.00000,0.00002,1.66882
3.20000,0.15994,147.15117,0.00000,0.00002,1.84342
3.30000,0.16508,163.87251,0.00000,0.00003,2.05290
3.40000,0.16986,181.27833,0.00000,0.00003,2.27095
3.50000,0.17506,200.35757,0.00000,0.00004,2.50996
3.60000,0.17991,221.12795,0.00000,0.00005,2.77016
3.70000,0.18505,243.18618,0.00000,0.00006,3.04649
3.80000,0.18995,266.40561,0.00000,0.00006,3.33737
3.90000,0.19503,291.03437,0.00000,0.00007,3.64591
4.00000,0.20000,315.93570,0.00000,0.00008,3.95785
4.10000,0.20502,341.79988,0.00000,0.00009,4.28187
4.20000,0.20998,368.92612,0.00000,0.00011,4.62169
4.30000,0.21500,396.99161,0.00000,0.00012,4.97327
4.40000,0.22003,425.96948,0.00000,0.00013,5.33629
4.50000,0.22505,454.54055,0.00000,0.00015,5.69421
4.60000,0.23001,481.87193,0.00000,0.00015,6.03660
4.70000,0.23497,506.42896,0.00000,0.00017,6.34424
4.80000,0.24005,534.71089,0.00000,0.00018,6.69854
4.90000,0.24502,560.20082,0.00000,0.00019,7.01786
5.00000,0.25010,587.00950,0.00000,0.00021,7.35370
5.10000,0.25494,612.00238,0.00000,0.00022,7.66680
5.20000,0.26008,641.19478,0.00000,0.00023,8.03251
5.30000,0.26499,668.97427,0.00000,0.00025,8.38051
5.40000,0.27013,698.35656,0.00000,0.00026,8.74859
5.50000,0.27491,726.72563,0.00000,0.00027,9.10399
5.60000,0.28005,758.69174,0.00000,0.00029,9.50444
5.70000,0.28490,788.40479,0.00000,0.00031,9.87667
5.80000,0.29010,821.24053,0.00000,0.00032,10.28801
5.90000,0.29500,851.79340,0.00000,0.00034,10.67076
6.00000,0.30008,882.46809,0.00000,0.00036,11.05503
6.10000,0.30493,912.22925,0.00000,0.00037,11.42786
6.20000,0.31001,942.94734,0.00000,0.00039,11.81268
6.30000,0.31491,974.11508,0.00000,0.00040,12.20313
6.40000,0.32005,1008.43189,0.00000,0.00042,12.63303
6.50000,0.32496,1048.24863,0.00000,0.00044,13.13183
6.60000,0.32998,1087.72144,0.00000,0.00046,13.62633
6.70000,0.33494,1127.69045,0.00000,0.00048,14.12703
6.80000,0.33996,1166.17354,0.00000,0.00051,14.60913
6.90000,0.34505,1206.76421,0.00000,0.00053,15.11762
7.00000,0.35001,1244.43369,0.00000,0.00055,15.58952
7.10000,0.35503,1286.29068,0.00000,0.00057,16.11388
7.20000,0.35987,1323.52291,0.00000,0.00060,16.58031
7.30000,0.36501,1363.87544,0.00000,0.00062,17.08582
7.40000,0.36992,1400.89681,0.00000,0.00064,17.54960
7.50000,0.37506,1442.12246,0.00000,0.00066,18.06605
7.60000,0.37984,1481.27135,0.00000,0.00068,18.55648
7.70000,0.38504,1520.45824,0.00000,0.00071,19.04739
7.80000,0.38989,1557.46313,0.00000,0.00073,19.51097
7.90000,0.39503,1597.05244,0.00000,0.00076,20.00692
8.00000,0.39987,1636.41758,0.00000,0.00077,20.50006
8.10000,0.40501,1677.77985,0.00000,0.00080,21.01823
8.20000,0.40992,1716.04864,0.00000,0.00082,21.49763
8.30000,0.41506,1755.02673,0.00000,0.00084,21.98593
8.40000,0.41990,1793.06343,0.00000,0.00087,22.46243
8.50000,0.42498,1831.33688,0.00000,0.00090,22.94190
8.60000,0.42995,1870.38630,0.00000,0.00092,23.43108
8.70000,0.43503,1907.43450,0.00000,0.00094,23.89520
8.80000,0.43999,1946.40979,0.00000,0.00096,24.38346
8.90000,0.44501,1983.29482,0.00000,0.00098,24.84553
9.00000,0.44998,2020.57194,0.00000,0.00100,25.31252
9.10000,0.45500,2056.75270,0.00000,0.00103,25.76577
9.20000,0.46002,2093.61315,0.00000,0.00105,26.22754
9.30000,0.46504,2127.71185,0.00000,0.00106,26.65471
9.40000,0.47006,2164.84256,0.00000,0.00109,27.11986
9.50000,0.47497,2196.66492,0.00000,0.00111,27.51851
9.60000,0.47999,2233.73417,0.00000,0.00113,27.98289
9.70000,0.48501,2266.27607,0.00000,0.00115,28.39056
9.80000,0.49009,2303.37065,0.00000,0.00117,28.85525
9.90000,0.49494,2334.96055,0.00000,0.00120,29.25099
10.00000,0.50002,2369.27681,0.00000,0.00121,29.68089
10.10000,0.50486,2400.75067,0.00000,0.00123,30.07517
10.20000,0.51012,2434.33043,0.00000,0.00125,30.49584
10.30000,0.51491,2466.51452,0.00000,0.00127,30.89902
10.40000,0.52005,2502.75135,0.00000,0.00129,31.35298
10.50000,0.52489,2533.26613,0.00000,0.00131,31.73525
10.60000,0.53003,2566.69093,0.00000,0.00133,32.15397
10.70000,0.53494,2598.29983,0.00000,0.00135,32.54995
10.80000,0.54002,2630.37141,0.00000,0.00137,32.95172
10.90000,0.54492,2661.28872,0.00000,0.00139,33.33904
11.00000,0.55000,2692.49324,0.00000,0.00141,33.72995
11.10000,0.55491,2722.62152,0.00000,0.00142,34.10738
11.20000,0.56005,2753.57179,0.00000,0.00144,34.49511
11.30000,0.56495,2786.31765,0.00000,0.00147,34.90533
11.40000,0.56997,2814.67680,0.00000,0.00148,35.26059
11.50000,0.57500,2846.51760,0.00000,0.00150,35.65948
11.60000,0.58002,2875.08089,0.00000,0.00152,36.01730
11.70000,0.58504,2906.84961,0.00000,0.00154,36.41528
11.80000,0.58994,2933.52585,0.00000,0.00155,36.74946
11.90000,0.59503,2964.92763,0.00000,0.00157,37.14285
12.00000,0.59987,2991.45356,0.00000,0.00159,37.47515
12.10000,0.60501,3021.23353,0.00000,0.00160,37.84821
12.20000,0.60985,3046.22650,0.00000,0.00162,38.16131
12.30000,0.61499,3077.20974,0.00000,0.00163,38.54945
12.40000,0.61984,3104.86183,0.00000,0.00165,38.89586
12.50000,0.62504,3133.53017,0.00000,0.00167,39.25500
12.60000,0.62994,3159.18103,0.00000,0.00169,39.57634
12.70000,0.63508,3186.16778,0.00000,0.00170,39.91441
12.80000,0.63993,3211.14026,0.00000,0.00172,40.22725
12.90000,0.64501,3236.26064,0.00000,0.00173,40.54194
13.00000,0.64991,3259.25983,0.00000,0.00175,40.83006
13.10000,0.65505,3282.12827,0.00000,0.00176,41.11655
13.20000,0.65990,3306.55277,0.00000,0.00179,41.42252
13.30000,0.66492,3330.48515,0.00000,0.00180,41.72233
13.40000,0.66988,3356.02574,0.00000,0.00182,42.04229
13.50000,0.67496,3380.16227,0.00000,0.00183,42.34466
13.60000,0.67999,3406.20391,0.00000,0.00185,42.67089
13.70000,0.68501,3430.10426,0.00000,0.00186,42.97030
13.80000,0.69003,3456.03898,0.00000,0.00188,43.29520
13.90000,0.69505,3480.56033,0.00000,0.00189,43.60238
14.00000,0.70008,3505.78092,0.00000,0.00191,43.91833
14.10000,0.70504,3530.89646,0.00000,0.00192,44.23297
14.20000,0.71000,3557.52558,0.00000,0.00194,44.56656
14.30000,0.71496,3580.50242,0.00000,0.00196,44.85440
14.40000,0.72004,3606.21735,0.00000,0.00197,45.17654
14.50000,0.72495,3629.02358,0.00000,0.00199,45.46224
14.60000,0.73009,3656.04907,0.00000,0.00200,45.80080
14.70000,0.73499,3679.74341,0.00000,0.00202,46.09763
14.80000,0.74007,3704.65629,0.00000,0.00203,46.40972
14.90000,0.74498,3728.16361,0.00000,0.00205,46.70421
15.00000,0.75012,3753.01838,0.00000,0.00206,47.01558
15.10000,0.75484,3775.84174,0.00000,0.00207,47.30149
15.20000,0.76004,3802.59342,0.00000,0.00209,47.63662
15.30000,0.76489,3824.18931,0.00000,0.00211,47.90716
15.40000,0.77003,3848.01812,0.00000,0.00212,48.20568
15.50000,0.77493,3870.56917,0.00000,0.00213,48.48818
15.60000,0.78001,3895.48428,0.00000,0.00215,48.80030
15.70000,0.78492,3919.10896,0.00000,0.00216,49.09626
15.80000,0.79006,3942.57531,0.00000,0.00217,49.39023
15.90000,0.79496,3965.69856,0.00000,0.00219,49.67991
16.00000,0.79998,3987.24563,0.00000,0.00220,49.94984
16.10000,0.80495,4011.31064,0.00000,0.00222,50.25131
16.20000,0.80997,4031.81426,0.00000,0.00223,50.50816
16.30000,0.81499,4054.15595,0.00000,0.00225,50.78805
16.40000,0.82001,4073.14897,0.00000,0.00226,51.02598
16.50000,0.82504,4094.20878,0.00000,0.00227,51.28981
16.60000,0.82994,4116.27181,0.00000,0.00228,51.56620
16.70000,0.83502,4139.05866,0.00000,0.00230,51.85166
16.80000,0.83992,4159.73254,0.00000,0.00232,52.11065
16.90000,0.84506,4183.77407,0.00000,0.00233,52.41183
17.00000,0.84991,4204.22517,0.00000,0.00234,52.66803
17.10000,0.85505,4227.89119,0.00000,0.00235,52.96450
17.20000,0.85989,4247.65982,0.00000,0.00237,53.21215
17.30000,0.86509,4271.82205,0.00000,0.00238,53.51484
17.40000,0.86994,4292.14053,0.00000,0.00239,53.76938
17.50000,0.87508,4316.72186,0.00000,0.00241,54.07732
17.60000,0.87986,4337.71871,0.00000,0.00242,54.34035
17.70000,0.88506,4362.47773,0.00000,0.00243,54.65052
17.80000,0.88991,4384.62868,0.00000,0.00245,54.92801
17.90000,0.89505,4408.59459,0.00000,0.00246,55.22824
18.00000,0.89995,4430.43932,0.00000,0.00248,55.50190
18.10000,0.90503,4452.86557,0.00000,0.00249,55.78284
18.20000,0.91000,4476.42580,0.00000,0.00251,56.07799
18.30000,0.91502,4497.84957,0.00000,0.00252,56.34638
18.40000,0.91998,4521.28090,0.00000,0.00254,56.63991
18.50000,0.92500,4544.22794,0.00000,0.00255,56.92738
18.60000,0.92997,4567.56391,0.00000,0.00257,57.21972
18.70000,0.93499,4589.47308,0.00000,0.00258,57.49418
18.80000,0.94001,4612.61831,0.00000,0.00260,57.78413
18.90000,0.94497,4633.76306,0.00000,0.00261,58.04902
19.00000,0.95000,4658.07170,0.00000,0.00262,58.35354
19.10000,0.95490,4678.98399,0.00000,0.00264,58.61552
19.20000,0.96004,4703.69458,0.00000,0.00265,58.92508
19.30000,0.96494,4725.61866,0.00000,0.00267,59.19973
19.40000,0.97002,4751.14360,0.00000,0.00268,59.51949
19.50000,0.97487,4774.08729,0.00000,0.00269,59.80692
19.60000,0.98007,4798.71631,0.00000,0.00271,60.11546
19.70000,0.98491,4819.87670,0.00000,0.00273,60.38054
19.80000,0.99011,4843.94394,0.00000,0.00274,60.68204
19.90000,0.99484,4865.30736,0.00000,0.00275,60.94967
20.00000,1.00004,4890.07384,0.00000,0.00277,61.25993
20.10000,1.00488,4911.78930,0.00000,0.00279,61.53197
20.20000,1.01008,4936.07111,0.00000,0.00280,61.83616
20.30000,1.01499,4959.48493,0.00000,0.00282,62.12947
20.40000,1.02001,4984.15343,0.00000,0.00283,62.43850
20.50000,1.02491,5008.06607,0.00000,0.00284,62.73807
20.60000,1.02999,5031.28171,0.00000,0.00286,63.02890
20.70000,1.03496,5055.85186,0.00000,0.00288,63.33670
20.80000,1.03998,5077.65748,0.00000,0.00289,63.60987
20.90000,1.04494,5103.07476,0.00000,0.00291,63.92828
21.00000,1.04996,5125.86869,0.00000,0.00292,64.21383
21.10000,1.05499,5150.15349,0.00000,0.00294,64.51805
21.20000,1.06001,5172.05186,0.00000,0.00296,64.79238
21.30000,1.06503,5197.63753,0.00000,0.00297,65.11290
21.40000,1.06993,5220.14275,0.00000,0.00298,65.39484
21.50000,1.07502,5245.17037,0.00000,0.00300,65.70837
21.60000,1.07992,5266.43544,0.00000,0.00302,65.97476
21.70000,1.08512,5290.98809,0.00000,0.00303,66.28234
21.80000,1.08990,5314.21714,0.00000,0.00304,66.57334
21.90000,1.09504,5339.20936,0.00000,0.00306,66.88643
22.00000,1.09989,5361.57414,0.00000,0.00307,67.16660
22.10000,1.10509,5386.60847,0.00000,0.00309,67.48022
22.20000,1.10993,5408.74414,0.00000,0.00310,67.75752
22.30000,1.11507,5433.94424,0.00000,0.00312,68.07321
22.40000,1.11992,5456.49789,0.00000,0.00314,68.35575
22.50000,1.12506,5480.15945,0.00000,0.00315,68.65217
22.60000,1.12996,5502.45307,0.00000,0.00317,68.93145
22.70000,1.13504,5526.20590,0.00000,0.00318,69.22901
22.80000,1.13995,5551.11952,0.00000,0.00320,69.54112
22.90000,1.14503,5575.07798,0.00000,0.00322,69.84125
23.00000,1.14993,5599.87910,0.00000,0.00323,70.15195
23.10000,1.15507,5623.81595,0.00000,0.00324,70.45181
23.20000,1.15998,5648.12310,0.00000,0.00326,70.75632
23.30000,1.16500,5671.19233,0.00000,0.00328,71.04532
23.40000,1.17002,5696.31718,0.00000,0.00330,71.36006
23.50000,1.17504,5718.78627,0.00000,0.00331,71.64154
23.60000,1.18007,5743.54827,0.00000,0.00333,71.95175
23.70000,1.18497,5765.95441,0.00000,0.00334,72.23244
23.80000,1.18999,5792.13277,0.00000,0.00336,72.56039
23.90000,1.19489,5814.19282,0.00000,0.00337,72.83674
24.00000,1.20009,5840.97654,0.00000,0.00339,73.17227
24.10000,1.20494,5862.88907,0.00000,0.00340,73.44678
24.20000,1.21008,5888.62635,0.00000,0.00342,73.76920
24.30000,1.21486,5911.61549,0.00000,0.00343,74.05719
24.40000,1.22006,5938.19059,0.00000,0.00345,74.39011
24.50000,1.22491,5960.78821,0.00000,0.00347,74.67320
24.60000,1.23011,5986.91069,0.00000,0.00348,75.00045
24.70000,1.23489,6010.81736,0.00000,0.00350,75.29994
24.80000,1.24003,6035.29140,0.00000,0.00351,75.60653
24.90000,1.24488,6059.42793,0.00000,0.00353,75.90890
25.00000,1.25008,6083.71645,0.00000,0.00355,76.21317
25.10000,1.25492,6107.01479,0.00000,0.00356,76.50504
25.20000,1.25994,6131.62443,0.00000,0.00358,76.81333
25.30000,1.26491,6156.41363,0.00000,0.00360,77.12388
25.40000,1.26999,6179.86433,0.00000,0.00361,77.41766
25.50000,1.27495,6205.93652,0.00000,0.00363,77.74427
25.60000,1.28003,6228.72077,0.00000,0.00364,78.02970
25.70000,1.28500,6254.64618,0.00000,0.00366,78.35448
25.80000,1.28996,6277.12309,0.00000,0.00368,78.63606
25.90000,1.29504,6302.25837,0.00000,0.00370,78.95093
26.00000,1.30000,6323.60801,0.00000,0.00371,79.21839
26.10000,1.30503,6351.15206,0.00000,0.00373,79.56345
26.20000,1.30993,6373.61929,0.00000,0.00374,79.84490
26.30000,1.31507,6400.52259,0.00000,0.00376,80.18193
26.40000,1.31991,6424.36892,0.00000,0.00378,80.48066
26.50000,1.32505,6451.05541,0.00000,0.00379,80.81498
26.60000,1.32990,6474.65065,0.00000,0.00381,81.11056
26.70000,1.33510,6501.62101,0.00000,0.00383,81.44843
26.80000,1.33994,6525.08289,0.00000,0.00385,81.74235
26.90000,1.34514,6550.16378,0.00000,0.00386,82.05655
27.00000,1.34999,6573.30379,0.00000,0.00388,82.34643
27.10000,1.35507,6598.70207,0.00000,0.00390,82.66460
27.20000,1.35991,6623.29271,0.00000,0.00391,82.97266
27.30000,1.36511,6648.95177,0.00000,0.00393,83.29410
27.40000,1.36996,6671.14034,0.00000,0.00395,83.57207
27.50000,1.37504,6696.77928,0.00000,0.00396,83.89326
27.60000,1.37994,6720.78058,0.00000,0.00398,84.19393
27.70000,1.38502,6746.60876,0.00000,0.00400,84.51749
27.80000,1.38999,6771.53170,0.00000,0.00402,84.82971
27.90000,1.39507,6795.90479,0.00000,0.00404,85.13504
28.00000,1.39997,6821.54149,0.00000,0.00405,85.45620
28.10000,1.40499,6847.01279,0.00000,0.00407,85.77529
28.20000,1.40996,6871.69358,0.00000,0.00409,86.08448
28.30000,1.41498,6896.05996,0.00000,0.00411,86.38973
28.40000,1.42000,6922.73453,0.00000,0.00412,86.72389
28.50000,1.42490,6944.07523,0.00000,0.00414,86.99123
28.60000,1.42999,6971.47921,0.00000,0.00416,87.33453
28.70000,1.43489,6994.76972,0.00000,0.00417,87.62630
28.80000,1.44009,7022.10963,0.00000,0.00420,87.96880
28.90000,1.44493,7044.65881,0.00000,0.00421,88.25128
29.00000,1.45007,7071.96444,0.00000,0.00423,88.59335
29.10000,1.45492,7095.85175,0.00000,0.00424,88.89260
29.20000,1.46006,7121.42363,0.00000,0.00426,89.21295
29.30000,1.46490,7144.88402,0.00000,0.00428,89.50685
29.40000,1.47010,7170.83365,0.00000,0.00430,89.83193
29.50000,1.47489,7194.80664,0.00000,0.00432,90.13225
29.60000,1.48003,7221.93122,0.00000,0.00434,90.47205
29.70000,1.48487,7246.91227,0.00000,0.00435,90.78500
29.80000,1.49001,7273.87369,0.00000,0.00437,91.12275
29.90000,1.49492,7298.07392,0.00000,0.00438,91.42592
30.00000,1.50000,7323.70690,0.00000,0.00441,91.74703
30.10000,1.50496,7349.45014,0.00000,0.00442,92.06953
30.20000,1.51004,7374.58393,0.00000,0.00444,92.38439
30.30000,1.51501,7400.00233,0.00000,0.00446,92.70282
30.40000,1.52003,7424.07590,0.00000,0.00447,93.00440
30.50000,1.52499,7450.81529,0.00000,0.00450,93.33937
30.60000,1.53001,7475.36868,0.00000,0.00451,93.64696
30.70000,1.53504,7500.58889,0.00000,0.00453,93.96291
30.80000,1.54000,7524.16104,0.00000,0.00455,94.25820
30.90000,1.54502,7551.04274,0.00000,0.00457,94.59496
31.00000,1.54992,7573.68207,0.00000,0.00459,94.87857
31.10000,1.55506,7600.38272,0.00000,0.00460,95.21306
31.20000,1.55991,7624.14783,0.00000,0.00462,95.51078
31.30000,1.56511,7651.08243,0.00000,0.00464,95.84820
31.40000,1.56995,7675.04498,0.00000,0.00466,96.14839
31.50000,1.57503,7701.30455,0.00000,0.00468,96.47735
31.60000,1.57994,7725.66274,0.00000,0.00469,96.78250
31.70000,1.58508,7752.16073,0.00000,0.00471,97.11445
31.80000,1.58992,7774.84253,0.00000,0.00473,97.39859
31.90000,1.59506,7801.63184,0.00000,0.00475,97.73419
32.00000,1.59991,7826.79096,0.00000,0.00477,98.04937
32.10000,1.60505,7852.65267,0.00000,0.00478,98.37335
32.20000,1.61001,7878.36611,0.00000,0.00480,98.69547
32.30000,1.61503,7903.25329,0.00000,0.00482,99.00724
32.40000,1.61994,7928.03466,0.00000,0.00484,99.31769
32.50000,1.62502,7952.24905,0.00000,0.00486,99.62103
32.60000,1.62998,7976.44928,0.00000,0.00488,99.92420
32.70000,1.63506,8000.88942,0.00000,0.00489,100.23037
32.80000,1.63997,8027.14750,0.00000,0.00492,100.55932
32.90000,1.64505,8051.54070,0.00000,0.00493,100.86490
33.00000,1.65001,8079.40587,0.00000,0.00496,101.21398
33.10000,1.65497,8102.34323,0.00000,0.00497,101.50132
33.20000,1.66006,8129.97669,0.00000,0.00499,101.84750
33.30000,1.66490,8152.73970,0.00000,0.00501,102.13266
33.40000,1.67004,8180.61829,0.00000,0.00503,102.48191
33.50000,1.67494,8203.25986,0.00000,0.00505,102.76555
33.60000,1.68008,8229.92623,0.00000,0.00507,103.09961
33.70000,1.68493,8253.17428,0.00000,0.00508,103.39085
33.80000,1.69007,8280.94035,0.00000,0.00510,103.73868
33.90000,1.69491,8304.70175,0.00000,0.00512,104.03635
34.00000,1.70005,8330.37272,0.00000,0.00514,104.35794
34.10000,1.70490,8355.24201,0.00000,0.00516,104.66949
34.20000,1.70998,8379.77827,0.00000,0.00518,104.97687
34.30000,1.71488,8406.06317,0.00000,0.00520,105.30615
34.40000,1.72002,8432.24674,0.00000,0.00521,105.63416
34.50000,1.72493,8456.70104,0.00000,0.00523,105.94051
34.60000,1.73007,8482.14328,0.00000,0.00525,106.25923
34.70000,1.73491,8507.02897,0.00000,0.00527,106.57099
34.80000,1.73999,8532.67163,0.00000,0.00529,106.89222
34.90000,1.74496,8558.00435,0.00000,0.00531,107.20958
35.00000,1.74998,8581.52509,0.00000,0.00533,107.50423
35.10000,1.75500,8607.52687,0.00000,0.00535,107.82996
35.20000,1.75996,8632.64129,0.00000,0.00537,108.14458
35.30000,1.76493,8659.51031,0.00000,0.00538,108.48118
35.40000,1.77001,8684.80280,0.00000,0.00540,108.79803
35.50000,1.77509,8713.01666,0.00000,0.00543,109.15148
35.60000,1.78005,8736.16040,0.00000,0.00544,109.44141
35.70000,1.78508,8762.77015,0.00000,0.00546,109.77476
35.80000,1.78998,8785.86173,0.00000,0.00548,110.06404
35.90000,1.79506,8810.92697,0.00000,0.00550,110.37804
36.00000,1.79996,8833.81963,0.00000,0.00552,110.66482
36.10000,1.80510,8860.85033,0.00000,0.00554,111.00345
36.20000,1.80995,8884.68102,0.00000,0.00555,111.30199
36.30000,1.81509,8912.53501,0.00000,0.00558,111.65092
36.40000,1.81993,8935.81659,0.00000,0.00559,111.94258
36.50000,1.82513,8961.55164,0.00000,0.00561,112.26498
36.60000,1.82998,8986.97674,0.00000,0.00563,112.58349
36.70000,1.83506,9013.40246,0.00000,0.00565,112.91453
36.80000,1.83990,9037.94765,0.00000,0.00567,113.22202
36.90000,1.84510,9064.87033,0.00000,0.00569,113.55929
37.00000,1.84995,9089.16593,0.00000,0.00571,113.86365
37.10000,1.85503,9117.08549,0.00000,0.00573,114.21341
37.20000,1.85987,9141.65899,0.00000,0.00575,114.52125
37.30000,1.86501,9166.28391,0.00000,0.00577,114.82974
37.40000,1.86998,9192.45183,0.00000,0.00579,115.15756
37.50000,1.87500,9216.36000,0.00000,0.00581,115.45706
37.60000,1.87996,9243.48980,0.00000,0.00583,115.79693
37.70000,1.88504,9268.53940,0.00000,0.00585,116.11073
37.80000,1.89001,9294.22677,0.00000,0.00587,116.43253
37.90000,1.89497,9318.51938,0.00000,0.00589,116.73685
38.00000,1.89999,9344.97267,0.00000,0.00591,117.06825
38.10000,1.90483,9368.26542,0.00000,0.00593,117.36004
38.20000,1.91004,9395.22013,0.00000,0.00595,117.69772
38.30000,1.91488,9416.99743,0.00000,0.00597,117.97053
38.40000,1.92008,9445.59202,0.00000,0.00599,118.32874
38.50000,1.92486,9467.82753,0.00000,0.00601,118.60730
38.60000,1.93000,9496.06597,0.00000,0.00603,118.96105
38.70000,1.93485,9520.80041,0.00000,0.00605,119.27091
38.80000,1.94011,9548.31988,0.00000,0.00607,119.61566
38.90000,1.94489,9572.42697,0.00000,0.00609,119.91766
39.00000,1.95003,9598.97339,0.00000,0.00611,120.25021
39.10000,1.95482,9623.32189,0.00000,0.00613,120.55524
39.20000,1.96002,9649.80945,0.00000,0.00615,120.88706
39.30000,1.96498,9673.69974,0.00000,0.00617,121.18634
39.40000,1.97000,9697.65261,0.00000,0.00619,121.48641
39.50000,1.97491,9724.87181,0.00000,0.00621,121.82740
39.60000,1.97999,9749.67107,0.00000,0.00623,122.13807
39.70000,1.98495,9775.64901,0.00000,0.00625,122.46350
39.80000,1.99003,9799.62796,0.00000,0.00626,122.76390
39.90000,1.99500,9825.31533,0.00000,0.00629,123.08569
40.00000,2.00002,9850.07063,0.00000,0.00631,123.39581
40.10000,2.00504,9877.37402,0.00000,0.00633,123.73785
40.20000,2.01006,9901.88345,0.00000,0.00635,124.04489
40.30000,2.01503,9928.58484,0.00000,0.00637,124.37939
40.40000,2.01999,9952.48780,0.00000,0.00639,124.67883
40.50000,2.02501,9979.59599,0.00000,0.00641,125.01843
40.60000,2.02997,10003.59505,0.00000,0.00643,125.31907
40.70000,2.03505,10029.72424,0.00000,0.00645,125.64640
40.80000,2.03996,10053.89616,0.00000,0.00647,125.94922
40.90000,2.04504,10079.54925,0.00000,0.00649,126.27058
41.00000,2.04988,10104.73669,0.00000,0.00651,126.58612
41.10000,2.05508,10132.65923,0.00000,0.00652,126.93591
41.20000,2.05993,10156.39454,0.00000,0.00655,127.23325
41.30000,2.06513,10183.53254,0.00000,0.00657,127.57322
41.40000,2.06991,10206.51236,0.00000,0.00659,127.86110
41.50000,2.07505,10233.60193,0.00000,0.00661,128.20046
41.60000,2.07996,10257.48923,0.00000,0.00663,128.49971
41.70000,2.08504,10284.01032,0.00000,0.00665,128.83195
41.80000,2.08994,10308.74103,0.00000,0.00666,129.14176
41.90000,2.09496,10334.49173,0.00000,0.00669,129.46435
42.00000,2.09993,10361.38684,0.00000,0.00671,129.80128
42.10000,2.10501,10386.22931,0.00000,0.00673,130.11249
42.20000,2.10997,10413.81061,0.00000,0.00675,130.45801
42.30000,2.11499,10437.31123,0.00000,0.00677,130.75241
42.40000,2.11996,10465.67336,0.00000,0.00680,131.10772
42.50000,2.12498,10488.85211,0.00000,0.00681,131.39808
42.60000,2.13000,10516.14955,0.00000,0.00684,131.74005
42.70000,2.13496,10540.41609,0.00000,0.00685,132.04405
42.80000,2.13999,10567.44829,0.00000,0.00688,132.38269
42.90000,2.14489,10591.27301,0.00000,0.00690,132.68115
43.00000,2.15003,10618.67177,0.00000,0.00692,133.02439
43.10000,2.15493,10643.31979,0.00000,0.00694,133.33316
43.20000,2.16013,10670.51664,0.00000,0.00696,133.67387
43.30000,2.16492,10693.46517,0.00000,0.00698,133.96136
43.40000,2.17006,10720.35208,0.00000,0.00700,134.29818
43.50000,2.17490,10745.26235,0.00000,0.00702,134.61024
43.60000,2.18010,10771.95108,0.00000,0.00704,134.94458
43.70000,2.18495,10796.80845,0.00000,0.00706,135.25598
43.80000,2.19003,10823.03077,0.00000,0.00709,135.58448
43.90000,2.19487,10846.41293,0.00000,0.00710,135.87739
44.00000,2.20001,10873.87800,0.00000,0.00712,136.22146
44.10000,2.20492,10898.66161,0.00000,0.00715,136.53193
44.20000,2.21006,10925.00910,0.00000,0.00717,136.86200
44.30000,2.21496,10951.87366,0.00000,0.00719,137.19854
44.40000,2.21998,10976.78393,0.00000,0.00721,137.51060
44.50000,2.22501,11002.23437,0.00000,0.00723,137.82943
44.60000,2.23003,11027.30930,0.00000,0.00725,138.14356
44.70000,2.23499,11052.13091,0.00000,0.00728,138.45451
44.80000,2.24001,11077.45171,0.00000,0.00729,138.77171
44.90000,2.24498,11104.71264,0.00000,0.00732,139.11322
45.00000,2.25000,11127.35644,0.00000,0.00734,139.39689
45.10000,2.25502,11155.57104,0.00000,0.00736,139.75034
45.20000,2.25992,11179.88899,0.00000,0.00738,140.05498
45.30000,2.26506,11208.37405,0.00000,0.00740,140.41183
45.40000,2.26997,11232.21442,0.00000,0.00742,140.71048
45.50000,2.27505,11258.60214,0.00000,0.00744,141.04105
45.60000,2.27995,11282.41420,0.00000,0.00746,141.33936
45.70000,2.28503,11310.05734,0.00000,0.00748,141.68565
45.80000,2.28988,11334.38423,0.00000,0.00750,141.99041
45.90000,2.29508,11362.64801,0.00000,0.00752,142.34448
46.00000,2.29992,11387.09188,0.00000,0.00755,142.65070
46.10000,2.30506,11414.25893,0.00000,0.00757,142.99103
46.20000,2.30985,11439.22359,0.00000,0.00759,143.30377
46.30000,2.31499,11466.18873,0.00000,0.00761,143.64158
46.40000,2.31989,11491.16904,0.00000,0.00763,143.95451
46.50000,2.32509,11516.86162,0.00000,0.00765,144.27637
46.60000,2.32994,11542.43052,0.00000,0.00768,144.59669
46.70000,2.33502,11567.98974,0.00000,0.00769,144.91688
46.80000,2.33992,11595.07930,0.00000,0.00772,145.25624
46.90000,2.34500,11619.97691,0.00000,0.00774,145.56814
47.00000,2.34997,11646.48458,0.00000,0.00776,145.90021
47.10000,2.35499,11669.32136,0.00000,0.00778,146.18630
47.20000,2.35995,11697.20069,0.00000,0.00780,146.53556
47.30000,2.36491,11721.24520,0.00000,0.00782,146.83677
47.40000,2.37000,11749.62297,0.00000,0.00785,147.19227
47.50000,2.37496,11774.97879,0.00000,0.00786,147.50991
47.60000,2.37998,11802.55190,0.00000,0.00789,147.85533
47.70000,2.38488,11827.43907,0.00000,0.00790,148.16710
47.80000,2.39003,11854.48691,0.00000,0.00793,148.50594
47.90000,2.39493,11877.82213,0.00000,0.00795,148.79827
48.00000,2.40007,11904.46541,0.00000,0.00798,149.13204
48.10000,2.40491,11929.53587,0.00000,0.00800,149.44611
48.20000,2.40999,11955.92880,0.00000,0.00802,149.77675
48.30000,2.41490,11980.85845,0.00000,0.00804,150.08905
48.40000,2.42010,12008.26839,0.00000,0.00806,150.43243
48.50000,2.42494,12032.78452,0.00000,0.00809,150.73955
48.60000,2.43002,12058.17536,0.00000,0.00811,151.05763
48.70000,2.43493,12084.61896,0.00000,0.00813,151.38890
48.80000,2.44007,12110.86512,0.00000,0.00815,151.71770
48.90000,2.44503,12135.60477,0.00000,0.00817,152.02762
49.00000,2.45005,12161.00380,0.00000,0.00819,152.34580
49.10000,2.45496,12187.55692,0.00000,0.00821,152.67845
49.20000,2.46004,12214.14804,0.00000,0.00824,153.01156
49.30000,2.46494,12239.09780,0.00000,0.00826,153.32412
49.40000,2.47002,12264.87383,0.00000,0.00828,153.64703
49.50000,2.47493,12291.37555,0.00000,0.00830,153.97902
49.60000,2.47995,12317.57402,0.00000,0.00832,154.30722
49.70000,2.48503,12345.33712,0.00000,0.00835,154.65502
49.80000,2.48999,12368.94503,0.00000,0.00837,154.95077
49.90000,2.49508,12397.16411,0.00000,0.00839,155.30428
50.00000,2.49992,12421.43959,0.00000,0.00841,155.60839
50.10000,2.50500,12449.63408,0.00000,0.00843,155.96159
50.20000,2.50990,12472.31960,0.00000,0.00846,156.24578
50.30000,2.51510,12500.49919,0.00000,0.00848,156.59880
50.40000,2.51995,12522.98355,0.00000,0.00850,156.88047
50.50000,2.52503,12551.09310,0.00000,0.00852,157.23261
50.60000,2.52987,12576.75290,0.00000,0.00854,157.55406
50.70000,2.53507,12603.63907,0.00000,0.00856,157.89087
50.80000,2.53992,12628.92187,0.00000,0.00859,158.20760
50.90000,2.54512,12656.98224,0.00000,0.00861,158.55913
51.00000,2.54990,12681.63621,0.00000,0.00863,158.86798
51.10000,2.55504,12709.38218,0.00000,0.00865,159.21556
51.20000,2.55995,12734.42507,0.00000,0.00868,159.52928
51.30000,2.56503,12760.23537,0.00000,0.00870,159.85262
51.40000,2.56987,12785.01898,0.00000,0.00872,160.16309
51.50000,2.57495,12811.62649,0.00000,0.00874,160.49642
51.60000,2.57992,12839.09529,0.00000,0.00877,160.84053
51.70000,2.58506,12864.72082,0.00000,0.00879,161.16155
51.80000,2.59002,12891.86478,0.00000,0.00881,161.50159
51.90000,2.59504,12916.04191,0.00000,0.00883,161.80447
52.00000,2.60001,12943.10540,0.00000,0.00885,162.14351
52.10000,2.60497,12967.83835,0.00000,0.00887,162.45335
52.20000,2.61005,12995.64242,0.00000,0.00890,162.80166
52.30000,2.61495,13019.43213,0.00000,0.00892,163.09968
52.40000,2.62004,13047.54168,0.00000,0.00894,163.45182
52.50000,2.62494,13071.62642,0.00000,0.00896,163.75354
52.60000,2.63008,13099.70766,0.00000,0.00899,164.10533
52.70000,2.63498,13123.83264,0.00000,0.00901,164.40755
52.80000,2.64012,13150.00951,0.00000,0.00903,164.73548
52.90000,2.64491,13175.24463,0.00000,0.00905,165.05161
53.00000,2.65005,13203.10384,0.00000,0.00908,165.40061
53.10000,2.65495,13230.65460,0.00000,0.00911,165.74575
53.20000,2.66009,13257.11608,0.00000,0.00912,166.07724
53.30000,2.66494,13281.18593,0.00000,0.00915,166.37878
53.40000,2.67002,13307.73234,0.00000,0.00917,166.71134
53.50000,2.67492,13332.69626,0.00000,0.00919,167.02407
53.60000,2.68006,13358.52444,0.00000,0.00921,167.34763
53.70000,2.68497,13384.24981,0.00000,0.00924,167.66990
53.80000,2.68999,13408.55360,0.00000,0.00926,167.97436
53.90000,2.69489,13436.26827,0.00000,0.00928,168.32156
54.00000,2.70003,13461.87443,0.00000,0.00931,168.64234
54.10000,2.70500,13489.75748,0.00000,0.00933,168.99164
54.20000,2.71008,13514.72437,0.00000,0.00935,169.30441
54.30000,2.71498,13540.73137,0.00000,0.00937,169.63021
54.40000,2.72000,13565.78469,0.00000,0.00939,169.94406
54.50000,2.72497,13594.20270,0.00000,0.00942,170.30007
54.60000,2.72999,13617.56176,0.00000,0.00944,170.59269
54.70000,2.73507,13646.44021,0.00000,0.00947,170.95447
54.80000,2.73985,13669.57724,0.00000,0.00948,171.24431
54.90000,2.74500,13698.56149,0.00000,0.00951,171.60741
55.00000,2.74990,13722.59706,0.00000,0.00953,171.90851
55.10000,2.75510,13750.19103,0.00000,0.00956,172.25419
55.20000,2.75994,13774.72579,0.00000,0.00958,172.56155
55.30000,2.76508,13802.10519,0.00000,0.00960,172.90454
55.40000,2.76993,13827.96019,0.00000,0.00962,173.22844
55.50000,2.77507,13855.70318,0.00000,0.00964,173.57599
55.60000,2.77997,13880.62984,0.00000,0.00967,173.88825
55.70000,2.78505,13906.37755,0.00000,0.00969,174.21081
55.80000,2.78984,13931.71847,0.00000,0.00971,174.52826
55.90000,2.79498,13957.32760,0.00000,0.00973,174.84908
56.00000,2.79988,13982.48672,0.00000,0.00976,175.16426
56.10000,2.80502,14009.49955,0.00000,0.00978,175.50266
56.20000,2.80993,14035.79116,0.00000,0.00980,175.83202
56.30000,2.81495,14062.32417,0.00000,0.00983,176.16441
56.40000,2.81991,14089.41895,0.00000,0.00985,176.50384
56.50000,2.82505,14115.03851,0.00000,0.00987,176.82479
56.60000,2.83002,14141.24966,0.00000,0.00990,177.15314
56.70000,2.83498,14165.55345,0.00000,0.00991,177.45761
56.80000,2.84000,14193.42309,0.00000,0.00994,177.80674
56.90000,2.84490,14217.02504,0.00000,0.00996,178.10241
57.00000,2.84999,14244.16304,0.00000,0.00998,178.44238
57.10000,2.85495,14268.90939,0.00000,0.01000,178.75239
57.20000,2.86003,14297.23203,0.00000,0.01003,179.10720
57.30000,2.86487,14321.88302,0.00000,0.01005,179.41601
57.40000,2.87007,14348.12546,0.00000,0.01007,179.74476
57.50000,2.87498,14372.43223,0.00000,0.01009,180.04926
57.60000,2.88018,14398.98610,0.00000,0.01012,180.38191
57.70000,2.88490,14423.01571,0.00000,0.01014,180.68294
57.80000,2.89004,14451.37113,0.00000,0.01017,181.03816
57.90000,2.89495,14476.41701,0.00000,0.01019,181.35192
58.00000,2.90009,14503.36874,0.00000,0.01021,181.68956
58.10000,2.90487,14527.79323,0.00000,0.01023,181.99553
58.20000,2.90995,14554.57807,0.00000,0.01026,182.33108
58.30000,2.91486,14581.33161,0.00000,0.01028,182.66623
58.40000,2.92006,14606.72021,0.00000,0.01030,182.98428
58.50000,2.92502,14632.92986,0.00000,0.01033,183.31262
58.60000,2.93004,14659.55973,0.00000,0.01035,183.64622
58.70000,2.93495,14687.26993,0.00000,0.01037,183.99336
58.80000,2.94003,14711.82853,0.00000,0.01039,184.30102
58.90000,2.94499,14738.64466,0.00000,0.01042,184.63695
59.00000,2.95007,14763.15707,0.00000,0.01044,184.94403
59.10000,2.95498,14789.31904,0.00000,0.01046,185.27177
59.20000,2.95994,14814.30978,0.00000,0.01048,185.58484
59.30000,2.96502,14842.09150,0.00000,0.01051,185.93287
59.40000,2.96998,14866.27907,0.00000,0.01053,186.23588
59.50000,2.97507,14894.61958,0.00000,0.01056,186.59091
59.60000,2.97991,14918.80715,0.00000,0.01058,186.89392
59.70000,2.98505,14947.83312,0.00000,0.01060,187.25754
59.80000,2.98989,14970.95078,0.00000,0.01062,187.54714
59.90000,2.99504,14998.55220,0.00000,0.01065,187.89292
60.00000,2.99988,15021.93362,0.00000,0.01067,188.18583
60.10000,3.00502,15050.17728,0.00000,0.01069,188.53965
60.20000,3.00986,15075.56289,0.00000,0.01072,188.85766
60.30000,3.01500,15104.03156,0.00000,0.01074,189.21430
60.40000,3.01991,15129.17578,0.00000,0.01076,189.52929
60.50000,3.02499,15155.02781,0.00000,0.01078,189.85315
60.60000,3.02989,15181.18083,0.00000,0.01081,190.18078
60.70000,3.03503,15207.20720,0.00000,0.01083,190.50682
60.80000,3.03994,15232.50043,0.00000,0.01086,190.82368
60.90000,3.04502,15259.11540,0.00000,0.01088,191.15710
61.00000,3.04992,15284.79755,0.00000,0.01090,191.47883
61.10000,3.05500,15309.94028,0.00000,0.01092,191.79380
61.20000,3.06003,15337.10808,0.00000,0.01095,192.13414
61.30000,3.06505,15361.79036,0.00000,0.01097,192.44335
61.40000,3.07001,15388.81660,0.00000,0.01099,192.78192
61.50000,3.07497,15412.74041,0.00000,0.01102,193.08162
61.60000,3.08000,15441.63227,0.00000,0.01104,193.44356
61.70000,3.08496,15465.86901,0.00000,0.01107,193.74718
61.80000,3.09010,15494.51947,0.00000,0.01109,194.10610
61.90000,3.09500,15517.89194,0.00000,0.01111,194.39890
62.00000,3.10009,15546.18329,0.00000,0.01114,194.75331
62.10000,3.10499,15570.76871,0.00000,0.01116,195.06131
62.20000,3.11013,15596.96794,0.00000,0.01118,195.38951
62.30000,3.11503,15621.93781,0.00000,0.01120,195.70232
62.40000,3.12011,15647.83752,0.00000,0.01123,196.02678
62.50000,3.12490,15673.38854,0.00000,0.01125,196.34687
62.60000,3.13010,15702.10159,0.00000,0.01128,196.70657
62.70000,3.13494,15726.43220,0.00000,0.01130,197.01136
62.80000,3.14014,15754.30632,0.00000,0.01132,197.36056
62.90000,3.14493,15777.93062,0.00000,0.01134,197.65651
63.00000,3.15007,15805.35769,0.00000,0.01137,198.00010
63.10000,3.15497,15830.72245,0.00000,0.01139,198.31785
63.20000,3.16011,15856.43888,0.00000,0.01141,198.64001
63.30000,3.16496,15880.69648,0.00000,0.01144,198.94390
63.40000,3.16998,15907.13710,0.00000,0.01146,199.27513
63.50000,3.17488,15934.92329,0.00000,0.01148,199.62322
63.60000,3.18002,15960.97350,0.00000,0.01150,199.94956
63.70000,3.18499,15987.85073,0.00000,0.01153,200.28626
63.80000,3.18995,16011.47503,0.00000,0.01155,200.58221
63.90000,3.19497,16039.12264,0.00000,0.01157,200.92856
64.00000,3.19999,16064.33243,0.00000,0.01160,201.24438
64.10000,3.20502,16092.18717,0.00000,0.01162,201.59332
64.20000,3.21004,16116.45371,0.00000,0.01164,201.89732
64.30000,3.21506,16142.03155,0.00000,0.01167,202.21775
64.40000,3.21990,16165.76463,0.00000,0.01169,202.51506
64.50000,3.22510,16194.78166,0.00000,0.01172,202.87857
64.60000,3.22995,16218.14817,0.00000,0.01173,203.17129
64.70000,3.23509,16244.89725,0.00000,0.01176,203.50639
64.80000,3.23987,16268.92537,0.00000,0.01178,203.80740
64.90000,3.24501,16297.28973,0.00000,0.01181,204.16273
65.00000,3.24986,16322.05248,0.00000,0.01183,204.47294
65.10000,3.25506,16349.95192,0.00000,0.01185,204.82245
65.20000,3.25990,16374.31085,0.00000,0.01188,205.12760
65.30000,3.26504,16400.91836,0.00000,0.01190,205.46093
65.40000,3.26989,16424.68870,0.00000,0.01192,205.75871
65.50000,3.27503,16450.77169,0.00000,0.01195,206.08546
65.60000,3.27999,16477.92161,0.00000,0.01197,206.42558
65.70000,3.28501,16503.08073,0.00000,0.01199,206.74075
65.80000,3.28992,16529.24865,0.00000,0.01202,207.06857
65.90000,3.29500,16554.48824,0.00000,0.01204,207.38476
66.00000,3.29996,16581.68584,0.00000,0.01206,207.72547
66.10000,3.30504,16606.79728,0.00000,0.01209,208.04005
66.20000,3.31001,16632.90262,0.00000,0.01211,208.36709
66.30000,3.31503,16657.13340,0.00000,0.01213,208.67063
66.40000,3.32005,16684.79145,0.00000,0.01216,209.01712
66.50000,3.32501,16707.87036,0.00000,0.01218,209.30624
66.60000,3.33010,16736.09912,0.00000,0.01220,209.65987
66.70000,3.33500,16759.04244,0.00000,0.01222,209.94729
66.80000,3.34002,16786.19236,0.00000,0.01225,210.28741
66.90000,3.34492,16810.98342,0.00000,0.01227,210.59798
67.00000,3.35007,16838.30023,0.00000,0.01230,210.94018
67.10000,3.35497,16863.72161,0.00000,0.01232,211.25865
67.20000,3.36011,16891.01756,0.00000,0.01235,211.60060
67.30000,3.36495,16916.30632,0.00000,0.01238,211.91740
67.40000,3.37009,16943.66038,0.00000,0.01240,212.26007
67.50000,3.37494,16968.47379,0.00000,0.01242,212.57092
67.60000,3.38008,16994.91143,0.00000,0.01244,212.90212
67.70000,3.38486,17019.04684,0.00000,0.01246,213.20447
67.80000,3.39006,17045.48448,0.00000,0.01249,213.53567
67.90000,3.39491,17070.68086,0.00000,0.01251,213.85131
68.00000,3.40011,17097.09316,0.00000,0.01254,214.18219
68.10000,3.40501,17123.26705,0.00000,0.01256,214.51008
68.20000,3.40997,17148.39786,0.00000,0.01258,214.82490
68.30000,3.41494,17176.15873,0.00000,0.01261,215.17267
68.40000,3.42002,17200.19132,0.00000,0.01263,215.47374
68.50000,3.42504,17227.55134,0.00000,0.01266,215.81649
68.60000,3.43000,17251.18607,0.00000,0.01268,216.11257
68.70000,3.43497,17277.54772,0.00000,0.01270,216.44282
68.80000,3.43993,17302.06311,0.00000,0.01272,216.74993
68.90000,3.44501,17329.62877,0.00000,0.01275,217.09526
69.00000,3.44991,17354.11435,0.00000,0.01277,217.40200
69.10000,3.45500,17381.47289,0.00000,0.01279,217.74473
69.20000,3.45990,17406.52323,0.00000,0.01281,218.05854
69.30000,3.46498,17433.59268,0.00000,0.01284,218.39765
69.40000,3.46988,17457.77726,0.00000,0.01286,218.70062
69.50000,3.47508,17484.95251,0.00000,0.01289,219.04106
69.60000,3.47993,17509.10729,0.00000,0.01291,219.34366
69.70000,3.48507,17535.99495,0.00000,0.01294,219.68049
69.80000,3.48991,17561.30606,0.00000,0.01296,219.99757
69.90000,3.49505,17586.65442,0.00000,0.01298,220.31512
70.00000,3.49996,17612.19501,0.00000,0.01301,220.63508
70.10000,3.50498,17636.31105,0.00000,0.01303,220.93719
70.20000,3.50988,17662.03642,0.00000,0.01305,221.25946
70.30000,3.51496,17687.62618,0.00000,0.01308,221.58003
70.40000,3.51993,17712.91643,0.00000,0.01310,221.89685
70.50000,3.52501,17737.91462,0.00000,0.01312,222.21002
70.60000,3.52991,17765.06156,0.00000,0.01315,222.55010
70.70000,3.53499,17790.44867,0.00000,0.01317,222.86813
70.80000,3.54002,17817.14857,0.00000,0.01320,223.20261
70.90000,3.54504,17841.61329,0.00000,0.01322,223.50909
71.00000,3.55000,17867.29246,0.00000,0.01324,223.83079
71.10000,3.55502,17891.32506,0.00000,0.01327,224.13185
71.20000,3.55999,17917.84465,0.00000,0.01329,224.46407
71.30000,3.56501,17941.60604,0.00000,0.01331,224.76174
71.40000,3.57009,17970.16561,0.00000,0.01334,225.11952
71.50000,3.57493,17994.53199,0.00000,0.01336,225.42477
71.60000,3.58007,18022.21090,0.00000,0.01339,225.77151
71.70000,3.58498,18046.60559,0.00000,0.01341,226.07711
71.80000,3.59006,18072.18194,0.00000,0.01344,226.39752
71.90000,3.59490,18095.83604,0.00000,0.01346,226.69384
72.00000,3.59999,18122.70284,0.00000,0.01348,227.03041
72.10000,3.60483,18147.15266,0.00000,0.01351,227.33671
72.20000,3.61003,18175.34715,0.00000,0.01353,227.68991
72.30000,3.61487,18199.71502,0.00000,0.01356,227.99518
72.40000,3.62001,18226.89176,0.00000,0.01358,228.33563
72.50000,3.62486,18252.26694,0.00000,0.01360,228.65352
72.60000,3.63000,18279.06668,0.00000,0.01363,228.98925
72.70000,3.63496,18304.20345,0.00000,0.01366,229.30415
72.80000,3.64010,18331.03299,0.00000,0.01368,229.64025
72.90000,3.64495,18355.83448,0.00000,0.01370,229.95095
73.00000,3.64997,18380.97423,0.00000,0.01372,230.26588
73.10000,3.65493,18408.46539,0.00000,0.01375,230.61028
73.20000,3.66001,18433.28327,0.00000,0.01377,230.92118
73.30000,3.66504,18459.32305,0.00000,0.01380,231.24739
73.40000,3.66994,18482.02199,0.00000,0.01382,231.53175
73.50000,3.67496,18508.97223,0.00000,0.01384,231.86937
73.60000,3.67992,18533.11658,0.00000,0.01387,232.17183
73.70000,3.68501,18560.40210,0.00000,0.01389,232.51365
73.80000,3.68991,18582.06391,0.00000,0.01391,232.78502
73.90000,3.69505,18611.81706,0.00000,0.01394,233.15775
74.00000,3.69989,18635.70660,0.00000,0.01396,233.45702
74.10000,3.70509,18663.36465,0.00000,0.01399,233.80350
74.20000,3.70994,18687.58500,0.00000,0.01401,234.10692
74.30000,3.71508,18713.22393,0.00000,0.01403,234.42811
74.40000,3.71986,18738.57081,0.00000,0.01406,234.74564
74.50000,3.72501,18764.64337,0.00000,0.01408,235.07226
74.60000,3.72991,18790.66080,0.00000,0.01411,235.39819
74.70000,3.73505,18816.93900,0.00000,0.01413,235.72739
74.80000,3.73995,18840.44409,0.00000,0.01415,236.02185
74.90000,3.74503,18867.74451,0.00000,0.01417,236.36385
75.00000,3.74994,18893.59504,0.00000,0.01420,236.68769
75.10000,3.75508,18917.87499,0.00000,0.01423,236.99186
75.20000,3.76004,18943.08925,0.00000,0.01425,237.30773
75.30000,3.76500,18965.80458,0.00000,0.01427,237.59229
75.40000,3.76997,18992.39272,0.00000,0.01430,237.92537
75.50000,3.77505,19018.33862,0.00000,0.01432,238.25041
75.60000,3.77995,19044.76136,0.00000,0.01435,238.58141
75.70000,3.78503,19069.38255,0.00000,0.01437,238.88985
75.80000,3.78994,19094.22725,0.00000,0.01439,239.20109
75.90000,3.79490,19118.82162,0.00000,0.01441,239.50920
76.00000,3.79998,19145.88362,0.00000,0.01444,239.84821
76.10000,3.80500,19170.24255,0.00000,0.01446,240.15337
76.20000,3.81009,19196.27637,0.00000,0.01449,240.47950
76.30000,3.81493,19219.48940,0.00000,0.01451,240.77030
76.40000,3.82001,19247.40821,0.00000,0.01454,241.12005
76.50000,3.82491,19270.95801,0.00000,0.01456,241.41507
76.60000,3.83012,19298.85596,0.00000,0.01459,241.76456
76.70000,3.83490,19322.14648,0.00000,0.01461,242.05633
76.80000,3.84004,19347.35030,0.00000,0.01463,242.37207
76.90000,3.84488,19372.37531,0.00000,0.01466,242.68557
77.00000,3.85008,19398.96941,0.00000,0.01468,243.01872
77.10000,3.85493,19423.74557,0.00000,0.01471,243.32910
77.20000,3.86007,19449.95075,0.00000,0.01473,243.65738
77.30000,3.86491,19473.11610,0.00000,0.01475,243.94759
77.40000,3.86999,19499.12012,0.00000,0.01477,244.27335
77.50000,3.87496,19523.08714,0.00000,0.01480,244.57359
77.60000,3.88010,19548.41465,0.00000,0.01482,244.89088
77.70000,3.88494,19573.42327,0.00000,0.01485,245.20417
77.80000,3.88996,19597.62871,0.00000,0.01487,245.50741
77.90000,3.89493,19625.00662,0.00000,0.01490,245.85038
78.00000,3.89995,19650.31922,0.00000,0.01492,246.16748
78.10000,3.90497,19676.78964,0.00000,0.01494,246.49909
78.20000,3.90999,19700.90121,0.00000,0.01496,246.80114
78.30000,3.91496,19726.17060,0.00000,0.01499,247.11770
78.40000,3.91998,19749.40002,0.00000,0.01502,247.40871
78.50000,3.92506,19775.53964,0.00000,0.01504,247.73617
78.60000,3.92996,19798.10297,0.00000,0.01506,248.01883
78.70000,3.93511,19824.48548,0.00000,0.01509,248.34933
78.80000,3.93995,19848.40333,0.00000,0.01511,248.64896
78.90000,3.94503,19874.81713,0.00000,0.01513,248.97986
79.00000,3.94993,19898.28050,0.00000,0.01516,249.27379
79.10000,3.95507,19924.02077,0.00000,0.01518,249.59625
79.20000,3.95986,19946.99389,0.00000,0.01521,249.88404
79.30000,3.96506,19973.03218,0.00000,0.01523,250.21024
79.40000,3.96990,19994.29464,0.00000,0.01525,250.47660
79.50000,3.97510,20019.98127,0.00000,0.01528,250.79839
79.60000,3.97995,20042.83369,0.00000,0.01530,251.08467
79.70000,3.98497,20068.11649,0.00000,0.01533,251.40140
79.80000,3.98993,20092.45306,0.00000,0.01535,251.70627
79.90000,3.99501,20114.76010,0.00000,0.01537,251.98572
80.00000,3.99998,20138.39632,0.00000,0.01539,252.28182
80.10000,4.00506,20157.17775,0.00000,0.01541,252.51710
80.12000,4.00608,19889.73767,0.00000,0.01539,249.16677
80.12200,4.00619,19436.41752,0.00000,0.01534,243.48785
80.12400,4.00637,18750.09984,0.00000,0.01525,234.89007
80.12600,4.00661,17903.59616,0.00000,0.01517,224.28558
80.12800,4.00691,16941.44905,0.00000,0.01517,212.23237
80.13000,4.00715,15885.52296,0.00000,0.01524,199.00436
80.13200,4.00757,14769.90581,0.00000,0.01523,185.02857
80.13400,4.00787,13628.03578,0.00000,0.01501,170.72391
80.13600,4.00817,12476.75866,0.00000,0.01457,156.30139
80.13800,4.00853,11328.23005,0.00000,0.01387,141.91331