File: scratch/college-stuff/ME Lab/ME lab Fall 2013/group4/group4.is_tens_RawData/Specimen_RawData_4.csv
Time,Extension,Load,Strain 2,Tensile strain,Tensile stress
(sec),(mm),(N),(mm/mm),(mm/mm),(MPa)
0.00000,0.00006,0.01467,0.00000,0.00000,0.00018
0.30000,0.01369,43.88328,0.00000,0.00000,0.53926
0.60000,0.03001,62.04218,0.00000,0.00000,0.76241
0.90000,0.04490,76.62203,0.00000,-0.00001,0.94158
1.20000,0.06009,95.46989,0.00000,-0.00002,1.17319
1.50000,0.07498,118.42026,0.00000,-0.00002,1.45522
1.80000,0.09004,142.46855,0.00000,-0.00002,1.75074
2.10000,0.10505,168.94124,0.00000,-0.00003,2.07605
2.40000,0.11994,193.48133,0.00000,-0.00003,2.37762
2.70000,0.13506,227.72748,0.00000,-0.00004,2.79845
3.00000,0.14995,269.53344,0.00000,-0.00004,3.31219
3.30000,0.16508,322.06392,0.00000,-0.00005,3.95772
3.60000,0.17991,388.52992,0.00000,-0.00005,4.77449
3.90000,0.19503,467.36789,0.00000,-0.00006,5.74330
4.20000,0.20998,559.85227,0.00000,-0.00005,6.87980
4.50000,0.22505,665.49238,0.00000,-0.00005,8.17797
4.80000,0.24005,786.33046,0.00000,-0.00005,9.66290
5.10000,0.25494,917.15641,0.00000,-0.00004,11.27057
5.40000,0.27013,1076.98198,0.00000,-0.00003,13.23461
5.70000,0.28490,1243.35457,0.00000,-0.00001,15.27909
6.00000,0.30008,1424.53918,0.00000,0.00001,17.50560
6.30000,0.31491,1613.47911,0.00000,0.00003,19.82741
6.60000,0.32998,1810.66114,0.00000,0.00005,22.25050
6.90000,0.34505,2018.42692,0.00000,0.00009,24.80365
7.20000,0.35987,2222.69762,0.00000,0.00011,27.31385
7.50000,0.37506,2428.70841,0.00000,0.00015,29.84544
7.80000,0.38989,2626.22274,0.00000,0.00017,32.27261
8.10000,0.40501,2826.92201,0.00000,0.00020,34.73893
8.40000,0.41990,3020.68796,0.00000,0.00024,37.12004
8.70000,0.43497,3214.31793,0.00000,0.00027,39.49948
9.00000,0.44992,3406.31679,0.00000,0.00030,41.85888
9.30000,0.46504,3592.17338,0.00000,0.00033,44.14280
9.60000,0.47999,3777.51738,0.00000,0.00036,46.42042
9.90000,0.49488,3955.48977,0.00000,0.00039,48.60745
10.20000,0.51012,4135.60793,0.00000,0.00042,50.82085
10.50000,0.52489,4302.54340,0.00000,0.00045,52.87226
10.80000,0.54002,4459.77710,0.00000,0.00048,54.80444
11.10000,0.55491,4610.79180,0.00000,0.00050,56.66020
11.40000,0.56997,4763.49518,0.00000,0.00053,58.53671
11.70000,0.58504,4913.87844,0.00000,0.00056,60.38471
12.00000,0.59987,5050.13913,0.00000,0.00058,62.05917
12.30000,0.61493,5186.60955,0.00000,0.00060,63.73620
12.60000,0.62994,5315.85328,0.00000,0.00062,65.32442
12.90000,0.64501,5441.75766,0.00000,0.00064,66.87161
13.20000,0.65990,5566.62604,0.00000,0.00067,68.40607
13.50000,0.67496,5690.99039,0.00000,0.00068,69.93433
13.80000,0.68997,5819.89810,0.00000,0.00071,71.51843
14.10000,0.70504,5947.31681,0.00000,0.00073,73.08423
14.40000,0.72004,6075.98275,0.00000,0.00075,74.66535
14.70000,0.73499,6205.20599,0.00000,0.00077,76.25333
15.00000,0.75006,6333.88162,0.00000,0.00080,77.83457
15.30000,0.76483,6463.76535,0.00000,0.00082,79.43066
15.60000,0.78001,6597.91604,0.00000,0.00084,81.07919
15.90000,0.79496,6730.30019,0.00000,0.00086,82.70600
16.20000,0.80997,6863.55084,0.00000,0.00088,84.34347
16.50000,0.82498,6997.84979,0.00000,0.00091,85.99381
16.80000,0.83992,7128.79077,0.00000,0.00093,87.60290
17.10000,0.85505,7269.15300,0.00000,0.00095,89.32775
17.40000,0.86994,7403.25898,0.00000,0.00098,90.97573
17.70000,0.88500,7542.37324,0.00000,0.00100,92.68525
18.00000,0.89989,7677.78531,0.00000,0.00103,94.34927
18.30000,0.91502,7815.52419,0.00000,0.00105,96.04189
18.60000,0.92997,7952.87266,0.00000,0.00108,97.72971
18.90000,0.94491,8088.76082,0.00000,0.00110,99.39959
19.20000,0.95998,8230.68917,0.00000,0.00112,101.14369
19.50000,0.97487,8369.41749,0.00000,0.00115,102.84847
19.80000,0.99011,8510.88241,0.00000,0.00117,104.58687
20.10000,1.00488,8651.78481,0.00000,0.00120,106.31837
20.40000,1.02001,8792.70136,0.00000,0.00122,108.05004
20.70000,1.03496,8935.68248,0.00000,0.00125,109.80707
21.00000,1.04996,9078.42219,0.00000,0.00128,111.56115
21.30000,1.06503,9223.49766,0.00000,0.00130,113.34392
21.60000,1.07992,9361.53382,0.00000,0.00133,115.04019
21.90000,1.09504,9510.85836,0.00000,0.00135,116.87518
22.20000,1.10993,9648.93550,0.00000,0.00138,118.57196
22.50000,1.12506,9797.20131,0.00000,0.00140,120.39394
22.80000,1.13989,9941.25158,0.00000,0.00143,122.16412
23.10000,1.15507,10086.72640,0.00000,0.00146,123.95180
23.40000,1.17002,10231.78026,0.00000,0.00149,125.73431
23.70000,1.18497,10372.78548,0.00000,0.00151,127.46707
24.00000,1.20003,10523.90039,0.00000,0.00154,129.32406
24.30000,1.21486,10668.90135,0.00000,0.00156,131.10592
24.60000,1.23005,10819.87023,0.00000,0.00160,132.96111
24.90000,1.24488,10966.28755,0.00000,0.00162,134.76038
25.20000,1.25994,11115.83710,0.00000,0.00165,136.59813
25.50000,1.27495,11263.55752,0.00000,0.00167,138.41341
25.80000,1.28996,11411.07008,0.00000,0.00171,140.22614
26.10000,1.30503,11564.99684,0.00000,0.00173,142.11768
26.40000,1.31991,11711.83437,0.00000,0.00176,143.92211
26.70000,1.33510,11865.88407,0.00000,0.00179,145.81517
27.00000,1.34993,12012.02646,0.00000,0.00182,147.61105
27.30000,1.36505,12165.37431,0.00000,0.00185,149.49548
27.60000,1.37988,12314.10727,0.00000,0.00188,151.32320
27.90000,1.39513,12466.33381,0.00000,0.00191,153.19386
28.20000,1.40996,12618.23922,0.00000,0.00194,155.06056
28.50000,1.42490,12764.96351,0.00000,0.00196,156.86360
28.80000,1.44009,12922.81300,0.00000,0.00199,158.80335
29.10000,1.45492,13070.53864,0.00000,0.00202,160.61869
29.40000,1.47004,13226.83394,0.00000,0.00205,162.53934
29.70000,1.48493,13377.30289,0.00000,0.00208,164.38839
30.00000,1.50000,13531.54778,0.00000,0.00211,166.28385
30.30000,1.51495,13684.89861,0.00000,0.00214,168.16832
30.60000,1.53001,13838.10043,0.00000,0.00217,170.05095
30.90000,1.54496,13992.17099,0.00000,0.00220,171.94427
31.20000,1.55991,14142.46261,0.00000,0.00223,173.79114
31.50000,1.57503,14298.46287,0.00000,0.00227,175.70817
31.80000,1.58992,14449.73797,0.00000,0.00229,177.56713
32.10000,1.60505,14605.80826,0.00000,0.00233,179.48501
32.40000,1.61994,14758.29184,0.00000,0.00236,181.35882
32.70000,1.63506,14910.49081,0.00000,0.00239,183.22914
33.00000,1.65001,15069.62627,0.00000,0.00242,185.18469
33.30000,1.66490,15218.95230,0.00000,0.00245,187.01970
33.60000,1.68008,15378.26359,0.00000,0.00249,188.97741
33.90000,1.69485,15528.67442,0.00000,0.00252,190.82575
34.20000,1.70998,15683.59435,0.00000,0.00255,192.72950
34.50000,1.72493,15838.26840,0.00000,0.00259,194.63023
34.80000,1.73993,15993.34031,0.00000,0.00262,196.53585
35.10000,1.75500,16147.06516,0.00000,0.00265,198.42491
35.40000,1.76995,16302.23542,0.00000,0.00269,200.33174
35.70000,1.78502,16456.48628,0.00000,0.00272,202.22726
36.00000,1.80002,16605.72290,0.00000,0.00276,204.06117
36.30000,1.81509,16763.09705,0.00000,0.00279,205.99508
36.60000,1.82992,16912.49460,0.00000,0.00283,207.83097
36.90000,1.84504,17067.57545,0.00000,0.00286,209.73670
37.20000,1.85987,17220.72363,0.00000,0.00290,211.61868
37.50000,1.87500,17372.82872,0.00000,0.00294,213.48783
37.80000,1.89001,17527.47744,0.00000,0.00297,215.38825
38.10000,1.90483,17674.82758,0.00000,0.00300,217.19898
38.40000,1.92008,17830.13046,0.00000,0.00304,219.10744
38.70000,1.93485,17980.61877,0.00000,0.00308,220.95673
39.00000,1.94997,18132.21127,0.00000,0.00312,222.81959
39.30000,1.96498,18279.94883,0.00000,0.00316,224.63508
39.60000,1.97999,18429.02899,0.00000,0.00320,226.46706
39.90000,1.99500,18575.54913,0.00000,0.00324,228.26759
40.20000,2.01000,18722.40305,0.00000,0.00329,230.07222
40.50000,2.02501,18868.29436,0.00000,0.00333,231.86502
40.80000,2.03996,19011.93112,0.00000,0.00337,233.63012
41.10000,2.05508,19156.02237,0.00000,0.00341,235.40080
41.40000,2.06991,19292.40525,0.00000,0.00346,237.07675
41.70000,2.08504,19436.94949,0.00000,0.00350,238.85300
42.00000,2.09987,19576.48546,0.00000,0.00355,240.56770
42.30000,2.11499,19711.39908,0.00000,0.00360,242.22560
42.60000,2.13000,19850.03799,0.00000,0.00365,243.92928
42.90000,2.14489,19980.00741,0.00000,0.00370,245.52642
43.20000,2.16013,20114.70646,0.00000,0.00375,247.18169
43.50000,2.17490,20240.05055,0.00000,0.00380,248.72199
43.80000,2.18997,20365.24266,0.00000,0.00386,250.26043
44.10000,2.20492,20489.43788,0.00000,0.00391,251.78661
44.40000,2.22004,20609.22384,0.00000,0.00397,253.25862
44.70000,2.23493,20724.75702,0.00000,0.00402,254.67836
45.00000,2.25000,20837.16542,0.00000,0.00408,256.05970
45.30000,2.26506,20948.99416,0.00000,0.00415,257.43392
45.60000,2.27995,21052.05655,0.00000,0.00421,258.70041
45.90000,2.29502,21157.74900,0.00000,0.00428,259.99923
46.20000,2.30985,21251.88410,0.00000,0.00435,261.15601
46.50000,2.32509,21347.11891,0.00000,0.00443,262.32632
46.80000,2.33992,21434.12083,0.00000,0.00450,263.39545
47.10000,2.35493,21515.41114,0.00000,0.00458,264.39439
47.40000,2.37000,21596.53008,0.00000,0.00467,265.39123
47.70000,2.38488,21668.12271,0.00000,0.00476,266.27101
48.00000,2.40013,21738.33251,0.00000,0.00486,267.13379
48.30000,2.41490,21799.25740,0.00000,0.00495,267.88247
48.60000,2.42996,21859.90214,0.00000,0.00505,268.62771
48.90000,2.44503,21914.58941,0.00000,0.00515,269.29974
49.20000,2.46004,21966.16083,0.00000,0.00526,269.93348
49.50000,2.47493,22010.97310,0.00000,0.00537,270.48416
49.80000,2.49005,22055.54247,0.00000,0.00549,271.03186
50.10000,2.50500,22099.00320,0.00000,0.00561,271.56593
50.40000,2.51989,22132.22086,0.00000,0.00573,271.97413
50.70000,2.53507,22172.08743,0.00000,0.00586,272.46403
51.00000,2.54984,22201.13724,0.00000,0.00599,272.82101
51.30000,2.56509,22234.91073,0.00000,0.00612,273.23604
51.60000,2.57992,22264.78755,0.00000,0.00625,273.60319
51.90000,2.59498,22288.31649,0.00000,0.00639,273.89232
52.20000,2.61005,22317.13533,0.00000,0.00653,274.24647
52.50000,2.62494,22336.76016,0.00000,0.00667,274.48763
52.80000,2.64012,22361.83286,0.00000,0.00681,274.79574
53.10000,2.65495,22381.58286,0.00000,0.00695,275.03844
53.40000,2.67002,22403.05841,0.00000,0.00710,275.30234
53.70000,2.68497,22421.48966,0.00000,0.00725,275.52884
54.00000,2.70003,22440.97143,0.00000,0.00739,275.76824
54.30000,2.71498,22457.37165,0.00000,0.00754,275.96978
54.60000,2.72999,22474.50799,0.00000,0.00770,276.18036
54.90000,2.74500,22494.01659,0.00000,0.00786,276.42009
55.20000,2.75994,22503.92139,0.00000,0.00801,276.54181
55.50000,2.77507,22521.96819,0.00000,0.00817,276.76358
55.80000,2.78984,22533.16939,0.00000,0.00832,276.90122
56.10000,2.80502,22549.33119,0.00000,0.00848,277.09983
56.40000,2.81997,22562.80780,0.00000,0.00864,277.26544
56.70000,2.83498,22572.28345,0.00000,0.00881,277.38188
57.00000,2.85005,22586.79271,0.00000,0.00897,277.56018
57.30000,2.86493,22596.20726,0.00000,0.00913,277.67587
57.60000,2.88012,22610.19498,0.00000,0.00929,277.84776
57.90000,2.89495,22619.95822,0.00000,0.00945,277.96774
58.20000,2.90995,22634.16499,0.00000,0.00961,278.14232
58.50000,2.92502,22644.87892,0.00000,0.00978,278.27398
58.80000,2.94009,22655.30229,0.00000,0.00995,278.40207
59.10000,2.95498,22664.62892,0.00000,0.01012,278.51668
59.40000,2.96998,22673.62177,0.00000,0.01028,278.62719
59.70000,2.98505,22687.89858,0.00000,0.01045,278.80263
60.00000,2.99988,22692.76083,0.00000,0.01062,278.86238
60.30000,3.01506,22706.74706,0.00000,0.01079,279.03425
60.60000,3.02989,22714.04415,0.00000,0.01095,279.12392
60.90000,3.04508,22724.06071,0.00000,0.01112,279.24701
61.20000,3.06003,22734.49153,0.00000,0.01129,279.37519
61.50000,3.07497,22740.92734,0.00000,0.01145,279.45428
61.80000,3.09010,22753.25060,0.00000,0.01162,279.60572
62.10000,3.10499,22759.19169,0.00000,0.01179,279.67872
62.40000,3.12005,22767.36200,0.00000,0.01196,279.77912
62.70000,3.13500,22773.98109,0.00000,0.01213,279.86046
63.00000,3.15007,22786.74841,0.00000,0.01230,280.01736
63.30000,3.16496,22792.19925,0.00000,0.01247,280.08434
63.60000,3.18002,22802.80888,0.00000,0.01264,280.21472
63.90000,3.19497,22811.52159,0.00000,0.01280,280.32178
64.20000,3.21010,22817.65491,0.00000,0.01297,280.39715
64.50000,3.22510,22830.05714,0.00000,0.01314,280.54956
64.80000,3.23987,22832.78704,0.00000,0.01330,280.58311
65.10000,3.25512,22845.22504,0.00000,0.01347,280.73595
65.40000,3.26989,22850.16328,0.00000,0.01364,280.79664
65.70000,3.28501,22860.24839,0.00000,0.01380,280.92057
66.00000,3.29996,22868.45744,0.00000,0.01397,281.02145
66.30000,3.31503,22874.74573,0.00000,0.01413,281.09872
66.60000,3.33010,22885.79494,0.00000,0.01430,281.23450
66.90000,3.34492,22890.39493,0.00000,0.01446,281.29103
67.20000,3.36005,22900.98518,0.00000,0.01464,281.42117
67.50000,3.37500,22905.90852,0.00000,0.01480,281.48167
67.80000,3.39006,22916.63438,0.00000,0.01497,281.61347
68.10000,3.40501,22921.56518,0.00000,0.01513,281.67407
68.40000,3.42008,22930.53865,0.00000,0.01530,281.78434
68.70000,3.43497,22939.47786,0.00000,0.01546,281.89419
69.00000,3.44997,22944.16130,0.00000,0.01562,281.95174
69.30000,3.46498,22954.97954,0.00000,0.01579,282.08468
69.60000,3.47987,22958.34124,0.00000,0.01595,282.12599
69.90000,3.49511,22967.75579,0.00000,0.01612,282.24168
70.20000,3.50988,22974.87706,0.00000,0.01627,282.32920
70.50000,3.52501,22982.70911,0.00000,0.01644,282.42544
70.80000,3.54008,22991.63193,0.00000,0.01660,282.53509
71.10000,3.55502,22996.42861,0.00000,0.01676,282.59403
71.40000,3.57009,23005.68968,0.00000,0.01693,282.70784
71.70000,3.58498,23010.85144,0.00000,0.01709,282.77127
72.00000,3.59999,23019.87708,0.00000,0.01725,282.88218
72.30000,3.61487,23026.55280,0.00000,0.01741,282.96422
72.60000,3.63000,23036.32647,0.00000,0.01757,283.08432
72.90000,3.64495,23041.05610,0.00000,0.01773,283.14244
73.20000,3.66007,23047.37121,0.00000,0.01790,283.22005
73.50000,3.67496,23055.20475,0.00000,0.01805,283.31631
73.80000,3.68997,23058.10452,0.00000,0.01822,283.35194
74.10000,3.70509,23072.53033,0.00000,0.01838,283.52922
74.40000,3.71986,23074.82809,0.00000,0.01854,283.55745
74.70000,3.73505,23084.23221,0.00000,0.01870,283.67302
75.00000,3.75000,23091.51739,0.00000,0.01886,283.76254
75.30000,3.76500,23095.78806,0.00000,0.01902,283.81502
75.60000,3.78001,23105.38441,0.00000,0.01918,283.93295
75.90000,3.79490,23110.84121,0.00000,0.01933,284.00001
76.20000,3.81009,23122.06179,0.00000,0.01949,284.13789
76.50000,3.82497,23124.59350,0.00000,0.01965,284.16900
76.80000,3.84004,23132.89046,0.00000,0.01981,284.27096
77.10000,3.85499,23138.10587,0.00000,0.01996,284.33505
77.40000,3.87005,23146.25084,0.00000,0.02012,284.43514
77.70000,3.88494,23152.90123,0.00000,0.02029,284.51686
78.00000,3.90001,23160.79289,0.00000,0.02044,284.61384
78.30000,3.91496,23167.02008,0.00000,0.02059,284.69037
78.60000,3.92996,23169.81256,0.00000,0.02075,284.72468
78.90000,3.94509,23180.65912,0.00000,0.02090,284.85797
79.20000,3.95986,23182.79147,0.00000,0.02106,284.88417
79.50000,3.97510,23195.34570,0.00000,0.02122,285.03845
79.80000,3.98993,23200.42700,0.00000,0.02137,285.10089
80.10000,4.00500,23206.01642,0.00000,0.02153,285.16958
80.40000,4.02007,23214.63823,0.00000,0.02168,285.27553
80.70000,4.03495,23218.87016,0.00000,0.02184,285.32753
81.00000,4.05008,23228.33091,0.00000,0.02199,285.44379
81.30000,4.06485,23232.77742,0.00000,0.02214,285.49843
81.60000,4.08003,23242.34545,0.00000,0.02230,285.61601
81.90000,4.09492,23246.10651,0.00000,0.02246,285.66223
82.20000,4.10999,23253.54218,0.00000,0.02261,285.75360
82.50000,4.12488,23259.50861,0.00000,0.02276,285.82692
82.80000,4.14006,23266.25735,0.00000,0.02292,285.90985
83.10000,4.15501,23275.37984,0.00000,0.02307,286.02196
83.40000,4.16996,23277.77594,0.00000,0.02323,286.05140
83.70000,4.18508,23287.87744,0.00000,0.02338,286.17553
84.00000,4.19991,23290.83383,0.00000,0.02353,286.21186
84.30000,4.21510,23300.22603,0.00000,0.02368,286.32728
84.60000,4.22993,23306.07921,0.00000,0.02384,286.39921
84.90000,4.24499,23312.44498,0.00000,0.02399,286.47743
85.20000,4.26000,23320.53035,0.00000,0.02415,286.57679
85.50000,4.27495,23324.31674,0.00000,0.02430,286.62332
85.80000,4.29008,23332.11303,0.00000,0.02446,286.71913
86.10000,4.30496,23335.97690,0.00000,0.02461,286.76661
86.40000,4.32003,23344.40351,0.00000,0.02476,286.87016
86.70000,4.33492,23347.65792,0.00000,0.02491,286.91015
87.00000,4.34998,23357.45096,0.00000,0.02506,287.03049
87.30000,4.36493,23360.74710,0.00000,0.02521,287.07100
87.60000,4.38006,23366.11152,0.00000,0.02537,287.13692
87.90000,4.39501,23374.63796,0.00000,0.02551,287.24170
88.20000,4.41001,23377.29037,0.00000,0.02567,287.27429
88.50000,4.42514,23387.10725,0.00000,0.02581,287.39493
88.80000,4.43985,23390.01447,0.00000,0.02597,287.43066
89.10000,4.45515,23400.17557,0.00000,0.02612,287.55552
89.40000,4.46998,23403.45383,0.00000,0.02627,287.59581
89.70000,4.48505,23408.08809,0.00000,0.02643,287.65275
90.00000,4.50006,23416.54301,0.00000,0.02658,287.75665
90.30000,4.51494,23421.38588,0.00000,0.02672,287.81617
90.60000,4.53007,23429.16429,0.00000,0.02687,287.91175
90.90000,4.54490,23431.17744,0.00000,0.02703,287.93649
91.20000,4.55996,23439.42672,0.00000,0.02717,288.03786
91.50000,4.57497,23443.30698,0.00000,0.02732,288.08555
91.80000,4.58998,23450.41335,0.00000,0.02747,288.17287
92.10000,4.60493,23456.16519,0.00000,0.02762,288.24356
92.40000,4.62005,23463.20599,0.00000,0.02777,288.33008
92.70000,4.63506,23471.13937,0.00000,0.02791,288.42757
93.00000,4.65007,23472.74870,0.00000,0.02806,288.44734
93.30000,4.66514,23481.64469,0.00000,0.02821,288.55666
93.60000,4.67990,23486.30130,0.00000,0.02836,288.61389
93.90000,4.69515,23493.96348,0.00000,0.02851,288.70804
94.20000,4.70992,23498.36528,0.00000,0.02866,288.76214
94.50000,4.72498,23502.74771,0.00000,0.02880,288.81599
94.80000,4.73999,23510.16402,0.00000,0.02894,288.90713
95.10000,4.75494,23512.67636,0.00000,0.02909,288.93800
95.40000,4.77001,23521.90018,0.00000,0.02924,289.05135
95.70000,4.78489,23525.51073,0.00000,0.02939,289.09572
96.00000,4.80002,23535.44831,0.00000,0.02954,289.21783
96.30000,4.81503,23537.78034,0.00000,0.02968,289.24649
96.60000,4.83003,23543.36828,0.00000,0.02983,289.31516
96.90000,4.84498,23550.22430,0.00000,0.02997,289.39941
97.20000,4.86011,23554.26103,0.00000,0.03012,289.44902
97.50000,4.87506,23562.70701,0.00000,0.03026,289.55281
97.80000,4.88994,23562.31511,0.00000,0.03041,289.54799
98.10000,4.90513,23571.98149,0.00000,0.03056,289.66678
98.40000,4.91990,23574.56684,0.00000,0.03070,289.69855
98.70000,4.93508,23580.80298,0.00000,0.03085,289.77518
99.00000,4.94997,23588.68271,0.00000,0.03099,289.87201
99.30000,4.96498,23590.29055,0.00000,0.03114,289.89177
99.60000,4.98005,23598.09130,0.00000,0.03128,289.98763
99.90000,4.99493,23598.63520,0.00000,0.03143,289.99431
100.20000,5.01006,23606.30482,0.00000,0.03157,290.08856
100.50000,5.02495,23610.37582,0.00000,0.03171,290.13859
100.80000,5.04002,23616.76842,0.00000,0.03185,290.21714
101.10000,5.05496,23621.72306,0.00000,0.03200,290.27803
101.40000,5.07003,23627.63584,0.00000,0.03214,290.35069
101.70000,5.08504,23632.73501,0.00000,0.03228,290.41335
102.00000,5.10004,23635.52898,0.00000,0.03242,290.44769
102.30000,5.11505,23644.17315,0.00000,0.03256,290.55391
102.60000,5.12994,23644.94652,0.00000,0.03270,290.56341
102.90000,5.14506,23654.90794,0.00000,0.03284,290.68583
103.20000,5.15983,23656.66479,0.00000,0.03298,290.70742
103.50000,5.17508,23663.57446,0.00000,0.03312,290.79233
103.80000,5.18997,23667.22971,0.00000,0.03326,290.83724
104.10000,5.20497,23670.98629,0.00000,0.03340,290.88341
104.40000,5.22004,23677.00040,0.00000,0.03354,290.95731
104.70000,5.23493,23680.86874,0.00000,0.03368,291.00485
105.00000,5.25006,23686.18846,0.00000,0.03382,291.07022
105.30001,5.26494,23690.57983,0.00000,0.03396,291.12418
105.60001,5.28001,23697.26598,0.00000,0.03410,291.20635
105.90001,5.29496,23699.93776,0.00000,0.03423,291.23918
106.20001,5.31002,23707.77428,0.00000,0.03437,291.33548
106.50001,5.32491,23712.92114,0.00000,0.03451,291.39873
106.80001,5.34004,23716.27837,0.00000,0.03465,291.43998
107.10001,5.35505,23723.77217,0.00000,0.03478,291.53207
107.40001,5.36993,23723.55908,0.00000,0.03492,291.52945
107.70001,5.38512,23731.77707,0.00000,0.03506,291.63044
108.00001,5.39989,23733.99734,0.00000,0.03520,291.65772
108.30001,5.41507,23741.20057,0.00000,0.03534,291.74624
108.60001,5.42996,23745.32670,0.00000,0.03547,291.79695
108.90001,5.44497,23746.28633,0.00000,0.03560,291.80874
109.20001,5.46010,23754.64588,0.00000,0.03574,291.91147
109.50001,5.47498,23756.88106,0.00000,0.03588,291.93893
109.80001,5.48999,23761.85209,0.00000,0.03601,292.00002
110.10001,5.50500,23766.83950,0.00000,0.03614,292.06131
110.40001,5.52001,23773.65232,0.00000,0.03628,292.14503
110.70001,5.53489,23773.85795,0.00000,0.03642,292.14756
111.00001,5.55008,23781.17442,0.00000,0.03655,292.23747
111.30001,5.56497,23786.94713,0.00000,0.03669,292.30840
111.60001,5.58003,23787.99468,0.00000,0.03683,292.32128
111.90001,5.59504,23798.02912,0.00000,0.03696,292.44459
112.20001,5.60987,23795.74478,0.00000,0.03709,292.41651
112.50001,5.62517,23804.11774,0.00000,0.03723,292.51941
112.80001,5.63988,23804.61246,0.00000,0.03736,292.52549
113.10001,5.65501,23810.42540,0.00000,0.03749,292.59692
113.40001,5.67002,23817.02960,0.00000,0.03763,292.67808
113.70001,5.68490,23818.89820,0.00000,0.03776,292.70104
114.00001,5.70009,23825.83916,0.00000,0.03790,292.78633
114.30001,5.71492,23827.03722,0.00000,0.03803,292.80106
114.60001,5.73005,23833.01258,0.00000,0.03816,292.87448
114.90001,5.74499,23837.02844,0.00000,0.03830,292.92383
115.20001,5.76006,23843.80251,0.00000,0.03843,293.00708
115.50001,5.77495,23844.38217,0.00000,0.03856,293.01420
115.80001,5.79013,23850.80755,0.00000,0.03870,293.09316
116.10001,5.80496,23854.84129,0.00000,0.03883,293.14273
116.40001,5.81997,23855.10057,0.00000,0.03896,293.14591
116.70001,5.83510,23864.10385,0.00000,0.03909,293.25655
117.00001,5.84986,23863.34985,0.00000,0.03922,293.24729
117.30001,5.86511,23870.40704,0.00000,0.03935,293.33401
117.60001,5.87988,23872.50066,0.00000,0.03948,293.35974
117.90001,5.89500,23876.30343,0.00000,0.03962,293.40647
118.20001,5.91007,23881.57547,0.00000,0.03975,293.47125
118.50001,5.92496,23884.03118,0.00000,0.03988,293.50143
118.80001,5.94015,23892.14486,0.00000,0.04001,293.60114
119.10001,5.95497,23893.72587,0.00000,0.04013,293.62057
119.40001,5.97004,23898.67455,0.00000,0.04026,293.68138
119.70001,5.98499,23900.44183,0.00000,0.04039,293.70310
120.00001,6.00011,23907.73892,0.00000,0.04052,293.79277
120.30001,6.01488,23906.59750,0.00000,0.04065,293.77874
120.60001,6.03007,23913.71280,0.00000,0.04078,293.86618
120.90001,6.04490,23918.09821,0.00000,0.04091,293.92007
121.20001,6.05996,23918.58697,0.00000,0.04104,293.92607
121.50001,6.07509,23926.38475,0.00000,0.04117,294.02190
121.80001,6.08986,23925.35359,0.00000,0.04129,294.00923
122.10001,6.10516,23933.24673,0.00000,0.04142,294.10622
122.40001,6.11993,23936.31339,0.00000,0.04155,294.14391
122.70001,6.13500,23937.69324,0.00000,0.04167,294.16086
123.00001,6.15001,23944.35108,0.00000,0.04181,294.24268
123.30001,6.16501,23946.74420,0.00000,0.04193,294.27209
123.60001,6.18008,23951.11471,0.00000,0.04206,294.32579
123.90001,6.19497,23952.00878,0.00000,0.04219,294.33678
124.20001,6.21004,23959.20604,0.00000,0.04231,294.42523
124.50001,6.22504,23962.00001,0.00000,0.04244,294.45956
124.80001,6.24011,23967.11707,0.00000,0.04256,294.52244
125.10001,6.25488,23967.13495,0.00000,0.04269,294.52266
125.40001,6.27012,23971.08972,0.00000,0.04282,294.57126
125.70001,6.28495,23974.51550,0.00000,0.04294,294.61336
126.00001,6.29990,23976.31854,0.00000,0.04307,294.63551
126.30001,6.31509,23982.28496,0.00000,0.04320,294.70883
126.60001,6.32985,23983.23566,0.00000,0.04332,294.72052
126.90001,6.34510,23988.79081,0.00000,0.04345,294.78878
127.20001,6.35993,23990.90081,0.00000,0.04357,294.81471
127.50001,6.37499,23995.26089,0.00000,0.04370,294.86829
127.80001,6.39006,24000.23341,0.00000,0.04382,294.92939
128.10001,6.40501,24003.62194,0.00000,0.04395,294.97103
128.40001,6.42008,24007.17586,0.00000,0.04407,295.01471
128.70001,6.43496,24006.51723,0.00000,0.04420,295.00661
129.00001,6.45003,24012.73698,0.00000,0.04432,295.08305
129.30001,6.46492,24013.54760,0.00000,0.04444,295.09301
129.60001,6.47998,24020.06984,0.00000,0.04457,295.17316
129.90001,6.49487,24021.48694,0.00000,0.04469,295.19057
130.20001,6.51012,24026.26127,0.00000,0.04481,295.24924
130.50001,6.52495,24029.56784,0.00000,0.04494,295.28987
130.80001,6.53989,24029.43224,0.00000,0.04506,295.28821
131.10001,6.55508,24038.22094,0.00000,0.04518,295.39621
131.40001,6.56985,24039.60973,0.00000,0.04531,295.41327
131.70001,6.58504,24045.78924,0.00000,0.04543,295.48921
132.00001,6.59998,24049.14647,0.00000,0.04556,295.53047
132.30001,6.61499,24050.38923,0.00000,0.04568,295.54574
132.60001,6.63000,24054.31271,0.00000,0.04580,295.59395
132.90001,6.64494,24057.10965,0.00000,0.04592,295.62832
133.20001,6.66001,24062.01065,0.00000,0.04605,295.68855
133.50001,6.67496,24062.56795,0.00000,0.04617,295.69540
133.80001,6.69003,24067.72524,0.00000,0.04630,295.75878
134.10001,6.70491,24067.41232,0.00000,0.04642,295.75493
134.40001,6.72010,24075.76293,0.00000,0.04654,295.85755
134.70001,6.73493,24075.78081,0.00000,0.04667,295.85777
135.00001,6.75005,24076.39325,0.00000,0.04679,295.86529
135.30001,6.76500,24084.74088,0.00000,0.04692,295.96787
135.60001,6.77989,24081.57885,0.00000,0.04704,295.92902
135.90001,6.79508,24089.57481,0.00000,0.04716,296.02728
136.20001,6.80990,24091.43150,0.00000,0.04728,296.05009
136.50001,6.82509,24096.18050,0.00000,0.04741,296.10845
136.80001,6.83998,24098.63174,0.00000,0.04753,296.13857
137.10001,6.85498,24101.20964,0.00000,0.04766,296.17025
137.40001,6.87005,24107.01662,0.00000,0.04778,296.24161
137.70001,6.88500,24106.35203,0.00000,0.04790,296.23344
138.00001,6.90001,24110.03113,0.00000,0.04803,296.27866
138.30001,6.91495,24112.20670,0.00000,0.04815,296.30539
138.60001,6.93002,24117.63668,0.00000,0.04828,296.37212
138.90001,6.94491,24118.07030,0.00000,0.04840,296.37745
139.20001,6.96003,24122.69861,0.00000,0.04852,296.43432
139.50001,6.97492,24122.39909,0.00000,0.04864,296.43064
139.80001,6.99005,24126.27041,0.00000,0.04876,296.47821
140.10001,7.00506,24132.13402,0.00000,0.04889,296.55027
140.40001,7.01988,24130.87934,0.00000,0.04901,296.53485
140.70001,7.03513,24137.52079,0.00000,0.04913,296.61647
141.00001,7.04996,24138.68010,0.00000,0.04926,296.63071
141.30001,7.06509,24142.17144,0.00000,0.04938,296.67362
141.60001,7.07991,24143.72116,0.00000,0.04950,296.69266
141.90001,7.09504,24148.22131,0.00000,0.04962,296.74796
142.20001,7.10999,24150.76643,0.00000,0.04975,296.77924
142.50001,7.12493,24152.30721,0.00000,0.04987,296.79817
142.80001,7.14000,24156.30817,0.00000,0.04999,296.84734
143.10001,7.15501,24155.70319,0.00000,0.05011,296.83990
143.40001,7.17002,24161.34477,0.00000,0.05024,296.90923
143.70001,7.18490,24161.06164,0.00000,0.05036,296.90575
144.00001,7.20003,24166.94462,0.00000,0.05048,296.97804
144.30001,7.21492,24170.17072,0.00000,0.05060,297.01769
144.60001,7.23004,24171.01860,0.00000,0.05072,297.02811
144.90001,7.24505,24176.83601,0.00000,0.05084,297.09959
145.20001,7.25994,24174.95698,0.00000,0.05096,297.07650
145.50001,7.27519,24180.87721,0.00000,0.05109,297.14926
145.80001,7.28995,24182.83522,0.00000,0.05121,297.17332
146.10001,7.30508,24185.67687,0.00000,0.05133,297.20824
146.40001,7.32003,24187.70194,0.00000,0.05145,297.23312
146.70001,7.33503,24189.34405,0.00000,0.05157,297.25330
147.00001,7.34998,24190.99212,0.00000,0.05169,297.27355
147.30001,7.36505,24195.74559,0.00000,0.05181,297.33197
147.60001,7.38000,24197.02113,0.00000,0.05193,297.34764
147.90001,7.39494,24197.42346,0.00000,0.05205,297.35259
148.20001,7.41007,24202.33935,0.00000,0.05217,297.41299
148.50001,7.42496,24202.84897,0.00000,0.05230,297.41926
148.80001,7.44003,24206.93189,0.00000,0.05242,297.46943
149.10001,7.45497,24210.93732,0.00000,0.05254,297.51865
149.40001,7.47010,24211.35455,0.00000,0.05266,297.52378
149.70001,7.48511,24217.06319,0.00000,0.05278,297.59393
150.00001,7.49999,24214.72818,0.00000,0.05290,297.56524
150.30001,7.51518,24221.09842,0.00000,0.05302,297.64352
150.60001,7.52995,24220.68715,0.00000,0.05314,297.63846
150.90001,7.54502,24224.03544,0.00000,0.05327,297.67961
151.20001,7.55996,24226.71914,0.00000,0.05339,297.71259
151.50001,7.57497,24226.93819,0.00000,0.05351,297.71528
151.80001,7.59004,24229.42370,0.00000,0.05363,297.74582
152.10001,7.60498,24228.85448,0.00000,0.05375,297.73883
152.40001,7.62005,24232.50377,0.00000,0.05387,297.78367
152.70001,7.63494,24234.21592,0.00000,0.05399,297.80471
153.00001,7.65001,24240.14211,0.00000,0.05411,297.87754
153.30001,7.66495,24239.96627,0.00000,0.05423,297.87538
153.60001,7.68008,24242.48159,0.00000,0.05434,297.90629
153.90001,7.69497,24245.86117,0.00000,0.05446,297.94782
154.20001,7.71009,24245.28599,0.00000,0.05458,297.94075
154.50001,7.72504,24249.78316,0.00000,0.05470,297.99601
154.80001,7.73993,24248.91740,0.00000,0.05481,297.98537
155.10001,7.75518,24254.62902,0.00000,0.05493,298.05556
155.40001,7.76988,24251.75011,0.00000,0.05505,298.02018
155.70001,7.78501,24255.94032,0.00000,0.05517,298.07168
156.00001,7.79996,24258.29768,0.00000,0.05528,298.10064
156.30001,7.81502,24261.09463,0.00000,0.05540,298.13502
156.60001,7.83003,24263.89754,0.00000,0.05552,298.16946
156.90001,7.84492,24263.33874,0.00000,0.05563,298.16259
157.20001,7.86005,24268.83578,0.00000,0.05575,298.23014
157.50001,7.87493,24267.41570,0.00000,0.05586,298.21269
157.80001,7.89000,24272.56256,0.00000,0.05598,298.27594
158.10001,7.90489,24272.82780,0.00000,0.05610,298.27920
158.40001,7.92007,24276.98374,0.00000,0.05621,298.33027
158.70001,7.93496,24279.89393,0.00000,0.05633,298.36603
159.00001,7.95003,24277.55892,0.00000,0.05645,298.33734
159.30001,7.96510,24284.51627,0.00000,0.05657,298.42283
159.60001,7.97992,24282.55081,0.00000,0.05668,298.39868
159.90001,7.99511,24287.36538,0.00000,0.05680,298.45785
160.20001,8.00988,24288.02252,0.00000,0.05691,298.46592
160.50001,8.02501,24289.99245,0.00000,0.05702,298.49013
160.80001,8.04001,24291.71503,0.00000,0.05714,298.51130
161.10001,8.05496,24291.78953,0.00000,0.05725,298.51221
161.40001,8.06997,24295.42691,0.00000,0.05737,298.55691
161.70001,8.08497,24295.83073,0.00000,0.05748,298.56187
162.00001,8.10004,24301.69880,0.00000,0.05760,298.63398
162.30001,8.11493,24300.24147,0.00000,0.05771,298.61608
162.60001,8.13005,24304.50320,0.00000,0.05783,298.66845
162.90001,8.14494,24303.63297,0.00000,0.05794,298.65775
163.20001,8.16007,24308.51609,0.00000,0.05805,298.71776
163.50001,8.17490,24309.15385,0.00000,0.05817,298.72560
163.80001,8.19002,24310.67228,0.00000,0.05828,298.74426
164.10001,8.20503,24314.81928,0.00000,0.05840,298.79522
164.40001,8.21986,24312.06405,0.00000,0.05851,298.76136
164.70001,8.23511,24316.96057,0.00000,0.05862,298.82153
165.00001,8.24987,24317.88743,0.00000,0.05873,298.83292
165.30001,8.26500,24321.24913,0.00000,0.05885,298.87423
165.60001,8.28001,24324.03862,0.00000,0.05896,298.90851
165.90001,8.29495,24324.49162,0.00000,0.05908,298.91408
166.20001,8.31002,24327.87716,0.00000,0.05920,298.95568
166.50001,8.32497,24327.36307,0.00000,0.05931,298.94936
166.80001,8.34004,24330.73819,0.00000,0.05942,298.99084
167.10001,8.35492,24330.45954,0.00000,0.05954,298.98741
167.40001,8.37005,24334.91200,0.00000,0.05965,299.04213
167.70001,8.38488,24334.41430,0.00000,0.05977,299.03601
168.00001,8.40012,24338.19473,0.00000,0.05988,299.08247
168.30001,8.41495,24338.48381,0.00000,0.05999,299.08602
168.60001,8.43002,24338.22751,0.00000,0.06011,299.08287
168.90001,8.44509,24343.26559,0.00000,0.06023,299.14478
169.20001,8.45991,24340.28685,0.00000,0.06034,299.10818
169.50001,8.47510,24344.52325,0.00000,0.06045,299.16024
169.80001,8.48993,24343.67090,0.00000,0.06057,299.14976
170.10001,8.50494,24346.67349,0.00000,0.06068,299.18666
170.40001,8.52000,24350.73704,0.00000,0.06079,299.23660
170.70001,8.53495,24351.25411,0.00000,0.06090,299.24295
171.00001,8.55002,24351.67432,0.00000,0.06102,299.24811
171.30001,8.56502,24352.59521,0.00000,0.06113,299.25943
171.60001,8.58009,24355.95095,0.00000,0.06124,299.30067
171.90001,8.59498,24354.29096,0.00000,0.06136,299.28027
172.20001,8.61011,24359.20984,0.00000,0.06147,299.34071
172.50001,8.62493,24357.26672,0.00000,0.06158,299.31684
172.80001,8.64012,24360.37958,0.00000,0.06170,299.35509
173.10001,8.65495,24361.64021,0.00000,0.06180,299.37058
173.40001,8.66995,24359.44080,0.00000,0.06192,299.34355
173.70001,8.68514,24365.87214,0.00000,0.06203,299.42258
174.00001,8.69985,24363.25997,0.00000,0.06214,299.39048
174.30001,8.71504,24367.05828,0.00000,0.06225,299.43716
174.60001,8.72992,24368.72274,0.00000,0.06236,299.45761
174.90001,8.74499,24371.33491,0.00000,0.06247,299.48971
175.20001,8.76012,24373.69823,0.00000,0.06259,299.51876
175.50001,8.77500,24372.64621,0.00000,0.06270,299.50583
175.80001,8.79007,24375.53853,0.00000,0.06281,299.54137
176.10001,8.80502,24375.27031,0.00000,0.06292,299.53808
176.40001,8.82009,24379.43369,0.00000,0.06303,299.58924
176.70001,8.83491,24376.24782,0.00000,0.06314,299.55009
177.00001,8.85010,24380.09828,0.00000,0.06325,299.59740
177.30001,8.86493,24379.99398,0.00000,0.06337,299.59612
177.60001,8.88005,24379.96864,0.00000,0.06347,299.59581
177.90001,8.89500,24384.03517,0.00000,0.06359,299.64578
178.20001,8.90995,24381.34849,0.00000,0.06369,299.61277
178.50001,8.92514,24386.82318,0.00000,0.06380,299.68004
178.80001,8.93984,24384.34511,0.00000,0.06391,299.64959
179.10001,8.95509,24388.84377,0.00000,0.06402,299.70487
179.40001,8.96998,24390.36220,0.00000,0.06413,299.72353
179.70001,8.98493,24391.57665,0.00000,0.06424,299.73846
180.00001,9.00005,24393.57787,0.00000,0.06435,299.76305
180.30001,9.01506,24393.20087,0.00000,0.06446,299.75842
180.60001,9.03001,24393.77606,0.00000,0.06456,299.76548
180.90001,9.04507,24394.84745,0.00000,0.06468,299.77865
181.20001,9.06008,24398.35966,0.00000,0.06479,299.82181
181.50001,9.07491,24397.11541,0.00000,0.06490,299.80652
181.80001,9.09016,24402.66013,0.00000,0.06500,299.87466
182.10001,9.10486,24400.70808,0.00000,0.06511,299.85067
182.40001,9.12005,24400.95693,0.00000,0.06522,299.85373
182.70001,9.13500,24403.64957,0.00000,0.06533,299.88682
183.00001,9.14989,24401.05230,0.00000,0.06543,299.85490
183.30001,9.16507,24406.84438,0.00000,0.06554,299.92608
183.60001,9.17990,24406.18277,0.00000,0.06565,299.91795
183.90001,9.19503,24406.89653,0.00000,0.06576,299.92672
184.20001,9.20997,24408.15121,0.00000,0.06587,299.94214
184.50001,9.22504,24409.86186,0.00000,0.06597,299.96316
184.80001,9.24005,24411.43990,0.00000,0.06609,299.98255
185.10001,9.25511,24411.60232,0.00000,0.06619,299.98454
185.40001,9.26994,24413.37556,0.00000,0.06630,300.00634
185.70001,9.28507,24412.48596,0.00000,0.06640,299.99540
186.00001,9.30008,24416.46159,0.00000,0.06651,300.04426
186.30001,9.31484,24411.51440,0.00000,0.06662,299.98346
186.60001,9.33009,24416.31109,0.00000,0.06673,300.04241
186.90001,9.34492,24418.46728,0.00000,0.06683,300.06891
187.20001,9.36005,24416.66871,0.00000,0.06694,300.04680
187.50001,9.37505,24420.14962,0.00000,0.06704,300.08958
187.80001,9.38988,24417.45549,0.00000,0.06715,300.05647
188.10001,9.40513,24421.80365,0.00000,0.06725,300.10991
188.40001,9.41995,24422.15085,0.00000,0.06737,300.11417
188.70001,9.43502,24422.35202,0.00000,0.06747,300.11664
189.00001,9.44997,24423.75571,0.00000,0.06758,300.13389
189.30001,9.46498,24423.86895,0.00000,0.06768,300.13528
189.60001,9.47992,24423.84958,0.00000,0.06779,300.13505
189.90001,9.49505,24424.94035,0.00000,0.06789,300.14845
190.20001,9.51000,24427.05780,0.00000,0.06800,300.17447
190.50001,9.52494,24424.99846,0.00000,0.06811,300.14916
190.80001,9.54007,24428.67458,0.00000,0.06821,300.19434
191.10001,9.55484,24425.26966,0.00000,0.06831,300.15250
191.40001,9.57009,24429.32278,0.00000,0.06842,300.20230
191.70001,9.58491,24429.93522,0.00000,0.06852,300.20983
192.00001,9.59998,24429.37046,0.00000,0.06862,300.20289
192.30001,9.61505,24433.94959,0.00000,0.06873,300.25916
192.60001,9.62987,24429.44497,0.00000,0.06883,300.20381
192.90001,9.64512,24433.78121,0.00000,0.06894,300.25709
193.20001,9.65995,24431.17499,0.00000,0.06904,300.22507
193.50001,9.67502,24432.34324,0.00000,0.06914,300.23942
193.80001,9.69002,24434.04347,0.00000,0.06924,300.26032
194.10001,9.70503,24434.91369,0.00000,0.06935,300.27101
194.40001,9.71998,24434.72892,0.00000,0.06945,300.26874
194.70001,9.73510,24436.42914,0.00000,0.06955,300.28963
195.00001,9.74999,24434.20738,0.00000,0.06965,300.26233
195.30001,9.76494,24432.31046,0.00000,0.06974,300.23902
195.60001,9.78007,24437.39772,0.00000,0.06985,300.30153
195.90001,9.79483,24434.10456,0.00000,0.06995,300.26107
196.20001,9.81008,24438.47358,0.00000,0.07004,300.31476
196.50001,9.82491,24439.11284,0.00000,0.07014,300.32261
196.80001,9.83997,24436.34570,0.00000,0.07025,300.28861
197.10001,9.85510,24440.76389,0.00000,0.07034,300.34290
197.40001,9.86993,24437.41560,0.00000,0.07044,300.30175
197.70001,9.88518,24442.32404,0.00000,0.07054,300.36207
198.00001,9.89994,24439.12774,0.00000,0.07064,300.32279
198.30001,9.91507,24440.63574,0.00000,0.07074,300.34133
198.60001,9.93002,24439.21566,0.00000,0.07083,300.32387
198.90001,9.94503,24441.03807,0.00000,0.07093,300.34627
199.20001,9.95997,24441.52236,0.00000,0.07103,300.35222
199.50001,9.97498,24439.74912,0.00000,0.07112,300.33043
199.80001,9.98999,24443.38948,0.00000,0.07122,300.37516
200.10001,10.00499,24439.37510,0.00000,0.07134,300.32583
200.40001,10.02006,24443.15255,0.00000,0.07144,300.37225
200.70001,10.03489,24441.14983,0.00000,0.07153,300.34764
201.00001,10.05008,24444.25672,0.00000,0.07163,300.38582
201.30001,10.06490,24445.32812,0.00000,0.07172,300.39899
201.60001,10.07997,24442.03794,0.00000,0.07182,300.35856
201.90001,10.09510,24445.00774,0.00000,0.07191,300.39505
202.20001,10.10992,24443.10039,0.00000,0.07201,300.37161
202.50001,10.12511,24444.24629,0.00000,0.07210,300.38569
202.80001,10.13988,24443.25387,0.00000,0.07220,300.37350
203.10001,10.15507,24445.27745,0.00000,0.07229,300.39837
203.40001,10.17001,24443.23450,0.00000,0.07238,300.37326
203.70001,10.18502,24442.19291,0.00000,0.07247,300.36046
204.00001,10.19997,24442.38067,0.00000,0.07256,300.36277
204.30001,10.21503,24441.18410,0.00000,0.07265,300.34806
204.60001,10.22998,24443.62938,0.00000,0.07274,300.37811
204.90001,10.24487,24440.28556,0.00000,0.07283,300.33702
205.20001,10.26006,24442.69955,0.00000,0.07292,300.36669
205.50001,10.27488,24439.92943,0.00000,0.07301,300.33265
205.80001,10.29013,24440.36752,0.00000,0.07309,300.33803
206.10001,10.30496,24439.38106,0.00000,0.07318,300.32591
206.40001,10.31996,24437.01029,0.00000,0.07326,300.29677
206.70001,10.33515,24440.70131,0.00000,0.07335,300.34213
207.00001,10.34998,24436.03724,0.00000,0.07343,300.28482
207.30001,10.36511,24434.26102,0.00000,0.07351,300.26299
207.60001,10.37999,24436.01042,0.00000,0.07360,300.28449
207.90001,10.39500,24433.53683,0.00000,0.07368,300.25409
208.20001,10.40995,24432.23298,0.00000,0.07376,300.23807
208.50001,10.42496,24431.73677,0.00000,0.07384,300.23197
208.80001,10.43996,24430.90379,0.00000,0.07392,300.22173
209.10001,10.45503,24428.30652,0.00000,0.07400,300.18982
209.40001,10.47004,24431.16009,0.00000,0.07407,300.22488
209.70001,10.48486,24427.30516,0.00000,0.07415,300.17751
210.00001,10.50005,24429.01880,0.00000,0.07422,300.19857
210.30001,10.51494,24426.37086,0.00000,0.07430,300.16603
210.60001,10.53013,24426.03856,0.00000,0.07437,300.16195
210.90001,10.54501,24425.55428,0.00000,0.07445,300.15599
211.20001,10.56002,24419.21830,0.00000,0.07452,300.07813
211.50001,10.57509,24421.22549,0.00000,0.07459,300.10280
211.80001,10.58991,24415.64947,0.00000,0.07465,300.03428
212.10001,10.60510,24416.51821,0.00000,0.07473,300.04495
212.40001,10.61993,24410.90047,0.00000,0.07479,299.97592
212.70001,10.63500,24411.00329,0.00000,0.07486,299.97718
213.00001,10.65000,24408.36877,0.00000,0.07492,299.94481
213.30001,10.66501,24406.43907,0.00000,0.07498,299.92110
213.60001,10.68002,24405.71785,0.00000,0.07505,299.91223
213.90001,10.69497,24398.91249,0.00000,0.07511,299.82860
214.20001,10.71003,24399.17028,0.00000,0.07517,299.83177
214.50001,10.72486,24392.57503,0.00000,0.07523,299.75073
214.80001,10.74005,24390.48737,0.00000,0.07529,299.72507
215.10001,10.75487,24385.28240,0.00000,0.07534,299.66111
215.40001,10.77006,24382.91162,0.00000,0.07540,299.63198
215.70001,10.78495,24378.20584,0.00000,0.07545,299.57415
216.00001,10.79996,24369.46034,0.00000,0.07550,299.46668
216.30001,10.81508,24366.39667,0.00000,0.07555,299.42903
216.60001,10.82997,24357.04470,0.00000,0.07560,299.31411
216.90001,10.84504,24351.72051,0.00000,0.07565,299.24868
217.20001,10.85992,24343.32520,0.00000,0.07569,299.14551
217.50001,10.87505,24339.67590,0.00000,0.07573,299.10067
217.80001,10.88994,24329.45669,0.00000,0.07577,298.97509
218.10001,10.90501,24320.54281,0.00000,0.07582,298.86555
218.40001,10.91995,24312.98047,0.00000,0.07585,298.77262
218.70001,10.93502,24301.66602,0.00000,0.07589,298.63358
219.00001,10.95009,24293.57171,0.00000,0.07592,298.53411
219.30001,10.96491,24277.18937,0.00000,0.07595,298.33280
219.60001,10.98010,24269.83416,0.00000,0.07599,298.24241
219.90001,10.99493,24254.04340,0.00000,0.07601,298.04837
220.20001,11.01005,24242.07181,0.00000,0.07604,297.90125
220.50001,11.02494,24230.06743,0.00000,0.07606,297.75373
220.80001,11.04001,24212.26203,0.00000,0.07608,297.53493
221.10001,11.05514,24197.66635,0.00000,0.07611,297.35557
221.40001,11.06991,24177.60342,0.00000,0.07612,297.10902
221.70001,11.08503,24159.45232,0.00000,0.07614,296.88597
222.00001,11.09998,24139.06008,0.00000,0.07616,296.63538
222.30001,11.11505,24118.48605,0.00000,0.07617,296.38255
222.60001,11.12999,24093.09000,0.00000,0.07618,296.07047
222.90001,11.14500,24066.56742,0.00000,0.07619,295.74455
223.20001,11.16007,24038.67245,0.00000,0.07620,295.40176
223.50001,11.17502,24005.51587,0.00000,0.07620,294.99431
223.80001,11.19008,23976.69554,0.00000,0.07621,294.64015
224.10001,11.20491,23938.32058,0.00000,0.07621,294.16857
224.40001,11.22010,23901.99602,0.00000,0.07621,293.72219
224.70001,11.23486,23859.62009,0.00000,0.07621,293.20145
225.00001,11.25011,23810.10056,0.00000,0.07620,292.59293
225.30001,11.26500,23756.80655,0.00000,0.07620,291.93802
225.60001,11.27995,23690.27585,0.00000,0.07619,291.12045
225.90001,11.29507,23604.52116,0.00000,0.07618,290.06664
226.20001,11.30990,23440.73653,0.00000,0.07614,288.05396
226.50001,11.32515,23092.69160,0.00000,0.07607,283.77697
226.80001,11.33997,22837.93241,0.00000,0.07601,280.64634
227.10001,11.35504,22429.04305,0.00000,0.07591,275.62166
227.16601,11.35845,21145.69694,0.00000,0.07395,259.85112
227.17201,11.35923,18241.10001,0.00000,0.06732,224.15768
227.17801,11.36018,14516.76190,0.00000,0.05982,178.39076
227.18001,11.36048,13241.96309,0.00000,0.05703,162.72526