File: scratch/college-stuff/ME Lab/ME lab Fall 2013/group11/group11.is_tens_RawData/Specimen_RawData_4.csv
Time,Extension,Load,Strain 2,Tensile strain,Tensile stress
(sec),(mm),(N),(mm/mm),(mm/mm),(MPa)
0.00000,0.00006,0.04748,0.00000,0.00000,0.00059
0.10000,0.00161,2.45708,0.00000,0.00000,0.03065
0.20000,0.00723,3.07844,0.00000,0.00000,0.03840
0.30000,0.01357,2.98923,0.00000,0.00000,0.03729
0.40000,0.01937,2.88647,0.00000,0.00000,0.03600
0.50000,0.02469,2.80800,0.00000,0.00000,0.03503
0.60000,0.02995,2.65936,0.00000,0.00000,0.03317
0.70000,0.03498,2.56043,0.00000,0.00000,0.03194
0.80000,0.04006,2.98278,0.00000,0.00000,0.03721
0.90000,0.04502,2.85906,0.00000,0.00000,0.03566
1.00000,0.05004,2.95581,0.00000,0.00000,0.03687
1.10000,0.05501,3.12453,0.00000,0.00000,0.03897
1.20000,0.06003,3.43553,0.00000,0.00000,0.04285
1.30000,0.06505,2.99517,0.00000,0.00000,0.03736
1.40000,0.06995,3.54782,0.00000,0.00000,0.04425
1.50000,0.07504,2.59503,0.00000,0.00000,0.03237
1.60000,0.07994,3.09132,0.00000,0.00000,0.03856
1.70000,0.08514,3.36242,0.00000,0.00000,0.04194
1.80000,0.08998,2.71685,0.00000,0.00000,0.03389
1.90000,0.09513,3.67386,0.00000,0.00000,0.04583
2.00000,0.09997,3.73817,0.00000,0.00000,0.04663
2.10000,0.10511,3.35773,0.00000,0.00000,0.04188
2.20000,0.10995,3.34580,0.00000,0.00000,0.04173
2.30000,0.11509,4.05745,0.00000,0.00000,0.05061
2.40000,0.11988,3.67880,0.00000,0.00000,0.04589
2.50000,0.12508,3.96774,0.00000,0.00000,0.04949
2.60000,0.12998,4.14915,0.00000,0.00000,0.05175
2.70000,0.13512,3.00638,0.00000,0.00000,0.03750
2.80000,0.13997,4.11250,0.00000,0.00000,0.05130
2.90000,0.14499,3.65625,0.00000,0.00000,0.04561
3.00000,0.14995,3.03572,0.00000,0.00000,0.03787
3.10000,0.15503,3.02420,0.00000,0.00000,0.03772
3.20000,0.16000,3.81822,0.00000,0.00000,0.04763
3.30000,0.16496,3.45351,0.00000,0.00000,0.04308
3.40000,0.16998,4.11193,0.00000,0.00000,0.05129
3.50000,0.17494,4.09191,0.00000,0.00000,0.05104
3.60000,0.18003,3.81573,0.00000,0.00000,0.04760
3.70000,0.18499,4.47738,0.00000,0.00000,0.05585
3.80000,0.19007,4.23797,0.00000,0.00000,0.05286
3.90000,0.19491,4.04726,0.00000,0.00000,0.05048
4.00000,0.20012,4.67803,0.00000,0.00000,0.05835
4.10000,0.20490,6.17295,0.00000,0.00000,0.07700
4.20000,0.21010,6.23219,0.00000,0.00000,0.07774
4.30000,0.21494,6.31299,0.00000,0.00000,0.07875
4.40000,0.22009,6.79182,0.00000,0.00000,0.08472
4.50000,0.22499,15.36749,0.00000,0.00000,0.19169
4.60000,0.23013,44.55671,0.00000,0.00000,0.55578
4.70000,0.23497,78.10224,0.00000,0.00001,0.97422
4.80000,0.24000,112.71540,0.00000,0.00000,1.40597
4.90000,0.24496,148.58481,0.00000,0.00001,1.85339
5.00000,0.25004,185.28305,0.00000,0.00001,2.31115
5.10000,0.25500,222.43899,0.00000,0.00002,2.77462
5.20000,0.26002,259.85704,0.00000,0.00002,3.24136
5.30000,0.26499,298.55340,0.00000,0.00002,3.72404
5.40000,0.27001,330.91756,0.00000,0.00003,4.12774
5.50000,0.27497,366.19189,0.00000,0.00003,4.56774
5.60000,0.28005,398.96686,0.00000,0.00004,4.97656
5.70000,0.28496,433.21475,0.00000,0.00004,5.40376
5.80000,0.28998,464.19911,0.00000,0.00004,5.79024
5.90000,0.29500,497.41822,0.00000,0.00005,6.20461
6.00000,0.29996,526.97854,0.00000,0.00005,6.57333
6.10000,0.30511,557.93920,0.00000,0.00005,6.95952
6.20000,0.30995,586.61527,0.00000,0.00006,7.31721
6.30000,0.31503,617.83092,0.00000,0.00006,7.70659
6.40000,0.31987,646.52781,0.00000,0.00007,8.06454
6.50000,0.32514,680.02748,0.00000,0.00007,8.48240
6.60000,0.32992,716.53840,0.00000,0.00008,8.93783
6.70000,0.33506,760.90829,0.00000,0.00009,9.49128
6.80000,0.33990,802.00685,0.00000,0.00010,10.00393
6.90000,0.34505,842.34271,0.00000,0.00011,10.50706
7.00000,0.34995,883.81898,0.00000,0.00011,11.02442
7.10000,0.35503,927.15332,0.00000,0.00012,11.56496
7.20000,0.35993,969.74578,0.00000,0.00013,12.09624
7.30000,0.36496,1012.06247,0.00000,0.00014,12.62408
7.40000,0.36992,1051.02481,0.00000,0.00015,13.11008
7.50000,0.37500,1088.06873,0.00000,0.00016,13.57215
7.60000,0.37996,1121.91830,0.00000,0.00017,13.99438
7.70000,0.38498,1154.87380,0.00000,0.00017,14.40545
7.80000,0.38995,1186.01667,0.00000,0.00018,14.79392
7.90000,0.39497,1214.41493,0.00000,0.00018,15.14815
8.00000,0.39999,1244.13632,0.00000,0.00019,15.51888
8.10000,0.40495,1270.49703,0.00000,0.00020,15.84770
8.20000,0.40998,1298.44183,0.00000,0.00020,16.19627
8.30000,0.41494,1322.97073,0.00000,0.00021,16.50223
8.40000,0.42008,1349.53819,0.00000,0.00021,16.83362
8.50000,0.42498,1372.62801,0.00000,0.00022,17.12164
8.60000,0.43007,1399.42104,0.00000,0.00022,17.45584
8.70000,0.43491,1422.23602,0.00000,0.00023,17.74043
8.80000,0.44005,1447.30452,0.00000,0.00023,18.05312
8.90000,0.44489,1468.97892,0.00000,0.00024,18.32348
9.00000,0.45004,1494.14642,0.00000,0.00024,18.63741
9.10000,0.45488,1516.91921,0.00000,0.00025,18.92147
9.20000,0.46002,1540.44759,0.00000,0.00025,19.21496
9.30000,0.46492,1564.25815,0.00000,0.00026,19.51196
9.40000,0.47012,1592.14344,0.00000,0.00026,19.85979
9.50000,0.47497,1618.30354,0.00000,0.00026,20.18610
9.60000,0.47999,1647.52677,0.00000,0.00027,20.55062
9.70000,0.48489,1673.75840,0.00000,0.00028,20.87782
9.80000,0.49003,1704.79212,0.00000,0.00029,21.26493
9.90000,0.49494,1733.53758,0.00000,0.00029,21.62349
10.00000,0.50002,1763.54013,0.00000,0.00029,21.99773
10.10000,0.50492,1793.48625,0.00000,0.00030,22.37126
10.20000,0.51000,1824.10087,0.00000,0.00030,22.75314
10.30000,0.51503,1856.48110,0.00000,0.00031,23.15704
10.40000,0.52005,1887.12664,0.00000,0.00032,23.53930
10.50000,0.52501,1922.01827,0.00000,0.00033,23.97452
10.60000,0.52991,1953.73446,0.00000,0.00033,24.37014
10.70000,0.53500,1988.06860,0.00000,0.00034,24.79841
10.80000,0.53996,2019.99713,0.00000,0.00034,25.19667
10.90000,0.54504,2056.23545,0.00000,0.00035,25.64870
11.00000,0.54988,2088.42140,0.00000,0.00036,26.05017
11.10000,0.55503,2124.70759,0.00000,0.00037,26.50279
11.20000,0.55987,2156.31388,0.00000,0.00037,26.89704
11.30000,0.56507,2193.70518,0.00000,0.00038,27.36344
11.40000,0.56991,2226.45346,0.00000,0.00039,27.77193
11.50000,0.57506,2262.11268,0.00000,0.00039,28.21673
11.60000,0.57990,2297.58974,0.00000,0.00040,28.65926
11.70000,0.58504,2338.10022,0.00000,0.00041,29.16457
11.80000,0.58994,2374.23275,0.00000,0.00041,29.61527
11.90000,0.59503,2411.41319,0.00000,0.00042,30.07905
12.00000,0.59987,2448.91718,0.00000,0.00043,30.54686
12.10000,0.60489,2487.74048,0.00000,0.00043,31.03113
12.20000,0.60991,2525.62668,0.00000,0.00044,31.50370
12.30000,0.61499,2564.90298,0.00000,0.00045,31.99362
12.40000,0.61996,2603.64134,0.00000,0.00046,32.47683
12.50000,0.62498,2641.64507,0.00000,0.00047,32.95087
12.60000,0.62994,2681.91397,0.00000,0.00047,33.45317
12.70000,0.63502,2720.30719,0.00000,0.00048,33.93207
12.80000,0.64005,2760.72435,0.00000,0.00049,34.43622
12.90000,0.64489,2797.86028,0.00000,0.00049,34.89944
13.00000,0.65003,2840.10414,0.00000,0.00050,35.42637
13.10000,0.65493,2877.92590,0.00000,0.00051,35.89815
13.20000,0.66008,2919.25184,0.00000,0.00052,36.41363
13.30000,0.66492,2957.27272,0.00000,0.00052,36.88789
13.40000,0.67006,2999.28989,0.00000,0.00053,37.41200
13.50000,0.67484,3035.90465,0.00000,0.00054,37.86872
13.60000,0.68011,3078.15298,0.00000,0.00054,38.39571
13.70000,0.68501,3116.40874,0.00000,0.00055,38.87289
13.80000,0.69009,3158.53730,0.00000,0.00056,39.39839
13.90000,0.69493,3196.63137,0.00000,0.00057,39.87356
14.00000,0.70008,3237.17073,0.00000,0.00058,40.37923
14.10000,0.70498,3275.96590,0.00000,0.00058,40.86315
14.20000,0.71012,3317.52785,0.00000,0.00059,41.38158
14.30000,0.71490,3356.09429,0.00000,0.00060,41.86264
14.40000,0.72004,3397.82201,0.00000,0.00061,42.38313
14.50000,0.72489,3434.87374,0.00000,0.00061,42.84530
14.60000,0.73009,3474.71423,0.00000,0.00062,43.34226
14.70000,0.73499,3511.38338,0.00000,0.00063,43.79966
14.80000,0.74001,3549.16565,0.00000,0.00063,44.27094
14.90000,0.74498,3585.35498,0.00000,0.00064,44.72235
15.00000,0.75000,3620.53365,0.00000,0.00065,45.16115
15.10000,0.75502,3656.74943,0.00000,0.00065,45.61290
15.20000,0.75998,3691.65763,0.00000,0.00066,46.04833
15.30000,0.76495,3730.85625,0.00000,0.00067,46.53728
15.40000,0.76991,3764.05194,0.00000,0.00068,46.95135
15.50000,0.77505,3802.47198,0.00000,0.00068,47.43058
15.60000,0.77995,3835.40094,0.00000,0.00069,47.84133
15.70000,0.78504,3871.88829,0.00000,0.00069,48.29646
15.80000,0.78988,3906.18369,0.00000,0.00070,48.72424
15.90000,0.79508,3944.75386,0.00000,0.00071,49.20535
16.00000,0.79992,3978.34927,0.00000,0.00072,49.62441
16.10000,0.80513,4015.60329,0.00000,0.00072,50.08910
16.20000,0.80985,4049.84951,0.00000,0.00073,50.51628
16.30000,0.81505,4088.78960,0.00000,0.00074,51.00200
16.40000,0.81983,4122.90320,0.00000,0.00075,51.42752
16.50000,0.82504,4161.29120,0.00000,0.00075,51.90636
16.60000,0.82988,4197.26968,0.00000,0.00076,52.35514
16.70000,0.83496,4235.28962,0.00000,0.00077,52.82939
16.80000,0.83986,4269.52355,0.00000,0.00077,53.25641
16.90000,0.84500,4307.30954,0.00000,0.00078,53.72774
17.00000,0.84997,4343.57114,0.00000,0.00079,54.18005
17.10000,0.85505,4382.90015,0.00000,0.00079,54.67062
17.20000,0.86001,4419.17218,0.00000,0.00080,55.12307
17.30000,0.86497,4454.76845,0.00000,0.00081,55.56708
17.40000,0.87000,4495.05746,0.00000,0.00082,56.06963
17.50000,0.87502,4530.43431,0.00000,0.00081,56.51091
17.60000,0.88004,4570.02558,0.00000,0.00083,57.00475
17.70000,0.88494,4605.03213,0.00000,0.00084,57.44141
17.80000,0.89003,4645.12855,0.00000,0.00084,57.94156
17.90000,0.89493,4680.60188,0.00000,0.00085,58.38404
18.00000,0.90013,4720.80521,0.00000,0.00086,58.88552
18.10000,0.90497,4758.05141,0.00000,0.00087,59.35012
18.20000,0.91012,4799.39468,0.00000,0.00087,59.86582
18.30000,0.91490,4833.81972,0.00000,0.00088,60.29522
18.40000,0.92010,4875.16485,0.00000,0.00089,60.81095
18.50000,0.92500,4910.28875,0.00000,0.00089,61.24907
18.60000,0.93009,4951.79929,0.00000,0.00091,61.76685
18.70000,0.93493,4988.37009,0.00000,0.00091,62.22302
18.80000,0.94001,5030.11718,0.00000,0.00092,62.74376
18.90000,0.94491,5066.50731,0.00000,0.00092,63.19768
19.00000,0.95006,5107.12601,0.00000,0.00093,63.70434
19.10000,0.95490,5145.42311,0.00000,0.00094,64.18204
19.20000,0.95998,5185.72256,0.00000,0.00094,64.68472
19.30000,0.96494,5224.33817,0.00000,0.00096,65.16640
19.40000,0.97002,5264.29825,0.00000,0.00096,65.66485
19.50000,0.97493,5303.30874,0.00000,0.00097,66.15145
19.60000,0.98001,5343.68269,0.00000,0.00098,66.65506
19.70000,0.98491,5383.76234,0.00000,0.00098,67.15500
19.80000,0.98999,5423.15021,0.00000,0.00100,67.64631
19.90000,0.99502,5465.12343,0.00000,0.00100,68.16986
20.00000,0.99998,5501.71286,0.00000,0.00100,68.62627
20.10000,1.00500,5545.33042,0.00000,0.00102,69.17033
20.20000,1.00996,5581.84385,0.00000,0.00102,69.62579
20.30000,1.01505,5625.05610,0.00000,0.00103,70.16480
20.40000,1.01995,5663.58976,0.00000,0.00103,70.64546
20.50000,1.02503,5705.98245,0.00000,0.00105,71.17425
20.60000,1.02987,5744.47960,0.00000,0.00105,71.65445
20.70000,1.03502,5786.08178,0.00000,0.00106,72.17338
20.80000,1.03992,5824.71937,0.00000,0.00107,72.65533
20.90000,1.04506,5868.39952,0.00000,0.00107,73.20018
21.00000,1.04990,5907.69127,0.00000,0.00108,73.69029
21.10000,1.05499,5950.75823,0.00000,0.00109,74.22749
21.20000,1.05989,5989.77879,0.00000,0.00110,74.71421
21.30000,1.06503,6032.87928,0.00000,0.00111,75.25183
21.40000,1.06999,6072.86021,0.00000,0.00112,75.75054
21.50000,1.07502,6115.06328,0.00000,0.00113,76.27697
21.60000,1.07992,6155.42717,0.00000,0.00113,76.78045
21.70000,1.08500,6196.43629,0.00000,0.00114,77.29198
21.80000,1.09002,6239.50697,0.00000,0.00115,77.82923
21.90000,1.09498,6279.61978,0.00000,0.00115,78.32958
22.00000,1.09995,6321.70811,0.00000,0.00117,78.85457
22.10000,1.10497,6361.32658,0.00000,0.00117,79.34876
22.20000,1.10999,6404.79624,0.00000,0.00118,79.89098
22.30000,1.11501,6444.47580,0.00000,0.00119,80.38593
22.40000,1.12004,6489.30445,0.00000,0.00119,80.94511
22.50000,1.12500,6528.37232,0.00000,0.00120,81.43242
22.60000,1.13008,6573.42747,0.00000,0.00121,81.99443
22.70000,1.13498,6611.47237,0.00000,0.00122,82.46898
22.80000,1.14007,6656.45003,0.00000,0.00123,83.03002
22.90000,1.14497,6696.13555,0.00000,0.00123,83.52504
23.00000,1.15005,6740.82115,0.00000,0.00125,84.08243
23.10000,1.15489,6780.97457,0.00000,0.00125,84.58329
23.20000,1.16010,6825.90529,0.00000,0.00126,85.14374
23.30000,1.16494,6866.51617,0.00000,0.00127,85.65030
23.40000,1.17008,6912.22176,0.00000,0.00127,86.22042
23.50000,1.17492,6952.57112,0.00000,0.00129,86.72372
23.60000,1.18012,6997.45491,0.00000,0.00129,87.28358
23.70000,1.18497,7037.75808,0.00000,0.00130,87.78631
23.80000,1.19005,7083.35936,0.00000,0.00131,88.35512
23.90000,1.19489,7125.27931,0.00000,0.00132,88.87801
24.00000,1.20003,7169.42474,0.00000,0.00133,89.42867
24.10000,1.20494,7212.50251,0.00000,0.00133,89.96600
24.20000,1.21008,7256.23593,0.00000,0.00134,90.51152
24.30000,1.21498,7298.80705,0.00000,0.00135,91.04253
24.40000,1.21994,7341.73506,0.00000,0.00136,91.57800
24.50000,1.22497,7386.49592,0.00000,0.00137,92.13633
24.60000,1.22999,7428.68111,0.00000,0.00138,92.66253
24.70000,1.23507,7475.57729,0.00000,0.00139,93.24750
24.80000,1.23997,7515.90356,0.00000,0.00139,93.75051
24.90000,1.24500,7563.42858,0.00000,0.00140,94.34332
25.00000,1.24990,7602.42939,0.00000,0.00141,94.82980
25.10000,1.25510,7651.29551,0.00000,0.00142,95.43934
25.20000,1.25994,7690.83425,0.00000,0.00143,95.93253
25.30000,1.26503,7738.84654,0.00000,0.00143,96.53142
25.40000,1.26987,7777.92037,0.00000,0.00145,97.01881
25.50000,1.27507,7825.91179,0.00000,0.00146,97.61744
25.60000,1.27991,7866.21124,0.00000,0.00146,98.12012
25.70000,1.28512,7913.31083,0.00000,0.00147,98.70762
25.80000,1.28990,7956.00638,0.00000,0.00148,99.24019
25.90000,1.29504,8001.30963,0.00000,0.00149,99.80528
26.00000,1.29994,8044.50214,0.00000,0.00149,100.34405
26.10000,1.30503,8089.89629,0.00000,0.00151,100.91028
26.20000,1.30993,8134.07153,0.00000,0.00152,101.46130
26.30000,1.31495,8179.61469,0.00000,0.00152,102.02939
26.40000,1.31991,8224.85387,0.00000,0.00153,102.59369
26.50000,1.32499,8267.06141,0.00000,0.00154,103.12017
26.60000,1.33002,8312.16946,0.00000,0.00155,103.68283
26.70000,1.33504,8356.84240,0.00000,0.00156,104.24006
26.80000,1.34000,8405.64147,0.00000,0.00156,104.84876
26.90000,1.34502,8448.35639,0.00000,0.00158,105.38157
27.00000,1.35005,8494.88452,0.00000,0.00159,105.96195
27.10000,1.35501,8536.15329,0.00000,0.00160,106.47672
27.20000,1.35997,8582.74698,0.00000,0.00160,107.05791
27.30000,1.36499,8626.09223,0.00000,0.00161,107.59858
27.40000,1.37008,8673.81394,0.00000,0.00163,108.19384
27.50000,1.37498,8716.07438,0.00000,0.00163,108.72098
27.60000,1.38006,8763.29690,0.00000,0.00164,109.31002
27.70000,1.38490,8805.71231,0.00000,0.00164,109.83909
27.80000,1.39005,8854.19473,0.00000,0.00165,110.44385
27.90000,1.39495,8896.63175,0.00000,0.00166,110.97319
28.00000,1.40015,8945.33023,0.00000,0.00167,111.58063
28.10000,1.40493,8987.80450,0.00000,0.00169,112.11044
28.20000,1.41002,9037.07072,0.00000,0.00169,112.72497
28.30000,1.41486,9079.74690,0.00000,0.00170,113.25730
28.40000,1.42006,9128.34778,0.00000,0.00172,113.86353
28.50000,1.42490,9171.47771,0.00000,0.00172,114.40151
28.60000,1.43005,9218.60114,0.00000,0.00173,114.98931
28.70000,1.43489,9264.27469,0.00000,0.00174,115.55903
28.80000,1.43997,9310.19410,0.00000,0.00175,116.13181
28.90000,1.44493,9356.84964,0.00000,0.00176,116.71377
29.00000,1.45007,9401.69543,0.00000,0.00177,117.27316
29.10000,1.45492,9447.09256,0.00000,0.00178,117.83943
29.20000,1.46000,9492.43605,0.00000,0.00179,118.40502
29.30000,1.46496,9540.91176,0.00000,0.00180,119.00969
29.40000,1.47004,9584.31736,0.00000,0.00181,119.55112
29.50000,1.47501,9633.57687,0.00000,0.00181,120.16556
29.60000,1.47991,9675.88127,0.00000,0.00183,120.69325
29.70000,1.48499,9725.57515,0.00000,0.00183,121.31311
29.80000,1.48989,9770.02755,0.00000,0.00185,121.86759
29.90000,1.49498,9818.35574,0.00000,0.00185,122.47042
30.00000,1.49988,9861.77921,0.00000,0.00187,123.01207
30.10000,1.50502,9910.59840,0.00000,0.00188,123.62102
30.20000,1.50992,9954.76171,0.00000,0.00188,124.17190
30.30000,1.51507,10004.77597,0.00000,0.00190,124.79576
30.40000,1.51991,10047.05057,0.00000,0.00190,125.32307
30.50000,1.52511,10096.51273,0.00000,0.00191,125.94005
30.60000,1.52989,10141.37492,0.00000,0.00193,126.49964
30.70000,1.53504,10189.36411,0.00000,0.00193,127.09824
30.80000,1.53994,10233.80235,0.00000,0.00195,127.65254
30.90000,1.54502,10279.70016,0.00000,0.00195,128.22506
31.00000,1.54986,10324.64728,0.00000,0.00196,128.78571
31.10000,1.55501,10373.64081,0.00000,0.00197,129.39684
31.20000,1.55997,10420.57127,0.00000,0.00198,129.98223
31.30000,1.56505,10466.56445,0.00000,0.00199,130.55593
31.40000,1.57001,10513.67596,0.00000,0.00200,131.14358
31.50000,1.57497,10559.83752,0.00000,0.00201,131.71938
31.60000,1.57994,10609.19985,0.00000,0.00202,132.33511
31.70000,1.58502,10653.97263,0.00000,0.00203,132.89359
31.80000,1.58998,10702.93188,0.00000,0.00204,133.50429
31.90000,1.59500,10747.38055,0.00000,0.00205,134.05872
32.00000,1.59997,10797.13926,0.00000,0.00206,134.67939
32.10000,1.60493,10841.27799,0.00000,0.00207,135.22996
32.20000,1.61007,10891.90766,0.00000,0.00208,135.86150
32.30000,1.61497,10935.28271,0.00000,0.00209,136.40254
32.40000,1.62012,10985.98093,0.00000,0.00210,137.03493
32.50000,1.62490,11029.35150,0.00000,0.00212,137.57592
32.60000,1.63004,11079.98118,0.00000,0.00212,138.20746
32.70000,1.63488,11123.90012,0.00000,0.00213,138.75528
32.80000,1.64009,11174.29808,0.00000,0.00214,139.38393
32.90000,1.64487,11218.68491,0.00000,0.00215,139.93759
33.00000,1.65001,11269.84283,0.00000,0.00216,140.57572
33.10000,1.65485,11314.96131,0.00000,0.00217,141.13851
33.20000,1.66000,11363.97645,0.00000,0.00218,141.74990
33.30000,1.66496,11410.63869,0.00000,0.00219,142.33195
33.40000,1.67004,11458.80297,0.00000,0.00220,142.93273
33.50000,1.67488,11507.27719,0.00000,0.00221,143.53738
33.60000,1.67997,11555.44445,0.00000,0.00223,144.13820
33.70000,1.68493,11603.40980,0.00000,0.00223,144.73650
33.80000,1.69001,11649.30761,0.00000,0.00225,145.30902
33.90000,1.69491,11697.96959,0.00000,0.00226,145.91601
34.00000,1.69993,11744.67355,0.00000,0.00227,146.49857
34.10000,1.70496,11795.06779,0.00000,0.00227,147.12717
34.20000,1.70998,11838.89508,0.00000,0.00229,147.67386
34.30000,1.71500,11889.22673,0.00000,0.00230,148.30168
34.40000,1.71990,11933.46903,0.00000,0.00231,148.85354
34.50000,1.72499,11985.44577,0.00000,0.00232,149.50188
34.60000,1.72995,12030.43088,0.00000,0.00233,150.06300
34.70000,1.73509,12080.59937,0.00000,0.00234,150.68879
34.80000,1.73987,12123.05948,0.00000,0.00235,151.21842
34.90000,1.74502,12176.31698,0.00000,0.00236,151.88273
35.00000,1.74986,12221.50996,0.00000,0.00238,152.44645
35.10000,1.75500,12270.49977,0.00000,0.00239,153.05753
35.20000,1.75990,12316.07199,0.00000,0.00240,153.62598
35.30000,1.76499,12365.30021,0.00000,0.00241,154.24003
35.40000,1.76983,12413.13666,0.00000,0.00242,154.83673
35.50000,1.77497,12463.21872,0.00000,0.00243,155.46143
35.60000,1.77993,12508.60393,0.00000,0.00244,156.02755
35.70000,1.78508,12556.45603,0.00000,0.00245,156.62444
35.80000,1.78992,12604.73281,0.00000,0.00246,157.22663
35.90000,1.79494,12654.48481,0.00000,0.00248,157.84721
36.00000,1.79996,12701.60526,0.00000,0.00249,158.43498
36.10000,1.80510,12749.14443,0.00000,0.00250,159.02796
36.20000,1.81001,12797.21707,0.00000,0.00251,159.62760
36.30000,1.81503,12844.17212,0.00000,0.00252,160.21330
36.40000,1.81993,12894.93144,0.00000,0.00253,160.84645
36.50000,1.82501,12940.37104,0.00000,0.00254,161.41325
36.60000,1.83004,12991.09459,0.00000,0.00256,162.04596
36.70000,1.83500,13037.08702,0.00000,0.00257,162.61965
36.80000,1.83996,13088.75978,0.00000,0.00258,163.26419
36.90000,1.84492,13134.19789,0.00000,0.00260,163.83097
37.00000,1.85001,13185.34613,0.00000,0.00261,164.46897
37.10000,1.85491,13231.83775,0.00000,0.00262,165.04889
37.20000,1.86005,13282.92191,0.00000,0.00263,165.68610
37.30000,1.86483,13328.60291,0.00000,0.00264,166.25591
37.40000,1.87004,13379.00907,0.00000,0.00265,166.88465
37.50000,1.87488,13424.19237,0.00000,0.00267,167.44825
37.60000,1.88008,13476.64446,0.00000,0.00268,168.10252
37.70000,1.88486,13520.82342,0.00000,0.00269,168.65359
37.80000,1.89007,13574.21428,0.00000,0.00270,169.31957
37.90000,1.89491,13618.08926,0.00000,0.00271,169.86685
38.00000,1.89999,13667.89192,0.00000,0.00273,170.48807
38.10000,1.90489,13713.37920,0.00000,0.00274,171.05546
38.20000,1.90998,13763.96269,0.00000,0.00275,171.68642
38.30000,1.91488,13812.82657,0.00000,0.00277,172.29593
38.40000,1.91996,13863.15376,0.00000,0.00278,172.92369
38.50000,1.92492,13910.12371,0.00000,0.00279,173.50957
38.60000,1.92994,13957.12942,0.00000,0.00280,174.09590
38.70000,1.93491,14007.50875,0.00000,0.00281,174.72432
38.80000,1.93993,14055.09561,0.00000,0.00283,175.31790
38.90000,1.94501,14107.50002,0.00000,0.00284,175.97157
39.00000,1.95003,14150.20376,0.00000,0.00286,176.50424
39.10000,1.95500,14200.96904,0.00000,0.00287,177.13747
39.20000,1.95990,14246.06144,0.00000,0.00288,177.69993
39.30000,1.96504,14298.30343,0.00000,0.00289,178.35158
39.40000,1.96994,14342.90111,0.00000,0.00291,178.90787
39.50000,1.97503,14390.94245,0.00000,0.00292,179.50712
39.60000,1.97987,14435.88734,0.00000,0.00293,180.06775
39.70000,1.98501,14489.39592,0.00000,0.00294,180.73519
39.80000,1.98985,14534.48832,0.00000,0.00295,181.29766
39.90000,1.99512,14585.83325,0.00000,0.00297,181.93812
40.00000,1.99996,14631.50680,0.00000,0.00299,182.50783
40.10000,2.00504,14680.73428,0.00000,0.00301,183.12188
40.20000,2.00994,14728.92165,0.00000,0.00301,183.72295
40.30000,2.01503,14778.15807,0.00000,0.00304,184.33710
40.40000,2.01999,14825.21743,0.00000,0.00305,184.92410
40.50000,2.02507,14873.34967,0.00000,0.00306,185.52449
40.60000,2.02991,14920.14527,0.00000,0.00307,186.10820
40.70000,2.03499,14970.89416,0.00000,0.00309,186.74122
40.80000,2.03996,15017.98332,0.00000,0.00311,187.32859
40.90000,2.04504,15066.65796,0.00000,0.00312,187.93574
41.00000,2.04994,15115.57400,0.00000,0.00314,188.54590
41.10000,2.05502,15162.57674,0.00000,0.00315,189.13219
41.20000,2.05999,15211.81762,0.00000,0.00317,189.74641
41.30000,2.06501,15257.09629,0.00000,0.00318,190.31120
41.40000,2.07003,15306.72312,0.00000,0.00320,190.93022
41.50000,2.07493,15351.52644,0.00000,0.00321,191.48908
41.60000,2.08002,15403.86081,0.00000,0.00323,192.14188
41.70000,2.08492,15447.23958,0.00000,0.00325,192.68297
41.80000,2.09006,15498.05105,0.00000,0.00326,193.31677
41.90000,2.09490,15543.33568,0.00000,0.00328,193.88164
42.00000,2.09999,15593.76270,0.00000,0.00330,194.51064
42.10000,2.10489,15640.03080,0.00000,0.00331,195.08777
42.20000,2.11009,15691.49494,0.00000,0.00333,195.72972
42.30000,2.11493,15735.57109,0.00000,0.00335,196.27951
42.40000,2.12008,15785.44378,0.00000,0.00336,196.90160
42.50000,2.12486,15828.88961,0.00000,0.00339,197.44353
42.60000,2.13000,15878.07834,0.00000,0.00341,198.05709
42.70000,2.13484,15923.75189,0.00000,0.00342,198.62680
42.80000,2.13999,15971.60548,0.00000,0.00344,199.22371
42.90000,2.14489,16018.13138,0.00000,0.00346,199.80406
43.00000,2.14991,16065.04023,0.00000,0.00348,200.38918
43.10000,2.15487,16112.85657,0.00000,0.00350,200.98562
43.20000,2.16001,16159.78330,0.00000,0.00352,201.57097
43.30000,2.16498,16205.07240,0.00000,0.00354,202.13589
43.40000,2.17000,16249.95172,0.00000,0.00356,202.69570
43.50000,2.17496,16297.70249,0.00000,0.00358,203.29132
43.60000,2.17992,16341.36438,0.00000,0.00360,203.83594
43.70000,2.18501,16391.17301,0.00000,0.00362,204.45724
43.80000,2.18997,16434.05408,0.00000,0.00364,204.99212
43.90000,2.19499,16480.44586,0.00000,0.00366,205.57079
44.00000,2.19989,16524.68890,0.00000,0.00369,206.12266
44.10000,2.20504,16574.33510,0.00000,0.00371,206.74193
44.20000,2.20994,16616.98669,0.00000,0.00374,207.27395
44.30000,2.21514,16664.72256,0.00000,0.00377,207.86939
44.40000,2.21986,16705.32525,0.00000,0.00379,208.37585
44.50000,2.22507,16755.17857,0.00000,0.00381,208.99770
44.60000,2.22991,16798.09391,0.00000,0.00384,209.53301
44.70000,2.23511,16843.48285,0.00000,0.00387,210.09918
44.80000,2.23995,16885.47581,0.00000,0.00389,210.62298
44.90000,2.24504,16932.38318,0.00000,0.00392,211.20808
45.00000,2.24994,16974.43128,0.00000,0.00395,211.73258
45.10000,2.25508,17020.36858,0.00000,0.00398,212.30558
45.20000,2.25992,17060.93252,0.00000,0.00401,212.81156
45.30000,2.26506,17105.15022,0.00000,0.00404,213.36311
45.40000,2.26991,17147.70347,0.00000,0.00408,213.89391
45.50000,2.27499,17192.26986,0.00000,0.00412,214.44981
45.60000,2.27995,17233.78748,0.00000,0.00415,214.96769
45.70000,2.28503,17273.97591,0.00000,0.00419,215.46898
45.80000,2.28994,17315.19103,0.00000,0.00423,215.98308
45.90000,2.29502,17355.74305,0.00000,0.00427,216.48891
46.00000,2.29998,17396.72273,0.00000,0.00432,217.00008
46.10000,2.30500,17432.02657,0.00000,0.00436,217.44045
46.20000,2.31003,17472.17625,0.00000,0.00442,217.94126
46.30000,2.31493,17503.39717,0.00000,0.00447,218.33070
46.40000,2.31995,17541.10157,0.00000,0.00453,218.80101
46.50000,2.32491,17569.60452,0.00000,0.00460,219.15654
46.60000,2.33006,17602.30809,0.00000,0.00466,219.56447
46.70000,2.33496,17624.63003,0.00000,0.00475,219.84291
46.80000,2.34004,17653.91231,0.00000,0.00483,220.20816
46.90000,2.34488,17676.47564,0.00000,0.00493,220.48961
47.00000,2.35009,17702.12501,0.00000,0.00503,220.80955
47.10000,2.35487,17719.39099,0.00000,0.00514,221.02492
47.20000,2.36001,17742.35964,0.00000,0.00525,221.31142
47.30000,2.36485,17760.45561,0.00000,0.00536,221.53714
47.40000,2.36994,17781.36939,0.00000,0.00548,221.79801
47.50000,2.37490,17797.27340,0.00000,0.00561,221.99640
47.60000,2.38004,17815.15777,0.00000,0.00574,222.21948
47.70000,2.38494,17829.68789,0.00000,0.00587,222.40072
47.80000,2.38997,17847.62889,0.00000,0.00600,222.62451
47.90000,2.39493,17861.27836,0.00000,0.00614,222.79477
48.00000,2.40001,17873.54499,0.00000,0.00628,222.94778
48.10000,2.40503,17890.37883,0.00000,0.00642,223.15776
48.20000,2.40999,17899.94687,0.00000,0.00656,223.27710
48.30000,2.41502,17915.68249,0.00000,0.00671,223.47338
48.40000,2.41998,17925.78846,0.00000,0.00686,223.59944
48.50000,2.42506,17940.42736,0.00000,0.00701,223.78204
48.60000,2.43002,17949.24736,0.00000,0.00716,223.89206
48.70000,2.43511,17964.06507,0.00000,0.00730,224.07689
48.80000,2.44001,17972.63324,0.00000,0.00746,224.18377
48.90000,2.44509,17986.97859,0.00000,0.00762,224.36271
49.00000,2.44999,17994.63481,0.00000,0.00778,224.45821
49.10000,2.45514,18007.80594,0.00000,0.00793,224.62250
49.20000,2.45998,18015.34295,0.00000,0.00809,224.71651
49.30000,2.46512,18029.24722,0.00000,0.00826,224.88995
49.40000,2.46996,18034.36279,0.00000,0.00842,224.95376
49.50000,2.47511,18046.61602,0.00000,0.00858,225.10660
49.60000,2.47995,18052.76871,0.00000,0.00874,225.18335
49.70000,2.48503,18066.67447,0.00000,0.00890,225.35680
49.80000,2.48999,18073.13412,0.00000,0.00907,225.43738
49.90000,2.49508,18081.96008,0.00000,0.00923,225.54747
50.00000,2.49998,18088.15449,0.00000,0.00940,225.62473
50.10000,2.50506,18097.71657,0.00000,0.00957,225.74401
50.20000,2.50990,18106.52465,0.00000,0.00973,225.85388
50.30000,2.51505,18115.77678,0.00000,0.00990,225.96928
50.40000,2.51995,18120.72843,0.00000,0.01007,226.03105
50.50000,2.52509,18128.31610,0.00000,0.01024,226.12570
50.60000,2.52993,18136.58774,0.00000,0.01041,226.22887
50.70000,2.53495,18144.65076,0.00000,0.01057,226.32945
50.80000,2.53998,18154.45572,0.00000,0.01075,226.45175
50.90000,2.54506,18158.09458,0.00000,0.01092,226.49714
51.00000,2.55002,18164.92975,0.00000,0.01109,226.58240
51.10000,2.55492,18169.29728,0.00000,0.01126,226.63688
51.20000,2.56001,18179.57014,0.00000,0.01144,226.76502
51.30000,2.56491,18183.58302,0.00000,0.01161,226.81507
51.40000,2.57011,18193.10933,0.00000,0.01179,226.93390
51.50000,2.57489,18193.25835,0.00000,0.01196,226.93576
51.60000,2.58004,18203.62657,0.00000,0.01213,227.06509
51.70000,2.58488,18205.64419,0.00000,0.01231,227.09026
51.80000,2.59008,18215.31057,0.00000,0.01248,227.21083
51.90000,2.59498,18217.70221,0.00000,0.01266,227.24066
52.00000,2.60007,18224.44499,0.00000,0.01283,227.32477
52.10000,2.60491,18226.76510,0.00000,0.01301,227.35371
52.20000,2.61005,18235.83990,0.00000,0.01318,227.46691
52.30000,2.61495,18238.51764,0.00000,0.01337,227.50031
52.40000,2.62004,18243.80606,0.00000,0.01354,227.56627
52.50000,2.62500,18246.69987,0.00000,0.01372,227.60237
52.60000,2.63002,18252.23267,0.00000,0.01389,227.67138
52.70000,2.63498,18255.96541,0.00000,0.01407,227.71794
52.80000,2.64006,18259.15873,0.00000,0.01425,227.75778
52.90000,2.64503,18264.08803,0.00000,0.01444,227.81926
53.00000,2.64999,18263.47560,0.00000,0.01462,227.81162
53.10000,2.65501,18271.40003,0.00000,0.01480,227.91047
53.20000,2.66003,18271.02304,0.00000,0.01498,227.90577
53.30000,2.66506,18275.14768,0.00000,0.01517,227.95722
53.40000,2.67002,18273.73058,0.00000,0.01535,227.93954
53.50000,2.67504,18278.14430,0.00000,0.01554,227.99460
53.60000,2.68006,18277.92227,0.00000,0.01573,227.99183
53.70000,2.68509,18280.24983,0.00000,0.01592,228.02086
53.80000,2.68999,18276.47090,0.00000,0.01611,227.97372
53.90000,2.69507,18278.13536,0.00000,0.01630,227.99448
54.00000,2.69985,18271.07221,0.00000,0.01649,227.90638
54.10000,2.70506,18269.41222,0.00000,0.01669,227.88567
54.20000,2.70996,18246.42569,0.00000,0.01690,227.59895
54.30000,2.71516,18211.13974,0.00000,0.01715,227.15881
54.40000,2.71994,18163.97011,0.00000,0.01740,226.57043
54.50000,2.72503,18135.24365,0.00000,0.01764,226.21211
54.60000,2.72993,18109.36183,0.00000,0.01787,225.88927
54.70000,2.73507,18090.62064,0.00000,0.01809,225.65550
54.80000,2.73991,18062.01935,0.00000,0.01832,225.29874
54.90000,2.74505,18036.86917,0.00000,0.01856,224.98502
55.00000,2.74996,18007.96986,0.00000,0.01880,224.62454
55.10000,2.75504,17983.92683,0.00000,0.01903,224.32464
55.20000,2.76000,17961.18915,0.00000,0.01925,224.04102
55.30000,2.76508,17930.03082,0.00000,0.01949,223.65236
55.40000,2.76999,17892.06713,0.00000,0.01974,223.17882
55.50000,2.77501,17848.72264,0.00000,0.01999,222.63815
55.60000,2.78003,17776.25978,0.00000,0.02027,221.73428
55.70000,2.78505,17567.03854,0.00000,0.02073,219.12453
55.80000,2.79008,17456.98750,0.00000,0.02107,217.75180
55.90000,2.79498,17290.43126,0.00000,0.02148,215.67424
56.00000,2.80012,17065.81414,0.00000,0.02199,212.87245
56.10000,2.80502,16923.01184,0.00000,0.02238,211.09119
56.20000,2.81017,16718.69159,0.00000,0.02290,208.54258
56.24600,2.81238,16464.85329,0.00000,0.02341,205.37630
56.26600,2.81339,16208.34917,0.00000,0.02388,202.17676
56.28200,2.81423,15927.18810,0.00000,0.02437,198.66966
56.29800,2.81501,15645.61278,0.00000,0.02485,195.15740
56.31400,2.81591,15387.29966,0.00000,0.02529,191.93530
56.33200,2.81686,15113.79480,0.00000,0.02576,188.52371
56.35600,2.81812,14858.92087,0.00000,0.02621,185.34451
56.39400,2.82015,14608.10453,0.00000,0.02670,182.21592
56.43000,2.82188,14356.44478,0.00000,0.02719,179.07681
56.47000,2.82380,14096.76820,0.00000,0.02768,175.83771
56.49000,2.82475,13839.01536,0.00000,0.02814,172.62260
56.49800,2.82517,13550.49312,0.00000,0.02862,169.02368
56.50200,2.82541,13265.67233,0.00000,0.02905,165.47093
56.50600,2.82565,12759.54694,0.00000,0.02987,159.15772
56.50800,2.82583,12343.62647,0.00000,0.03068,153.96968
56.51000,2.82595,11800.08650,0.00000,0.03189,147.18977
56.51200,2.82619,11163.96040,0.00000,0.03342,139.25498
56.51400,2.82637,10475.67874,0.00000,0.03504,130.66962
56.51600,2.82661,9755.24038,0.00000,0.03652,121.68314
56.51800,2.82685,9011.03467,0.00000,0.03787,112.40021
56.52000,2.82715,8254.57051,0.00000,0.03916,102.96436