File: scratch/college-stuff/ME Lab/ME lab Fall 2013/group11/group11.is_tens_RawData/Specimen_RawData_3.csv
Time,Extension,Load,Strain 2,Tensile strain,Tensile stress
(sec),(mm),(N),(mm/mm),(mm/mm),(MPa)
0.00000,0.00006,-0.03123,0.00000,0.00000,-0.00039
0.10000,0.00155,2.67533,0.00000,0.00000,0.03337
0.20000,0.00717,6.49322,0.00000,0.00001,0.08099
0.30000,0.01351,12.42739,0.00000,0.00001,0.15501
0.40000,0.01937,14.54668,0.00000,0.00002,0.18145
0.50000,0.02469,15.86087,0.00000,0.00001,0.19784
0.60000,0.02995,16.15518,0.00000,0.00002,0.20151
0.70000,0.03498,17.32357,0.00000,0.00002,0.21609
0.80000,0.04006,18.57364,0.00000,0.00002,0.23168
0.90000,0.04502,20.11661,0.00000,0.00002,0.25093
1.00000,0.05004,21.97054,0.00000,0.00002,0.27405
1.10000,0.05501,23.50889,0.00000,0.00002,0.29324
1.20000,0.06003,25.15794,0.00000,0.00001,0.31381
1.30000,0.06505,26.89999,0.00000,0.00001,0.33554
1.40000,0.06995,28.41075,0.00000,0.00002,0.35438
1.50000,0.07504,29.86606,0.00000,0.00001,0.37254
1.60000,0.07994,31.72439,0.00000,0.00001,0.39572
1.70000,0.08514,33.00839,0.00000,0.00001,0.41173
1.80000,0.08998,33.82755,0.00000,0.00001,0.42195
1.90000,0.09513,35.73250,0.00000,0.00001,0.44571
2.00000,0.09997,37.49887,0.00000,0.00001,0.46775
2.10000,0.10511,39.29290,0.00000,0.00001,0.49012
2.20000,0.10995,41.06366,0.00000,0.00001,0.51221
2.30000,0.11509,43.12273,0.00000,0.00001,0.53790
2.40000,0.11988,44.17148,0.00000,0.00000,0.55098
2.50000,0.12502,45.19890,0.00000,0.00000,0.56379
2.60000,0.12998,46.26035,0.00000,0.00000,0.57703
2.70000,0.13512,47.65197,0.00000,0.00000,0.59439
2.80000,0.13997,50.06916,0.00000,0.00000,0.62454
2.90000,0.14505,52.28638,0.00000,0.00000,0.65220
3.00000,0.14995,54.87748,0.00000,0.00000,0.68452
3.10000,0.15503,56.62854,0.00000,-0.00001,0.70636
3.20000,0.16000,58.73780,0.00000,-0.00001,0.73267
3.30000,0.16496,61.29488,0.00000,-0.00001,0.76457
3.40000,0.16998,64.93052,0.00000,-0.00001,0.80992
3.50000,0.17494,69.10193,0.00000,-0.00001,0.86195
3.60000,0.18009,72.70875,0.00000,-0.00001,0.90694
3.70000,0.18499,74.52318,0.00000,-0.00002,0.92957
3.80000,0.19007,77.43948,0.00000,-0.00002,0.96595
3.90000,0.19491,80.26476,0.00000,-0.00002,1.00119
4.00000,0.20012,84.62464,0.00000,-0.00003,1.05558
4.10000,0.20496,88.26865,0.00000,-0.00003,1.10103
4.20000,0.21010,94.38607,0.00000,-0.00003,1.17734
4.30000,0.21494,99.98429,0.00000,-0.00003,1.24717
4.40000,0.22009,106.61180,0.00000,-0.00003,1.32983
4.50000,0.22493,113.36952,0.00000,-0.00002,1.41413
4.60000,0.23013,120.76523,0.00000,-0.00002,1.50638
4.70000,0.23497,128.37340,0.00000,-0.00002,1.60128
4.80000,0.24000,138.87563,0.00000,-0.00002,1.73228
4.90000,0.24496,148.21525,0.00000,-0.00002,1.84878
5.00000,0.25004,160.63619,0.00000,-0.00002,2.00371
5.10000,0.25500,175.57499,0.00000,-0.00002,2.19006
5.20000,0.26002,190.78901,0.00000,-0.00001,2.37983
5.30000,0.26499,210.76663,0.00000,-0.00001,2.62902
5.40000,0.27001,231.28365,0.00000,0.00000,2.88494
5.50000,0.27497,254.25078,0.00000,0.00001,3.17143
5.60000,0.28005,275.65272,0.00000,0.00001,3.43839
5.70000,0.28502,299.83534,0.00000,0.00003,3.74003
5.80000,0.28998,322.12529,0.00000,0.00003,4.01807
5.90000,0.29500,345.02016,0.00000,0.00004,4.30365
6.00000,0.29996,369.65320,0.00000,0.00005,4.61091
6.10000,0.30511,400.69744,0.00000,0.00007,4.99815
6.20000,0.30995,430.86545,0.00000,0.00008,5.37445
6.30000,0.31503,463.61163,0.00000,0.00009,5.78291
6.40000,0.31987,497.62866,0.00000,0.00011,6.20723
6.50000,0.32514,534.68533,0.00000,0.00013,6.66946
6.60000,0.32992,570.74632,0.00000,0.00015,7.11927
6.70000,0.33506,610.70160,0.00000,0.00017,7.61766
6.80000,0.33990,650.54731,0.00000,0.00019,8.11468
6.90000,0.34505,691.83530,0.00000,0.00021,8.62969
7.00000,0.34995,731.71682,0.00000,0.00023,9.12716
7.10000,0.35503,773.24230,0.00000,0.00026,9.64513
7.20000,0.35993,816.54703,0.00000,0.00028,10.18530
7.30000,0.36496,860.45293,0.00000,0.00030,10.73296
7.40000,0.36992,902.84217,0.00000,0.00032,11.26171
7.50000,0.37506,936.79540,0.00000,0.00034,11.68523
7.60000,0.37996,978.76191,0.00000,0.00036,12.20870
7.70000,0.38492,1022.21798,0.00000,0.00039,12.75076
7.80000,0.38995,1067.95356,0.00000,0.00041,13.32125
7.90000,0.39491,1110.88511,0.00000,0.00044,13.85676
8.00000,0.39999,1156.39511,0.00000,0.00046,14.42443
8.10000,0.40495,1199.15251,0.00000,0.00049,14.95777
8.20000,0.40998,1243.91261,0.00000,0.00051,15.51609
8.30000,0.41494,1286.95117,0.00000,0.00053,16.05294
8.40000,0.42008,1331.14653,0.00000,0.00056,16.60421
8.50000,0.42492,1371.14804,0.00000,0.00058,17.10318
8.60000,0.43007,1416.65684,0.00000,0.00061,17.67084
8.70000,0.43491,1459.58634,0.00000,0.00063,18.20632
8.80000,0.43999,1504.04703,0.00000,0.00066,18.76091
8.90000,0.44489,1545.12608,0.00000,0.00068,19.27331
9.00000,0.45004,1589.87865,0.00000,0.00071,19.83154
9.10000,0.45488,1632.28400,0.00000,0.00073,20.36049
9.20000,0.46002,1676.41155,0.00000,0.00076,20.91092
9.30000,0.46492,1718.74743,0.00000,0.00078,21.43900
9.40000,0.47006,1762.57025,0.00000,0.00080,21.98563
9.50000,0.47497,1803.88633,0.00000,0.00083,22.50099
9.60000,0.47999,1846.73537,0.00000,0.00086,23.03547
9.70000,0.48489,1888.91850,0.00000,0.00088,23.56165
9.80000,0.49003,1930.72725,0.00000,0.00090,24.08315
9.90000,0.49494,1972.52147,0.00000,0.00093,24.60448
10.00000,0.49996,2014.53902,0.00000,0.00095,25.12859
10.10000,0.50492,2057.18782,0.00000,0.00098,25.66058
10.20000,0.50994,2096.79920,0.00000,0.00100,26.15467
10.30000,0.51503,2139.67469,0.00000,0.00102,26.68949
10.40000,0.52005,2179.93148,0.00000,0.00105,27.19163
10.50000,0.52501,2222.39569,0.00000,0.00107,27.72132
10.60000,0.52991,2261.94672,0.00000,0.00110,28.21466
10.70000,0.53500,2304.46532,0.00000,0.00112,28.74502
10.80000,0.53996,2342.40405,0.00000,0.00114,29.21825
10.90000,0.54504,2384.33126,0.00000,0.00117,29.74124
11.00000,0.54988,2421.03264,0.00000,0.00119,30.19904
11.10000,0.55503,2462.79929,0.00000,0.00121,30.72002
11.20000,0.55987,2500.76707,0.00000,0.00123,31.19361
11.30000,0.56507,2541.77786,0.00000,0.00126,31.70517
11.40000,0.56991,2580.24465,0.00000,0.00128,32.18499
11.50000,0.57506,2620.21832,0.00000,0.00130,32.68360
11.60000,0.57990,2657.70294,0.00000,0.00133,33.15117
11.70000,0.58504,2696.08367,0.00000,0.00134,33.62992
11.80000,0.58988,2734.08219,0.00000,0.00137,34.10390
11.90000,0.59503,2772.90493,0.00000,0.00139,34.58816
12.00000,0.59987,2810.72315,0.00000,0.00141,35.05989
12.10000,0.60495,2847.77116,0.00000,0.00143,35.52201
12.20000,0.60991,2886.35213,0.00000,0.00145,36.00325
12.30000,0.61499,2922.91399,0.00000,0.00147,36.45931
12.40000,0.61990,2961.58958,0.00000,0.00149,36.94174
12.50000,0.62498,2998.03186,0.00000,0.00152,37.39631
12.60000,0.63000,3035.90894,0.00000,0.00154,37.86877
12.70000,0.63502,3070.35185,0.00000,0.00156,38.29840
12.80000,0.64005,3108.40085,0.00000,0.00158,38.77301
12.90000,0.64495,3141.75524,0.00000,0.00160,39.18906
13.00000,0.65003,3180.34925,0.00000,0.00162,39.67046
13.10000,0.65493,3214.22033,0.00000,0.00164,40.09296
13.20000,0.66008,3249.56179,0.00000,0.00166,40.53379
13.30000,0.66492,3282.57084,0.00000,0.00168,40.94554
13.40000,0.67006,3318.47444,0.00000,0.00170,41.39338
13.50000,0.67490,3351.34752,0.00000,0.00172,41.80343
13.60000,0.68011,3386.62341,0.00000,0.00174,42.24345
13.70000,0.68501,3418.83712,0.00000,0.00177,42.64527
13.80000,0.69009,3453.18913,0.00000,0.00179,43.07376
13.90000,0.69493,3485.74668,0.00000,0.00180,43.47987
14.00000,0.70008,3519.05786,0.00000,0.00182,43.89538
14.10000,0.70498,3551.18327,0.00000,0.00184,44.29610
14.20000,0.71012,3584.21132,0.00000,0.00186,44.70808
14.30000,0.71490,3615.55256,0.00000,0.00188,45.09902
14.40000,0.72004,3647.76477,0.00000,0.00190,45.50083
14.50000,0.72495,3677.12602,0.00000,0.00192,45.86707
14.60000,0.73009,3707.58064,0.00000,0.00194,46.24695
14.70000,0.73499,3735.90216,0.00000,0.00196,46.60022
14.80000,0.74007,3762.95559,0.00000,0.00197,46.93767
14.90000,0.74498,3790.53354,0.00000,0.00199,47.28167
15.00000,0.75006,3813.87323,0.00000,0.00201,47.57280
15.10000,0.75502,3839.94319,0.00000,0.00202,47.89799
15.20000,0.75998,3862.21968,0.00000,0.00203,48.17585
15.30000,0.76501,3887.38066,0.00000,0.00205,48.48970
15.40000,0.76991,3909.68509,0.00000,0.00206,48.76792
15.50000,0.77499,3936.08138,0.00000,0.00208,49.09718
15.60000,0.77995,3959.28659,0.00000,0.00209,49.38663
15.70000,0.78504,3987.08098,0.00000,0.00211,49.73333
15.80000,0.78994,4012.51353,0.00000,0.00212,50.05056
15.90000,0.79508,4040.50425,0.00000,0.00214,50.39971
16.00000,0.79992,4066.51348,0.00000,0.00216,50.72414
16.10000,0.80513,4094.45688,0.00000,0.00217,51.07269
16.20000,0.80985,4119.89987,0.00000,0.00218,51.39006
16.30000,0.81505,4149.64929,0.00000,0.00221,51.76114
16.40000,0.81989,4176.69453,0.00000,0.00222,52.09849
16.50000,0.82504,4205.80655,0.00000,0.00223,52.46163
16.60000,0.82988,4232.12312,0.00000,0.00225,52.78989
16.70000,0.83502,4259.88212,0.00000,0.00227,53.13614
16.80000,0.83986,4287.44107,0.00000,0.00229,53.47990
16.90000,0.84500,4315.39230,0.00000,0.00230,53.82856
17.00000,0.84997,4342.20694,0.00000,0.00232,54.16303
17.10000,0.85505,4370.62122,0.00000,0.00234,54.51746
17.20000,0.86001,4398.15968,0.00000,0.00235,54.86097
17.30000,0.86497,4425.12892,0.00000,0.00237,55.19737
17.40000,0.87006,4455.04114,0.00000,0.00238,55.57048
17.50000,0.87502,4480.57652,0.00000,0.00240,55.88900
17.60000,0.88004,4510.16054,0.00000,0.00242,56.25802
17.70000,0.88494,4535.33120,0.00000,0.00244,56.57199
17.80000,0.89003,4564.48980,0.00000,0.00246,56.93570
17.90000,0.89493,4590.34070,0.00000,0.00247,57.25816
18.00000,0.90013,4619.29403,0.00000,0.00249,57.61931
18.10000,0.90497,4644.51052,0.00000,0.00250,57.93385
18.20000,0.91012,4674.26032,0.00000,0.00252,58.30494
18.30000,0.91496,4699.55057,0.00000,0.00254,58.62040
18.40000,0.92010,4728.13472,0.00000,0.00255,58.97695
18.50000,0.92500,4753.94130,0.00000,0.00257,59.29885
18.60000,0.93009,4783.45044,0.00000,0.00259,59.66693
18.70000,0.93493,4809.64109,0.00000,0.00260,59.99363
18.80000,0.94001,4837.45672,0.00000,0.00262,60.34059
18.90000,0.94491,4864.08919,0.00000,0.00265,60.67279
19.00000,0.95006,4890.49554,0.00000,0.00266,61.00217
19.10000,0.95490,4917.54822,0.00000,0.00267,61.33962
19.20000,0.95998,4945.66858,0.00000,0.00269,61.69038
19.30000,0.96494,4973.43205,0.00000,0.00271,62.03669
19.40000,0.97002,5000.69596,0.00000,0.00272,62.37677
19.50000,0.97493,5027.61230,0.00000,0.00274,62.71252
19.60000,0.98001,5055.71924,0.00000,0.00276,63.06311
19.70000,0.98491,5084.51723,0.00000,0.00278,63.42233
19.80000,0.98999,5109.85032,0.00000,0.00280,63.73832
19.90000,0.99508,5138.69040,0.00000,0.00281,64.09806
20.00000,0.99998,5163.77911,0.00000,0.00283,64.41101
20.10000,1.00500,5193.33519,0.00000,0.00284,64.77968
20.20000,1.00996,5217.67847,0.00000,0.00286,65.08333
20.30000,1.01505,5246.59455,0.00000,0.00288,65.44402
20.40000,1.01995,5271.67320,0.00000,0.00290,65.75684
20.50000,1.02503,5300.10872,0.00000,0.00291,66.11153
20.60000,1.02987,5326.40330,0.00000,0.00293,66.43952
20.70000,1.03508,5355.26052,0.00000,0.00295,66.79948
20.80000,1.03992,5380.18160,0.00000,0.00296,67.11033
20.90000,1.04506,5409.20757,0.00000,0.00298,67.47239
21.00000,1.04990,5435.60237,0.00000,0.00300,67.80163
21.10000,1.05505,5464.31169,0.00000,0.00301,68.15974
21.20000,1.05989,5489.13442,0.00000,0.00303,68.46937
21.30000,1.06503,5516.07981,0.00000,0.00305,68.80547
21.40000,1.06999,5542.44928,0.00000,0.00307,69.13440
21.50000,1.07502,5569.82569,0.00000,0.00309,69.47588
21.60000,1.07992,5597.23005,0.00000,0.00310,69.81771
21.70000,1.08500,5623.56412,0.00000,0.00312,70.14619
21.80000,1.09002,5651.63903,0.00000,0.00313,70.49639
21.90000,1.09498,5676.72402,0.00000,0.00315,70.80929
22.00000,1.09995,5704.35487,0.00000,0.00317,71.15395
22.10000,1.10497,5729.96214,0.00000,0.00319,71.47336
22.20000,1.10999,5756.14013,0.00000,0.00321,71.79989
22.30000,1.11501,5781.17035,0.00000,0.00322,72.11211
22.40000,1.12010,5809.43152,0.00000,0.00324,72.46463
22.50000,1.12500,5835.11218,0.00000,0.00326,72.78496
22.60000,1.13008,5863.24632,0.00000,0.00327,73.13590
22.70000,1.13498,5887.19696,0.00000,0.00329,73.43465
22.80000,1.14013,5913.49006,0.00000,0.00331,73.76262
22.90000,1.14497,5939.39014,0.00000,0.00332,74.08569
23.00000,1.15005,5967.41587,0.00000,0.00334,74.43527
23.10000,1.15489,5992.37233,0.00000,0.00336,74.74657
23.20000,1.16010,6019.47084,0.00000,0.00338,75.08458
23.30000,1.16494,6045.01031,0.00000,0.00339,75.40315
23.40000,1.17008,6072.63148,0.00000,0.00341,75.74769
23.50000,1.17498,6097.78948,0.00000,0.00342,76.06150
23.60000,1.18012,6124.01702,0.00000,0.00345,76.38865
23.70000,1.18497,6147.72774,0.00000,0.00346,76.68441
23.80000,1.19011,6174.82476,0.00000,0.00347,77.02241
23.90000,1.19489,6200.18020,0.00000,0.00349,77.33868
24.00000,1.20003,6227.58903,0.00000,0.00351,77.68057
24.10000,1.20494,6253.10093,0.00000,0.00353,77.99879
24.20000,1.21008,6279.46854,0.00000,0.00355,78.32769
24.30000,1.21498,6305.30566,0.00000,0.00357,78.64998
24.40000,1.21994,6329.71749,0.00000,0.00358,78.95448
24.50000,1.22497,6355.97259,0.00000,0.00360,79.28198
24.60000,1.22999,6380.76738,0.00000,0.00362,79.59126
24.70000,1.23507,6407.69079,0.00000,0.00363,79.92709
24.80000,1.23997,6431.51999,0.00000,0.00365,80.22433
24.90000,1.24500,6459.42166,0.00000,0.00366,80.57236
25.00000,1.24990,6482.18393,0.00000,0.00368,80.85629
25.10000,1.25510,6510.39556,0.00000,0.00371,81.20819
25.20000,1.25994,6532.51410,0.00000,0.00372,81.48409
25.30000,1.26503,6559.90019,0.00000,0.00374,81.82569
25.40000,1.26987,6582.13198,0.00000,0.00375,82.10300
25.50000,1.27507,6608.69107,0.00000,0.00377,82.43429
25.60000,1.27991,6630.37077,0.00000,0.00378,82.70471
25.70000,1.28512,6656.62512,0.00000,0.00380,83.03220
25.80000,1.28996,6679.83741,0.00000,0.00382,83.32174
25.90000,1.29504,6704.72980,0.00000,0.00383,83.63224
26.00000,1.29994,6729.08947,0.00000,0.00385,83.93609
26.10000,1.30503,6751.83162,0.00000,0.00386,84.21977
26.20000,1.30993,6775.99683,0.00000,0.00388,84.52120
26.30000,1.31501,6800.57183,0.00000,0.00390,84.82774
26.40000,1.31991,6825.12820,0.00000,0.00392,85.13404
26.50000,1.32499,6849.07362,0.00000,0.00393,85.43273
26.60000,1.33002,6873.45639,0.00000,0.00395,85.73687
26.70000,1.33504,6895.54736,0.00000,0.00396,86.01243
26.80000,1.34000,6920.77801,0.00000,0.00398,86.32714
26.90000,1.34502,6941.91754,0.00000,0.00400,86.59083
27.00000,1.35005,6966.71978,0.00000,0.00401,86.90020
27.10000,1.35501,6988.52167,0.00000,0.00403,87.17215
27.20000,1.36003,7013.29336,0.00000,0.00405,87.48114
27.30000,1.36499,7037.12478,0.00000,0.00406,87.77841
27.40000,1.37008,7062.18779,0.00000,0.00408,88.09103
27.50000,1.37498,7084.75634,0.00000,0.00410,88.37255
27.60000,1.38012,7110.22839,0.00000,0.00411,88.69027
27.70000,1.38490,7132.90051,0.00000,0.00412,88.97308
27.80000,1.39005,7159.33517,0.00000,0.00415,89.30281
27.90000,1.39495,7181.48798,0.00000,0.00416,89.57914
28.00000,1.40015,7208.49112,0.00000,0.00418,89.91597
28.10000,1.40493,7231.07308,0.00000,0.00419,90.19765
28.20000,1.41002,7258.33848,0.00000,0.00422,90.53774
28.30000,1.41492,7281.61186,0.00000,0.00423,90.82805
28.40000,1.42006,7308.29164,0.00000,0.00424,91.16084
28.50000,1.42496,7332.06198,0.00000,0.00426,91.45734
28.60000,1.43005,7356.74798,0.00000,0.00428,91.76527
28.70000,1.43489,7381.81844,0.00000,0.00430,92.07799
28.80000,1.43997,7405.85700,0.00000,0.00432,92.37783
28.90000,1.44493,7431.36108,0.00000,0.00433,92.69596
29.00000,1.45007,7456.14171,0.00000,0.00435,93.00507
29.10000,1.45498,7482.00491,0.00000,0.00436,93.32767
29.20000,1.46000,7505.49659,0.00000,0.00438,93.62070
29.30000,1.46496,7530.77865,0.00000,0.00440,93.93606
29.40000,1.47004,7554.26884,0.00000,0.00442,94.22907
29.50000,1.47507,7579.37133,0.00000,0.00444,94.54218
29.60000,1.47997,7602.89356,0.00000,0.00445,94.83559
29.70000,1.48499,7628.69269,0.00000,0.00447,95.15740
29.80000,1.48989,7652.62619,0.00000,0.00449,95.45594
29.90000,1.49504,7678.63616,0.00000,0.00450,95.78038
30.00000,1.49988,7702.64715,0.00000,0.00453,96.07988
30.10000,1.50502,7729.24200,0.00000,0.00455,96.41161
30.20000,1.50992,7752.29037,0.00000,0.00456,96.69911
30.30000,1.51513,7778.58198,0.00000,0.00458,97.02706
30.40000,1.51991,7800.92701,0.00000,0.00459,97.30579
30.50000,1.52511,7827.02118,0.00000,0.00462,97.63127
30.60000,1.52989,7851.87408,0.00000,0.00462,97.94128
30.70000,1.53504,7876.85886,0.00000,0.00465,98.25293
30.80000,1.53994,7901.56201,0.00000,0.00467,98.56107
30.90000,1.54502,7925.88145,0.00000,0.00469,98.86442
31.00000,1.54986,7949.13992,0.00000,0.00470,99.15454
31.10000,1.55501,7975.35032,0.00000,0.00472,99.48148
31.20000,1.55997,7998.77197,0.00000,0.00474,99.77363
31.30000,1.56505,8023.86105,0.00000,0.00475,100.08658
31.40000,1.57007,8049.58344,0.00000,0.00477,100.40743
31.50000,1.57503,8073.59815,0.00000,0.00479,100.70698
31.60000,1.58000,8100.58117,0.00000,0.00481,101.04356
31.70000,1.58502,8123.83071,0.00000,0.00483,101.33356
31.80000,1.59004,8150.73997,0.00000,0.00484,101.66922
31.90000,1.59500,8174.50210,0.00000,0.00486,101.96562
32.00000,1.59997,8200.81010,0.00000,0.00488,102.29377
32.10000,1.60493,8224.69443,0.00000,0.00489,102.59170
32.20000,1.61007,8251.19168,0.00000,0.00492,102.92222
32.30000,1.61503,8273.54416,0.00000,0.00493,103.20103
32.40000,1.62012,8300.55326,0.00000,0.00495,103.53793
32.50000,1.62496,8323.27902,0.00000,0.00497,103.82141
32.60000,1.63004,8350.22256,0.00000,0.00499,104.15749
32.70000,1.63494,8373.54586,0.00000,0.00501,104.44841
32.80000,1.64015,8400.11239,0.00000,0.00502,104.77980
32.90000,1.64493,8423.32169,0.00000,0.00505,105.06930
33.00000,1.65001,8450.58262,0.00000,0.00506,105.40934
33.10000,1.65485,8474.77168,0.00000,0.00508,105.71107
33.20000,1.66006,8501.12215,0.00000,0.00510,106.03975
33.30000,1.66496,8525.81859,0.00000,0.00511,106.34781
33.40000,1.67004,8550.45766,0.00000,0.00514,106.65515
33.50000,1.67488,8576.06679,0.00000,0.00516,106.97458
33.60000,1.68003,8601.29073,0.00000,0.00519,107.28922
33.70000,1.68493,8627.18076,0.00000,0.00520,107.61216
33.80000,1.69001,8650.34461,0.00000,0.00521,107.90110
33.90000,1.69491,8677.33285,0.00000,0.00524,108.23774
34.00000,1.69993,8702.17532,0.00000,0.00524,108.54761
34.10000,1.70496,8728.47587,0.00000,0.00527,108.87568
34.20000,1.70998,8752.37063,0.00000,0.00529,109.17373
34.30000,1.71500,8778.63020,0.00000,0.00531,109.50128
34.40000,1.71990,8801.09817,0.00000,0.00533,109.78154
34.50000,1.72499,8828.09460,0.00000,0.00534,110.11828
34.60000,1.72995,8851.34116,0.00000,0.00536,110.40825
34.70000,1.73509,8877.88013,0.00000,0.00538,110.73929
34.80000,1.73987,8900.30563,0.00000,0.00540,111.01902
34.90000,1.74502,8928.51055,0.00000,0.00542,111.37083
35.00000,1.74986,8952.54016,0.00000,0.00544,111.67057
35.10000,1.75500,8978.48159,0.00000,0.00546,111.99415
35.20000,1.75990,9002.76154,0.00000,0.00547,112.29701
35.30000,1.76505,9028.22688,0.00000,0.00549,112.61466
35.40000,1.76989,9053.18707,0.00000,0.00552,112.92600
35.50000,1.77497,9079.61056,0.00000,0.00552,113.25560
35.60000,1.77993,9103.44645,0.00000,0.00556,113.55292
35.70000,1.78508,9129.79767,0.00000,0.00557,113.88161
35.80000,1.78998,9154.64759,0.00000,0.00560,114.19158
35.90000,1.79500,9179.80969,0.00000,0.00561,114.50544
36.00000,1.79996,9204.45919,0.00000,0.00562,114.81291
36.10000,1.80510,9229.68164,0.00000,0.00565,115.12753
36.20000,1.81001,9254.41682,0.00000,0.00566,115.43606
36.30000,1.81503,9280.28226,0.00000,0.00568,115.75870
36.40000,1.81999,9307.05965,0.00000,0.00571,116.09271
36.50000,1.82501,9330.30173,0.00000,0.00572,116.38262
36.60000,1.83004,9357.24378,0.00000,0.00575,116.71869
36.70000,1.83500,9380.30258,0.00000,0.00577,117.00631
36.80000,1.84002,9407.85110,0.00000,0.00578,117.34994
36.90000,1.84492,9431.85687,0.00000,0.00580,117.64938
37.00000,1.85001,9458.98145,0.00000,0.00581,117.98772
37.10000,1.85497,9483.35305,0.00000,0.00584,118.29173
37.20000,1.86005,9510.27274,0.00000,0.00586,118.62751
37.30000,1.86489,9535.25454,0.00000,0.00587,118.93913
37.40000,1.87004,9562.57209,0.00000,0.00589,119.27987
37.50000,1.87488,9586.52273,0.00000,0.00591,119.57863
37.60000,1.88008,9613.10193,0.00000,0.00594,119.91016
37.70000,1.88486,9637.04959,0.00000,0.00595,120.20888
37.80000,1.89007,9664.55117,0.00000,0.00597,120.55192
37.90000,1.89491,9688.32001,0.00000,0.00599,120.84841
38.00000,1.89999,9713.01347,0.00000,0.00601,121.15642
38.10000,1.90489,9737.67638,0.00000,0.00603,121.46406
38.20000,1.90998,9763.98289,0.00000,0.00605,121.79220
38.30000,1.91488,9789.16436,0.00000,0.00607,122.10630
38.40000,1.91996,9815.04694,0.00000,0.00609,122.42915
38.50000,1.92492,9839.94901,0.00000,0.00611,122.73977
38.60000,1.92994,9864.89952,0.00000,0.00614,123.05099
38.70000,1.93491,9891.78121,0.00000,0.00616,123.38630
38.80000,1.93993,9917.12213,0.00000,0.00618,123.70240
38.90000,1.94501,9945.68542,0.00000,0.00619,124.05868
39.00000,1.95003,9968.26664,0.00000,0.00621,124.34035
39.10000,1.95506,9994.58954,0.00000,0.00623,124.66869
39.20000,1.95990,10018.16764,0.00000,0.00625,124.96280
39.30000,1.96504,10045.10000,0.00000,0.00627,125.29874
39.40000,1.96994,10068.02246,0.00000,0.00630,125.58467
39.50000,1.97503,10094.58378,0.00000,0.00631,125.91598
39.60000,1.97987,10118.27365,0.00000,0.00633,126.21148
39.70000,1.98501,10146.57095,0.00000,0.00635,126.56445
39.80000,1.98985,10170.64750,0.00000,0.00637,126.86477
39.90000,1.99512,10198.38080,0.00000,0.00639,127.21071
40.00000,2.00002,10221.94698,0.00000,0.00641,127.50466
40.10000,2.00510,10247.87873,0.00000,0.00643,127.82813
40.20000,2.00994,10272.78826,0.00000,0.00645,128.13884
40.30000,2.01503,10299.12829,0.00000,0.00647,128.46740
40.40000,2.01999,10325.00565,0.00000,0.00649,128.79018
40.50000,2.02507,10350.50154,0.00000,0.00651,129.10821
40.60000,2.02991,10376.34015,0.00000,0.00653,129.43051
40.70000,2.03499,10402.65858,0.00000,0.00655,129.75879
40.80000,2.03990,10427.59344,0.00000,0.00657,130.06982
40.90000,2.04504,10453.54307,0.00000,0.00659,130.39351
41.00000,2.05000,10478.82959,0.00000,0.00661,130.70892
41.10000,2.05502,10504.35007,0.00000,0.00663,131.02725
41.20000,2.05999,10531.39344,0.00000,0.00665,131.36458
41.30000,2.06501,10555.10417,0.00000,0.00668,131.66034
41.40000,2.07003,10581.27433,0.00000,0.00669,131.98678
41.50000,2.07499,10605.40378,0.00000,0.00671,132.28776
41.60000,2.08002,10633.77112,0.00000,0.00673,132.64160
41.70000,2.08492,10656.12808,0.00000,0.00675,132.92047
41.80000,2.09006,10683.87479,0.00000,0.00677,133.26658
41.90000,2.09496,10708.31567,0.00000,0.00679,133.57144
42.00000,2.10005,10735.09529,0.00000,0.00682,133.90548
42.10000,2.10489,10761.39361,0.00000,0.00684,134.23352
42.20000,2.11009,10789.36011,0.00000,0.00686,134.58236
42.30000,2.11493,10812.59102,0.00000,0.00688,134.87213
42.40000,2.12008,10839.00258,0.00000,0.00689,135.20158
42.50000,2.12486,10864.12519,0.00000,0.00692,135.51495
42.60000,2.13000,10890.73196,0.00000,0.00694,135.84683
42.70000,2.13484,10914.50304,0.00000,0.00696,136.14334
42.80000,2.13999,10941.33109,0.00000,0.00698,136.47799
42.90000,2.14489,10966.90893,0.00000,0.00700,136.79704
43.00000,2.14997,10994.14378,0.00000,0.00702,137.13675
43.10000,2.15487,11019.37443,0.00000,0.00704,137.45147
43.20000,2.16001,11044.69672,0.00000,0.00706,137.76733
43.30000,2.16504,11070.04955,0.00000,0.00708,138.08357
43.40000,2.17000,11093.95400,0.00000,0.00710,138.38175
43.50000,2.17496,11120.12565,0.00000,0.00712,138.70820
43.60000,2.17992,11143.87214,0.00000,0.00714,139.00441
43.70000,2.18501,11171.91091,0.00000,0.00717,139.35415
43.80000,2.18997,11197.02831,0.00000,0.00718,139.66746
43.90000,2.19499,11223.58143,0.00000,0.00721,139.99867
44.00000,2.19989,11248.46190,0.00000,0.00723,140.30902
44.10000,2.20504,11276.34048,0.00000,0.00725,140.65677
44.20000,2.20994,11299.32478,0.00000,0.00727,140.94346
44.30000,2.21514,11327.17207,0.00000,0.00729,141.29082
44.40000,2.21992,11351.05044,0.00000,0.00731,141.58867
44.50000,2.22507,11378.57735,0.00000,0.00733,141.93203
44.60000,2.22991,11403.64259,0.00000,0.00735,142.24468
44.70000,2.23511,11430.77165,0.00000,0.00737,142.58308
44.80000,2.23995,11454.88247,0.00000,0.00739,142.88383
44.90000,2.24510,11481.74256,0.00000,0.00741,143.21887
45.00000,2.24994,11505.75802,0.00000,0.00743,143.51843
45.10000,2.25502,11532.92209,0.00000,0.00746,143.85727
45.20000,2.25992,11557.54998,0.00000,0.00747,144.16447
45.30000,2.26506,11584.85785,0.00000,0.00750,144.50509
45.40000,2.26997,11610.15630,0.00000,0.00752,144.82066
45.50000,2.27505,11637.33378,0.00000,0.00754,145.15966
45.60000,2.27995,11662.66650,0.00000,0.00757,145.47565
45.70000,2.28503,11687.93514,0.00000,0.00758,145.79084
45.80000,2.28994,11714.11648,0.00000,0.00760,146.11742
45.90000,2.29502,11740.61671,0.00000,0.00763,146.44797
46.00000,2.29992,11768.36714,0.00000,0.00765,146.79412
46.10000,2.30494,11792.83410,0.00000,0.00766,147.09931
46.20000,2.31003,11820.85723,0.00000,0.00769,147.44886
46.30000,2.31493,11843.71486,0.00000,0.00771,147.73398
46.40000,2.31995,11872.60449,0.00000,0.00774,148.09434
46.50000,2.32491,11895.67223,0.00000,0.00776,148.38207
46.60000,2.33006,11923.37796,0.00000,0.00778,148.72767
46.70000,2.33496,11946.15662,0.00000,0.00780,149.01180
46.80000,2.34004,11973.05992,0.00000,0.00782,149.34738
46.90000,2.34488,11997.76456,0.00000,0.00784,149.65554
47.00000,2.35009,12025.16407,0.00000,0.00786,149.99731
47.10000,2.35487,12048.97091,0.00000,0.00788,150.29426
47.20000,2.36007,12075.58140,0.00000,0.00790,150.62619
47.30000,2.36485,12100.80981,0.00000,0.00792,150.94088
47.40000,2.36994,12127.20796,0.00000,0.00794,151.27016
47.50000,2.37484,12152.46245,0.00000,0.00796,151.58518
47.60000,2.38004,12178.29883,0.00000,0.00799,151.90745
47.70000,2.38494,12204.40492,0.00000,0.00801,152.23309
47.80000,2.39003,12231.11302,0.00000,0.00803,152.56624
47.90000,2.39493,12257.37110,0.00000,0.00804,152.89377
48.00000,2.39995,12281.29715,0.00000,0.00807,153.19221
48.10000,2.40503,12309.13252,0.00000,0.00810,153.53942
48.20000,2.40999,12333.41321,0.00000,0.00811,153.84229
48.30000,2.41502,12360.46404,0.00000,0.00813,154.17971
48.40000,2.41998,12384.76560,0.00000,0.00815,154.48284
48.50000,2.42506,12412.25079,0.00000,0.00817,154.82568
48.60000,2.43002,12436.24091,0.00000,0.00820,155.12492
48.70000,2.43511,12463.19264,0.00000,0.00823,155.46111
48.80000,2.44001,12488.63414,0.00000,0.00824,155.77846
48.90000,2.44509,12515.93083,0.00000,0.00827,156.11894
49.00000,2.44999,12539.07830,0.00000,0.00829,156.40768
49.10000,2.45514,12566.61415,0.00000,0.00831,156.75115
49.20000,2.45998,12591.97593,0.00000,0.00833,157.06750
49.30000,2.46512,12619.76063,0.00000,0.00835,157.41408
49.40000,2.46996,12644.15681,0.00000,0.00837,157.71839
49.50000,2.47511,12671.93705,0.00000,0.00840,158.06491
49.60000,2.47995,12696.89947,0.00000,0.00842,158.37628
49.70000,2.48503,12723.98680,0.00000,0.00844,158.71415
49.80000,2.48993,12749.43501,0.00000,0.00846,159.03159
49.90000,2.49508,12776.30478,0.00000,0.00848,159.36675
50.00000,2.49998,12800.66371,0.00000,0.00850,159.67059
50.10000,2.50506,12826.64537,0.00000,0.00853,159.99468
50.20000,2.50990,12853.02192,0.00000,0.00854,160.32369
50.30000,2.51505,12879.04978,0.00000,0.00857,160.64835
50.40000,2.51995,12905.53212,0.00000,0.00859,160.97868
50.50000,2.52503,12930.58842,0.00000,0.00861,161.29122
50.60000,2.52993,12956.18415,0.00000,0.00863,161.61050
50.70000,2.53495,12981.59361,0.00000,0.00866,161.92744
50.80000,2.53998,13010.36328,0.00000,0.00868,162.28631
50.90000,2.54500,13034.01291,0.00000,0.00870,162.58130
51.00000,2.55002,13060.94378,0.00000,0.00872,162.91723
51.10000,2.55492,13084.56957,0.00000,0.00874,163.21193
51.20000,2.56001,13111.56005,0.00000,0.00877,163.54860
51.30000,2.56491,13136.82646,0.00000,0.00878,163.86376
51.40000,2.57011,13163.86312,0.00000,0.00880,164.20100
51.50000,2.57489,13187.46954,0.00000,0.00883,164.49546
51.60000,2.58004,13215.24978,0.00000,0.00886,164.84198
51.70000,2.58488,13239.51483,0.00000,0.00887,165.14465
51.80000,2.59008,13268.20403,0.00000,0.00890,165.50251
51.90000,2.59492,13292.16659,0.00000,0.00892,165.80141
52.00000,2.60007,13318.61466,0.00000,0.00894,166.13132
52.10000,2.60491,13343.00339,0.00000,0.00896,166.43553
52.20000,2.61005,13368.01350,0.00000,0.00898,166.74750
52.30000,2.61495,13393.29332,0.00000,0.00901,167.06283
52.40000,2.62004,13419.51042,0.00000,0.00902,167.38985
52.50000,2.62500,13445.37586,0.00000,0.00905,167.71249
52.60000,2.63002,13471.57508,0.00000,0.00907,168.03929
52.70000,2.63498,13497.90394,0.00000,0.00909,168.36770
52.80000,2.64000,13522.93640,0.00000,0.00910,168.67995
52.90000,2.64503,13549.81959,0.00000,0.00913,169.01528
53.00000,2.64999,13574.55552,0.00000,0.00915,169.32382
53.10000,2.65501,13602.00793,0.00000,0.00918,169.66625
53.20000,2.66003,13625.97644,0.00000,0.00920,169.96523
53.30000,2.66506,13654.70886,0.00000,0.00922,170.32363
53.40000,2.67008,13677.51658,0.00000,0.00924,170.60812
53.50000,2.67504,13704.87213,0.00000,0.00926,170.94934
53.60000,2.68000,13730.06999,0.00000,0.00928,171.26365
53.70000,2.68509,13756.10083,0.00000,0.00931,171.58835
53.80000,2.68999,13780.59238,0.00000,0.00933,171.89385
53.90000,2.69507,13807.63650,0.00000,0.00935,172.23119
54.00000,2.69985,13830.66475,0.00000,0.00937,172.51843
54.10000,2.70506,13859.45529,0.00000,0.00939,172.87756
54.20000,2.70996,13883.81124,0.00000,0.00941,173.18136
54.30000,2.71510,13910.95668,0.00000,0.00944,173.51996
54.40000,2.71994,13934.84771,0.00000,0.00946,173.81797
54.50000,2.72503,13962.20624,0.00000,0.00949,174.15923
54.60000,2.72987,13986.92429,0.00000,0.00950,174.46755
54.70000,2.73507,14013.39024,0.00000,0.00953,174.79768
54.80000,2.73991,14038.47188,0.00000,0.00955,175.11054
54.90000,2.74500,14064.79180,0.00000,0.00957,175.43884
55.00000,2.74996,14091.27414,0.00000,0.00960,175.76917
55.10000,2.75498,14116.85348,0.00000,0.00961,176.08824
55.20000,2.76000,14143.87524,0.00000,0.00964,176.42530
55.30000,2.76502,14168.35040,0.00000,0.00967,176.73059
55.40000,2.76999,14195.16057,0.00000,0.00969,177.06501
55.50000,2.77501,14219.41221,0.00000,0.00970,177.36752
55.60000,2.77997,14246.31923,0.00000,0.00973,177.70315
55.70000,2.78499,14270.71542,0.00000,0.00974,178.00746
55.80000,2.79008,14297.41681,0.00000,0.00977,178.34052
55.90000,2.79492,14321.54179,0.00000,0.00980,178.64145
56.00000,2.80000,14348.25659,0.00000,0.00982,178.97468
56.10000,2.80490,14372.24001,0.00000,0.00984,179.27384
56.20000,2.81005,14399.48678,0.00000,0.00987,179.61370
56.30000,2.81489,14423.51788,0.00000,0.00988,179.91346
56.40000,2.82003,14450.72293,0.00000,0.00991,180.25280
56.50000,2.82487,14476.47363,0.00000,0.00992,180.57401
56.60000,2.83002,14502.34205,0.00000,0.00994,180.89668
56.70000,2.83492,14527.41772,0.00000,0.00996,181.20946
56.80000,2.84000,14552.83165,0.00000,0.00998,181.52647
56.90000,2.84484,14577.33810,0.00000,0.01002,181.83215
57.00000,2.84993,14603.25122,0.00000,0.01003,182.15538
57.10000,2.85489,14628.61151,0.00000,0.01006,182.47172
57.20000,2.85997,14654.52313,0.00000,0.01008,182.79493
57.30000,2.86493,14680.16356,0.00000,0.01011,183.11476
57.40000,2.87002,14705.84124,0.00000,0.01013,183.43505
57.50000,2.87498,14731.98682,0.00000,0.01015,183.76118
57.60000,2.88006,14757.29793,0.00000,0.01017,184.07690
57.70000,2.88502,14782.11433,0.00000,0.01019,184.38645
57.80000,2.88999,14807.95890,0.00000,0.01021,184.70883
57.90000,2.89501,14834.57983,0.00000,0.01024,185.04089
58.00000,2.90003,14859.29340,0.00000,0.01026,185.34915
58.10000,2.90505,14885.70422,0.00000,0.01029,185.67859
58.20000,2.91001,14910.87675,0.00000,0.01030,185.99259
58.30000,2.91498,14938.53480,0.00000,0.01033,186.33758
58.40000,2.91988,14962.30811,0.00000,0.01034,186.63412
58.50000,2.92502,14990.06599,0.00000,0.01038,186.98036
58.60000,2.92998,15014.48005,0.00000,0.01039,187.28489
58.70000,2.93507,15041.80282,0.00000,0.01042,187.62571
58.80000,2.93991,15065.70429,0.00000,0.01044,187.92384
58.90000,2.94511,15094.26236,0.00000,0.01047,188.28007
59.00000,2.94995,15117.75255,0.00000,0.01049,188.57307
59.10000,2.95516,15146.07668,0.00000,0.01051,188.92638
59.20000,2.95994,15169.47597,0.00000,0.01053,189.21825
59.30000,2.96508,15196.41876,0.00000,0.01056,189.55433
59.40000,2.96992,15221.69858,0.00000,0.01058,189.86966
59.50000,2.97507,15247.05440,0.00000,0.01060,190.18594
59.60000,2.97997,15272.20011,0.00000,0.01062,190.49959
59.70000,2.98505,15298.69884,0.00000,0.01065,190.83013
59.80000,2.98989,15324.92638,0.00000,0.01066,191.15728
59.90000,2.99498,15350.21514,0.00000,0.01069,191.47272
60.00000,2.99994,15376.04183,0.00000,0.01072,191.79488
60.10000,3.00502,15400.71815,0.00000,0.01073,192.10268
60.20000,3.00998,15427.68329,0.00000,0.01076,192.43903
60.30000,3.01494,15450.75625,0.00000,0.01078,192.72684
60.40000,3.02003,15479.61384,0.00000,0.01080,193.08679
60.50000,3.02499,15503.42739,0.00000,0.01082,193.38384
60.60000,3.03001,15530.20626,0.00000,0.01085,193.71787
60.70000,3.03485,15554.36552,0.00000,0.01087,194.01922
60.80000,3.04006,15581.70468,0.00000,0.01089,194.36024
60.90000,3.04496,15605.86691,0.00000,0.01091,194.66163
61.00000,3.05010,15632.85589,0.00000,0.01094,194.99828
61.10000,3.05494,15656.35353,0.00000,0.01096,195.29138
61.20000,3.06009,15683.99072,0.00000,0.01098,195.63611
61.30000,3.06499,15708.64320,0.00000,0.01100,195.94362
61.40000,3.07007,15735.92573,0.00000,0.01103,196.28393
61.50000,3.07491,15760.40983,0.00000,0.01105,196.58934
61.60000,3.07994,15786.65078,0.00000,0.01107,196.91666
61.70000,3.08484,15812.51919,0.00000,0.01109,197.23933
61.80000,3.08998,15838.15068,0.00000,0.01112,197.55905
61.90000,3.09494,15863.43944,0.00000,0.01114,197.87449
62.00000,3.10009,15888.55535,0.00000,0.01117,198.18777
62.10000,3.10499,15914.99001,0.00000,0.01120,198.51751
62.20000,3.11001,15941.26523,0.00000,0.01121,198.84526
62.30000,3.11497,15967.27371,0.00000,0.01124,199.16968
62.40000,3.12005,15992.65188,0.00000,0.01125,199.48624
62.50000,3.12496,16018.16416,0.00000,0.01128,199.80447
62.60000,3.12998,16042.81813,0.00000,0.01130,200.11199
62.70000,3.13494,16071.16312,0.00000,0.01132,200.46555
62.80000,3.14002,16094.17498,0.00000,0.01134,200.75260
62.90000,3.14511,16121.60057,0.00000,0.01137,201.09469
63.00000,3.15001,16144.78230,0.00000,0.01139,201.38385
63.10000,3.15503,16173.29568,0.00000,0.01142,201.73952
63.20000,3.15993,16196.97958,0.00000,0.01143,202.03494
63.30000,3.16508,16224.08628,0.00000,0.01146,202.37306
63.40000,3.16992,16247.24269,0.00000,0.01148,202.66190
63.50000,3.17500,16273.82338,0.00000,0.01150,202.99346
63.60000,3.17984,16299.95555,0.00000,0.01153,203.31942
63.70000,3.18505,16328.00847,0.00000,0.01155,203.66935
63.80000,3.18995,16352.08428,0.00000,0.01158,203.96966
63.90000,3.19509,16377.31791,0.00000,0.01160,204.28441
64.00000,3.19987,16401.38626,0.00000,0.01162,204.58463
64.10000,3.20502,16428.10851,0.00000,0.01165,204.91795
64.20000,3.20992,16452.97706,0.00000,0.01166,205.22816
64.30000,3.21506,16478.73521,0.00000,0.01169,205.54945
64.40000,3.21990,16503.16268,0.00000,0.01172,205.85415
64.50000,3.22499,16529.20693,0.00000,0.01173,206.17902
64.60000,3.22989,16554.25131,0.00000,0.01176,206.49141
64.70000,3.23497,16579.14519,0.00000,0.01178,206.80193
64.80000,3.23999,16606.00603,0.00000,0.01180,207.13698
64.90000,3.24495,16629.75401,0.00000,0.01182,207.43320
65.00000,3.24992,16656.11863,0.00000,0.01185,207.76207
65.10000,3.25494,16679.62819,0.00000,0.01187,208.05532
65.20000,3.26002,16708.13709,0.00000,0.01189,208.41092
65.30000,3.26498,16731.29946,0.00000,0.01191,208.69984
65.40000,3.27001,16757.47931,0.00000,0.01193,209.02640
65.50000,3.27485,16781.66240,0.00000,0.01196,209.32805
65.60000,3.28005,16809.09991,0.00000,0.01198,209.67030
65.70000,3.28495,16833.20403,0.00000,0.01200,209.97096
65.80000,3.29010,16860.31371,0.00000,0.01203,210.30912
65.90000,3.29488,16883.48949,0.00000,0.01205,210.59820
66.00000,3.30002,16911.27568,0.00000,0.01207,210.94480
66.10000,3.30492,16935.89389,0.00000,0.01210,211.25188
66.20000,3.31013,16962.54760,0.00000,0.01212,211.58434
66.30000,3.31497,16986.82606,0.00000,0.01214,211.88718
66.40000,3.32005,17012.09992,0.00000,0.01217,212.20244
66.50000,3.32495,17037.46170,0.00000,0.01218,212.51879
66.60000,3.33004,17062.30193,0.00000,0.01221,212.82864
66.70000,3.33500,17087.28373,0.00000,0.01224,213.14025
66.80000,3.34002,17112.76621,0.00000,0.01226,213.45811
66.90000,3.34486,17137.94768,0.00000,0.01228,213.77222
67.00000,3.35001,17164.91431,0.00000,0.01231,214.10859
67.10000,3.35497,17191.61123,0.00000,0.01233,214.44160
67.20000,3.36005,17216.29798,0.00000,0.01235,214.74953
67.30000,3.36495,17241.65082,0.00000,0.01238,215.06577
67.40000,3.36997,17265.94716,0.00000,0.01240,215.36883
67.50000,3.37506,17292.74690,0.00000,0.01242,215.70312
67.60000,3.38002,17316.41591,0.00000,0.01245,215.99836
67.70000,3.38504,17343.11432,0.00000,0.01246,216.33139
67.80000,3.38994,17366.15598,0.00000,0.01249,216.61880
67.90000,3.39503,17393.60243,0.00000,0.01252,216.96116
68.00000,3.39993,17417.33849,0.00000,0.01253,217.25723
68.10000,3.40507,17444.71043,0.00000,0.01256,217.59866
68.20000,3.40991,17467.55242,0.00000,0.01258,217.88358
68.30000,3.41506,17494.16590,0.00000,0.01261,218.21555
68.40000,3.41990,17517.94964,0.00000,0.01263,218.51222
68.50000,3.42510,17545.15469,0.00000,0.01265,218.85156
68.60000,3.42994,17568.76707,0.00000,0.01267,219.14609
68.70000,3.43509,17595.29114,0.00000,0.01270,219.47695
68.80000,3.43987,17618.76196,0.00000,0.01272,219.76971
68.90000,3.44495,17645.24132,0.00000,0.01275,220.10000
69.00000,3.44985,17670.32892,0.00000,0.01276,220.41294
69.10000,3.45500,17695.67281,0.00000,0.01279,220.72907
69.20000,3.45990,17720.11071,0.00000,0.01281,221.03390
69.30000,3.46492,17745.28027,0.00000,0.01283,221.34785
69.40000,3.46988,17771.44074,0.00000,0.01286,221.67417
69.50000,3.47497,17796.16624,0.00000,0.01288,221.98258
69.60000,3.48005,17823.16118,0.00000,0.01291,222.31931
69.70000,3.48501,17846.38017,0.00000,0.01293,222.60893
69.80000,3.48997,17872.44678,0.00000,0.01295,222.93408
69.90000,3.49493,17895.04886,0.00000,0.01298,223.21601
70.00000,3.50008,17922.24050,0.00000,0.01300,223.55519
70.10000,3.50498,17946.11216,0.00000,0.01302,223.85295
70.20000,3.51000,17971.81964,0.00000,0.01304,224.17362
70.30000,3.51490,17996.42891,0.00000,0.01306,224.48058
70.40000,3.52005,18023.41640,0.00000,0.01309,224.81722
70.50000,3.52495,18047.89305,0.00000,0.01311,225.12253
70.60000,3.53015,18074.04906,0.00000,0.01314,225.44879
70.70000,3.53493,18098.12635,0.00000,0.01316,225.74912
70.80000,3.54008,18125.14812,0.00000,0.01319,226.08618
70.90000,3.54498,18149.30737,0.00000,0.01321,226.38753
71.00000,3.55012,18175.42017,0.00000,0.01324,226.71325
71.10000,3.55496,18199.50491,0.00000,0.01325,227.01368
71.20000,3.56005,18226.14670,0.00000,0.01328,227.34600
71.30000,3.56489,18250.73808,0.00000,0.01330,227.65274
71.40000,3.57003,18276.47239,0.00000,0.01333,227.97374
71.50000,3.57499,18301.40799,0.00000,0.01335,228.28478
71.60000,3.58007,18326.49559,0.00000,0.01337,228.59771
71.70000,3.58492,18351.11380,0.00000,0.01340,228.90479
71.80000,3.59006,18376.56051,0.00000,0.01342,229.22220
71.90000,3.59496,18402.78804,0.00000,0.01345,229.54935
72.00000,3.60004,18427.48672,0.00000,0.01346,229.85744
72.10000,3.60489,18452.35080,0.00000,0.01349,230.16758
72.20000,3.60991,18476.68588,0.00000,0.01351,230.47113
72.30000,3.61493,18504.04888,0.00000,0.01354,230.81244
72.40000,3.61995,18527.20827,0.00000,0.01356,231.10132
72.50000,3.62504,18555.28057,0.00000,0.01359,231.45149
72.60000,3.62988,18576.84702,0.00000,0.01361,231.72050
72.70000,3.63496,18605.34251,0.00000,0.01363,232.07594
72.80000,3.63992,18629.21417,0.00000,0.01365,232.37371
72.90000,3.64513,18655.13474,0.00000,0.01368,232.69703
73.00000,3.64991,18677.51926,0.00000,0.01370,232.97625
73.10000,3.65505,18704.24747,0.00000,0.01373,233.30964
73.20000,3.65983,18726.69458,0.00000,0.01375,233.58964
73.30000,3.66510,18753.25739,0.00000,0.01377,233.92097
73.40000,3.66994,18776.29012,0.00000,0.01379,234.20828
73.50000,3.67502,18801.53865,0.00000,0.01381,234.52322
73.60000,3.67986,18825.97506,0.00000,0.01384,234.82803
73.70000,3.68501,18851.55439,0.00000,0.01386,235.14709
73.80000,3.68991,18876.26946,0.00000,0.01388,235.45538
73.90000,3.69505,18900.28268,0.00000,0.01391,235.75491
74.00000,3.69995,18924.73102,0.00000,0.01393,236.05987
74.10000,3.70498,18947.70563,0.00000,0.01395,236.34645
74.20000,3.70994,18974.22671,0.00000,0.01397,236.67726
74.30000,3.71502,18996.78856,0.00000,0.01400,236.95869
74.40000,3.72010,19024.27524,0.00000,0.01402,237.30155
74.50000,3.72495,19046.04286,0.00000,0.01405,237.57307
74.60000,3.72997,19073.78882,0.00000,0.01407,237.91916
74.70000,3.73499,19097.82290,0.00000,0.01409,238.21895
74.80000,3.74007,19124.10557,0.00000,0.01411,238.54679
74.90000,3.74503,19146.72554,0.00000,0.01414,238.82895
75.00000,3.75006,19172.20354,0.00000,0.01416,239.14675
75.10000,3.75496,19195.35547,0.00000,0.01418,239.43554
75.20000,3.76016,19222.53221,0.00000,0.01421,239.77453
75.30000,3.76506,19246.51116,0.00000,0.01423,240.07363
75.40000,3.77015,19271.43037,0.00000,0.01425,240.38447
75.50000,3.77493,19293.18756,0.00000,0.01428,240.65586
75.60000,3.78007,19320.62805,0.00000,0.01430,240.99814
75.70000,3.78491,19342.49252,0.00000,0.01433,241.27087
75.80000,3.79006,19369.80784,0.00000,0.01435,241.61159
75.90000,3.79484,19392.03888,0.00000,0.01438,241.88889
76.00000,3.79998,19418.29473,0.00000,0.01440,242.21640
76.10000,3.80488,19443.69823,0.00000,0.01442,242.53327
76.20000,3.81009,19469.17325,0.00000,0.01445,242.85104
76.30000,3.81505,19494.07905,0.00000,0.01447,243.16170
76.40000,3.82001,19518.05353,0.00000,0.01450,243.46075
76.50000,3.82491,19541.99076,0.00000,0.01452,243.75933
76.60000,3.83006,19567.49409,0.00000,0.01454,244.07745
76.70000,3.83496,19592.06313,0.00000,0.01457,244.38392
76.80000,3.84004,19615.72319,0.00000,0.01459,244.67904
76.90000,3.84494,19642.33071,0.00000,0.01461,245.01094
77.00000,3.84996,19665.24869,0.00000,0.01464,245.29681
77.10000,3.85499,19690.97257,0.00000,0.01466,245.61768
77.20000,3.86001,19714.38378,0.00000,0.01468,245.90970
77.30000,3.86503,19740.09871,0.00000,0.01471,246.23046
77.40000,3.86993,19761.66517,0.00000,0.01473,246.49947
77.50000,3.87502,19787.73624,0.00000,0.01475,246.82467
77.60000,3.87992,19812.63608,0.00000,0.01478,247.13526
77.70000,3.88512,19838.48512,0.00000,0.01481,247.45769
77.80000,3.88990,19861.51040,0.00000,0.01483,247.74490
77.90000,3.89505,19886.32232,0.00000,0.01485,248.05439
78.00000,3.89983,19909.43253,0.00000,0.01487,248.34266
78.10000,3.90503,19935.80163,0.00000,0.01490,248.67158
78.20000,3.90993,19960.03389,0.00000,0.01492,248.97384
78.30000,3.91502,19983.63286,0.00000,0.01495,249.26821
78.40000,3.91992,20007.43896,0.00000,0.01497,249.56516
78.50000,3.92506,20033.44297,0.00000,0.01499,249.88952
78.60000,3.92996,20056.89889,0.00000,0.01501,250.18210
78.70000,3.93505,20081.25633,0.00000,0.01504,250.48593
78.80000,3.93995,20104.85232,0.00000,0.01506,250.78025
78.90000,3.94497,20127.77030,0.00000,0.01509,251.06612
79.00000,3.94999,20153.93823,0.00000,0.01511,251.39253
79.10000,3.95507,20177.23918,0.00000,0.01514,251.68318
79.20000,3.96004,20203.65298,0.00000,0.01516,252.01266
79.30000,3.96500,20226.23569,0.00000,0.01518,252.29434
79.40000,3.97002,20253.75366,0.00000,0.01521,252.63759
79.50000,3.97504,20277.08292,0.00000,0.01523,252.92859
79.60000,3.98013,20303.15548,0.00000,0.01526,253.25381
79.70000,3.98503,20324.51481,0.00000,0.01528,253.52024
79.80000,3.99005,20349.19113,0.00000,0.01531,253.82804
79.90000,3.99495,20372.56211,0.00000,0.01533,254.11956
80.00000,4.00010,20398.32771,0.00000,0.01535,254.44095
80.10000,4.00500,20419.99251,0.00000,0.01537,254.71119
80.20000,4.01014,20445.69403,0.00000,0.01540,255.03178
80.30000,4.01492,20468.71036,0.00000,0.01542,255.31888
80.40000,4.02013,20494.96621,0.00000,0.01545,255.64639
80.50000,4.02497,20517.26729,0.00000,0.01547,255.92456
80.60000,4.03011,20542.98967,0.00000,0.01550,256.24541
80.70000,4.03489,20564.66341,0.00000,0.01552,256.51576
80.80000,4.04004,20589.17582,0.00000,0.01554,256.82152
80.90000,4.04488,20612.83886,0.00000,0.01557,257.11668
81.00000,4.05008,20636.79546,0.00000,0.01559,257.41551
81.10000,4.05498,20657.52745,0.00000,0.01561,257.67411
81.20000,4.06001,20677.57547,0.00000,0.01563,257.92418
81.30000,4.06491,20700.31166,0.00000,0.01565,258.20779
81.40000,4.06999,20723.14322,0.00000,0.01568,258.49258
81.50000,4.07495,20746.47695,0.00000,0.01570,258.78363
81.60000,4.08003,20766.26122,0.00000,0.01572,259.03042
81.70000,4.08494,20787.73975,0.00000,0.01574,259.29833
81.80000,4.08996,20782.67336,0.00000,0.01574,259.23513
81.80600,4.09026,20268.87536,0.00000,0.01572,252.82621
81.80800,4.09044,19656.43167,0.00000,0.01580,245.18683
81.81000,4.09068,18846.46118,0.00000,0.01604,235.08356
81.81200,4.09086,17904.03873,0.00000,0.01649,223.32815
81.81400,4.09122,16855.23391,0.00000,0.01708,210.24575
81.81600,4.09151,15727.69135,0.00000,0.01771,196.18122
81.81800,4.09187,14560.62943,0.00000,0.01829,181.62373
81.82000,4.09223,13378.92115,0.00000,0.01882,166.88356
81.82200,4.09259,12192.91762,0.00000,0.01930,152.08980