File: scratch/college-stuff/ME Lab/ME lab Fall 2013/group11/group11.is_tens_RawData/Specimen_RawData_5.csv
Time,Extension,Load,Strain 2,Tensile strain,Tensile stress
(sec),(mm),(N),(mm/mm),(mm/mm),(MPa)
0.00000,0.00000,0.02542,0.00000,0.00000,0.00032
0.30000,0.01357,9.79586,0.00000,0.00000,0.12219
0.60000,0.02995,22.19123,0.00000,0.00000,0.27680
0.90000,0.04502,41.95716,0.00000,0.00000,0.52336
1.20000,0.05997,64.87106,0.00000,-0.00001,0.80918
1.50000,0.07504,92.45781,0.00000,-0.00001,1.15328
1.80000,0.08998,111.54932,0.00000,-0.00002,1.39142
2.10000,0.10511,135.47344,0.00000,-0.00003,1.68984
2.40000,0.11988,170.52772,0.00000,-0.00003,2.12710
2.70000,0.13512,211.08806,0.00000,-0.00004,2.63303
3.00000,0.14995,263.18030,0.00000,-0.00004,3.28281
3.30000,0.16496,326.88733,0.00000,-0.00004,4.07747
3.60000,0.18003,407.51891,0.00000,-0.00004,5.08324
3.90000,0.19491,501.96084,0.00000,-0.00003,6.26127
4.20000,0.21010,616.80302,0.00000,-0.00003,7.69377
4.50000,0.22493,740.53472,0.00000,-0.00002,9.23715
4.80000,0.24000,869.28718,0.00000,-0.00001,10.84316
5.10000,0.25500,1003.47521,0.00000,0.00000,12.51697
5.40000,0.27001,1165.74029,0.00000,0.00001,14.54100
5.70000,0.28496,1349.79859,0.00000,0.00003,16.83687
6.00000,0.29996,1539.80684,0.00000,0.00006,19.20696
6.30000,0.31503,1737.59833,0.00000,0.00009,21.67414
6.60000,0.32986,1928.45594,0.00000,0.00011,24.05482
6.90000,0.34505,2123.75596,0.00000,0.00014,26.49092
7.20000,0.35993,2314.47369,0.00000,0.00017,28.86986
7.50000,0.37506,2501.83977,0.00000,0.00020,31.20699
7.80000,0.38995,2687.36538,0.00000,0.00022,33.52117
8.10000,0.40495,2865.17870,0.00000,0.00025,35.73915
8.40000,0.42008,3042.21027,0.00000,0.00028,37.94737
8.70000,0.43491,3211.48038,0.00000,0.00031,40.05878
9.00000,0.45004,3380.06206,0.00000,0.00033,42.16160
9.30000,0.46492,3536.76677,0.00000,0.00036,44.11628
9.60000,0.47999,3688.74557,0.00000,0.00038,46.01200
9.90000,0.49494,3826.24939,0.00000,0.00040,47.72717
10.20000,0.50994,3962.94557,0.00000,0.00043,49.43227
10.50000,0.52501,4099.80714,0.00000,0.00045,51.13943
10.80000,0.53996,4222.00263,0.00000,0.00047,52.66365
11.10000,0.55503,4348.76792,0.00000,0.00049,54.24487
11.40000,0.56991,4465.57403,0.00000,0.00051,55.70187
11.70000,0.58504,4584.29977,0.00000,0.00053,57.18281
12.00000,0.59981,4698.54921,0.00000,0.00055,58.60791
12.30000,0.61499,4815.63695,0.00000,0.00056,60.06842
12.60000,0.63000,4935.48959,0.00000,0.00058,61.56341
12.90000,0.64495,5052.83922,0.00000,0.00061,63.02719
13.20000,0.66008,5174.63125,0.00000,0.00062,64.54638
13.50000,0.67490,5293.41139,0.00000,0.00065,66.02799
13.80000,0.69009,5419.51209,0.00000,0.00067,67.60093
14.10000,0.70498,5539.93024,0.00000,0.00069,69.10298
14.40000,0.72004,5666.51039,0.00000,0.00071,70.68189
14.70000,0.73499,5789.13167,0.00000,0.00073,72.21142
15.00000,0.75000,5915.90293,0.00000,0.00075,73.79272
15.30000,0.76495,6043.91620,0.00000,0.00077,75.38950
15.60000,0.77995,6168.25707,0.00000,0.00079,76.94048
15.90000,0.79508,6300.85766,0.00000,0.00081,78.59449
16.20000,0.80985,6425.94323,0.00000,0.00083,80.15476
16.50000,0.82509,6558.30652,0.00000,0.00085,81.80581
16.80000,0.83986,6686.71206,0.00000,0.00088,83.40749
17.10000,0.85505,6819.17593,0.00000,0.00090,85.05980
17.40000,0.87000,6951.17787,0.00000,0.00092,86.70634
17.70000,0.88494,7082.36843,0.00000,0.00094,88.34276
18.00000,0.90013,7216.74934,0.00000,0.00097,90.01898
18.30000,0.91496,7346.28066,0.00000,0.00099,91.63470
18.60000,0.93003,7483.93908,0.00000,0.00101,93.35180
18.90000,0.94491,7615.92016,0.00000,0.00103,94.99808
19.20000,0.95998,7753.44372,0.00000,0.00106,96.71350
19.50000,0.97493,7889.21341,0.00000,0.00108,98.40704
19.80000,0.98999,8025.99266,0.00000,0.00110,100.11317
20.10000,1.00500,8166.31690,0.00000,0.00113,101.86352
20.40000,1.01995,8299.94604,0.00000,0.00115,103.53036
20.70000,1.03502,8441.68290,0.00000,0.00118,105.29833
21.00000,1.04990,8578.07919,0.00000,0.00121,106.99969
21.30000,1.06503,8720.17816,0.00000,0.00123,108.77217
21.60000,1.07992,8858.99290,0.00000,0.00125,110.50370
21.90000,1.09498,8997.33230,0.00000,0.00128,112.22929
22.20000,1.10999,9138.09687,0.00000,0.00131,113.98513
22.50000,1.12500,9278.31531,0.00000,0.00133,115.73416
22.80000,1.14007,9420.43215,0.00000,0.00136,117.50687
23.10000,1.15495,9561.37255,0.00000,0.00138,119.26491
23.40000,1.17008,9706.71922,0.00000,0.00141,121.07791
23.70000,1.18497,9845.90575,0.00000,0.00143,122.81407
24.00000,1.20003,9991.01996,0.00000,0.00146,124.62417
24.30000,1.21492,10136.24817,0.00000,0.00149,126.43569
24.60000,1.22999,10278.98714,0.00000,0.00151,128.21616
24.90000,1.24500,10428.34967,0.00000,0.00154,130.07925
25.20000,1.25994,10568.02273,0.00000,0.00156,131.82148
25.50000,1.27507,10715.54422,0.00000,0.00159,133.66161
25.80000,1.28990,10857.49716,0.00000,0.00161,135.43228
26.10000,1.30503,11004.27732,0.00000,0.00164,137.26315
26.40000,1.31991,11153.12278,0.00000,0.00167,139.11980
26.70000,1.33498,11297.35708,0.00000,0.00170,140.91892
27.00000,1.35005,11446.28674,0.00000,0.00173,142.77661
27.30000,1.36499,11590.68644,0.00000,0.00175,144.57780
27.60000,1.38006,11739.14224,0.00000,0.00178,146.42958
27.90000,1.39495,11884.49487,0.00000,0.00180,148.24265
28.20000,1.41002,12037.99620,0.00000,0.00183,150.15737
28.50000,1.42490,12183.69231,0.00000,0.00186,151.97473
28.80000,1.44003,12333.85950,0.00000,0.00189,153.84786
29.10000,1.45492,12483.98647,0.00000,0.00192,155.72048
29.40000,1.47004,12632.36403,0.00000,0.00195,157.57129
29.70000,1.48499,12783.99378,0.00000,0.00197,159.46266
30.00000,1.49988,12931.84310,0.00000,0.00200,161.30687
30.30000,1.51513,13086.11333,0.00000,0.00203,163.23118
30.60000,1.52989,13232.94044,0.00000,0.00206,165.06265
30.90000,1.54502,13381.70171,0.00000,0.00209,166.91824
31.20000,1.55991,13533.47003,0.00000,0.00212,168.81134
31.50000,1.57497,13682.29538,0.00000,0.00215,170.66773
31.80000,1.59004,13837.28981,0.00000,0.00218,172.60107
32.10000,1.60493,13986.32526,0.00000,0.00220,174.46008
32.40000,1.62012,14139.59712,0.00000,0.00223,176.37194
32.70000,1.63494,14287.97096,0.00000,0.00226,178.22270
33.00000,1.65001,14443.91906,0.00000,0.00230,180.16793
33.30000,1.66490,14594.16002,0.00000,0.00233,182.04198
33.60000,1.68003,14748.69549,0.00000,0.00236,183.96960
33.90000,1.69491,14900.87062,0.00000,0.00239,185.86777
34.20000,1.70998,15050.31884,0.00000,0.00242,187.73193
34.50000,1.72499,15206.10601,0.00000,0.00245,189.67516
34.80000,1.73987,15353.31011,0.00000,0.00248,191.51133
35.10000,1.75500,15509.25523,0.00000,0.00251,193.45653
35.40000,1.76983,15660.27105,0.00000,0.00254,195.34024
35.70000,1.78508,15814.33564,0.00000,0.00257,197.26199
36.00000,1.79996,15967.33332,0.00000,0.00261,199.17042
36.30000,1.81503,16119.18211,0.00000,0.00264,201.06452
36.60000,1.83004,16274.38217,0.00000,0.00267,203.00043
36.90000,1.84492,16425.60959,0.00000,0.00270,204.88678
37.20000,1.86005,16583.57680,0.00000,0.00274,206.85721
37.50000,1.87488,16733.95038,0.00000,0.00277,208.73291
37.80000,1.89001,16892.04872,0.00000,0.00280,210.70497
38.10000,1.90489,17039.40481,0.00000,0.00284,212.54303
38.40000,1.91996,17196.79534,0.00000,0.00287,214.50626
38.70000,1.93491,17350.58725,0.00000,0.00290,216.42460
39.00000,1.95003,17499.32617,0.00000,0.00294,218.27992
39.30000,1.96504,17656.06850,0.00000,0.00297,220.23506
39.60000,1.97987,17802.29658,0.00000,0.00300,222.05905
39.90000,1.99512,17958.81689,0.00000,0.00304,224.01143
40.20000,2.00988,18110.07112,0.00000,0.00308,225.89811
40.50000,2.02507,18262.41761,0.00000,0.00311,227.79843
40.80000,2.03996,18412.59599,0.00000,0.00315,229.67169
41.10000,2.05496,18562.07103,0.00000,0.00319,231.53619
41.40000,2.07003,18713.31334,0.00000,0.00322,233.42273
41.70000,2.08492,18858.61754,0.00000,0.00326,235.23520
42.00000,2.09999,19009.56631,0.00000,0.00330,237.11807
42.30000,2.11499,19155.99257,0.00000,0.00333,238.94454
42.60000,2.13000,19303.59900,0.00000,0.00338,240.78573
42.90000,2.14489,19446.88559,0.00000,0.00342,242.57303
43.20000,2.16007,19591.22717,0.00000,0.00346,244.37349
43.50000,2.17490,19730.64840,0.00000,0.00350,246.11258
43.80000,2.18997,19870.57924,0.00000,0.00354,247.85802
44.10000,2.20504,20012.00020,0.00000,0.00358,249.62205
44.40000,2.21992,20144.51474,0.00000,0.00362,251.27499
44.70000,2.23511,20284.26081,0.00000,0.00367,253.01813
45.00000,2.24988,20414.26450,0.00000,0.00371,254.63974
45.30000,2.26506,20547.39147,0.00000,0.00375,256.30032
45.60000,2.27995,20677.14781,0.00000,0.00380,257.91885
45.90000,2.29502,20803.26825,0.00000,0.00385,259.49203
46.20000,2.31003,20928.60788,0.00000,0.00390,261.05547
46.50000,2.32491,21046.51183,0.00000,0.00394,262.52616
46.80000,2.34004,21164.54989,0.00000,0.00399,263.99852
47.10000,2.35487,21277.61096,0.00000,0.00404,265.40880
47.40000,2.36994,21390.99389,0.00000,0.00410,266.82309
47.70000,2.38494,21498.58922,0.00000,0.00415,268.16520
48.00000,2.40001,21602.48309,0.00000,0.00421,269.46113
48.30000,2.41496,21705.31303,0.00000,0.00426,270.74379
48.60000,2.43002,21798.78801,0.00000,0.00432,271.90976
48.90000,2.44509,21896.50238,0.00000,0.00438,273.12861
49.20000,2.45998,21980.40783,0.00000,0.00445,274.17522
49.50000,2.47511,22066.54251,0.00000,0.00452,275.24963
49.80000,2.48999,22146.38293,0.00000,0.00459,276.24553
50.10000,2.50500,22218.63717,0.00000,0.00466,277.14680
50.40000,2.51995,22290.11506,0.00000,0.00473,278.03839
50.70000,2.53495,22355.95137,0.00000,0.00481,278.85960
51.00000,2.55002,22417.05656,0.00000,0.00489,279.62181
51.30000,2.56497,22472.67962,0.00000,0.00498,280.31563
51.60000,2.58004,22525.44165,0.00000,0.00507,280.97376
51.90000,2.59498,22571.79767,0.00000,0.00516,281.55199
52.20000,2.61005,22617.95700,0.00000,0.00526,282.12776
52.50000,2.62494,22657.13215,0.00000,0.00537,282.61642
52.80000,2.64006,22697.09259,0.00000,0.00549,283.11487
53.10000,2.65501,22735.68958,0.00000,0.00560,283.59631
53.40000,2.67008,22763.91685,0.00000,0.00572,283.94841
53.70000,2.68509,22795.57884,0.00000,0.00584,284.34335
54.00000,2.69985,22820.59640,0.00000,0.00596,284.65541
54.30000,2.71516,22852.03338,0.00000,0.00610,285.04754
54.60000,2.72987,22874.27932,0.00000,0.00623,285.32503
54.90000,2.74500,22898.00495,0.00000,0.00637,285.62097
55.20000,2.76000,22921.06003,0.00000,0.00652,285.90855
55.50000,2.77501,22938.58975,0.00000,0.00666,286.12721
55.80000,2.79008,22960.56151,0.00000,0.00681,286.40128
56.10000,2.80496,22976.23903,0.00000,0.00696,286.59684
56.40000,2.82003,22995.50027,0.00000,0.00711,286.83709
56.70000,2.83492,23008.61925,0.00000,0.00726,287.00073
57.00000,2.84993,23026.40676,0.00000,0.00742,287.22261
57.30000,2.86493,23038.76728,0.00000,0.00758,287.37679
57.60000,2.88006,23053.26015,0.00000,0.00774,287.55757
57.90000,2.89495,23068.79610,0.00000,0.00790,287.75136
58.20000,2.91001,23079.74100,0.00000,0.00807,287.88788
58.50000,2.92508,23095.04151,0.00000,0.00823,288.07873
58.80000,2.93991,23103.51133,0.00000,0.00840,288.18438
59.10000,2.95516,23118.43187,0.00000,0.00857,288.37049
59.40000,2.96992,23126.38909,0.00000,0.00873,288.46975
59.70000,2.98505,23138.41283,0.00000,0.00890,288.61973
60.00000,2.99994,23148.72146,0.00000,0.00907,288.74832
60.30000,3.01494,23157.79477,0.00000,0.00924,288.86149
60.60000,3.03001,23169.93177,0.00000,0.00941,289.01288
60.90000,3.04496,23176.99194,0.00000,0.00958,289.10095
61.20000,3.06009,23190.50729,0.00000,0.00975,289.26954
61.50000,3.07491,23196.11460,0.00000,0.00992,289.33948
61.80000,3.08998,23208.92513,0.00000,0.01009,289.49927
62.10000,3.10499,23215.86609,0.00000,0.01026,289.58585
62.40000,3.12011,23224.58029,0.00000,0.01044,289.69455
62.70000,3.13494,23235.66526,0.00000,0.01061,289.83282
63.00000,3.15001,23239.32797,0.00000,0.01078,289.87851
63.30000,3.16508,23252.71666,0.00000,0.01096,290.04551
63.60000,3.17984,23258.95280,0.00000,0.01113,290.12330
63.90000,3.19509,23267.95161,0.00000,0.01131,290.23555
64.20000,3.20998,23276.37970,0.00000,0.01148,290.34068
64.50000,3.22499,23284.13725,0.00000,0.01165,290.43744
64.80000,3.23999,23293.08093,0.00000,0.01182,290.54900
65.10000,3.25494,23298.37680,0.00000,0.01199,290.61506
65.40000,3.27001,23309.15332,0.00000,0.01216,290.74948
65.70000,3.28495,23314.92454,0.00000,0.01233,290.82147
66.00000,3.30002,23324.87404,0.00000,0.01250,290.94558
66.30000,3.31497,23329.94044,0.00000,0.01268,291.00877
66.60000,3.33004,23339.00034,0.00000,0.01285,291.12178
66.90000,3.34486,23345.77888,0.00000,0.01302,291.20633
67.20000,3.36011,23355.08615,0.00000,0.01319,291.32243
67.50000,3.37506,23363.15215,0.00000,0.01336,291.42304
67.80000,3.38994,23365.84032,0.00000,0.01352,291.45657
68.10000,3.40513,23378.28130,0.00000,0.01370,291.61176
68.40000,3.41990,23382.63243,0.00000,0.01387,291.66603
68.70000,3.43509,23391.96503,0.00000,0.01404,291.78244
69.00000,3.44991,23397.24898,0.00000,0.01420,291.84835
69.30000,3.46492,23403.44489,0.00000,0.01437,291.92564
69.60000,3.48005,23412.78046,0.00000,0.01454,292.04209
69.90000,3.49493,23416.46850,0.00000,0.01470,292.08809
70.20000,3.51000,23425.61632,0.00000,0.01487,292.20220
70.50000,3.52495,23431.58871,0.00000,0.01504,292.27669
70.80000,3.54008,23441.47563,0.00000,0.01521,292.40002
71.10000,3.55496,23444.67044,0.00000,0.01538,292.43987
71.40000,3.57009,23454.95075,0.00000,0.01554,292.56810
71.70000,3.58492,23459.92923,0.00000,0.01571,292.63020
72.00000,3.60010,23468.32752,0.00000,0.01588,292.73496
72.30000,3.61493,23477.43660,0.00000,0.01605,292.84858
72.60000,3.62988,23480.55840,0.00000,0.01621,292.88752
72.90000,3.64513,23491.45859,0.00000,0.01637,293.02349
73.20000,3.65983,23492.42270,0.00000,0.01654,293.03551
73.50000,3.67502,23500.74500,0.00000,0.01670,293.13932
73.80000,3.68997,23509.10008,0.00000,0.01687,293.24354
74.10000,3.70498,23515.89799,0.00000,0.01703,293.32834
74.40000,3.72010,23526.07548,0.00000,0.01720,293.45529
74.70000,3.73499,23530.76190,0.00000,0.01736,293.51374
75.00000,3.75006,23537.64325,0.00000,0.01752,293.59958
75.30000,3.76506,23542.96297,0.00000,0.01769,293.66593
75.60000,3.78007,23551.46706,0.00000,0.01785,293.77201
75.90000,3.79484,23555.26090,0.00000,0.01801,293.81933
76.20000,3.81009,23566.26838,0.00000,0.01817,293.95664
76.50000,3.82491,23570.49882,0.00000,0.01834,294.00941
76.80000,3.84004,23577.11792,0.00000,0.01850,294.09197
77.10000,3.85505,23584.79053,0.00000,0.01866,294.18767
77.40000,3.86993,23588.13286,0.00000,0.01882,294.22937
77.70000,3.88512,23599.57546,0.00000,0.01898,294.37210
78.00000,3.89989,23601.89706,0.00000,0.01914,294.40106
78.30000,3.91508,23610.01223,0.00000,0.01930,294.50228
78.60000,3.92996,23615.81922,0.00000,0.01946,294.57471
78.90000,3.94497,23621.20450,0.00000,0.01962,294.64189
79.20000,3.96010,23631.17337,0.00000,0.01978,294.76624
79.50000,3.97504,23636.09225,0.00000,0.01994,294.82759
79.80000,3.99005,23642.47739,0.00000,0.02010,294.90724
80.10000,4.00506,23647.60041,0.00000,0.02026,294.97114
80.40000,4.02013,23657.30107,0.00000,0.02042,295.09214
80.70000,4.03489,23658.96553,0.00000,0.02057,295.11291
81.00000,4.05008,23668.03586,0.00000,0.02073,295.22605
81.30000,4.06491,23674.81142,0.00000,0.02089,295.31056
81.60000,4.08003,23680.05514,0.00000,0.02105,295.37597
81.90000,4.09504,23688.06899,0.00000,0.02121,295.47593
82.20000,4.10981,23688.49218,0.00000,0.02136,295.48121
82.50000,4.12506,23698.57579,0.00000,0.02151,295.60699
82.80000,4.13988,23704.16522,0.00000,0.02167,295.67671
83.10000,4.15501,23712.12095,0.00000,0.02182,295.77595
83.40000,4.16996,23719.57898,0.00000,0.02198,295.86897
83.70000,4.18497,23724.48593,0.00000,0.02214,295.93018
84.00000,4.20009,23732.39994,0.00000,0.02230,296.02890
84.30000,4.21504,23736.56034,0.00000,0.02245,296.08079
84.60000,4.22999,23743.43872,0.00000,0.02261,296.16659
84.90000,4.24505,23748.94172,0.00000,0.02277,296.23523
85.20000,4.26006,23757.07179,0.00000,0.02292,296.33665
85.50000,4.27483,23759.63628,0.00000,0.02308,296.36863
85.80000,4.29008,23769.04041,0.00000,0.02323,296.48594
86.10000,4.30496,23775.38234,0.00000,0.02339,296.56504
86.40000,4.32003,23778.10180,0.00000,0.02354,296.59897
86.70000,4.33504,23788.11985,0.00000,0.02370,296.72393
87.00000,4.34986,23790.08979,0.00000,0.02385,296.74850
87.30000,4.36517,23799.57885,0.00000,0.02401,296.86686
87.60000,4.37994,23804.76594,0.00000,0.02416,296.93156
87.90000,4.39501,23807.90114,0.00000,0.02431,296.97067
88.20000,4.41001,23816.99085,0.00000,0.02447,297.08405
88.50000,4.42496,23822.18391,0.00000,0.02461,297.14883
88.80000,4.44003,23829.56296,0.00000,0.02477,297.24087
89.10000,4.45503,23832.56108,0.00000,0.02492,297.27827
89.40000,4.47004,23840.65241,0.00000,0.02508,297.37920
89.70000,4.48499,23843.45233,0.00000,0.02524,297.41412
90.00000,4.50006,23853.66708,0.00000,0.02539,297.54154
90.30000,4.51488,23856.98706,0.00000,0.02554,297.58295
90.60000,4.53007,23864.81464,0.00000,0.02569,297.68059
90.90000,4.54496,23870.22972,0.00000,0.02584,297.74813
91.20000,4.55996,23872.08790,0.00000,0.02599,297.77131
91.50000,4.57509,23881.57994,0.00000,0.02614,297.88971
91.80000,4.58986,23884.63914,0.00000,0.02629,297.92787
92.10000,4.60511,23893.80634,0.00000,0.02645,298.04222
92.40000,4.61987,23898.43613,0.00000,0.02660,298.09997
92.70000,4.63506,23904.16265,0.00000,0.02675,298.17140
93.00000,4.65001,23908.88780,0.00000,0.02690,298.23034
93.30000,4.66502,23916.20576,0.00000,0.02705,298.32162
93.60000,4.68002,23921.80264,0.00000,0.02721,298.39144
93.90000,4.69503,23926.36985,0.00000,0.02736,298.44840
94.20000,4.70998,23934.59529,0.00000,0.02751,298.55101
94.50000,4.72492,23935.85742,0.00000,0.02766,298.56675
94.80000,4.73999,23944.48519,0.00000,0.02781,298.67437
95.10000,4.75482,23946.07365,0.00000,0.02795,298.69418
95.40000,4.77001,23953.91017,0.00000,0.02811,298.79193
95.70000,4.78495,23961.34734,0.00000,0.02826,298.88470
96.00000,4.79996,23963.35155,0.00000,0.02841,298.90970
96.30000,4.81509,23972.82720,0.00000,0.02856,299.02790
96.60000,4.82985,23973.85687,0.00000,0.02871,299.04074
96.90000,4.84516,23982.52785,0.00000,0.02885,299.14890
97.20000,4.85999,23986.42302,0.00000,0.02900,299.19749
97.50000,4.87500,23993.25371,0.00000,0.02915,299.28269
97.80000,4.88994,23998.40802,0.00000,0.02931,299.34698
98.10000,4.90501,24005.10609,0.00000,0.02946,299.43053
98.40000,4.92002,24008.49462,0.00000,0.02961,299.47280
98.70000,4.93502,24014.21964,0.00000,0.02975,299.54421
99.00000,4.95003,24019.91338,0.00000,0.02990,299.61523
99.30000,4.96498,24021.96676,0.00000,0.03005,299.64084
99.60000,4.98005,24030.53194,0.00000,0.03019,299.74768
99.90000,4.99487,24033.23054,0.00000,0.03035,299.78134
100.20000,5.01012,24040.32052,0.00000,0.03049,299.86978
100.50000,5.02501,24046.17965,0.00000,0.03064,299.94287
100.80000,5.03996,24048.20621,0.00000,0.03079,299.96815
101.10000,5.05508,24057.74891,0.00000,0.03094,300.08718
101.40000,5.06991,24059.97813,0.00000,0.03109,300.11498
101.70000,5.08516,24067.09790,0.00000,0.03123,300.20379
102.00000,5.09992,24067.73418,0.00000,0.03138,300.21173
102.30000,5.11499,24075.06853,0.00000,0.03153,300.30322
102.60000,5.13000,24081.84111,0.00000,0.03168,300.38769
102.90000,5.14501,24085.29818,0.00000,0.03182,300.43082
103.20000,5.15995,24093.61005,0.00000,0.03197,300.53450
103.50000,5.17496,24095.57998,0.00000,0.03211,300.55907
103.80000,5.19003,24101.72522,0.00000,0.03226,300.63572
104.10000,5.20491,24103.02460,0.00000,0.03241,300.65193
104.40000,5.21998,24110.45283,0.00000,0.03255,300.74459
104.70000,5.23487,24116.13613,0.00000,0.03270,300.81548
105.00000,5.25006,24120.77636,0.00000,0.03285,300.87336
105.30001,5.26500,24128.14498,0.00000,0.03299,300.96527
105.60001,5.27995,24129.50993,0.00000,0.03313,300.98230
105.90001,5.29514,24139.48476,0.00000,0.03328,301.10672
106.20001,5.30996,24141.64543,0.00000,0.03343,301.13367
106.50001,5.32509,24148.71454,0.00000,0.03358,301.22185
106.80001,5.33998,24152.15224,0.00000,0.03372,301.26473
107.10001,5.35505,24156.43781,0.00000,0.03387,301.31818
107.40001,5.36993,24160.02005,0.00000,0.03401,301.36287
107.70001,5.38500,24165.55583,0.00000,0.03415,301.43192
108.00001,5.40001,24171.51630,0.00000,0.03430,301.50627
108.30001,5.41495,24174.40861,0.00000,0.03444,301.54235
108.60001,5.43002,24181.34212,0.00000,0.03459,301.62883
108.90001,5.44491,24183.26437,0.00000,0.03473,301.65281
109.20001,5.46010,24189.67634,0.00000,0.03487,301.73279
109.50001,5.47492,24193.58045,0.00000,0.03501,301.78149
109.80001,5.49011,24198.60512,0.00000,0.03516,301.84416
110.10001,5.50500,24206.16746,0.00000,0.03530,301.93849
110.40001,5.52001,24206.52658,0.00000,0.03544,301.94297
110.70001,5.53513,24213.60463,0.00000,0.03559,302.03126
111.00001,5.54990,24216.76219,0.00000,0.03573,302.07065
111.30001,5.56509,24220.43234,0.00000,0.03588,302.11643
111.60001,5.57991,24225.05021,0.00000,0.03602,302.17403
111.90001,5.59504,24231.57096,0.00000,0.03616,302.25537
112.20001,5.60999,24234.49010,0.00000,0.03630,302.29178
112.50001,5.62500,24237.10078,0.00000,0.03645,302.32434
112.80001,5.64000,24242.67977,0.00000,0.03659,302.39393
113.10001,5.65501,24244.65716,0.00000,0.03673,302.41860
113.40001,5.67008,24252.89005,0.00000,0.03687,302.52129
113.70001,5.68484,24253.28195,0.00000,0.03701,302.52618
114.00001,5.70003,24260.23036,0.00000,0.03715,302.61285
114.30001,5.71486,24264.09721,0.00000,0.03729,302.66109
114.60001,5.73011,24269.69707,0.00000,0.03743,302.73094
114.90001,5.74499,24274.25534,0.00000,0.03758,302.78780
115.20001,5.75988,24273.10944,0.00000,0.03772,302.77350
115.50001,5.77513,24284.45071,0.00000,0.03786,302.91497
115.80001,5.78995,24283.52088,0.00000,0.03800,302.90337
116.10001,5.80508,24289.79427,0.00000,0.03813,302.98162
116.40001,5.81991,24291.23670,0.00000,0.03827,302.99961
116.70001,5.83504,24296.99153,0.00000,0.03841,303.07140
117.00001,5.84998,24301.02527,0.00000,0.03855,303.12171
117.30001,5.86493,24304.21561,0.00000,0.03869,303.16151
117.60001,5.87994,24309.97342,0.00000,0.03883,303.23333
117.90001,5.89500,24312.19667,0.00000,0.03897,303.26106
118.20001,5.91007,24318.13031,0.00000,0.03911,303.33508
118.50001,5.92490,24319.81713,0.00000,0.03925,303.35612
118.80001,5.94003,24326.90114,0.00000,0.03939,303.44448
119.10001,5.95491,24330.35076,0.00000,0.03952,303.48751
119.40001,5.97010,24334.16247,0.00000,0.03967,303.53505
119.70001,5.98499,24339.67590,0.00000,0.03980,303.60383
120.00001,5.99994,24339.68782,0.00000,0.03994,303.60398
120.30001,6.01506,24346.85230,0.00000,0.04008,303.69334
120.60001,6.02989,24348.09357,0.00000,0.04022,303.70883
120.90001,6.04502,24353.37901,0.00000,0.04035,303.77475
121.20001,6.05996,24355.85260,0.00000,0.04049,303.80561
121.50001,6.07503,24361.67598,0.00000,0.04063,303.87825
121.80001,6.08998,24364.88271,0.00000,0.04076,303.91825
122.10001,6.10499,24368.29805,0.00000,0.04090,303.96085
122.40001,6.11999,24374.47757,0.00000,0.04104,304.03793
122.70001,6.13500,24376.46985,0.00000,0.04117,304.06278
123.00001,6.15007,24382.12484,0.00000,0.04131,304.13332
123.30001,6.16489,24381.27398,0.00000,0.04144,304.12271
123.60001,6.18008,24387.42369,0.00000,0.04158,304.19941
123.90001,6.19485,24390.54251,0.00000,0.04172,304.23832
124.20001,6.21004,24394.84596,0.00000,0.04185,304.29200
124.50001,6.22504,24400.90328,0.00000,0.04199,304.36755
124.80001,6.23993,24401.22515,0.00000,0.04212,304.37157
125.10001,6.25512,24406.71623,0.00000,0.04226,304.44006
125.40001,6.26988,24407.33910,0.00000,0.04239,304.44783
125.70001,6.28495,24411.41307,0.00000,0.04253,304.49865
126.00001,6.29996,24416.62550,0.00000,0.04266,304.56367
126.30001,6.31497,24420.47000,0.00000,0.04279,304.61162
126.60001,6.32997,24424.24595,0.00000,0.04293,304.65872
126.90001,6.34498,24426.16820,0.00000,0.04306,304.68270
127.20001,6.35999,24430.95744,0.00000,0.04320,304.74244
127.50001,6.37499,24432.59805,0.00000,0.04333,304.76290
127.80001,6.39012,24439.39894,0.00000,0.04347,304.84773
128.10001,6.40489,24437.77174,0.00000,0.04360,304.82744
128.40001,6.42008,24445.26106,0.00000,0.04373,304.92086
128.70001,6.43496,24447.21758,0.00000,0.04387,304.94526
129.00001,6.45009,24449.38868,0.00000,0.04400,304.97234
129.30001,6.46504,24455.75595,0.00000,0.04413,305.05176
129.60001,6.47987,24455.44899,0.00000,0.04426,305.04794
129.90001,6.49517,24462.59856,0.00000,0.04440,305.13712
130.20001,6.50988,24462.20964,0.00000,0.04453,305.13227
130.50001,6.52501,24465.14666,0.00000,0.04466,305.16890
130.80001,6.53995,24470.11471,0.00000,0.04480,305.23087
131.10001,6.55502,24474.04861,0.00000,0.04493,305.27994
131.40001,6.57003,24478.47873,0.00000,0.04506,305.33520
131.70001,6.58498,24480.09104,0.00000,0.04519,305.35531
132.00001,6.60004,24485.58658,0.00000,0.04532,305.42386
132.30001,6.61505,24486.15879,0.00000,0.04545,305.43100
132.60001,6.63006,24490.72748,0.00000,0.04558,305.48799
132.90001,6.64488,24491.65583,0.00000,0.04571,305.49957
133.20001,6.66013,24497.02471,0.00000,0.04585,305.56654
133.50001,6.67490,24499.33290,0.00000,0.04598,305.59533
133.80001,6.68997,24500.21207,0.00000,0.04611,305.60629
134.10001,6.70503,24507.06959,0.00000,0.04624,305.69183
134.40001,6.71992,24507.02637,0.00000,0.04637,305.69129
134.70001,6.73511,24512.95853,0.00000,0.04650,305.76529
135.00001,6.74993,24514.72282,0.00000,0.04663,305.78730
135.30001,6.76500,24519.21403,0.00000,0.04676,305.84332
135.60001,6.78001,24521.90816,0.00000,0.04689,305.87692
135.90001,6.79502,24524.47563,0.00000,0.04702,305.90895
136.20001,6.80996,24526.53199,0.00000,0.04715,305.93460
136.50001,6.82509,24529.24103,0.00000,0.04728,305.96839
136.80001,6.84004,24534.10625,0.00000,0.04741,306.02908
137.10001,6.85498,24534.13755,0.00000,0.04754,306.02947
137.40001,6.87011,24539.42299,0.00000,0.04768,306.09540
137.70001,6.88494,24539.30229,0.00000,0.04781,306.09389
138.00001,6.90019,24543.98423,0.00000,0.04793,306.15229
138.30001,6.91495,24545.29703,0.00000,0.04806,306.16867
138.60001,6.93002,24546.70817,0.00000,0.04819,306.18627
138.90001,6.94509,24553.56121,0.00000,0.04832,306.27175
139.20001,6.95986,24552.14858,0.00000,0.04844,306.25413
139.50001,6.97510,24557.70224,0.00000,0.04857,306.32340
139.80001,6.98993,24559.80033,0.00000,0.04870,306.34957
140.10001,7.00500,24563.22014,0.00000,0.04883,306.39223
140.40001,7.02000,24567.01100,0.00000,0.04896,306.43952
140.70001,7.03501,24570.65433,0.00000,0.04909,306.48496
141.00001,7.04996,24572.52443,0.00000,0.04922,306.50829
141.30001,7.06509,24574.33045,0.00000,0.04934,306.53082
141.60001,7.08003,24580.36095,0.00000,0.04947,306.60604
141.90001,7.09498,24578.45360,0.00000,0.04960,306.58225
142.20001,7.11005,24585.39307,0.00000,0.04972,306.66881
142.50001,7.12482,24585.00862,0.00000,0.04986,306.66401
142.80001,7.14006,24588.11700,0.00000,0.04998,306.70279
143.10001,7.15495,24590.95269,0.00000,0.05011,306.73816
143.40001,7.16996,24592.12691,0.00000,0.05024,306.75280
143.70001,7.18502,24600.11393,0.00000,0.05036,306.85243
144.00001,7.19985,24599.73693,0.00000,0.05049,306.84773
144.30001,7.21510,24605.35914,0.00000,0.05062,306.91786
144.60001,7.22998,24606.91482,0.00000,0.05075,306.93726
144.90001,7.24499,24608.82515,0.00000,0.05088,306.96109
145.20001,7.26006,24611.67127,0.00000,0.05100,306.99659
145.50001,7.27507,24614.82882,0.00000,0.05114,307.03598
145.80001,7.28989,24617.04165,0.00000,0.05127,307.06358
146.10001,7.30508,24619.37964,0.00000,0.05140,307.09274
146.40001,7.32003,24623.83062,0.00000,0.05152,307.14826
146.70001,7.33491,24619.92949,0.00000,0.05165,307.09960
147.00001,7.35010,24628.80164,0.00000,0.05178,307.21027
147.30001,7.36487,24627.29514,0.00000,0.05191,307.19148
147.60001,7.38012,24633.22580,0.00000,0.05204,307.26546
147.90001,7.39500,24635.33580,0.00000,0.05217,307.29178
148.20001,7.40995,24634.47452,0.00000,0.05229,307.28103
148.50001,7.42514,24641.55555,0.00000,0.05242,307.36936
148.80001,7.43991,24639.93728,0.00000,0.05255,307.34917
149.10001,7.45503,24644.42551,0.00000,0.05268,307.40516
149.40001,7.46992,24646.51763,0.00000,0.05281,307.43125
149.70001,7.48505,24650.61396,0.00000,0.05294,307.48235
150.00001,7.49999,24651.27259,0.00000,0.05307,307.49056
150.30001,7.51506,24653.68956,0.00000,0.05320,307.52071
150.60001,7.52995,24656.52823,0.00000,0.05333,307.55612
150.90001,7.54507,24657.69798,0.00000,0.05346,307.57071
151.20001,7.56002,24662.63920,0.00000,0.05358,307.63235
151.50001,7.57485,24661.15057,0.00000,0.05371,307.61378
151.80001,7.59004,24667.22727,0.00000,0.05384,307.68958
152.10001,7.60486,24669.04372,0.00000,0.05397,307.71224
152.40001,7.62005,24669.42221,0.00000,0.05410,307.71696
152.70001,7.63494,24674.75832,0.00000,0.05423,307.78352
153.00001,7.64995,24675.36479,0.00000,0.05436,307.79108
153.30001,7.66513,24680.90206,0.00000,0.05449,307.86015
153.60001,7.67996,24680.14061,0.00000,0.05462,307.85065
153.90001,7.69509,24683.53212,0.00000,0.05475,307.89296
154.20001,7.71003,24684.82405,0.00000,0.05488,307.90907
154.50001,7.72504,24688.37649,0.00000,0.05501,307.95338
154.80001,7.73999,24688.89058,0.00000,0.05514,307.95980
155.10001,7.75506,24692.08688,0.00000,0.05527,307.99967
155.40001,7.76994,24692.56371,0.00000,0.05540,308.00561
155.70001,7.78501,24694.04489,0.00000,0.05552,308.02409
156.00001,7.80008,24700.55968,0.00000,0.05566,308.10535
156.30001,7.81485,24697.82084,0.00000,0.05578,308.07119
156.60001,7.83003,24704.30285,0.00000,0.05592,308.15204
156.90001,7.84486,24705.86151,0.00000,0.05605,308.17149
157.20001,7.86005,24707.59749,0.00000,0.05618,308.19314
157.50001,7.87499,24710.44362,0.00000,0.05631,308.22864
157.80001,7.88994,24709.59425,0.00000,0.05644,308.21805
158.10001,7.90507,24715.95705,0.00000,0.05657,308.29741
158.40001,7.91995,24716.94052,0.00000,0.05670,308.30968
158.70001,7.93508,24717.99850,0.00000,0.05683,308.32288
159.00001,7.94997,24718.53048,0.00000,0.05696,308.32951
159.30001,7.96504,24722.40329,0.00000,0.05710,308.37782
159.60001,7.97998,24721.93986,0.00000,0.05722,308.37204
159.90001,7.99505,24727.21040,0.00000,0.05736,308.43778
160.20001,8.00994,24728.69456,0.00000,0.05749,308.45630
160.50001,8.02507,24729.85983,0.00000,0.05762,308.47083
160.80001,8.04007,24733.13808,0.00000,0.05774,308.51172
161.10001,8.05484,24730.56614,0.00000,0.05788,308.47964
161.40001,8.07003,24736.31650,0.00000,0.05801,308.55137
161.70001,8.08491,24739.41147,0.00000,0.05814,308.58998
162.00001,8.09998,24739.99262,0.00000,0.05827,308.59722
162.30001,8.11505,24744.09491,0.00000,0.05841,308.64839
162.60001,8.13000,24742.01322,0.00000,0.05854,308.62243
162.90001,8.14518,24748.86477,0.00000,0.05867,308.70789
163.20001,8.15995,24746.50741,0.00000,0.05880,308.67849
163.50001,8.17508,24751.79583,0.00000,0.05893,308.74445
163.80001,8.19002,24750.77957,0.00000,0.05906,308.73178
164.10001,8.20503,24754.60768,0.00000,0.05919,308.77953
164.40001,8.21992,24752.63923,0.00000,0.05932,308.75497
164.70001,8.23499,24754.45271,0.00000,0.05945,308.77759
165.00001,8.24999,24761.14333,0.00000,0.05958,308.86105
165.30001,8.26500,24758.89772,0.00000,0.05972,308.83304
165.60001,8.28007,24765.06978,0.00000,0.05984,308.91003
165.90001,8.29483,24762.99405,0.00000,0.05998,308.88414
166.20001,8.31014,24768.29588,0.00000,0.06011,308.95027
166.50001,8.32497,24769.88286,0.00000,0.06024,308.97006
166.80001,8.34004,24769.45519,0.00000,0.06038,308.96473
167.10001,8.35504,24773.93299,0.00000,0.06051,309.02058
167.40001,8.36999,24774.69146,0.00000,0.06064,309.03004
167.70001,8.38506,24776.27248,0.00000,0.06077,309.04977
168.00001,8.39994,24776.19201,0.00000,0.06090,309.04876
168.30001,8.41507,24777.74769,0.00000,0.06103,309.06817
168.60001,8.42996,24777.68958,0.00000,0.06117,309.06744
168.90001,8.44503,24783.01227,0.00000,0.06130,309.13384
169.20001,8.45991,24783.08082,0.00000,0.06143,309.13469
169.50001,8.47504,24784.46513,0.00000,0.06156,309.15196
169.80001,8.48999,24789.68501,0.00000,0.06170,309.21707
170.10001,8.50500,24786.45593,0.00000,0.06183,309.17679
170.40001,8.52006,24793.28215,0.00000,0.06196,309.26194
170.70001,8.53477,24788.87737,0.00000,0.06209,309.20699
171.00001,8.55008,24795.04943,0.00000,0.06222,309.28398
171.30001,8.56490,24793.32536,0.00000,0.06236,309.26248
171.60001,8.58003,24795.08221,0.00000,0.06249,309.28439
171.90001,8.59504,24799.16811,0.00000,0.06262,309.33536
172.20001,8.60999,24796.56190,0.00000,0.06275,309.30285
172.50001,8.62511,24802.13344,0.00000,0.06288,309.37235
172.80001,8.64000,24799.77310,0.00000,0.06301,309.34290
173.10001,8.65507,24801.93824,0.00000,0.06314,309.36991
173.40001,8.66995,24802.48511,0.00000,0.06328,309.37673
173.70001,8.68508,24805.88406,0.00000,0.06340,309.41913
174.00001,8.69991,24805.61286,0.00000,0.06353,309.41575
174.30001,8.71498,24807.16109,0.00000,0.06366,309.43506
174.60001,8.72998,24810.94301,0.00000,0.06379,309.48223
174.90001,8.74505,24809.68237,0.00000,0.06392,309.46651
175.20001,8.76006,24811.42730,0.00000,0.06405,309.48827
175.50001,8.77483,24810.61071,0.00000,0.06419,309.47809
175.80001,8.79007,24816.10626,0.00000,0.06432,309.54664
176.10001,8.80496,24816.66952,0.00000,0.06445,309.55366
176.40001,8.81997,24817.23726,0.00000,0.06458,309.56074
176.70001,8.83503,24819.28915,0.00000,0.06471,309.58634
177.00001,8.84998,24818.11196,0.00000,0.06484,309.57166
177.30001,8.86505,24820.44548,0.00000,0.06497,309.60076
177.60001,8.87987,24820.18769,0.00000,0.06510,309.59755
177.90001,8.89500,24824.01729,0.00000,0.06523,309.64532
178.20001,8.90995,24824.09030,0.00000,0.06536,309.64623
178.50001,8.92502,24827.36260,0.00000,0.06549,309.68704
178.80001,8.93996,24827.06308,0.00000,0.06562,309.68331
179.10001,8.95503,24826.25991,0.00000,0.06575,309.67329
179.40001,8.96998,24831.90596,0.00000,0.06588,309.74372
179.70001,8.98493,24829.81384,0.00000,0.06601,309.71762
180.00001,9.00005,24832.45581,0.00000,0.06613,309.75058
180.30001,9.01488,24830.36220,0.00000,0.06626,309.72446
180.60001,9.03013,24833.38416,0.00000,0.06639,309.76215
180.90001,9.04495,24833.64344,0.00000,0.06652,309.76539
181.20001,9.05996,24834.01299,0.00000,0.06665,309.77000
181.50001,9.07509,24837.87984,0.00000,0.06678,309.81823
181.80001,9.08998,24837.61162,0.00000,0.06690,309.81489
182.10001,9.10504,24837.78000,0.00000,0.06703,309.81699
182.40001,9.11993,24836.94106,0.00000,0.06716,309.80652
182.70001,9.13506,24840.95991,0.00000,0.06729,309.85665
183.00001,9.14994,24840.64996,0.00000,0.06741,309.85279
183.30001,9.16501,24844.22177,0.00000,0.06754,309.89734
183.60001,9.17996,24843.59890,0.00000,0.06767,309.88957
183.90001,9.19503,24843.59294,0.00000,0.06780,309.88950
184.20001,9.21003,24846.75199,0.00000,0.06792,309.92890
184.50001,9.22492,24843.34409,0.00000,0.06805,309.88639
184.80001,9.24017,24848.87540,0.00000,0.06817,309.95539
185.10001,9.25494,24846.51059,0.00000,0.06831,309.92589
185.40001,9.27012,24848.66530,0.00000,0.06843,309.95277
185.70001,9.28501,24848.57291,0.00000,0.06856,309.95161
186.00001,9.29996,24846.03077,0.00000,0.06868,309.91990
186.30001,9.31502,24851.63659,0.00000,0.06881,309.98983
186.60001,9.32985,24850.16584,0.00000,0.06893,309.97148
186.90001,9.34504,24854.30390,0.00000,0.06906,310.02310
187.20001,9.35993,24853.27274,0.00000,0.06918,310.01024
187.50001,9.37499,24855.56304,0.00000,0.06931,310.03881
187.80001,9.38994,24854.29645,0.00000,0.06943,310.02301
188.10001,9.40507,24856.27830,0.00000,0.06956,310.04773
188.40001,9.41995,24857.24241,0.00000,0.06968,310.05975
188.70001,9.43502,24857.48380,0.00000,0.06981,310.06276
189.00001,9.45009,24862.31327,0.00000,0.06994,310.12301
189.30001,9.46498,24857.62388,0.00000,0.07006,310.06451
189.60001,9.48010,24860.40592,0.00000,0.07018,310.09921
189.90001,9.49487,24858.64013,0.00000,0.07031,310.07719
190.20001,9.51012,24862.16128,0.00000,0.07043,310.12111
190.50001,9.52494,24862.20300,0.00000,0.07055,310.12163
190.80001,9.53995,24861.59950,0.00000,0.07068,310.11410
191.10001,9.55502,24866.36192,0.00000,0.07081,310.17351
191.40001,9.56997,24865.37099,0.00000,0.07093,310.16115
191.70001,9.58503,24867.43480,0.00000,0.07105,310.18689
192.00001,9.59992,24866.25910,0.00000,0.07118,310.17222
192.30001,9.61499,24869.52543,0.00000,0.07130,310.21297
192.60001,9.62994,24868.09045,0.00000,0.07143,310.19507
192.90001,9.64506,24869.45689,0.00000,0.07155,310.21211
193.20001,9.65995,24870.29731,0.00000,0.07167,310.22260
193.50001,9.67508,24869.66550,0.00000,0.07180,310.21471
193.80001,9.69008,24874.38023,0.00000,0.07192,310.27352
194.10001,9.70485,24869.67146,0.00000,0.07205,310.21479
194.40001,9.72016,24875.11784,0.00000,0.07218,310.28273
194.70001,9.73493,24873.17771,0.00000,0.07230,310.25852
195.00001,9.75011,24874.45027,0.00000,0.07242,310.27440
195.30001,9.76500,24875.50825,0.00000,0.07255,310.28759
195.60001,9.77995,24875.09102,0.00000,0.07267,310.28239
195.90001,9.79507,24879.46302,0.00000,0.07279,310.33693
196.20001,9.80990,24876.52898,0.00000,0.07292,310.30033
196.50001,9.82497,24876.92684,0.00000,0.07304,310.30529
196.80001,9.83997,24878.67326,0.00000,0.07317,310.32707
197.10001,9.85504,24879.97711,0.00000,0.07329,310.34334
197.40001,9.86993,24880.85777,0.00000,0.07342,310.35432
197.70001,9.88506,24881.72650,0.00000,0.07354,310.36516
198.00001,9.90000,24882.67720,0.00000,0.07367,310.37702
198.30001,9.91507,24880.87267,0.00000,0.07379,310.35451
198.60001,9.93008,24883.06761,0.00000,0.07392,310.38189
198.90001,9.94497,24879.38702,0.00000,0.07404,310.33598
199.20001,9.96009,24884.27907,0.00000,0.07416,310.39700
199.50001,9.97486,24884.87959,0.00000,0.07429,310.40449
199.80001,9.99005,24885.01966,0.00000,0.07441,310.40624
200.10001,10.00499,24886.42633,0.00000,0.07454,310.42378
200.40001,10.01994,24883.77392,0.00000,0.07466,310.39070
200.70001,10.03507,24888.09228,0.00000,0.07479,310.44456
201.00001,10.04990,24887.63630,0.00000,0.07491,310.43888
201.30001,10.06496,24889.34547,0.00000,0.07504,310.46020
201.60001,10.07997,24889.89532,0.00000,0.07517,310.46705
201.90001,10.09504,24891.14553,0.00000,0.07529,310.48265
202.20001,10.10998,24888.69578,0.00000,0.07542,310.45209
202.50001,10.12505,24889.51236,0.00000,0.07554,310.46228
202.80001,10.13994,24890.62846,0.00000,0.07567,310.47620
203.10001,10.15507,24889.91022,0.00000,0.07579,310.46724
203.40001,10.17001,24892.22437,0.00000,0.07592,310.49611
203.70001,10.18490,24888.38434,0.00000,0.07604,310.44821
204.00001,10.20015,24894.08404,0.00000,0.07616,310.51930
204.30001,10.21491,24893.63402,0.00000,0.07629,310.51369
204.60001,10.22998,24895.24782,0.00000,0.07642,310.53382
204.90001,10.24499,24896.92271,0.00000,0.07655,310.55471
205.20001,10.25994,24896.04503,0.00000,0.07668,310.54376
205.50001,10.27506,24897.32057,0.00000,0.07680,310.55967
205.80001,10.28989,24895.15841,0.00000,0.07693,310.53270
206.10001,10.30496,24896.81840,0.00000,0.07706,310.55341
206.40001,10.31996,24894.69796,0.00000,0.07718,310.52696
206.70001,10.33503,24899.59747,0.00000,0.07731,310.58807
207.00001,10.34992,24895.23590,0.00000,0.07744,310.53367
207.30001,10.36511,24896.96443,0.00000,0.07756,310.55523
207.60001,10.37999,24898.31448,0.00000,0.07769,310.57207
207.90001,10.39506,24896.25514,0.00000,0.07782,310.54638
208.20001,10.41007,24900.59286,0.00000,0.07794,310.60049
208.50001,10.42483,24896.53230,0.00000,0.07807,310.54984
208.80001,10.44014,24900.97582,0.00000,0.07820,310.60527
209.10001,10.45491,24898.06265,0.00000,0.07833,310.56893
209.40001,10.46998,24896.68280,0.00000,0.07845,310.55172
209.70001,10.48498,24899.43802,0.00000,0.07858,310.58609
210.00001,10.49993,24899.82992,0.00000,0.07871,310.59097
210.30001,10.51506,24902.40186,0.00000,0.07884,310.62306
210.60001,10.52995,24900.25014,0.00000,0.07896,310.59622
210.90001,10.54507,24899.18023,0.00000,0.07909,310.58287
211.20001,10.56002,24898.38153,0.00000,0.07922,310.57291
211.50001,10.57503,24900.48409,0.00000,0.07934,310.59913
211.80001,10.58991,24898.56482,0.00000,0.07947,310.57519
212.10001,10.60510,24901.48693,0.00000,0.07960,310.61164
212.40001,10.61999,24901.59571,0.00000,0.07973,310.61300
212.70001,10.63500,24899.05357,0.00000,0.07986,310.58129
213.00001,10.65006,24903.20653,0.00000,0.07999,310.63309
213.30001,10.66483,24899.58107,0.00000,0.08011,310.58787
213.60001,10.68014,24903.70274,0.00000,0.08024,310.63928
213.90001,10.69490,24902.22454,0.00000,0.08037,310.62084
214.20001,10.70997,24900.74486,0.00000,0.08049,310.60239
214.50001,10.72504,24902.88019,0.00000,0.08062,310.62902
214.80001,10.73993,24901.15613,0.00000,0.08076,310.60752
215.10001,10.75505,24902.72224,0.00000,0.08088,310.62705
215.40001,10.77000,24901.83413,0.00000,0.08101,310.61597
215.70001,10.78507,24903.00089,0.00000,0.08114,310.63053
216.00001,10.80001,24900.83873,0.00000,0.08127,310.60356
216.30001,10.81508,24902.46594,0.00000,0.08139,310.62385
216.60001,10.82991,24900.17265,0.00000,0.08152,310.59525
216.90001,10.84510,24901.32749,0.00000,0.08165,310.60965
217.20001,10.85998,24904.63555,0.00000,0.08178,310.65092
217.50001,10.87493,24900.29186,0.00000,0.08190,310.59674
217.80001,10.89012,24904.47760,0.00000,0.08203,310.64895
218.10001,10.90489,24900.39021,0.00000,0.08217,310.59796
218.40001,10.92007,24901.91162,0.00000,0.08229,310.61694
218.70001,10.93496,24903.13500,0.00000,0.08242,310.63220
219.00001,10.94997,24900.60925,0.00000,0.08255,310.60070
219.30001,10.96509,24903.24676,0.00000,0.08268,310.63359
219.60001,10.97998,24899.78969,0.00000,0.08281,310.59047
219.90001,10.99511,24901.66128,0.00000,0.08293,310.61382
220.20001,11.01000,24897.66181,0.00000,0.08306,310.56393
220.50001,11.02500,24899.53041,0.00000,0.08319,310.58724
220.80001,11.04001,24900.26951,0.00000,0.08331,310.59646
221.10001,11.05508,24901.17997,0.00000,0.08344,310.60781
221.40001,11.06991,24898.89264,0.00000,0.08356,310.57928
221.70001,11.08509,24898.87625,0.00000,0.08369,310.57908
222.00001,11.10004,24900.79552,0.00000,0.08382,310.60302
222.30001,11.11487,24895.94072,0.00000,0.08395,310.54246
222.60001,11.13011,24901.27087,0.00000,0.08407,310.60895
222.90001,11.14488,24898.20570,0.00000,0.08420,310.57071
223.20001,11.16007,24899.11020,0.00000,0.08433,310.58200
223.50001,11.17502,24898.70191,0.00000,0.08446,310.57690
223.80001,11.19002,24896.55912,0.00000,0.08458,310.55018
224.10001,11.20509,24898.35471,0.00000,0.08471,310.57257
224.40001,11.21998,24896.28047,0.00000,0.08483,310.54670
224.70001,11.23504,24896.67088,0.00000,0.08496,310.55157
225.00001,11.24999,24894.48786,0.00000,0.08508,310.52434
225.30001,11.26506,24897.00168,0.00000,0.08521,310.55570
225.60001,11.27995,24894.64581,0.00000,0.08534,310.52631
225.90001,11.29507,24897.56495,0.00000,0.08546,310.56272
226.20001,11.30990,24896.01821,0.00000,0.08558,310.54343
226.50001,11.32509,24895.55627,0.00000,0.08571,310.53767
226.80001,11.34003,24896.74389,0.00000,0.08584,310.55248
227.10001,11.35486,24890.29765,0.00000,0.08596,310.47207
227.40001,11.37011,24895.62184,0.00000,0.08609,310.53848
227.70001,11.38487,24892.20500,0.00000,0.08621,310.49586
228.00001,11.40000,24893.83519,0.00000,0.08633,310.51620
228.30001,11.41495,24893.76217,0.00000,0.08646,310.51529
228.60001,11.43002,24891.69091,0.00000,0.08658,310.48945
228.90001,11.44508,24892.33613,0.00000,0.08670,310.49750
229.20001,11.45997,24889.06384,0.00000,0.08683,310.45668
229.50001,11.47504,24892.40170,0.00000,0.08695,310.49832
229.80001,11.49005,24889.64796,0.00000,0.08708,310.46397
230.10001,11.50505,24892.26609,0.00000,0.08720,310.49663
230.40001,11.51994,24887.10582,0.00000,0.08732,310.43226
230.70001,11.53513,24889.70906,0.00000,0.08744,310.46473
231.00001,11.54989,24888.25619,0.00000,0.08757,310.44661
231.30001,11.56502,24886.85548,0.00000,0.08769,310.42914
231.60001,11.58003,24889.24563,0.00000,0.08781,310.45895
231.90001,11.59486,24883.02141,0.00000,0.08793,310.38131
232.20001,11.61016,24886.81376,0.00000,0.08805,310.42862
232.50001,11.62487,24881.55961,0.00000,0.08817,310.36308
232.80001,11.64006,24883.51315,0.00000,0.08829,310.38744
233.10001,11.65500,24883.58915,0.00000,0.08842,310.38839
233.40001,11.67001,24883.28516,0.00000,0.08853,310.38460
233.70001,11.68502,24883.75157,0.00000,0.08865,310.39042
234.00001,11.70003,24879.79382,0.00000,0.08877,310.34105
234.30001,11.71503,24880.01734,0.00000,0.08889,310.34384
234.60001,11.72998,24877.01029,0.00000,0.08901,310.30633
234.90001,11.74505,24879.94879,0.00000,0.08912,310.34298
235.20001,11.75994,24876.67799,0.00000,0.08924,310.30219
235.50001,11.77506,24876.75399,0.00000,0.08936,310.30313
235.80001,11.78989,24875.71537,0.00000,0.08947,310.29018
236.10001,11.80502,24873.20155,0.00000,0.08959,310.25882
236.40001,11.82002,24875.09400,0.00000,0.08971,310.28243
236.70001,11.83485,24871.18542,0.00000,0.08982,310.23367
237.00001,11.85010,24872.52504,0.00000,0.08993,310.25038
237.30001,11.86493,24869.37642,0.00000,0.09005,310.21111
237.60001,11.87999,24867.41692,0.00000,0.09016,310.18667
237.90001,11.89500,24866.80895,0.00000,0.09027,310.17908
238.20001,11.90995,24865.98790,0.00000,0.09038,310.16884
238.50001,11.92501,24866.25463,0.00000,0.09050,310.17217
238.80001,11.93996,24865.74650,0.00000,0.09061,310.16583
239.10001,11.95503,24865.51106,0.00000,0.09072,310.16289
239.40001,11.96998,24861.70083,0.00000,0.09082,310.11537
239.70001,11.98510,24863.10452,0.00000,0.09093,310.13288
240.00001,11.99987,24857.49125,0.00000,0.09104,310.06286
240.30001,12.01500,24858.06495,0.00000,0.09114,310.07001
240.60001,12.02994,24856.96226,0.00000,0.09125,310.05626
240.90001,12.04501,24851.07481,0.00000,0.09135,309.98282
241.20001,12.06008,24854.28005,0.00000,0.09146,310.02280
241.50001,12.07491,24847.45830,0.00000,0.09156,309.93771
241.80001,12.09021,24848.75470,0.00000,0.09167,309.95388
242.10001,12.10498,24846.43459,0.00000,0.09175,309.92494
242.40001,12.11999,24843.12803,0.00000,0.09186,309.88370
242.70001,12.13499,24842.97901,0.00000,0.09196,309.88184
243.00001,12.15000,24837.94540,0.00000,0.09206,309.81905
243.30001,12.16501,24837.72337,0.00000,0.09215,309.81628
243.60001,12.17996,24832.28445,0.00000,0.09225,309.74844
243.90001,12.19502,24833.15766,0.00000,0.09234,309.75933
244.20001,12.20997,24827.29852,0.00000,0.09243,309.68625
244.50001,12.22504,24825.54615,0.00000,0.09252,309.66439
244.80001,12.23993,24820.05805,0.00000,0.09261,309.59593
245.10001,12.25505,24818.94344,0.00000,0.09270,309.58203
245.40001,12.26994,24815.86635,0.00000,0.09278,309.54364
245.70001,12.28501,24810.95344,0.00000,0.09286,309.48236
246.00001,12.30013,24809.92824,0.00000,0.09295,309.46957
246.30001,12.31490,24801.41371,0.00000,0.09303,309.36337
246.60001,12.33015,24801.11867,0.00000,0.09310,309.35969
246.90001,12.34492,24793.14357,0.00000,0.09318,309.26021
247.20001,12.36004,24792.13923,0.00000,0.09325,309.24768
247.50001,12.37499,24786.17132,0.00000,0.09332,309.17324
247.80001,12.38994,24780.10505,0.00000,0.09340,309.09757
248.10001,12.40500,24775.22790,0.00000,0.09347,309.03674
248.40001,12.42001,24765.89233,0.00000,0.09353,308.92029
248.70001,12.43508,24761.29532,0.00000,0.09359,308.86295
249.00001,12.44997,24752.82997,0.00000,0.09366,308.75735
249.30001,12.46503,24748.58612,0.00000,0.09371,308.70442
249.60001,12.47992,24737.79172,0.00000,0.09377,308.56977
249.90001,12.49505,24729.15202,0.00000,0.09382,308.46200
250.20001,12.51000,24721.92794,0.00000,0.09387,308.37189
250.50001,12.52512,24709.98615,0.00000,0.09392,308.22294
250.80001,12.54013,24702.73972,0.00000,0.09397,308.13255
251.10001,12.55490,24689.75782,0.00000,0.09402,307.97061
251.40001,12.57020,24682.20145,0.00000,0.09406,307.87636
251.70001,12.58497,24666.69232,0.00000,0.09410,307.68290
252.00001,12.60004,24652.59880,0.00000,0.09413,307.50711
252.30001,12.61504,24640.88053,0.00000,0.09417,307.36094
252.60001,12.63005,24625.44739,0.00000,0.09420,307.16843
252.90001,12.64500,24609.26622,0.00000,0.09423,306.96659
253.20001,12.65995,24589.67417,0.00000,0.09426,306.72221
253.50001,12.67501,24572.84331,0.00000,0.09428,306.51227
253.80001,12.68996,24548.75410,0.00000,0.09430,306.21179
254.10001,12.70509,24530.52551,0.00000,0.09433,305.98441
254.40001,12.71992,24502.27737,0.00000,0.09434,305.63206
254.70001,12.73510,24478.33568,0.00000,0.09436,305.33342
255.00001,12.74999,24453.65340,0.00000,0.09437,305.02554
255.30001,12.76500,24416.39900,0.00000,0.09438,304.56084
255.60001,12.78012,24384.97990,0.00000,0.09438,304.16893
255.90001,12.79495,24338.91296,0.00000,0.09439,303.59431
256.20001,12.81014,24283.99622,0.00000,0.09439,302.90930
256.50001,12.82491,24197.66635,0.00000,0.09437,301.83245
256.80001,12.83997,24071.12867,0.00000,0.09436,300.25407
257.10001,12.85510,23935.74715,0.00000,0.09433,298.56537
257.40001,12.87005,23691.60503,0.00000,0.09428,295.52004
257.68401,12.88434,23111.36723,0.00000,0.09415,288.28237
257.71601,12.88589,21927.96469,0.00000,0.09377,273.52106
257.72201,12.88667,18962.46970,0.00000,0.09254,236.53061
257.72801,12.88768,15127.88981,0.00000,0.09043,188.69952
257.73001,12.88804,13810.66740,0.00000,0.08964,172.26899