File: scratch/college-stuff/ME Lab/ME lab Fall 2013/group5/group5.is_tens_RawData/Specimen_RawData_2.csv
Time,Extension,Load,Strain 2,Tensile strain,Tensile stress
(sec),(mm),(N),(mm/mm),(mm/mm),(MPa)
0.00000,0.00000,-0.17624,0.00000,0.00000,-0.00217
0.30000,0.01363,21.28001,0.00000,0.00000,0.26181
0.60000,0.03007,32.07537,0.00000,0.00000,0.39463
0.90000,0.04490,38.78665,0.00000,-0.00001,0.47720
1.20000,0.06009,47.39423,0.00000,-0.00001,0.58310
1.50000,0.07498,58.26530,0.00000,-0.00002,0.71685
1.80000,0.09004,73.31853,0.00000,-0.00003,0.90205
2.10000,0.10511,89.75844,0.00000,-0.00003,1.10431
2.40000,0.11988,107.75701,0.00000,-0.00004,1.32575
2.70000,0.13512,128.98233,0.00000,-0.00005,1.58689
3.00000,0.14995,151.76410,0.00000,-0.00006,1.86718
3.30000,0.16508,191.91811,0.00000,-0.00007,2.36120
3.60000,0.17991,243.52446,0.00000,-0.00007,2.99612
3.90000,0.19503,303.06329,0.00000,-0.00008,3.72863
4.20000,0.21004,369.10712,0.00000,-0.00008,4.54118
4.50000,0.22499,453.79740,0.00000,-0.00008,5.58314
4.80000,0.24005,569.27083,0.00000,-0.00008,7.00382
5.10000,0.25494,709.59656,0.00000,-0.00007,8.73027
5.40000,0.27013,878.37204,0.00000,-0.00005,10.80674
5.70000,0.28484,1048.44989,0.00000,-0.00003,12.89924
6.00000,0.30008,1234.06304,0.00000,-0.00001,15.18286
6.30000,0.31491,1431.17635,0.00000,0.00002,17.60798
6.60000,0.32998,1629.41832,0.00000,0.00005,20.04698
6.90000,0.34505,1832.34178,0.00000,0.00008,22.54357
7.20000,0.35987,2030.74273,0.00000,0.00011,24.98453
7.50000,0.37506,2230.20706,0.00000,0.00014,27.43857
7.80000,0.38989,2422.00997,0.00000,0.00017,29.79835
8.10000,0.40501,2614.11797,0.00000,0.00020,32.16188
8.40000,0.41996,2799.89038,0.00000,0.00023,34.44747
8.70000,0.43497,2982.38248,0.00000,0.00026,36.69270
9.00000,0.44998,3165.31286,0.00000,0.00029,38.94332
9.30000,0.46498,3338.92554,0.00000,0.00032,41.07930
9.60000,0.48005,3510.33583,0.00000,0.00035,43.18819
9.90000,0.49488,3671.51462,0.00000,0.00037,45.17119
10.20000,0.51006,3834.88350,0.00000,0.00041,47.18115
10.50000,0.52489,3991.57293,0.00000,0.00043,49.10892
10.80000,0.54002,4140.59311,0.00000,0.00045,50.94234
11.10000,0.55497,4282.35456,0.00000,0.00048,52.68645
11.40000,0.56997,4421.98478,0.00000,0.00051,54.40434
11.70000,0.58504,4557.03288,0.00000,0.00053,56.06586
12.00000,0.59981,4684.04442,0.00000,0.00055,57.62850
12.30000,0.61493,4817.59086,0.00000,0.00056,59.27154
12.60000,0.62994,4941.90119,0.00000,0.00059,60.80095
12.90000,0.64501,5066.64217,0.00000,0.00061,62.33566
13.20000,0.65996,5190.07072,0.00000,0.00063,63.85422
13.50000,0.67502,5314.01932,0.00000,0.00065,65.37917
13.80000,0.69003,5441.01223,0.00000,0.00068,66.94159
14.10000,0.70504,5565.26706,0.00000,0.00070,68.47031
14.40000,0.72004,5694.19861,0.00000,0.00072,70.05658
14.70000,0.73499,5820.91361,0.00000,0.00074,71.61557
15.00000,0.75012,5950.34175,0.00000,0.00077,73.20794
15.30000,0.76489,6076.42829,0.00000,0.00079,74.75921
15.60000,0.77995,6209.09929,0.00000,0.00081,76.39148
15.90000,0.79496,6338.88543,0.00000,0.00083,77.98826
16.20000,0.80997,6471.02371,0.00000,0.00085,79.61397
16.50000,0.82504,6604.33546,0.00000,0.00088,81.25413
16.80000,0.83992,6733.92192,0.00000,0.00090,82.84845
17.10000,0.85505,6870.20570,0.00000,0.00092,84.52517
17.40000,0.87000,7002.79698,0.00000,0.00095,86.15646
17.70000,0.88500,7138.13156,0.00000,0.00097,87.82150
18.00000,0.89995,7274.55765,0.00000,0.00100,89.49997
18.30000,0.91508,7407.69655,0.00000,0.00102,91.13800
18.60000,0.92997,7546.22892,0.00000,0.00105,92.84238
18.90000,0.94491,7679.51757,0.00000,0.00107,94.48225
19.20000,0.96004,7821.47646,0.00000,0.00110,96.22880
19.50000,0.97487,7956.82967,0.00000,0.00112,97.89407
19.80000,0.99005,8098.38027,0.00000,0.00114,99.63558
20.10000,1.00494,8235.61102,0.00000,0.00117,101.32395
20.40000,1.01995,8374.97562,0.00000,0.00119,103.03858
20.70000,1.03496,8518.22123,0.00000,0.00122,104.80095
21.00000,1.04990,8657.95836,0.00000,0.00124,106.52016
21.30000,1.06503,8801.85068,0.00000,0.00127,108.29049
21.60000,1.07992,8941.25625,0.00000,0.00129,110.00561
21.90000,1.09504,9086.45540,0.00000,0.00132,111.79202
22.20000,1.10993,9225.79095,0.00000,0.00134,113.50629
22.50000,1.12500,9371.62638,0.00000,0.00137,115.30052
22.80000,1.13995,9515.81970,0.00000,0.00140,117.07455
23.10000,1.15501,9658.60337,0.00000,0.00142,118.83124
23.40000,1.17002,9805.35671,0.00000,0.00145,120.63677
23.70000,1.18491,9946.18237,0.00000,0.00147,122.36937
24.00000,1.20003,10093.96985,0.00000,0.00150,124.18762
24.30000,1.21486,10238.16243,0.00000,0.00152,125.96164
24.60000,1.23005,10387.92208,0.00000,0.00155,127.80416
24.90000,1.24494,10534.38634,0.00000,0.00158,129.60613
25.20000,1.25994,10679.83136,0.00000,0.00160,131.39556
25.50000,1.27501,10829.32204,0.00000,0.00163,133.23477
25.80000,1.28996,10974.67840,0.00000,0.00166,135.02311
26.10000,1.30503,11125.32914,0.00000,0.00168,136.87659
26.40000,1.31991,11271.41640,0.00000,0.00171,138.67392
26.70000,1.33504,11423.80014,0.00000,0.00174,140.54872
27.00000,1.34999,11570.23087,0.00000,0.00177,142.35028
27.30000,1.36505,11721.33833,0.00000,0.00179,144.20938
27.60000,1.37988,11868.52008,0.00000,0.00182,146.02018
27.90000,1.39507,12019.43681,0.00000,0.00185,147.87693
28.20000,1.41002,12170.92723,0.00000,0.00188,149.74074
28.50000,1.42484,12317.06664,0.00000,0.00191,151.53871
28.80000,1.44009,12471.56933,0.00000,0.00194,153.43958
29.10000,1.45492,12621.72312,0.00000,0.00197,155.28695
29.40000,1.47004,12771.64519,0.00000,0.00200,157.13146
29.70000,1.48493,12924.37017,0.00000,0.00203,159.01046
30.00000,1.49994,13076.39927,0.00000,0.00206,160.88090
30.30000,1.51501,13232.33098,0.00000,0.00209,162.79935
30.60000,1.52995,13381.71065,0.00000,0.00212,164.63719
30.90000,1.54502,13536.61269,0.00000,0.00215,166.54297
31.20000,1.55991,13687.35880,0.00000,0.00218,168.39762
31.50000,1.57503,13843.76436,0.00000,0.00221,170.32190
31.80000,1.58992,13993.71773,0.00000,0.00224,172.16680
32.10000,1.60505,14150.20823,0.00000,0.00227,174.09213
32.40000,1.61994,14304.92401,0.00000,0.00230,175.99562
32.70000,1.63506,14456.27660,0.00000,0.00233,177.85773
33.00000,1.65001,14613.61051,0.00000,0.00236,179.79344
33.30000,1.66490,14765.13743,0.00000,0.00239,181.65769
33.60000,1.68008,14926.00590,0.00000,0.00243,183.63688
33.90000,1.69485,15078.00967,0.00000,0.00245,185.50701
34.20000,1.70998,15231.61083,0.00000,0.00249,187.39679
34.50000,1.72493,15388.07452,0.00000,0.00252,189.32178
34.80000,1.73993,15544.10011,0.00000,0.00255,191.24139
35.10000,1.75500,15700.07652,0.00000,0.00258,193.16039
35.40000,1.76995,15852.84919,0.00000,0.00261,195.03998
35.70000,1.78508,16011.06226,0.00000,0.00265,196.98649
36.00000,1.79996,16162.26137,0.00000,0.00268,198.84672
36.30000,1.81509,16321.91688,0.00000,0.00271,200.81099
36.60000,1.82998,16473.13237,0.00000,0.00274,202.67141
36.90000,1.84504,16631.08170,0.00000,0.00278,204.61469
37.20000,1.85987,16787.13113,0.00000,0.00281,206.53459
37.50000,1.87500,16939.72349,0.00000,0.00284,208.41195
37.80000,1.89007,17097.11850,0.00000,0.00288,210.34841
38.10000,1.90477,17248.60817,0.00000,0.00291,212.21221
38.40000,1.92008,17410.12633,0.00000,0.00295,214.19939
38.70000,1.93485,17564.01062,0.00000,0.00298,216.09265
39.00000,1.94997,17720.27314,0.00000,0.00302,218.01517
39.30000,1.96498,17875.00232,0.00000,0.00305,219.91883
39.60000,1.97999,18030.47210,0.00000,0.00309,221.83160
39.90000,1.99506,18184.46368,0.00000,0.00312,223.72618
40.20000,2.01000,18336.45254,0.00000,0.00316,225.59612
40.50000,2.02501,18490.40240,0.00000,0.00320,227.49019
40.80000,2.03996,18642.04407,0.00000,0.00323,229.35586
41.10000,2.05508,18796.28301,0.00000,0.00328,231.25348
41.40000,2.06985,18941.51568,0.00000,0.00331,233.04030
41.70000,2.08504,19095.56538,0.00000,0.00335,234.93560
42.00000,2.09993,19245.55153,0.00000,0.00339,236.78090
42.30000,2.11499,19392.10147,0.00000,0.00343,238.58393
42.60000,2.13006,19543.03682,0.00000,0.00347,240.44091
42.90000,2.14483,19684.91077,0.00000,0.00352,242.18640
43.20000,2.16013,19833.19372,0.00000,0.00355,244.01075
43.50000,2.17490,19974.26599,0.00000,0.00360,245.74638
43.80000,2.18997,20114.47847,0.00000,0.00365,247.47144
44.10000,2.20498,20255.60141,0.00000,0.00369,249.20769
44.40000,2.22004,20388.74924,0.00000,0.00374,250.84583
44.70000,2.23499,20523.72843,0.00000,0.00379,252.50650
45.00000,2.25000,20651.72344,0.00000,0.00383,254.08124
45.30000,2.26506,20784.48236,0.00000,0.00388,255.71460
45.60000,2.27995,20905.21157,0.00000,0.00394,257.19995
45.90000,2.29508,21030.64805,0.00000,0.00399,258.74321
46.20000,2.30985,21146.27808,0.00000,0.00405,260.16582
46.50000,2.32509,21260.85162,0.00000,0.00410,261.57544
46.80000,2.33992,21368.04312,0.00000,0.00416,262.89423
47.10000,2.35493,21468.24002,0.00000,0.00422,264.12697
47.40000,2.37000,21568.72302,0.00000,0.00429,265.36323
47.70000,2.38488,21659.24609,0.00000,0.00435,266.47694
48.00000,2.40007,21746.87386,0.00000,0.00442,267.55504
48.30000,2.41490,21824.07677,0.00000,0.00450,268.50488
48.60000,2.42996,21898.83888,0.00000,0.00457,269.42469
48.90000,2.44503,21967.22627,0.00000,0.00465,270.26607
49.20000,2.46004,22029.27470,0.00000,0.00473,271.02946
49.50000,2.47499,22086.67845,0.00000,0.00482,271.73571
49.80000,2.48999,22137.50184,0.00000,0.00492,272.36100
50.10000,2.50500,22188.35652,0.00000,0.00502,272.98667
50.40000,2.51995,22228.47342,0.00000,0.00513,273.48023
50.70000,2.53507,22273.59414,0.00000,0.00524,274.03536
51.00000,2.54990,22308.11417,0.00000,0.00535,274.46007
51.30000,2.56503,22344.01554,0.00000,0.00547,274.90177
51.60000,2.57998,22377.17807,0.00000,0.00559,275.30977
51.90000,2.59498,22402.06003,0.00000,0.00571,275.61590
52.20000,2.61011,22434.74871,0.00000,0.00584,276.01807
52.50000,2.62494,22456.03055,0.00000,0.00597,276.27990
52.80000,2.64012,22482.09864,0.00000,0.00611,276.60062
53.10000,2.65495,22503.34620,0.00000,0.00625,276.86203
53.40000,2.66996,22524.27340,0.00000,0.00639,277.11951
53.70000,2.68503,22543.48993,0.00000,0.00654,277.35593
54.00000,2.70003,22562.10595,0.00000,0.00668,277.58496
54.30000,2.71498,22579.09775,0.00000,0.00683,277.79402
54.60000,2.72999,22594.35356,0.00000,0.00698,277.98171
54.90000,2.74505,22613.91729,0.00000,0.00714,278.22241
55.20000,2.75994,22623.33184,0.00000,0.00729,278.33824
55.50000,2.77507,22640.45477,0.00000,0.00745,278.54890
55.80000,2.78984,22652.54110,0.00000,0.00760,278.69760
56.10000,2.80502,22667.13083,0.00000,0.00776,278.87710
56.40000,2.81997,22682.19441,0.00000,0.00792,279.06243
56.70000,2.83492,22689.49002,0.00000,0.00808,279.15219
57.00000,2.85005,22704.84865,0.00000,0.00825,279.34115
57.30000,2.86487,22713.93687,0.00000,0.00841,279.45296
57.60000,2.88018,22726.43745,0.00000,0.00857,279.60676
57.90000,2.89495,22735.58080,0.00000,0.00873,279.71925
58.20000,2.90995,22748.40325,0.00000,0.00890,279.87701
58.50000,2.92502,22758.60310,0.00000,0.00907,280.00250
58.80000,2.94003,22767.05354,0.00000,0.00924,280.10647
59.10000,2.95498,22777.91947,0.00000,0.00940,280.24015
59.40000,2.96992,22784.28525,0.00000,0.00957,280.31847
59.70000,2.98505,22798.57695,0.00000,0.00973,280.49430
60.00000,2.99988,22802.75375,0.00000,0.00990,280.54569
60.30000,3.01506,22814.71938,0.00000,0.01007,280.69291
60.60000,3.02989,22821.08814,0.00000,0.01024,280.77126
60.90000,3.04508,22829.60415,0.00000,0.01041,280.87604
61.20000,3.06009,22841.21215,0.00000,0.01058,281.01885
61.50000,3.07491,22846.11762,0.00000,0.01074,281.07920
61.80000,3.09010,22858.09517,0.00000,0.01091,281.22656
62.10000,3.10493,22864.43859,0.00000,0.01108,281.30461
62.40000,3.12011,22873.17663,0.00000,0.01125,281.41211
62.70000,3.13494,22879.22651,0.00000,0.01142,281.48655
63.00000,3.15001,22891.43652,0.00000,0.01159,281.63677
63.30000,3.16496,22897.65328,0.00000,0.01176,281.71325
63.60000,3.18002,22905.91896,0.00000,0.01192,281.81495
63.90000,3.19497,22915.55852,0.00000,0.01209,281.93354
64.20000,3.21004,22921.34911,0.00000,0.01227,282.00479
64.50000,3.22510,22932.37746,0.00000,0.01243,282.14047
64.80000,3.23987,22934.80486,0.00000,0.01260,282.17034
65.10000,3.25506,22946.93142,0.00000,0.01276,282.31953
65.40000,3.26989,22952.06785,0.00000,0.01293,282.38272
65.70000,3.28501,22959.99974,0.00000,0.01309,282.48031
66.00000,3.30002,22968.45764,0.00000,0.01326,282.58437
66.30000,3.31497,22973.09190,0.00000,0.01343,282.64139
66.60000,3.33016,22984.88170,0.00000,0.01360,282.78644
66.90000,3.34492,22989.52192,0.00000,0.01376,282.84353
67.20000,3.36005,22999.39841,0.00000,0.01393,282.96504
67.50000,3.37500,23004.88502,0.00000,0.01409,283.03254
67.80000,3.39006,23014.16844,0.00000,0.01426,283.14676
68.10000,3.40501,23020.24066,0.00000,0.01442,283.22146
68.40000,3.42002,23025.87032,0.00000,0.01459,283.29073
68.70000,3.43497,23035.33554,0.00000,0.01475,283.40718
69.00000,3.44991,23040.10689,0.00000,0.01492,283.46588
69.30000,3.46498,23050.00573,0.00000,0.01508,283.58767
69.60000,3.47993,23054.35091,0.00000,0.01524,283.64113
69.90000,3.49505,23063.34674,0.00000,0.01541,283.75181
70.20000,3.50988,23070.27429,0.00000,0.01557,283.83704
70.50000,3.52501,23076.59090,0.00000,0.01573,283.91475
70.80000,3.54008,23087.02469,0.00000,0.01589,284.04312
71.10000,3.55496,23089.75458,0.00000,0.01605,284.07670
71.40000,3.57015,23099.97082,0.00000,0.01622,284.20240
71.70000,3.58498,23104.80326,0.00000,0.01638,284.26185
72.00000,3.59999,23112.80519,0.00000,0.01654,284.36030
72.30000,3.61493,23119.44813,0.00000,0.01670,284.44203
72.60000,3.63000,23128.99679,0.00000,0.01686,284.55951
72.90000,3.64501,23134.99004,0.00000,0.01702,284.63324
73.20000,3.66001,23139.11170,0.00000,0.01718,284.68395
73.50000,3.67502,23148.61268,0.00000,0.01733,284.80084
73.80000,3.68991,23150.81209,0.00000,0.01750,284.82790
74.10000,3.70509,23164.91157,0.00000,0.01766,285.00137
74.40000,3.71992,23165.95465,0.00000,0.01782,285.01421
74.70000,3.73505,23175.70746,0.00000,0.01798,285.13420
75.00000,3.75000,23184.20708,0.00000,0.01814,285.23877
75.30000,3.76500,23187.04724,0.00000,0.01829,285.27371
75.60000,3.78001,23197.27987,0.00000,0.01845,285.39960
75.90000,3.79490,23200.98281,0.00000,0.01861,285.44516
76.20000,3.81009,23211.38978,0.00000,0.01877,285.57320
76.50000,3.82491,23215.25067,0.00000,0.01892,285.62070
76.80000,3.84004,23221.96811,0.00000,0.01908,285.70335
77.10000,3.85499,23227.74827,0.00000,0.01924,285.77446
77.40000,3.87005,23235.07220,0.00000,0.01940,285.86457
77.70000,3.88500,23243.81620,0.00000,0.01956,285.97215
78.00000,3.89995,23249.65745,0.00000,0.01971,286.04401
78.30000,3.91502,23256.51795,0.00000,0.01987,286.12842
78.60000,3.92996,23259.10330,0.00000,0.02002,286.16023
78.90000,3.94503,23268.44335,0.00000,0.02017,286.27514
79.20000,3.95986,23271.88551,0.00000,0.02033,286.31749
79.50000,3.97510,23283.58889,0.00000,0.02048,286.46148
79.80000,3.98993,23290.19159,0.00000,0.02064,286.54271
80.10000,4.00506,23295.44425,0.00000,0.02080,286.60734
80.40000,4.02007,23304.45200,0.00000,0.02096,286.71816
80.70000,4.03495,23307.02245,0.00000,0.02110,286.74978
81.00000,4.05014,23316.82295,0.00000,0.02126,286.87036
81.30000,4.06485,23321.42889,0.00000,0.02141,286.92703
81.60000,4.08003,23329.69606,0.00000,0.02157,287.02874
81.90000,4.09492,23334.11574,0.00000,0.02172,287.08312
82.20000,4.10999,23341.52460,0.00000,0.02187,287.17427
82.50000,4.12494,23347.77564,0.00000,0.02203,287.25118
82.80000,4.14000,23352.66620,0.00000,0.02218,287.31135
83.10000,4.15501,23362.17016,0.00000,0.02233,287.42827
83.40000,4.16996,23365.02969,0.00000,0.02248,287.46346
83.70000,4.18503,23373.56210,0.00000,0.02264,287.56843
84.00000,4.19991,23377.76572,0.00000,0.02279,287.62015
84.30000,4.21510,23386.81668,0.00000,0.02295,287.73150
84.60000,4.22993,23393.03344,0.00000,0.02310,287.80799
84.90000,4.24505,23397.45611,0.00000,0.02324,287.86240
85.20000,4.26000,23405.87378,0.00000,0.02340,287.96597
85.50000,4.27489,23409.62589,0.00000,0.02356,288.01213
85.80000,4.29008,23417.74553,0.00000,0.02371,288.11203
86.10000,4.30496,23421.65560,0.00000,0.02386,288.16013
86.40000,4.32003,23429.39824,0.00000,0.02401,288.25539
86.70000,4.33492,23433.17270,0.00000,0.02416,288.30183
87.00000,4.34998,23442.01803,0.00000,0.02431,288.41065
87.30000,4.36499,23447.57020,0.00000,0.02446,288.47896
87.60000,4.38006,23451.16436,0.00000,0.02462,288.52318
87.90000,4.39501,23459.03218,0.00000,0.02477,288.61998
88.20000,4.40995,23462.98993,0.00000,0.02491,288.66868
88.50000,4.42514,23472.74721,0.00000,0.02506,288.78872
88.80000,4.43985,23475.28040,0.00000,0.02521,288.81989
89.10000,4.45509,23484.59512,0.00000,0.02536,288.93449
89.40000,4.46998,23488.68698,0.00000,0.02551,288.98483
89.70000,4.48499,23493.32422,0.00000,0.02566,289.04188
90.00000,4.50006,23502.13528,0.00000,0.02582,289.15029
90.30000,4.51494,23506.84255,0.00000,0.02597,289.20820
90.60000,4.53007,23515.42562,0.00000,0.02612,289.31380
90.90000,4.54490,23517.78746,0.00000,0.02626,289.34286
91.20000,4.55996,23524.81037,0.00000,0.02641,289.42926
91.50000,4.57497,23529.04677,0.00000,0.02655,289.48138
91.80000,4.58998,23535.02661,0.00000,0.02670,289.55495
92.10000,4.60499,23542.45782,0.00000,0.02685,289.64638
92.40000,4.61999,23547.71495,0.00000,0.02700,289.71106
92.70000,4.63506,23556.60796,0.00000,0.02715,289.82047
93.00000,4.65001,23557.85966,0.00000,0.02730,289.83587
93.30000,4.66514,23566.49935,0.00000,0.02744,289.94217
93.60000,4.67990,23571.50614,0.00000,0.02759,290.00377
93.90000,4.69509,23578.65125,0.00000,0.02774,290.09167
94.20000,4.70992,23585.18988,0.00000,0.02789,290.17212
94.50000,4.72498,23587.53532,0.00000,0.02803,290.20098
94.80000,4.74005,23596.44473,0.00000,0.02818,290.31059
95.10000,4.75488,23597.77838,0.00000,0.02832,290.32700
95.40000,4.77007,23606.35698,0.00000,0.02847,290.43254
95.70000,4.78489,23610.74984,0.00000,0.02862,290.48659
96.00000,4.80002,23618.84564,0.00000,0.02877,290.58619
96.30000,4.81503,23622.00767,0.00000,0.02892,290.62509
96.60000,4.83003,23626.51527,0.00000,0.02906,290.68055
96.90000,4.84504,23634.98360,0.00000,0.02920,290.78474
97.20000,4.86011,23638.25887,0.00000,0.02934,290.82504
97.50000,4.87506,23646.28017,0.00000,0.02949,290.92372
97.80000,4.88994,23647.38882,0.00000,0.02963,290.93736
98.10000,4.90513,23656.20285,0.00000,0.02978,291.04580
98.40000,4.91990,23659.58840,0.00000,0.02992,291.08746
98.70000,4.93508,23665.43263,0.00000,0.03007,291.15936
99.00000,4.94997,23673.64317,0.00000,0.03022,291.26037
99.30000,4.96498,23675.03792,0.00000,0.03036,291.27753
99.60000,4.98011,23683.54648,0.00000,0.03050,291.38222
99.90000,4.99493,23683.93689,0.00000,0.03064,291.38702
100.20000,5.01012,23691.98501,0.00000,0.03079,291.48604
100.50000,5.02495,23695.91892,0.00000,0.03093,291.53444
100.80000,5.04002,23701.75868,0.00000,0.03107,291.60628
101.10000,5.05496,23707.45689,0.00000,0.03121,291.67639
101.40000,5.07009,23713.63640,0.00000,0.03135,291.75242
101.70000,5.08504,23718.57762,0.00000,0.03149,291.81321
102.00000,5.10004,23720.72339,0.00000,0.03164,291.83961
102.30000,5.11505,23729.84737,0.00000,0.03178,291.95186
102.60000,5.12994,23730.42107,0.00000,0.03193,291.95892
102.90000,5.14506,23740.38398,0.00000,0.03206,292.08150
103.20000,5.15989,23742.96486,0.00000,0.03220,292.11325
103.50000,5.17508,23748.37250,0.00000,0.03236,292.17978
103.80000,5.18997,23754.14521,0.00000,0.03250,292.25080
104.10000,5.20497,23756.41465,0.00000,0.03264,292.27872
104.40000,5.22004,23763.57019,0.00000,0.03278,292.36676
104.70000,5.23487,23766.74563,0.00000,0.03293,292.40583
105.00000,5.25006,23772.02809,0.00000,0.03307,292.47082
105.30001,5.26494,23776.37178,0.00000,0.03321,292.52426
105.60001,5.28001,23782.38291,0.00000,0.03335,292.59821
105.90001,5.29502,23788.43427,0.00000,0.03348,292.67267
106.20001,5.31002,23793.27416,0.00000,0.03362,292.73221
106.50001,5.32497,23799.12585,0.00000,0.03375,292.80421
106.80001,5.34004,23801.34314,0.00000,0.03389,292.83149
107.10001,5.35505,23809.85171,0.00000,0.03403,292.93617
107.40001,5.36993,23808.90548,0.00000,0.03417,292.92453
107.70001,5.38506,23816.59597,0.00000,0.03431,293.01914
108.00001,5.39989,23819.77290,0.00000,0.03444,293.05823
108.30001,5.41507,23825.70952,0.00000,0.03458,293.13127
108.60001,5.43002,23831.85476,0.00000,0.03472,293.20687
108.90001,5.44491,23832.64899,0.00000,0.03485,293.21665
109.20001,5.46016,23840.73883,0.00000,0.03500,293.31618
109.50001,5.47498,23842.18276,0.00000,0.03513,293.33394
109.80001,5.48999,23848.31160,0.00000,0.03526,293.40935
110.10001,5.50494,23854.29293,0.00000,0.03540,293.48293
110.40001,5.52001,23859.98517,0.00000,0.03553,293.55297
110.70001,5.53495,23860.94034,0.00000,0.03567,293.56472
111.00001,5.55008,23865.86517,0.00000,0.03580,293.62531
111.30001,5.56503,23872.26671,0.00000,0.03594,293.70407
111.60001,5.57997,23873.47519,0.00000,0.03608,293.71894
111.90001,5.59510,23884.34261,0.00000,0.03621,293.85264
112.20001,5.60993,23882.02846,0.00000,0.03634,293.82417
112.50001,5.62511,23890.09446,0.00000,0.03648,293.92341
112.80001,5.63988,23891.32380,0.00000,0.03661,293.93853
113.10001,5.65501,23896.60180,0.00000,0.03674,294.00347
113.40001,5.67002,23903.84078,0.00000,0.03687,294.09253
113.70001,5.68484,23903.84078,0.00000,0.03701,294.09253
114.00001,5.70009,23912.12732,0.00000,0.03715,294.19448
114.30001,5.71492,23913.63233,0.00000,0.03728,294.21300
114.60001,5.73005,23918.91032,0.00000,0.03741,294.27793
114.90001,5.74499,23923.75916,0.00000,0.03754,294.33759
115.20001,5.76006,23929.86417,0.00000,0.03767,294.41270
115.50001,5.77495,23932.23345,0.00000,0.03780,294.44185
115.80001,5.79007,23936.60843,0.00000,0.03793,294.49567
116.10001,5.80496,23942.23064,0.00000,0.03807,294.56485
116.40001,5.81997,23942.29174,0.00000,0.03820,294.56560
116.70001,5.83510,23951.00296,0.00000,0.03834,294.67277
117.00001,5.84986,23951.25777,0.00000,0.03846,294.67591
117.30001,5.86505,23957.61907,0.00000,0.03859,294.75417
117.60001,5.87988,23961.24303,0.00000,0.03872,294.79876
117.90001,5.89506,23962.77785,0.00000,0.03885,294.81764
118.20001,5.91007,23969.83653,0.00000,0.03898,294.90448
118.50001,5.92490,23971.52781,0.00000,0.03911,294.92529
118.80001,5.94015,23979.68024,0.00000,0.03925,295.02559
119.10001,5.95497,23981.31788,0.00000,0.03937,295.04574
119.40001,5.97004,23986.06539,0.00000,0.03950,295.10415
119.70001,5.98499,23988.46298,0.00000,0.03963,295.13365
120.00001,6.00006,23994.36086,0.00000,0.03976,295.20621
120.30001,6.01488,23994.62461,0.00000,0.03989,295.20946
120.60001,6.03001,24000.34517,0.00000,0.04002,295.27984
120.90001,6.04496,24005.97781,0.00000,0.04015,295.34914
121.20001,6.05996,24005.16123,0.00000,0.04027,295.33909
121.50001,6.07509,24014.09447,0.00000,0.04041,295.44900
121.80001,6.08986,24013.38220,0.00000,0.04052,295.44023
122.10001,6.10510,24020.50793,0.00000,0.04065,295.52790
122.40001,6.11993,24024.13934,0.00000,0.04078,295.57258
122.70001,6.13500,24025.23160,0.00000,0.04091,295.58602
123.00001,6.15007,24033.61648,0.00000,0.04104,295.68918
123.30001,6.16501,24034.17379,0.00000,0.04117,295.69604
123.60001,6.18014,24039.36237,0.00000,0.04130,295.75987
123.90001,6.19497,24039.79748,0.00000,0.04143,295.76522
124.20001,6.21004,24047.13929,0.00000,0.04155,295.85555
124.50001,6.22504,24050.59934,0.00000,0.04167,295.89812
124.80001,6.24011,24055.03541,0.00000,0.04180,295.95270
125.10001,6.25494,24057.07985,0.00000,0.04193,295.97785
125.40001,6.27012,24059.32099,0.00000,0.04205,296.00543
125.70001,6.28495,24063.95227,0.00000,0.04218,296.06240
126.00001,6.29990,24065.47070,0.00000,0.04231,296.08109
126.30001,6.31503,24072.53981,0.00000,0.04244,296.16806
126.60001,6.32991,24072.90190,0.00000,0.04256,296.17251
126.90001,6.34510,24078.02194,0.00000,0.04269,296.23551
127.20001,6.35993,24082.28666,0.00000,0.04281,296.28798
127.50001,6.37499,24084.74833,0.00000,0.04294,296.31826
127.80001,6.39012,24092.43882,0.00000,0.04307,296.41288
128.10001,6.40501,24093.37163,0.00000,0.04319,296.42436
128.40001,6.42014,24097.19080,0.00000,0.04332,296.47134
128.70001,6.43496,24097.61548,0.00000,0.04344,296.47657
129.00001,6.45003,24102.92923,0.00000,0.04357,296.54194
129.30001,6.46498,24105.04818,0.00000,0.04369,296.56801
129.60001,6.47998,24110.86708,0.00000,0.04382,296.63960
129.90001,6.49487,24113.23041,0.00000,0.04394,296.66868
130.20001,6.51006,24117.17474,0.00000,0.04407,296.71721
130.50001,6.52501,24121.51545,0.00000,0.04420,296.77061
130.80001,6.53989,24121.43201,0.00000,0.04433,296.76959
131.10001,6.55508,24129.11952,0.00000,0.04445,296.86417
131.40001,6.56991,24131.60801,0.00000,0.04457,296.89478
131.70001,6.58504,24136.51645,0.00000,0.04470,296.95517
132.00001,6.59998,24140.67239,0.00000,0.04482,297.00630
132.30001,6.61499,24141.02256,0.00000,0.04494,297.01061
132.60001,6.63000,24146.20966,0.00000,0.04507,297.07443
132.90001,6.64488,24147.29595,0.00000,0.04519,297.08779
133.20001,6.66007,24153.34731,0.00000,0.04533,297.16225
133.50001,6.67496,24153.89568,0.00000,0.04545,297.16899
133.80001,6.69003,24159.16473,0.00000,0.04558,297.23382
134.10001,6.70497,24159.56408,0.00000,0.04571,297.23873
134.40001,6.72004,24167.38868,0.00000,0.04583,297.33500
134.70001,6.73493,24169.11721,0.00000,0.04595,297.35626
135.00001,6.74999,24168.60312,0.00000,0.04607,297.34994
135.30001,6.76506,24177.67197,0.00000,0.04620,297.46152
135.60001,6.77983,24173.69932,0.00000,0.04633,297.41264
135.90001,6.79508,24181.36299,0.00000,0.04645,297.50693
136.20001,6.80990,24182.59382,0.00000,0.04657,297.52207
136.50001,6.82509,24188.98195,0.00000,0.04670,297.60066
136.80001,6.83998,24191.95473,0.00000,0.04683,297.63724
137.10001,6.85498,24191.99795,0.00000,0.04695,297.63777
137.40001,6.87011,24199.37700,0.00000,0.04708,297.72856
137.70001,6.88500,24197.48455,0.00000,0.04720,297.70527
138.00001,6.90007,24203.40329,0.00000,0.04733,297.77809
138.30001,6.91495,24205.10799,0.00000,0.04746,297.79906
138.60001,6.93002,24210.35618,0.00000,0.04758,297.86363
138.90001,6.94497,24210.44707,0.00000,0.04770,297.86475
139.20001,6.96003,24214.09190,0.00000,0.04783,297.90960
139.50001,6.97492,24215.78914,0.00000,0.04795,297.93048
139.80001,6.99005,24218.68294,0.00000,0.04807,297.96608
140.10001,7.00506,24224.23512,0.00000,0.04820,298.03439
140.40001,7.01988,24224.28578,0.00000,0.04832,298.03501
140.70001,7.03513,24230.49361,0.00000,0.04845,298.11139
141.00001,7.04996,24231.23121,0.00000,0.04858,298.12046
141.30001,7.06509,24235.16959,0.00000,0.04870,298.16892
141.60001,7.07997,24237.16635,0.00000,0.04882,298.19348
141.90001,7.09498,24239.93051,0.00000,0.04895,298.22749
142.20001,7.11005,24244.43215,0.00000,0.04907,298.28288
142.50001,7.12487,24244.36808,0.00000,0.04919,298.28209
142.80001,7.14000,24249.24821,0.00000,0.04931,298.34213
143.10001,7.15495,24249.25268,0.00000,0.04944,298.34218
143.40001,7.17002,24253.86459,0.00000,0.04956,298.39892
143.70001,7.18490,24254.35930,0.00000,0.04969,298.40501
144.00001,7.19997,24259.15152,0.00000,0.04981,298.46397
144.30001,7.21498,24263.28212,0.00000,0.04993,298.51479
144.60001,7.22998,24262.97218,0.00000,0.05006,298.51098
144.90001,7.24505,24267.96854,0.00000,0.05018,298.57245
145.20001,7.25994,24267.61985,0.00000,0.05030,298.56816
145.50001,7.27513,24272.82780,0.00000,0.05043,298.63223
145.80001,7.28989,24275.16282,0.00000,0.05055,298.66096
146.10001,7.30508,24277.60959,0.00000,0.05067,298.69106
146.40001,7.32003,24281.66270,0.00000,0.05080,298.74093
146.70001,7.33503,24281.27080,0.00000,0.05092,298.73611
147.00001,7.35004,24284.83814,0.00000,0.05104,298.78000
147.30001,7.36499,24287.15825,0.00000,0.05116,298.80854
147.60001,7.38006,24289.14607,0.00000,0.05128,298.83300
147.90001,7.39494,24289.67506,0.00000,0.05140,298.83951
148.20001,7.41001,24295.03649,0.00000,0.05153,298.90547
148.50001,7.42496,24296.06169,0.00000,0.05165,298.91808
148.80001,7.44003,24299.48747,0.00000,0.05177,298.96023
149.10001,7.45497,24303.81477,0.00000,0.05189,299.01347
149.40001,7.47004,24303.77901,0.00000,0.05201,299.01303
149.70001,7.48511,24310.47112,0.00000,0.05214,299.09536
150.00001,7.49993,24306.23770,0.00000,0.05226,299.04328
150.30001,7.51518,24312.81060,0.00000,0.05238,299.12415
150.60001,7.52995,24313.48413,0.00000,0.05250,299.13243
150.90001,7.54507,24317.67583,0.00000,0.05263,299.18400
151.20001,7.55996,24321.24466,0.00000,0.05274,299.22791
151.50001,7.57497,24320.44595,0.00000,0.05287,299.21809
151.80001,7.59004,24324.51993,0.00000,0.05298,299.26821
152.10001,7.60492,24323.55881,0.00000,0.05310,299.25638
152.40001,7.62005,24327.91591,0.00000,0.05322,299.30999
152.70001,7.63494,24330.25390,0.00000,0.05334,299.33875
153.00001,7.65001,24335.59895,0.00000,0.05346,299.40451
153.30001,7.66501,24337.39752,0.00000,0.05359,299.42664
153.60001,7.68008,24339.23036,0.00000,0.05371,299.44919
153.90001,7.69503,24342.46689,0.00000,0.05383,299.48901
154.20001,7.71009,24341.69650,0.00000,0.05395,299.47953
154.50001,7.72504,24347.61077,0.00000,0.05407,299.55230
154.80001,7.73987,24346.40974,0.00000,0.05418,299.53752
155.10001,7.75518,24352.69058,0.00000,0.05430,299.61480
155.40001,7.76988,24350.17973,0.00000,0.05442,299.58390
155.70001,7.78501,24353.67256,0.00000,0.05454,299.62688
156.00001,7.79996,24357.30845,0.00000,0.05467,299.67161
156.30001,7.81496,24357.61839,0.00000,0.05479,299.67542
156.60001,7.83009,24363.24507,0.00000,0.05491,299.74465
156.90001,7.84486,24360.85492,0.00000,0.05503,299.71524
157.20001,7.86005,24367.84655,0.00000,0.05515,299.80126
157.50001,7.87499,24366.02265,0.00000,0.05527,299.77882
157.80001,7.89000,24371.10990,0.00000,0.05538,299.84141
158.10001,7.90495,24373.15136,0.00000,0.05550,299.86653
158.40001,7.92007,24375.40591,0.00000,0.05562,299.89427
158.70001,7.93496,24379.02391,0.00000,0.05575,299.93878
159.00001,7.95003,24374.93503,0.00000,0.05586,299.88847
159.30001,7.96510,24382.82371,0.00000,0.05598,299.98553
159.60001,7.97986,24379.26382,0.00000,0.05610,299.94173
159.90001,7.99517,24384.58502,0.00000,0.05622,300.00720
160.20001,8.00988,24385.83672,0.00000,0.05633,300.02260
160.50001,8.02501,24387.31790,0.00000,0.05646,300.04082
160.80001,8.04001,24389.69761,0.00000,0.05658,300.07010
161.10001,8.05496,24388.47423,0.00000,0.05669,300.05505
161.40001,8.07003,24393.76116,0.00000,0.05682,300.12009
161.70001,8.08491,24394.19478,0.00000,0.05693,300.12543
162.00001,8.10004,24399.10173,0.00000,0.05704,300.18580
162.30001,8.11499,24398.59360,0.00000,0.05716,300.17955
162.60001,8.13000,24401.45761,0.00000,0.05727,300.21478
162.90001,8.14494,24402.08644,0.00000,0.05738,300.22252
163.20001,8.16013,24406.54933,0.00000,0.05751,300.27743
163.50001,8.17496,24407.53281,0.00000,0.05763,300.28953
163.80001,8.19002,24408.08266,0.00000,0.05775,300.29629
164.10001,8.20509,24411.93759,0.00000,0.05786,300.34372
164.40001,8.21986,24410.05111,0.00000,0.05798,300.32051
164.70001,8.23511,24415.71653,0.00000,0.05810,300.39021
165.00001,8.24993,24415.72547,0.00000,0.05821,300.39032
165.30001,8.26500,24417.44208,0.00000,0.05833,300.41144
165.60001,8.28001,24422.06591,0.00000,0.05844,300.46833
165.90001,8.29490,24421.96757,0.00000,0.05856,300.46712
166.20001,8.31008,24426.50348,0.00000,0.05868,300.52293
166.50001,8.32491,24426.64653,0.00000,0.05879,300.52469
166.80001,8.33998,24429.88157,0.00000,0.05891,300.56449
167.10001,8.35498,24430.13191,0.00000,0.05903,300.56757
167.40001,8.36999,24433.92128,0.00000,0.05915,300.61419
167.70001,8.38488,24433.76482,0.00000,0.05927,300.61226
168.00001,8.40012,24435.65577,0.00000,0.05939,300.63553
168.30001,8.41501,24437.71511,0.00000,0.05950,300.66087
168.60001,8.42996,24437.25169,0.00000,0.05962,300.65516
168.90001,8.44515,24443.17490,0.00000,0.05974,300.72804
169.20001,8.45985,24440.22298,0.00000,0.05986,300.69172
169.50001,8.47510,24444.15540,0.00000,0.05997,300.74010
169.80001,8.48993,24445.60528,0.00000,0.06009,300.75794
170.10001,8.50494,24446.32053,0.00000,0.06020,300.76674
170.40001,8.52000,24451.27070,0.00000,0.06032,300.82764
170.70001,8.53489,24451.53892,0.00000,0.06043,300.83094
171.00001,8.55002,24454.01549,0.00000,0.06056,300.86141
171.30001,8.56496,24454.69350,0.00000,0.06068,300.86975
171.60001,8.58009,24456.98678,0.00000,0.06079,300.89797
171.90001,8.59498,24456.36839,0.00000,0.06091,300.89036
172.20001,8.61005,24461.41690,0.00000,0.06103,300.95247
172.50001,8.62499,24461.19189,0.00000,0.06115,300.94970
172.80001,8.64012,24462.33481,0.00000,0.06127,300.96376
173.10001,8.65501,24464.50442,0.00000,0.06139,300.99046
173.40001,8.66995,24462.28713,0.00000,0.06150,300.96318
173.70001,8.68514,24468.32210,0.00000,0.06163,301.03743
174.00001,8.69985,24466.27170,0.00000,0.06174,301.01220
174.30001,8.71504,24470.22498,0.00000,0.06186,301.06084
174.60001,8.72992,24471.66741,0.00000,0.06199,301.07859
174.90001,8.74499,24472.36478,0.00000,0.06211,301.08717
175.20001,8.76012,24476.39555,0.00000,0.06222,301.13676
175.50001,8.77500,24474.85775,0.00000,0.06234,301.11784
175.80001,8.79013,24478.69480,0.00000,0.06245,301.16504
176.10001,8.80502,24478.69182,0.00000,0.06258,301.16501
176.40001,8.82009,24482.17869,0.00000,0.06269,301.20791
176.70001,8.83491,24479.91222,0.00000,0.06281,301.18002
177.00001,8.85010,24483.50787,0.00000,0.06293,301.22426
177.30001,8.86493,24483.53022,0.00000,0.06304,301.22454
177.60001,8.88005,24482.88202,0.00000,0.06316,301.21656
177.90001,8.89500,24488.11233,0.00000,0.06328,301.28091
178.20001,8.90995,24486.43148,0.00000,0.06340,301.26023
178.50001,8.92514,24491.15813,0.00000,0.06351,301.31838
178.80001,8.93984,24489.27760,0.00000,0.06363,301.29525
179.10001,8.95509,24493.53933,0.00000,0.06375,301.34768
179.40001,8.96998,24495.19485,0.00000,0.06387,301.36805
179.70001,8.98499,24496.23793,0.00000,0.06399,301.38088
180.00001,9.00005,24499.43125,0.00000,0.06411,301.42017
180.30001,9.01500,24498.75921,0.00000,0.06423,301.41190
180.60001,9.03007,24500.37599,0.00000,0.06434,301.43179
180.90001,9.04501,24501.02419,0.00000,0.06446,301.43977
181.20001,9.06008,24503.82262,0.00000,0.06457,301.47420
181.50001,9.07491,24503.98952,0.00000,0.06470,301.47625
181.80001,9.09009,24507.97111,0.00000,0.06482,301.52524
182.10001,9.10492,24507.29758,0.00000,0.06494,301.51695
182.40001,9.12005,24505.49304,0.00000,0.06506,301.49475
182.70001,9.13500,24510.11240,0.00000,0.06518,301.55158
183.00001,9.14983,24506.36625,0.00000,0.06529,301.50549
183.30001,9.16507,24513.62014,0.00000,0.06541,301.59474
183.60001,9.17990,24513.37427,0.00000,0.06553,301.59171
183.90001,9.19503,24513.85707,0.00000,0.06565,301.59765
184.20001,9.20997,24515.82998,0.00000,0.06577,301.62192
184.50001,9.22498,24516.37834,0.00000,0.06589,301.62867
184.80001,9.24005,24519.64319,0.00000,0.06601,301.66884
185.10001,9.25511,24518.94432,0.00000,0.06613,301.66024
185.40001,9.27000,24520.55067,0.00000,0.06625,301.68000
185.70001,9.28501,24518.72677,0.00000,0.06636,301.65756
186.00001,9.30008,24523.02724,0.00000,0.06648,301.71047
186.30001,9.31484,24519.52100,0.00000,0.06660,301.66734
186.60001,9.33003,24523.67991,0.00000,0.06672,301.71850
186.90001,9.34492,24525.49785,0.00000,0.06684,301.74087
187.20001,9.36005,24524.44136,0.00000,0.06696,301.72787
187.50001,9.37505,24528.59581,0.00000,0.06708,301.77898
187.80001,9.38988,24526.18778,0.00000,0.06719,301.74936
188.10001,9.40513,24531.18861,0.00000,0.06732,301.81088
188.40001,9.41989,24531.67439,0.00000,0.06743,301.81686
188.70001,9.43502,24532.33749,0.00000,0.06755,301.82502
189.00001,9.44997,24534.02132,0.00000,0.06767,301.84573
189.30001,9.46498,24533.39696,0.00000,0.06779,301.83805
189.60001,9.47998,24533.95426,0.00000,0.06791,301.84491
189.90001,9.49499,24533.82909,0.00000,0.06803,301.84337
190.20001,9.51000,24538.16980,0.00000,0.06815,301.89677
190.50001,9.52494,24536.26841,0.00000,0.06827,301.87338
190.80001,9.54001,24539.70611,0.00000,0.06839,301.91568
191.10001,9.55484,24535.88396,0.00000,0.06851,301.86865
191.40001,9.57009,24540.13228,0.00000,0.06862,301.92092
191.70001,9.58497,24542.59247,0.00000,0.06875,301.95119
192.00001,9.59998,24540.65084,0.00000,0.06887,301.92730
192.30001,9.61505,24546.61578,0.00000,0.06899,302.00069
192.60001,9.62981,24542.75489,0.00000,0.06911,301.95319
192.90001,9.64512,24546.33415,0.00000,0.06923,301.99722
193.20001,9.65995,24545.57866,0.00000,0.06935,301.98793
193.50001,9.67502,24546.38779,0.00000,0.06947,301.99788
193.80001,9.69002,24549.38143,0.00000,0.06959,302.03471
194.10001,9.70503,24549.66158,0.00000,0.06971,302.03816
194.40001,9.72004,24551.08464,0.00000,0.06983,302.05567
194.70001,9.73504,24552.70886,0.00000,0.06995,302.07565
195.00001,9.74999,24551.16808,0.00000,0.07007,302.05669
195.30001,9.76494,24550.38726,0.00000,0.07019,302.04709
195.60001,9.78007,24554.51488,0.00000,0.07032,302.09787
195.90001,9.79483,24551.78499,0.00000,0.07044,302.06428
196.20001,9.81002,24554.53873,0.00000,0.07056,302.09816
196.50001,9.82491,24556.66065,0.00000,0.07067,302.12427
196.80001,9.83997,24555.21524,0.00000,0.07079,302.10649
197.10001,9.85510,24559.83013,0.00000,0.07091,302.16326
197.40001,9.86987,24556.40137,0.00000,0.07104,302.12108
197.70001,9.88512,24561.57058,0.00000,0.07115,302.18468
198.00001,9.89994,24559.85993,0.00000,0.07128,302.16363
198.30001,9.91507,24560.45300,0.00000,0.07141,302.17093
198.60001,9.93002,24560.18329,0.00000,0.07153,302.16761
198.90001,9.94503,24559.84801,0.00000,0.07165,302.16348
199.20001,9.95997,24561.82688,0.00000,0.07177,302.18783
199.50001,9.97492,24559.52168,0.00000,0.07189,302.15947
199.80001,9.98999,24563.96371,0.00000,0.07201,302.21412
200.10001,10.00499,24561.77175,0.00000,0.07213,302.18715
200.40001,10.02006,24564.98146,0.00000,0.07225,302.22664
200.70001,10.03489,24562.87146,0.00000,0.07237,302.20068
201.00001,10.05001,24566.38068,0.00000,0.07250,302.24386
201.30001,10.06496,24570.13726,0.00000,0.07262,302.29007
201.60001,10.07991,24565.56261,0.00000,0.07273,302.23379
201.90001,10.09510,24569.84371,0.00000,0.07286,302.28646
202.20001,10.10992,24568.30889,0.00000,0.07298,302.26758
202.50001,10.12511,24569.20892,0.00000,0.07311,302.27865
202.80001,10.13994,24569.48459,0.00000,0.07323,302.28204
203.10001,10.15501,24571.72573,0.00000,0.07335,302.30962
203.40001,10.17001,24570.90616,0.00000,0.07347,302.29953
203.70001,10.18502,24570.14918,0.00000,0.07359,302.29022
204.00001,10.20003,24571.40833,0.00000,0.07371,302.30571
204.30001,10.21498,24571.72424,0.00000,0.07383,302.30960
204.60001,10.22998,24575.00696,0.00000,0.07395,302.34999
204.90001,10.24493,24572.70771,0.00000,0.07407,302.32170
205.20001,10.26006,24575.68049,0.00000,0.07419,302.35827
205.50001,10.27494,24574.64188,0.00000,0.07432,302.34550
205.80001,10.29007,24575.21111,0.00000,0.07444,302.35250
206.10001,10.30496,24577.55059,0.00000,0.07457,302.38128
206.40001,10.31996,24574.67467,0.00000,0.07468,302.34590
206.70001,10.33515,24579.17184,0.00000,0.07481,302.40123
207.00001,10.34998,24575.00994,0.00000,0.07493,302.35002
207.30001,10.36511,24574.99355,0.00000,0.07505,302.34982
207.60001,10.37999,24577.81881,0.00000,0.07517,302.38458
207.90001,10.39500,24575.53148,0.00000,0.07529,302.35644
208.20001,10.40995,24576.85769,0.00000,0.07541,302.37276
208.50001,10.42490,24575.30946,0.00000,0.07553,302.35371
208.80001,10.44002,24578.01700,0.00000,0.07565,302.38702
209.10001,10.45497,24575.64622,0.00000,0.07577,302.35785
209.40001,10.47004,24578.95279,0.00000,0.07589,302.39853
209.70001,10.48492,24577.34048,0.00000,0.07601,302.37870
210.00001,10.50005,24580.84524,0.00000,0.07613,302.42182
210.30001,10.51494,24581.11644,0.00000,0.07626,302.42515
210.60001,10.53013,24580.91229,0.00000,0.07638,302.42264
210.90001,10.54501,24582.80176,0.00000,0.07650,302.44589
211.20001,10.56002,24577.82477,0.00000,0.07662,302.38466
211.50001,10.57509,24582.24744,0.00000,0.07673,302.43907
211.80001,10.58991,24579.34916,0.00000,0.07685,302.40341
212.10001,10.60516,24581.49642,0.00000,0.07697,302.42983
212.40001,10.61993,24578.36270,0.00000,0.07709,302.39127
212.70001,10.63500,24579.95117,0.00000,0.07721,302.41082
213.00001,10.65000,24581.13283,0.00000,0.07733,302.42535
213.30001,10.66501,24581.64394,0.00000,0.07745,302.43164
213.60001,10.68002,24584.39171,0.00000,0.07756,302.46545
213.90001,10.69497,24581.57539,0.00000,0.07769,302.43080
214.20001,10.71003,24583.94319,0.00000,0.07780,302.45993
214.50001,10.72492,24581.70652,0.00000,0.07792,302.43241
214.80001,10.74005,24583.48870,0.00000,0.07804,302.45434
215.10001,10.75487,24583.39185,0.00000,0.07816,302.45315
215.40001,10.77006,24583.87613,0.00000,0.07828,302.45911
215.70001,10.78495,24585.94888,0.00000,0.07840,302.48461
216.00001,10.79996,24582.36814,0.00000,0.07852,302.44055
216.30001,10.81514,24585.96975,0.00000,0.07864,302.48486
216.60001,10.82991,24581.85256,0.00000,0.07875,302.43421
216.90001,10.84504,24584.49155,0.00000,0.07887,302.46668
217.20001,10.85992,24583.97001,0.00000,0.07899,302.46026
217.50001,10.87505,24586.76398,0.00000,0.07910,302.49464
217.80001,10.89000,24584.89686,0.00000,0.07922,302.47166
218.10001,10.90495,24582.61102,0.00000,0.07934,302.44354
218.40001,10.92001,24585.40499,0.00000,0.07946,302.47792
218.70001,10.93496,24584.62268,0.00000,0.07958,302.46829
219.00001,10.95003,24587.47327,0.00000,0.07970,302.50336
219.30001,10.96491,24583.50211,0.00000,0.07981,302.45450
219.60001,10.98010,24586.09939,0.00000,0.07993,302.48646
219.90001,10.99493,24583.81206,0.00000,0.08004,302.45832
220.20001,11.01012,24585.14273,0.00000,0.08016,302.47469
220.50001,11.02494,24586.41082,0.00000,0.08028,302.49029
220.80001,11.03995,24584.09816,0.00000,0.08040,302.46184
221.10001,11.05514,24585.62553,0.00000,0.08051,302.48063
221.40001,11.06991,24580.91825,0.00000,0.08063,302.42271
221.70001,11.08503,24582.22210,0.00000,0.08075,302.43876
222.00001,11.09998,24583.34267,0.00000,0.08086,302.45254
222.30001,11.11505,24584.45728,0.00000,0.08097,302.46626
222.60001,11.12999,24585.34837,0.00000,0.08109,302.47722
222.90001,11.14500,24583.98789,0.00000,0.08121,302.46048
223.20001,11.16007,24586.47043,0.00000,0.08133,302.49102
223.50001,11.17502,24582.95226,0.00000,0.08144,302.44774
223.80001,11.19002,24585.07121,0.00000,0.08156,302.47381
224.10001,11.20491,24581.85405,0.00000,0.08168,302.43423
224.40001,11.22010,24585.11740,0.00000,0.08179,302.47438
224.70001,11.23486,24582.71384,0.00000,0.08190,302.44481
225.00001,11.25011,24581.29525,0.00000,0.08202,302.42735
225.30001,11.26500,24583.53937,0.00000,0.08213,302.45496
225.60001,11.27989,24579.21356,0.00000,0.08224,302.40174
225.90001,11.29513,24584.24270,0.00000,0.08236,302.46362
226.20001,11.30984,24583.04763,0.00000,0.08248,302.44891
226.50001,11.32503,24583.56321,0.00000,0.08259,302.45526
226.80001,11.33991,24583.13257,0.00000,0.08271,302.44996
227.10001,11.35498,24580.62619,0.00000,0.08282,302.41912
227.40001,11.36993,24582.06862,0.00000,0.08294,302.43687
227.70001,11.38494,24581.53367,0.00000,0.08304,302.43029
228.00001,11.40000,24583.64069,0.00000,0.08316,302.45621
228.30001,11.41495,24580.57255,0.00000,0.08327,302.41846
228.60001,11.43008,24581.31760,0.00000,0.08339,302.42763
228.90001,11.44496,24579.79769,0.00000,0.08350,302.40893
229.20001,11.46009,24580.46824,0.00000,0.08361,302.41718
229.50001,11.47498,24581.11793,0.00000,0.08373,302.42517
229.80001,11.49005,24578.67116,0.00000,0.08383,302.39507
230.10001,11.50499,24580.11657,0.00000,0.08394,302.41285
230.40001,11.51988,24576.52241,0.00000,0.08406,302.36863
230.70001,11.53513,24579.97054,0.00000,0.08417,302.41105
231.00001,11.54989,24577.28237,0.00000,0.08428,302.37798
231.30001,11.56496,24576.51943,0.00000,0.08439,302.36860
231.60001,11.57997,24577.66682,0.00000,0.08451,302.38271
231.90001,11.59504,24577.06034,0.00000,0.08461,302.37525
232.20001,11.60998,24576.09028,0.00000,0.08473,302.36332
232.50001,11.62505,24573.13091,0.00000,0.08483,302.32691
232.80001,11.64006,24574.08309,0.00000,0.08494,302.33862
233.10001,11.65500,24572.36946,0.00000,0.08505,302.31754
233.40001,11.67013,24573.89832,0.00000,0.08515,302.33635
233.70001,11.68490,24569.05097,0.00000,0.08526,302.27671
234.00001,11.70015,24570.40995,0.00000,0.08537,302.29343
234.30001,11.71491,24568.70824,0.00000,0.08548,302.27249
234.60001,11.72998,24567.46399,0.00000,0.08558,302.25718
234.90001,11.74505,24570.49936,0.00000,0.08569,302.29453
235.20001,11.75988,24566.52373,0.00000,0.08580,302.24562
235.50001,11.77518,24568.34465,0.00000,0.08591,302.26802
235.80001,11.78989,24565.24670,0.00000,0.08601,302.22991
236.10001,11.80502,24565.04852,0.00000,0.08611,302.22747
236.40001,11.81996,24565.26756,0.00000,0.08621,302.23016
236.70001,11.83497,24565.11408,0.00000,0.08631,302.22827
237.00001,11.84998,24562.48701,0.00000,0.08642,302.19595
237.30001,11.86504,24560.42320,0.00000,0.08652,302.17056
237.60001,11.88005,24560.51409,0.00000,0.08661,302.17168
237.90001,11.89500,24554.30627,0.00000,0.08671,302.09530
238.20001,11.91007,24558.20292,0.00000,0.08682,302.14324
238.50001,11.92489,24553.44796,0.00000,0.08691,302.08474
238.80001,11.94008,24555.42684,0.00000,0.08701,302.10909
239.10001,11.95491,24554.48806,0.00000,0.08711,302.09754
239.40001,11.96998,24550.70168,0.00000,0.08720,302.05096
239.70001,11.98510,24553.66850,0.00000,0.08731,302.08746
240.00001,11.99987,24548.02245,0.00000,0.08740,302.01799
240.30001,12.01506,24548.97612,0.00000,0.08749,302.02973
240.60001,12.02988,24545.73959,0.00000,0.08759,301.98991
240.90001,12.04501,24544.36570,0.00000,0.08768,301.97300
241.20001,12.06002,24540.92801,0.00000,0.08777,301.93071
241.50001,12.07503,24540.20381,0.00000,0.08786,301.92180
241.80001,12.09003,24539.03258,0.00000,0.08795,301.90739
242.10001,12.10510,24536.29225,0.00000,0.08804,301.87367
242.40001,12.11999,24534.17927,0.00000,0.08812,301.84768
242.70001,12.13499,24528.72097,0.00000,0.08821,301.78052
243.00001,12.15012,24529.20377,0.00000,0.08829,301.78646
243.30001,12.16489,24523.20606,0.00000,0.08838,301.71267
243.60001,12.18008,24523.32675,0.00000,0.08846,301.71416
243.90001,12.19496,24522.32242,0.00000,0.08854,301.70180
244.20001,12.20997,24516.10416,0.00000,0.08862,301.62530
244.50001,12.22510,24516.37238,0.00000,0.08870,301.62860
244.80001,12.23993,24509.42397,0.00000,0.08877,301.54311
245.10001,12.25511,24507.70885,0.00000,0.08885,301.52201
245.40001,12.26994,24503.27426,0.00000,0.08891,301.46745
245.70001,12.28495,24498.49248,0.00000,0.08899,301.40862
246.00001,12.30001,24494.92961,0.00000,0.08906,301.36478
246.30001,12.31496,24489.32379,0.00000,0.08912,301.29581
246.60001,12.32997,24484.04431,0.00000,0.08919,301.23086
246.90001,12.34503,24477.59062,0.00000,0.08925,301.15146
247.20001,12.36004,24475.48062,0.00000,0.08931,301.12550
247.50001,12.37493,24466.30150,0.00000,0.08937,301.01257
247.80001,12.39006,24463.60737,0.00000,0.08943,300.97942
248.10001,12.40494,24455.26570,0.00000,0.08948,300.87679
248.40001,12.42007,24447.02834,0.00000,0.08954,300.77545
248.70001,12.43496,24441.26159,0.00000,0.08959,300.70450
249.00001,12.44997,24429.85028,0.00000,0.08964,300.56410
249.30001,12.46509,24425.80611,0.00000,0.08969,300.51435
249.60001,12.47986,24413.28764,0.00000,0.08973,300.36033
249.90001,12.49511,24403.15932,0.00000,0.08977,300.23572
250.20001,12.50993,24390.22064,0.00000,0.08981,300.07653
250.50001,12.52506,24379.69744,0.00000,0.08985,299.94706
250.80001,12.54001,24363.28530,0.00000,0.08989,299.74514
251.10001,12.55502,24349.97857,0.00000,0.08992,299.58143
251.40001,12.56996,24335.88356,0.00000,0.08995,299.40802
251.70001,12.58503,24316.27363,0.00000,0.08998,299.16675
252.00001,12.60010,24301.54383,0.00000,0.09001,298.98553
252.30001,12.61492,24278.34719,0.00000,0.09003,298.70014
252.60001,12.63011,24262.20328,0.00000,0.09005,298.50152
252.90001,12.64488,24238.14088,0.00000,0.09007,298.20547
253.20001,12.66007,24214.44356,0.00000,0.09008,297.91392
253.50001,12.67495,24188.96854,0.00000,0.09010,297.60050
253.80001,12.68996,24157.60159,0.00000,0.09011,297.21459
254.10001,12.70509,24128.96007,0.00000,0.09011,296.86221
254.40001,12.71985,24092.45521,0.00000,0.09012,296.41308
254.70001,12.73510,24056.78630,0.00000,0.09012,295.97424
255.00001,12.75005,24016.28494,0.00000,0.09013,295.47595
255.30001,12.76500,23974.65557,0.00000,0.09013,294.96377
255.60001,12.77994,23925.34316,0.00000,0.09012,294.35708
255.90001,12.79507,23880.55325,0.00000,0.09012,293.80602
256.20001,12.80996,23830.59412,0.00000,0.09012,293.19136
256.50001,12.82502,23775.56562,0.00000,0.09011,292.51434
256.80001,12.84003,23715.41411,0.00000,0.09010,291.77429
257.10001,12.85492,23641.86496,0.00000,0.09009,290.86940
257.40001,12.87011,23561.48511,0.00000,0.09007,289.88048
257.70001,12.88493,23457.83859,0.00000,0.09005,288.60530
258.00001,12.90006,23349.29705,0.00000,0.09003,287.26989
258.30001,12.91501,23149.08653,0.00000,0.08998,284.80667
258.40201,12.92027,21601.45640,0.00000,0.08804,265.76595
258.40801,12.92105,18485.45671,0.00000,0.08258,227.42934
258.41401,12.92212,14623.91913,0.00000,0.07801,179.92026
258.41601,12.92242,13320.34469,0.00000,0.07634,163.88219