File: scratch/college-stuff/ME Lab/ME lab Fall 2013/group5/group5.is_tens_RawData/Specimen_RawData_5.csv
Time,Extension,Load,Strain 2,Tensile strain,Tensile stress
(sec),(mm),(N),(mm/mm),(mm/mm),(MPa)
0.00000,0.00000,-0.13819,0.00000,0.00000,-0.00165
0.10000,0.00173,1.46055,0.00000,0.00000,0.01749
0.20000,0.00753,2.13447,0.00000,0.00001,0.02555
0.30000,0.01363,2.78935,0.00000,0.00001,0.03339
0.40000,0.01949,2.80004,0.00000,0.00001,0.03352
0.50000,0.02469,3.36208,0.00000,0.00001,0.04025
0.60000,0.03001,3.25536,0.00000,0.00001,0.03897
0.70000,0.03498,3.34274,0.00000,0.00002,0.04002
0.80000,0.04012,4.01243,0.00000,0.00002,0.04804
0.90000,0.04496,4.14445,0.00000,0.00001,0.04962
1.00000,0.05004,4.17693,0.00000,0.00002,0.05001
1.10000,0.05495,4.81293,0.00000,0.00002,0.05762
1.20000,0.06009,5.06023,0.00000,0.00002,0.06058
1.30000,0.06493,4.29916,0.00000,0.00002,0.05147
1.40000,0.07001,5.09375,0.00000,0.00002,0.06098
1.50000,0.07498,5.10019,0.00000,0.00002,0.06106
1.60000,0.08012,5.38487,0.00000,0.00002,0.06447
1.70000,0.08502,5.98193,0.00000,0.00002,0.07162
1.80000,0.09004,6.20287,0.00000,0.00003,0.07426
1.90000,0.09501,5.55447,0.00000,0.00003,0.06650
2.00000,0.10003,6.55344,0.00000,0.00003,0.07846
2.10000,0.10505,6.52861,0.00000,0.00002,0.07816
2.20000,0.11001,6.07847,0.00000,0.00002,0.07277
2.30000,0.11503,6.86227,0.00000,0.00002,0.08216
2.40000,0.11988,6.77845,0.00000,0.00002,0.08115
2.50000,0.12508,6.47980,0.00000,0.00002,0.07758
2.60000,0.12998,6.75968,0.00000,0.00002,0.08093
2.70000,0.13512,7.09694,0.00000,0.00002,0.08497
2.80000,0.13991,8.02360,0.00000,0.00002,0.09606
2.90000,0.14511,8.01281,0.00000,0.00002,0.09593
3.00000,0.14995,8.25962,0.00000,0.00002,0.09889
3.10000,0.15515,9.06413,0.00000,0.00001,0.10852
3.20000,0.15994,8.64309,0.00000,0.00002,0.10348
3.30000,0.16508,9.47883,0.00000,0.00001,0.11348
3.40000,0.16992,9.43828,0.00000,0.00001,0.11300
3.50000,0.17506,10.07687,0.00000,0.00001,0.12064
3.60000,0.17997,10.91028,0.00000,0.00001,0.13062
3.70000,0.18505,11.83930,0.00000,0.00001,0.14174
3.80000,0.18995,12.70914,0.00000,0.00001,0.15216
3.90000,0.19503,12.82177,0.00000,0.00000,0.15350
4.00000,0.20006,13.84194,0.00000,0.00000,0.16572
4.10000,0.20502,15.00697,0.00000,0.00000,0.17967
4.20000,0.21004,15.83344,0.00000,-0.00001,0.18956
4.30000,0.21500,16.72464,0.00000,-0.00001,0.20023
4.40000,0.22009,18.11097,0.00000,-0.00001,0.21683
4.50000,0.22505,19.19112,0.00000,-0.00002,0.22976
4.60000,0.23007,22.15736,0.00000,-0.00002,0.26527
4.70000,0.23491,26.53597,0.00000,-0.00003,0.31769
4.80000,0.24005,29.39813,0.00000,-0.00003,0.35196
4.90000,0.24502,36.52569,0.00000,-0.00003,0.43729
5.00000,0.25016,48.72482,0.00000,-0.00003,0.58334
5.10000,0.25494,62.39717,0.00000,-0.00004,0.74703
5.20000,0.26008,80.20552,0.00000,-0.00003,0.96024
5.30000,0.26499,98.79289,0.00000,-0.00004,1.18277
5.40000,0.27013,123.89057,0.00000,-0.00002,1.48324
5.50000,0.27497,149.18711,0.00000,-0.00002,1.78610
5.60000,0.28005,178.37739,0.00000,-0.00001,2.13557
5.70000,0.28490,210.05182,0.00000,0.00000,2.51478
5.80000,0.29004,247.84296,0.00000,0.00002,2.96723
5.90000,0.29500,286.58521,0.00000,0.00004,3.43106
6.00000,0.30008,328.66832,0.00000,0.00006,3.93488
6.10000,0.30499,371.31682,0.00000,0.00008,4.44548
6.20000,0.31001,413.30783,0.00000,0.00010,4.94821
6.30000,0.31491,457.68232,0.00000,0.00012,5.47947
6.40000,0.32005,501.18016,0.00000,0.00014,6.00023
6.50000,0.32496,544.79935,0.00000,0.00017,6.52245
6.60000,0.32998,586.71180,0.00000,0.00019,7.02423
6.70000,0.33494,632.58661,0.00000,0.00021,7.57346
6.80000,0.33990,675.70927,0.00000,0.00024,8.08973
6.90000,0.34505,721.75427,0.00000,0.00026,8.64099
7.00000,0.34995,764.42999,0.00000,0.00029,9.15191
7.10000,0.35503,812.49876,0.00000,0.00031,9.72740
7.20000,0.35987,856.64736,0.00000,0.00033,10.25596
7.30000,0.36507,901.43001,0.00000,0.00036,10.79211
7.40000,0.36992,943.60504,0.00000,0.00038,11.29703
7.50000,0.37506,989.12362,0.00000,0.00041,11.84199
7.60000,0.37984,1033.58952,0.00000,0.00043,12.37435
7.70000,0.38504,1079.43621,0.00000,0.00045,12.92323
7.80000,0.38989,1122.80892,0.00000,0.00048,13.44250
7.90000,0.39503,1167.14789,0.00000,0.00050,13.97333
8.00000,0.39993,1210.17797,0.00000,0.00053,14.48850
8.10000,0.40501,1255.53310,0.00000,0.00055,15.03150
8.20000,0.40992,1298.05505,0.00000,0.00057,15.54058
8.30000,0.41506,1342.11443,0.00000,0.00059,16.06807
8.40000,0.41996,1386.05591,0.00000,0.00062,16.59415
8.50000,0.42498,1428.95905,0.00000,0.00065,17.10779
8.60000,0.42995,1474.04242,0.00000,0.00067,17.64754
8.70000,0.43497,1515.46719,0.00000,0.00069,18.14348
8.80000,0.43999,1557.64911,0.00000,0.00072,18.64850
8.90000,0.44501,1599.70652,0.00000,0.00074,19.15201
9.00000,0.45004,1645.46538,0.00000,0.00076,19.69985
9.10000,0.45494,1686.96269,0.00000,0.00079,20.19666
9.20000,0.46002,1729.96446,0.00000,0.00081,20.71149
9.30000,0.46504,1770.07094,0.00000,0.00083,21.19165
9.40000,0.47006,1813.33106,0.00000,0.00085,21.70957
9.50000,0.47491,1851.96809,0.00000,0.00088,22.17214
9.60000,0.48005,1894.99110,0.00000,0.00090,22.68722
9.70000,0.48495,1933.57263,0.00000,0.00092,23.14913
9.80000,0.49015,1975.97612,0.00000,0.00094,23.65679
9.90000,0.49494,2014.66642,0.00000,0.00096,24.12000
10.00000,0.50008,2056.14995,0.00000,0.00099,24.61665
10.10000,0.50486,2093.09328,0.00000,0.00100,25.05894
10.20000,0.51012,2133.42216,0.00000,0.00103,25.54177
10.30000,0.51497,2171.72336,0.00000,0.00105,26.00032
10.40000,0.52005,2213.04540,0.00000,0.00107,26.49503
10.50000,0.52489,2250.84387,0.00000,0.00109,26.94756
10.60000,0.53003,2291.14965,0.00000,0.00111,27.43011
10.70000,0.53494,2329.53597,0.00000,0.00114,27.88968
10.80000,0.54002,2366.96545,0.00000,0.00116,28.33780
10.90000,0.54492,2404.91722,0.00000,0.00118,28.79216
11.00000,0.54994,2441.09184,0.00000,0.00120,29.22525
11.10000,0.55497,2480.46033,0.00000,0.00122,29.69658
11.20000,0.55999,2517.05870,0.00000,0.00124,30.13474
11.30000,0.56501,2556.71516,0.00000,0.00126,30.60952
11.40000,0.56997,2591.36260,0.00000,0.00128,31.02433
11.50000,0.57500,2629.21397,0.00000,0.00130,31.47749
11.60000,0.57996,2663.02824,0.00000,0.00132,31.88232
11.70000,0.58510,2701.24786,0.00000,0.00135,32.33989
11.80000,0.58988,2734.34650,0.00000,0.00137,32.73616
11.90000,0.59503,2772.56276,0.00000,0.00139,33.19369
12.00000,0.59981,2805.12441,0.00000,0.00141,33.58353
12.10000,0.60501,2842.28250,0.00000,0.00143,34.02839
12.20000,0.60985,2876.65986,0.00000,0.00145,34.43996
12.30000,0.61499,2912.80188,0.00000,0.00147,34.87266
12.40000,0.61984,2946.07710,0.00000,0.00149,35.27104
12.50000,0.62504,2980.14376,0.00000,0.00151,35.67889
12.60000,0.62994,3013.71198,0.00000,0.00153,36.08078
12.70000,0.63508,3047.06916,0.00000,0.00154,36.48014
12.80000,0.63993,3079.70401,0.00000,0.00157,36.87085
12.90000,0.64501,3113.25621,0.00000,0.00158,37.27254
13.00000,0.64997,3145.41645,0.00000,0.00160,37.65757
13.10000,0.65505,3176.78750,0.00000,0.00162,38.03315
13.20000,0.65996,3207.91826,0.00000,0.00164,38.40586
13.30000,0.66498,3237.62447,0.00000,0.00166,38.76150
13.40000,0.66994,3268.17743,0.00000,0.00167,39.12729
13.50000,0.67496,3298.65329,0.00000,0.00169,39.49215
13.60000,0.68005,3331.28385,0.00000,0.00171,39.88281
13.70000,0.68507,3360.40892,0.00000,0.00172,40.23151
13.80000,0.69003,3390.54242,0.00000,0.00174,40.59227
13.90000,0.69499,3417.63645,0.00000,0.00176,40.91665
14.00000,0.70008,3446.75779,0.00000,0.00178,41.26529
14.10000,0.70504,3474.22659,0.00000,0.00179,41.59415
14.20000,0.71006,3504.04270,0.00000,0.00181,41.95112
14.30000,0.71490,3529.59894,0.00000,0.00182,42.25708
14.40000,0.72004,3557.88544,0.00000,0.00184,42.59574
14.50000,0.72495,3582.99613,0.00000,0.00186,42.89637
14.60000,0.73015,3611.28263,0.00000,0.00187,43.23502
14.70000,0.73499,3636.10126,0.00000,0.00188,43.53215
14.80000,0.74013,3662.65699,0.00000,0.00190,43.85008
14.90000,0.74498,3686.39790,0.00000,0.00191,44.13431
15.00000,0.75012,3712.35497,0.00000,0.00193,44.44508
15.10000,0.75490,3734.98127,0.00000,0.00194,44.71596
15.20000,0.76004,3757.70107,0.00000,0.00196,44.98797
15.30000,0.76489,3778.70388,0.00000,0.00197,45.23942
15.40000,0.77003,3801.03402,0.00000,0.00198,45.50676
15.50000,0.77493,3821.52162,0.00000,0.00199,45.75204
15.60000,0.78001,3844.50629,0.00000,0.00200,46.02722
15.70000,0.78492,3866.61254,0.00000,0.00202,46.29188
15.80000,0.79000,3888.24679,0.00000,0.00203,46.55089
15.90000,0.79502,3910.86861,0.00000,0.00204,46.82172
16.00000,0.80004,3931.60060,0.00000,0.00205,47.06993
16.10000,0.80501,3954.82406,0.00000,0.00207,47.34797
16.20000,0.80997,3974.58859,0.00000,0.00208,47.58459
16.30000,0.81499,3996.85390,0.00000,0.00209,47.85116
16.40000,0.81995,4016.25969,0.00000,0.00211,48.08349
16.50000,0.82504,4038.18637,0.00000,0.00212,48.34600
16.60000,0.82994,4059.80796,0.00000,0.00213,48.60485
16.70000,0.83502,4082.90923,0.00000,0.00215,48.88143
16.80000,0.83986,4103.08130,0.00000,0.00216,49.12293
16.90000,0.84506,4127.10346,0.00000,0.00217,49.41053
17.00000,0.84991,4148.16700,0.00000,0.00218,49.66271
17.10000,0.85505,4171.87586,0.00000,0.00220,49.94655
17.20000,0.85989,4192.53111,0.00000,0.00221,50.19384
17.30000,0.86509,4216.49516,0.00000,0.00222,50.48075
17.40000,0.87000,4235.82532,0.00000,0.00224,50.71217
17.50000,0.87508,4257.17235,0.00000,0.00225,50.96774
17.60000,0.87992,4278.01944,0.00000,0.00226,51.21733
17.70000,0.88500,4301.41166,0.00000,0.00228,51.49738
17.80000,0.88997,4323.73509,0.00000,0.00229,51.76464
17.90000,0.89505,4346.96861,0.00000,0.00230,52.04280
18.00000,0.89995,4370.45135,0.00000,0.00232,52.32394
18.10000,0.90503,4393.20803,0.00000,0.00233,52.59639
18.20000,0.91000,4417.35238,0.00000,0.00235,52.88545
18.30000,0.91502,4438.46583,0.00000,0.00236,53.13822
18.40000,0.92004,4463.05424,0.00000,0.00237,53.43260
18.50000,0.92500,4485.74573,0.00000,0.00239,53.70427
18.60000,0.93003,4510.27751,0.00000,0.00240,53.99797
18.70000,0.93499,4531.86221,0.00000,0.00241,54.25638
18.80000,0.94007,4556.31912,0.00000,0.00243,54.54919
18.90000,0.94491,4578.31174,0.00000,0.00244,54.81249
19.00000,0.95000,4603.21344,0.00000,0.00246,55.11062
19.10000,0.95490,4624.70837,0.00000,0.00247,55.36796
19.20000,0.96004,4648.88774,0.00000,0.00249,55.65744
19.30000,0.96494,4671.51739,0.00000,0.00250,55.92837
19.40000,0.97008,4696.35129,0.00000,0.00252,56.22568
19.50000,0.97487,4718.97684,0.00000,0.00254,56.49656
19.60000,0.98007,4745.72405,0.00000,0.00255,56.81678
19.70000,0.98491,4768.12422,0.00000,0.00256,57.08496
19.80000,0.99005,4792.41014,0.00000,0.00258,57.37572
19.90000,0.99490,4814.90903,0.00000,0.00259,57.64508
20.00000,0.99998,4838.82427,0.00000,0.00261,57.93140
20.10000,1.00488,4861.17862,0.00000,0.00262,58.19903
20.20000,1.01008,4884.34546,0.00000,0.00263,58.47639
20.30000,1.01499,4906.89315,0.00000,0.00264,58.74633
20.40000,1.02001,4930.62437,0.00000,0.00266,59.03045
20.50000,1.02497,4955.39978,0.00000,0.00267,59.32706
20.60000,1.02999,4978.63032,0.00000,0.00269,59.60518
20.70000,1.03496,5003.95820,0.00000,0.00270,59.90841
20.80000,1.03998,5025.70160,0.00000,0.00272,60.16873
20.90000,1.04494,5051.92727,0.00000,0.00273,60.48271
21.00000,1.04990,5073.91989,0.00000,0.00275,60.74601
21.10000,1.05499,5098.25312,0.00000,0.00276,61.03733
21.20000,1.05995,5121.53208,0.00000,0.00277,61.31603
21.30000,1.06503,5146.85698,0.00000,0.00279,61.61923
21.40000,1.06987,5169.01240,0.00000,0.00281,61.88448
21.50000,1.07502,5194.87448,0.00000,0.00282,62.19410
21.60000,1.07986,5216.89840,0.00000,0.00283,62.45778
21.70000,1.08512,5242.16369,0.00000,0.00285,62.76026
21.80000,1.08996,5263.50103,0.00000,0.00286,63.01572
21.90000,1.09504,5289.09564,0.00000,0.00288,63.32214
22.00000,1.09989,5312.29936,0.00000,0.00289,63.59994
22.10000,1.10503,5336.01120,0.00000,0.00291,63.88382
22.20000,1.10993,5359.80090,0.00000,0.00292,64.16864
22.30000,1.11501,5384.11662,0.00000,0.00294,64.45975
22.40000,1.11992,5407.90372,0.00000,0.00295,64.74453
22.50000,1.12500,5431.24788,0.00000,0.00296,65.02401
22.60000,1.12996,5454.45867,0.00000,0.00298,65.30190
22.70000,1.13504,5477.90192,0.00000,0.00299,65.58257
22.80000,1.13995,5501.88310,0.00000,0.00301,65.86967
22.90000,1.14503,5526.61978,0.00000,0.00302,66.16583
23.00000,1.14993,5549.80747,0.00000,0.00304,66.44343
23.10000,1.15501,5574.62946,0.00000,0.00305,66.74061
23.20000,1.15998,5600.23226,0.00000,0.00307,67.04713
23.30000,1.16500,5623.97726,0.00000,0.00308,67.33141
23.40000,1.17002,5649.35170,0.00000,0.00310,67.63520
23.50000,1.17498,5670.62795,0.00000,0.00311,67.88992
23.60000,1.18007,5696.39951,0.00000,0.00312,68.19846
23.70000,1.18497,5717.40717,0.00000,0.00314,68.44997
23.80000,1.18999,5743.84630,0.00000,0.00315,68.76651
23.90000,1.19489,5765.93764,0.00000,0.00317,69.03099
24.00000,1.20009,5792.24974,0.00000,0.00318,69.34600
24.10000,1.20494,5815.92433,0.00000,0.00320,69.62944
24.20000,1.21008,5841.72793,0.00000,0.00322,69.93837
24.30000,1.21486,5865.57016,0.00000,0.00323,70.22381
24.40000,1.22000,5890.78031,0.00000,0.00324,70.52563
24.50000,1.22491,5915.43019,0.00000,0.00326,70.82074
24.60000,1.23005,5940.32109,0.00000,0.00327,71.11874
24.70000,1.23489,5965.05105,0.00000,0.00329,71.41482
24.80000,1.24003,5990.64939,0.00000,0.00330,71.72128
24.90000,1.24494,6014.95542,0.00000,0.00332,72.01228
25.00000,1.25002,6039.21488,0.00000,0.00334,72.30272
25.10000,1.25498,6064.28795,0.00000,0.00335,72.60290
25.20000,1.25994,6087.33147,0.00000,0.00337,72.87878
25.30000,1.26497,6113.34629,0.00000,0.00338,73.19024
25.40000,1.26993,6135.18097,0.00000,0.00340,73.45165
25.50000,1.27501,6161.24719,0.00000,0.00342,73.76372
25.60000,1.27997,6185.43774,0.00000,0.00343,74.05333
25.70000,1.28500,6213.36363,0.00000,0.00345,74.38767
25.80000,1.28996,6235.77274,0.00000,0.00346,74.65595
25.90000,1.29510,6261.94701,0.00000,0.00347,74.96932
26.00000,1.29994,6284.30620,0.00000,0.00349,75.23700
26.10000,1.30503,6310.72596,0.00000,0.00351,75.55331
26.20000,1.30987,6333.88534,0.00000,0.00352,75.83058
26.30000,1.31507,6361.32434,0.00000,0.00354,76.15908
26.40000,1.31991,6384.03073,0.00000,0.00355,76.43093
26.50000,1.32505,6410.91242,0.00000,0.00357,76.75276
26.60000,1.32990,6436.47462,0.00000,0.00359,77.05880
26.70000,1.33504,6462.72451,0.00000,0.00360,77.37306
26.80000,1.33994,6487.94249,0.00000,0.00362,77.67498
26.90000,1.34508,6512.66500,0.00000,0.00364,77.97096
27.00000,1.34999,6536.97252,0.00000,0.00365,78.26198
27.10000,1.35507,6562.64052,0.00000,0.00367,78.56928
27.20000,1.35997,6587.51428,0.00000,0.00368,78.86707
27.30000,1.36505,6613.60100,0.00000,0.00370,79.17939
27.40000,1.36996,6636.89300,0.00000,0.00372,79.45825
27.50000,1.37504,6661.34879,0.00000,0.00373,79.75104
27.60000,1.37994,6686.90875,0.00000,0.00375,80.05704
27.70000,1.38496,6710.94283,0.00000,0.00376,80.34479
27.80000,1.38999,6737.58611,0.00000,0.00378,80.66376
27.90000,1.39507,6762.22295,0.00000,0.00380,80.95872
28.00000,1.40003,6787.31650,0.00000,0.00381,81.25915
28.10000,1.40499,6814.50590,0.00000,0.00383,81.58466
28.20000,1.40996,6839.72612,0.00000,0.00384,81.88661
28.30000,1.41498,6863.68942,0.00000,0.00386,82.17350
28.40000,1.42006,6890.76781,0.00000,0.00388,82.49769
28.50000,1.42490,6912.86325,0.00000,0.00390,82.76222
28.60000,1.43005,6940.68447,0.00000,0.00391,83.09530
28.70000,1.43489,6963.20161,0.00000,0.00393,83.36488
28.80000,1.44009,6989.70258,0.00000,0.00394,83.68215
28.90000,1.44493,7013.87227,0.00000,0.00396,83.97152
29.00000,1.45007,7041.47667,0.00000,0.00398,84.30200
29.10000,1.45492,7064.89086,0.00000,0.00399,84.58232
29.20000,1.46006,7090.53874,0.00000,0.00401,84.88939
29.30000,1.46490,7115.25679,0.00000,0.00403,85.18532
29.40000,1.47004,7140.88827,0.00000,0.00404,85.49218
29.50000,1.47489,7165.87976,0.00000,0.00406,85.79138
29.60000,1.48003,7191.69974,0.00000,0.00407,86.10051
29.70000,1.48493,7217.99806,0.00000,0.00409,86.41535
29.80000,1.49001,7243.91267,0.00000,0.00411,86.72561
29.90000,1.49492,7270.04632,0.00000,0.00412,87.03849
30.00000,1.49994,7295.41928,0.00000,0.00414,87.34226
30.10000,1.50496,7321.96718,0.00000,0.00416,87.66009
30.20000,1.50998,7345.70473,0.00000,0.00417,87.94429
30.30000,1.51501,7372.81442,0.00000,0.00420,88.26885
30.40000,1.51997,7396.07736,0.00000,0.00421,88.54736
30.50000,1.52499,7424.10570,0.00000,0.00423,88.88292
30.60000,1.52995,7448.47506,0.00000,0.00424,89.17467
30.70000,1.53504,7474.72122,0.00000,0.00426,89.48890
30.80000,1.54000,7497.60494,0.00000,0.00428,89.76287
30.90000,1.54508,7525.20859,0.00000,0.00429,90.09334
31.00000,1.54986,7547.50445,0.00000,0.00431,90.36027
31.10000,1.55506,7575.23924,0.00000,0.00433,90.69232
31.20000,1.55991,7598.45823,0.00000,0.00434,90.97030
31.30000,1.56511,7626.40461,0.00000,0.00436,91.30488
31.40000,1.56995,7651.27242,0.00000,0.00438,91.60260
31.50000,1.57503,7676.93445,0.00000,0.00440,91.90984
31.60000,1.57988,7701.99448,0.00000,0.00441,92.20986
31.70000,1.58508,7728.62285,0.00000,0.00443,92.52866
31.80000,1.58992,7753.00413,0.00000,0.00445,92.82056
31.90000,1.59500,7779.81877,0.00000,0.00447,93.14159
32.00000,1.59991,7805.40928,0.00000,0.00449,93.44796
32.10000,1.60499,7831.57051,0.00000,0.00450,93.76117
32.20000,1.61001,7857.90011,0.00000,0.00452,94.07639
32.30000,1.61503,7883.29095,0.00000,0.00454,94.38038
32.40000,1.62000,7909.37841,0.00000,0.00455,94.69270
32.50000,1.62502,7933.91094,0.00000,0.00457,94.98641
32.60000,1.62998,7960.01554,0.00000,0.00459,95.29894
32.70000,1.63506,7983.46698,0.00000,0.00461,95.57971
32.80000,1.64003,8011.56089,0.00000,0.00463,95.91605
32.90000,1.64499,8036.82134,0.00000,0.00464,96.21848
33.00000,1.65001,8064.17987,0.00000,0.00467,96.54602
33.10000,1.65491,8088.62820,0.00000,0.00467,96.83872
33.20000,1.66006,8116.80853,0.00000,0.00470,97.17610
33.30000,1.66490,8140.88210,0.00000,0.00471,97.46431
33.40000,1.67004,8168.96707,0.00000,0.00473,97.80055
33.50000,1.67488,8192.77763,0.00000,0.00475,98.08562
33.60000,1.68008,8219.82324,0.00000,0.00476,98.40941
33.70000,1.68493,8243.46915,0.00000,0.00478,98.69251
33.80000,1.69013,8272.53088,0.00000,0.00480,99.04044
33.90000,1.69491,8297.14686,0.00000,0.00482,99.33515
34.00000,1.70005,8322.72545,0.00000,0.00484,99.64138
34.10000,1.70490,8347.97174,0.00000,0.00485,99.94363
34.20000,1.70998,8372.62571,0.00000,0.00487,100.23879
34.30000,1.71488,8399.45897,0.00000,0.00489,100.56005
34.40000,1.72002,8425.29163,0.00000,0.00491,100.86932
34.50000,1.72493,8451.47818,0.00000,0.00493,101.18283
34.60000,1.73001,8476.92639,0.00000,0.00494,101.48750
34.70000,1.73497,8503.08239,0.00000,0.00496,101.80065
34.80000,1.73999,8528.17297,0.00000,0.00498,102.10104
34.90000,1.74496,8555.11129,0.00000,0.00500,102.42355
35.00000,1.74998,8578.50090,0.00000,0.00501,102.70357
35.10000,1.75500,8605.40494,0.00000,0.00503,103.02567
35.20000,1.75996,8630.31223,0.00000,0.00504,103.32387
35.30000,1.76499,8658.56856,0.00000,0.00506,103.66216
35.40000,1.76995,8683.60624,0.00000,0.00508,103.96192
35.50000,1.77509,8711.64873,0.00000,0.00510,104.29765
35.60000,1.78005,8735.54796,0.00000,0.00512,104.58377
35.70000,1.78513,8762.56153,0.00000,0.00514,104.90719
35.80000,1.78992,8785.36031,0.00000,0.00515,105.18014
35.90000,1.79506,8810.83980,0.00000,0.00517,105.48518
36.00000,1.79996,8835.04227,0.00000,0.00519,105.77494
36.10000,1.80516,8862.66232,0.00000,0.00521,106.10561
36.20000,1.80995,8887.89594,0.00000,0.00522,106.40772
36.30000,1.81509,8915.15389,0.00000,0.00524,106.73405
36.40000,1.81993,8939.04567,0.00000,0.00526,107.02009
36.50000,1.82513,8967.59480,0.00000,0.00528,107.36189
36.60000,1.82998,8992.04984,0.00000,0.00530,107.65467
36.70000,1.83506,9019.14835,0.00000,0.00532,107.97910
36.80000,1.83990,9043.54677,0.00000,0.00533,108.27120
36.90000,1.84504,9069.83912,0.00000,0.00536,108.58598
37.00000,1.85001,9096.68654,0.00000,0.00537,108.90740
37.10000,1.85503,9122.04236,0.00000,0.00539,109.21096
37.20000,1.85993,9148.94044,0.00000,0.00541,109.53299
37.30000,1.86501,9173.82687,0.00000,0.00543,109.83094
37.40000,1.86998,9199.97692,0.00000,0.00545,110.14401
37.50000,1.87500,9224.40961,0.00000,0.00547,110.43653
37.60000,1.88002,9251.99762,0.00000,0.00548,110.76682
37.70000,1.88498,9277.13513,0.00000,0.00550,111.06777
37.80000,1.89007,9304.24184,0.00000,0.00552,111.39229
37.90000,1.89497,9328.16043,0.00000,0.00554,111.67865
38.00000,1.89999,9354.90578,0.00000,0.00556,111.99885
38.10000,1.90483,9379.27812,0.00000,0.00558,112.29064
38.20000,1.91004,9406.15088,0.00000,0.00560,112.61237
38.30000,1.91488,9429.60531,0.00000,0.00562,112.89317
38.40000,1.92008,9457.07187,0.00000,0.00564,113.22201
38.50000,1.92486,9482.15425,0.00000,0.00566,113.52230
38.60000,1.93000,9511.52965,0.00000,0.00568,113.87399
38.70000,1.93485,9537.85032,0.00000,0.00569,114.18910
38.80000,1.94005,9565.10380,0.00000,0.00572,114.51539
38.90000,1.94495,9589.58194,0.00000,0.00573,114.80844
39.00000,1.95003,9616.91365,0.00000,0.00575,115.13566
39.10000,1.95488,9643.21792,0.00000,0.00577,115.45058
39.20000,1.95996,9669.33593,0.00000,0.00579,115.76328
39.30000,1.96498,9695.17082,0.00000,0.00581,116.07258
39.40000,1.97000,9720.33814,0.00000,0.00583,116.37388
39.50000,1.97497,9747.98203,0.00000,0.00585,116.70484
39.60000,1.97999,9773.44736,0.00000,0.00587,117.00972
39.70000,1.98501,9800.89977,0.00000,0.00588,117.33838
39.80000,1.99003,9824.49874,0.00000,0.00590,117.62092
39.90000,1.99506,9851.50635,0.00000,0.00592,117.94426
40.00000,2.00002,9876.83758,0.00000,0.00594,118.24753
40.10000,2.00504,9906.24130,0.00000,0.00596,118.59955
40.20000,2.01000,9930.31412,0.00000,0.00598,118.88776
40.30000,2.01509,9956.64075,0.00000,0.00600,119.20295
40.40000,2.01999,9980.09890,0.00000,0.00601,119.48379
40.50000,2.02507,10007.97078,0.00000,0.00603,119.81748
40.60000,2.02991,10033.24464,0.00000,0.00605,120.12006
40.70000,2.03511,10059.85588,0.00000,0.00607,120.43866
40.80000,2.03996,10084.67451,0.00000,0.00609,120.73579
40.90000,2.04510,10111.95704,0.00000,0.00611,121.06243
41.00000,2.04994,10137.87165,0.00000,0.00613,121.37268
41.10000,2.05508,10165.76588,0.00000,0.00615,121.70664
41.20000,2.05999,10190.13003,0.00000,0.00617,121.99833
41.30000,2.06507,10216.67048,0.00000,0.00619,122.31608
41.40000,2.06991,10239.79113,0.00000,0.00620,122.59288
41.50000,2.07505,10268.26426,0.00000,0.00622,122.93377
41.60000,2.07990,10293.28853,0.00000,0.00624,123.23336
41.70000,2.08504,10319.99141,0.00000,0.00626,123.55306
41.80000,2.09000,10345.93359,0.00000,0.00628,123.86364
41.90000,2.09496,10371.74165,0.00000,0.00630,124.17262
42.00000,2.09993,10399.23429,0.00000,0.00631,124.50177
42.10000,2.10501,10424.55584,0.00000,0.00633,124.80492
42.20000,2.11003,10451.64242,0.00000,0.00636,125.12921
42.30000,2.11499,10475.88736,0.00000,0.00637,125.41947
42.40000,2.12002,10504.71812,0.00000,0.00639,125.76464
42.50000,2.12492,10530.04116,0.00000,0.00641,126.06781
42.60000,2.13006,10558.30345,0.00000,0.00643,126.40618
42.70000,2.13496,10581.93296,0.00000,0.00645,126.68907
42.80000,2.14005,10610.03134,0.00000,0.00647,127.02547
42.90000,2.14489,10634.24870,0.00000,0.00649,127.31541
43.00000,2.15003,10662.13623,0.00000,0.00650,127.64928
43.10000,2.15493,10686.91164,0.00000,0.00653,127.94590
43.20000,2.16013,10714.13755,0.00000,0.00655,128.27185
43.30000,2.16492,10739.85621,0.00000,0.00657,128.57976
43.40000,2.17006,10767.01805,0.00000,0.00659,128.90495
43.50000,2.17490,10792.07063,0.00000,0.00661,129.20489
43.60000,2.18010,10818.50901,0.00000,0.00663,129.52141
43.70000,2.18495,10843.43120,0.00000,0.00665,129.81978
43.80000,2.19003,10869.28695,0.00000,0.00667,130.12934
43.90000,2.19487,10894.92589,0.00000,0.00669,130.43629
44.00000,2.20001,10922.11083,0.00000,0.00671,130.76175
44.10000,2.20498,10948.95452,0.00000,0.00673,131.08313
44.20000,2.21006,10974.58005,0.00000,0.00674,131.38993
44.30000,2.21496,11001.75232,0.00000,0.00677,131.71524
44.40000,2.21998,11026.48601,0.00000,0.00678,132.01135
44.50000,2.22501,11053.09352,0.00000,0.00681,132.32991
44.60000,2.23003,11077.71844,0.00000,0.00682,132.62472
44.70000,2.23505,11104.21270,0.00000,0.00685,132.94191
44.80000,2.24001,11129.63483,0.00000,0.00686,133.24627
44.90000,2.24504,11158.32552,0.00000,0.00688,133.58976
45.00000,2.25000,11181.41115,0.00000,0.00690,133.86615
45.10000,2.25508,11209.69132,0.00000,0.00692,134.20473
45.20000,2.25992,11232.84772,0.00000,0.00694,134.48196
45.30000,2.26506,11260.81645,0.00000,0.00696,134.81681
45.40000,2.26997,11285.32961,0.00000,0.00699,135.11028
45.50000,2.27505,11311.96767,0.00000,0.00700,135.42920
45.60000,2.27995,11337.05676,0.00000,0.00702,135.72957
45.70000,2.28503,11365.25199,0.00000,0.00705,136.06713
45.80000,2.28988,11390.27104,0.00000,0.00706,136.36666
45.90000,2.29508,11418.28299,0.00000,0.00709,136.70203
46.00000,2.29986,11443.09565,0.00000,0.00710,136.99909
46.10000,2.30506,11470.41917,0.00000,0.00712,137.32621
46.20000,2.30991,11495.52092,0.00000,0.00714,137.62674
46.30000,2.31499,11522.38995,0.00000,0.00716,137.94842
46.40000,2.31989,11548.34181,0.00000,0.00718,138.25912
46.50000,2.32503,11575.19668,0.00000,0.00720,138.58063
46.60000,2.33000,11601.49798,0.00000,0.00723,138.89552
46.70000,2.33502,11626.38143,0.00000,0.00724,139.19343
46.80000,2.33992,11654.24958,0.00000,0.00726,139.52707
46.90000,2.34494,11677.19886,0.00000,0.00728,139.80182
47.00000,2.35003,11705.05211,0.00000,0.00730,140.13529
47.10000,2.35499,11728.98188,0.00000,0.00732,140.42178
47.20000,2.36001,11757.89759,0.00000,0.00734,140.76796
47.30000,2.36491,11783.12078,0.00000,0.00736,141.06994
47.40000,2.37000,11811.11932,0.00000,0.00738,141.40515
47.50000,2.37490,11834.71456,0.00000,0.00740,141.68763
47.60000,2.38004,11862.27426,0.00000,0.00742,142.01758
47.70000,2.38488,11886.57731,0.00000,0.00744,142.30854
47.80000,2.39003,11914.01407,0.00000,0.00746,142.63702
47.90000,2.39487,11938.55405,0.00000,0.00748,142.93082
48.00000,2.40007,11966.28958,0.00000,0.00750,143.26288
48.10000,2.40491,11992.61472,0.00000,0.00752,143.57805
48.20000,2.40999,12019.63425,0.00000,0.00755,143.90153
48.30000,2.41490,12044.70173,0.00000,0.00756,144.20164
48.40000,2.42004,12070.73554,0.00000,0.00758,144.51332
48.50000,2.42494,12095.69722,0.00000,0.00760,144.81217
48.60000,2.42996,12121.17597,0.00000,0.00762,145.11721
48.70000,2.43493,12147.16882,0.00000,0.00765,145.42840
48.80000,2.44001,12173.58783,0.00000,0.00766,145.74469
48.90000,2.44503,12200.53807,0.00000,0.00768,146.06735
49.00000,2.45005,12225.17490,0.00000,0.00771,146.36230
49.10000,2.45496,12252.64743,0.00000,0.00773,146.69121
49.20000,2.46004,12278.27892,0.00000,0.00775,146.99808
49.30000,2.46494,12304.05942,0.00000,0.00777,147.30673
49.40000,2.47002,12329.60746,0.00000,0.00779,147.61259
49.50000,2.47499,12357.16715,0.00000,0.00780,147.94254
49.60000,2.47995,12383.08027,0.00000,0.00782,148.25278
49.70000,2.48503,12411.36715,0.00000,0.00785,148.59144
49.80000,2.48999,12434.76793,0.00000,0.00786,148.87159
49.90000,2.49508,12462.35147,0.00000,0.00788,149.20183
50.00000,2.49992,12486.01675,0.00000,0.00790,149.48516
50.10000,2.50500,12513.95494,0.00000,0.00793,149.81964
50.20000,2.50990,12537.88769,0.00000,0.00795,150.10617
50.30000,2.51510,12566.05983,0.00000,0.00797,150.44345
50.40000,2.51995,12590.51263,0.00000,0.00799,150.73620
50.50000,2.52503,12619.07816,0.00000,0.00801,151.07819
50.60000,2.52987,12645.28483,0.00000,0.00803,151.39195
50.70000,2.53507,12671.30673,0.00000,0.00805,151.70349
50.80000,2.53998,12696.95759,0.00000,0.00807,152.01058
50.90000,2.54506,12722.59355,0.00000,0.00809,152.31750
51.00000,2.54990,12748.35169,0.00000,0.00811,152.62588
51.10000,2.55498,12775.98739,0.00000,0.00813,152.95674
51.20000,2.55995,12801.58758,0.00000,0.00815,153.26324
51.30000,2.56503,12828.51249,0.00000,0.00817,153.58559
51.40000,2.56993,12854.99036,0.00000,0.00819,153.90258
51.50000,2.57495,12880.82302,0.00000,0.00821,154.21186
51.60000,2.57992,12908.86998,0.00000,0.00823,154.54764
51.70000,2.58500,12933.31981,0.00000,0.00825,154.84036
51.80000,2.59002,12961.11047,0.00000,0.00827,155.17308
51.90000,2.59498,12985.29208,0.00000,0.00829,155.46258
52.00000,2.60001,13012.63422,0.00000,0.00832,155.78993
52.10000,2.60497,13037.27627,0.00000,0.00833,156.08495
52.20000,2.61011,13065.74792,0.00000,0.00836,156.42582
52.30000,2.61489,13088.00429,0.00000,0.00838,156.69227
52.40000,2.62010,13116.17792,0.00000,0.00840,157.02958
52.50000,2.62494,13140.25670,0.00000,0.00842,157.31785
52.60000,2.63008,13169.14111,0.00000,0.00844,157.66366
52.70000,2.63498,13195.11831,0.00000,0.00846,157.97467
52.80000,2.64012,13222.89854,0.00000,0.00849,158.30726
52.90000,2.64491,13247.38115,0.00000,0.00850,158.60037
53.00000,2.64999,13274.53852,0.00000,0.00853,158.92550
53.10000,2.65495,13300.46505,0.00000,0.00855,159.23590
53.20000,2.66009,13326.42734,0.00000,0.00857,159.54672
53.30000,2.66494,13350.83097,0.00000,0.00859,159.83889
53.40000,2.66996,13377.31034,0.00000,0.00861,160.15591
53.50000,2.67492,13404.01918,0.00000,0.00864,160.47567
53.60000,2.68000,13430.00680,0.00000,0.00866,160.78680
53.70000,2.68497,13457.16715,0.00000,0.00868,161.11197
53.80000,2.68999,13483.19054,0.00000,0.00870,161.42353
53.90000,2.69495,13509.59539,0.00000,0.00872,161.73965
54.00000,2.69997,13534.54441,0.00000,0.00874,162.03834
54.10000,2.70500,13561.90592,0.00000,0.00876,162.36592
54.20000,2.71008,13587.11720,0.00000,0.00878,162.66776
54.30000,2.71504,13613.95419,0.00000,0.00881,162.98905
54.40000,2.71994,13638.97324,0.00000,0.00882,163.28859
54.50000,2.72503,13666.75943,0.00000,0.00885,163.62125
54.60000,2.72993,13690.93508,0.00000,0.00887,163.91069
54.70000,2.73507,13719.13999,0.00000,0.00889,164.24836
54.80000,2.73985,13742.28448,0.00000,0.00891,164.52545
54.90000,2.74505,13771.05713,0.00000,0.00893,164.86992
55.00000,2.74990,13796.29821,0.00000,0.00895,165.17211
55.10000,2.75510,13824.88757,0.00000,0.00897,165.51439
55.20000,2.75994,13850.04222,0.00000,0.00899,165.81555
55.30000,2.76508,13876.85090,0.00000,0.00901,166.13651
55.40000,2.76993,13903.16784,0.00000,0.00903,166.45158
55.50000,2.77507,13928.54452,0.00000,0.00905,166.75539
55.60000,2.77991,13953.26257,0.00000,0.00908,167.05132
55.70000,2.78505,13980.18003,0.00000,0.00910,167.37359
55.80000,2.78990,14005.39726,0.00000,0.00911,167.67549
55.90000,2.79498,14033.11640,0.00000,0.00914,168.00735
56.00000,2.79994,14059.68070,0.00000,0.00916,168.32538
56.10000,2.80496,14086.41934,0.00000,0.00918,168.64550
56.20000,2.80993,14113.02090,0.00000,0.00920,168.96398
56.30000,2.81495,14137.98034,0.00000,0.00922,169.26280
56.40000,2.81997,14166.32980,0.00000,0.00924,169.60221
56.50000,2.82499,14191.00016,0.00000,0.00926,169.89757
56.60000,2.83002,14218.10687,0.00000,0.00928,170.22209
56.70000,2.83492,14242.65653,0.00000,0.00930,170.51601
56.80000,2.84000,14270.95979,0.00000,0.00932,170.85486
56.90000,2.84490,14295.38876,0.00000,0.00934,171.14733
57.00000,2.84999,14323.25393,0.00000,0.00937,171.48094
57.10000,2.85489,14346.34179,0.00000,0.00939,171.75735
57.20000,2.86003,14374.11308,0.00000,0.00941,172.08983
57.30000,2.86487,14398.60761,0.00000,0.00943,172.38309
57.40000,2.87007,14425.65918,0.00000,0.00945,172.70695
57.50000,2.87498,14450.69611,0.00000,0.00947,173.00670
57.60000,2.88012,14478.15597,0.00000,0.00949,173.33546
57.70000,2.88490,14503.02452,0.00000,0.00952,173.63319
57.80000,2.89004,14529.61117,0.00000,0.00953,173.95149
57.90000,2.89489,14554.26365,0.00000,0.00955,174.24663
58.00000,2.90003,14581.08723,0.00000,0.00958,174.56777
58.10000,2.90487,14606.21953,0.00000,0.00960,174.86866
58.20000,2.90995,14633.84628,0.00000,0.00962,175.19941
58.30000,2.91492,14661.60715,0.00000,0.00964,175.53177
58.40000,2.92006,14687.54709,0.00000,0.00967,175.84233
58.50000,2.92502,14714.45262,0.00000,0.00969,176.16445
58.60000,2.93004,14740.40449,0.00000,0.00971,176.47515
58.70000,2.93495,14767.45456,0.00000,0.00973,176.79900
58.80000,2.94003,14792.31417,0.00000,0.00975,177.09662
58.90000,2.94499,14819.40597,0.00000,0.00978,177.42097
59.00000,2.95001,14844.17170,0.00000,0.00980,177.71747
59.10000,2.95504,14872.40642,0.00000,0.00982,178.05550
59.20000,2.95994,14897.80694,0.00000,0.00984,178.35960
59.30000,2.96502,14925.40389,0.00000,0.00987,178.69000
59.40000,2.96992,14948.49026,0.00000,0.00989,178.96639
59.50000,2.97507,14977.09751,0.00000,0.00991,179.30889
59.60000,2.97991,15001.07795,0.00000,0.00993,179.59599
59.70000,2.98505,15029.09362,0.00000,0.00995,179.93139
59.80000,2.98989,15054.01582,0.00000,0.00997,180.22977
59.90000,2.99509,15082.16411,0.00000,0.01000,180.56677
60.00000,2.99988,15108.39611,0.00000,0.01002,180.88082
60.10000,3.00502,15135.99455,0.00000,0.01004,181.21123
60.20000,3.00980,15162.00304,0.00000,0.01006,181.52261
60.30000,3.01500,15188.56734,0.00000,0.01008,181.84065
60.40000,3.01991,15213.33307,0.00000,0.01011,182.13715
60.50000,3.02499,15238.82896,0.00000,0.01013,182.44239
60.60000,3.02989,15266.24411,0.00000,0.01015,182.77061
60.70000,3.03503,15292.87994,0.00000,0.01017,183.08950
60.80000,3.04000,15319.50533,0.00000,0.01019,183.40826
60.90000,3.04502,15344.55419,0.00000,0.01021,183.70815
61.00000,3.04998,15371.92315,0.00000,0.01024,184.03582
61.10000,3.05494,15395.97064,0.00000,0.01026,184.32372
61.20000,3.06003,15424.42590,0.00000,0.01028,184.66439
61.30000,3.06499,15448.82655,0.00000,0.01030,184.95652
61.40000,3.07007,15476.93014,0.00000,0.01032,185.29299
61.50000,3.07497,15502.18761,0.00000,0.01034,185.59537
61.60000,3.08006,15530.35527,0.00000,0.01036,185.93260
61.70000,3.08496,15553.57277,0.00000,0.01038,186.21057
61.80000,3.09010,15582.01462,0.00000,0.01040,186.55108
61.90000,3.09494,15606.45849,0.00000,0.01043,186.84373
62.00000,3.10009,15635.15365,0.00000,0.01045,187.18727
62.10000,3.10493,15659.98793,0.00000,0.01047,187.48459
62.20000,3.11007,15687.87098,0.00000,0.01049,187.81841
62.30000,3.11497,15714.80632,0.00000,0.01052,188.14089
62.40000,3.12011,15741.89365,0.00000,0.01054,188.46518
62.50000,3.12490,15766.45821,0.00000,0.01055,188.75928
62.60000,3.13010,15794.24739,0.00000,0.01058,189.09197
62.70000,3.13494,15818.76278,0.00000,0.01060,189.38548
62.80000,3.14008,15845.79796,0.00000,0.01063,189.70915
62.90000,3.14493,15869.96317,0.00000,0.01065,189.99846
63.00000,3.15001,15898.85950,0.00000,0.01067,190.34441
63.10000,3.15497,15925.38655,0.00000,0.01069,190.66200
63.20000,3.16011,15951.66773,0.00000,0.01072,190.97664
63.30000,3.16496,15977.80585,0.00000,0.01074,191.28957
63.40000,3.16998,16003.03501,0.00000,0.01076,191.59162
63.50000,3.17494,16031.45301,0.00000,0.01078,191.93185
63.60000,3.17996,16056.67472,0.00000,0.01081,192.23381
63.70000,3.18499,16084.54138,0.00000,0.01083,192.56743
63.80000,3.18995,16108.80196,0.00000,0.01085,192.85788
63.90000,3.19497,16136.56729,0.00000,0.01087,193.19030
64.00000,3.19993,16162.76950,0.00000,0.01089,193.50400
64.10000,3.20508,16191.43784,0.00000,0.01092,193.84722
64.20000,3.20998,16215.94280,0.00000,0.01094,194.14060
64.30000,3.21506,16242.35660,0.00000,0.01096,194.45683
64.40000,3.21984,16266.75129,0.00000,0.01098,194.74889
64.50000,3.22510,16296.76372,0.00000,0.01100,195.10820
64.60000,3.22989,16322.41160,0.00000,0.01103,195.41526
64.70000,3.23509,16349.81632,0.00000,0.01105,195.74336
64.80000,3.23987,16373.54344,0.00000,0.01107,196.02742
64.90000,3.24501,16401.16721,0.00000,0.01109,196.35814
65.00000,3.24986,16425.18491,0.00000,0.01112,196.64569
65.10000,3.25506,16451.65533,0.00000,0.01114,196.96260
65.20000,3.25996,16477.89180,0.00000,0.01116,197.27670
65.30000,3.26504,16504.33093,0.00000,0.01118,197.59324
65.40000,3.26989,16531.56579,0.00000,0.01121,197.91930
65.50000,3.27497,16556.72342,0.00000,0.01123,198.22049
65.60000,3.28005,16585.78962,0.00000,0.01125,198.56848
65.70000,3.28501,16609.96377,0.00000,0.01127,198.85790
65.80000,3.28998,16636.59066,0.00000,0.01130,199.17668
65.90000,3.29500,16659.72173,0.00000,0.01131,199.45361
66.00000,3.30002,16687.55561,0.00000,0.01134,199.78684
66.10000,3.30504,16711.49880,0.00000,0.01136,200.07349
66.20000,3.31007,16739.07042,0.00000,0.01138,200.40359
66.30000,3.31497,16762.87055,0.00000,0.01141,200.68853
66.40000,3.32011,16792.00530,0.00000,0.01143,201.03734
66.50000,3.32495,16814.40026,0.00000,0.01145,201.30545
66.60000,3.33010,16841.44139,0.00000,0.01147,201.62919
66.70000,3.33500,16865.93741,0.00000,0.01149,201.92247
66.80000,3.34008,16892.98153,0.00000,0.01151,202.24624
66.90000,3.34492,16917.85157,0.00000,0.01154,202.54399
67.00000,3.35007,16945.97900,0.00000,0.01156,202.88074
67.10000,3.35497,16970.67916,0.00000,0.01158,203.17646
67.20000,3.36011,16996.76961,0.00000,0.01161,203.48882
67.30000,3.36495,17021.66498,0.00000,0.01163,203.78687
67.40000,3.37009,17048.69866,0.00000,0.01166,204.11052
67.50000,3.37494,17073.73857,0.00000,0.01168,204.41030
67.60000,3.38008,17100.43699,0.00000,0.01170,204.72994
67.70000,3.38492,17125.54097,0.00000,0.01172,205.03049
67.80000,3.39006,17154.08415,0.00000,0.01175,205.37222
67.90000,3.39491,17179.22986,0.00000,0.01177,205.67327
68.00000,3.40005,17204.44858,0.00000,0.01179,205.97519
68.10000,3.40501,17230.47793,0.00000,0.01181,206.28682
68.20000,3.41003,17254.30936,0.00000,0.01184,206.57213
68.30000,3.41500,17281.93313,0.00000,0.01186,206.90285
68.40000,3.42002,17305.07016,0.00000,0.01188,207.17985
68.50000,3.42504,17333.27359,0.00000,0.01191,207.51751
68.60000,3.43000,17357.59228,0.00000,0.01192,207.80866
68.70000,3.43497,17385.15049,0.00000,0.01195,208.13859
68.80000,3.43987,17410.17401,0.00000,0.01197,208.43818
68.90000,3.44501,17437.04081,0.00000,0.01199,208.75983
69.00000,3.44991,17460.84541,0.00000,0.01202,209.04483
69.10000,3.45500,17487.93572,0.00000,0.01204,209.36916
69.20000,3.45984,17512.93987,0.00000,0.01206,209.66851
69.30000,3.46504,17540.76034,0.00000,0.01208,210.00158
69.40000,3.46988,17564.36378,0.00000,0.01211,210.28417
69.50000,3.47508,17590.93553,0.00000,0.01213,210.60229
69.60000,3.47993,17616.36138,0.00000,0.01215,210.90670
69.70000,3.48501,17642.94207,0.00000,0.01217,211.22493
69.80000,3.48991,17667.35017,0.00000,0.01219,211.51714
69.90000,3.49505,17694.00090,0.00000,0.01222,211.83621
70.00000,3.50002,17719.69050,0.00000,0.01224,212.14377
70.10000,3.50498,17744.41600,0.00000,0.01226,212.43979
70.20000,3.50988,17771.35283,0.00000,0.01228,212.76229
70.30000,3.51502,17796.06193,0.00000,0.01230,213.05811
70.40000,3.51999,17822.46381,0.00000,0.01233,213.37420
70.50000,3.52501,17846.12536,0.00000,0.01235,213.65748
70.60000,3.52997,17872.96981,0.00000,0.01237,213.97886
70.70000,3.53499,17898.39715,0.00000,0.01239,214.28329
70.80000,3.54008,17925.64094,0.00000,0.01242,214.60945
70.90000,3.54504,17950.21743,0.00000,0.01244,214.90369
71.00000,3.55006,17977.35393,0.00000,0.01246,215.22857
71.10000,3.55496,18001.85740,0.00000,0.01249,215.52193
71.20000,3.55999,18028.84191,0.00000,0.01251,215.84500
71.30000,3.56495,18052.77914,0.00000,0.01253,216.13158
71.40000,3.57015,18079.86349,0.00000,0.01256,216.45584
71.50000,3.57493,18103.71429,0.00000,0.01257,216.74138
71.60000,3.58007,18131.21885,0.00000,0.01260,217.07067
71.70000,3.58498,18155.90560,0.00000,0.01262,217.36623
71.80000,3.59012,18183.39974,0.00000,0.01265,217.69540
71.90000,3.59490,18206.67684,0.00000,0.01267,217.97407
72.00000,3.59999,18233.83272,0.00000,0.01269,218.29919
72.10000,3.60483,18258.34960,0.00000,0.01271,218.59271
72.20000,3.61003,18285.54869,0.00000,0.01274,218.91834
72.30000,3.61493,18309.77201,0.00000,0.01276,219.20835
72.40000,3.62001,18336.38698,0.00000,0.01279,219.52699
72.50000,3.62486,18361.82773,0.00000,0.01281,219.83157
72.60000,3.63000,18389.07301,0.00000,0.01283,220.15776
72.70000,3.63496,18414.35581,0.00000,0.01286,220.46045
72.80000,3.64004,18441.14065,0.00000,0.01288,220.78112
72.90000,3.64501,18466.97032,0.00000,0.01290,221.09036
73.00000,3.65003,18491.26518,0.00000,0.01293,221.38122
73.10000,3.65499,18517.93081,0.00000,0.01295,221.70047
73.20000,3.66001,18541.91124,0.00000,0.01297,221.98757
73.30000,3.66504,18569.14014,0.00000,0.01300,222.31356
73.40000,3.66994,18591.43376,0.00000,0.01302,222.58046
73.50000,3.67502,18619.73405,0.00000,0.01304,222.91928
73.60000,3.67986,18642.60286,0.00000,0.01306,223.19307
73.70000,3.68507,18668.82890,0.00000,0.01309,223.50705
73.80000,3.68991,18691.44589,0.00000,0.01311,223.77783
73.90000,3.69511,18718.99813,0.00000,0.01313,224.10769
74.00000,3.69989,18743.99781,0.00000,0.01315,224.40699
74.10000,3.70509,18771.66629,0.00000,0.01318,224.73824
74.20000,3.70994,18796.28450,0.00000,0.01320,225.03298
74.30000,3.71508,18821.75952,0.00000,0.01322,225.33797
74.40000,3.71992,18847.18239,0.00000,0.01325,225.64234
74.50000,3.72501,18872.30426,0.00000,0.01327,225.94310
74.60000,3.72991,18896.87777,0.00000,0.01329,226.23730
74.70000,3.73505,18922.39898,0.00000,0.01332,226.54285
74.80000,3.73995,18946.15889,0.00000,0.01334,226.82730
74.90000,3.74503,18970.87544,0.00000,0.01336,227.12322
75.00000,3.75000,18998.90155,0.00000,0.01338,227.45875
75.10000,3.75508,19023.73433,0.00000,0.01341,227.75605
75.20000,3.76004,19049.20787,0.00000,0.01343,228.06103
75.30000,3.76500,19072.16907,0.00000,0.01345,228.33592
75.40000,3.76997,19097.80949,0.00000,0.01347,228.64290
75.50000,3.77505,19123.45290,0.00000,0.01350,228.94990
75.60000,3.78001,19147.70901,0.00000,0.01352,229.24030
75.70000,3.78503,19172.94562,0.00000,0.01354,229.54244
75.80000,3.79000,19198.09878,0.00000,0.01357,229.84358
75.90000,3.79490,19222.05985,0.00000,0.01359,230.13045
76.00000,3.79998,19249.73875,0.00000,0.01361,230.46182
76.10000,3.80494,19272.91453,0.00000,0.01363,230.73929
76.20000,3.81015,19299.66062,0.00000,0.01366,231.05950
76.30000,3.81493,19321.71732,0.00000,0.01368,231.32357
76.40000,3.82001,19349.73747,0.00000,0.01371,231.65903
76.50000,3.82491,19373.31706,0.00000,0.01373,231.94133
76.60000,3.83012,19401.01385,0.00000,0.01375,232.27292
76.70000,3.83496,19424.61133,0.00000,0.01378,232.55544
76.80000,3.84004,19450.24580,0.00000,0.01380,232.86234
76.90000,3.84488,19474.55406,0.00000,0.01382,233.15336
77.00000,3.85002,19499.13055,0.00000,0.01385,233.44759
77.10000,3.85493,19523.74429,0.00000,0.01387,233.74228
77.20000,3.86007,19549.07179,0.00000,0.01390,234.04550
77.30000,3.86491,19573.56334,0.00000,0.01392,234.33872
77.40000,3.86999,19599.03240,0.00000,0.01394,234.64364
77.50000,3.87496,19626.00052,0.00000,0.01397,234.96651
77.60000,3.88004,19650.41310,0.00000,0.01399,235.25878
77.70000,3.88500,19677.10108,0.00000,0.01402,235.57829
77.80000,3.88996,19699.68826,0.00000,0.01404,235.84871
77.90000,3.89493,19725.88599,0.00000,0.01406,236.16236
78.00000,3.89995,19749.57436,0.00000,0.01408,236.44596
78.10000,3.90497,19775.17605,0.00000,0.01411,236.75247
78.20000,3.90993,19797.72002,0.00000,0.01413,237.02237
78.30000,3.91502,19824.63300,0.00000,0.01416,237.34458
78.40000,3.91992,19849.14541,0.00000,0.01418,237.63804
78.50000,3.92512,19876.79750,0.00000,0.01420,237.96910
78.60000,3.92996,19897.62634,0.00000,0.01422,238.21847
78.70000,3.93511,19924.19809,0.00000,0.01425,238.53659
78.80000,3.93989,19947.87604,0.00000,0.01427,238.82007
78.90000,3.94503,19972.92489,0.00000,0.01429,239.11996
79.00000,3.94993,19996.47170,0.00000,0.01432,239.40187
79.10000,3.95507,20021.70235,0.00000,0.01434,239.70393
79.20000,3.95986,20045.52484,0.00000,0.01436,239.98914
79.30000,3.96500,20070.92237,0.00000,0.01438,240.29320
79.40000,3.96990,20095.07716,0.00000,0.01440,240.58239
79.50000,3.97504,20120.55516,0.00000,0.01443,240.88742
79.60000,3.98001,20144.40298,0.00000,0.01445,241.17293
79.70000,3.98497,20168.15245,0.00000,0.01448,241.45726
79.80000,3.98993,20194.52006,0.00000,0.01450,241.77294
79.90000,3.99501,20218.11157,0.00000,0.01452,242.05538
80.00000,3.99998,20243.36904,0.00000,0.01455,242.35777
80.10000,4.00506,20267.72797,0.00000,0.01457,242.64940
80.20000,4.00996,20292.45198,0.00000,0.01459,242.94540
80.30000,4.01498,20314.72474,0.00000,0.01461,243.21206
80.40000,4.02007,20340.30259,0.00000,0.01464,243.51828
80.50000,4.02509,20362.48147,0.00000,0.01466,243.78381
80.60000,4.03011,20386.69288,0.00000,0.01468,244.07367
80.70000,4.03495,20409.53934,0.00000,0.01471,244.34720
80.80000,4.04004,20435.64916,0.00000,0.01473,244.65979
80.90000,4.04494,20458.54330,0.00000,0.01475,244.93388
81.00000,4.05008,20485.27896,0.00000,0.01478,245.25397
81.10000,4.05486,20507.38186,0.00000,0.01480,245.51859
81.20000,4.06001,20534.08921,0.00000,0.01483,245.83833
81.30000,4.06485,20556.42456,0.00000,0.01485,246.10574
81.40000,4.07005,20581.43467,0.00000,0.01487,246.40516
81.50000,4.07495,20604.74306,0.00000,0.01490,246.68421
81.60000,4.07998,20628.93361,0.00000,0.01492,246.97383
81.70000,4.08488,20654.15680,0.00000,0.01494,247.27581
81.80000,4.09002,20679.12370,0.00000,0.01497,247.57471
81.90000,4.09492,20702.15791,0.00000,0.01499,247.85049
82.00000,4.10000,20725.96848,0.00000,0.01502,248.13555
82.10000,4.10491,20749.84610,0.00000,0.01503,248.42142
82.20000,4.10999,20773.61643,0.00000,0.01506,248.70600
82.30000,4.11495,20798.95735,0.00000,0.01508,249.00939
82.40000,4.12003,20821.19584,0.00000,0.01511,249.27563
82.50000,4.12494,20846.43245,0.00000,0.01513,249.57777
82.60000,4.12996,20870.19384,0.00000,0.01515,249.86225
82.70000,4.13498,20895.55860,0.00000,0.01517,250.16592
82.80000,4.14000,20917.64808,0.00000,0.01520,250.43038
82.90000,4.14503,20941.66428,0.00000,0.01522,250.71790
83.00000,4.14987,20962.26215,0.00000,0.01525,250.96451
83.10000,4.15501,20989.05295,0.00000,0.01527,251.28525
83.20000,4.15985,21003.47579,0.00000,0.01528,251.45792
83.30000,4.16506,21011.80702,0.00000,0.01529,251.55767
83.30800,4.16547,20349.70522,0.00000,0.01551,243.63085
83.31000,4.16565,19668.37794,0.00000,0.01594,235.47386
83.31200,4.16589,18807.99979,0.00000,0.01669,225.17324
83.31400,4.16613,17822.84230,0.00000,0.01764,213.37873
83.31600,4.16643,16736.59980,0.00000,0.01864,200.37401
83.31800,4.16679,15582.29923,0.00000,0.01965,186.55449
83.32000,4.16715,14396.46780,0.00000,0.02069,172.35747
83.32200,4.16751,13198.40252,0.00000,0.02173,158.01399
83.32400,4.16787,11999.41933,0.00000,0.02274,143.65951