File: scratch/college-stuff/ME Lab/ME lab Fall 2013/group5/group5.is_tens_RawData/Specimen_RawData_3.csv
Time,Extension,Load,Strain 2,Tensile strain,Tensile stress
(sec),(mm),(N),(mm/mm),(mm/mm),(MPa)
0.00000,0.00000,-0.23928,0.00000,0.00000,-0.00293
0.10000,0.00167,1.49386,0.00000,0.00000,0.01827
0.20000,0.00753,3.60008,0.00000,0.00001,0.04402
0.30000,0.01363,4.10681,0.00000,0.00001,0.05021
0.40000,0.01955,6.66902,0.00000,0.00001,0.08154
0.50000,0.02469,8.24559,0.00000,0.00002,0.10082
0.60000,0.03001,10.75433,0.00000,0.00001,0.13149
0.70000,0.03498,13.08396,0.00000,0.00002,0.15997
0.80000,0.04012,14.64786,0.00000,0.00002,0.17910
0.90000,0.04490,15.76066,0.00000,0.00002,0.19270
1.00000,0.05004,18.17984,0.00000,0.00003,0.22228
1.10000,0.05495,20.92508,0.00000,0.00003,0.25585
1.20000,0.06009,21.31503,0.00000,0.00003,0.26061
1.30000,0.06493,22.19216,0.00000,0.00003,0.27134
1.40000,0.07001,23.03864,0.00000,0.00003,0.28169
1.50000,0.07498,23.85302,0.00000,0.00003,0.29164
1.60000,0.08012,26.68976,0.00000,0.00003,0.32633
1.70000,0.08502,29.42976,0.00000,0.00003,0.35983
1.80000,0.09004,32.15860,0.00000,0.00003,0.39319
1.90000,0.09501,35.92542,0.00000,0.00003,0.43925
2.00000,0.10003,38.99994,0.00000,0.00004,0.47684
2.10000,0.10505,43.47029,0.00000,0.00004,0.53150
2.20000,0.11001,46.11491,0.00000,0.00003,0.56383
2.30000,0.11503,48.62025,0.00000,0.00004,0.59447
2.40000,0.11988,50.44882,0.00000,0.00003,0.61682
2.50000,0.12508,54.18907,0.00000,0.00003,0.66256
2.60000,0.12998,59.14766,0.00000,0.00003,0.72318
2.70000,0.13512,65.61736,0.00000,0.00003,0.80229
2.80000,0.13991,73.45382,0.00000,0.00003,0.89810
2.90000,0.14505,81.88782,0.00000,0.00003,1.00122
3.00000,0.14989,92.33485,0.00000,0.00002,1.12895
3.10000,0.15515,103.75608,0.00000,0.00002,1.26860
3.20000,0.15994,116.08336,0.00000,0.00002,1.41932
3.30000,0.16502,132.98397,0.00000,0.00002,1.62596
3.40000,0.16992,151.11850,0.00000,0.00002,1.84769
3.50000,0.17506,173.15780,0.00000,0.00002,2.11715
3.60000,0.17991,196.62587,0.00000,0.00002,2.40409
3.70000,0.18505,222.43585,0.00000,0.00002,2.71966
3.80000,0.18995,250.49956,0.00000,0.00002,3.06279
3.90000,0.19503,277.16416,0.00000,0.00002,3.38881
4.00000,0.20006,305.11890,0.00000,0.00002,3.73061
4.10000,0.20502,334.62259,0.00000,0.00002,4.09134
4.20000,0.21004,366.84375,0.00000,0.00003,4.48530
4.30000,0.21500,400.56044,0.00000,0.00002,4.89755
4.40000,0.22009,437.47094,0.00000,0.00003,5.34884
4.50000,0.22499,472.51098,0.00000,0.00003,5.77727
4.60000,0.23007,513.26728,0.00000,0.00003,6.27558
4.70000,0.23491,552.19871,0.00000,0.00004,6.75159
4.80000,0.24005,595.55834,0.00000,0.00004,7.28173
4.90000,0.24496,636.40499,0.00000,0.00005,7.78115
5.00000,0.25016,679.12336,0.00000,0.00005,8.30346
5.10000,0.25494,719.29502,0.00000,0.00005,8.79463
5.20000,0.26008,762.86173,0.00000,0.00006,9.32731
5.30000,0.26499,804.40072,0.00000,0.00007,9.83519
5.40000,0.27013,848.09093,0.00000,0.00007,10.36938
5.50000,0.27491,887.01565,0.00000,0.00008,10.84530
5.60000,0.28005,928.78314,0.00000,0.00008,11.35598
5.70000,0.28490,968.66731,0.00000,0.00008,11.84364
5.80000,0.29004,1011.50433,0.00000,0.00009,12.36739
5.90000,0.29500,1053.46097,0.00000,0.00009,12.88039
6.00000,0.30008,1092.71957,0.00000,0.00010,13.36039
6.10000,0.30499,1133.17333,0.00000,0.00011,13.85501
6.20000,0.31001,1172.88753,0.00000,0.00011,14.34058
6.30000,0.31491,1215.10783,0.00000,0.00012,14.85680
6.40000,0.32005,1257.41698,0.00000,0.00013,15.37410
6.50000,0.32496,1300.78830,0.00000,0.00013,15.90439
6.60000,0.32998,1341.17762,0.00000,0.00014,16.39822
6.70000,0.33494,1382.81826,0.00000,0.00015,16.90735
6.80000,0.33990,1422.87193,0.00000,0.00015,17.39707
6.90000,0.34505,1468.71209,0.00000,0.00015,17.95755
7.00000,0.34995,1513.03951,0.00000,0.00016,18.49953
7.10000,0.35503,1567.73273,0.00000,0.00018,19.16825
7.20000,0.35987,1620.41616,0.00000,0.00018,19.81239
7.30000,0.36507,1680.88824,0.00000,0.00019,20.55177
7.40000,0.36992,1735.20874,0.00000,0.00020,21.21593
7.50000,0.37506,1793.88374,0.00000,0.00021,21.93334
7.60000,0.37984,1847.89654,0.00000,0.00022,22.59374
7.70000,0.38498,1906.25694,0.00000,0.00023,23.30729
7.80000,0.38989,1961.60898,0.00000,0.00024,23.98407
7.90000,0.39503,2017.24488,0.00000,0.00025,24.66431
8.00000,0.39987,2072.53955,0.00000,0.00026,25.34039
8.10000,0.40501,2127.50100,0.00000,0.00027,26.01239
8.20000,0.40992,2179.36020,0.00000,0.00028,26.64645
8.30000,0.41500,2233.77701,0.00000,0.00029,27.31179
8.40000,0.41996,2287.20978,0.00000,0.00029,27.96510
8.50000,0.42498,2339.65907,0.00000,0.00031,28.60639
8.60000,0.42995,2390.21070,0.00000,0.00032,29.22447
8.70000,0.43497,2439.86063,0.00000,0.00033,29.83152
8.80000,0.43999,2491.98340,0.00000,0.00034,30.46881
8.90000,0.44501,2540.69194,0.00000,0.00035,31.06436
9.00000,0.44998,2592.39227,0.00000,0.00036,31.69649
9.10000,0.45494,2637.92574,0.00000,0.00036,32.25321
9.20000,0.46002,2687.60547,0.00000,0.00037,32.86063
9.30000,0.46504,2732.50621,0.00000,0.00038,33.40962
9.40000,0.47006,2781.83855,0.00000,0.00039,34.01280
9.50000,0.47491,2823.78644,0.00000,0.00040,34.52568
9.60000,0.48005,2870.83965,0.00000,0.00041,35.10099
9.70000,0.48495,2913.73488,0.00000,0.00042,35.62546
9.80000,0.49009,2958.46518,0.00000,0.00042,36.17236
9.90000,0.49494,2997.96052,0.00000,0.00043,36.65526
10.00000,0.50002,3040.83917,0.00000,0.00044,37.17953
10.10000,0.50486,3079.60901,0.00000,0.00044,37.65356
10.20000,0.51012,3122.02163,0.00000,0.00045,38.17212
10.30000,0.51497,3158.05897,0.00000,0.00045,38.61274
10.40000,0.52005,3198.82594,0.00000,0.00046,39.11119
10.50000,0.52489,3232.51449,0.00000,0.00046,39.52309
10.60000,0.53003,3270.61675,0.00000,0.00047,39.98896
10.70000,0.53494,3305.94182,0.00000,0.00049,40.42087
10.80000,0.54002,3343.78108,0.00000,0.00048,40.88352
10.90000,0.54492,3380.21144,0.00000,0.00049,41.32894
11.00000,0.55000,3414.43270,0.00000,0.00050,41.74736
11.10000,0.55497,3451.82791,0.00000,0.00051,42.20458
11.20000,0.55999,3487.95950,0.00000,0.00051,42.64635
11.30000,0.56501,3527.10225,0.00000,0.00052,43.12494
11.40000,0.56997,3562.65865,0.00000,0.00053,43.55967
11.50000,0.57500,3600.94607,0.00000,0.00053,44.02780
11.60000,0.57996,3635.41842,0.00000,0.00054,44.44929
11.70000,0.58510,3673.98672,0.00000,0.00055,44.92085
11.80000,0.58988,3708.25417,0.00000,0.00056,45.33983
11.90000,0.59503,3748.69406,0.00000,0.00056,45.83428
12.00000,0.59981,3782.09203,0.00000,0.00057,46.24263
12.10000,0.60501,3822.49355,0.00000,0.00058,46.73661
12.20000,0.60985,3856.03346,0.00000,0.00058,47.14669
12.30000,0.61493,3895.45187,0.00000,0.00059,47.62865
12.40000,0.61984,3931.72614,0.00000,0.00060,48.07216
12.50000,0.62504,3969.82431,0.00000,0.00060,48.53798
12.60000,0.62994,4005.48242,0.00000,0.00061,48.97396
12.70000,0.63508,4042.89849,0.00000,0.00062,49.43144
12.80000,0.63993,4079.65407,0.00000,0.00063,49.88084
12.90000,0.64501,4118.12663,0.00000,0.00063,50.35123
13.00000,0.64997,4156.19053,0.00000,0.00064,50.81663
13.10000,0.65505,4193.80143,0.00000,0.00065,51.27649
13.20000,0.65996,4232.00577,0.00000,0.00065,51.74360
13.30000,0.66498,4267.38895,0.00000,0.00066,52.17622
13.40000,0.66994,4307.31289,0.00000,0.00066,52.66436
13.50000,0.67496,4344.50954,0.00000,0.00067,53.11916
13.60000,0.68005,4384.31278,0.00000,0.00069,53.60582
13.70000,0.68507,4422.69407,0.00000,0.00068,54.07510
13.80000,0.69003,4461.21022,0.00000,0.00070,54.54602
13.90000,0.69499,4499.43058,0.00000,0.00070,55.01333
14.00000,0.70008,4538.38520,0.00000,0.00071,55.48962
14.10000,0.70504,4577.17143,0.00000,0.00072,55.96385
14.20000,0.71006,4617.16838,0.00000,0.00072,56.45288
14.30000,0.71490,4653.67548,0.00000,0.00073,56.89925
14.40000,0.72004,4694.77177,0.00000,0.00073,57.40172
14.50000,0.72495,4732.50225,0.00000,0.00075,57.86304
14.60000,0.73015,4776.23567,0.00000,0.00076,58.39776
14.70000,0.73499,4814.00378,0.00000,0.00075,58.85954
14.80000,0.74013,4853.79919,0.00000,0.00077,59.34610
14.90000,0.74492,4890.17069,0.00000,0.00077,59.79081
15.00000,0.75012,4932.59132,0.00000,0.00078,60.30947
15.10000,0.75490,4970.64814,0.00000,0.00079,60.77479
15.20000,0.76004,5014.57006,0.00000,0.00079,61.31181
15.30000,0.76489,5052.50394,0.00000,0.00081,61.77561
15.40000,0.77003,5094.40117,0.00000,0.00081,62.28788
15.50000,0.77493,5132.17002,0.00000,0.00082,62.74967
15.60000,0.77995,5174.60257,0.00000,0.00083,63.26848
15.70000,0.78492,5216.25057,0.00000,0.00083,63.77770
15.80000,0.79000,5255.59969,0.00000,0.00084,64.25881
15.90000,0.79502,5297.98195,0.00000,0.00085,64.77701
16.00000,0.79998,5337.95618,0.00000,0.00086,65.26576
16.10000,0.80495,5381.70375,0.00000,0.00087,65.80065
16.20000,0.80997,5421.37921,0.00000,0.00088,66.28575
16.30000,0.81499,5463.83709,0.00000,0.00088,66.80487
16.40000,0.81995,5500.89031,0.00000,0.00089,67.25791
16.50000,0.82504,5544.58834,0.00000,0.00090,67.79220
16.60000,0.82988,5586.30638,0.00000,0.00090,68.30227
16.70000,0.83502,5630.49875,0.00000,0.00091,68.84260
16.80000,0.83986,5669.15050,0.00000,0.00092,69.31519
16.90000,0.84512,5713.40546,0.00000,0.00093,69.85628
17.00000,0.84991,5750.45906,0.00000,0.00094,70.30932
17.10000,0.85505,5796.99166,0.00000,0.00094,70.87827
17.20000,0.85989,5836.27224,0.00000,0.00095,71.35854
17.30000,0.86509,5881.16087,0.00000,0.00096,71.90738
17.40000,0.86994,5921.71289,0.00000,0.00097,72.40320
17.50000,0.87502,5964.96649,0.00000,0.00097,72.93205
17.60000,0.87992,6006.74339,0.00000,0.00099,73.44284
17.70000,0.88500,6050.25664,0.00000,0.00099,73.97487
17.80000,0.88997,6092.71377,0.00000,0.00100,74.49398
17.90000,0.89505,6134.22059,0.00000,0.00101,75.00147
18.00000,0.89995,6178.63834,0.00000,0.00102,75.54456
18.10000,0.90503,6221.47880,0.00000,0.00103,76.06836
18.20000,0.91000,6265.47039,0.00000,0.00104,76.60623
18.30000,0.91502,6305.28629,0.00000,0.00104,77.09305
18.40000,0.91998,6348.99735,0.00000,0.00105,77.62749
18.50000,0.92500,6390.19534,0.00000,0.00106,78.13121
18.60000,0.92997,6436.61246,0.00000,0.00107,78.69874
18.70000,0.93499,6476.73458,0.00000,0.00108,79.18930
18.80000,0.94007,6522.19877,0.00000,0.00109,79.74518
18.90000,0.94491,6562.31865,0.00000,0.00109,80.23571
19.00000,0.95000,6609.36311,0.00000,0.00110,80.81091
19.10000,0.95484,6650.15802,0.00000,0.00111,81.30970
19.20000,0.96004,6696.61909,0.00000,0.00112,81.87777
19.30000,0.96494,6737.46616,0.00000,0.00113,82.37720
19.40000,0.97002,6782.85360,0.00000,0.00114,82.93214
19.50000,0.97487,6826.20779,0.00000,0.00115,83.46222
19.60000,0.98007,6872.06015,0.00000,0.00115,84.02284
19.70000,0.98491,6912.63825,0.00000,0.00116,84.51898
19.80000,0.99005,6957.84912,0.00000,0.00117,85.07176
19.90000,0.99490,6999.97768,0.00000,0.00118,85.58685
20.00000,0.99998,7046.58255,0.00000,0.00119,86.15668
20.10000,1.00488,7089.35484,0.00000,0.00119,86.67965
20.20000,1.01008,7134.00692,0.00000,0.00121,87.22559
20.30000,1.01499,7177.29405,0.00000,0.00121,87.75485
20.40000,1.02001,7221.56465,0.00000,0.00122,88.29614
20.50000,1.02491,7268.88403,0.00000,0.00123,88.87470
20.60000,1.02999,7311.94615,0.00000,0.00124,89.40121
20.70000,1.03502,7357.73370,0.00000,0.00125,89.96104
20.80000,1.03998,7399.17979,0.00000,0.00126,90.46779
20.90000,1.04494,7448.84163,0.00000,0.00127,91.07499
21.00000,1.04990,7491.50813,0.00000,0.00128,91.59667
21.10000,1.05499,7538.09884,0.00000,0.00129,92.16632
21.20000,1.05995,7581.05814,0.00000,0.00130,92.69157
21.30000,1.06503,7628.73814,0.00000,0.00131,93.27454
21.40000,1.06987,7672.24133,0.00000,0.00132,93.80644
21.50000,1.07502,7719.73059,0.00000,0.00133,94.38708
21.60000,1.07992,7761.18785,0.00000,0.00133,94.89397
21.70000,1.08512,7809.66282,0.00000,0.00134,95.48666
21.80000,1.08990,7852.76294,0.00000,0.00135,96.01363
21.90000,1.09504,7900.79311,0.00000,0.00136,96.60088
22.00000,1.09989,7942.30029,0.00000,0.00137,97.10838
22.10000,1.10503,7988.61459,0.00000,0.00138,97.67465
22.20000,1.10993,8032.73022,0.00000,0.00139,98.21404
22.30000,1.11501,8082.31905,0.00000,0.00140,98.82035
22.40000,1.11992,8126.90705,0.00000,0.00141,99.36552
22.50000,1.12500,8173.00603,0.00000,0.00142,99.92916
22.60000,1.12996,8217.40776,0.00000,0.00143,100.47205
22.70000,1.13498,8263.24895,0.00000,0.00144,101.03253
22.80000,1.13995,8310.08255,0.00000,0.00144,101.60516
22.90000,1.14497,8356.11299,0.00000,0.00146,102.16796
23.00000,1.14993,8401.80963,0.00000,0.00147,102.72668
23.10000,1.15501,8447.74768,0.00000,0.00148,103.28835
23.20000,1.15998,8494.17374,0.00000,0.00149,103.85599
23.30000,1.16500,8538.58590,0.00000,0.00150,104.39901
23.40000,1.17002,8585.83823,0.00000,0.00151,104.97675
23.50000,1.17498,8628.30207,0.00000,0.00151,105.49594
23.60000,1.18007,8678.24182,0.00000,0.00152,106.10654
23.70000,1.18491,8722.08700,0.00000,0.00154,106.64262
23.80000,1.18999,8771.07158,0.00000,0.00154,107.24155
23.90000,1.19489,8812.94012,0.00000,0.00155,107.75346
24.00000,1.20003,8862.63996,0.00000,0.00156,108.36113
24.10000,1.20488,8905.97105,0.00000,0.00157,108.89093
24.20000,1.21008,8957.38527,0.00000,0.00158,109.51955
24.30000,1.21486,9001.39958,0.00000,0.00160,110.05771
24.40000,1.22000,9050.83865,0.00000,0.00160,110.66218
24.50000,1.22491,9095.96756,0.00000,0.00161,111.21396
24.60000,1.23005,9143.98730,0.00000,0.00162,111.80109
24.70000,1.23489,9189.35090,0.00000,0.00163,112.35574
24.80000,1.23997,9237.87653,0.00000,0.00164,112.94905
24.90000,1.24488,9284.36741,0.00000,0.00165,113.51748
25.00000,1.25002,9332.90124,0.00000,0.00166,114.11089
25.10000,1.25492,9378.55244,0.00000,0.00167,114.66905
25.20000,1.25994,9423.39078,0.00000,0.00168,115.21728
25.30000,1.26497,9472.49085,0.00000,0.00169,115.81761
25.40000,1.26993,9517.61156,0.00000,0.00170,116.36929
25.50000,1.27501,9567.79644,0.00000,0.00171,116.98289
25.60000,1.27997,9611.78020,0.00000,0.00172,117.52067
25.70000,1.28500,9662.81518,0.00000,0.00173,118.14466
25.80000,1.28996,9705.98534,0.00000,0.00174,118.67249
25.90000,1.29504,9757.09930,0.00000,0.00175,119.29744
26.00000,1.29994,9800.31565,0.00000,0.00176,119.82584
26.10000,1.30503,9852.36689,0.00000,0.00177,120.46225
26.20000,1.30987,9896.75447,0.00000,0.00178,121.00497
26.30000,1.31501,9949.17303,0.00000,0.00179,121.64588
26.40000,1.31991,9992.70156,0.00000,0.00180,122.17809
26.50000,1.32505,10041.04763,0.00000,0.00181,122.76920
26.60000,1.32984,10088.19565,0.00000,0.00182,123.34567
26.70000,1.33504,10139.34910,0.00000,0.00183,123.97111
26.80000,1.33994,10186.12981,0.00000,0.00184,124.54308
26.90000,1.34514,10233.16458,0.00000,0.00185,125.11817
27.00000,1.34999,10278.86197,0.00000,0.00186,125.67690
27.10000,1.35501,10328.12446,0.00000,0.00187,126.27922
27.20000,1.35997,10376.07864,0.00000,0.00188,126.86554
27.30000,1.36505,10425.37913,0.00000,0.00189,127.46832
27.40000,1.36996,10469.69518,0.00000,0.00190,128.01016
27.50000,1.37504,10517.67766,0.00000,0.00191,128.59683
27.60000,1.37988,10566.32996,0.00000,0.00192,129.19169
27.70000,1.38496,10615.03515,0.00000,0.00193,129.78720
27.80000,1.38999,10664.27901,0.00000,0.00194,130.38929
27.90000,1.39507,10710.96361,0.00000,0.00195,130.96009
28.00000,1.39997,10760.91602,0.00000,0.00197,131.57084
28.10000,1.40493,10807.57231,0.00000,0.00197,132.14130
28.20000,1.41002,10856.89515,0.00000,0.00198,132.74435
28.30000,1.41498,10903.10216,0.00000,0.00199,133.30931
28.40000,1.42006,10955.42312,0.00000,0.00201,133.94903
28.50000,1.42484,10998.80710,0.00000,0.00202,134.47947
28.60000,1.43005,11051.72113,0.00000,0.00203,135.12644
28.70000,1.43489,11094.98292,0.00000,0.00204,135.65539
28.80000,1.44009,11147.57806,0.00000,0.00205,136.29846
28.90000,1.44493,11192.86790,0.00000,0.00206,136.85220
29.00000,1.45007,11245.03687,0.00000,0.00207,137.49006
29.10000,1.45492,11289.95195,0.00000,0.00208,138.03922
29.20000,1.46006,11339.69277,0.00000,0.00209,138.64739
29.30000,1.46490,11387.79819,0.00000,0.00210,139.23556
29.40000,1.47004,11438.21552,0.00000,0.00211,139.85200
29.50000,1.47489,11485.81803,0.00000,0.00212,140.43402
29.60000,1.47997,11536.08933,0.00000,0.00214,141.04868
29.70000,1.48493,11585.29595,0.00000,0.00215,141.65031
29.80000,1.49001,11633.17934,0.00000,0.00216,142.23577
29.90000,1.49492,11681.33691,0.00000,0.00217,142.82458
30.00000,1.49994,11729.37825,0.00000,0.00218,143.41197
30.10000,1.50496,11783.21764,0.00000,0.00219,144.07025
30.20000,1.50998,11829.77408,0.00000,0.00220,144.63948
30.30000,1.51501,11879.19751,0.00000,0.00222,145.24377
30.40000,1.51997,11923.28483,0.00000,0.00223,145.78281
30.50000,1.52499,11975.85240,0.00000,0.00224,146.42554
30.60000,1.52995,12023.10398,0.00000,0.00225,147.00328
30.70000,1.53504,12074.19410,0.00000,0.00226,147.62794
30.80000,1.54000,12119.00190,0.00000,0.00227,148.17579
30.90000,1.54502,12171.43834,0.00000,0.00228,148.81692
31.00000,1.54986,12216.41153,0.00000,0.00229,149.36680
31.10000,1.55506,12269.85976,0.00000,0.00231,150.02029
31.20000,1.55991,12315.36940,0.00000,0.00232,150.57673
31.30000,1.56505,12367.86321,0.00000,0.00233,151.21856
31.40000,1.56989,12415.22804,0.00000,0.00234,151.79767
31.50000,1.57503,12465.96426,0.00000,0.00235,152.41801
31.60000,1.57988,12512.33220,0.00000,0.00236,152.98494
31.70000,1.58508,12564.38494,0.00000,0.00238,153.62137
31.80000,1.58992,12611.51135,0.00000,0.00239,154.19758
31.90000,1.59500,12663.47766,0.00000,0.00240,154.83295
32.00000,1.59991,12710.98405,0.00000,0.00241,155.41380
32.10000,1.60505,12760.14298,0.00000,0.00242,156.01486
32.20000,1.61001,12809.23784,0.00000,0.00244,156.61512
32.30000,1.61503,12857.55634,0.00000,0.00245,157.20590
32.40000,1.62000,12909.33192,0.00000,0.00246,157.83895
32.50000,1.62502,12956.10815,0.00000,0.00247,158.41087
32.60000,1.62998,13007.25192,0.00000,0.00248,159.03619
32.70000,1.63500,13055.00716,0.00000,0.00250,159.62008
32.80000,1.64003,13106.57710,0.00000,0.00251,160.25061
32.90000,1.64499,13153.26691,0.00000,0.00252,160.82148
33.00000,1.65001,13206.81870,0.00000,0.00253,161.47624
33.10000,1.65491,13253.73948,0.00000,0.00254,162.04993
33.20000,1.66006,13306.62817,0.00000,0.00256,162.69658
33.30000,1.66490,13351.88448,0.00000,0.00257,163.24992
33.40000,1.67004,13405.47800,0.00000,0.00259,163.90519
33.50000,1.67488,13452.69233,0.00000,0.00260,164.48247
33.60000,1.68008,13506.07574,0.00000,0.00261,165.13518
33.70000,1.68493,13551.79399,0.00000,0.00262,165.69416
33.80000,1.69007,13604.27141,0.00000,0.00263,166.33579
33.90000,1.69485,13652.11308,0.00000,0.00265,166.92074
34.00000,1.69999,13701.71607,0.00000,0.00266,167.52722
34.10000,1.70490,13749.52048,0.00000,0.00267,168.11171
34.20000,1.70998,13798.50060,0.00000,0.00269,168.71058
34.30000,1.71488,13850.78430,0.00000,0.00270,169.34983
34.40000,1.71996,13900.43497,0.00000,0.00271,169.95690
34.50000,1.72493,13949.38231,0.00000,0.00272,170.55537
34.60000,1.73001,13999.14324,0.00000,0.00274,171.16378
34.70000,1.73491,14050.12906,0.00000,0.00275,171.78717
34.80000,1.73999,14099.84827,0.00000,0.00277,172.39507
34.90000,1.74502,14150.82812,0.00000,0.00278,173.01839
35.00000,1.74998,14197.28696,0.00000,0.00279,173.58643
35.10000,1.75500,14248.54696,0.00000,0.00280,174.21317
35.20000,1.75996,14296.84162,0.00000,0.00282,174.80366
35.30000,1.76499,14350.28166,0.00000,0.00283,175.45706
35.40000,1.76995,14396.40075,0.00000,0.00284,176.02094
35.50000,1.77509,14450.25355,0.00000,0.00286,176.67939
35.60000,1.77999,14495.74083,0.00000,0.00287,177.23555
35.70000,1.78508,14548.05732,0.00000,0.00289,177.87521
35.80000,1.78992,14594.48785,0.00000,0.00290,178.44290
35.90000,1.79506,14644.96106,0.00000,0.00291,179.06002
36.00000,1.79996,14693.62974,0.00000,0.00293,179.65508
36.10000,1.80510,14745.68993,0.00000,0.00294,180.29161
36.20000,1.80995,14791.93121,0.00000,0.00296,180.85699
36.30000,1.81509,14845.42638,0.00000,0.00297,181.51106
36.40000,1.81993,14892.34120,0.00000,0.00299,182.08467
36.50000,1.82513,14944.39095,0.00000,0.00300,182.72107
36.60000,1.82998,14991.71555,0.00000,0.00302,183.29970
36.70000,1.83506,15043.55073,0.00000,0.00303,183.93347
36.80000,1.83990,15093.29230,0.00000,0.00305,184.54165
36.90000,1.84504,15143.65673,0.00000,0.00307,185.15744
37.00000,1.84995,15192.41035,0.00000,0.00308,185.75354
37.10000,1.85503,15241.97161,0.00000,0.00309,186.35951
37.20000,1.85993,15294.02286,0.00000,0.00311,186.99593
37.30000,1.86501,15341.41600,0.00000,0.00313,187.57539
37.40000,1.86998,15392.90994,0.00000,0.00314,188.20499
37.50000,1.87500,15439.30769,0.00000,0.00316,188.77229
37.60000,1.88002,15493.72077,0.00000,0.00318,189.43758
37.70000,1.88498,15540.84122,0.00000,0.00319,190.01371
37.80000,1.89007,15591.12370,0.00000,0.00321,190.62850
37.90000,1.89497,15636.72125,0.00000,0.00322,191.18601
38.00000,1.89999,15689.55928,0.00000,0.00324,191.83204
38.10000,1.90477,15736.99713,0.00000,0.00326,192.41205
38.20000,1.91004,15790.41481,0.00000,0.00328,193.06518
38.30000,1.91482,15834.55503,0.00000,0.00329,193.60487
38.40000,1.92008,15888.17835,0.00000,0.00331,194.26051
38.50000,1.92486,15934.16780,0.00000,0.00333,194.82281
38.60000,1.93000,15988.56896,0.00000,0.00335,195.48796
38.70000,1.93485,16037.37622,0.00000,0.00337,196.08471
38.80000,1.94005,16088.50509,0.00000,0.00338,196.70985
38.90000,1.94489,16132.94333,0.00000,0.00340,197.25318
39.00000,1.94997,16184.66526,0.00000,0.00342,197.88557
39.10000,1.95488,16232.98228,0.00000,0.00344,198.47633
39.20000,1.95996,16284.24823,0.00000,0.00346,199.10315
39.30000,1.96498,16333.69923,0.00000,0.00348,199.70777
39.40000,1.97000,16378.87061,0.00000,0.00350,200.26007
39.50000,1.97491,16428.57194,0.00000,0.00352,200.86775
39.60000,1.97999,16477.97525,0.00000,0.00354,201.47180
39.70000,1.98501,16529.51539,0.00000,0.00356,202.10196
39.80000,1.99003,16575.19937,0.00000,0.00358,202.66053
39.90000,1.99506,16624.98713,0.00000,0.00360,203.26927
40.00000,2.00002,16670.65322,0.00000,0.00363,203.82762
40.10000,2.00504,16723.14405,0.00000,0.00365,204.46941
40.20000,2.01000,16767.75664,0.00000,0.00367,205.01488
40.30000,2.01509,16817.17783,0.00000,0.00369,205.61914
40.40000,2.01999,16860.56405,0.00000,0.00371,206.14961
40.50000,2.02501,16911.93432,0.00000,0.00374,206.77770
40.60000,2.02991,16957.29643,0.00000,0.00377,207.33233
40.70000,2.03511,17006.59394,0.00000,0.00379,207.93508
40.80000,2.03996,17049.38263,0.00000,0.00382,208.45824
40.90000,2.04504,17096.25870,0.00000,0.00384,209.03138
41.00000,2.04988,17143.45366,0.00000,0.00387,209.60842
41.10000,2.05508,17192.21920,0.00000,0.00391,210.20467
41.20000,2.05999,17234.66665,0.00000,0.00394,210.72366
41.30000,2.06513,17280.57414,0.00000,0.00397,211.28496
41.40000,2.06991,17319.82678,0.00000,0.00400,211.76489
41.50000,2.07505,17367.59394,0.00000,0.00404,212.34893
41.60000,2.07996,17410.22170,0.00000,0.00408,212.87012
41.70000,2.08504,17453.15194,0.00000,0.00412,213.39502
41.80000,2.09000,17493.92748,0.00000,0.00416,213.89357
41.90000,2.09496,17532.06551,0.00000,0.00421,214.35988
42.00000,2.09993,17573.32385,0.00000,0.00426,214.86433
42.10000,2.10501,17609.22372,0.00000,0.00432,215.30327
42.20000,2.11003,17646.73591,0.00000,0.00438,215.76192
42.30000,2.11499,17678.30700,0.00000,0.00445,216.14793
42.40000,2.11996,17714.33651,0.00000,0.00451,216.58845
42.50000,2.12492,17744.80194,0.00000,0.00459,216.96095
42.60000,2.13006,17778.47260,0.00000,0.00466,217.37263
42.70000,2.13496,17804.12793,0.00000,0.00475,217.68631
42.80000,2.14005,17834.49054,0.00000,0.00484,218.05755
42.90000,2.14489,17857.66184,0.00000,0.00492,218.34085
43.00000,2.15003,17885.47933,0.00000,0.00502,218.68097
43.10000,2.15493,17906.87144,0.00000,0.00512,218.94253
43.20000,2.16013,17933.32398,0.00000,0.00522,219.26596
43.30000,2.16492,17952.19779,0.00000,0.00533,219.49672
43.40000,2.17006,17975.94577,0.00000,0.00544,219.78708
43.50000,2.17490,17994.61693,0.00000,0.00556,220.01537
43.60000,2.18010,18014.89443,0.00000,0.00569,220.26330
43.70000,2.18495,18031.70145,0.00000,0.00581,220.46879
43.80000,2.18997,18049.93451,0.00000,0.00593,220.69172
43.90000,2.19487,18064.86845,0.00000,0.00605,220.87431
44.00000,2.20001,18084.53649,0.00000,0.00619,221.11479
44.10000,2.20498,18098.36775,0.00000,0.00632,221.28390
44.20000,2.21000,18112.35845,0.00000,0.00646,221.45496
44.30000,2.21496,18127.70814,0.00000,0.00660,221.64264
44.40000,2.22004,18140.96719,0.00000,0.00674,221.80475
44.50000,2.22507,18155.90709,0.00000,0.00688,221.98742
44.60000,2.23009,18167.85634,0.00000,0.00702,222.13352
44.70000,2.23505,18181.37616,0.00000,0.00717,222.29882
44.80000,2.24001,18192.75469,0.00000,0.00731,222.43795
44.90000,2.24504,18207.51429,0.00000,0.00746,222.61841
45.00000,2.25000,18215.30461,0.00000,0.00761,222.71366
45.10000,2.25508,18230.08657,0.00000,0.00776,222.89439
45.20000,2.25992,18237.29724,0.00000,0.00791,222.98256
45.30000,2.26506,18253.70491,0.00000,0.00806,223.18317
45.40000,2.26997,18260.22565,0.00000,0.00822,223.26289
45.50000,2.27511,18272.96466,0.00000,0.00837,223.41865
45.60000,2.27995,18278.99218,0.00000,0.00853,223.49235
45.70000,2.28503,18291.42570,0.00000,0.00869,223.64437
45.80000,2.28988,18299.37994,0.00000,0.00885,223.74162
45.90000,2.29508,18311.74493,0.00000,0.00901,223.89281
46.00000,2.29992,18316.73384,0.00000,0.00917,223.95381
46.10000,2.30506,18328.20773,0.00000,0.00933,224.09409
46.20000,2.30991,18335.04736,0.00000,0.00949,224.17772
46.30000,2.31499,18344.47533,0.00000,0.00966,224.29299
46.40000,2.31995,18353.51437,0.00000,0.00982,224.40351
46.50000,2.32503,18361.08118,0.00000,0.00999,224.49603
46.60000,2.32994,18367.36202,0.00000,0.01016,224.57282
46.70000,2.33502,18375.11957,0.00000,0.01032,224.66767
46.80000,2.33992,18385.08248,0.00000,0.01049,224.78949
46.90000,2.34500,18389.89109,0.00000,0.01066,224.84828
47.00000,2.35003,18398.76771,0.00000,0.01083,224.95681
47.10000,2.35493,18402.03255,0.00000,0.01100,224.99673
47.20000,2.35995,18413.15180,0.00000,0.01116,225.13268
47.30000,2.36491,18415.86828,0.00000,0.01134,225.16590
47.40000,2.37000,18423.98196,0.00000,0.01151,225.26510
47.50000,2.37496,18427.29449,0.00000,0.01168,225.30560
47.60000,2.38004,18436.27989,0.00000,0.01185,225.41546
47.70000,2.38488,18439.47768,0.00000,0.01203,225.45456
47.80000,2.39008,18446.71667,0.00000,0.01220,225.54307
47.90000,2.39493,18447.03853,0.00000,0.01238,225.54701
48.00000,2.40007,18454.56362,0.00000,0.01256,225.63901
48.10000,2.40491,18456.94631,0.00000,0.01274,225.66815
48.20000,2.40999,18463.17351,0.00000,0.01292,225.74428
48.30000,2.41490,18464.09440,0.00000,0.01310,225.75554
48.40000,2.42010,18468.44554,0.00000,0.01327,225.80874
48.50000,2.42494,18468.22500,0.00000,0.01345,225.80605
48.60000,2.42996,18472.02480,0.00000,0.01363,225.85251
48.70000,2.43493,18473.14984,0.00000,0.01381,225.86626
48.80000,2.44001,18473.15878,0.00000,0.01400,225.86637
48.90000,2.44503,18471.82512,0.00000,0.01419,225.85007
49.00000,2.45005,18467.70048,0.00000,0.01438,225.79963
49.10000,2.45496,18465.17026,0.00000,0.01457,225.76870
49.20000,2.46004,18457.93575,0.00000,0.01477,225.68024
49.30000,2.46500,18445.94330,0.00000,0.01497,225.53361
49.40000,2.47002,18428.28095,0.00000,0.01518,225.31766
49.50000,2.47499,18404.98894,0.00000,0.01540,225.03288
49.60000,2.47995,18381.65671,0.00000,0.01561,224.74760
49.70000,2.48503,18363.36106,0.00000,0.01584,224.52390
49.80000,2.48999,18331.90024,0.00000,0.01606,224.13924
49.90000,2.49513,18300.66890,0.00000,0.01629,223.75738
50.00000,2.49992,18239.30889,0.00000,0.01655,223.00715
50.10000,2.50500,18188.76863,0.00000,0.01681,222.38921
50.20000,2.50996,18148.91398,0.00000,0.01705,221.90192
50.30000,2.51516,18119.81946,0.00000,0.01729,221.54619
50.40000,2.51995,18068.98564,0.00000,0.01753,220.92465
50.50000,2.52509,17961.22342,0.00000,0.01784,219.60707
50.54000,2.52706,17704.24247,0.00000,0.01820,216.46504
50.57400,2.52874,17447.44182,0.00000,0.01858,213.32520
50.58800,2.52945,17188.67272,0.00000,0.01894,210.16130
50.59800,2.52999,16894.48506,0.00000,0.01936,206.56435
50.60800,2.53053,16601.06927,0.00000,0.01978,202.97683
50.62000,2.53119,16325.84780,0.00000,0.02017,199.61177
50.64200,2.53238,16073.43256,0.00000,0.02058,196.52556
50.71400,2.53615,15813.86775,0.00000,0.02109,193.35193
50.76200,2.53842,15556.53661,0.00000,0.02155,190.20561
50.80000,2.54028,15301.60010,0.00000,0.02195,187.08857
50.80800,2.54069,14995.84764,0.00000,0.02237,183.35022
50.81200,2.54093,14720.72005,0.00000,0.02278,179.98631
50.81600,2.54117,14388.04865,0.00000,0.02325,175.91882
50.82000,2.54147,14021.45177,0.00000,0.02375,171.43654
50.82400,2.54171,13633.86959,0.00000,0.02430,166.69768
50.82800,2.54195,13215.26170,0.00000,0.02488,161.57947
50.83200,2.54225,12756.19119,0.00000,0.02551,155.96654
50.83400,2.54237,12494.84420,0.00000,0.02590,152.77112
50.83600,2.54255,12171.63578,0.00000,0.02643,148.81934
50.83800,2.54267,11744.07005,0.00000,0.02726,143.59160
50.84000,2.54285,11200.86536,0.00000,0.02845,136.94998
50.84200,2.54309,10572.35003,0.00000,0.02982,129.26530
50.84400,2.54327,9897.72454,0.00000,0.03105,121.01683
50.84600,2.54350,9197.63371,0.00000,0.03189,112.45701