File: scratch/college-stuff/ME Lab/ME lab Fall 2013/group5/group5.is_tens_RawData/Specimen_RawData_1.csv
Time,Extension,Load,Strain 2,Tensile strain,Tensile stress
(sec),(mm),(N),(mm/mm),(mm/mm),(MPa)
0.00000,0.00000,-0.16812,0.00000,0.00000,-0.00206
0.30000,0.01363,30.60859,0.00000,0.00001,0.37541
0.60000,0.03001,45.40887,0.00000,0.00001,0.55693
0.90000,0.04496,62.91275,0.00000,0.00000,0.77161
1.20000,0.06009,79.59145,0.00000,-0.00001,0.97617
1.50000,0.07498,99.58596,0.00000,-0.00002,1.22140
1.80000,0.09004,126.50475,0.00000,-0.00002,1.55156
2.10000,0.10511,152.90515,0.00000,-0.00003,1.87535
2.40000,0.11988,179.72001,0.00000,-0.00003,2.20423
2.70000,0.13506,209.60348,0.00000,-0.00004,2.57075
3.00000,0.14995,243.64993,0.00000,-0.00005,2.98832
3.30000,0.16502,288.00780,0.00000,-0.00006,3.53236
3.60000,0.17997,338.00378,0.00000,-0.00007,4.14556
3.90000,0.19503,404.44653,0.00000,-0.00007,4.96046
4.20000,0.21004,478.36788,0.00000,-0.00008,5.86710
4.50000,0.22505,561.71175,0.00000,-0.00008,6.88929
4.80000,0.24005,661.76951,0.00000,-0.00008,8.11649
5.10000,0.25494,774.47146,0.00000,-0.00008,9.49875
5.40000,0.27013,903.06001,0.00000,-0.00007,11.07587
5.70000,0.28490,1040.99130,0.00000,-0.00007,12.76757
6.00000,0.30008,1185.89448,0.00000,-0.00006,14.54478
6.30000,0.31491,1339.28042,0.00000,-0.00006,16.42604
6.60000,0.32998,1509.13754,0.00000,-0.00004,18.50930
6.90000,0.34505,1715.68766,0.00000,-0.00002,21.04260
7.20000,0.35981,1935.18475,0.00000,0.00001,23.73470
7.50000,0.37506,2165.43246,0.00000,0.00003,26.55864
7.80000,0.38989,2388.74964,0.00000,0.00007,29.29759
8.10000,0.40501,2609.42113,0.00000,0.00010,32.00409
8.40000,0.41996,2828.92771,0.00000,0.00013,34.69629
8.70000,0.43497,3055.77237,0.00000,0.00016,37.47850
9.00000,0.44998,3289.34416,0.00000,0.00019,40.34322
9.30000,0.46498,3518.73375,0.00000,0.00023,43.15664
9.60000,0.48005,3754.30323,0.00000,0.00027,46.04586
9.90000,0.49488,3982.40089,0.00000,0.00031,48.84344
10.20000,0.51006,4217.67160,0.00000,0.00034,51.72899
10.50000,0.52489,4447.76304,0.00000,0.00038,54.55102
10.80000,0.54002,4677.71105,0.00000,0.00042,57.37129
11.10000,0.55491,4906.86819,0.00000,0.00046,60.18187
11.40000,0.56991,5133.24142,0.00000,0.00050,62.95829
11.70000,0.58504,5361.89228,0.00000,0.00054,65.76265
12.00000,0.59975,5579.91751,0.00000,0.00058,68.43670
12.30000,0.61493,5803.53811,0.00000,0.00062,71.17936
12.60000,0.62994,6020.62531,0.00000,0.00065,73.84190
12.90000,0.64501,6235.94113,0.00000,0.00069,76.48271
13.20000,0.65990,6447.25412,0.00000,0.00072,79.07442
13.50000,0.67496,6653.01383,0.00000,0.00076,81.59803
13.80000,0.69003,6854.87539,0.00000,0.00079,84.07383
14.10000,0.70498,7031.52493,0.00000,0.00082,86.24040
14.40000,0.72004,7191.65057,0.00000,0.00085,88.20431
14.70000,0.73493,7345.36797,0.00000,0.00087,90.08963
15.00000,0.75012,7502.19375,0.00000,0.00091,92.01307
15.30000,0.76489,7655.74351,0.00000,0.00093,93.89633
15.60000,0.77995,7808.23380,0.00000,0.00095,95.76660
15.90000,0.79502,7951.25887,0.00000,0.00098,97.52077
16.20000,0.80997,8091.83195,0.00000,0.00100,99.24488
16.50000,0.82504,8231.91553,0.00000,0.00103,100.96298
16.80000,0.83992,8370.52986,0.00000,0.00105,102.66306
17.10000,0.85505,8515.39597,0.00000,0.00107,104.43982
17.40000,0.86994,8657.50834,0.00000,0.00110,106.18280
17.70000,0.88500,8799.36367,0.00000,0.00112,107.92263
18.00000,0.89989,8943.52049,0.00000,0.00115,109.69069
18.30000,0.91508,9084.29474,0.00000,0.00117,111.41726
18.60000,0.92997,9229.98935,0.00000,0.00120,113.20418
18.90000,0.94491,9367.61349,0.00000,0.00122,114.89211
19.20000,0.96004,9517.25692,0.00000,0.00125,116.72746
19.50000,0.97487,9659.40356,0.00000,0.00127,118.47087
19.80000,0.99005,9805.55266,0.00000,0.00130,120.26336
20.10000,1.00488,9948.69620,0.00000,0.00133,122.01899
20.40000,1.02001,10095.72670,0.00000,0.00135,123.82229
20.70000,1.03496,10242.13359,0.00000,0.00138,125.61795
21.00000,1.04990,10387.87737,0.00000,0.00140,127.40547
21.30000,1.06503,10537.96858,0.00000,0.00143,129.24631
21.60000,1.07992,10681.06443,0.00000,0.00146,131.00135
21.90000,1.09504,10830.89560,0.00000,0.00148,132.83901
22.20000,1.10993,10975.41302,0.00000,0.00151,134.61149
22.50000,1.12500,11126.29101,0.00000,0.00154,136.46198
22.80000,1.13989,11272.21286,0.00000,0.00156,138.25168
23.10000,1.15501,11419.81632,0.00000,0.00160,140.06201
23.40000,1.17002,11571.15698,0.00000,0.00162,141.91818
23.70000,1.18491,11714.73935,0.00000,0.00165,143.67919
24.00000,1.20003,11867.19686,0.00000,0.00168,145.54906
24.30000,1.21486,12016.81420,0.00000,0.00170,147.38409
24.60000,1.23005,12168.20180,0.00000,0.00173,149.24083
24.90000,1.24494,12318.07023,0.00000,0.00176,151.07894
25.20000,1.25994,12467.73228,0.00000,0.00179,152.91452
25.50000,1.27501,12620.32241,0.00000,0.00182,154.78601
25.80000,1.28996,12767.17037,0.00000,0.00185,156.58707
26.10000,1.30503,12920.71491,0.00000,0.00188,158.47027
26.40000,1.31991,13069.60881,0.00000,0.00191,160.29643
26.70000,1.33504,13225.04580,0.00000,0.00194,162.20283
27.00000,1.34993,13372.18732,0.00000,0.00197,164.00750
27.30000,1.36505,13527.85081,0.00000,0.00200,165.91668
27.60000,1.37988,13675.92961,0.00000,0.00203,167.73284
27.90000,1.39507,13829.39816,0.00000,0.00206,169.61511
28.20000,1.40996,13981.15158,0.00000,0.00209,171.47634
28.50000,1.42484,14129.61483,0.00000,0.00212,173.29721
28.80000,1.44009,14286.91745,0.00000,0.00215,175.22650
29.10000,1.45492,14436.00804,0.00000,0.00218,177.05507
29.40000,1.47004,14588.89246,0.00000,0.00221,178.93017
29.70000,1.48493,14741.14209,0.00000,0.00224,180.79748
30.00000,1.49994,14894.15914,0.00000,0.00227,182.67421
30.30000,1.51501,15048.93452,0.00000,0.00230,184.57250
30.60000,1.52995,15197.78073,0.00000,0.00233,186.39808
30.90000,1.54502,15351.96900,0.00000,0.00236,188.28917
31.20000,1.55991,15502.66147,0.00000,0.00240,190.13738
31.50000,1.57503,15657.22078,0.00000,0.00243,192.03303
31.80000,1.58992,15805.72575,0.00000,0.00246,193.85441
32.10000,1.60505,15961.21341,0.00000,0.00249,195.76144
32.40000,1.61994,16113.30211,0.00000,0.00253,197.62678
32.70000,1.63500,16262.89934,0.00000,0.00257,199.46157
33.00000,1.65001,16416.66442,0.00000,0.00260,201.34747
33.30000,1.66490,16565.89359,0.00000,0.00263,203.17774
33.60000,1.68008,16721.55559,0.00000,0.00267,205.08690
33.90000,1.69485,16868.43634,0.00000,0.00270,206.88837
34.20000,1.70998,17015.95187,0.00000,0.00274,208.69762
34.50000,1.72493,17168.80798,0.00000,0.00277,210.57237
34.80000,1.73993,17316.60962,0.00000,0.00281,212.38514
35.10000,1.75500,17463.39798,0.00000,0.00284,214.18547
35.40000,1.76995,17609.83616,0.00000,0.00288,215.98151
35.70000,1.78508,17759.10854,0.00000,0.00292,217.81231
36.00000,1.79996,17898.77266,0.00000,0.00296,219.52526
36.30000,1.81509,18045.53419,0.00000,0.00300,221.32527
36.60000,1.82992,18186.28311,0.00000,0.00304,223.05153
36.90000,1.84504,18328.52215,0.00000,0.00308,224.79606
37.20000,1.85993,18468.38892,0.00000,0.00312,226.51150
37.50000,1.87500,18602.79441,0.00000,0.00317,228.15996
37.80000,1.89007,18741.67323,0.00000,0.00321,229.86329
38.10000,1.90477,18869.86792,0.00000,0.00326,231.43557
38.40000,1.92008,19006.66058,0.00000,0.00331,233.11331
38.70000,1.93485,19132.98070,0.00000,0.00336,234.66260
39.00000,1.94997,19258.81356,0.00000,0.00341,236.20592
39.30000,1.96498,19382.21455,0.00000,0.00347,237.71941
39.60000,1.97999,19500.14085,0.00000,0.00353,239.16576
39.90000,1.99506,19616.81396,0.00000,0.00358,240.59673
40.20000,2.01000,19726.24511,0.00000,0.00364,241.93889
40.50000,2.02501,19835.50638,0.00000,0.00370,243.27896
40.80000,2.03996,19936.40661,0.00000,0.00377,244.51648
41.10000,2.05508,20037.01776,0.00000,0.00384,245.75046
41.40000,2.06991,20124.16273,0.00000,0.00391,246.81927
41.70000,2.08504,20217.58258,0.00000,0.00398,247.96505
42.00000,2.09993,20298.62851,0.00000,0.00406,248.95907
42.30000,2.11499,20374.68404,0.00000,0.00414,249.89187
42.60000,2.13006,20450.67400,0.00000,0.00422,250.82388
42.90000,2.14489,20511.75088,0.00000,0.00431,251.57297
43.20000,2.16013,20577.04031,0.00000,0.00440,252.37374
43.50000,2.17490,20632.47710,0.00000,0.00450,253.05366
43.80000,2.18997,20685.91416,0.00000,0.00460,253.70906
44.10000,2.20498,20736.10127,0.00000,0.00471,254.32459
44.40000,2.22004,20780.88671,0.00000,0.00482,254.87388
44.70000,2.23499,20823.61132,0.00000,0.00494,255.39789
45.00000,2.25000,20861.56905,0.00000,0.00505,255.86343
45.30000,2.26506,20902.73201,0.00000,0.00517,256.36829
45.60000,2.27995,20933.31218,0.00000,0.00529,256.74335
45.90000,2.29508,20970.79456,0.00000,0.00542,257.20306
46.20000,2.30991,20999.01289,0.00000,0.00555,257.54916
46.50000,2.32509,21030.15631,0.00000,0.00569,257.93112
46.80000,2.33992,21057.88141,0.00000,0.00582,258.27117
47.10000,2.35493,21081.77245,0.00000,0.00596,258.56419
47.40000,2.37000,21109.13694,0.00000,0.00610,258.89981
47.70000,2.38488,21130.39792,0.00000,0.00625,259.16057
48.00000,2.40013,21154.26064,0.00000,0.00639,259.45324
48.30000,2.41490,21173.35796,0.00000,0.00654,259.68747
48.60000,2.42996,21193.89772,0.00000,0.00670,259.93938
48.90000,2.44503,21214.93220,0.00000,0.00685,260.19737
49.20000,2.46004,21234.68071,0.00000,0.00701,260.43958
49.50000,2.47499,21251.81407,0.00000,0.00716,260.64972
49.80000,2.48999,21267.72255,0.00000,0.00731,260.84483
50.10000,2.50500,21287.25648,0.00000,0.00748,261.08441
50.40000,2.51995,21299.99846,0.00000,0.00764,261.24069
50.70000,2.53507,21319.55028,0.00000,0.00781,261.48049
51.00000,2.54990,21331.59488,0.00000,0.00797,261.62822
51.30000,2.56509,21347.48697,0.00000,0.00814,261.82313
51.60000,2.57998,21363.33883,0.00000,0.00830,262.01755
51.90000,2.59498,21372.70272,0.00000,0.00847,262.13240
52.20000,2.61011,21390.31142,0.00000,0.00864,262.34836
52.50000,2.62494,21400.03145,0.00000,0.00881,262.46758
52.80000,2.64012,21414.66141,0.00000,0.00898,262.64701
53.10000,2.65495,21426.38713,0.00000,0.00915,262.79083
53.40000,2.66996,21439.22448,0.00000,0.00932,262.94827
53.70000,2.68497,21451.72656,0.00000,0.00949,263.10161
54.00000,2.70003,21463.75477,0.00000,0.00966,263.24913
54.30000,2.71498,21475.46560,0.00000,0.00984,263.39276
54.60000,2.72999,21484.81756,0.00000,0.01001,263.50746
54.90000,2.74505,21499.69339,0.00000,0.01018,263.68991
55.20000,2.75994,21506.61051,0.00000,0.01035,263.77475
55.50000,2.77507,21519.67287,0.00000,0.01052,263.93496
55.80000,2.78990,21528.35131,0.00000,0.01069,264.04140
56.10000,2.80502,21538.97434,0.00000,0.01087,264.17169
56.40000,2.81997,21551.52857,0.00000,0.01104,264.32566
56.70000,2.83492,21557.95991,0.00000,0.01121,264.40454
57.00000,2.85005,21570.30851,0.00000,0.01138,264.55600
57.30000,2.86487,21578.70680,0.00000,0.01154,264.65900
57.60000,2.88012,21588.86343,0.00000,0.01172,264.78357
57.90000,2.89495,21597.57018,0.00000,0.01189,264.89035
58.20000,2.90995,21609.77125,0.00000,0.01206,265.04000
58.50000,2.92502,21619.49575,0.00000,0.01223,265.15927
58.80000,2.94003,21628.74639,0.00000,0.01239,265.27273
59.10000,2.95504,21638.19820,0.00000,0.01256,265.38865
59.40000,2.96992,21645.77395,0.00000,0.01273,265.48157
59.70000,2.98505,21659.18946,0.00000,0.01290,265.64610
60.00000,2.99988,21664.78634,0.00000,0.01307,265.71475
60.30000,3.01506,21675.63736,0.00000,0.01324,265.84783
60.60000,3.02989,21682.48892,0.00000,0.01340,265.93187
60.90000,3.04508,21691.42365,0.00000,0.01356,266.04145
61.20000,3.06003,21702.64274,0.00000,0.01372,266.17905
61.50000,3.07497,21708.35882,0.00000,0.01389,266.24916
61.80000,3.09016,21720.49731,0.00000,0.01406,266.39803
62.10000,3.10499,21726.33260,0.00000,0.01423,266.46960
62.40000,3.12005,21735.48490,0.00000,0.01439,266.58185
62.70000,3.13494,21741.92220,0.00000,0.01456,266.66081
63.00000,3.15001,21753.39758,0.00000,0.01472,266.80155
63.30000,3.16496,21759.91237,0.00000,0.01488,266.88145
63.60000,3.18002,21769.48637,0.00000,0.01504,266.99888
63.90000,3.19497,21779.43289,0.00000,0.01520,267.12087
64.20000,3.21004,21784.77794,0.00000,0.01537,267.18642
64.50000,3.22510,21796.08345,0.00000,0.01552,267.32508
64.80000,3.23987,21800.00544,0.00000,0.01569,267.37319
65.10000,3.25506,21811.75947,0.00000,0.01585,267.51735
65.40000,3.26989,21818.22658,0.00000,0.01602,267.59667
65.70000,3.28507,21827.63964,0.00000,0.01618,267.71212
66.00000,3.30002,21835.93363,0.00000,0.01634,267.81384
66.30000,3.31497,21841.47090,0.00000,0.01649,267.88175
66.60000,3.33016,21853.25176,0.00000,0.01665,268.02624
66.90000,3.34492,21858.80393,0.00000,0.01680,268.09434
67.20000,3.36005,21869.04550,0.00000,0.01696,268.21995
67.50000,3.37500,21875.04023,0.00000,0.01712,268.29348
67.80000,3.39006,21883.88109,0.00000,0.01729,268.40191
68.10000,3.40501,21892.03799,0.00000,0.01745,268.50195
68.40000,3.42002,21898.00888,0.00000,0.01760,268.57518
68.70000,3.43503,21908.27876,0.00000,0.01775,268.70114
69.00000,3.44991,21912.93985,0.00000,0.01791,268.75831
69.30000,3.46504,21924.07250,0.00000,0.01807,268.89485
69.60000,3.47993,21929.23427,0.00000,0.01822,268.95816
69.90000,3.49505,21938.21669,0.00000,0.01838,269.06832
70.20000,3.50994,21945.11890,0.00000,0.01853,269.15298
70.50000,3.52507,21952.47412,0.00000,0.01869,269.24319
70.80000,3.54008,21962.53985,0.00000,0.01884,269.36664
71.10000,3.55496,21966.53932,0.00000,0.01900,269.41570
71.40000,3.57009,21976.41134,0.00000,0.01916,269.53677
71.70000,3.58498,21982.05739,0.00000,0.01931,269.60602
72.00000,3.59999,21990.20684,0.00000,0.01946,269.70597
72.30000,3.61493,21997.61122,0.00000,0.01961,269.79679
72.60000,3.63000,22006.86932,0.00000,0.01977,269.91034
72.90000,3.64501,22012.92217,0.00000,0.01993,269.98457
73.20000,3.66001,22018.82899,0.00000,0.02008,270.05702
73.50000,3.67502,22028.25546,0.00000,0.02024,270.17263
73.80000,3.68991,22031.26699,0.00000,0.02039,270.20957
74.10000,3.70509,22046.09513,0.00000,0.02055,270.39143
74.40000,3.71986,22049.33167,0.00000,0.02069,270.43113
74.70000,3.73505,22058.34240,0.00000,0.02085,270.54164
75.00000,3.75000,22066.05375,0.00000,0.02100,270.63622
75.30000,3.76500,22069.16511,0.00000,0.02115,270.67438
75.60000,3.78001,22080.92660,0.00000,0.02131,270.81864
75.90000,3.79490,22084.34790,0.00000,0.02146,270.86060
76.20000,3.81015,22096.49086,0.00000,0.02161,271.00953
76.50000,3.82491,22099.83468,0.00000,0.02176,271.05054
76.80000,3.84004,22107.71739,0.00000,0.02192,271.14722
77.10000,3.85499,22114.67326,0.00000,0.02207,271.23253
77.40000,3.86999,22121.93161,0.00000,0.02222,271.32155
77.70000,3.88500,22130.69946,0.00000,0.02238,271.42909
78.00000,3.90001,22135.51104,0.00000,0.02252,271.48810
78.30000,3.91502,22143.76479,0.00000,0.02267,271.58933
78.60000,3.92996,22147.41409,0.00000,0.02283,271.63409
78.90000,3.94503,22156.68410,0.00000,0.02297,271.74779
79.20000,3.95986,22159.51383,0.00000,0.02312,271.78249
79.50000,3.97510,22171.74470,0.00000,0.02328,271.93250
79.80000,3.98993,22177.98084,0.00000,0.02343,272.00899
80.10000,4.00506,22182.86693,0.00000,0.02358,272.06892
80.40000,4.02007,22192.18463,0.00000,0.02373,272.18320
80.70000,4.03495,22195.55825,0.00000,0.02387,272.22457
81.00000,4.05014,22205.99800,0.00000,0.02403,272.35261
81.30000,4.06485,22209.96022,0.00000,0.02418,272.40121
81.60000,4.08003,22219.65641,0.00000,0.02433,272.52013
81.90000,4.09492,22223.41150,0.00000,0.02448,272.56619
82.20000,4.10993,22230.68923,0.00000,0.02463,272.65545
82.50000,4.12494,22237.56909,0.00000,0.02477,272.73983
82.80000,4.14000,22243.42525,0.00000,0.02492,272.81165
83.10000,4.15501,22253.78454,0.00000,0.02507,272.93871
83.40000,4.16996,22255.83643,0.00000,0.02522,272.96387
83.70000,4.18503,22265.09452,0.00000,0.02537,273.07742
84.00000,4.19991,22269.56636,0.00000,0.02552,273.13227
84.30000,4.21510,22278.82892,0.00000,0.02567,273.24587
84.60000,4.22993,22284.81174,0.00000,0.02581,273.31925
84.90000,4.24499,22290.47418,0.00000,0.02596,273.38870
85.20000,4.26000,22298.70260,0.00000,0.02611,273.48962
85.50000,4.27489,22303.64978,0.00000,0.02626,273.55030
85.80000,4.29008,22311.47587,0.00000,0.02641,273.64628
86.10000,4.30496,22315.55879,0.00000,0.02655,273.69636
86.40000,4.32003,22323.98689,0.00000,0.02670,273.79973
86.70000,4.33492,22327.48866,0.00000,0.02685,273.84267
87.00000,4.34998,22336.82126,0.00000,0.02700,273.95714
87.30000,4.36499,22342.26167,0.00000,0.02715,274.02386
87.60000,4.38006,22346.70073,0.00000,0.02729,274.07831
87.90000,4.39501,22354.36738,0.00000,0.02744,274.17234
88.20000,4.40995,22357.56814,0.00000,0.02758,274.21159
88.50000,4.42514,22368.21204,0.00000,0.02773,274.34214
88.80000,4.43985,22370.39208,0.00000,0.02787,274.36888
89.10000,4.45509,22379.88859,0.00000,0.02802,274.48535
89.40000,4.46998,22384.88942,0.00000,0.02816,274.54669
89.70000,4.48505,22389.52219,0.00000,0.02831,274.60351
90.00000,4.50006,22398.15593,0.00000,0.02846,274.70940
90.30000,4.51494,22402.25673,0.00000,0.02861,274.75969
90.60000,4.53007,22410.67290,0.00000,0.02875,274.86291
90.90000,4.54490,22411.63105,0.00000,0.02889,274.87467
91.20000,4.55996,22419.36922,0.00000,0.02903,274.96957
91.50000,4.57497,22424.47287,0.00000,0.02918,275.03217
91.80000,4.58998,22430.56595,0.00000,0.02932,275.10690
92.10000,4.60499,22437.40857,0.00000,0.02947,275.19082
92.40000,4.61999,22442.19035,0.00000,0.02961,275.24947
92.70000,4.63506,22451.88504,0.00000,0.02976,275.36837
93.00000,4.65001,22453.82816,0.00000,0.02990,275.39221
93.30000,4.66514,22462.49765,0.00000,0.03004,275.49854
93.60000,4.67996,22466.97545,0.00000,0.03018,275.55346
93.90000,4.69515,22474.19655,0.00000,0.03032,275.64202
94.20000,4.70992,22479.27785,0.00000,0.03047,275.70434
94.50000,4.72492,22482.20146,0.00000,0.03061,275.74020
94.80000,4.73999,22491.19878,0.00000,0.03075,275.85055
95.10000,4.75488,22494.14772,0.00000,0.03090,275.88672
95.40000,4.77007,22501.72198,0.00000,0.03104,275.97962
95.70000,4.78489,22506.21766,0.00000,0.03118,276.03475
96.00000,4.80002,22513.47452,0.00000,0.03133,276.12376
96.30000,4.81503,22517.37416,0.00000,0.03147,276.17159
96.60000,4.83003,22522.52102,0.00000,0.03161,276.23471
96.90000,4.84504,22529.73020,0.00000,0.03175,276.32313
97.20000,4.86005,22532.52566,0.00000,0.03189,276.35742
97.50000,4.87512,22542.14287,0.00000,0.03203,276.47537
97.80000,4.88994,22543.22469,0.00000,0.03217,276.48864
98.10000,4.90513,22551.74518,0.00000,0.03231,276.59314
98.40000,4.91990,22554.74329,0.00000,0.03245,276.62991
98.70000,4.93508,22561.22679,0.00000,0.03260,276.70943
99.00000,4.94997,22568.56263,0.00000,0.03274,276.79940
99.30000,4.96498,22569.89032,0.00000,0.03288,276.81569
99.60000,4.98011,22578.90254,0.00000,0.03302,276.92622
99.90000,4.99493,22578.78184,0.00000,0.03316,276.92474
100.20000,5.01006,22586.38442,0.00000,0.03330,277.01799
100.50000,5.02495,22590.64019,0.00000,0.03343,277.07018
100.80000,5.04002,22596.79586,0.00000,0.03357,277.14568
101.10000,5.05496,22602.06640,0.00000,0.03371,277.21032
101.40000,5.07009,22607.11044,0.00000,0.03385,277.27219
101.70000,5.08504,22613.01428,0.00000,0.03400,277.34460
102.00000,5.10004,22615.52811,0.00000,0.03413,277.37543
102.30000,5.11505,22624.98885,0.00000,0.03427,277.49146
102.60000,5.12994,22624.76534,0.00000,0.03441,277.48872
102.90000,5.14506,22635.06204,0.00000,0.03455,277.61501
103.20000,5.15989,22637.72637,0.00000,0.03469,277.64769
103.50000,5.17508,22644.32311,0.00000,0.03482,277.72859
103.80000,5.18997,22648.84859,0.00000,0.03496,277.78410
104.10000,5.20497,22651.42649,0.00000,0.03509,277.81571
104.40000,5.22004,22658.07539,0.00000,0.03523,277.89726
104.70000,5.23487,22662.05400,0.00000,0.03537,277.94606
105.00000,5.25006,22667.67621,0.00000,0.03551,278.01501
105.30001,5.26494,22671.18990,0.00000,0.03565,278.05811
105.60001,5.28001,22677.95205,0.00000,0.03579,278.14105
105.90001,5.29502,22682.20782,0.00000,0.03592,278.19324
106.20001,5.31002,22688.83288,0.00000,0.03606,278.27450
106.50001,5.32497,22695.21803,0.00000,0.03620,278.35281
106.80001,5.34004,22697.00319,0.00000,0.03633,278.37470
107.10001,5.35505,22704.67728,0.00000,0.03647,278.46883
107.40001,5.36993,22704.44483,0.00000,0.03661,278.46598
107.70001,5.38506,22711.72255,0.00000,0.03675,278.55524
108.00001,5.39989,22715.67881,0.00000,0.03689,278.60376
108.30001,5.41507,22720.72881,0.00000,0.03702,278.66570
108.60001,5.43002,22726.26460,0.00000,0.03716,278.73359
108.90001,5.44491,22727.49841,0.00000,0.03729,278.74872
109.20001,5.46016,22735.23659,0.00000,0.03743,278.84363
109.50001,5.47498,22736.93383,0.00000,0.03756,278.86445
109.80001,5.48999,22742.43385,0.00000,0.03770,278.93190
110.10001,5.50494,22748.08139,0.00000,0.03784,279.00117
110.40001,5.52001,22753.37130,0.00000,0.03797,279.06605
110.70001,5.53495,22756.44541,0.00000,0.03811,279.10375
111.00001,5.55002,22760.06043,0.00000,0.03824,279.14809
111.30001,5.56503,22766.69890,0.00000,0.03838,279.22951
111.60001,5.57997,22767.11166,0.00000,0.03852,279.23457
111.90001,5.59510,22777.55737,0.00000,0.03865,279.36269
112.20001,5.60993,22775.86013,0.00000,0.03879,279.34187
112.50001,5.62511,22783.28240,0.00000,0.03893,279.43290
112.80001,5.63988,22784.53261,0.00000,0.03906,279.44824
113.10001,5.65501,22789.12961,0.00000,0.03919,279.50462
113.40001,5.67002,22795.51327,0.00000,0.03933,279.58291
113.70001,5.68484,22795.64291,0.00000,0.03946,279.58450
114.00001,5.70009,22803.60758,0.00000,0.03960,279.68219
114.30001,5.71492,22804.30943,0.00000,0.03973,279.69080
114.60001,5.73005,22809.32665,0.00000,0.03986,279.75233
114.90001,5.74499,22813.47364,0.00000,0.04000,279.80319
115.20001,5.76000,22819.73660,0.00000,0.04013,279.88001
115.50001,5.77495,22822.22360,0.00000,0.04026,279.91051
115.80001,5.79007,22826.97707,0.00000,0.04039,279.96881
116.10001,5.80496,22831.16132,0.00000,0.04052,280.02013
116.40001,5.81997,22831.71862,0.00000,0.04065,280.02697
116.70001,5.83510,22839.74588,0.00000,0.04079,280.12542
117.00001,5.84986,22840.34491,0.00000,0.04093,280.13277
117.30001,5.86505,22846.15636,0.00000,0.04106,280.20404
117.60001,5.87988,22849.14851,0.00000,0.04119,280.24074
117.90001,5.89506,22852.16749,0.00000,0.04132,280.27777
118.20001,5.91007,22859.22915,0.00000,0.04145,280.36438
118.50001,5.92490,22860.10981,0.00000,0.04157,280.37518
118.80001,5.94015,22867.83904,0.00000,0.04170,280.46998
119.10001,5.95497,22869.97586,0.00000,0.04184,280.49618
119.40001,5.97004,22874.44919,0.00000,0.04197,280.55105
119.70001,5.98499,22876.93769,0.00000,0.04211,280.58157
120.00001,6.00006,22883.32582,0.00000,0.04224,280.65992
120.30001,6.01488,22883.55529,0.00000,0.04237,280.66273
120.60001,6.03001,22888.41158,0.00000,0.04250,280.72229
120.90001,6.04496,22893.83858,0.00000,0.04262,280.78886
121.20001,6.05990,22893.07415,0.00000,0.04276,280.77948
121.50001,6.07509,22903.06836,0.00000,0.04289,280.90206
121.80001,6.08986,22902.65709,0.00000,0.04301,280.89701
122.10001,6.10510,22908.23758,0.00000,0.04314,280.96546
122.40001,6.11993,22912.75412,0.00000,0.04327,281.02085
122.70001,6.13500,22913.63031,0.00000,0.04340,281.03160
123.00001,6.15007,22920.76051,0.00000,0.04353,281.11905
123.30001,6.16495,22922.28043,0.00000,0.04366,281.13769
123.60001,6.18014,22927.04433,0.00000,0.04379,281.19612
123.90001,6.19497,22928.92635,0.00000,0.04392,281.21920
124.20001,6.21004,22935.57674,0.00000,0.04405,281.30077
124.50001,6.22504,22938.89970,0.00000,0.04419,281.34152
124.80001,6.24011,22943.12119,0.00000,0.04431,281.39330
125.10001,6.25494,22944.69178,0.00000,0.04444,281.41256
125.40001,6.27012,22947.75993,0.00000,0.04457,281.45019
125.70001,6.28495,22952.66688,0.00000,0.04470,281.51037
126.00001,6.29990,22953.94838,0.00000,0.04483,281.52609
126.30001,6.31509,22959.56165,0.00000,0.04496,281.59494
126.60001,6.32991,22960.28584,0.00000,0.04510,281.60382
126.90001,6.34510,22966.19564,0.00000,0.04523,281.67630
127.20001,6.35993,22969.99991,0.00000,0.04536,281.72296
127.50001,6.37499,22972.36025,0.00000,0.04548,281.75191
127.80001,6.39012,22979.10005,0.00000,0.04561,281.83457
128.10001,6.40501,22980.57973,0.00000,0.04574,281.85272
128.40001,6.42014,22984.92938,0.00000,0.04587,281.90607
128.70001,6.43496,22984.44211,0.00000,0.04600,281.90009
129.00001,6.45003,22990.35788,0.00000,0.04613,281.97265
129.30001,6.46492,22990.84663,0.00000,0.04627,281.97864
129.60001,6.47998,22996.42414,0.00000,0.04640,282.04705
129.90001,6.49487,22999.69345,0.00000,0.04653,282.08715
130.20001,6.51006,23001.93161,0.00000,0.04666,282.11460
130.50001,6.52495,23007.70283,0.00000,0.04679,282.18538
130.80001,6.53989,23006.77598,0.00000,0.04693,282.17401
131.10001,6.55508,23013.63647,0.00000,0.04706,282.25816
131.40001,6.56991,23016.25013,0.00000,0.04719,282.29021
131.70001,6.58504,23020.13785,0.00000,0.04732,282.33789
132.00001,6.59998,23023.86612,0.00000,0.04744,282.38362
132.30001,6.61499,23024.67972,0.00000,0.04757,282.39360
132.60001,6.63000,23028.99212,0.00000,0.04771,282.44649
132.90001,6.64488,23030.72959,0.00000,0.04783,282.46780
133.20001,6.66007,23036.42482,0.00000,0.04797,282.53765
133.50001,6.67490,23035.34150,0.00000,0.04811,282.52436
133.80001,6.68997,23041.09484,0.00000,0.04824,282.59493
134.10001,6.70491,23041.59105,0.00000,0.04837,282.60101
134.40001,6.72010,23048.46495,0.00000,0.04850,282.68532
134.70001,6.73493,23050.88937,0.00000,0.04863,282.71506
135.00001,6.74999,23049.73900,0.00000,0.04875,282.70095
135.30001,6.76506,23058.31164,0.00000,0.04889,282.80609
135.60001,6.77983,23053.74295,0.00000,0.04902,282.75005
135.90001,6.79508,23061.69868,0.00000,0.04915,282.84763
136.20001,6.80990,23063.39592,0.00000,0.04928,282.86845
136.50001,6.82509,23068.42208,0.00000,0.04942,282.93009
136.80001,6.83998,23071.14452,0.00000,0.04955,282.96348
137.10001,6.85498,23070.75560,0.00000,0.04967,282.95871
137.40001,6.87011,23078.16744,0.00000,0.04981,283.04962
137.70001,6.88500,23077.37172,0.00000,0.04994,283.03986
138.00001,6.90007,23081.87932,0.00000,0.05007,283.09514
138.30001,6.91495,23083.01330,0.00000,0.05020,283.10905
138.60001,6.93002,23087.83978,0.00000,0.05033,283.16825
138.90001,6.94497,23088.28235,0.00000,0.05046,283.17367
139.20001,6.96003,23090.76041,0.00000,0.05059,283.20407
139.50001,6.97492,23092.69309,0.00000,0.05072,283.22777
139.80001,6.99005,23095.05641,0.00000,0.05085,283.25676
140.10001,7.00506,23101.60846,0.00000,0.05098,283.33712
140.40001,7.01988,23100.70395,0.00000,0.05111,283.32602
140.70001,7.03507,23106.72551,0.00000,0.05124,283.39988
141.00001,7.04996,23107.68366,0.00000,0.05137,283.41163
141.30001,7.06509,23110.99321,0.00000,0.05150,283.45222
141.60001,7.07997,23112.91546,0.00000,0.05163,283.47579
141.90001,7.09498,23115.43822,0.00000,0.05176,283.50674
142.20001,7.11005,23118.90572,0.00000,0.05189,283.54926
142.50001,7.12487,23120.42862,0.00000,0.05203,283.56794
142.80001,7.14006,23123.82013,0.00000,0.05216,283.60954
143.10001,7.15495,23123.63535,0.00000,0.05229,283.60727
143.40001,7.17002,23127.87920,0.00000,0.05242,283.65932
143.70001,7.18490,23129.36336,0.00000,0.05255,283.67753
144.00001,7.19997,23133.42690,0.00000,0.05268,283.72736
144.30001,7.21498,23137.75867,0.00000,0.05280,283.78049
144.60001,7.22998,23137.61711,0.00000,0.05293,283.77876
144.90001,7.24505,23142.73268,0.00000,0.05307,283.84150
145.20001,7.25994,23141.25150,0.00000,0.05320,283.82333
145.50001,7.27513,23147.04955,0.00000,0.05333,283.89444
145.80001,7.28995,23149.61404,0.00000,0.05346,283.92590
146.10001,7.30508,23151.50946,0.00000,0.05359,283.94914
146.40001,7.32003,23154.96206,0.00000,0.05371,283.99149
146.70001,7.33503,23153.32443,0.00000,0.05384,283.97140
147.00001,7.35004,23157.73219,0.00000,0.05397,284.02546
147.30001,7.36499,23160.39801,0.00000,0.05411,284.05816
147.60001,7.38006,23162.65702,0.00000,0.05424,284.08587
147.90001,7.39494,23162.69577,0.00000,0.05436,284.08634
148.20001,7.41001,23167.46712,0.00000,0.05450,284.14486
148.50001,7.42496,23167.34493,0.00000,0.05462,284.14336
148.80001,7.44003,23170.08674,0.00000,0.05476,284.17699
149.10001,7.45497,23174.86703,0.00000,0.05489,284.23562
149.40001,7.47004,23174.78955,0.00000,0.05502,284.23467
149.70001,7.48511,23180.44007,0.00000,0.05515,284.30397
150.00001,7.49993,23176.68051,0.00000,0.05527,284.25786
150.30001,7.51518,23182.95985,0.00000,0.05541,284.33488
150.60001,7.52995,23183.56633,0.00000,0.05554,284.34232
150.90001,7.54507,23186.92654,0.00000,0.05567,284.38353
151.20001,7.55996,23189.48507,0.00000,0.05579,284.41491
151.50001,7.57491,23188.66551,0.00000,0.05592,284.40486
151.80001,7.59004,23192.67392,0.00000,0.05605,284.45402
152.10001,7.60492,23191.07801,0.00000,0.05619,284.43444
152.40001,7.62005,23194.31603,0.00000,0.05632,284.47416
152.70001,7.63494,23196.19209,0.00000,0.05645,284.49717
153.00001,7.65001,23201.49243,0.00000,0.05658,284.56218
153.30001,7.66501,23203.04513,0.00000,0.05670,284.58122
153.60001,7.68008,23203.93324,0.00000,0.05683,284.59211
153.90001,7.69503,23208.62263,0.00000,0.05696,284.64963
154.20001,7.71009,23206.59459,0.00000,0.05709,284.62475
154.50001,7.72504,23211.83681,0.00000,0.05722,284.68905
154.80001,7.73987,23210.60300,0.00000,0.05735,284.67392
155.10001,7.75518,23216.43233,0.00000,0.05748,284.74541
155.40001,7.76988,23214.61290,0.00000,0.05761,284.72310
155.70001,7.78501,23217.61996,0.00000,0.05774,284.75998
156.00001,7.79996,23220.27981,0.00000,0.05787,284.79260
156.30001,7.81496,23222.09775,0.00000,0.05800,284.81490
156.60001,7.83009,23225.69788,0.00000,0.05813,284.85905
156.90001,7.84492,23224.78294,0.00000,0.05825,284.84783
157.20001,7.86011,23229.48426,0.00000,0.05838,284.90549
157.50001,7.87499,23228.67811,0.00000,0.05852,284.89560
157.80001,7.89000,23232.61201,0.00000,0.05865,284.94385
158.10001,7.90495,23234.10511,0.00000,0.05878,284.96216
158.40001,7.92007,23235.60566,0.00000,0.05891,284.98057
158.70001,7.93496,23239.50827,0.00000,0.05904,285.02843
159.00001,7.95003,23237.08832,0.00000,0.05917,284.99875
159.30001,7.96510,23244.20512,0.00000,0.05930,285.08604
159.60001,7.97992,23240.35764,0.00000,0.05943,285.03885
159.90001,7.99511,23245.83232,0.00000,0.05957,285.10600
160.20001,8.00988,23247.10637,0.00000,0.05969,285.12162
160.50001,8.02501,23248.11220,0.00000,0.05982,285.13396
160.80001,8.04001,23250.28628,0.00000,0.05995,285.16062
161.10001,8.05496,23249.17316,0.00000,0.06008,285.14697
161.40001,8.07003,23253.84170,0.00000,0.06021,285.20423
161.70001,8.08491,23254.40645,0.00000,0.06034,285.21116
162.00001,8.10004,23258.74120,0.00000,0.06048,285.26432
162.30001,8.11499,23257.46417,0.00000,0.06061,285.24866
162.60001,8.13000,23261.24310,0.00000,0.06074,285.29501
162.90001,8.14494,23261.17307,0.00000,0.06087,285.29415
163.20001,8.16007,23264.85068,0.00000,0.06100,285.33925
163.50001,8.17490,23265.97124,0.00000,0.06113,285.35300
163.80001,8.19002,23265.49441,0.00000,0.06126,285.34715
164.10001,8.20509,23270.10781,0.00000,0.06139,285.40373
164.40001,8.21986,23267.68339,0.00000,0.06152,285.37400
164.70001,8.23511,23270.26129,0.00000,0.06166,285.40561
165.00001,8.24987,23271.42358,0.00000,0.06179,285.41987
165.30001,8.26500,23274.02681,0.00000,0.06192,285.45180
165.60001,8.28001,23277.08304,0.00000,0.06205,285.48928
165.90001,8.29490,23277.06963,0.00000,0.06218,285.48912
166.20001,8.31008,23280.32553,0.00000,0.06231,285.52905
166.50001,8.32497,23279.55216,0.00000,0.06245,285.51956
166.80001,8.33998,23282.11218,0.00000,0.06258,285.55096
167.10001,8.35498,23282.48471,0.00000,0.06271,285.55553
167.40001,8.36999,23285.94774,0.00000,0.06284,285.59801
167.70001,8.38488,23285.12371,0.00000,0.06297,285.58790
168.00001,8.40012,23287.72396,0.00000,0.06311,285.61979
168.30001,8.41495,23288.93691,0.00000,0.06324,285.63467
168.60001,8.42996,23288.78194,0.00000,0.06337,285.63277
168.90001,8.44509,23293.69336,0.00000,0.06351,285.69300
169.20001,8.45985,23290.52538,0.00000,0.06364,285.65415
169.50001,8.47510,23294.02119,0.00000,0.06377,285.69702
169.80001,8.48993,23294.42352,0.00000,0.06390,285.70196
170.10001,8.50494,23295.47107,0.00000,0.06403,285.71481
170.40001,8.52000,23300.00997,0.00000,0.06416,285.77048
170.70001,8.53489,23299.96526,0.00000,0.06429,285.76993
171.00001,8.55002,23301.95308,0.00000,0.06443,285.79431
171.30001,8.56496,23300.96364,0.00000,0.06457,285.78217
171.60001,8.58009,23303.92897,0.00000,0.06470,285.81854
171.90001,8.59498,23303.13623,0.00000,0.06484,285.80882
172.20001,8.61005,23307.04331,0.00000,0.06497,285.85674
172.50001,8.62499,23306.47409,0.00000,0.06510,285.84976
172.80001,8.64012,23307.80476,0.00000,0.06524,285.86608
173.10001,8.65501,23309.72105,0.00000,0.06537,285.88958
173.40001,8.66995,23307.55740,0.00000,0.06550,285.86304
173.70001,8.68508,23313.19004,0.00000,0.06564,285.93213
174.00001,8.69985,23311.30654,0.00000,0.06578,285.90903
174.30001,8.71504,23313.50446,0.00000,0.06591,285.93598
174.60001,8.72992,23314.80235,0.00000,0.06604,285.95190
174.90001,8.74499,23315.69344,0.00000,0.06618,285.96283
175.20001,8.76012,23319.06557,0.00000,0.06632,286.00419
175.50001,8.77500,23317.30127,0.00000,0.06645,285.98255
175.80001,8.79007,23319.52304,0.00000,0.06659,286.00980
176.10001,8.80502,23318.52019,0.00000,0.06672,285.99750
176.40001,8.82009,23323.22448,0.00000,0.06686,286.05520
176.70001,8.83491,23320.31280,0.00000,0.06700,286.01949
177.00001,8.85010,23323.57913,0.00000,0.06713,286.05955
177.30001,8.86493,23323.40032,0.00000,0.06727,286.05735
177.60001,8.88005,23323.26919,0.00000,0.06740,286.05575
177.90001,8.89500,23327.45939,0.00000,0.06754,286.10714
178.20001,8.90989,23324.76974,0.00000,0.06767,286.07415
178.50001,8.92508,23328.97484,0.00000,0.06781,286.12572
178.80001,8.93984,23327.44896,0.00000,0.06795,286.10701
179.10001,8.95503,23330.09690,0.00000,0.06809,286.13949
179.40001,8.96998,23332.41403,0.00000,0.06822,286.16791
179.70001,8.98499,23332.23373,0.00000,0.06836,286.16569
180.00001,9.00005,23334.42569,0.00000,0.06850,286.19258
180.30001,9.01500,23333.04882,0.00000,0.06864,286.17569
180.60001,9.03007,23334.98746,0.00000,0.06878,286.19947
180.90001,9.04501,23334.66113,0.00000,0.06892,286.19547
181.20001,9.06008,23336.91865,0.00000,0.06906,286.22315
181.50001,9.07497,23336.28684,0.00000,0.06919,286.21541
181.80001,9.09009,23340.43980,0.00000,0.06933,286.26634
182.10001,9.10492,23338.56076,0.00000,0.06947,286.24329
182.40001,9.12005,23336.89481,0.00000,0.06961,286.22286
182.70001,9.13500,23340.67374,0.00000,0.06975,286.26921
183.00001,9.14983,23336.44778,0.00000,0.06989,286.21738
183.30001,9.16507,23342.18919,0.00000,0.07004,286.28780
183.60001,9.17990,23342.18174,0.00000,0.07017,286.28771
183.90001,9.19503,23341.93438,0.00000,0.07032,286.28467
184.20001,9.20997,23342.56768,0.00000,0.07046,286.29244
184.50001,9.22504,23343.63908,0.00000,0.07060,286.30558
184.80001,9.24005,23346.11863,0.00000,0.07074,286.33599
185.10001,9.25505,23344.01608,0.00000,0.07088,286.31020
185.40001,9.27000,23346.33619,0.00000,0.07103,286.33866
185.70001,9.28501,23342.75544,0.00000,0.07117,286.29474
186.00001,9.30008,23347.13340,0.00000,0.07131,286.34844
186.30001,9.31490,23342.82249,0.00000,0.07145,286.29556
186.60001,9.33003,23345.83551,0.00000,0.07160,286.33252
186.90001,9.34498,23348.56838,0.00000,0.07174,286.36604
187.20001,9.36005,23345.55238,0.00000,0.07188,286.32905
187.50001,9.37505,23348.68759,0.00000,0.07202,286.36750
187.80001,9.38988,23345.46894,0.00000,0.07216,286.32802
188.10001,9.40513,23349.38645,0.00000,0.07230,286.37607
188.40001,9.41995,23349.66809,0.00000,0.07244,286.37952
188.70001,9.43502,23349.20019,0.00000,0.07259,286.37379
189.00001,9.44997,23350.21645,0.00000,0.07274,286.38625
189.30001,9.46498,23349.80071,0.00000,0.07288,286.38115
189.60001,9.47998,23349.79326,0.00000,0.07303,286.38106
189.90001,9.49499,23349.02734,0.00000,0.07317,286.37167
190.20001,9.51006,23350.69031,0.00000,0.07331,286.39206
190.50001,9.52494,23348.46556,0.00000,0.07345,286.36477
190.80001,9.54001,23351.56649,0.00000,0.07360,286.40281
191.10001,9.55490,23346.90392,0.00000,0.07374,286.34562
191.40001,9.57009,23350.62176,0.00000,0.07388,286.39122
191.70001,9.58497,23351.06581,0.00000,0.07403,286.39667
192.00001,9.59992,23348.69057,0.00000,0.07418,286.36753
192.30001,9.61505,23353.50066,0.00000,0.07432,286.42653
192.60001,9.62981,23348.27930,0.00000,0.07446,286.36249
192.90001,9.64512,23350.87657,0.00000,0.07461,286.39435
193.20001,9.65995,23349.70236,0.00000,0.07475,286.37994
193.50001,9.67502,23348.78892,0.00000,0.07490,286.36874
193.80001,9.69002,23351.50838,0.00000,0.07504,286.40209
194.10001,9.70503,23350.13002,0.00000,0.07519,286.38519
194.40001,9.72004,23350.52490,0.00000,0.07533,286.39003
194.70001,9.73504,23350.26115,0.00000,0.07548,286.38680
195.00001,9.74999,23347.82779,0.00000,0.07562,286.35695
195.30001,9.76500,23346.13353,0.00000,0.07577,286.33617
195.60001,9.78007,23348.55646,0.00000,0.07592,286.36589
195.90001,9.79483,23344.50036,0.00000,0.07606,286.31614
196.20001,9.81002,23346.66252,0.00000,0.07621,286.34266
196.50001,9.82491,23347.22728,0.00000,0.07635,286.34959
196.80001,9.83997,23343.69123,0.00000,0.07649,286.30622
197.10001,9.85510,23346.79067,0.00000,0.07664,286.34423
197.40001,9.86987,23342.76885,0.00000,0.07678,286.29491
197.70001,9.88512,23345.82210,0.00000,0.07693,286.33235
198.00001,9.89994,23343.01770,0.00000,0.07707,286.29796
198.30001,9.91507,23342.59599,0.00000,0.07722,286.29279
198.60001,9.93002,23340.44874,0.00000,0.07736,286.26645
198.90001,9.94503,23338.22697,0.00000,0.07750,286.23920
199.20001,9.95997,23338.53692,0.00000,0.07764,286.24300
199.50001,9.97492,23335.75487,0.00000,0.07779,286.20888
199.80001,9.99005,23337.33141,0.00000,0.07793,286.22822
200.10001,10.00499,23332.77166,0.00000,0.07807,286.17229
200.40001,10.02006,23334.61493,0.00000,0.07822,286.19490
200.70001,10.03489,23331.86269,0.00000,0.07836,286.16114
201.00001,10.05001,23332.70460,0.00000,0.07850,286.17147
201.30001,10.06496,23332.84318,0.00000,0.07864,286.17317
201.60001,10.07991,23327.03024,0.00000,0.07878,286.10187
201.90001,10.09504,23329.42188,0.00000,0.07892,286.13121
202.20001,10.10992,23324.98133,0.00000,0.07906,286.07675
202.50001,10.12511,23323.39436,0.00000,0.07920,286.05728
202.80001,10.13994,23320.63019,0.00000,0.07933,286.02338
203.10001,10.15507,23320.46926,0.00000,0.07947,286.02141
203.40001,10.17007,23318.34435,0.00000,0.07961,285.99534
203.70001,10.18502,23314.40896,0.00000,0.07974,285.94708
204.00001,10.20003,23313.71158,0.00000,0.07988,285.93852
204.30001,10.21498,23310.35137,0.00000,0.08001,285.89731
204.60001,10.22998,23311.65224,0.00000,0.08015,285.91327
204.90001,10.24493,23307.05673,0.00000,0.08028,285.85690
205.20001,10.26000,23306.03898,0.00000,0.08041,285.84442
205.50001,10.27494,23302.23471,0.00000,0.08054,285.79776
205.80001,10.29007,23297.61535,0.00000,0.08067,285.74111
206.10001,10.30502,23296.94629,0.00000,0.08080,285.73290
206.40001,10.31991,23290.35401,0.00000,0.08093,285.65205
206.70001,10.33515,23292.09447,0.00000,0.08106,285.67339
207.00001,10.34998,23285.65270,0.00000,0.08119,285.59439
207.30001,10.36511,23280.86495,0.00000,0.08131,285.53567
207.60001,10.37999,23279.19304,0.00000,0.08143,285.51516
207.90001,10.39500,23273.34434,0.00000,0.08156,285.44343
208.20001,10.40995,23270.13165,0.00000,0.08167,285.40402
208.50001,10.42490,23264.15181,0.00000,0.08179,285.33068
208.80001,10.44002,23262.63934,0.00000,0.08191,285.31213
209.10001,10.45497,23255.13959,0.00000,0.08202,285.22015
209.40001,10.47004,23253.26800,0.00000,0.08214,285.19719
209.70001,10.48492,23245.29588,0.00000,0.08224,285.09942
210.00001,10.50005,23244.60745,0.00000,0.08236,285.09097
210.30001,10.51494,23238.32959,0.00000,0.08247,285.01398
210.60001,10.53007,23231.69857,0.00000,0.08257,284.93265
210.90001,10.54507,23228.93739,0.00000,0.08268,284.89878
211.20001,10.56002,23216.62009,0.00000,0.08278,284.74771
211.50001,10.57509,23215.17318,0.00000,0.08287,284.72997
211.80001,10.58991,23204.81539,0.00000,0.08297,284.60293
212.10001,10.60516,23200.68181,0.00000,0.08307,284.55223
212.40001,10.61993,23191.12718,0.00000,0.08316,284.43505
212.70001,10.63500,23185.37831,0.00000,0.08325,284.36454
213.00001,10.65000,23179.31056,0.00000,0.08334,284.29012
213.30001,10.66495,23172.04773,0.00000,0.08342,284.20104
213.60001,10.68002,23166.00382,0.00000,0.08351,284.12691
213.90001,10.69497,23154.80560,0.00000,0.08358,283.98957
214.20001,10.71003,23148.87941,0.00000,0.08366,283.91689
214.50001,10.72492,23135.67251,0.00000,0.08374,283.75491
214.80001,10.74005,23128.43800,0.00000,0.08380,283.66618
215.10001,10.75487,23119.11285,0.00000,0.08388,283.55180
215.40001,10.77006,23108.68055,0.00000,0.08394,283.42385
215.70001,10.78495,23099.17212,0.00000,0.08401,283.30724
216.00001,10.79996,23084.80442,0.00000,0.08406,283.13102
216.30001,10.81514,23076.96491,0.00000,0.08413,283.03487
216.60001,10.82991,23061.17415,0.00000,0.08418,282.84120
216.90001,10.84510,23050.59582,0.00000,0.08424,282.71146
217.20001,10.85992,23037.37700,0.00000,0.08428,282.54933
217.50001,10.87505,23026.37696,0.00000,0.08433,282.41442
217.80001,10.89000,23010.70541,0.00000,0.08437,282.22221
218.10001,10.90495,22995.25589,0.00000,0.08441,282.03272
218.40001,10.92001,22982.23823,0.00000,0.08445,281.87306
218.70001,10.93502,22965.74414,0.00000,0.08448,281.67076
219.00001,10.95003,22951.48522,0.00000,0.08452,281.49588
219.30001,10.96491,22929.92324,0.00000,0.08455,281.23143
219.60001,10.98010,22915.88038,0.00000,0.08457,281.05919
219.90001,10.99499,22896.22575,0.00000,0.08459,280.81813
220.20001,11.01005,22877.24167,0.00000,0.08462,280.58530
220.50001,11.02494,22860.18580,0.00000,0.08464,280.37611
220.80001,11.04001,22837.36467,0.00000,0.08465,280.09621
221.10001,11.05514,22817.42096,0.00000,0.08468,279.85161
221.40001,11.06991,22792.67311,0.00000,0.08468,279.54808
221.70001,11.08503,22772.50439,0.00000,0.08470,279.30071
222.00001,11.09998,22750.36275,0.00000,0.08471,279.02915
222.30001,11.11505,22727.03052,0.00000,0.08471,278.74298
222.60001,11.12999,22703.03518,0.00000,0.08472,278.44869
222.90001,11.14500,22675.57681,0.00000,0.08473,278.11191
223.20001,11.16007,22649.46252,0.00000,0.08473,277.79163
223.50001,11.17502,22619.01200,0.00000,0.08473,277.41816
223.80001,11.19002,22593.15252,0.00000,0.08474,277.10099
224.10001,11.20497,22561.35643,0.00000,0.08474,276.71102
224.40001,11.22004,22533.21856,0.00000,0.08474,276.36592
224.70001,11.23486,22501.54912,0.00000,0.08473,275.97750
225.00001,11.25011,22468.96029,0.00000,0.08473,275.57780
225.30001,11.26506,22438.45165,0.00000,0.08473,275.20362
225.60001,11.27989,22400.75469,0.00000,0.08472,274.74127
225.90001,11.29513,22370.10300,0.00000,0.08472,274.36533
226.20001,11.30984,22330.72370,0.00000,0.08471,273.88235
226.50001,11.32509,22293.23238,0.00000,0.08470,273.42253
226.80001,11.33991,22251.32734,0.00000,0.08470,272.90857
227.10001,11.35498,22211.25811,0.00000,0.08469,272.41713
227.40001,11.36999,22170.89534,0.00000,0.08468,271.92209
227.70001,11.38494,22122.96575,0.00000,0.08467,271.33424
228.00001,11.40006,22078.00001,0.00000,0.08466,270.78274
228.30001,11.41495,22025.32887,0.00000,0.08464,270.13674
228.60001,11.43008,21976.03881,0.00000,0.08463,269.53221
228.90001,11.44502,21919.93296,0.00000,0.08462,268.84408
229.20001,11.46015,21860.97950,0.00000,0.08460,268.12102
229.50001,11.47498,21797.48267,0.00000,0.08458,267.34225
229.80001,11.49010,21731.67020,0.00000,0.08457,266.53507
230.10001,11.50505,21661.87167,0.00000,0.08455,265.67900
230.40001,11.51988,21581.40242,0.00000,0.08453,264.69206
230.70001,11.53519,21489.86608,0.00000,0.08451,263.56938
231.00001,11.54989,21375.67997,0.00000,0.08448,262.16891
231.30001,11.56502,21218.15085,0.00000,0.08444,260.23684
231.56601,11.57841,20553.50691,0.00000,0.08424,252.08510
231.58001,11.57919,19537.49210,0.00000,0.08276,239.62386
231.58601,11.57991,16956.54541,0.00000,0.07692,207.96901
231.59201,11.58081,13575.85937,0.00000,0.07032,166.50550
231.59401,11.58110,12403.82269,0.00000,0.06831,152.13068