File: scratch/college-stuff/ME Lab/ME lab Fall 2013/group14/group14.is_tens_RawData/Specimen_RawData_4.csv
Time,Extension,Load,Strain 2,Tensile strain,Tensile stress
(sec),(mm),(N),(mm/mm),(mm/mm),(MPa)
0.00000,0.00000,-0.16153,0.00000,0.00000,-0.00193
0.10000,0.00161,2.06626,0.00000,0.00000,0.02464
0.20000,0.00729,4.32589,0.00000,0.00000,0.05159
0.30000,0.01357,6.79942,0.00000,0.00000,0.08109
0.40000,0.01931,9.68306,0.00000,0.00000,0.11548
0.50000,0.02469,11.49813,0.00000,0.00000,0.13713
0.60000,0.02995,12.74193,0.00000,0.00000,0.15196
0.70000,0.03498,15.12360,0.00000,0.00000,0.18036
0.80000,0.04000,16.71562,0.00000,0.00000,0.19935
0.90000,0.04496,19.29091,0.00000,-0.00001,0.23006
1.00000,0.04998,23.64456,0.00000,-0.00001,0.28199
1.10000,0.05507,31.62941,0.00000,0.00000,0.37721
1.20000,0.05997,36.30859,0.00000,-0.00001,0.43302
1.30000,0.06499,40.29534,0.00000,0.00000,0.48056
1.40000,0.06989,43.00555,0.00000,-0.00001,0.51289
1.50000,0.07504,48.91636,0.00000,-0.00001,0.58338
1.60000,0.07994,55.07322,0.00000,0.00000,0.65681
1.70000,0.08502,59.20409,0.00000,0.00000,0.70607
1.80000,0.08986,61.72935,0.00000,0.00000,0.73619
1.90000,0.09513,63.76007,0.00000,0.00001,0.76041
2.00000,0.09997,64.32662,0.00000,0.00001,0.76716
2.10000,0.10517,64.92040,0.00000,0.00001,0.77424
2.20000,0.10989,65.36843,0.00000,0.00001,0.77959
2.30000,0.11509,65.59515,0.00000,0.00001,0.78229
2.40000,0.11994,66.34620,0.00000,0.00001,0.79125
2.50000,0.12508,66.12128,0.00000,0.00001,0.78857
2.60000,0.12998,66.86614,0.00000,0.00002,0.79745
2.70000,0.13500,67.43787,0.00000,0.00002,0.80427
2.80000,0.13997,67.21574,0.00000,0.00002,0.80162
2.90000,0.14499,67.10129,0.00000,0.00002,0.80025
3.00000,0.15001,68.45560,0.00000,0.00002,0.81641
3.10000,0.15503,68.99506,0.00000,0.00002,0.82284
3.20000,0.16000,69.64512,0.00000,0.00002,0.83059
3.30000,0.16496,69.66137,0.00000,0.00003,0.83079
3.40000,0.17004,68.92989,0.00000,0.00003,0.82206
3.50000,0.17500,70.07941,0.00000,0.00003,0.83577
3.60000,0.18003,70.39630,0.00000,0.00003,0.83955
3.70000,0.18493,71.42235,0.00000,0.00003,0.85179
3.80000,0.19007,72.82426,0.00000,0.00003,0.86851
3.90000,0.19497,73.19076,0.00000,0.00003,0.87288
4.00000,0.20012,72.93806,0.00000,0.00004,0.86986
4.10000,0.20496,73.82079,0.00000,0.00004,0.88039
4.20000,0.21010,78.78808,0.00000,0.00004,0.93963
4.30000,0.21494,80.76581,0.00000,0.00004,0.96322
4.40000,0.22014,82.77999,0.00000,0.00004,0.98724
4.50000,0.22493,82.99596,0.00000,0.00004,0.98981
4.60000,0.23007,84.04909,0.00000,0.00004,1.00237
4.70000,0.23491,84.39542,0.00000,0.00004,1.00650
4.80000,0.24005,84.39088,0.00000,0.00004,1.00645
4.90000,0.24496,84.17800,0.00000,0.00004,1.00391
5.00000,0.25004,85.49186,0.00000,0.00004,1.01958
5.10000,0.25494,87.67546,0.00000,0.00004,1.04562
5.20000,0.26002,91.46865,0.00000,0.00004,1.09086
5.30000,0.26499,94.84450,0.00000,0.00004,1.13112
5.40000,0.27007,96.09857,0.00000,0.00004,1.14608
5.50000,0.27497,97.58908,0.00000,0.00004,1.16385
5.60000,0.27999,99.14958,0.00000,0.00004,1.18246
5.70000,0.28502,100.56898,0.00000,0.00004,1.19939
5.80000,0.28998,103.01134,0.00000,0.00004,1.22852
5.90000,0.29506,105.19043,0.00000,0.00004,1.25451
6.00000,0.29996,106.98789,0.00000,0.00003,1.27594
6.10000,0.30499,110.59421,0.00000,0.00003,1.31895
6.20000,0.30989,115.91365,0.00000,0.00003,1.38239
6.30000,0.31509,121.91103,0.00000,0.00003,1.45392
6.40000,0.31993,127.73154,0.00000,0.00004,1.52333
6.50000,0.32508,139.19477,0.00000,0.00004,1.66005
6.60000,0.32986,153.43453,0.00000,0.00004,1.82987
6.70000,0.33506,170.52528,0.00000,0.00004,2.03369
6.80000,0.33996,187.70787,0.00000,0.00005,2.23861
6.90000,0.34505,207.77879,0.00000,0.00006,2.47798
7.00000,0.34989,227.19014,0.00000,0.00007,2.70948
7.10000,0.35497,248.91754,0.00000,0.00008,2.96861
7.20000,0.35993,274.42155,0.00000,0.00009,3.27277
7.30000,0.36507,300.97354,0.00000,0.00009,3.58943
7.40000,0.36998,328.76602,0.00000,0.00011,3.92088
7.50000,0.37506,355.24655,0.00000,0.00012,4.23669
7.60000,0.37996,379.95810,0.00000,0.00013,4.53140
7.70000,0.38504,403.25769,0.00000,0.00013,4.80927
7.80000,0.39001,427.38467,0.00000,0.00015,5.09701
7.90000,0.39503,453.53440,0.00000,0.00015,5.40888
8.00000,0.39999,480.80073,0.00000,0.00016,5.73406
8.10000,0.40495,506.66817,0.00000,0.00017,6.04255
8.20000,0.41010,534.90144,0.00000,0.00018,6.37927
8.30000,0.41506,562.68992,0.00000,0.00019,6.71067
8.40000,0.42008,591.67137,0.00000,0.00020,7.05631
8.50000,0.42492,620.12002,0.00000,0.00021,7.39559
8.60000,0.43007,650.88547,0.00000,0.00023,7.76250
8.70000,0.43497,681.68757,0.00000,0.00024,8.12985
8.80000,0.44011,714.17228,0.00000,0.00025,8.51726
8.90000,0.44489,744.15612,0.00000,0.00026,8.87485
9.00000,0.45004,775.82621,0.00000,0.00028,9.25255
9.10000,0.45488,806.79497,0.00000,0.00029,9.62188
9.20000,0.46008,840.16332,0.00000,0.00030,10.01984
9.30000,0.46492,872.96143,0.00000,0.00032,10.41099
9.40000,0.47001,908.42051,0.00000,0.00034,10.83388
9.50000,0.47491,942.05923,0.00000,0.00035,11.23505
9.60000,0.48005,976.03910,0.00000,0.00037,11.64030
9.70000,0.48495,1011.24439,0.00000,0.00039,12.06016
9.80000,0.49003,1047.29570,0.00000,0.00040,12.49011
9.90000,0.49494,1086.06704,0.00000,0.00042,12.95250
10.00000,0.49996,1122.74354,0.00000,0.00044,13.38991
10.10000,0.50498,1160.45335,0.00000,0.00046,13.83963
10.20000,0.50994,1194.52495,0.00000,0.00048,14.24597
10.30000,0.51497,1232.00919,0.00000,0.00049,14.69301
10.40000,0.51987,1267.65547,0.00000,0.00052,15.11813
10.50000,0.52495,1306.49209,0.00000,0.00053,15.58130
10.60000,0.52991,1342.97106,0.00000,0.00055,16.01635
10.70000,0.53506,1383.02734,0.00000,0.00057,16.49406
10.80000,0.53990,1419.35349,0.00000,0.00060,16.92729
10.90000,0.54498,1459.50252,0.00000,0.00062,17.40611
11.00000,0.54988,1496.14327,0.00000,0.00064,17.84309
11.10000,0.55509,1536.61892,0.00000,0.00066,18.32581
11.20000,0.55993,1573.62968,0.00000,0.00068,18.76720
11.30000,0.56501,1612.68543,0.00000,0.00070,19.23298
11.40000,0.56985,1649.47025,0.00000,0.00072,19.67168
11.50000,0.57506,1688.74431,0.00000,0.00074,20.14006
11.60000,0.57996,1729.08921,0.00000,0.00076,20.62122
11.70000,0.58504,1768.22450,0.00000,0.00079,21.08795
11.80000,0.58994,1806.11946,0.00000,0.00081,21.53989
11.90000,0.59503,1843.72477,0.00000,0.00083,21.98837
12.00000,0.59993,1881.93489,0.00000,0.00085,22.44407
12.10000,0.60501,1919.50779,0.00000,0.00088,22.89216
12.20000,0.60991,1958.53543,0.00000,0.00090,23.35761
12.30000,0.61499,1997.28273,0.00000,0.00091,23.81971
12.40000,0.61990,2034.53600,0.00000,0.00093,24.26400
12.50000,0.62504,2072.47697,0.00000,0.00096,24.71648
12.60000,0.63000,2110.69882,0.00000,0.00098,25.17232
12.70000,0.63496,2147.43167,0.00000,0.00100,25.61040
12.80000,0.63999,2185.73660,0.00000,0.00102,26.06722
12.90000,0.64501,2220.51572,0.00000,0.00104,26.48200
13.00000,0.65009,2257.88616,0.00000,0.00106,26.92768
13.10000,0.65499,2293.01061,0.00000,0.00108,27.34658
13.20000,0.66002,2332.58139,0.00000,0.00111,27.81850
13.30000,0.66486,2366.68624,0.00000,0.00113,28.22524
13.40000,0.67000,2403.34515,0.00000,0.00115,28.66243
13.50000,0.67484,2435.95410,0.00000,0.00117,29.05133
13.60000,0.68005,2473.44412,0.00000,0.00119,29.49844
13.70000,0.68483,2507.47595,0.00000,0.00121,29.90430
13.80000,0.69003,2544.34515,0.00000,0.00123,30.34401
13.90000,0.69493,2578.64818,0.00000,0.00125,30.75311
14.00000,0.70013,2614.90177,0.00000,0.00128,31.18547
14.10000,0.70492,2648.19320,0.00000,0.00129,31.58251
14.20000,0.71000,2683.26737,0.00000,0.00132,32.00080
14.30000,0.71490,2716.57929,0.00000,0.00133,32.39808
14.40000,0.72004,2748.96771,0.00000,0.00135,32.78435
14.50000,0.72489,2782.02649,0.00000,0.00137,33.17861
14.60000,0.72997,2814.31153,0.00000,0.00139,33.56364
14.70000,0.73487,2848.18672,0.00000,0.00141,33.96764
14.80000,0.73995,2880.00237,0.00000,0.00143,34.34708
14.90000,0.74498,2912.25165,0.00000,0.00145,34.73168
15.00000,0.75006,2943.90414,0.00000,0.00147,35.10917
15.10000,0.75496,2976.73140,0.00000,0.00149,35.50067
15.20000,0.75992,3005.89744,0.00000,0.00150,35.84851
15.30000,0.76501,3038.24153,0.00000,0.00152,36.23425
15.40000,0.76997,3065.75224,0.00000,0.00154,36.56234
15.50000,0.77505,3098.56795,0.00000,0.00156,36.95370
15.60000,0.77989,3127.68295,0.00000,0.00157,37.30093
15.70000,0.78504,3159.86872,0.00000,0.00159,37.68478
15.80000,0.78988,3188.38917,0.00000,0.00161,38.02492
15.90000,0.79508,3219.30647,0.00000,0.00163,38.39364
16.00000,0.79992,3247.91968,0.00000,0.00164,38.73488
16.10000,0.80507,3277.67059,0.00000,0.00166,39.08969
16.20000,0.80991,3304.55564,0.00000,0.00167,39.41032
16.30000,0.81511,3333.87591,0.00000,0.00169,39.76000
16.40000,0.81995,3361.67030,0.00000,0.00171,40.09148
16.50000,0.82504,3389.47438,0.00000,0.00172,40.42307
16.60000,0.82994,3415.86135,0.00000,0.00174,40.73776
16.70000,0.83508,3442.78030,0.00000,0.00176,41.05880
16.80000,0.83998,3468.57384,0.00000,0.00177,41.36641
16.90000,0.84506,3493.23004,0.00000,0.00179,41.66047
17.00000,0.84997,3519.17557,0.00000,0.00180,41.96989
17.10000,0.85499,3543.79378,0.00000,0.00182,42.26349
17.20000,0.85995,3567.45422,0.00000,0.00183,42.54567
17.30000,0.86503,3587.95449,0.00000,0.00184,42.79015
17.40000,0.87000,3608.78855,0.00000,0.00185,43.03862
17.50000,0.87502,3628.18539,0.00000,0.00186,43.26995
17.60000,0.87998,3649.46574,0.00000,0.00188,43.52374
17.70000,0.88500,3669.16135,0.00000,0.00189,43.75863
17.80000,0.89009,3691.35775,0.00000,0.00190,44.02335
17.90000,0.89493,3710.00282,0.00000,0.00191,44.24571
18.00000,0.90001,3733.40733,0.00000,0.00192,44.52483
18.10000,0.90485,3752.46108,0.00000,0.00194,44.75207
18.20000,0.91006,3776.07346,0.00000,0.00195,45.03367
18.30000,0.91490,3796.08423,0.00000,0.00196,45.27232
18.40000,0.92010,3819.49246,0.00000,0.00197,45.55149
18.50000,0.92488,3840.20247,0.00000,0.00199,45.79848
18.60000,0.93009,3862.52292,0.00000,0.00200,46.06467
18.70000,0.93493,3882.09857,0.00000,0.00201,46.29813
18.80000,0.94013,3905.13688,0.00000,0.00203,46.57289
18.90000,0.94491,3926.16168,0.00000,0.00204,46.82363
19.00000,0.95000,3947.55825,0.00000,0.00205,47.07881
19.10000,0.95484,3970.63978,0.00000,0.00207,47.35408
19.20000,0.95998,3992.36083,0.00000,0.00208,47.61313
19.30000,0.96488,4014.75057,0.00000,0.00209,47.88015
19.40000,0.96996,4036.76257,0.00000,0.00210,48.14267
19.50000,0.97493,4059.69396,0.00000,0.00212,48.41615
19.60000,0.98001,4080.34995,0.00000,0.00213,48.66249
19.70000,0.98497,4102.31389,0.00000,0.00214,48.92444
19.80000,0.98999,4122.64951,0.00000,0.00216,49.16696
19.90000,0.99502,4147.06804,0.00000,0.00217,49.45818
20.00000,0.99992,4167.31164,0.00000,0.00218,49.69960
20.10000,1.00500,4190.91098,0.00000,0.00220,49.98105
20.20000,1.00996,4211.69102,0.00000,0.00221,50.22887
20.30000,1.01505,4234.33371,0.00000,0.00223,50.49891
20.40000,1.01995,4255.83236,0.00000,0.00224,50.75531
20.50000,1.02509,4278.31635,0.00000,0.00225,51.02345
20.60000,1.02993,4298.76000,0.00000,0.00226,51.26726
20.70000,1.03514,4321.77037,0.00000,0.00228,51.54169
20.80000,1.03992,4342.62529,0.00000,0.00229,51.79040
20.90000,1.04506,4365.74109,0.00000,0.00231,52.06608
21.00000,1.04990,4386.90521,0.00000,0.00232,52.31849
21.10000,1.05505,4411.10618,0.00000,0.00233,52.60711
21.20000,1.05995,4432.35263,0.00000,0.00235,52.86050
21.30000,1.06503,4455.82159,0.00000,0.00236,53.14039
21.40000,1.06987,4477.81309,0.00000,0.00238,53.40266
21.50000,1.07502,4499.46448,0.00000,0.00239,53.66088
21.60000,1.07998,4521.83448,0.00000,0.00240,53.92766
21.70000,1.08512,4544.85901,0.00000,0.00242,54.20225
21.80000,1.08996,4566.36958,0.00000,0.00243,54.45879
21.90000,1.09498,4587.82315,0.00000,0.00244,54.71465
22.00000,1.09995,4610.13652,0.00000,0.00246,54.98076
22.10000,1.10503,4631.51745,0.00000,0.00247,55.23575
22.20000,1.10999,4653.28693,0.00000,0.00249,55.49537
22.30000,1.11495,4673.03209,0.00000,0.00250,55.73085
22.40000,1.11998,4695.14914,0.00000,0.00251,55.99462
22.50000,1.12494,4713.53941,0.00000,0.00252,56.21395
22.60000,1.13008,4736.49390,0.00000,0.00254,56.48770
22.70000,1.13498,4753.89808,0.00000,0.00255,56.69527
22.80000,1.14007,4775.64447,0.00000,0.00256,56.95461
22.90000,1.14485,4793.17941,0.00000,0.00257,57.16374
23.00000,1.15011,4815.91709,0.00000,0.00258,57.43491
23.10000,1.15489,4833.45054,0.00000,0.00260,57.64401
23.20000,1.16004,4855.17532,0.00000,0.00261,57.90310
23.30000,1.16482,4873.55702,0.00000,0.00262,58.12233
23.40000,1.17002,4895.09925,0.00000,0.00263,58.37924
23.50000,1.17486,4913.67728,0.00000,0.00264,58.60080
23.60000,1.18007,4933.55282,0.00000,0.00265,58.83784
23.70000,1.18491,4953.37062,0.00000,0.00267,59.07419
23.80000,1.18999,4974.99108,0.00000,0.00268,59.33203
23.90000,1.19495,4996.07474,0.00000,0.00269,59.58348
24.00000,1.20003,5017.19713,0.00000,0.00270,59.83539
24.10000,1.20500,5039.03218,0.00000,0.00272,60.09579
24.20000,1.20996,5058.93268,0.00000,0.00273,60.33313
24.30000,1.21498,5082.64713,0.00000,0.00275,60.61595
24.40000,1.22000,5102.44370,0.00000,0.00276,60.85204
24.50000,1.22503,5124.18859,0.00000,0.00277,61.11137
24.60000,1.22999,5144.05817,0.00000,0.00278,61.34834
24.70000,1.23507,5166.38979,0.00000,0.00279,61.61467
24.80000,1.23997,5185.62235,0.00000,0.00281,61.84404
24.90000,1.24512,5208.85848,0.00000,0.00282,62.12115
25.00000,1.25002,5228.77127,0.00000,0.00283,62.35863
25.10000,1.25510,5252.92605,0.00000,0.00284,62.64670
25.20000,1.25994,5271.53537,0.00000,0.00286,62.86864
25.30000,1.26503,5293.50415,0.00000,0.00287,63.13064
25.40000,1.26999,5313.82896,0.00000,0.00288,63.37303
25.50000,1.27513,5336.16617,0.00000,0.00290,63.63943
25.60000,1.27991,5357.05537,0.00000,0.00291,63.88856
25.70000,1.28506,5380.92516,0.00000,0.00292,64.17323
25.80000,1.28990,5400.55744,0.00000,0.00293,64.40736
25.90000,1.29510,5424.34342,0.00000,0.00295,64.69104
26.00000,1.29994,5445.34698,0.00000,0.00296,64.94153
26.10000,1.30503,5468.72877,0.00000,0.00297,65.22038
26.20000,1.30993,5489.76399,0.00000,0.00299,65.47125
26.30000,1.31507,5511.05477,0.00000,0.00300,65.72516
26.40000,1.31997,5531.72193,0.00000,0.00301,65.97164
26.50000,1.32499,5552.96540,0.00000,0.00303,66.22499
26.60000,1.32990,5576.65825,0.00000,0.00304,66.50755
26.70000,1.33498,5597.08774,0.00000,0.00305,66.75120
26.80000,1.34000,5620.41067,0.00000,0.00307,67.02935
26.90000,1.34496,5640.57268,0.00000,0.00308,67.26980
27.00000,1.34999,5665.53287,0.00000,0.00310,67.56748
27.10000,1.35501,5687.52997,0.00000,0.00311,67.82981
27.20000,1.36003,5710.26504,0.00000,0.00312,68.10095
27.30000,1.36499,5729.06360,0.00000,0.00313,68.32515
27.40000,1.37008,5752.02405,0.00000,0.00315,68.59898
27.50000,1.37492,5772.08214,0.00000,0.00316,68.83819
27.60000,1.38006,5795.46280,0.00000,0.00317,69.11703
27.70000,1.38490,5816.20596,0.00000,0.00319,69.36441
27.80000,1.39005,5840.42743,0.00000,0.00320,69.65328
27.90000,1.39489,5861.05958,0.00000,0.00321,69.89934
28.00000,1.40003,5884.47005,0.00000,0.00323,70.17853
28.10000,1.40487,5905.87035,0.00000,0.00324,70.43375
28.20000,1.41008,5928.89786,0.00000,0.00326,70.70838
28.30000,1.41492,5949.15040,0.00000,0.00327,70.94992
28.40000,1.42006,5973.19007,0.00000,0.00329,71.23661
28.50000,1.42490,5993.76969,0.00000,0.00329,71.48205
28.60000,1.42999,6016.67278,0.00000,0.00331,71.75519
28.70000,1.43501,6039.76883,0.00000,0.00333,72.03064
28.80000,1.44003,6060.70310,0.00000,0.00334,72.28030
28.90000,1.44499,6083.33461,0.00000,0.00335,72.55020
29.00000,1.45001,6104.79936,0.00000,0.00337,72.80619
29.10000,1.45498,6126.03873,0.00000,0.00338,73.05950
29.20000,1.46006,6147.14809,0.00000,0.00340,73.31125
29.30000,1.46508,6169.31580,0.00000,0.00341,73.57562
29.40000,1.47004,6191.18363,0.00000,0.00342,73.83642
29.50000,1.47501,6215.25384,0.00000,0.00344,74.12348
29.60000,1.47997,6235.92585,0.00000,0.00345,74.37002
29.70000,1.48505,6261.19003,0.00000,0.00347,74.67132
29.80000,1.49001,6282.68719,0.00000,0.00348,74.92769
29.90000,1.49504,6306.05444,0.00000,0.00350,75.20637
30.00000,1.49988,6327.39589,0.00000,0.00351,75.46089
30.10000,1.50508,6350.33697,0.00000,0.00353,75.73449
30.20000,1.50992,6371.01680,0.00000,0.00354,75.98112
30.30000,1.51513,6394.07113,0.00000,0.00355,76.25607
30.40000,1.51997,6417.16197,0.00000,0.00357,76.53145
30.50000,1.52511,6440.18874,0.00000,0.00358,76.80607
30.60000,1.52995,6462.01149,0.00000,0.00359,77.06633
30.70000,1.53510,6486.66769,0.00000,0.00361,77.36038
30.80000,1.53994,6506.60247,0.00000,0.00362,77.59812
30.90000,1.54508,6530.62761,0.00000,0.00364,77.88465
31.00000,1.54986,6551.61291,0.00000,0.00365,78.13492
31.10000,1.55506,6575.22082,0.00000,0.00367,78.41647
31.20000,1.55997,6597.55766,0.00000,0.00368,78.68286
31.30000,1.56499,6619.17105,0.00000,0.00370,78.94062
31.40000,1.56995,6643.34595,0.00000,0.00371,79.22893
31.50000,1.57503,6665.49429,0.00000,0.00372,79.49307
31.60000,1.58000,6690.38519,0.00000,0.00374,79.78992
31.70000,1.58502,6711.41967,0.00000,0.00375,80.04078
31.80000,1.59004,6735.80989,0.00000,0.00377,80.33166
31.90000,1.59500,6756.88535,0.00000,0.00378,80.58301
32.00000,1.60003,6781.33741,0.00000,0.00380,80.87463
32.10000,1.60493,6802.05077,0.00000,0.00381,81.12165
32.20000,1.61007,6826.11540,0.00000,0.00383,81.40865
32.30000,1.61485,6846.73563,0.00000,0.00384,81.65457
32.40000,1.62000,6871.44846,0.00000,0.00386,81.94930
32.50000,1.62484,6893.07302,0.00000,0.00387,82.20719
32.60000,1.63010,6916.90594,0.00000,0.00389,82.49142
32.70000,1.63494,6937.81599,0.00000,0.00390,82.74080
32.80000,1.64003,6962.13543,0.00000,0.00392,83.03083
32.90000,1.64487,6982.77280,0.00000,0.00393,83.27696
33.00000,1.65007,7004.97553,0.00000,0.00394,83.54175
33.10000,1.65497,7029.05878,0.00000,0.00396,83.82897
33.20000,1.66000,7051.52228,0.00000,0.00397,84.09687
33.30000,1.66490,7076.37966,0.00000,0.00399,84.39332
33.40000,1.66998,7100.02631,0.00000,0.00400,84.67533
33.50000,1.67494,7123.03594,0.00000,0.00402,84.94974
33.60000,1.68003,7146.51123,0.00000,0.00403,85.22971
33.70000,1.68499,7170.36128,0.00000,0.00405,85.51415
33.80000,1.69001,7192.03502,0.00000,0.00407,85.77263
33.90000,1.69497,7216.17192,0.00000,0.00408,86.06049
34.00000,1.70005,7237.58489,0.00000,0.00410,86.31586
34.10000,1.70502,7261.36789,0.00000,0.00411,86.59950
34.20000,1.71004,7284.59507,0.00000,0.00412,86.87651
34.30000,1.71506,7309.93226,0.00000,0.00415,87.17868
34.40000,1.71996,7330.52939,0.00000,0.00415,87.42432
34.50000,1.72505,7354.50238,0.00000,0.00418,87.71023
34.60000,1.72995,7375.99805,0.00000,0.00419,87.96658
34.70000,1.73509,7401.01486,0.00000,0.00420,88.26494
34.80000,1.73993,7422.27435,0.00000,0.00422,88.51848
34.90000,1.74508,7446.91864,0.00000,0.00423,88.81239
35.00000,1.74992,7468.23624,0.00000,0.00425,89.06662
35.10000,1.75506,7494.19853,0.00000,0.00427,89.37625
35.20000,1.75984,7516.69854,0.00000,0.00428,89.64459
35.30000,1.76505,7542.26744,0.00000,0.00430,89.94952
35.40000,1.76983,7563.24902,0.00000,0.00431,90.19975
35.50000,1.77503,7587.69810,0.00000,0.00433,90.49133
35.60000,1.77987,7611.21362,0.00000,0.00434,90.77178
35.70000,1.78502,7635.44440,0.00000,0.00436,91.06076
35.80000,1.78992,7657.94069,0.00000,0.00437,91.32905
35.90000,1.79506,7681.64247,0.00000,0.00439,91.61172
36.00000,1.79996,7704.47180,0.00000,0.00440,91.88398
36.10000,1.80504,7728.88139,0.00000,0.00442,92.17509
36.20000,1.80995,7751.87984,0.00000,0.00444,92.44937
36.30000,1.81503,7774.35228,0.00000,0.00445,92.71738
36.40000,1.81999,7798.29398,0.00000,0.00447,93.00291
36.50000,1.82501,7819.13921,0.00000,0.00448,93.25151
36.60000,1.82998,7844.86160,0.00000,0.00450,93.55828
36.70000,1.83494,7865.40210,0.00000,0.00452,93.80325
36.80000,1.84002,7891.34800,0.00000,0.00453,94.11268
36.90000,1.84492,7912.94947,0.00000,0.00454,94.37030
37.00000,1.85007,7938.37160,0.00000,0.00456,94.67348
37.10000,1.85491,7960.19211,0.00000,0.00457,94.93372
37.20000,1.86005,7985.57848,0.00000,0.00460,95.23648
37.30000,1.86489,8007.02795,0.00000,0.00461,95.49228
37.40000,1.87010,8030.54124,0.00000,0.00463,95.77270
37.50000,1.87494,8052.81699,0.00000,0.00464,96.03837
37.60000,1.88002,8077.79804,0.00000,0.00466,96.33629
37.70000,1.88492,8100.26228,0.00000,0.00467,96.60420
37.80000,1.89007,8125.73656,0.00000,0.00468,96.90801
37.90000,1.89497,8147.26204,0.00000,0.00471,97.16472
38.00000,1.89999,8171.49058,0.00000,0.00471,97.45367
38.10000,1.90495,8196.97231,0.00000,0.00474,97.75757
38.20000,1.91004,8219.00591,0.00000,0.00475,98.02034
38.30000,1.91500,8241.91943,0.00000,0.00476,98.29361
38.40000,1.92002,8264.96184,0.00000,0.00478,98.56842
38.50000,1.92498,8290.40185,0.00000,0.00479,98.87182
38.60000,1.93006,8314.30852,0.00000,0.00482,99.15693
38.70000,1.93497,8337.68249,0.00000,0.00483,99.43569
38.80000,1.94005,8361.02888,0.00000,0.00484,99.71412
38.90000,1.94495,8385.18664,0.00000,0.00487,100.00223
39.00000,1.94997,8408.60233,0.00000,0.00487,100.28148
39.10000,1.95506,8434.15186,0.00000,0.00490,100.58619
39.20000,1.96002,8456.44996,0.00000,0.00491,100.85212
39.30000,1.96510,8481.91902,0.00000,0.00493,101.15586
39.40000,1.96994,8502.59736,0.00000,0.00494,101.40247
39.50000,1.97503,8529.23542,0.00000,0.00496,101.72016
39.60000,1.97993,8551.88221,0.00000,0.00498,101.99025
39.70000,1.98507,8576.87220,0.00000,0.00499,102.28828
39.80000,1.98991,8598.07804,0.00000,0.00501,102.54118
39.90000,1.99512,8621.22253,0.00000,0.00503,102.81720
40.00000,1.99990,8643.31648,0.00000,0.00503,103.08070
40.10000,2.00504,8669.25567,0.00000,0.00506,103.39005
40.20000,2.00994,8691.48001,0.00000,0.00507,103.65510
40.30000,2.01509,8717.14428,0.00000,0.00509,103.96117
40.40000,2.01993,8741.53227,0.00000,0.00511,104.25202
40.50000,2.02501,8765.69599,0.00000,0.00512,104.54020
40.60000,2.02991,8789.27857,0.00000,0.00515,104.82145
40.70000,2.03505,8812.25616,0.00000,0.00516,105.09548
40.80000,2.03996,8836.22766,0.00000,0.00518,105.38137
40.90000,2.04498,8858.11299,0.00000,0.00519,105.64237
41.00000,2.04994,8882.69916,0.00000,0.00520,105.93559
41.10000,2.05496,8905.92486,0.00000,0.00523,106.21258
41.20000,2.05999,8930.31135,0.00000,0.00524,106.50342
41.30000,2.06495,8953.48936,0.00000,0.00526,106.77984
41.40000,2.06997,8978.12843,0.00000,0.00528,107.07368
41.50000,2.07493,9000.49731,0.00000,0.00529,107.34046
41.60000,2.08008,9026.60042,0.00000,0.00531,107.65176
41.70000,2.08498,9047.54996,0.00000,0.00532,107.90161
41.80000,2.09006,9072.24417,0.00000,0.00535,108.19611
41.90000,2.09490,9095.53096,0.00000,0.00536,108.47383
42.00000,2.10005,9120.10446,0.00000,0.00538,108.76690
42.10000,2.10489,9143.54846,0.00000,0.00540,109.04649
42.20000,2.11003,9167.87609,0.00000,0.00541,109.33663
42.30000,2.11487,9190.64507,0.00000,0.00543,109.60817
42.40000,2.12002,9216.05378,0.00000,0.00545,109.91120
42.50000,2.12492,9238.53815,0.00000,0.00547,110.17935
42.60000,2.13012,9263.04981,0.00000,0.00548,110.47167
42.70000,2.13496,9286.44016,0.00000,0.00550,110.75063
42.80000,2.14005,9311.57470,0.00000,0.00552,111.05038
42.90000,2.14495,9336.00664,0.00000,0.00553,111.34176
43.00000,2.15009,9360.97279,0.00000,0.00555,111.63951
43.10000,2.15499,9384.43840,0.00000,0.00557,111.91936
43.20000,2.16007,9408.03960,0.00000,0.00558,112.20083
43.30000,2.16492,9431.82334,0.00000,0.00560,112.48448
43.40000,2.17000,9455.11907,0.00000,0.00561,112.76230
43.50000,2.17502,9479.51153,0.00000,0.00564,113.05321
43.60000,2.18010,9501.79696,0.00000,0.00565,113.31899
43.70000,2.18507,9526.62379,0.00000,0.00567,113.61507
43.80000,2.19003,9550.44925,0.00000,0.00568,113.89922
43.90000,2.19499,9577.52615,0.00000,0.00570,114.22214
44.00000,2.19995,9599.70132,0.00000,0.00572,114.48660
44.10000,2.20510,9626.35279,0.00000,0.00573,114.80445
44.20000,2.20988,9647.55714,0.00000,0.00575,115.05733
44.30000,2.21502,9673.60884,0.00000,0.00577,115.36802
44.40000,2.21980,9694.85566,0.00000,0.00579,115.62142
44.50000,2.22507,9721.35440,0.00000,0.00581,115.93744
44.60000,2.22997,9742.84634,0.00000,0.00582,116.19375
44.70000,2.23511,9769.31751,0.00000,0.00584,116.50945
44.80000,2.23989,9792.41803,0.00000,0.00585,116.78495
44.90000,2.24504,9817.59354,0.00000,0.00587,117.08519
45.00000,2.24988,9839.62119,0.00000,0.00589,117.34790
45.10000,2.25508,9864.21183,0.00000,0.00591,117.64117
45.20000,2.25986,9887.87264,0.00000,0.00592,117.92335
45.30000,2.26495,9912.03710,0.00000,0.00594,118.21153
45.40000,2.26991,9937.03455,0.00000,0.00596,118.50965
45.50000,2.27499,9959.64035,0.00000,0.00597,118.77925
45.60000,2.27995,9985.46779,0.00000,0.00599,119.08727
45.70000,2.28498,10008.98257,0.00000,0.00601,119.36771
45.80000,2.28994,10033.88837,0.00000,0.00602,119.66474
45.90000,2.29502,10056.49567,0.00000,0.00604,119.93435
46.00000,2.30004,10081.02968,0.00000,0.00606,120.22695
46.10000,2.30494,10102.52759,0.00000,0.00607,120.48333
46.20000,2.31003,10129.88761,0.00000,0.00610,120.80963
46.30000,2.31493,10152.48522,0.00000,0.00611,121.07913
46.40000,2.32007,10177.92448,0.00000,0.00613,121.38252
46.50000,2.32497,10201.28652,0.00000,0.00614,121.66114
46.60000,2.33012,10227.81804,0.00000,0.00617,121.97756
46.70000,2.33490,10249.98501,0.00000,0.00618,122.24192
46.80000,2.34010,10274.85728,0.00000,0.00620,122.53855
46.90000,2.34494,10296.77466,0.00000,0.00622,122.79994
47.00000,2.35015,10322.20125,0.00000,0.00623,123.10318
47.10000,2.35493,10345.45526,0.00000,0.00625,123.38050
47.20000,2.36007,10370.76190,0.00000,0.00627,123.68231
47.30000,2.36491,10394.18876,0.00000,0.00629,123.96170
47.40000,2.37006,10419.80907,0.00000,0.00630,124.26725
47.50000,2.37496,10443.88935,0.00000,0.00632,124.55443
47.60000,2.37998,10468.90989,0.00000,0.00634,124.85283
47.70000,2.38488,10492.21978,0.00000,0.00636,125.13083
47.80000,2.39003,10517.81923,0.00000,0.00638,125.43613
47.90000,2.39499,10542.97686,0.00000,0.00640,125.73616
48.00000,2.40007,10565.92986,0.00000,0.00642,126.00990
48.10000,2.40497,10591.75357,0.00000,0.00643,126.31787
48.20000,2.41005,10615.47399,0.00000,0.00645,126.60076
48.30000,2.41496,10639.62281,0.00000,0.00647,126.88876
48.40000,2.42004,10662.77772,0.00000,0.00649,127.16491
48.50000,2.42500,10688.18495,0.00000,0.00651,127.46792
48.60000,2.42996,10711.99477,0.00000,0.00652,127.75188
48.70000,2.43505,10736.36785,0.00000,0.00654,128.04255
48.80000,2.43995,10758.39624,0.00000,0.00656,128.30526
48.90000,2.44503,10784.65357,0.00000,0.00658,128.61841
49.00000,2.44987,10808.62507,0.00000,0.00660,128.90429
49.10000,2.45502,10835.21098,0.00000,0.00661,129.22136
49.20000,2.45992,10857.98070,0.00000,0.00663,129.49291
49.30000,2.46512,10882.41264,0.00000,0.00666,129.78429
49.40000,2.46990,10905.60332,0.00000,0.00667,130.06086
49.50000,2.47505,10931.50824,0.00000,0.00669,130.36981
49.60000,2.47983,10955.00216,0.00000,0.00671,130.65000
49.70000,2.48509,10981.03225,0.00000,0.00673,130.96043
49.80000,2.48993,11004.36226,0.00000,0.00675,131.23867
49.90000,2.49502,11028.51480,0.00000,0.00676,131.52671
50.00000,2.49986,11053.00635,0.00000,0.00678,131.81880
50.10000,2.50500,11077.68565,0.00000,0.00680,132.11313
50.20000,2.51002,11101.81808,0.00000,0.00682,132.40093
50.30000,2.51505,11123.52610,0.00000,0.00683,132.65982
50.40000,2.51995,11148.82380,0.00000,0.00685,132.96152
50.50000,2.52497,11172.49057,0.00000,0.00687,133.24378
50.60000,2.53005,11198.11386,0.00000,0.00689,133.54936
50.70000,2.53501,11220.61759,0.00000,0.00691,133.81774
50.80000,2.54004,11246.70953,0.00000,0.00693,134.12892
50.90000,2.54494,11268.96888,0.00000,0.00694,134.39438
51.00000,2.55002,11296.48089,0.00000,0.00696,134.72249
51.10000,2.55498,11317.84767,0.00000,0.00698,134.97731
51.20000,2.56007,11344.35460,0.00000,0.00700,135.29344
51.30000,2.56491,11366.01567,0.00000,0.00701,135.55177
51.40000,2.57005,11392.61648,0.00000,0.00703,135.86901
51.50000,2.57489,11416.09773,0.00000,0.00705,136.14905
51.60000,2.58004,11442.13751,0.00000,0.00707,136.45960
51.70000,2.58494,11466.08219,0.00000,0.00709,136.74517
51.80000,2.59008,11492.21137,0.00000,0.00711,137.05678
51.90000,2.59492,11514.07361,0.00000,0.00713,137.31751
52.00000,2.60007,11539.64773,0.00000,0.00714,137.62251
52.10000,2.60491,11563.17070,0.00000,0.00716,137.90305
52.20000,2.61011,11588.52428,0.00000,0.00718,138.20542
52.30000,2.61495,11610.98182,0.00000,0.00720,138.47325
52.40000,2.62004,11637.47534,0.00000,0.00722,138.78921
52.50000,2.62494,11661.33508,0.00000,0.00724,139.07376
52.60000,2.63002,11685.44516,0.00000,0.00725,139.36130
52.70000,2.63492,11709.62900,0.00000,0.00728,139.64972
52.80000,2.64000,11733.53717,0.00000,0.00729,139.93485
52.90000,2.64491,11758.42807,0.00000,0.00731,140.23170
53.00000,2.64999,11781.41162,0.00000,0.00733,140.50580
53.10000,2.65501,11807.76581,0.00000,0.00735,140.82011
53.20000,2.65997,11832.22085,0.00000,0.00737,141.11176
53.30000,2.66500,11858.83209,0.00000,0.00738,141.42912
53.40000,2.66996,11882.07716,0.00000,0.00740,141.70635
53.50000,2.67504,11908.29277,0.00000,0.00742,142.01900
53.60000,2.68000,11930.13638,0.00000,0.00744,142.27950
53.70000,2.68509,11955.62780,0.00000,0.00746,142.58352
53.80000,2.68987,11977.71803,0.00000,0.00748,142.84697
53.90000,2.69507,12003.38826,0.00000,0.00750,143.15311
54.00000,2.69985,12026.21534,0.00000,0.00752,143.42535
54.10000,2.70506,12052.63287,0.00000,0.00753,143.74040
54.20000,2.70990,12076.04259,0.00000,0.00755,144.01959
54.30000,2.71498,12101.70537,0.00000,0.00757,144.32565
54.40000,2.71988,12125.99203,0.00000,0.00759,144.61529
54.50000,2.72509,12149.49340,0.00000,0.00761,144.89557
54.60000,2.72999,12173.61540,0.00000,0.00763,145.18325
54.70000,2.73501,12197.22629,0.00000,0.00764,145.46483
54.80000,2.73997,12222.19393,0.00000,0.00767,145.76260
54.90000,2.74500,12246.11700,0.00000,0.00768,146.04791
55.00000,2.75002,12270.62866,0.00000,0.00771,146.34023
55.10000,2.75504,12294.69478,0.00000,0.00772,146.62725
55.20000,2.76000,12319.22731,0.00000,0.00774,146.91982
55.30000,2.76502,12342.54614,0.00000,0.00776,147.19793
55.40000,2.77005,12367.56966,0.00000,0.00778,147.49636
55.50000,2.77507,12391.45547,0.00000,0.00780,147.78122
55.60000,2.78009,12416.93795,0.00000,0.00781,148.08513
55.70000,2.78505,12440.21878,0.00000,0.00783,148.36278
55.80000,2.79008,12467.26140,0.00000,0.00786,148.68529
55.90000,2.79498,12488.96047,0.00000,0.00787,148.94407
56.00000,2.80006,12514.39899,0.00000,0.00789,149.24745
56.10000,2.80496,12536.25304,0.00000,0.00791,149.50809
56.20000,2.81005,12562.75177,0.00000,0.00793,149.82411
56.30000,2.81495,12584.65499,0.00000,0.00795,150.08533
56.40000,2.82009,12611.42492,0.00000,0.00797,150.40459
56.50000,2.82493,12634.13280,0.00000,0.00798,150.67541
56.60000,2.83014,12661.52859,0.00000,0.00800,151.00213
56.70000,2.83492,12686.41800,0.00000,0.00803,151.29896
56.80000,2.84006,12711.52347,0.00000,0.00805,151.59837
56.90000,2.84490,12734.89147,0.00000,0.00806,151.87706
57.00000,2.85011,12760.16384,0.00000,0.00808,152.17846
57.10000,2.85489,12782.28760,0.00000,0.00810,152.44231
57.20000,2.86003,12808.00253,0.00000,0.00812,152.74899
57.30000,2.86493,12830.54203,0.00000,0.00814,153.01779
57.40000,2.87002,12855.82632,0.00000,0.00816,153.31934
57.50000,2.87498,12880.15693,0.00000,0.00818,153.60950
57.60000,2.88000,12903.34165,0.00000,0.00819,153.88601
57.70000,2.88490,12929.25924,0.00000,0.00822,154.19510
57.80000,2.88999,12952.95954,0.00000,0.00824,154.47775
57.90000,2.89501,12978.47480,0.00000,0.00825,154.78205
58.00000,2.90003,13000.27221,0.00000,0.00827,155.04201
58.10000,2.90499,13025.80833,0.00000,0.00829,155.34655
58.20000,2.90995,13048.59072,0.00000,0.00831,155.61826
58.30000,2.91504,13076.47526,0.00000,0.00833,155.95081
58.40000,2.91988,13096.96287,0.00000,0.00835,156.19514
58.50000,2.92502,13122.16371,0.00000,0.00837,156.49569
58.60000,2.92986,13146.58523,0.00000,0.00839,156.78694
58.70000,2.93501,13170.46434,0.00000,0.00841,157.07173
58.80000,2.93985,13192.94572,0.00000,0.00843,157.33984
58.90000,2.94511,13219.12706,0.00000,0.00845,157.65208
59.00000,2.94995,13242.33562,0.00000,0.00847,157.92887
59.10000,2.95504,13268.73153,0.00000,0.00849,158.24367
59.20000,2.95988,13292.76711,0.00000,0.00851,158.53032
59.30000,2.96502,13317.28250,0.00000,0.00853,158.82269
59.40000,2.96998,13341.02452,0.00000,0.00855,159.10584
59.50000,2.97501,13364.92747,0.00000,0.00856,159.39091
59.60000,2.97991,13388.98540,0.00000,0.00858,159.67782
59.70000,2.98499,13412.88984,0.00000,0.00860,159.96291
59.80000,2.98995,13437.28304,0.00000,0.00862,160.25382
59.90000,2.99504,13460.92820,0.00000,0.00864,160.53582
60.00000,3.00000,13487.90675,0.00000,0.00866,160.85756
60.10000,3.00502,13512.57861,0.00000,0.00868,161.15180
60.20000,3.01004,13539.42305,0.00000,0.00870,161.47195
60.30000,3.01500,13560.80770,0.00000,0.00872,161.72699
60.40000,3.02003,13586.25591,0.00000,0.00874,162.03048
60.50000,3.02499,13609.76398,0.00000,0.00876,162.31084
60.60000,3.03001,13635.19877,0.00000,0.00878,162.61418
60.70000,3.03497,13657.27186,0.00000,0.00879,162.87742
60.80000,3.04012,13684.15803,0.00000,0.00882,163.19807
60.90000,3.04496,13705.76620,0.00000,0.00883,163.45577
61.00000,3.05004,13732.47951,0.00000,0.00886,163.77435
61.10000,3.05494,13755.50181,0.00000,0.00887,164.04892
61.20000,3.06009,13779.93524,0.00000,0.00889,164.34031
61.30000,3.06493,13802.84131,0.00000,0.00891,164.61349
61.40000,3.07007,13828.07195,0.00000,0.00893,164.91439
61.50000,3.07491,13851.73649,0.00000,0.00895,165.19662
61.60000,3.08006,13877.75838,0.00000,0.00897,165.50696
61.70000,3.08490,13901.90274,0.00000,0.00899,165.79490
61.80000,3.09004,13925.67456,0.00000,0.00900,166.07841
61.90000,3.09494,13950.80686,0.00000,0.00902,166.37814
62.00000,3.10003,13975.43997,0.00000,0.00904,166.67191
62.10000,3.10493,13999.74674,0.00000,0.00906,166.96180
62.20000,3.11007,14023.49621,0.00000,0.00908,167.24504
62.30000,3.11497,14047.44983,0.00000,0.00910,167.53071
62.40000,3.11999,14070.74332,0.00000,0.00912,167.80851
62.50000,3.12496,14097.38958,0.00000,0.00914,168.12629
62.60000,3.13004,14122.34455,0.00000,0.00916,168.42391
62.70000,3.13506,14146.99256,0.00000,0.00918,168.71786
62.80000,3.13996,14168.36083,0.00000,0.00919,168.97270
62.90000,3.14499,14194.07725,0.00000,0.00921,169.27939
63.00000,3.14989,14216.13842,0.00000,0.00924,169.54250
63.10000,3.15503,14241.06359,0.00000,0.00925,169.83976
63.20000,3.15993,14263.80128,0.00000,0.00927,170.11093
63.30000,3.16508,14289.60264,0.00000,0.00929,170.41864
63.40000,3.16986,14313.21502,0.00000,0.00931,170.70024
63.50000,3.17506,14338.85694,0.00000,0.00933,171.00605
63.60000,3.17990,14362.50955,0.00000,0.00935,171.28813
63.70000,3.18511,14388.46290,0.00000,0.00937,171.59765
63.80000,3.18989,14411.97097,0.00000,0.00939,171.87801
63.90000,3.19503,14435.99612,0.00000,0.00941,172.16453
64.00000,3.19993,14460.00934,0.00000,0.00943,172.45092
64.10000,3.20508,14485.44860,0.00000,0.00945,172.75431
64.20000,3.20998,14510.19198,0.00000,0.00947,173.04940
64.30000,3.21500,14534.71333,0.00000,0.00949,173.34184
64.40000,3.21996,14560.25243,0.00000,0.00952,173.64642
64.50000,3.22505,14583.72474,0.00000,0.00953,173.92635
64.60000,3.23001,14608.43235,0.00000,0.00956,174.22102
64.70000,3.23509,14631.71244,0.00000,0.00958,174.49866
64.80000,3.23999,14655.68095,0.00000,0.00960,174.78451
64.90000,3.24501,14679.60775,0.00000,0.00961,175.06986
65.00000,3.24998,14704.36752,0.00000,0.00963,175.36515
65.10000,3.25506,14729.01553,0.00000,0.00965,175.65910
65.20000,3.26002,14754.24170,0.00000,0.00968,175.95995
65.30000,3.26498,14777.16416,0.00000,0.00969,176.23332
65.40000,3.27001,14803.02513,0.00000,0.00972,176.54174
65.50000,3.27497,14826.33054,0.00000,0.00973,176.81968
65.60000,3.28011,14852.27495,0.00000,0.00976,177.12910
65.70000,3.28495,14874.34804,0.00000,0.00977,177.39234
65.80000,3.29004,14900.91980,0.00000,0.00979,177.70924
65.90000,3.29488,14924.07471,0.00000,0.00982,177.98539
66.00000,3.30008,14950.12641,0.00000,0.00984,178.29608
66.10000,3.30492,14972.57501,0.00000,0.00985,178.56380
66.20000,3.31007,14997.93231,0.00000,0.00987,178.86622
66.30000,3.31485,15020.05011,0.00000,0.00989,179.13000
66.40000,3.32005,15043.99925,0.00000,0.00991,179.41561
66.50000,3.32489,15068.53551,0.00000,0.00993,179.70824
66.60000,3.33010,15093.43684,0.00000,0.00995,180.00521
66.70000,3.33494,15117.99097,0.00000,0.00997,180.29804
66.80000,3.34002,15142.14426,0.00000,0.00999,180.58610
66.90000,3.34492,15167.28401,0.00000,0.01001,180.88592
67.00000,3.35007,15190.53429,0.00000,0.01003,181.16320
67.10000,3.35497,15215.35814,0.00000,0.01005,181.45925
67.20000,3.35993,15237.52213,0.00000,0.01007,181.72358
67.30000,3.36495,15262.91966,0.00000,0.01009,182.02647
67.40000,3.36992,15285.21031,0.00000,0.01011,182.29231
67.50000,3.37500,15310.97442,0.00000,0.01013,182.59958
67.60000,3.37996,15332.22198,0.00000,0.01014,182.85298
67.70000,3.38504,15359.59840,0.00000,0.01017,183.17947
67.80000,3.38994,15382.71606,0.00000,0.01018,183.45517
67.90000,3.39503,15407.00644,0.00000,0.01020,183.74486
68.00000,3.39993,15428.46709,0.00000,0.01022,184.00080
68.10000,3.40507,15453.88550,0.00000,0.01024,184.30394
68.20000,3.40991,15478.04177,0.00000,0.01026,184.59203
68.30000,3.41506,15503.18301,0.00000,0.01028,184.89187
68.40000,3.41996,15526.13825,0.00000,0.01030,185.16563
68.50000,3.42510,15551.75632,0.00000,0.01032,185.47115
68.60000,3.42994,15574.83226,0.00000,0.01034,185.74636
68.70000,3.43503,15600.16274,0.00000,0.01036,186.04845
68.80000,3.43993,15624.34137,0.00000,0.01038,186.33681
68.90000,3.44507,15648.60195,0.00000,0.01040,186.62614
69.00000,3.44997,15672.44977,0.00000,0.01042,186.91055
69.10000,3.45500,15697.51650,0.00000,0.01044,187.20950
69.20000,3.45990,15722.69499,0.00000,0.01047,187.50978
69.30000,3.46498,15748.24005,0.00000,0.01049,187.81443
69.40000,3.46994,15772.95214,0.00000,0.01050,188.10915
69.50000,3.47503,15797.05179,0.00000,0.01053,188.39656
69.60000,3.47993,15822.02762,0.00000,0.01055,188.69443
69.70000,3.48501,15845.10505,0.00000,0.01057,188.96965
69.80000,3.48997,15869.32838,0.00000,0.01059,189.25854
69.90000,3.49505,15892.12269,0.00000,0.01061,189.53038
70.00000,3.50002,15917.42486,0.00000,0.01063,189.83214
70.10000,3.50492,15941.16241,0.00000,0.01065,190.11523
70.20000,3.50994,15966.58379,0.00000,0.01067,190.41841
70.30000,3.51490,15989.09497,0.00000,0.01069,190.68688
70.40000,3.52005,16016.08694,0.00000,0.01071,191.00879
70.50000,3.52489,16037.70256,0.00000,0.01073,191.26658
70.60000,3.53003,16064.04036,0.00000,0.01075,191.58068
70.70000,3.53487,16086.51727,0.00000,0.01077,191.84875
70.80000,3.54008,16112.62560,0.00000,0.01079,192.16011
70.90000,3.54492,16133.99982,0.00000,0.01081,192.41502
71.00000,3.55006,16161.34793,0.00000,0.01083,192.74118
71.10000,3.55490,16183.73096,0.00000,0.01085,193.00812
71.20000,3.56005,16208.99290,0.00000,0.01087,193.30940
71.30000,3.56495,16231.55624,0.00000,0.01089,193.57849
71.40000,3.57009,16255.73337,0.00000,0.01091,193.86683
71.50000,3.57493,16279.56629,0.00000,0.01093,194.15106
71.60000,3.57996,16302.68395,0.00000,0.01095,194.42676
71.70000,3.58492,16328.12470,0.00000,0.01097,194.73017
71.80000,3.59000,16351.04269,0.00000,0.01099,195.00349
71.90000,3.59496,16376.95730,0.00000,0.01101,195.31255
72.00000,3.59993,16400.37000,0.00000,0.01103,195.59177
72.10000,3.60501,16425.63790,0.00000,0.01105,195.89312
72.20000,3.60997,16447.30568,0.00000,0.01107,196.15153
72.30000,3.61505,16472.40669,0.00000,0.01109,196.45088
72.40000,3.61995,16494.16238,0.00000,0.01111,196.71034
72.50000,3.62504,16520.98000,0.00000,0.01113,197.03017
72.60000,3.62994,16543.95908,0.00000,0.01115,197.30422
72.70000,3.63502,16568.45212,0.00000,0.01117,197.59633
72.80000,3.63992,16593.03457,0.00000,0.01119,197.88950
72.90000,3.64501,16618.90298,0.00000,0.01121,198.19801
73.00000,3.64985,16642.25310,0.00000,0.01123,198.47648
73.10000,3.65505,16667.00542,0.00000,0.01126,198.77168
73.20000,3.65995,16689.99493,0.00000,0.01127,199.04585
73.30000,3.66516,16714.81878,0.00000,0.01129,199.34191
73.40000,3.66994,16737.63245,0.00000,0.01131,199.61398
73.50000,3.67502,16761.89601,0.00000,0.01133,199.90335
73.60000,3.67998,16784.34014,0.00000,0.01135,200.17102
73.70000,3.68513,16810.51403,0.00000,0.01137,200.48317
73.80000,3.68991,16832.31741,0.00000,0.01139,200.74320
73.90000,3.69505,16857.08761,0.00000,0.01141,201.03861
74.00000,3.69995,16881.67900,0.00000,0.01143,201.33189
74.10000,3.70504,16905.74735,0.00000,0.01145,201.61893
74.20000,3.71000,16928.32857,0.00000,0.01147,201.88824
74.30000,3.71502,16951.99460,0.00000,0.01149,202.17048
74.40000,3.71998,16977.52476,0.00000,0.01151,202.47495
74.50000,3.72501,17001.46049,0.00000,0.01154,202.76041
74.60000,3.73003,17025.68084,0.00000,0.01155,203.04926
74.70000,3.73505,17047.53339,0.00000,0.01158,203.30988
74.80000,3.74001,17073.18872,0.00000,0.01160,203.61585
74.90000,3.74486,17093.88345,0.00000,0.01162,203.86265
75.00000,3.75000,17121.22411,0.00000,0.01164,204.18872
75.10000,3.75490,17142.31521,0.00000,0.01166,204.44025
75.20000,3.76010,17167.63526,0.00000,0.01168,204.74222
75.30000,3.76494,17191.05691,0.00000,0.01170,205.02155
75.40000,3.77009,17217.05943,0.00000,0.01172,205.33166
75.50000,3.77493,17240.42743,0.00000,0.01174,205.61035
75.60000,3.78013,17264.63139,0.00000,0.01176,205.89900
75.70000,3.78491,17286.49288,0.00000,0.01178,206.15972
75.80000,3.79006,17309.74317,0.00000,0.01180,206.43701
75.90000,3.79484,17332.79526,0.00000,0.01182,206.71193
76.00000,3.79998,17356.30631,0.00000,0.01184,206.99232
76.10000,3.80488,17380.12731,0.00000,0.01186,207.27641
76.20000,3.80997,17404.57714,0.00000,0.01188,207.56800
76.30000,3.81487,17429.00312,0.00000,0.01191,207.85931
76.40000,3.81995,17452.87776,0.00000,0.01192,208.14404
76.50000,3.82497,17477.65541,0.00000,0.01194,208.43954
76.60000,3.83006,17500.76860,0.00000,0.01196,208.71519
76.70000,3.83496,17525.10816,0.00000,0.01199,209.00546
76.80000,3.83998,17547.07694,0.00000,0.01200,209.26747
76.90000,3.84506,17573.06159,0.00000,0.01202,209.57736
77.00000,3.85002,17594.58631,0.00000,0.01205,209.83406
77.10000,3.85505,17620.34595,0.00000,0.01207,210.14128
77.20000,3.85995,17641.78872,0.00000,0.01208,210.39700
77.30000,3.86503,17667.41127,0.00000,0.01211,210.70258
77.40000,3.86993,17689.23253,0.00000,0.01212,210.96282
77.50000,3.87514,17714.49298,0.00000,0.01215,211.26408
77.60000,3.87998,17736.78064,0.00000,0.01217,211.52988
77.70000,3.88506,17761.63131,0.00000,0.01219,211.82625
77.80000,3.88990,17785.15428,0.00000,0.01221,212.10679
77.90000,3.89505,17809.22264,0.00000,0.01223,212.39383
78.00000,3.89995,17833.41616,0.00000,0.01225,212.68236
78.10000,3.90509,17858.34879,0.00000,0.01227,212.97971
78.20000,3.90987,17880.45913,0.00000,0.01229,213.24340
78.30000,3.91502,17906.25602,0.00000,0.01231,213.55106
78.40000,3.91992,17927.66899,0.00000,0.01233,213.80643
78.50000,3.92512,17953.05610,0.00000,0.01235,214.10920
78.60000,3.92996,17975.66116,0.00000,0.01237,214.37879
78.70000,3.93505,17999.54474,0.00000,0.01239,214.66362
78.80000,3.93995,18023.69207,0.00000,0.01241,214.95160
78.90000,3.94503,18048.19554,0.00000,0.01243,215.24383
79.00000,3.94993,18071.51884,0.00000,0.01245,215.52199
79.10000,3.95501,18094.67226,0.00000,0.01248,215.79812
79.20000,3.95992,18118.73317,0.00000,0.01250,216.08507
79.30000,3.96494,18140.61701,0.00000,0.01252,216.34606
79.40000,3.97002,18165.67630,0.00000,0.01254,216.64492
79.50000,3.97498,18187.19804,0.00000,0.01256,216.90159
79.60000,3.98001,18212.97407,0.00000,0.01258,217.20899
79.70000,3.98491,18235.94123,0.00000,0.01260,217.48290
79.80000,3.99005,18261.30450,0.00000,0.01263,217.78538
79.90000,3.99495,18282.96781,0.00000,0.01264,218.04374
80.00000,4.00010,18307.74546,0.00000,0.01266,218.33924
80.10000,4.00488,18329.55033,0.00000,0.01268,218.59929
80.20000,4.01002,18353.52927,0.00000,0.01271,218.88526
80.30000,4.01486,18374.97354,0.00000,0.01272,219.14101
80.40000,4.02007,18399.31607,0.00000,0.01275,219.43132
80.50000,4.02491,18421.89282,0.00000,0.01277,219.70057
80.60000,4.02999,18447.22778,0.00000,0.01279,220.00272
80.70000,4.03489,18469.75237,0.00000,0.01281,220.27135
80.80000,4.04004,18493.42138,0.00000,0.01283,220.55362
80.90000,4.04500,18516.78342,0.00000,0.01285,220.83224
81.00000,4.05008,18539.53600,0.00000,0.01287,221.10359
81.10000,4.05492,18563.09623,0.00000,0.01289,221.38457
81.20000,4.06001,18585.51800,0.00000,0.01291,221.65197
81.30000,4.06503,18610.27330,0.00000,0.01293,221.94721
81.40000,4.07005,18632.77107,0.00000,0.01295,222.21552
81.50000,4.07501,18657.41611,0.00000,0.01297,222.50943
81.60000,4.07998,18681.05978,0.00000,0.01300,222.79141
81.70000,4.08500,18705.51556,0.00000,0.01302,223.08307
81.80000,4.09002,18727.02837,0.00000,0.01303,223.33963
81.90000,4.09510,18751.88351,0.00000,0.01305,223.63606
82.00000,4.10000,18773.76288,0.00000,0.01308,223.89699
82.10000,4.10509,18800.06343,0.00000,0.01310,224.21066
82.20000,4.10999,18821.09344,0.00000,0.01312,224.46146
82.30000,4.11507,18846.54760,0.00000,0.01314,224.76503
82.40000,4.11997,18868.51788,0.00000,0.01316,225.02705
82.50000,4.12506,18893.15248,0.00000,0.01318,225.32084
82.60000,4.12990,18915.94380,0.00000,0.01320,225.59265
82.70000,4.13510,18939.73053,0.00000,0.01322,225.87633
82.80000,4.13994,18962.30429,0.00000,0.01324,226.14555
82.90000,4.14509,18985.69316,0.00000,0.01326,226.42449
83.00000,4.14993,19008.47703,0.00000,0.01328,226.69621
83.10000,4.15507,19034.04891,0.00000,0.01331,227.00118
83.20000,4.15991,19057.11740,0.00000,0.01332,227.27630
83.30000,4.16506,19081.01439,0.00000,0.01334,227.56129
83.40000,4.16990,19104.33471,0.00000,0.01337,227.83941
83.50000,4.17498,19128.81285,0.00000,0.01339,228.13134
83.60000,4.17988,19152.51017,0.00000,0.01341,228.41396
83.70000,4.18503,19174.35825,0.00000,0.01343,228.67452
83.80000,4.18999,19197.21216,0.00000,0.01345,228.94707
83.90000,4.19501,19219.61606,0.00000,0.01347,229.21426
84.00000,4.19997,19244.55464,0.00000,0.01349,229.51168
84.10000,4.20505,19266.21944,0.00000,0.01352,229.77006
84.20000,4.21008,19291.15355,0.00000,0.01354,230.06742
84.30000,4.21498,19310.96613,0.00000,0.01355,230.30371
84.40000,4.22006,19336.88670,0.00000,0.01358,230.61284
84.50000,4.22490,19356.90194,0.00000,0.01360,230.85154
84.60000,4.23011,19382.20859,0.00000,0.01362,231.15335
84.70000,4.23495,19402.17614,0.00000,0.01364,231.39149
84.80000,4.24009,19428.22486,0.00000,0.01366,231.70215
84.90000,4.24487,19450.10722,0.00000,0.01369,231.96312
85.00000,4.25002,19476.24236,0.00000,0.01371,232.27480
85.10000,4.25492,19498.34526,0.00000,0.01372,232.53840
85.20000,4.26012,19522.94856,0.00000,0.01375,232.83183
85.30000,4.26490,19543.89960,0.00000,0.01376,233.08169
85.40000,4.26999,19568.71003,0.00000,0.01379,233.37758
85.50000,4.27489,19590.87402,0.00000,0.01381,233.64191
85.60000,4.28003,19614.70693,0.00000,0.01383,233.92614
85.70000,4.28505,19637.85887,0.00000,0.01385,234.20225
85.80000,4.29002,19660.89606,0.00000,0.01387,234.47700
85.90000,4.29492,19686.67656,0.00000,0.01389,234.78446
86.00000,4.30006,19709.12665,0.00000,0.01391,235.05220
86.10000,4.30502,19733.12050,0.00000,0.01393,235.33835
86.20000,4.31005,19754.14902,0.00000,0.01395,235.58914
86.30000,4.31501,19776.28618,0.00000,0.01398,235.85314
86.40000,4.32003,19797.46521,0.00000,0.01400,236.10573
86.50000,4.32505,19820.59777,0.00000,0.01402,236.38161
86.60000,4.33007,19840.76351,0.00000,0.01404,236.62211
86.70000,4.33504,19864.83335,0.00000,0.01406,236.90916
86.80000,4.34000,19886.17480,0.00000,0.01408,237.16368
86.90000,4.34502,19911.59618,0.00000,0.01410,237.46686
87.00000,4.34992,19932.62321,0.00000,0.01412,237.71763
87.10000,4.35513,19957.86279,0.00000,0.01414,238.01864
87.20000,4.35991,19977.60683,0.00000,0.01416,238.25411
87.30000,4.36505,19999.82297,0.00000,0.01418,238.51906
87.40000,4.36995,20021.30747,0.00000,0.01420,238.77528
87.50000,4.37516,20044.81852,0.00000,0.01422,239.05568
87.60000,4.38000,20062.56133,0.00000,0.01424,239.26728
87.67400,4.38388,19717.16136,0.00000,0.01435,235.14802
87.67600,4.38400,19205.87718,0.00000,0.01450,229.05041
87.67800,4.38412,18478.72287,0.00000,0.01472,220.37833
87.68000,4.38442,17607.79023,0.00000,0.01508,209.99154
87.68200,4.38472,16627.46668,0.00000,0.01577,198.30014
87.68400,4.38502,15560.07862,0.00000,0.01689,185.57041
87.68600,4.38538,14443.02499,0.00000,0.01830,172.24836
87.68800,4.38574,13306.92768,0.00000,0.01971,158.69920
87.69000,4.38598,12164.59423,0.00000,0.02093,145.07566
87.69200,4.38634,11027.56634,0.00000,0.02188,131.51540