File: scratch/college-stuff/ME Lab/ME lab Fall 2013/group14/group14.is_tens_RawData/Specimen_RawData_2.csv
Time,Extension,Load,Strain 2,Tensile strain,Tensile stress
(sec),(mm),(N),(mm/mm),(mm/mm),(MPa)
0.00000,0.00000,0.07920,0.00000,0.00000,0.00096
0.30000,0.01345,19.51516,0.00000,0.00000,0.23704
0.60000,0.02989,35.70692,0.00000,0.00001,0.43371
0.90000,0.04502,48.29302,0.00000,0.00001,0.58659
1.20000,0.05997,64.22875,0.00000,0.00001,0.78015
1.50000,0.07504,79.35679,0.00000,0.00001,0.96391
1.80000,0.08998,100.82625,0.00000,0.00001,1.22468
2.10000,0.10511,133.38409,0.00000,0.00001,1.62015
2.40000,0.11994,161.29181,0.00000,0.00001,1.95913
2.70000,0.13512,197.74067,0.00000,0.00001,2.40185
3.00000,0.14995,247.41259,0.00000,0.00001,3.00519
3.30000,0.16496,307.69506,0.00000,0.00000,3.73741
3.60000,0.18009,385.93623,0.00000,0.00000,4.68777
3.90000,0.19491,489.55777,0.00000,0.00000,5.94640
4.20000,0.21010,623.78803,0.00000,0.00001,7.57683
4.50000,0.22493,775.19710,0.00000,0.00003,9.41591
4.80000,0.24000,936.62068,0.00000,0.00005,11.37664
5.10000,0.25500,1117.41461,0.00000,0.00007,13.57265
5.40000,0.27001,1303.96597,0.00000,0.00010,15.83859
5.70000,0.28502,1497.62481,0.00000,0.00012,18.19087
6.00000,0.29996,1693.16735,0.00000,0.00015,20.56602
6.30000,0.31509,1895.78440,0.00000,0.00018,23.02710
6.60000,0.32986,2092.05523,0.00000,0.00021,25.41110
6.90000,0.34499,2301.92207,0.00000,0.00024,27.96024
7.20000,0.35993,2507.15967,0.00000,0.00027,30.45316
7.50000,0.37500,2711.44584,0.00000,0.00030,32.93451
7.80000,0.38995,2919.60090,0.00000,0.00033,35.46286
8.10000,0.40489,3121.63159,0.00000,0.00036,37.91683
8.40000,0.42008,3327.25979,0.00000,0.00039,40.41448
8.70000,0.43491,3525.70489,0.00000,0.00042,42.82489
9.00000,0.45004,3726.71448,0.00000,0.00045,45.26645
9.30000,0.46486,3920.93845,0.00000,0.00049,47.62559
9.60000,0.47999,4115.00521,0.00000,0.00052,49.98282
9.90000,0.49494,4305.28820,0.00000,0.00055,52.29408
10.20000,0.50994,4492.86103,0.00000,0.00058,54.57243
10.50000,0.52501,4684.14724,0.00000,0.00061,56.89589
10.80000,0.53990,4862.63670,0.00000,0.00064,59.06390
11.10000,0.55503,5046.95848,0.00000,0.00067,61.30276
11.40000,0.56991,5220.41321,0.00000,0.00070,63.40963
11.70000,0.58504,5393.99646,0.00000,0.00073,65.51805
12.00000,0.59987,5557.34634,0.00000,0.00076,67.50218
12.30000,0.61493,5704.27664,0.00000,0.00078,69.28686
12.60000,0.63000,5844.57442,0.00000,0.00080,70.99099
12.90000,0.64495,5973.65126,0.00000,0.00082,72.55882
13.20000,0.66008,6103.49439,0.00000,0.00084,74.13595
13.50000,0.67490,6226.75270,0.00000,0.00087,75.63311
13.80000,0.69009,6352.57959,0.00000,0.00089,77.16146
14.10000,0.70498,6478.06898,0.00000,0.00091,78.68571
14.40000,0.72004,6607.31494,0.00000,0.00093,80.25560
14.70000,0.73499,6733.71479,0.00000,0.00095,81.79091
15.00000,0.75000,6861.34547,0.00000,0.00097,83.34117
15.30000,0.76501,6993.64096,0.00000,0.00100,84.94810
15.60000,0.77989,7118.50226,0.00000,0.00101,86.46472
15.90000,0.79508,7253.95903,0.00000,0.00104,88.11005
16.20000,0.80985,7380.47510,0.00000,0.00106,89.64677
16.50000,0.82504,7515.26505,0.00000,0.00108,91.28399
16.80000,0.83986,7645.59284,0.00000,0.00111,92.86702
17.10000,0.85505,7777.73410,0.00000,0.00113,94.47207
17.40000,0.87006,7914.35018,0.00000,0.00116,96.13147
17.70000,0.88494,8043.78763,0.00000,0.00118,97.70368
18.00000,0.90013,8180.15561,0.00000,0.00120,99.36007
18.30000,0.91496,8310.90137,0.00000,0.00122,100.94817
18.60000,0.93003,8449.35849,0.00000,0.00125,102.62994
18.90000,0.94491,8581.93114,0.00000,0.00127,104.24023
19.20000,0.95998,8722.95275,0.00000,0.00129,105.95314
19.50000,0.97493,8859.25740,0.00000,0.00132,107.60876
19.80000,0.98999,8997.80542,0.00000,0.00134,109.29163
20.10000,1.00506,9140.25828,0.00000,0.00137,111.02194
20.40000,1.01995,9276.38039,0.00000,0.00139,112.67534
20.70000,1.03502,9416.89536,0.00000,0.00141,114.38210
21.00000,1.04990,9559.03977,0.00000,0.00144,116.10865
21.30000,1.06503,9700.17090,0.00000,0.00147,117.82290
21.60000,1.07992,9840.95261,0.00000,0.00149,119.53290
21.90000,1.09498,9979.29275,0.00000,0.00151,121.21325
22.20000,1.10999,10123.97781,0.00000,0.00154,122.97066
22.50000,1.12494,10262.92369,0.00000,0.00156,124.65836
22.80000,1.14007,10407.97979,0.00000,0.00159,126.42028
23.10000,1.15489,10550.06981,0.00000,0.00161,128.14618
23.40000,1.17008,10695.84265,0.00000,0.00164,129.91680
23.70000,1.18497,10835.61555,0.00000,0.00166,131.61455
24.00000,1.19998,10982.70938,0.00000,0.00169,133.40122
24.30000,1.21498,11128.40325,0.00000,0.00172,135.17089
24.60000,1.22999,11271.48569,0.00000,0.00174,136.90884
24.90000,1.24500,11422.06267,0.00000,0.00177,138.73782
25.20000,1.25988,11563.73173,0.00000,0.00180,140.45860
25.50000,1.27507,11711.55795,0.00000,0.00182,142.25417
25.80000,1.28996,11857.26300,0.00000,0.00185,144.02397
26.10000,1.30497,12005.03781,0.00000,0.00188,145.81891
26.40000,1.31991,12155.22513,0.00000,0.00190,147.64316
26.70000,1.33504,12299.45868,0.00000,0.00193,149.39509
27.00000,1.35011,12449.97010,0.00000,0.00196,151.22327
27.30000,1.36493,12595.66545,0.00000,0.00199,152.99296
27.60000,1.38006,12744.06463,0.00000,0.00202,154.79549
27.90000,1.39489,12891.61444,0.00000,0.00204,156.58770
28.20000,1.41002,13043.77913,0.00000,0.00207,158.43596
28.50000,1.42490,13192.66260,0.00000,0.00210,160.24437
28.80000,1.43997,13339.82050,0.00000,0.00213,162.03182
29.10000,1.45498,13493.30544,0.00000,0.00216,163.89612
29.40000,1.46998,13639.51266,0.00000,0.00219,165.67202
29.70000,1.48499,13793.30605,0.00000,0.00222,167.54007
30.00000,1.49988,13938.93063,0.00000,0.00225,169.30890
30.30000,1.51507,14094.56730,0.00000,0.00228,171.19933
30.60000,1.52995,14241.18727,0.00000,0.00231,172.98025
30.90000,1.54502,14390.14971,0.00000,0.00234,174.78962
31.20000,1.55997,14542.59008,0.00000,0.00237,176.64123
31.50000,1.57497,14690.83428,0.00000,0.00240,178.44188
31.80000,1.59004,14845.97921,0.00000,0.00243,180.32634
32.10000,1.60487,14993.44856,0.00000,0.00246,182.11757
32.40000,1.62012,15146.66378,0.00000,0.00249,183.97860
32.70000,1.63494,15295.18813,0.00000,0.00252,185.78265
33.00000,1.65001,15450.10060,0.00000,0.00255,187.66429
33.30000,1.66496,15600.18212,0.00000,0.00258,189.48725
33.60000,1.67997,15753.93975,0.00000,0.00262,191.35486
33.90000,1.69497,15907.31144,0.00000,0.00265,193.21779
34.20000,1.70992,16054.25179,0.00000,0.00268,195.00260
34.50000,1.72499,16208.01538,0.00000,0.00271,196.87028
34.80000,1.73987,16355.53539,0.00000,0.00274,198.66213
35.10000,1.75500,16509.59402,0.00000,0.00277,200.53340
35.40000,1.76989,16659.84690,0.00000,0.00280,202.35844
35.70000,1.78508,16812.01756,0.00000,0.00284,204.20678
36.00000,1.79996,16963.87529,0.00000,0.00287,206.05132
36.30000,1.81497,17113.78843,0.00000,0.00290,207.87223
36.60000,1.83004,17265.82795,0.00000,0.00294,209.71898
36.90000,1.84486,17416.23282,0.00000,0.00297,211.54587
37.20000,1.86005,17570.37193,0.00000,0.00301,213.41811
37.50000,1.87488,17716.76838,0.00000,0.00304,215.19632
37.80000,1.89001,17869.55595,0.00000,0.00307,217.05215
38.10000,1.90489,18013.96608,0.00000,0.00311,218.80622
38.40000,1.91996,18166.21125,0.00000,0.00315,220.65546
38.70000,1.93491,18315.36591,0.00000,0.00318,222.46717
39.00000,1.94997,18457.80909,0.00000,0.00322,224.19735
39.30000,1.96504,18608.35403,0.00000,0.00326,226.02594
39.60000,1.97987,18745.93794,0.00000,0.00329,227.69710
39.90000,1.99512,18894.80054,0.00000,0.00333,229.50526
40.20000,2.00994,19037.74589,0.00000,0.00337,231.24154
40.50000,2.02507,19180.28146,0.00000,0.00340,232.97284
40.80000,2.03996,19319.31227,0.00000,0.00344,234.66158
41.10000,2.05496,19456.72929,0.00000,0.00348,236.33071
41.40000,2.07003,19596.85683,0.00000,0.00352,238.03277
41.70000,2.08492,19727.60111,0.00000,0.00356,239.62085
42.00000,2.09999,19864.31330,0.00000,0.00360,241.28142
42.30000,2.11493,19994.41683,0.00000,0.00365,242.86172
42.60000,2.13000,20123.10624,0.00000,0.00369,244.42484
42.90000,2.14489,20249.53067,0.00000,0.00373,245.96045
43.20000,2.16001,20370.85891,0.00000,0.00377,247.43416
43.50000,2.17496,20491.72670,0.00000,0.00382,248.90228
43.80000,2.18997,20606.56995,0.00000,0.00387,250.29722
44.10000,2.20504,20722.60827,0.00000,0.00391,251.70668
44.40000,2.21992,20829.31101,0.00000,0.00396,253.00274
44.70000,2.23511,20936.79905,0.00000,0.00400,254.30834
45.00000,2.24988,21037.80359,0.00000,0.00406,255.53519
45.30000,2.26506,21135.90539,0.00000,0.00410,256.72678
45.60000,2.27995,21229.76184,0.00000,0.00415,257.86681
45.90000,2.29496,21318.74859,0.00000,0.00420,258.94769
46.20000,2.31003,21403.99963,0.00000,0.00426,259.98318
46.50000,2.32491,21480.48878,0.00000,0.00431,260.91226
46.80000,2.34004,21558.19535,0.00000,0.00436,261.85612
47.10000,2.35487,21627.71523,0.00000,0.00441,262.70054
47.40000,2.36994,21697.81029,0.00000,0.00446,263.55195
47.70000,2.38494,21762.23695,0.00000,0.00451,264.33451
48.00000,2.39995,21820.67484,0.00000,0.00457,265.04432
48.30000,2.41496,21881.54906,0.00000,0.00462,265.78373
48.60000,2.43002,21933.77763,0.00000,0.00468,266.41812
48.90000,2.44515,21988.91193,0.00000,0.00474,267.08781
49.20000,2.45992,22033.29355,0.00000,0.00480,267.62689
49.50000,2.47511,22084.31214,0.00000,0.00487,268.24658
49.80000,2.48993,22127.89804,0.00000,0.00493,268.77600
50.10000,2.50506,22169.17872,0.00000,0.00500,269.27741
50.40000,2.52001,22209.43421,0.00000,0.00508,269.76638
50.70000,2.53495,22246.61708,0.00000,0.00516,270.21802
51.00000,2.55002,22285.21258,0.00000,0.00524,270.68682
51.30000,2.56491,22319.75496,0.00000,0.00533,271.10639
51.60000,2.58004,22353.53291,0.00000,0.00542,271.51667
51.90000,2.59498,22383.34417,0.00000,0.00551,271.87877
52.20000,2.61005,22415.47853,0.00000,0.00561,272.26909
52.50000,2.62500,22443.27366,0.00000,0.00572,272.60670
52.80000,2.64000,22471.32957,0.00000,0.00582,272.94748
53.10000,2.65501,22500.81450,0.00000,0.00594,273.30562
53.40000,2.67002,22520.94299,0.00000,0.00605,273.55011
53.70000,2.68509,22547.36423,0.00000,0.00618,273.87104
54.00000,2.69985,22566.38408,0.00000,0.00630,274.10206
54.30000,2.71516,22592.57287,0.00000,0.00644,274.42016
54.60000,2.72987,22610.45128,0.00000,0.00658,274.63732
54.90000,2.74500,22630.29218,0.00000,0.00672,274.87832
55.20000,2.76000,22650.85429,0.00000,0.00686,275.12808
55.50000,2.77501,22666.95946,0.00000,0.00701,275.32370
55.80000,2.79008,22687.28763,0.00000,0.00717,275.57061
56.10000,2.80490,22700.54668,0.00000,0.00732,275.73166
56.40000,2.82003,22720.03293,0.00000,0.00749,275.96835
56.70000,2.83498,22731.73630,0.00000,0.00764,276.11051
57.00000,2.84993,22747.28864,0.00000,0.00781,276.29941
57.30000,2.86493,22761.02304,0.00000,0.00797,276.46624
57.60000,2.88006,22773.88275,0.00000,0.00814,276.62244
57.90000,2.89501,22789.22647,0.00000,0.00831,276.80881
58.20000,2.91001,22798.00624,0.00000,0.00848,276.91545
58.50000,2.92508,22814.00412,0.00000,0.00866,277.10977
58.80000,2.93991,22822.03436,0.00000,0.00883,277.20731
59.10000,2.95516,22835.98185,0.00000,0.00900,277.37672
59.40000,2.96992,22844.75416,0.00000,0.00918,277.48328
59.70000,2.98505,22855.78698,0.00000,0.00936,277.61729
60.00000,3.00000,22867.92696,0.00000,0.00953,277.76474
60.30000,3.01494,22875.23746,0.00000,0.00971,277.85354
60.60000,3.03001,22889.21028,0.00000,0.00989,278.02326
60.90000,3.04496,22896.43139,0.00000,0.01006,278.11097
61.20000,3.06009,22909.33430,0.00000,0.01023,278.26770
61.50000,3.07497,22916.40937,0.00000,0.01042,278.35363
61.80000,3.08998,22927.93989,0.00000,0.01060,278.49369
62.10000,3.10499,22937.62416,0.00000,0.01078,278.61132
62.40000,3.12011,22944.92126,0.00000,0.01095,278.69995
62.70000,3.13500,22956.10905,0.00000,0.01113,278.83585
63.00000,3.15001,22960.66731,0.00000,0.01131,278.89121
63.30000,3.16508,22973.43314,0.00000,0.01149,279.04627
63.60000,3.17990,22979.41893,0.00000,0.01166,279.11898
63.90000,3.19509,22989.08234,0.00000,0.01184,279.23636
64.20000,3.20998,22997.33162,0.00000,0.01202,279.33655
64.50000,3.22499,23004.99529,0.00000,0.01219,279.42964
64.80000,3.24005,23014.85091,0.00000,0.01237,279.54935
65.10000,3.25494,23018.41229,0.00000,0.01254,279.59261
65.40000,3.27007,23030.53588,0.00000,0.01272,279.73987
65.70000,3.28495,23035.33107,0.00000,0.01289,279.79811
66.00000,3.30002,23045.62777,0.00000,0.01305,279.92318
66.30000,3.31497,23050.97431,0.00000,0.01323,279.98812
66.60000,3.33004,23060.22793,0.00000,0.01340,280.10052
66.90000,3.34492,23067.80815,0.00000,0.01358,280.19260
67.20000,3.36005,23076.21837,0.00000,0.01375,280.29475
67.50000,3.37506,23086.24834,0.00000,0.01392,280.41658
67.80000,3.38994,23088.59974,0.00000,0.01409,280.44514
68.10000,3.40513,23100.07066,0.00000,0.01425,280.58447
68.40000,3.41990,23105.34716,0.00000,0.01442,280.64856
68.70000,3.43509,23114.78555,0.00000,0.01459,280.76321
69.00000,3.44991,23121.37932,0.00000,0.01476,280.84330
69.30000,3.46492,23127.99692,0.00000,0.01493,280.92368
69.60000,3.48005,23137.60668,0.00000,0.01509,281.04040
69.90000,3.49493,23140.19799,0.00000,0.01526,281.07188
70.20000,3.51000,23148.66781,0.00000,0.01542,281.17476
70.50000,3.52495,23156.22121,0.00000,0.01559,281.26650
70.80000,3.54008,23166.53728,0.00000,0.01575,281.39181
71.10000,3.55496,23170.59338,0.00000,0.01592,281.44107
71.40000,3.57003,23179.77399,0.00000,0.01608,281.55259
71.70000,3.58492,23185.70614,0.00000,0.01624,281.62464
72.00000,3.60004,23193.05241,0.00000,0.01640,281.71387
72.30000,3.61493,23202.39544,0.00000,0.01657,281.82736
72.60000,3.62988,23205.17451,0.00000,0.01674,281.86111
72.90000,3.64513,23216.76761,0.00000,0.01689,282.00193
73.20000,3.65983,23217.61101,0.00000,0.01705,282.01217
73.50000,3.67502,23225.25382,0.00000,0.01721,282.10501
73.80000,3.68991,23233.85626,0.00000,0.01736,282.20950
74.10000,3.70498,23241.40668,0.00000,0.01752,282.30121
74.40000,3.72010,23250.35036,0.00000,0.01769,282.40984
74.70000,3.73499,23255.66113,0.00000,0.01785,282.47435
75.00000,3.75006,23262.12525,0.00000,0.01801,282.55286
75.30000,3.76506,23268.02760,0.00000,0.01816,282.62456
75.60000,3.78007,23277.40788,0.00000,0.01832,282.73849
75.90000,3.79484,23281.14659,0.00000,0.01847,282.78391
76.20000,3.81009,23292.14364,0.00000,0.01863,282.91748
76.50000,3.82491,23296.18484,0.00000,0.01878,282.96657
76.80000,3.84004,23302.14530,0.00000,0.01894,283.03897
77.10000,3.85505,23311.07706,0.00000,0.01910,283.14746
77.40000,3.86993,23313.91424,0.00000,0.01925,283.18192
77.70000,3.88512,23325.68318,0.00000,0.01941,283.32487
78.00000,3.89983,23327.69185,0.00000,0.01956,283.34927
78.30000,3.91508,23336.03203,0.00000,0.01971,283.45057
78.60000,3.92996,23341.75557,0.00000,0.01987,283.52009
78.90000,3.94497,23347.63408,0.00000,0.02002,283.59150
79.20000,3.96010,23357.22446,0.00000,0.02016,283.70798
79.50000,3.97504,23361.52941,0.00000,0.02031,283.76027
79.80000,3.99005,23369.19606,0.00000,0.02047,283.85340
80.10000,4.00500,23373.80797,0.00000,0.02062,283.90942
80.40000,4.02013,23383.78876,0.00000,0.02078,284.03065
80.70000,4.03495,23384.86761,0.00000,0.02093,284.04375
81.00000,4.05008,23394.25534,0.00000,0.02108,284.15778
81.30000,4.06491,23400.66433,0.00000,0.02123,284.23563
81.60000,4.08003,23404.01113,0.00000,0.02137,284.27628
81.90000,4.09504,23414.17819,0.00000,0.02152,284.39977
82.20000,4.10987,23414.09922,0.00000,0.02167,284.39881
82.50000,4.12506,23423.67321,0.00000,0.02182,284.51510
82.80000,4.13988,23429.30734,0.00000,0.02197,284.58354
83.10000,4.15501,23436.28556,0.00000,0.02212,284.66830
83.40000,4.16996,23444.16976,0.00000,0.02226,284.76406
83.70000,4.18497,23449.56994,0.00000,0.02241,284.82966
84.00000,4.20009,23456.82681,0.00000,0.02256,284.91780
84.30000,4.21498,23460.76071,0.00000,0.02270,284.96559
84.60000,4.23005,23468.32007,0.00000,0.02286,285.05741
84.90000,4.24499,23473.20020,0.00000,0.02300,285.11668
85.20000,4.26006,23481.34071,0.00000,0.02315,285.21556
85.50000,4.27489,23483.70105,0.00000,0.02330,285.24423
85.80000,4.29008,23492.49721,0.00000,0.02344,285.35107
86.10000,4.30496,23499.87626,0.00000,0.02359,285.44070
86.40000,4.32003,23502.08014,0.00000,0.02373,285.46747
86.70000,4.33504,23512.87305,0.00000,0.02388,285.59857
87.00000,4.34986,23515.09631,0.00000,0.02403,285.62557
87.30000,4.36517,23524.44082,0.00000,0.02418,285.73907
87.60000,4.37994,23530.00492,0.00000,0.02432,285.80666
87.90000,4.39501,23534.58405,0.00000,0.02446,285.86228
88.20000,4.41001,23542.36394,0.00000,0.02460,285.95678
88.50000,4.42496,23546.61077,0.00000,0.02475,286.00836
88.80000,4.44003,23555.47696,0.00000,0.02490,286.11605
89.10000,4.45497,23557.58250,0.00000,0.02504,286.14163
89.40000,4.47004,23566.11192,0.00000,0.02518,286.24523
89.70000,4.48499,23569.19199,0.00000,0.02532,286.28264
90.00000,4.50006,23579.06699,0.00000,0.02547,286.40259
90.30000,4.51488,23581.75218,0.00000,0.02561,286.43521
90.60000,4.53007,23588.92858,0.00000,0.02575,286.52237
90.90000,4.54496,23595.51042,0.00000,0.02590,286.60232
91.20000,4.55996,23596.40747,0.00000,0.02604,286.61322
91.50000,4.57509,23605.04121,0.00000,0.02619,286.71809
91.80000,4.58986,23608.69795,0.00000,0.02633,286.76250
92.10000,4.60511,23616.97555,0.00000,0.02646,286.86305
92.40000,4.61987,23622.32059,0.00000,0.02661,286.92797
92.70000,4.63506,23628.17228,0.00000,0.02675,286.99905
93.00000,4.65001,23633.03751,0.00000,0.02689,287.05814
93.30000,4.66502,23638.05324,0.00000,0.02703,287.11907
93.60000,4.68002,23645.01804,0.00000,0.02718,287.20366
93.90000,4.69497,23648.55707,0.00000,0.02732,287.24665
94.20000,4.70998,23656.78400,0.00000,0.02746,287.34658
94.50000,4.72492,23657.41283,0.00000,0.02760,287.35422
94.80000,4.73999,23666.49806,0.00000,0.02774,287.46457
95.10000,4.75488,23668.62595,0.00000,0.02789,287.49042
95.40000,4.77001,23676.06759,0.00000,0.02803,287.58081
95.70000,4.78495,23684.22151,0.00000,0.02816,287.67985
96.00000,4.79996,23685.72205,0.00000,0.02830,287.69807
96.30000,4.81509,23695.16492,0.00000,0.02844,287.81277
96.60000,4.82991,23696.47920,0.00000,0.02858,287.82873
96.90000,4.84516,23705.46311,0.00000,0.02872,287.93786
97.20000,4.85999,23708.23473,0.00000,0.02886,287.97152
97.50000,4.87506,23715.21890,0.00000,0.02901,288.05636
97.80000,4.88994,23721.64279,0.00000,0.02915,288.13438
98.10000,4.90501,23727.20838,0.00000,0.02929,288.20199
98.40000,4.92002,23731.43286,0.00000,0.02943,288.25330
98.70000,4.93496,23736.07010,0.00000,0.02956,288.30962
99.00000,4.95003,23742.65939,0.00000,0.02970,288.38966
99.30000,4.96498,23745.43995,0.00000,0.02983,288.42344
99.60000,4.98005,23753.12448,0.00000,0.02997,288.51678
99.90000,4.99487,23756.07640,0.00000,0.03011,288.55263
100.20000,5.01006,23762.47495,0.00000,0.03026,288.63035
100.50000,5.02501,23769.33396,0.00000,0.03039,288.71366
100.80000,5.03996,23770.92689,0.00000,0.03053,288.73301
101.10000,5.05508,23780.14773,0.00000,0.03066,288.84501
101.40000,5.06991,23782.37396,0.00000,0.03080,288.87205
101.70000,5.08510,23788.84107,0.00000,0.03094,288.95061
102.00000,5.09992,23791.79597,0.00000,0.03107,288.98650
102.30000,5.11505,23797.27960,0.00000,0.03121,289.05310
102.60000,5.13000,23803.84207,0.00000,0.03134,289.13282
102.90000,5.14495,23807.20526,0.00000,0.03148,289.17367
103.20000,5.16001,23814.87042,0.00000,0.03162,289.26677
103.50000,5.17496,23817.05791,0.00000,0.03175,289.29334
103.80000,5.19003,23824.02718,0.00000,0.03189,289.37799
104.10000,5.20497,23824.62472,0.00000,0.03202,289.38525
104.40000,5.21998,23831.59250,0.00000,0.03216,289.46989
104.70000,5.23493,23836.95096,0.00000,0.03229,289.53497
105.00000,5.25000,23840.52873,0.00000,0.03242,289.57843
105.30001,5.26500,23847.76473,0.00000,0.03255,289.66632
105.60001,5.28001,23849.52605,0.00000,0.03269,289.68771
105.90001,5.29514,23857.27763,0.00000,0.03282,289.78187
106.20001,5.30990,23860.49926,0.00000,0.03295,289.82100
106.50001,5.32509,23867.70993,0.00000,0.03309,289.90858
106.80001,5.33992,23871.54996,0.00000,0.03322,289.95523
107.10001,5.35505,23876.64765,0.00000,0.03336,290.01715
107.40001,5.36999,23878.42238,0.00000,0.03349,290.03870
107.70001,5.38500,23883.26079,0.00000,0.03361,290.09747
108.00001,5.40007,23889.60272,0.00000,0.03374,290.17451
108.30001,5.41490,23891.18224,0.00000,0.03388,290.19369
108.60001,5.43002,23899.65206,0.00000,0.03400,290.29657
108.90001,5.44497,23901.03489,0.00000,0.03414,290.31337
109.20001,5.46004,23907.03112,0.00000,0.03427,290.38620
109.50001,5.47498,23912.74422,0.00000,0.03440,290.45559
109.80001,5.49011,23916.72581,0.00000,0.03453,290.50396
110.10001,5.50506,23924.85738,0.00000,0.03466,290.60272
110.40001,5.51994,23924.10636,0.00000,0.03479,290.59360
110.70001,5.53513,23932.15001,0.00000,0.03492,290.69130
111.00001,5.54990,23934.48204,0.00000,0.03505,290.71963
111.30001,5.56509,23938.85553,0.00000,0.03518,290.77275
111.60001,5.57991,23944.39727,0.00000,0.03532,290.84007
111.90001,5.59504,23948.09425,0.00000,0.03544,290.88497
112.20001,5.60999,23952.36939,0.00000,0.03557,290.93690
112.50001,5.62500,23955.54334,0.00000,0.03569,290.97545
112.80001,5.64006,23960.79153,0.00000,0.03582,291.03920
113.10001,5.65495,23964.33651,0.00000,0.03595,291.08226
113.40001,5.67008,23971.17764,0.00000,0.03608,291.16535
113.70001,5.68490,23973.08350,0.00000,0.03621,291.18850
114.00001,5.69997,23979.32112,0.00000,0.03634,291.26427
114.30001,5.71486,23983.60670,0.00000,0.03647,291.31632
114.60001,5.73011,23987.43331,0.00000,0.03659,291.36280
114.90001,5.74505,23992.63531,0.00000,0.03672,291.42599
115.20001,5.75994,23993.11811,0.00000,0.03684,291.43185
115.50001,5.77513,24002.65932,0.00000,0.03697,291.54774
115.80001,5.78995,24002.37024,0.00000,0.03710,291.54423
116.10001,5.80508,24008.42458,0.00000,0.03723,291.61777
116.40001,5.81997,24010.63293,0.00000,0.03736,291.64460
116.70001,5.83504,24015.62333,0.00000,0.03748,291.70521
117.00001,5.84998,24019.45293,0.00000,0.03761,291.75173
117.30001,5.86493,24022.85039,0.00000,0.03773,291.79299
117.60001,5.88000,24028.12243,0.00000,0.03785,291.85703
117.90001,5.89494,24030.23839,0.00000,0.03798,291.88273
118.20001,5.91007,24037.08547,0.00000,0.03810,291.96590
118.50001,5.92490,24038.84530,0.00000,0.03823,291.98728
118.80001,5.94003,24045.81159,0.00000,0.03836,292.07189
119.10001,5.95497,24050.25512,0.00000,0.03848,292.12587
119.40001,5.97010,24052.82855,0.00000,0.03861,292.15712
119.70001,5.98499,24058.72941,0.00000,0.03874,292.22880
120.00001,5.99994,24059.21668,0.00000,0.03886,292.23472
120.30001,6.01506,24065.95051,0.00000,0.03898,292.31651
120.60001,6.02983,24066.02949,0.00000,0.03911,292.31747
120.90001,6.04502,24072.95406,0.00000,0.03923,292.40158
121.20001,6.05996,24076.10863,0.00000,0.03936,292.43989
121.50001,6.07503,24082.58319,0.00000,0.03949,292.51854
121.80001,6.09004,24085.59471,0.00000,0.03961,292.55512
122.10001,6.10493,24088.47958,0.00000,0.03974,292.59016
122.40001,6.12005,24094.49369,0.00000,0.03986,292.66321
122.70001,6.13500,24097.31299,0.00000,0.03999,292.69745
123.00001,6.15007,24103.15275,0.00000,0.04011,292.76839
123.30001,6.16495,24101.88615,0.00000,0.04023,292.75300
123.60001,6.18002,24107.43088,0.00000,0.04036,292.82035
123.90001,6.19491,24111.39905,0.00000,0.04048,292.86855
124.20001,6.21010,24115.13329,0.00000,0.04061,292.91391
124.50001,6.22504,24122.36780,0.00000,0.04073,293.00178
124.80001,6.23993,24123.13521,0.00000,0.04085,293.01110
125.10001,6.25512,24127.78437,0.00000,0.04098,293.06757
125.40001,6.26988,24128.60096,0.00000,0.04109,293.07749
125.70001,6.28495,24132.30240,0.00000,0.04122,293.12245
126.00001,6.29996,24139.02581,0.00000,0.04135,293.20412
126.30001,6.31491,24141.47854,0.00000,0.04148,293.23391
126.60001,6.33003,24146.68351,0.00000,0.04160,293.29713
126.90001,6.34498,24147.56566,0.00000,0.04172,293.30785
127.20001,6.36005,24153.45609,0.00000,0.04184,293.37939
127.50001,6.37499,24154.21456,0.00000,0.04196,293.38861
127.80001,6.39012,24162.32228,0.00000,0.04208,293.48709
128.10001,6.40495,24161.87376,0.00000,0.04220,293.48164
128.40001,6.42008,24168.58524,0.00000,0.04232,293.56316
128.70001,6.43496,24171.08715,0.00000,0.04245,293.59355
129.00001,6.45003,24172.14662,0.00000,0.04257,293.60642
129.30001,6.46504,24179.67319,0.00000,0.04269,293.69784
129.60001,6.47987,24178.55114,0.00000,0.04282,293.68421
129.90001,6.49511,24187.05076,0.00000,0.04294,293.78745
130.20001,6.50988,24187.54548,0.00000,0.04306,293.79346
130.50001,6.52501,24191.85340,0.00000,0.04318,293.84579
130.80001,6.54001,24196.44445,0.00000,0.04330,293.90155
131.10001,6.55502,24198.91357,0.00000,0.04342,293.93154
131.40001,6.57003,24204.64307,0.00000,0.04355,294.00114
131.70001,6.58492,24206.26134,0.00000,0.04367,294.02079
132.00001,6.60010,24211.80457,0.00000,0.04379,294.08812
132.30001,6.61499,24212.73440,0.00000,0.04390,294.09942
132.60001,6.63006,24218.07498,0.00000,0.04403,294.16429
132.90001,6.64494,24220.31164,0.00000,0.04415,294.19145
133.20001,6.66013,24223.98329,0.00000,0.04428,294.23605
133.50001,6.67490,24227.04250,0.00000,0.04440,294.27321
133.80001,6.68997,24228.90216,0.00000,0.04453,294.29580
134.10001,6.70503,24236.16350,0.00000,0.04465,294.38400
134.40001,6.71986,24234.87902,0.00000,0.04477,294.36840
134.70001,6.73517,24240.24791,0.00000,0.04488,294.43361
135.00001,6.74987,24242.99419,0.00000,0.04500,294.46697
135.30001,6.76500,24246.97131,0.00000,0.04512,294.51527
135.60001,6.78001,24250.28086,0.00000,0.04524,294.55547
135.90001,6.79502,24252.54285,0.00000,0.04536,294.58295
136.20001,6.81002,24256.62428,0.00000,0.04548,294.63252
136.50001,6.82503,24258.52269,0.00000,0.04561,294.65558
136.80001,6.84010,24263.04668,0.00000,0.04574,294.71053
137.10001,6.85498,24265.08963,0.00000,0.04585,294.73535
137.40001,6.87011,24268.33659,0.00000,0.04597,294.77479
137.70001,6.88494,24269.38117,0.00000,0.04609,294.78748
138.00001,6.90013,24273.43279,0.00000,0.04621,294.83669
138.30001,6.91495,24276.36087,0.00000,0.04632,294.87225
138.60001,6.93002,24278.54240,0.00000,0.04644,294.89875
138.90001,6.94509,24284.39856,0.00000,0.04656,294.96988
139.20001,6.95986,24284.04689,0.00000,0.04668,294.96561
139.50001,6.97510,24289.02090,0.00000,0.04680,295.02603
139.80001,6.98999,24290.99530,0.00000,0.04692,295.05001
140.10001,7.00500,24294.52389,0.00000,0.04704,295.09287
140.40001,7.02000,24299.17157,0.00000,0.04716,295.14932
140.70001,7.03501,24301.89252,0.00000,0.04728,295.18237
141.00001,7.05002,24303.78646,0.00000,0.04739,295.20538
141.30001,7.06509,24304.72970,0.00000,0.04751,295.21684
141.60001,7.08003,24311.23853,0.00000,0.04763,295.29589
141.90001,7.09498,24309.33267,0.00000,0.04775,295.27275
142.20001,7.11005,24316.70427,0.00000,0.04786,295.36228
142.50001,7.12487,24315.69099,0.00000,0.04798,295.34998
142.80001,7.14006,24319.61596,0.00000,0.04810,295.39765
143.10001,7.15495,24323.15350,0.00000,0.04821,295.44062
143.40001,7.16996,24323.92538,0.00000,0.04832,295.45000
143.70001,7.18502,24330.61153,0.00000,0.04845,295.53121
144.00001,7.19985,24331.33870,0.00000,0.04856,295.54004
144.30001,7.21510,24336.47811,0.00000,0.04868,295.60247
144.60001,7.22992,24338.27519,0.00000,0.04880,295.62429
144.90001,7.24499,24340.92462,0.00000,0.04892,295.65648
145.20001,7.26006,24344.59776,0.00000,0.04904,295.70109
145.50001,7.27501,24346.24285,0.00000,0.04915,295.72107
145.80001,7.28995,24349.60753,0.00000,0.04927,295.76194
146.10001,7.30502,24351.79055,0.00000,0.04938,295.78846
146.40001,7.32003,24355.85260,0.00000,0.04950,295.83780
146.70001,7.33491,24352.09900,0.00000,0.04962,295.79221
147.00001,7.35010,24361.68790,0.00000,0.04974,295.90868
147.30001,7.36487,24359.90572,0.00000,0.04985,295.88703
147.60001,7.38012,24366.90927,0.00000,0.04997,295.97210
147.90001,7.39500,24370.03404,0.00000,0.05009,296.01005
148.20001,7.40995,24368.71231,0.00000,0.05021,295.99400
148.50001,7.42514,24375.96768,0.00000,0.05033,296.08213
148.80001,7.43991,24375.03636,0.00000,0.05044,296.07081
149.10001,7.45509,24379.13567,0.00000,0.05055,296.12061
149.40001,7.46998,24381.48111,0.00000,0.05068,296.14909
149.70001,7.48505,24384.92626,0.00000,0.05079,296.19094
150.00001,7.50005,24386.22564,0.00000,0.05091,296.20672
150.30001,7.51506,24388.59642,0.00000,0.05103,296.23552
150.60001,7.53001,24392.95352,0.00000,0.05115,296.28844
150.90001,7.54502,24393.50188,0.00000,0.05126,296.29510
151.20001,7.56002,24398.24790,0.00000,0.05138,296.35275
151.50001,7.57485,24396.86805,0.00000,0.05149,296.33599
151.80001,7.59004,24402.63182,0.00000,0.05161,296.40600
152.10001,7.60492,24403.79262,0.00000,0.05173,296.42010
152.40001,7.62005,24404.61814,0.00000,0.05185,296.43013
152.70001,7.63494,24410.59947,0.00000,0.05196,296.50278
153.00001,7.64995,24409.72179,0.00000,0.05208,296.49212
153.30001,7.66513,24416.19933,0.00000,0.05219,296.57080
153.60001,7.67990,24415.93558,0.00000,0.05230,296.56759
153.90001,7.69509,24419.25853,0.00000,0.05242,296.60796
154.20001,7.70997,24420.59070,0.00000,0.05254,296.62414
154.50001,7.72498,24423.16711,0.00000,0.05266,296.65543
154.80001,7.73999,24424.38304,0.00000,0.05277,296.67020
155.10001,7.75506,24426.97883,0.00000,0.05289,296.70173
155.40001,7.76994,24428.58368,0.00000,0.05300,296.72122
155.70001,7.78495,24428.64478,0.00000,0.05312,296.72197
156.00001,7.80008,24434.94499,0.00000,0.05323,296.79849
156.30001,7.81490,24433.58898,0.00000,0.05335,296.78202
156.60001,7.83003,24439.90409,0.00000,0.05346,296.85873
156.90001,7.84492,24441.27500,0.00000,0.05358,296.87538
157.20001,7.86005,24442.04241,0.00000,0.05369,296.88470
157.50001,7.87499,24445.57697,0.00000,0.05381,296.92763
157.80001,7.88994,24445.61124,0.00000,0.05393,296.92805
158.10001,7.90513,24450.60909,0.00000,0.05404,296.98876
158.40001,7.91995,24451.01291,0.00000,0.05415,296.99366
158.70001,7.93508,24451.99043,0.00000,0.05427,297.00553
159.00001,7.94997,24453.71747,0.00000,0.05438,297.02651
159.30001,7.96504,24457.51876,0.00000,0.05449,297.07268
159.60001,7.97998,24456.66641,0.00000,0.05460,297.06233
159.90001,7.99505,24461.55548,0.00000,0.05471,297.12172
160.20001,8.00994,24464.48356,0.00000,0.05483,297.15728
160.50001,8.02501,24464.14977,0.00000,0.05494,297.15323
160.80001,8.04007,24469.09100,0.00000,0.05505,297.21325
161.10001,8.05484,24466.35962,0.00000,0.05516,297.18007
161.40001,8.07003,24471.91924,0.00000,0.05528,297.24760
161.70001,8.08491,24476.04537,0.00000,0.05539,297.29772
162.00001,8.09998,24475.90530,0.00000,0.05550,297.29602
162.30001,8.11499,24478.95855,0.00000,0.05561,297.33310
162.60001,8.12994,24478.32525,0.00000,0.05572,297.32541
162.90001,8.14518,24483.92361,0.00000,0.05584,297.39341
163.20001,8.15995,24481.57817,0.00000,0.05595,297.36492
163.50001,8.17502,24486.17369,0.00000,0.05605,297.42074
163.80001,8.18996,24487.39707,0.00000,0.05616,297.43560
164.10001,8.20503,24489.79914,0.00000,0.05627,297.46478
164.40001,8.21998,24490.15826,0.00000,0.05638,297.46914
164.70001,8.23493,24491.28181,0.00000,0.05649,297.48279
165.00001,8.24999,24496.86378,0.00000,0.05660,297.55059
165.30001,8.26500,24496.62238,0.00000,0.05671,297.54766
165.60001,8.28007,24502.57838,0.00000,0.05682,297.62000
165.90001,8.29490,24502.51728,0.00000,0.05693,297.61926
166.20001,8.31008,24506.77902,0.00000,0.05704,297.67102
166.50001,8.32497,24508.20804,0.00000,0.05715,297.68838
166.80001,8.34010,24509.23175,0.00000,0.05725,297.70081
167.10001,8.35504,24513.94945,0.00000,0.05736,297.75812
167.40001,8.36999,24513.29827,0.00000,0.05747,297.75021
167.70001,8.38512,24515.93876,0.00000,0.05758,297.78228
168.00001,8.39994,24515.75547,0.00000,0.05769,297.78005
168.30001,8.41507,24519.21105,0.00000,0.05780,297.82203
168.60001,8.42996,24519.12463,0.00000,0.05791,297.82098
168.90001,8.44503,24522.39394,0.00000,0.05803,297.86069
169.20001,8.45997,24523.77677,0.00000,0.05814,297.87749
169.50001,8.47504,24526.38745,0.00000,0.05825,297.90920
169.80001,8.49005,24531.20947,0.00000,0.05836,297.96777
170.10001,8.50500,24528.43040,0.00000,0.05847,297.93401
170.40001,8.52012,24534.63227,0.00000,0.05858,298.00934
170.70001,8.53483,24532.79197,0.00000,0.05869,297.98699
171.00001,8.55008,24537.89115,0.00000,0.05880,298.04893
171.30001,8.56490,24538.36054,0.00000,0.05891,298.05463
171.60001,8.58003,24538.91188,0.00000,0.05902,298.06132
171.90001,8.59510,24542.93072,0.00000,0.05913,298.11014
172.20001,8.60993,24539.31868,0.00000,0.05924,298.06626
172.50001,8.62511,24546.63068,0.00000,0.05935,298.15508
172.80001,8.64000,24544.84999,0.00000,0.05946,298.13345
173.10001,8.65507,24547.36382,0.00000,0.05957,298.16398
173.40001,8.67001,24547.86152,0.00000,0.05968,298.17003
173.70001,8.68508,24551.31859,0.00000,0.05979,298.21202
174.00001,8.69997,24552.71930,0.00000,0.05990,298.22904
174.30001,8.71498,24553.49714,0.00000,0.06001,298.23848
174.60001,8.72998,24558.55608,0.00000,0.06012,298.29993
174.90001,8.74505,24556.92142,0.00000,0.06022,298.28008
175.20001,8.76006,24558.68721,0.00000,0.06033,298.30152
175.50001,8.77483,24559.61704,0.00000,0.06044,298.31282
175.80001,8.79007,24563.17693,0.00000,0.06055,298.35606
176.10001,8.80496,24564.55231,0.00000,0.06066,298.37276
176.40001,8.82003,24565.01722,0.00000,0.06077,298.37841
176.70001,8.83503,24567.85589,0.00000,0.06088,298.41289
177.00001,8.84998,24566.97524,0.00000,0.06099,298.40219
177.30001,8.86505,24569.63062,0.00000,0.06111,298.43445
177.60001,8.87987,24569.72599,0.00000,0.06121,298.43561
177.90001,8.89500,24574.44072,0.00000,0.06132,298.49287
178.20001,8.91001,24574.93842,0.00000,0.06143,298.49892
178.50001,8.92502,24577.78305,0.00000,0.06154,298.53347
178.80001,8.93996,24579.28360,0.00000,0.06164,298.55170
179.10001,8.95497,24577.72344,0.00000,0.06176,298.53275
179.40001,8.97004,24583.70626,0.00000,0.06187,298.60542
179.70001,8.98499,24582.00008,0.00000,0.06198,298.58469
180.00001,9.00005,24585.67321,0.00000,0.06209,298.62931
180.30001,9.01488,24583.97150,0.00000,0.06220,298.60864
180.60001,9.03013,24586.38996,0.00000,0.06231,298.63802
180.90001,9.04495,24586.62987,0.00000,0.06242,298.64093
181.20001,9.05996,24586.87425,0.00000,0.06253,298.64390
181.50001,9.07503,24590.39390,0.00000,0.06264,298.68665
181.80001,9.08992,24590.79027,0.00000,0.06274,298.69146
182.10001,9.10510,24592.49496,0.00000,0.06285,298.71217
182.40001,9.11993,24591.34161,0.00000,0.06295,298.69816
182.70001,9.13506,24595.47967,0.00000,0.06305,298.74842
183.00001,9.14994,24595.61229,0.00000,0.06316,298.75003
183.30001,9.16501,24598.43457,0.00000,0.06326,298.78431
183.60001,9.17996,24598.87564,0.00000,0.06336,298.78967
183.90001,9.19503,24599.55215,0.00000,0.06346,298.79789
184.20001,9.21003,24602.70077,0.00000,0.06357,298.83613
184.50001,9.22498,24600.56692,0.00000,0.06367,298.81022
184.80001,9.24017,24605.88813,0.00000,0.06379,298.87485
185.10001,9.25494,24603.99568,0.00000,0.06389,298.85186
185.40001,9.27012,24606.27407,0.00000,0.06400,298.87954
185.70001,9.28501,24607.39911,0.00000,0.06411,298.89320
186.00001,9.29996,24605.34126,0.00000,0.06422,298.86821
186.30001,9.31508,24610.97986,0.00000,0.06433,298.93670
186.60001,9.32985,24609.92634,0.00000,0.06444,298.92390
186.90001,9.34504,24614.13592,0.00000,0.06455,298.97503
187.20001,9.35993,24613.90048,0.00000,0.06465,298.97217
187.50001,9.37499,24616.01198,0.00000,0.06476,298.99782
187.80001,9.39000,24616.09691,0.00000,0.06487,298.99885
188.10001,9.40501,24616.82260,0.00000,0.06498,299.00766
188.40001,9.42001,24620.44209,0.00000,0.06509,299.05163
188.70001,9.43502,24619.71492,0.00000,0.06521,299.04280
189.00001,9.45009,24624.49968,0.00000,0.06532,299.10091
189.30001,9.46498,24619.73727,0.00000,0.06542,299.04307
189.60001,9.48004,24623.13622,0.00000,0.06553,299.08435
189.90001,9.49487,24622.30176,0.00000,0.06564,299.07422
190.20001,9.51012,24625.69922,0.00000,0.06575,299.11548
190.50001,9.52494,24626.73932,0.00000,0.06586,299.12812
190.80001,9.53995,24627.03735,0.00000,0.06597,299.13174
191.10001,9.55508,24631.27375,0.00000,0.06608,299.18319
191.40001,9.56997,24629.98182,0.00000,0.06619,299.16750
191.70001,9.58509,24632.04563,0.00000,0.06631,299.19257
192.00001,9.59992,24632.26020,0.00000,0.06642,299.19518
192.30001,9.61499,24635.89758,0.00000,0.06653,299.23936
192.60001,9.62999,24635.38796,0.00000,0.06664,299.23317
192.90001,9.64506,24634.73976,0.00000,0.06674,299.22529
193.20001,9.66001,24635.77688,0.00000,0.06686,299.23789
193.50001,9.67508,24634.78446,0.00000,0.06696,299.22584
193.80001,9.69008,24640.10119,0.00000,0.06708,299.29042
194.10001,9.70491,24636.38932,0.00000,0.06718,299.24533
194.40001,9.72010,24641.99066,0.00000,0.06729,299.31337
194.70001,9.73493,24640.46329,0.00000,0.06740,299.29482
195.00001,9.75011,24641.26498,0.00000,0.06751,299.30455
195.30001,9.76500,24641.90125,0.00000,0.06762,299.31228
195.60001,9.77995,24641.57492,0.00000,0.06772,299.30832
195.90001,9.79507,24646.40141,0.00000,0.06783,299.36694
196.20001,9.80996,24644.54323,0.00000,0.06794,299.34437
196.50001,9.82497,24643.55975,0.00000,0.06805,299.33243
196.80001,9.83997,24645.44177,0.00000,0.06815,299.35529
197.10001,9.85498,24646.60853,0.00000,0.06826,299.36946
197.40001,9.86993,24647.57562,0.00000,0.06837,299.38121
197.70001,9.88506,24649.04487,0.00000,0.06848,299.39905
198.00001,9.90000,24651.63171,0.00000,0.06859,299.43047
198.30001,9.91507,24647.88109,0.00000,0.06869,299.38492
198.60001,9.93008,24650.54244,0.00000,0.06879,299.41724
198.90001,9.94497,24648.05543,0.00000,0.06890,299.38703
199.20001,9.96009,24653.28127,0.00000,0.06901,299.45051
199.50001,9.97486,24653.77897,0.00000,0.06911,299.45655
199.80001,9.99005,24652.99517,0.00000,0.06923,299.44703
200.10001,10.00499,24655.86513,0.00000,0.06933,299.48189
200.40001,10.01994,24654.49721,0.00000,0.06944,299.46528
200.70001,10.03513,24657.30458,0.00000,0.06955,299.49938
201.00001,10.04990,24656.22872,0.00000,0.06966,299.48631
201.30001,10.06502,24658.85133,0.00000,0.06976,299.51817
201.60001,10.07997,24660.56645,0.00000,0.06987,299.53900
201.90001,10.09504,24661.04478,0.00000,0.06997,299.54481
202.20001,10.10998,24660.39211,0.00000,0.07008,299.53688
202.50001,10.12505,24660.42340,0.00000,0.07019,299.53726
202.80001,10.14000,24662.14150,0.00000,0.07030,299.55813
203.10001,10.15501,24660.77805,0.00000,0.07041,299.54157
203.40001,10.17007,24663.71804,0.00000,0.07052,299.57728
203.70001,10.18490,24660.42936,0.00000,0.07063,299.53733
204.00001,10.20015,24665.54195,0.00000,0.07074,299.59943
204.30001,10.21485,24665.64775,0.00000,0.07085,299.60072
204.60001,10.23004,24667.27793,0.00000,0.07096,299.62052
204.90001,10.24499,24669.18826,0.00000,0.07106,299.64372
205.20001,10.25988,24667.65195,0.00000,0.07117,299.62506
205.50001,10.27512,24669.06458,0.00000,0.07128,299.64222
205.80001,10.28989,24668.63096,0.00000,0.07139,299.63695
206.10001,10.30496,24669.66361,0.00000,0.07150,299.64950
206.40001,10.31996,24668.63096,0.00000,0.07160,299.63695
206.70001,10.33503,24673.26671,0.00000,0.07171,299.69326
207.00001,10.34992,24668.96772,0.00000,0.07182,299.64104
207.30001,10.36505,24670.73351,0.00000,0.07193,299.66249
207.60001,10.37999,24673.54238,0.00000,0.07203,299.69661
207.90001,10.39506,24671.29976,0.00000,0.07215,299.66937
208.20001,10.41007,24675.08912,0.00000,0.07225,299.71540
208.50001,10.42483,24670.75735,0.00000,0.07236,299.66278
208.80001,10.44014,24675.62109,0.00000,0.07247,299.72186
209.10001,10.45491,24674.03859,0.00000,0.07258,299.70264
209.40001,10.46998,24672.00458,0.00000,0.07268,299.67793
209.70001,10.48498,24675.04442,0.00000,0.07279,299.71485
210.00001,10.49993,24674.68530,0.00000,0.07289,299.71049
210.30001,10.51512,24677.29896,0.00000,0.07299,299.74224
210.60001,10.52995,24674.54076,0.00000,0.07309,299.70874
210.90001,10.54507,24674.54672,0.00000,0.07320,299.70881
211.20001,10.56002,24674.01773,0.00000,0.07330,299.70238
211.50001,10.57503,24675.93998,0.00000,0.07340,299.72573
211.80001,10.58991,24675.46612,0.00000,0.07351,299.71998
212.10001,10.60510,24677.64169,0.00000,0.07361,299.74640
212.40001,10.61999,24679.08561,0.00000,0.07371,299.76394
212.70001,10.63494,24675.37373,0.00000,0.07381,299.71885
213.00001,10.65006,24680.30304,0.00000,0.07391,299.77873
213.30001,10.66489,24677.77282,0.00000,0.07402,299.74799
213.60001,10.68014,24681.29843,0.00000,0.07412,299.79082
213.90001,10.69490,24680.53699,0.00000,0.07422,299.78157
214.20001,10.70997,24678.97981,0.00000,0.07432,299.76266
214.50001,10.72504,24681.64265,0.00000,0.07443,299.79500
214.80001,10.73993,24679.54755,0.00000,0.07453,299.76955
215.10001,10.75505,24681.56517,0.00000,0.07463,299.79406
215.40001,10.76988,24682.11204,0.00000,0.07474,299.80070
215.70001,10.78501,24681.63371,0.00000,0.07484,299.79489
216.00001,10.80001,24680.34625,0.00000,0.07494,299.77925
216.30001,10.81508,24681.14346,0.00000,0.07504,299.78894
216.60001,10.82991,24680.26280,0.00000,0.07514,299.77824
216.90001,10.84504,24681.07343,0.00000,0.07524,299.78809
217.20001,10.85998,24685.64659,0.00000,0.07534,299.84363
217.50001,10.87493,24681.55473,0.00000,0.07544,299.79393
217.80001,10.89012,24685.06098,0.00000,0.07554,299.83652
218.10001,10.90489,24681.57709,0.00000,0.07564,299.79420
218.40001,10.92001,24682.41304,0.00000,0.07574,299.80436
218.70001,10.93496,24683.67964,0.00000,0.07584,299.81974
219.00001,10.95003,24682.43688,0.00000,0.07593,299.80465
219.30001,10.96509,24684.84938,0.00000,0.07603,299.83395
219.60001,10.97998,24680.31645,0.00000,0.07613,299.77889
219.90001,10.99517,24683.74968,0.00000,0.07623,299.82059
220.20001,11.01000,24680.92591,0.00000,0.07633,299.78629
220.50001,11.02506,24682.33705,0.00000,0.07643,299.80343
220.80001,11.04001,24682.09267,0.00000,0.07652,299.80047
221.10001,11.05502,24682.54715,0.00000,0.07662,299.80599
221.40001,11.06991,24681.78272,0.00000,0.07672,299.79670
221.70001,11.08503,24681.06747,0.00000,0.07682,299.78801
222.00001,11.10004,24683.28923,0.00000,0.07691,299.81500
222.30001,11.11487,24677.98740,0.00000,0.07701,299.75060
222.60001,11.13005,24682.11055,0.00000,0.07711,299.80068
222.90001,11.14488,24679.83812,0.00000,0.07720,299.77308
223.20001,11.16007,24680.50122,0.00000,0.07729,299.78114
223.50001,11.17502,24680.84544,0.00000,0.07739,299.78532
223.80001,11.19002,24678.03359,0.00000,0.07748,299.75116
224.10001,11.20509,24679.97521,0.00000,0.07758,299.77475
224.40001,11.21998,24676.89663,0.00000,0.07767,299.73735
224.70001,11.23504,24677.33622,0.00000,0.07777,299.74269
225.00001,11.24993,24675.75967,0.00000,0.07786,299.72354
225.30001,11.26506,24677.84733,0.00000,0.07795,299.74890
225.60001,11.28000,24675.79693,0.00000,0.07803,299.72399
225.90001,11.29507,24677.75047,0.00000,0.07812,299.74772
226.20001,11.30990,24677.11270,0.00000,0.07821,299.73998
226.50001,11.32509,24675.31562,0.00000,0.07830,299.71815
226.80001,11.34009,24677.33324,0.00000,0.07839,299.74266
227.10001,11.35492,24671.64397,0.00000,0.07847,299.67355
227.40001,11.37005,24674.20548,0.00000,0.07856,299.70466
227.70001,11.38487,24670.87209,0.00000,0.07865,299.66418
228.00001,11.40006,24671.78255,0.00000,0.07873,299.67523
228.30001,11.41495,24671.00769,0.00000,0.07882,299.66582
228.60001,11.43002,24668.22118,0.00000,0.07890,299.63198
228.90001,11.44508,24668.46555,0.00000,0.07898,299.63494
229.20001,11.45997,24666.31532,0.00000,0.07906,299.60883
229.50001,11.47510,24668.13326,0.00000,0.07914,299.63091
229.80001,11.48999,24664.77305,0.00000,0.07921,299.59009
230.10001,11.50505,24667.29432,0.00000,0.07929,299.62072
230.40001,11.51994,24661.91798,0.00000,0.07937,299.55541
230.70001,11.53513,24663.22184,0.00000,0.07945,299.57125
231.00001,11.54989,24661.25339,0.00000,0.07952,299.54734
231.30001,11.56502,24658.50860,0.00000,0.07960,299.51400
231.60001,11.58003,24661.45754,0.00000,0.07967,299.54982
231.90001,11.59486,24655.27207,0.00000,0.07975,299.47469
232.20001,11.61010,24655.99030,0.00000,0.07983,299.48341
232.50001,11.62493,24651.78370,0.00000,0.07990,299.43232
232.80001,11.64006,24652.16666,0.00000,0.07997,299.43697
233.10001,11.65500,24650.02239,0.00000,0.08004,299.41092
233.40001,11.67001,24648.67979,0.00000,0.08012,299.39462
233.70001,11.68502,24648.08822,0.00000,0.08019,299.38743
234.00001,11.69997,24643.58360,0.00000,0.08026,299.33272
234.30001,11.71509,24642.75062,0.00000,0.08033,299.32260
234.60001,11.72998,24639.26226,0.00000,0.08041,299.28023
234.90001,11.74505,24639.66012,0.00000,0.08047,299.28506
235.20001,11.76000,24635.49078,0.00000,0.08054,299.23442
235.50001,11.77506,24631.86383,0.00000,0.08061,299.19036
235.80001,11.78989,24630.90122,0.00000,0.08068,299.17867
236.10001,11.80502,24626.29974,0.00000,0.08075,299.12278
236.40001,11.82002,24626.51879,0.00000,0.08081,299.12544
236.70001,11.83485,24620.54491,0.00000,0.08087,299.05288
237.00001,11.85010,24618.78955,0.00000,0.08093,299.03156
237.30001,11.86493,24613.46239,0.00000,0.08099,298.96685
237.60001,11.88005,24607.95790,0.00000,0.08105,298.89999
237.90001,11.89494,24604.54106,0.00000,0.08110,298.85849
238.20001,11.91001,24600.65633,0.00000,0.08115,298.81130
238.50001,11.92507,24599.12896,0.00000,0.08121,298.79275
238.80001,11.93996,24593.34880,0.00000,0.08126,298.72254
239.10001,11.95503,24589.66821,0.00000,0.08131,298.67783
239.40001,11.96998,24580.53678,0.00000,0.08136,298.56692
239.70001,11.98504,24576.66993,0.00000,0.08140,298.51995
240.00001,11.99993,24567.58469,0.00000,0.08145,298.40960
240.30001,12.01500,24562.29180,0.00000,0.08149,298.34531
240.60001,12.02994,24556.04821,0.00000,0.08154,298.26947
240.90001,12.04495,24543.06334,0.00000,0.08158,298.11175
241.20001,12.06008,24541.23199,0.00000,0.08162,298.08950
241.50001,12.07491,24526.30848,0.00000,0.08165,297.90824
241.80001,12.09015,24520.48957,0.00000,0.08169,297.83756
242.10001,12.10492,24510.40000,0.00000,0.08172,297.71500
242.40001,12.11999,24497.27654,0.00000,0.08175,297.55560
242.70001,12.13505,24488.40737,0.00000,0.08178,297.44787
243.00001,12.15000,24472.56297,0.00000,0.08181,297.25542
243.30001,12.16501,24462.95917,0.00000,0.08184,297.13877
243.60001,12.17996,24445.29384,0.00000,0.08186,296.92419
243.90001,12.19502,24432.90949,0.00000,0.08188,296.77377
244.20001,12.20991,24413.73020,0.00000,0.08190,296.54081
244.50001,12.22504,24397.06326,0.00000,0.08192,296.33836
244.80001,12.23993,24375.94086,0.00000,0.08193,296.08180
245.10001,12.25505,24355.38322,0.00000,0.08195,295.83210
245.40001,12.27000,24333.50235,0.00000,0.08196,295.56632
245.70001,12.28501,24307.49536,0.00000,0.08197,295.25043
246.00001,12.30007,24287.15676,0.00000,0.08198,295.00339
246.30001,12.31484,24254.50087,0.00000,0.08199,294.60673
246.60001,12.33015,24230.50255,0.00000,0.08199,294.31524
246.90001,12.34492,24197.85261,0.00000,0.08200,293.91866
247.20001,12.36004,24164.08807,0.00000,0.08200,293.50853
247.50001,12.37499,24126.69361,0.00000,0.08200,293.05432
247.80001,12.39000,24085.65730,0.00000,0.08200,292.55588
248.10001,12.40500,24042.86712,0.00000,0.08199,292.03613
248.40001,12.41995,23998.63452,0.00000,0.08199,291.49886
248.70001,12.43508,23958.75007,0.00000,0.08199,291.01440
249.00001,12.44997,23907.62419,0.00000,0.08198,290.39340
249.30001,12.46503,23857.35810,0.00000,0.08198,289.78285
249.60001,12.47992,23791.51434,0.00000,0.08196,288.98308
249.90001,12.49505,23718.39732,0.00000,0.08195,288.09496
250.20001,12.51000,23646.36958,0.00000,0.08194,287.22008
250.50001,12.52506,23568.42011,0.00000,0.08193,286.27327
250.80001,12.54013,23479.30968,0.00000,0.08191,285.19089
251.10001,12.55490,23344.58679,0.00000,0.08188,283.55448
251.40001,12.57020,23033.96761,0.00000,0.08182,279.78155
251.70001,12.58503,22504.47571,0.00000,0.08171,273.35009
251.78801,12.58969,21607.35577,0.00000,0.08135,262.45325
251.79401,12.59017,19736.20653,0.00000,0.07756,239.72537
251.80001,12.59101,16462.12041,0.00000,0.07204,199.95676
251.80601,12.59209,12726.53639,0.00000,0.06733,154.58258