File: scratch/college-stuff/ME Lab/ME lab Fall 2013/group14/group14.is_tens_RawData/Specimen_RawData_1.csv
Time,Extension,Load,Strain 2,Tensile strain,Tensile stress
(sec),(mm),(N),(mm/mm),(mm/mm),(MPa)
0.00000,0.00000,-0.20478,0.00000,0.00000,-0.00252
0.10000,0.00149,3.16502,0.00000,0.00000,0.03891
0.20000,0.00700,14.06971,0.00000,0.00000,0.17297
0.30000,0.01345,19.90231,0.00000,0.00000,0.24468
0.40000,0.01937,25.36886,0.00000,0.00000,0.31188
0.50000,0.02469,37.14855,0.00000,0.00000,0.45670
0.60000,0.02989,49.97978,0.00000,0.00000,0.61444
0.70000,0.03498,60.71458,0.00000,0.00000,0.74642
0.80000,0.04006,67.90478,0.00000,0.00000,0.83481
0.90000,0.04508,75.56131,0.00000,-0.00001,0.92894
1.00000,0.04998,82.11200,0.00000,-0.00001,1.00947
1.10000,0.05501,90.76960,0.00000,-0.00001,1.11591
1.20000,0.05997,98.72147,0.00000,-0.00001,1.21367
1.30000,0.06505,107.01453,0.00000,-0.00001,1.31562
1.40000,0.06995,115.52264,0.00000,-0.00001,1.42022
1.50000,0.07504,123.99118,0.00000,-0.00001,1.52433
1.60000,0.07994,132.11035,0.00000,-0.00001,1.62415
1.70000,0.08514,143.33293,0.00000,-0.00002,1.76212
1.80000,0.08998,153.98201,0.00000,-0.00002,1.89303
1.90000,0.09513,165.06010,0.00000,-0.00002,2.02923
2.00000,0.09997,174.72941,0.00000,-0.00001,2.14810
2.10000,0.10511,186.88687,0.00000,-0.00002,2.29756
2.20000,0.10995,197.42965,0.00000,-0.00001,2.42717
2.30000,0.11509,208.86122,0.00000,-0.00002,2.56771
2.40000,0.11994,218.38730,0.00000,-0.00002,2.68482
2.50000,0.12502,228.25697,0.00000,-0.00002,2.80616
2.60000,0.12998,238.33953,0.00000,-0.00002,2.93011
2.70000,0.13506,249.22823,0.00000,-0.00002,3.06398
2.80000,0.13997,260.57481,0.00000,-0.00002,3.20347
2.90000,0.14499,273.16690,0.00000,-0.00003,3.35828
3.00000,0.14995,287.34114,0.00000,-0.00003,3.53253
3.10000,0.15497,300.82620,0.00000,-0.00003,3.69832
3.20000,0.16006,316.74001,0.00000,-0.00003,3.89396
3.30000,0.16496,332.44495,0.00000,-0.00003,4.08703
3.40000,0.16998,350.26709,0.00000,-0.00003,4.30614
3.50000,0.17494,367.05388,0.00000,-0.00003,4.51251
3.60000,0.18009,386.59961,0.00000,-0.00003,4.75280
3.70000,0.18499,406.09962,0.00000,-0.00003,4.99253
3.80000,0.19007,429.25808,0.00000,-0.00003,5.27724
3.90000,0.19491,451.58616,0.00000,-0.00003,5.55174
4.00000,0.20012,477.16121,0.00000,-0.00003,5.86615
4.10000,0.20496,500.41904,0.00000,-0.00003,6.15208
4.20000,0.21010,528.35988,0.00000,-0.00003,6.49558
4.30000,0.21494,555.76204,0.00000,-0.00002,6.83246
4.40000,0.22009,586.66966,0.00000,-0.00003,7.21244
4.50000,0.22499,617.03278,0.00000,-0.00002,7.58572
4.60000,0.23007,648.57076,0.00000,-0.00002,7.97344
4.70000,0.23497,680.81822,0.00000,-0.00002,8.36989
4.80000,0.24000,717.12723,0.00000,-0.00002,8.81626
4.90000,0.24490,756.82933,0.00000,-0.00002,9.30436
5.00000,0.25004,796.56430,0.00000,-0.00002,9.79285
5.10000,0.25500,838.12280,0.00000,-0.00001,10.30377
5.20000,0.26002,879.56451,0.00000,-0.00001,10.81325
5.30000,0.26499,925.57082,0.00000,-0.00001,11.37884
5.40000,0.27001,971.59231,0.00000,0.00000,11.94462
5.50000,0.27503,1019.83268,0.00000,0.00001,12.53768
5.60000,0.27999,1065.01235,0.00000,0.00001,13.09312
5.70000,0.28502,1114.61245,0.00000,0.00002,13.70289
5.80000,0.28992,1163.06227,0.00000,0.00002,14.29853
5.90000,0.29506,1218.97124,0.00000,0.00003,14.98586
6.00000,0.29996,1271.84885,0.00000,0.00003,15.63594
6.10000,0.30511,1332.51334,0.00000,0.00004,16.38174
6.20000,0.30995,1389.32122,0.00000,0.00005,17.08012
6.30000,0.31503,1450.12056,0.00000,0.00006,17.82758
6.40000,0.31987,1507.00826,0.00000,0.00007,18.52695
6.50000,0.32514,1572.57728,0.00000,0.00008,19.33305
6.60000,0.32992,1634.35731,0.00000,0.00009,20.09256
6.70000,0.33500,1701.24955,0.00000,0.00010,20.91493
6.80000,0.33984,1765.60786,0.00000,0.00010,21.70614
6.90000,0.34499,1834.98170,0.00000,0.00012,22.55901
7.00000,0.34995,1903.72020,0.00000,0.00013,23.40407
7.10000,0.35503,1972.51607,0.00000,0.00014,24.24984
7.20000,0.35993,2043.95354,0.00000,0.00015,25.12808
7.30000,0.36496,2111.61748,0.00000,0.00016,25.95994
7.40000,0.36992,2182.13201,0.00000,0.00018,26.82683
7.50000,0.37500,2249.47780,0.00000,0.00019,27.65477
7.60000,0.37996,2316.47901,0.00000,0.00020,28.47847
7.70000,0.38492,2380.93585,0.00000,0.00021,29.27090
7.80000,0.38995,2450.34993,0.00000,0.00022,30.12427
7.90000,0.39491,2513.91344,0.00000,0.00023,30.90571
8.00000,0.39999,2584.78690,0.00000,0.00024,31.77702
8.10000,0.40489,2652.90160,0.00000,0.00025,32.61441
8.20000,0.40998,2725.21209,0.00000,0.00026,33.50338
8.30000,0.41488,2793.64269,0.00000,0.00028,34.34466
8.40000,0.42008,2867.84954,0.00000,0.00029,35.25695
8.50000,0.42492,2935.27748,0.00000,0.00030,36.08590
8.60000,0.43007,3010.66414,0.00000,0.00031,37.01269
8.70000,0.43491,3080.31999,0.00000,0.00033,37.86903
8.80000,0.43999,3152.81004,0.00000,0.00034,38.76021
8.90000,0.44483,3221.76218,0.00000,0.00035,39.60790
9.00000,0.45004,3295.84926,0.00000,0.00036,40.51872
9.10000,0.45488,3366.23527,0.00000,0.00038,41.38403
9.20000,0.45996,3438.73687,0.00000,0.00039,42.27536
9.30000,0.46492,3507.83616,0.00000,0.00040,43.12486
9.40000,0.47006,3580.17758,0.00000,0.00042,44.01421
9.50000,0.47497,3651.85030,0.00000,0.00042,44.89535
9.60000,0.47999,3724.11795,0.00000,0.00044,45.78379
9.70000,0.48489,3794.26442,0.00000,0.00045,46.64617
9.80000,0.48997,3866.83010,0.00000,0.00046,47.53828
9.90000,0.49494,3938.37765,0.00000,0.00048,48.41787
10.00000,0.49996,4008.25329,0.00000,0.00048,49.27692
10.10000,0.50492,4083.27729,0.00000,0.00050,50.19925
10.20000,0.50994,4151.85578,0.00000,0.00051,51.04234
10.30000,0.51503,4226.49793,0.00000,0.00053,51.95999
10.40000,0.51999,4296.83924,0.00000,0.00054,52.82475
10.50000,0.52501,4371.54099,0.00000,0.00055,53.74312
10.60000,0.52991,4440.89547,0.00000,0.00057,54.59576
10.70000,0.53500,4515.23177,0.00000,0.00058,55.50964
10.80000,0.53990,4581.95433,0.00000,0.00059,56.32992
10.90000,0.54504,4657.73791,0.00000,0.00061,57.26159
11.00000,0.54982,4726.22402,0.00000,0.00061,58.10355
11.10000,0.55503,4799.26616,0.00000,0.00063,59.00152
11.20000,0.55987,4866.06658,0.00000,0.00064,59.82275
11.30000,0.56507,4941.48545,0.00000,0.00066,60.74994
11.40000,0.56991,5008.29592,0.00000,0.00067,61.57130
11.50000,0.57506,5081.72438,0.00000,0.00068,62.47402
11.60000,0.57990,5148.28376,0.00000,0.00070,63.29229
11.70000,0.58504,5218.68505,0.00000,0.00071,64.15780
11.80000,0.58988,5287.01656,0.00000,0.00072,64.99786
11.90000,0.59497,5356.64633,0.00000,0.00074,65.85387
12.00000,0.59987,5424.81802,0.00000,0.00075,66.69197
12.10000,0.60489,5492.33295,0.00000,0.00076,67.52199
12.20000,0.60991,5564.52870,0.00000,0.00077,68.40955
12.30000,0.61493,5628.53254,0.00000,0.00079,69.19641
12.40000,0.61996,5698.38360,0.00000,0.00080,70.05515
12.50000,0.62492,5763.11238,0.00000,0.00081,70.85091
12.60000,0.63000,5834.60107,0.00000,0.00083,71.72978
12.70000,0.63496,5897.67508,0.00000,0.00083,72.50521
12.80000,0.64005,5968.14714,0.00000,0.00085,73.37158
12.90000,0.64489,6026.80743,0.00000,0.00086,74.09274
13.00000,0.65003,6096.04269,0.00000,0.00087,74.94391
13.10000,0.65493,6159.09435,0.00000,0.00089,75.71906
13.20000,0.66002,6223.38131,0.00000,0.00090,76.50940
13.30000,0.66492,6283.83607,0.00000,0.00091,77.25262
13.40000,0.67006,6351.46573,0.00000,0.00092,78.08405
13.50000,0.67484,6410.80961,0.00000,0.00093,78.81361
13.60000,0.68005,6475.35771,0.00000,0.00095,79.60716
13.70000,0.68495,6535.79012,0.00000,0.00096,80.35011
13.80000,0.69009,6599.01202,0.00000,0.00097,81.12735
13.90000,0.69493,6658.49820,0.00000,0.00098,81.85866
14.00000,0.70002,6717.85101,0.00000,0.00099,82.58834
14.10000,0.70498,6776.41705,0.00000,0.00100,83.30834
14.20000,0.71006,6834.36096,0.00000,0.00102,84.02069
14.30000,0.71490,6888.16234,0.00000,0.00103,84.68212
14.40000,0.72004,6945.13097,0.00000,0.00104,85.38249
14.50000,0.72489,6992.77371,0.00000,0.00105,85.96820
14.60000,0.73003,7039.21318,0.00000,0.00105,86.53912
14.70000,0.73499,7081.34398,0.00000,0.00106,87.05707
14.80000,0.74001,7124.64899,0.00000,0.00107,87.58946
14.90000,0.74498,7170.67420,0.00000,0.00108,88.15528
15.00000,0.75000,7211.65687,0.00000,0.00109,88.65912
15.10000,0.75502,7256.91915,0.00000,0.00110,89.21557
15.20000,0.75998,7296.97868,0.00000,0.00110,89.70805
15.30000,0.76501,7346.31419,0.00000,0.00112,90.31458
15.40000,0.76991,7388.09928,0.00000,0.00112,90.82828
15.50000,0.77505,7435.24283,0.00000,0.00113,91.40785
15.60000,0.77989,7477.03537,0.00000,0.00114,91.92165
15.70000,0.78504,7524.56114,0.00000,0.00115,92.50592
15.80000,0.78988,7567.74992,0.00000,0.00116,93.03688
15.90000,0.79508,7615.24662,0.00000,0.00117,93.62080
16.00000,0.79992,7656.87972,0.00000,0.00118,94.13263
16.10000,0.80507,7703.17763,0.00000,0.00119,94.70181
16.20000,0.80985,7746.03710,0.00000,0.00120,95.22872
16.30000,0.81505,7796.38439,0.00000,0.00120,95.84768
16.40000,0.81989,7838.48539,0.00000,0.00121,96.36526
16.50000,0.82504,7883.95852,0.00000,0.00122,96.92430
16.60000,0.82988,7926.86865,0.00000,0.00123,97.45183
16.70000,0.83496,7974.01145,0.00000,0.00124,98.03140
16.80000,0.83986,8019.77888,0.00000,0.00125,98.59406
16.90000,0.84500,8065.55226,0.00000,0.00126,99.15679
17.00000,0.84997,8111.26009,0.00000,0.00127,99.71872
17.10000,0.85505,8154.73720,0.00000,0.00128,100.25322
17.20000,0.86001,8202.13035,0.00000,0.00129,100.83586
17.30000,0.86497,8245.50912,0.00000,0.00130,101.36916
17.40000,0.87006,8294.43559,0.00000,0.00131,101.97065
17.50000,0.87502,8337.97157,0.00000,0.00131,102.50588
17.60000,0.88004,8386.81981,0.00000,0.00133,103.10641
17.70000,0.88494,8429.00425,0.00000,0.00134,103.62502
17.80000,0.89003,8477.02771,0.00000,0.00135,104.21541
17.90000,0.89493,8518.80983,0.00000,0.00136,104.72908
18.00000,0.90013,8568.37183,0.00000,0.00137,105.33839
18.10000,0.90491,8613.51043,0.00000,0.00137,105.89331
18.20000,0.91012,8662.58815,0.00000,0.00138,106.49667
18.30000,0.91496,8703.01723,0.00000,0.00139,106.99370
18.40000,0.92010,8750.80824,0.00000,0.00140,107.58123
18.50000,0.92494,8794.50515,0.00000,0.00140,108.11844
18.60000,0.93003,8843.76168,0.00000,0.00142,108.72399
18.70000,0.93493,8889.82266,0.00000,0.00143,109.29026
18.80000,0.94001,8936.35303,0.00000,0.00144,109.86230
18.90000,0.94491,8982.06607,0.00000,0.00145,110.42429
19.00000,0.95000,9028.70595,0.00000,0.00146,110.99767
19.10000,0.95484,9075.43525,0.00000,0.00147,111.57215
19.20000,0.95998,9122.42383,0.00000,0.00148,112.14983
19.30000,0.96494,9170.41078,0.00000,0.00149,112.73977
19.40000,0.97002,9216.77575,0.00000,0.00150,113.30978
19.50000,0.97493,9263.94686,0.00000,0.00151,113.88969
19.60000,0.98001,9309.77240,0.00000,0.00152,114.45306
19.70000,0.98497,9357.60662,0.00000,0.00152,115.04113
19.80000,0.98999,9400.85053,0.00000,0.00154,115.57277
19.90000,0.99502,9453.23929,0.00000,0.00155,116.21683
20.00000,0.99992,9495.37158,0.00000,0.00155,116.73479
20.10000,1.00506,9546.63604,0.00000,0.00157,117.36503
20.20000,1.00990,9588.46807,0.00000,0.00158,117.87931
20.30000,1.01505,9639.26315,0.00000,0.00159,118.50378
20.40000,1.01995,9683.09119,0.00000,0.00159,119.04259
20.50000,1.02503,9733.15164,0.00000,0.00160,119.65803
20.60000,1.02981,9778.71343,0.00000,0.00162,120.21816
20.70000,1.03502,9828.54068,0.00000,0.00162,120.83073
20.80000,1.03986,9874.00562,0.00000,0.00164,121.38967
20.90000,1.04506,9922.56403,0.00000,0.00164,121.98664
21.00000,1.04990,9968.00959,0.00000,0.00166,122.54534
21.10000,1.05499,10017.31977,0.00000,0.00167,123.15155
21.20000,1.05989,10064.77326,0.00000,0.00167,123.73494
21.30000,1.06503,10112.65516,0.00000,0.00168,124.32359
21.40000,1.06993,10158.95829,0.00000,0.00170,124.89284
21.50000,1.07502,10207.28052,0.00000,0.00171,125.48690
21.60000,1.07992,10253.83770,0.00000,0.00171,126.05927
21.70000,1.08500,10300.77636,0.00000,0.00173,126.63633
21.80000,1.09002,10348.76928,0.00000,0.00174,127.22635
21.90000,1.09498,10393.74769,0.00000,0.00175,127.77931
22.00000,1.10001,10444.21345,0.00000,0.00175,128.39973
22.10000,1.10497,10490.25133,0.00000,0.00177,128.96571
22.20000,1.10999,10537.80913,0.00000,0.00178,129.55038
22.30000,1.11501,10582.91644,0.00000,0.00178,130.10492
22.40000,1.12004,10633.28534,0.00000,0.00180,130.72415
22.50000,1.12494,10680.19643,0.00000,0.00181,131.30087
22.60000,1.13008,10730.45284,0.00000,0.00182,131.91871
22.70000,1.13498,10774.87618,0.00000,0.00183,132.46485
22.80000,1.14007,10824.26980,0.00000,0.00184,133.07209
22.90000,1.14491,10870.05213,0.00000,0.00185,133.63493
23.00000,1.15005,10922.32019,0.00000,0.00186,134.27750
23.10000,1.15489,10967.22037,0.00000,0.00186,134.82950
23.20000,1.16010,11016.57674,0.00000,0.00188,135.43628
23.30000,1.16494,11062.67422,0.00000,0.00189,136.00300
23.40000,1.17008,11114.56454,0.00000,0.00190,136.64093
23.50000,1.17492,11161.04648,0.00000,0.00191,137.21237
23.60000,1.18007,11208.97532,0.00000,0.00192,137.80160
23.70000,1.18497,11254.51177,0.00000,0.00193,138.36142
23.80000,1.19005,11304.36957,0.00000,0.00195,138.97437
23.90000,1.19489,11353.25283,0.00000,0.00195,139.57533
24.00000,1.20003,11401.88798,0.00000,0.00197,140.17324
24.10000,1.20494,11450.33240,0.00000,0.00198,140.76881
24.20000,1.21002,11499.12551,0.00000,0.00199,141.36867
24.30000,1.21492,11547.52299,0.00000,0.00200,141.96366
24.40000,1.21994,11594.20460,0.00000,0.00201,142.53756
24.50000,1.22497,11645.52346,0.00000,0.00202,143.16847
24.60000,1.22999,11693.14235,0.00000,0.00203,143.75389
24.70000,1.23501,11744.93507,0.00000,0.00205,144.39062
24.80000,1.23997,11789.63780,0.00000,0.00205,144.94019
24.90000,1.24500,11840.96932,0.00000,0.00207,145.57125
25.00000,1.24984,11884.99406,0.00000,0.00208,146.11248
25.10000,1.25510,11938.78502,0.00000,0.00209,146.77378
25.20000,1.25994,11982.99974,0.00000,0.00210,147.31735
25.30000,1.26503,12034.49070,0.00000,0.00211,147.95038
25.40000,1.26987,12077.45150,0.00000,0.00213,148.47853
25.50000,1.27507,12129.20547,0.00000,0.00213,149.11479
25.60000,1.27991,12173.22052,0.00000,0.00215,149.65590
25.70000,1.28512,12225.04675,0.00000,0.00216,150.29305
25.80000,1.28996,12273.65807,0.00000,0.00217,150.89067
25.90000,1.29504,12325.75327,0.00000,0.00219,151.53112
26.00000,1.29994,12373.11810,0.00000,0.00220,152.11341
26.10000,1.30503,12418.71044,0.00000,0.00221,152.67392
26.20000,1.30993,12468.13983,0.00000,0.00222,153.28160
26.30000,1.31495,12517.96186,0.00000,0.00223,153.89410
26.40000,1.31991,12569.86111,0.00000,0.00225,154.53215
26.50000,1.32499,12615.68666,0.00000,0.00226,155.09552
26.60000,1.33002,12665.12424,0.00000,0.00227,155.70330
26.70000,1.33498,12711.15392,0.00000,0.00228,156.26918
26.80000,1.34000,12765.16616,0.00000,0.00230,156.93320
26.90000,1.34502,12811.12134,0.00000,0.00230,157.49817
27.00000,1.35005,12862.22786,0.00000,0.00232,158.12646
27.10000,1.35501,12906.09986,0.00000,0.00233,158.66582
27.20000,1.36003,12957.33750,0.00000,0.00234,159.29573
27.30000,1.36499,13004.83644,0.00000,0.00236,159.87967
27.40000,1.37008,13055.14723,0.00000,0.00237,160.49819
27.50000,1.37498,13100.72392,0.00000,0.00238,161.05850
27.60000,1.38006,13153.44721,0.00000,0.00240,161.70667
27.70000,1.38490,13199.38153,0.00000,0.00241,162.27138
27.80000,1.39005,13251.81127,0.00000,0.00242,162.91595
27.90000,1.39495,13296.38064,0.00000,0.00244,163.46388
28.00000,1.40009,13349.97863,0.00000,0.00245,164.12280
28.10000,1.40487,13396.01576,0.00000,0.00246,164.68878
28.20000,1.41002,13447.36665,0.00000,0.00247,165.32008
28.30000,1.41492,13494.62122,0.00000,0.00249,165.90102
28.40000,1.42006,13545.30007,0.00000,0.00250,166.52406
28.50000,1.42496,13592.95696,0.00000,0.00252,167.10995
28.60000,1.42999,13640.79416,0.00000,0.00253,167.69805
28.70000,1.43489,13690.40012,0.00000,0.00255,168.30790
28.80000,1.43997,13738.89297,0.00000,0.00256,168.90406
28.90000,1.44499,13789.30211,0.00000,0.00257,169.52379
29.00000,1.45007,13836.86811,0.00000,0.00259,170.10856
29.10000,1.45498,13885.99724,0.00000,0.00260,170.71254
29.20000,1.46000,13931.87791,0.00000,0.00261,171.27659
29.30000,1.46502,13985.00502,0.00000,0.00263,171.92973
29.40000,1.47004,14031.14796,0.00000,0.00264,172.49701
29.50000,1.47507,14082.02350,0.00000,0.00266,173.12246
29.60000,1.47991,14126.28740,0.00000,0.00267,173.66664
29.70000,1.48499,14179.51286,0.00000,0.00269,174.32098
29.80000,1.48989,14226.64970,0.00000,0.00270,174.90048
29.90000,1.49504,14277.58038,0.00000,0.00272,175.52661
30.00000,1.49988,14321.86067,0.00000,0.00273,176.07099
30.10000,1.50502,14373.77036,0.00000,0.00275,176.70916
30.20000,1.50986,14420.24559,0.00000,0.00277,177.28052
30.30000,1.51507,14471.49217,0.00000,0.00278,177.91054
30.40000,1.51991,14516.02280,0.00000,0.00280,178.45799
30.50000,1.52505,14565.83142,0.00000,0.00281,179.07033
30.60000,1.52995,14613.93684,0.00000,0.00283,179.66173
30.70000,1.53504,14661.90666,0.00000,0.00284,180.25147
30.80000,1.53988,14709.18953,0.00000,0.00286,180.83276
30.90000,1.54502,14757.31134,0.00000,0.00288,181.42436
31.00000,1.54986,14804.59869,0.00000,0.00290,182.00570
31.10000,1.55495,14853.86193,0.00000,0.00291,182.61134
31.20000,1.55997,14902.04036,0.00000,0.00293,183.20364
31.30000,1.56505,14948.44705,0.00000,0.00294,183.77415
31.40000,1.57001,14999.48949,0.00000,0.00296,184.40166
31.50000,1.57497,15044.98571,0.00000,0.00298,184.96099
31.60000,1.58000,15096.44091,0.00000,0.00300,185.59357
31.70000,1.58502,15139.69600,0.00000,0.00301,186.12534
31.80000,1.59004,15190.49257,0.00000,0.00304,186.74983
31.90000,1.59500,15235.92025,0.00000,0.00305,187.30831
32.00000,1.60003,15286.53502,0.00000,0.00307,187.93056
32.10000,1.60487,15331.74962,0.00000,0.00309,188.48642
32.20000,1.61007,15382.44337,0.00000,0.00311,189.10965
32.30000,1.61497,15426.33474,0.00000,0.00314,189.64924
32.40000,1.62012,15476.27300,0.00000,0.00316,190.26317
32.50000,1.62496,15519.29414,0.00000,0.00318,190.79207
32.60000,1.63004,15570.09965,0.00000,0.00320,191.41667
32.70000,1.63494,15614.18027,0.00000,0.00322,191.95859
32.80000,1.64009,15667.13452,0.00000,0.00324,192.60960
32.90000,1.64487,15707.93241,0.00000,0.00326,193.11116
33.00000,1.65001,15758.51589,0.00000,0.00329,193.73303
33.10000,1.65485,15803.92420,0.00000,0.00331,194.29127
33.20000,1.66000,15851.59004,0.00000,0.00334,194.87727
33.30000,1.66490,15897.59737,0.00000,0.00336,195.44288
33.40000,1.67004,15945.12314,0.00000,0.00338,196.02715
33.50000,1.67488,15992.00219,0.00000,0.00341,196.60348
33.60000,1.68003,16036.82339,0.00000,0.00344,197.15450
33.70000,1.68493,16084.32680,0.00000,0.00346,197.73850
33.80000,1.69001,16126.66547,0.00000,0.00349,198.25901
33.90000,1.69491,16174.52353,0.00000,0.00352,198.84737
34.00000,1.69993,16217.84568,0.00000,0.00354,199.37997
34.10000,1.70496,16267.04037,0.00000,0.00357,199.98476
34.20000,1.70998,16307.72948,0.00000,0.00360,200.48499
34.30000,1.71500,16353.13183,0.00000,0.00363,201.04316
34.40000,1.71984,16394.79250,0.00000,0.00366,201.55533
34.50000,1.72499,16443.36730,0.00000,0.00369,202.15250
34.60000,1.72989,16485.05330,0.00000,0.00372,202.66498
34.70000,1.73503,16531.18730,0.00000,0.00375,203.23215
34.80000,1.73987,16569.75299,0.00000,0.00379,203.70627
34.90000,1.74502,16617.09994,0.00000,0.00382,204.28834
35.00000,1.74986,16658.24354,0.00000,0.00386,204.79416
35.10000,1.75500,16701.95311,0.00000,0.00390,205.33152
35.20000,1.75990,16742.47533,0.00000,0.00393,205.82969
35.30000,1.76499,16785.52628,0.00000,0.00397,206.35895
35.40000,1.76989,16826.43741,0.00000,0.00401,206.86191
35.50000,1.77497,16869.76552,0.00000,0.00405,207.39458
35.60000,1.77993,16909.31171,0.00000,0.00409,207.88076
35.70000,1.78502,16949.68343,0.00000,0.00413,208.37708
35.80000,1.78998,16988.95842,0.00000,0.00418,208.85992
35.90000,1.79500,17028.83691,0.00000,0.00423,209.35018
36.00000,1.79996,17070.22786,0.00000,0.00428,209.85904
36.10000,1.80510,17108.56408,0.00000,0.00433,210.33034
36.20000,1.81001,17147.01504,0.00000,0.00438,210.80305
36.30000,1.81503,17183.32171,0.00000,0.00443,211.24940
36.40000,1.81993,17222.00364,0.00000,0.00449,211.72495
36.50000,1.82501,17257.36707,0.00000,0.00454,212.15970
36.60000,1.83004,17298.11430,0.00000,0.00460,212.66064
36.70000,1.83500,17331.44373,0.00000,0.00466,213.07039
36.80000,1.84002,17370.25827,0.00000,0.00473,213.54757
36.90000,1.84492,17402.26150,0.00000,0.00479,213.94101
37.00000,1.85001,17439.36092,0.00000,0.00485,214.39711
37.10000,1.85497,17470.78449,0.00000,0.00492,214.78342
37.20000,1.86005,17508.46356,0.00000,0.00499,215.24665
37.30000,1.86483,17537.70262,0.00000,0.00506,215.60611
37.40000,1.87004,17572.98112,0.00000,0.00513,216.03982
37.50000,1.87488,17600.91633,0.00000,0.00520,216.38325
37.60000,1.88008,17635.97131,0.00000,0.00529,216.81421
37.70000,1.88486,17664.13450,0.00000,0.00536,217.16044
37.80000,1.89007,17698.56215,0.00000,0.00544,217.58369
37.90000,1.89491,17725.70759,0.00000,0.00553,217.91741
38.00000,1.89999,17755.33706,0.00000,0.00561,218.28168
38.10000,1.90489,17782.57042,0.00000,0.00569,218.61648
38.20000,1.90998,17811.85865,0.00000,0.00577,218.97654
38.30000,1.91488,17841.14391,0.00000,0.00587,219.33657
38.40000,1.91996,17868.70360,0.00000,0.00596,219.67539
38.50000,1.92492,17894.54371,0.00000,0.00605,219.99306
38.60000,1.92994,17919.99936,0.00000,0.00614,220.30601
38.70000,1.93497,17949.46790,0.00000,0.00624,220.66829
38.80000,1.93993,17971.00455,0.00000,0.00634,220.93306
38.90000,1.94501,17998.57914,0.00000,0.00645,221.27206
39.00000,1.94997,18016.07460,0.00000,0.00656,221.48715
39.10000,1.95500,18042.48542,0.00000,0.00666,221.81184
39.20000,1.95990,18063.62122,0.00000,0.00676,222.07168
39.30000,1.96504,18089.95754,0.00000,0.00687,222.39545
39.40000,1.96994,18109.02059,0.00000,0.00698,222.62981
39.50000,1.97509,18130.43654,0.00000,0.00709,222.89310
39.60000,1.97987,18148.85736,0.00000,0.00720,223.11956
39.70000,1.98501,18175.47530,0.00000,0.00732,223.44680
39.80000,1.98991,18191.76525,0.00000,0.00744,223.64706
39.90000,1.99512,18213.21696,0.00000,0.00755,223.91079
40.00000,2.00002,18229.82430,0.00000,0.00768,224.11496
40.10000,2.00510,18250.39536,0.00000,0.00780,224.36785
40.20000,2.00994,18268.28569,0.00000,0.00792,224.58780
40.30000,2.01503,18286.80336,0.00000,0.00805,224.81545
40.40000,2.01999,18304.66092,0.00000,0.00818,225.03499
40.50000,2.02507,18322.25174,0.00000,0.00831,225.25125
40.60000,2.02991,18337.70424,0.00000,0.00844,225.44122
40.70000,2.03505,18355.17138,0.00000,0.00858,225.65596
40.80000,2.03996,18370.43315,0.00000,0.00871,225.84358
40.90000,2.04504,18385.60700,0.00000,0.00884,226.03013
41.00000,2.05000,18399.73181,0.00000,0.00898,226.20378
41.10000,2.05502,18412.09978,0.00000,0.00911,226.35583
41.20000,2.05999,18427.26469,0.00000,0.00925,226.54226
41.30000,2.06501,18438.42715,0.00000,0.00939,226.67949
41.40000,2.07003,18452.51620,0.00000,0.00955,226.85270
41.50000,2.07499,18459.91015,0.00000,0.00970,226.94360
41.60000,2.08002,18471.44961,0.00000,0.00985,227.08546
41.70000,2.08492,18460.56581,0.00000,0.01001,226.95166
41.80000,2.09006,18444.45020,0.00000,0.01020,226.75354
41.90000,2.09490,18429.22717,0.00000,0.01039,226.56639
42.00000,2.10005,18426.50920,0.00000,0.01058,226.53297
42.10000,2.10489,18411.48138,0.00000,0.01078,226.34822
42.20000,2.11015,18383.09467,0.00000,0.01100,225.99924
42.30000,2.11499,18331.79146,0.00000,0.01124,225.36853
42.40000,2.12014,18268.78935,0.00000,0.01150,224.59399
42.50000,2.12492,18194.79018,0.00000,0.01178,223.68425
42.60000,2.13006,18067.89488,0.00000,0.01212,222.12422
42.63800,2.13203,17794.59417,0.00000,0.01249,218.76430
42.64800,2.13251,17542.00161,0.00000,0.01284,215.65896
42.65600,2.13293,17263.11892,0.00000,0.01322,212.23041
42.66400,2.13335,16974.56092,0.00000,0.01364,208.68292
42.67200,2.13377,16703.89324,0.00000,0.01402,205.35537
42.68200,2.13431,16400.77978,0.00000,0.01445,201.62893
42.69000,2.13472,16125.32437,0.00000,0.01484,198.24252
42.69600,2.13502,15871.68425,0.00000,0.01523,195.12431
42.70200,2.13538,15604.13986,0.00000,0.01563,191.83515
42.70800,2.13568,15348.90085,0.00000,0.01601,188.69728
42.71600,2.13616,15056.31506,0.00000,0.01645,185.10027
42.72600,2.13670,14787.96601,0.00000,0.01685,181.80122
42.74600,2.13783,14530.86734,0.00000,0.01728,178.64049
42.84600,2.14280,14424.45517,0.00000,0.01765,177.33227
42.94600,2.14752,14255.56093,0.00000,0.01808,175.25591
43.04600,2.15254,14062.85316,0.00000,0.01855,172.88679
43.10600,2.15541,13799.27546,0.00000,0.01903,169.64640
43.11600,2.15589,13511.15406,0.00000,0.01944,166.10427
43.11800,2.15601,13217.83811,0.00000,0.01987,162.49829
43.12000,2.15619,12760.55872,0.00000,0.02050,156.87656
43.12200,2.15637,12185.54974,0.00000,0.02114,149.80747
43.12400,2.15661,11537.75156,0.00000,0.02168,141.84353
43.12600,2.15685,10828.38774,0.00000,0.02216,133.12271
43.12800,2.15703,10066.24326,0.00000,0.02257,123.75301
43.13000,2.15726,9276.65606,0.00000,0.02292,114.04594
43.13200,2.15750,8483.64457,0.00000,0.02324,104.29676
43.13400,2.15774,7698.82649,0.00000,0.02352,94.64832